{"stream":"ethusdt@trade","data":{"e":"trade","E":1783465200209,"s":"ETHUSDT","t":4197008644,"p":"1775.32000000","q":"0.14000000","T":1783465200208,"m":true,"M":true}}
{"stream":"ethusdt@trade","data":{"e":"trade","E":1783465200209,"s":"ETHUSDT","t":4197008645,"p":"1775.32000000","q":"0.00290000","T":1783465200208,"m":true,"M":true}}
{"stream":"ethusdt@trade","data":{"e":"trade","E":1783465200209,"s":"ETHUSDT","t":4197008646,"p":"1775.31000000","q":"0.00290000","T":1783465200208,"m":true,"M":true}}
{"stream":"ethusdt@trade","data":{"e":"trade","E":1783465200209,"s":"ETHUSDT","t":4197008647,"p":"1775.30000000","q":"0.00290000","T":1783465200208,"m":true,"M":true}}
{"stream":"ethusdt@trade","data":{"e":"trade","E":1783465200209,"s":"ETHUSDT","t":4197008648,"p":"1775.30000000","q":"0.00940000","T":1783465200208,"m":true,"M":true}}
{"stream":"ethusdt@trade","data":{"e":"trade","E":1783465200209,"s":"ETHUSDT","t":4197008649,"p":"1775.29000000","q":"1.40440000","T":1783465200208,"m":true,"M":true}}
{"stream":"ethusdt@trade","data":{"e":"trade","E":1783465200209,"s":"ETHUSDT","t":4197008650,"p":"1775.29000000","q":"0.08440000","T":1783465200208,"m":true,"M":true}}
{"stream":"ethusdt@trade","data":{"e":"trade","E":1783465200209,"s":"ETHUSDT","t":4197008651,"p":"1775.29000000","q":"0.76040000","T":1783465200208,"m":true,"M":true}}
{"stream":"ethusdt@trade","data":{"e":"trade","E":1783465200209,"s":"ETHUSDT","t":4197008652,"p":"1775.28000000","q":"0.00290000","T":1783465200208,"m":true,"M":true}}
{"stream":"ethusdt@trade","data":{"e":"trade","E":1783465200209,"s":"ETHUSDT","t":4197008653,"p":"1775.28000000","q":"0.15220000","T":1783465200208,"m":true,"M":true}}
{"stream":"ethusdt@trade","data":{"e":"trade","E":1783465200211,"s":"ETHUSDT","t":4197008654,"p":"1775.29000000","q":"0.00290000","T":1783465200210,"m":false,"M":true}}
{"stream":"btcusdt@depth@100ms","data":{"e":"depthUpdate","E":1783465200214,"s":"BTCUSDT","U":97109089488,"u":97109089522,"b":[["63551.02000000","0.02477000"],["63551.01000000","0.01415000"],["63548.00000000","0.02818000"],["63547.84000000","0.00010000"],["63545.33000000","0.04939000"],["63544.66000000","0.00316000"],["63542.14000000","0.00000000"],["63542.13000000","0.00008000"],["63541.67000000","0.00787000"],["63539.00000000","0.00008000"],["63538.69000000","0.00000000"],["63537.00000000","0.00008000"],["63535.87000000","0.00008000"],["63534.40000000","1.22840000"],["63532.74000000","0.00008000"],["63468.92000000","2.83475000"],["63392.34000000","0.00008000"],["63389.35000000","0.00000000"],["57819.60000000","0.01729000"],["57195.92000000","0.00500000"],["50840.82000000","0.00044000"]],"a":[["63551.84000000","0.00252000"],["63552.69000000","0.00000000"],["63562.21000000","0.56676000"],["63562.43000000","0.00008000"],["63575.70000000","0.00000000"]]}}
{"stream":"ethusdt@depth@100ms","data":{"e":"depthUpdate","E":1783465200215,"s":"ETHUSDT","U":78545071304,"u":78545071970,"b":[["1775.55000000","0.00000000"],["1775.54000000","0.00000000"],["1775.53000000","0.00000000"],["1775.52000000","0.00000000"],["1775.51000000","0.00000000"],["1775.50000000","0.00000000"],["1775.49000000","0.00000000"],["1775.48000000","0.00000000"],["1775.47000000","0.00000000"],["1775.46000000","0.00000000"],["1775.45000000","0.00000000"],["1775.44000000","0.00000000"],["1775.43000000","0.00000000"],["1775.40000000","0.00000000"],["1775.39000000","0.00000000"],["1775.38000000","0.00000000"],["1775.36000000","0.00000000"],["1775.35000000","0.00000000"],["1775.34000000","0.00000000"],["1775.33000000","0.00000000"],["1775.32000000","0.00000000"],["1775.31000000","0.00000000"],["1775.30000000","0.00000000"],["1775.29000000","0.00000000"],["1775.28000000","13.77640000"],["1775.27000000","0.87990000"],["1775.26000000","0.00900000"],["1775.25000000","0.03690000"],["1775.24000000","0.14160000"],["1775.23000000","0.19930000"],["1775.22000000","0.00600000"],["1775.21000000","0.72330000"],["1775.20000000","0.44590000"],["1775.19000000","2.48380000"],["1775.18000000","0.00300000"],["1775.17000000","0.00430000"],["1775.16000000","0.28740000"],["1775.15000000","1.37910000"],["1775.14000000","0.58850000"],["1775.13000000","0.29020000"],["1775.12000000","1.58190000"],["1775.11000000","0.50340000"],["1775.10000000","0.00580000"],["1775.09000000","0.76050000"],["1775.08000000","0.87400000"],["1775.07000000","0.01030000"],["1775.06000000","5.36480000"],["1775.05000000","0.00290000"],["1775.03000000","0.00290000"],["1775.02000000","0.88240000"],["1775.01000000","0.94260000"],["1775.00000000","0.39050000"],["1774.98000000","0.01580000"],["1774.97000000","21.56830000"],["1774.96000000","0.90980000"],["1774.95000000","7.89060000"],["1774.94000000","0.00000000"],["1774.91000000","7.88480000"],["1774.90000000","27.01480000"],["1774.84000000","5.38940000"],["1774.82000000","0.00290000"],["1774.81000000","9.46610000"],["1774.80000000","7.92510000"],["1774.79000000","15.01870000"],["1774.78000000","22.91180000"],["1774.77000000","0.00000000"],["1774.76000000","2.82120000"],["1774.75000000","0.00290000"],["1774.74000000","0.56640000"],["1774.72000000","0.46990000"],["1774.71000000","25.69360000"],["1774.69000000","8.09110000"],["1774.68000000","0.86830000"],["1774.65000000","9.46180000"],["1774.64000000","0.04130000"],["1774.62000000","0.44440000"],["1774.59000000","16.20950000"],["1774.58000000","0.00290000"],["1774.56000000","0.03580000"],["1774.55000000","1.40180000"],["1774.51000000","6.00610000"],["1774.50000000","1.65150000"],["1774.49000000","0.80000000"],["1774.48000000","0.60990000"],["1774.47000000","0.14000000"],["1774.46000000","1.13500000"],["1774.41000000","15.45570000"],["1774.40000000","0.46990000"],["1774.39000000","9.46180000"],["1774.16000000","0.03000000"],["1774.08000000","0.11740000"],["1774.03000000","0.59110000"],["1773.92000000","0.24760000"],["1773.85000000","0.00000000"],["1773.68000000","24.48050000"],["1773.67000000","0.14790000"],["1773.54000000","1.00140000"],["1773.50000000","0.46520000"],["1773.48000000","2.91200000"],["1773.44000000","6.75070000"],["1773.42000000","0.00000000"],["1773.38000000","0.13250000"],["1773.37000000","15.77680000"],["1773.36000000","7.89220000"],["1773.32000000","0.00290000"],["1773.30000000","2.47500000"],["1773.26000000","0.03000000"],["1773.24000000","0.00840000"],["1773.20000000","0.13540000"],["1773.18000000","0.00740000"],["1773.17000000","0.00870000"],["1773.14000000","0.00000000"],["1773.12000000","23.65440000"],["1772.92000000","0.00000000"],["1772.87000000","7.88480000"],["1772.85000000","0.00000000"],["1772.79000000","15.01870000"],["1772.72000000","0.00460000"],["1772.60000000","0.02000000"],["1771.86000000","0.00290000"],["1768.87000000","0.00000000"],["1598.00000000","2.36330000"]],"a":[["1775.29000000","35.57560000"],["1775.30000000","0.00570000"],["1775.31000000","0.00570000"],["1775.32000000","0.00000000"],["1775.33000000","0.00000000"],["1775.34000000","0.00000000"],["1775.35000000","0.20450000"],["1775.36000000","0.03290000"],["1775.37000000","24.59080000"],["1775.39000000","0.43700000"],["1775.40000000","0.43700000"],["1775.44000000","0.03890000"],["1775.45000000","0.00600000"],["1775.46000000","0.85910000"],["1775.47000000","2.25630000"],["1775.48000000","0.20740000"],["1775.49000000","0.43700000"],["1775.50000000","0.00000000"],["1775.51000000","4.58130000"],["1775.52000000","12.43410000"],["1775.53000000","0.00290000"],["1775.54000000","0.78100000"],["1775.55000000","57.91150000"],["1775.56000000","4.05030000"],["1775.57000000","0.00300000"],["1775.58000000","0.00590000"],["1775.59000000","0.33530000"],["1775.60000000","0.68970000"],["1775.61000000","0.17360000"],["1775.62000000","3.41550000"],["1775.63000000","0.36390000"],["1775.65000000","0.00290000"],["1775.67000000","2.95050000"],["1775.68000000","0.81980000"],["1775.72000000","15.01570000"],["1775.74000000","16.31760000"],["1775.77000000","0.62860000"],["1775.81000000","0.00290000"],["1775.82000000","24.00310000"],["1775.88000000","9.06280000"],["1775.92000000","0.03290000"],["1775.94000000","0.00580000"],["1776.07000000","0.00560000"],["1776.10000000","0.07760000"],["1776.24000000","15.78690000"],["1776.26000000","8.02140000"],["1776.32000000","0.03000000"],["1776.37000000","0.29690000"],["1776.38000000","2.82800000"],["1776.40000000","1.23400000"],["1776.41000000","0.90700000"],["1776.56000000","2.81630000"],["1776.64000000","0.80000000"],["1776.72000000","0.00580000"],["1776.77000000","0.30250000"],["1776.86000000","0.00000000"],["1776.99000000","0.00000000"],["1777.26000000","0.00290000"],["1777.31000000","0.00290000"],["1777.41000000","27.25660000"],["1777.51000000","0.00000000"],["1777.53000000","0.00000000"],["1777.65000000","24.59080000"],["1779.03000000","24.59080000"]]}}
{"stream":"ethusdt@trade","data":{"e":"trade","E":1783465200219,"s":"ETHUSDT","t":4197008655,"p":"1775.28000000","q":"0.49900000","T":1783465200219,"m":true,"M":true}}
{"stream":"ethusdt@trade","data":{"e":"trade","E":1783465200219,"s":"ETHUSDT","t":4197008656,"p":"1775.28000000","q":"0.17000000","T":1783465200219,"m":true,"M":true}}
{"stream":"ethusdt@trade","data":{"e":"trade","E":1783465200220,"s":"ETHUSDT","t":4197008657,"p":"1775.28000000","q":"0.25030000","T":1783465200220,"m":true,"M":true}}
{"stream":"ethusdt@trade","data":{"e":"trade","E":1783465200220,"s":"ETHUSDT","t":4197008658,"p":"1775.28000000","q":"0.47470000","T":1783465200220,"m":true,"M":true}}
{"stream":"ethusdt@trade","data":{"e":"trade","E":1783465200237,"s":"ETHUSDT","t":4197008659,"p":"1775.28000000","q":"0.78100000","T":1783465200237,"m":true,"M":true}}
{"stream":"ethusdt@trade","data":{"e":"trade","E":1783465200251,"s":"ETHUSDT","t":4197008660,"p":"1775.28000000","q":"0.15590000","T":1783465200251,"m":true,"M":true}}
{"stream":"ethusdt@trade","data":{"e":"trade","E":1783465200251,"s":"ETHUSDT","t":4197008661,"p":"1775.28000000","q":"0.00300000","T":1783465200251,"m":true,"M":true}}
{"stream":"ethusdt@trade","data":{"e":"trade","E":1783465200251,"s":"ETHUSDT","t":4197008662,"p":"1775.28000000","q":"0.00500000","T":1783465200251,"m":true,"M":true}}
{"stream":"ethusdt@trade","data":{"e":"trade","E":1783465200251,"s":"ETHUSDT","t":4197008663,"p":"1775.28000000","q":"0.23610000","T":1783465200251,"m":true,"M":true}}
{"stream":"ethusdt@trade","data":{"e":"trade","E":1783465200252,"s":"ETHUSDT","t":4197008664,"p":"1775.28000000","q":"0.80000000","T":1783465200251,"m":true,"M":true}}
{"stream":"btcusdt@trade","data":{"e":"trade","E":1783465200310,"s":"BTCUSDT","t":6486989413,"p":"63551.02000000","q":"0.00008000","T":1783465200309,"m":true,"M":true}}
{"stream":"btcusdt@trade","data":{"e":"trade","E":1783465200310,"s":"BTCUSDT","t":6486989414,"p":"63551.02000000","q":"0.00008000","T":1783465200309,"m":true,"M":true}}
{"stream":"btcusdt@trade","data":{"e":"trade","E":1783465200310,"s":"BTCUSDT","t":6486989415,"p":"63551.02000000","q":"0.00008000","T":1783465200309,"m":true,"M":true}}
{"stream":"btcusdt@trade","data":{"e":"trade","E":1783465200310,"s":"BTCUSDT","t":6486989416,"p":"63551.02000000","q":"0.00008000","T":1783465200309,"m":true,"M":true}}
{"stream":"btcusdt@trade","data":{"e":"trade","E":1783465200310,"s":"BTCUSDT","t":6486989417,"p":"63551.02000000","q":"0.00009000","T":1783465200309,"m":true,"M":true}}
{"stream":"btcusdt@trade","data":{"e":"trade","E":1783465200310,"s":"BTCUSDT","t":6486989418,"p":"63551.02000000","q":"0.00009000","T":1783465200309,"m":true,"M":true}}
{"stream":"btcusdt@trade","data":{"e":"trade","E":1783465200310,"s":"BTCUSDT","t":6486989419,"p":"63551.02000000","q":"0.00009000","T":1783465200309,"m":true,"M":true}}
{"stream":"btcusdt@trade","data":{"e":"trade","E":1783465200310,"s":"BTCUSDT","t":6486989420,"p":"63551.02000000","q":"0.00271000","T":1783465200309,"m":true,"M":true}}
{"stream":"btcusdt@trade","data":{"e":"trade","E":1783465200310,"s":"BTCUSDT","t":6486989421,"p":"63551.02000000","q":"0.00029000","T":1783465200309,"m":true,"M":true}}
{"stream":"btcusdt@trade","data":{"e":"trade","E":1783465200310,"s":"BTCUSDT","t":6486989422,"p":"63551.02000000","q":"0.00009000","T":1783465200309,"m":true,"M":true}}
{"stream":"btcusdt@trade","data":{"e":"trade","E":1783465200310,"s":"BTCUSDT","t":6486989423,"p":"63551.02000000","q":"0.00009000","T":1783465200309,"m":true,"M":true}}
{"stream":"btcusdt@trade","data":{"e":"trade","E":1783465200310,"s":"BTCUSDT","t":6486989424,"p":"63551.02000000","q":"0.00943000","T":1783465200309,"m":true,"M":true}}
{"stream":"btcusdt@trade","data":{"e":"trade","E":1783465200310,"s":"BTCUSDT","t":6486989425,"p":"63551.02000000","q":"0.00034000","T":1783465200309,"m":true,"M":true}}
{"stream":"btcusdt@trade","data":{"e":"trade","E":1783465200310,"s":"BTCUSDT","t":6486989426,"p":"63551.02000000","q":"0.00008000","T":1783465200309,"m":true,"M":true}}
{"stream":"btcusdt@trade","data":{"e":"trade","E":1783465200310,"s":"BTCUSDT","t":6486989427,"p":"63551.02000000","q":"0.00008000","T":1783465200309,"m":true,"M":true}}
{"stream":"btcusdt@trade","data":{"e":"trade","E":1783465200310,"s":"BTCUSDT","t":6486989428,"p":"63551.02000000","q":"0.00008000","T":1783465200309,"m":true,"M":true}}
{"stream":"btcusdt@trade","data":{"e":"trade","E":1783465200310,"s":"BTCUSDT","t":6486989429,"p":"63551.02000000","q":"0.00008000","T":1783465200309,"m":true,"M":true}}
{"stream":"btcusdt@trade","data":{"e":"trade","E":1783465200310,"s":"BTCUSDT","t":6486989430,"p":"63551.02000000","q":"0.00009000","T":1783465200309,"m":true,"M":true}}
{"stream":"btcusdt@trade","data":{"e":"trade","E":1783465200310,"s":"BTCUSDT","t":6486989431,"p":"63551.02000000","q":"0.00009000","T":1783465200309,"m":true,"M":true}}
{"stream":"btcusdt@trade","data":{"e":"trade","E":1783465200310,"s":"BTCUSDT","t":6486989432,"p":"63551.02000000","q":"0.00009000","T":1783465200309,"m":true,"M":true}}
{"stream":"btcusdt@trade","data":{"e":"trade","E":1783465200310,"s":"BTCUSDT","t":6486989433,"p":"63551.02000000","q":"0.00009000","T":1783465200309,"m":true,"M":true}}
{"stream":"btcusdt@trade","data":{"e":"trade","E":1783465200310,"s":"BTCUSDT","t":6486989434,"p":"63551.02000000","q":"0.00016000","T":1783465200309,"m":true,"M":true}}
{"stream":"btcusdt@trade","data":{"e":"trade","E":1783465200310,"s":"BTCUSDT","t":6486989435,"p":"63551.02000000","q":"0.00009000","T":1783465200309,"m":true,"M":true}}
{"stream":"btcusdt@trade","data":{"e":"trade","E":1783465200310,"s":"BTCUSDT","t":6486989436,"p":"63551.02000000","q":"0.00009000","T":1783465200309,"m":true,"M":true}}
{"stream":"btcusdt@trade","data":{"e":"trade","E":1783465200310,"s":"BTCUSDT","t":6486989437,"p":"63551.02000000","q":"0.00009000","T":1783465200309,"m":true,"M":true}}
{"stream":"btcusdt@trade","data":{"e":"trade","E":1783465200310,"s":"BTCUSDT","t":6486989438,"p":"63551.02000000","q":"0.00200000","T":1783465200309,"m":true,"M":true}}
{"stream":"btcusdt@trade","data":{"e":"trade","E":1783465200310,"s":"BTCUSDT","t":6486989439,"p":"63551.02000000","q":"0.00786000","T":1783465200309,"m":true,"M":true}}
{"stream":"btcusdt@trade","data":{"e":"trade","E":1783465200310,"s":"BTCUSDT","t":6486989440,"p":"63551.02000000","q":"0.00009000","T":1783465200309,"m":true,"M":true}}
{"stream":"btcusdt@trade","data":{"e":"trade","E":1783465200310,"s":"BTCUSDT","t":6486989441,"p":"63551.02000000","q":"0.00008000","T":1783465200309,"m":true,"M":true}}
{"stream":"btcusdt@trade","data":{"e":"trade","E":1783465200310,"s":"BTCUSDT","t":6486989442,"p":"63551.02000000","q":"0.09071000","T":1783465200309,"m":true,"M":true}}
{"stream":"btcusdt@trade","data":{"e":"trade","E":1783465200310,"s":"BTCUSDT","t":6486989443,"p":"63551.02000000","q":"0.00008000","T":1783465200309,"m":true,"M":true}}
{"stream":"btcusdt@trade","data":{"e":"trade","E":1783465200310,"s":"BTCUSDT","t":6486989444,"p":"63551.02000000","q":"0.00271000","T":1783465200309,"m":true,"M":true}}
{"stream":"btcusdt@trade","data":{"e":"trade","E":1783465200310,"s":"BTCUSDT","t":6486989445,"p":"63551.02000000","q":"0.00009000","T":1783465200309,"m":true,"M":true}}
{"stream":"btcusdt@trade","data":{"e":"trade","E":1783465200310,"s":"BTCUSDT","t":6486989446,"p":"63551.02000000","q":"0.00008000","T":1783465200309,"m":true,"M":true}}
{"stream":"btcusdt@trade","data":{"e":"trade","E":1783465200310,"s":"BTCUSDT","t":6486989447,"p":"63551.02000000","q":"0.00008000","T":1783465200309,"m":true,"M":true}}
{"stream":"btcusdt@trade","data":{"e":"trade","E":1783465200310,"s":"BTCUSDT","t":6486989448,"p":"63551.02000000","q":"0.00008000","T":1783465200309,"m":true,"M":true}}
{"stream":"btcusdt@trade","data":{"e":"trade","E":1783465200310,"s":"BTCUSDT","t":6486989449,"p":"63551.02000000","q":"0.00008000","T":1783465200309,"m":true,"M":true}}
{"stream":"btcusdt@trade","data":{"e":"trade","E":1783465200310,"s":"BTCUSDT","t":6486989450,"p":"63551.02000000","q":"0.00271000","T":1783465200309,"m":true,"M":true}}
{"stream":"btcusdt@trade","data":{"e":"trade","E":1783465200310,"s":"BTCUSDT","t":6486989451,"p":"63551.02000000","q":"0.00008000","T":1783465200309,"m":true,"M":true}}
{"stream":"btcusdt@trade","data":{"e":"trade","E":1783465200310,"s":"BTCUSDT","t":6486989452,"p":"63551.02000000","q":"0.00008000","T":1783465200309,"m":true,"M":true}}
{"stream":"btcusdt@trade","data":{"e":"trade","E":1783465200310,"s":"BTCUSDT","t":6486989453,"p":"63551.02000000","q":"0.00271000","T":1783465200309,"m":true,"M":true}}
{"stream":"btcusdt@trade","data":{"e":"trade","E":1783465200310,"s":"BTCUSDT","t":6486989454,"p":"63551.02000000","q":"0.00008000","T":1783465200309,"m":true,"M":true}}
{"stream":"btcusdt@trade","data":{"e":"trade","E":1783465200310,"s":"BTCUSDT","t":6486989455,"p":"63551.02000000","q":"0.00008000","T":1783465200309,"m":true,"M":true}}
{"stream":"btcusdt@trade","data":{"e":"trade","E":1783465200310,"s":"BTCUSDT","t":6486989456,"p":"63551.02000000","q":"0.00271000","T":1783465200309,"m":true,"M":true}}
{"stream":"btcusdt@trade","data":{"e":"trade","E":1783465200310,"s":"BTCUSDT","t":6486989457,"p":"63551.02000000","q":"0.00008000","T":1783465200309,"m":true,"M":true}}
{"stream":"btcusdt@trade","data":{"e":"trade","E":1783465200310,"s":"BTCUSDT","t":6486989458,"p":"63551.02000000","q":"0.00258000","T":1783465200309,"m":true,"M":true}}
{"stream":"btcusdt@depth@100ms","data":{"e":"depthUpdate","E":1783465200314,"s":"BTCUSDT","U":97109089523,"u":97109089581,"b":[["63551.02000000","0.00162000"],["63551.01000000","0.01423000"],["63548.56000000","0.00032000"],["63546.87000000","0.00000000"],["63546.86000000","0.00026000"],["63546.01000000","0.00018000"],["63545.83000000","0.00009000"],["63545.82000000","0.00035000"],["63543.13000000","0.14505000"],["63540.29000000","0.00000000"],["63538.70000000","0.00000000"],["63538.18000000","0.02000000"],["63535.96000000","0.65737000"],["63535.95000000","0.42501000"],["63535.94000000","0.00000000"],["63535.60000000","0.00000000"],["63534.40000000","0.00000000"],["63532.69000000","1.22840000"],["63524.78000000","0.56710000"],["62146.20000000","0.00000000"],["57195.92000000","0.00500000"],["50870.40000000","0.00022000"],["50840.82000000","0.00066000"]],"a":[["63551.03000000","5.22730000"]]}}
{"stream":"ethusdt@depth@100ms","data":{"e":"depthUpdate","E":1783465200315,"s":"ETHUSDT","U":78545071971,"u":78545072213,"b":[["1775.28000000","1.56080000"],["1775.27000000","0.00880000"],["1775.26000000","0.00300000"],["1775.25000000","0.01300000"],["1775.23000000","0.19930000"],["1775.22000000","6.77390000"],["1775.21000000","0.44300000"],["1775.20000000","0.00590000"],["1775.19000000","0.00880000"],["1775.18000000","0.00000000"],["1775.17000000","0.00730000"],["1775.16000000","0.38740000"],["1775.15000000","0.73140000"],["1775.13000000","0.00840000"],["1775.11000000","0.50000000"],["1775.06000000","0.00000000"],["1775.01000000","0.00620000"],["1775.00000000","0.28050000"],["1774.97000000","9.16750000"],["1774.95000000","0.28760000"],["1774.94000000","0.00000000"],["1774.93000000","2.48930000"],["1774.92000000","3.38160000"],["1774.91000000","0.00000000"],["1774.90000000","2.42400000"],["1774.88000000","0.04790000"],["1774.87000000","19.89100000"],["1774.82000000","7.94400000"],["1774.81000000","9.46610000"],["1774.80000000","7.92510000"],["1774.79000000","0.00000000"],["1774.78000000","0.87400000"],["1774.74000000","0.00290000"],["1774.69000000","7.89110000"],["1774.66000000","0.44280000"],["1774.64000000","0.04130000"],["1774.62000000","15.46310000"],["1774.61000000","14.99550000"],["1774.57000000","0.28000000"],["1774.55000000","1.80180000"],["1774.53000000","24.59820000"],["1774.51000000","0.00000000"],["1774.50000000","0.31950000"],["1774.49000000","0.00000000"],["1774.43000000","10.52810000"],["1774.36000000","16.57250000"],["1774.33000000","0.73110000"],["1774.00000000","5.65280000"],["1773.92000000","0.21760000"],["1773.81000000","3.35130000"],["1773.80000000","8.32450000"],["1773.78000000","0.05640000"],["1773.42000000","0.43700000"],["1773.38000000","0.13250000"],["1773.36000000","7.89220000"],["1773.29000000","0.00000000"],["1773.21000000","0.00000000"],["1773.12000000","15.76960000"],["1773.06000000","0.21000000"],["1772.94000000","0.00000000"],["1772.83000000","0.01570000"],["1772.72000000","0.00460000"],["1772.71000000","20.08690000"],["1772.29000000","0.00000000"],["1771.71000000","0.13710000"],["1770.52000000","0.00290000"],["1770.36000000","0.00290000"],["1770.28000000","0.00290000"],["1770.20000000","0.00000000"],["1768.65000000","0.00900000"],["1764.66000000","0.00000000"],["1597.76000000","0.02800000"]],"a":[["1775.29000000","34.08160000"],["1775.34000000","0.00000000"],["1775.35000000","0.00600000"],["1775.36000000","7.64010000"],["1775.44000000","0.03290000"],["1775.45000000","0.28180000"],["1775.47000000","6.76490000"],["1775.48000000","0.00290000"],["1775.50000000","6.54380000"],["1775.51000000","0.43700000"],["1775.52000000","17.54540000"],["1775.53000000","0.00580000"],["1775.54000000","15.80400000"],["1775.55000000","57.70700000"],["1775.56000000","2.71590000"],["1775.57000000","1.33200000"],["1775.58000000","0.00290000"],["1775.61000000","5.03740000"],["1775.62000000","3.37200000"],["1775.65000000","0.00870000"],["1775.67000000","0.01130000"],["1775.71000000","0.28150000"],["1775.74000000","15.01870000"],["1775.76000000","0.03580000"],["1775.89000000","0.00580000"],["1775.91000000","1.79470000"],["1775.92000000","8.32530000"],["1776.03000000","0.00600000"],["1776.08000000","16.62710000"],["1776.09000000","0.00000000"],["1776.17000000","3.04360000"],["1776.33000000","20.56590000"],["1776.42000000","7.17290000"],["1776.43000000","8.32470000"],["1776.45000000","1.13400000"],["1776.55000000","18.35860000"],["1776.97000000","0.00000000"],["1777.21000000","7.88190000"],["1777.30000000","88.80930000"],["1777.51000000","1.64640000"],["1777.64000000","4.42390000"],["1777.80000000","52.84280000"],["1777.86000000","141.74300000"],["1778.26000000","0.00000000"],["1778.27000000","0.00290000"],["1778.37000000","0.00000000"],["1778.40000000","0.16940000"],["1778.54000000","8.18750000"],["1778.56000000","0.00000000"],["1778.57000000","26.51100000"],["1778.63000000","0.00580000"],["1778.87000000","42.30000000"],["1778.88000000","0.02530000"],["1779.02000000","0.00000000"],["1779.34000000","0.00000000"],["1780.22000000","0.00320000"],["1780.30000000","0.06140000"],["1780.32000000","0.00000000"],["1780.38000000","0.00740000"],["1781.53000000","0.00000000"],["1785.15000000","0.00000000"]]}}
{"stream":"btcusdt@trade","data":{"e":"trade","E":1783465200316,"s":"BTCUSDT","t":6486989459,"p":"63551.02000000","q":"0.00013000","T":1783465200315,"m":true,"M":true}}
{"stream":"btcusdt@trade","data":{"e":"trade","E":1783465200316,"s":"BTCUSDT","t":6486989460,"p":"63551.02000000","q":"0.00008000","T":1783465200315,"m":true,"M":true}}
{"stream":"btcusdt@trade","data":{"e":"trade","E":1783465200316,"s":"BTCUSDT","t":6486989461,"p":"63551.02000000","q":"0.00009000","T":1783465200315,"m":true,"M":true}}
{"stream":"btcusdt@trade","data":{"e":"trade","E":1783465200316,"s":"BTCUSDT","t":6486989462,"p":"63551.02000000","q":"0.00009000","T":1783465200315,"m":true,"M":true}}
{"stream":"btcusdt@trade","data":{"e":"trade","E":1783465200316,"s":"BTCUSDT","t":6486989463,"p":"63551.02000000","q":"0.00016000","T":1783465200315,"m":true,"M":true}}
{"stream":"btcusdt@trade","data":{"e":"trade","E":1783465200316,"s":"BTCUSDT","t":6486989464,"p":"63551.02000000","q":"0.00009000","T":1783465200315,"m":true,"M":true}}
{"stream":"btcusdt@trade","data":{"e":"trade","E":1783465200316,"s":"BTCUSDT","t":6486989465,"p":"63551.02000000","q":"0.00009000","T":1783465200315,"m":true,"M":true}}
{"stream":"btcusdt@trade","data":{"e":"trade","E":1783465200316,"s":"BTCUSDT","t":6486989466,"p":"63551.02000000","q":"0.00009000","T":1783465200315,"m":true,"M":true}}
{"stream":"btcusdt@trade","data":{"e":"trade","E":1783465200316,"s":"BTCUSDT","t":6486989467,"p":"63551.02000000","q":"0.00009000","T":1783465200315,"m":true,"M":true}}
{"stream":"btcusdt@trade","data":{"e":"trade","E":1783465200316,"s":"BTCUSDT","t":6486989468,"p":"63551.02000000","q":"0.00009000","T":1783465200315,"m":true,"M":true}}
{"stream":"btcusdt@trade","data":{"e":"trade","E":1783465200316,"s":"BTCUSDT","t":6486989469,"p":"63551.02000000","q":"0.00009000","T":1783465200315,"m":true,"M":true}}
{"stream":"btcusdt@trade","data":{"e":"trade","E":1783465200316,"s":"BTCUSDT","t":6486989470,"p":"63551.02000000","q":"0.00008000","T":1783465200315,"m":true,"M":true}}
{"stream":"btcusdt@trade","data":{"e":"trade","E":1783465200316,"s":"BTCUSDT","t":6486989471,"p":"63551.02000000","q":"0.00009000","T":1783465200315,"m":true,"M":true}}
{"stream":"btcusdt@trade","data":{"e":"trade","E":1783465200316,"s":"BTCUSDT","t":6486989472,"p":"63551.02000000","q":"0.00009000","T":1783465200315,"m":true,"M":true}}
{"stream":"btcusdt@trade","data":{"e":"trade","E":1783465200316,"s":"BTCUSDT","t":6486989473,"p":"63551.02000000","q":"0.00009000","T":1783465200315,"m":true,"M":true}}
{"stream":"btcusdt@trade","data":{"e":"trade","E":1783465200316,"s":"BTCUSDT","t":6486989474,"p":"63551.02000000","q":"0.00009000","T":1783465200315,"m":true,"M":true}}
{"stream":"btcusdt@trade","data":{"e":"trade","E":1783465200316,"s":"BTCUSDT","t":6486989475,"p":"63551.02000000","q":"0.00009000","T":1783465200315,"m":true,"M":true}}
{"stream":"btcusdt@trade","data":{"e":"trade","E":1783465200316,"s":"BTCUSDT","t":6486989476,"p":"63551.02000000","q":"0.00008000","T":1783465200315,"m":true,"M":true}}
{"stream":"btcusdt@trade","data":{"e":"trade","E":1783465200316,"s":"BTCUSDT","t":6486989477,"p":"63551.02000000","q":"0.00271000","T":1783465200315,"m":true,"M":true}}
{"stream":"btcusdt@trade","data":{"e":"trade","E":1783465200316,"s":"BTCUSDT","t":6486989478,"p":"63551.02000000","q":"0.00008000","T":1783465200315,"m":true,"M":true}}
{"stream":"btcusdt@trade","data":{"e":"trade","E":1783465200316,"s":"BTCUSDT","t":6486989479,"p":"63551.02000000","q":"0.00009000","T":1783465200315,"m":true,"M":true}}
{"stream":"btcusdt@trade","data":{"e":"trade","E":1783465200316,"s":"BTCUSDT","t":6486989480,"p":"63551.02000000","q":"0.00008000","T":1783465200315,"m":true,"M":true}}
{"stream":"btcusdt@trade","data":{"e":"trade","E":1783465200316,"s":"BTCUSDT","t":6486989481,"p":"63551.02000000","q":"0.00271000","T":1783465200315,"m":true,"M":true}}
{"stream":"btcusdt@trade","data":{"e":"trade","E":1783465200316,"s":"BTCUSDT","t":6486989482,"p":"63551.02000000","q":"0.00008000","T":1783465200315,"m":true,"M":true}}
{"stream":"btcusdt@trade","data":{"e":"trade","E":1783465200316,"s":"BTCUSDT","t":6486989483,"p":"63551.02000000","q":"0.00271000","T":1783465200315,"m":true,"M":true}}
{"stream":"btcusdt@trade","data":{"e":"trade","E":1783465200316,"s":"BTCUSDT","t":6486989484,"p":"63551.02000000","q":"0.00008000","T":1783465200315,"m":true,"M":true}}
{"stream":"btcusdt@trade","data":{"e":"trade","E":1783465200316,"s":"BTCUSDT","t":6486989485,"p":"63551.02000000","q":"0.00271000","T":1783465200315,"m":true,"M":true}}
{"stream":"btcusdt@trade","data":{"e":"trade","E":1783465200316,"s":"BTCUSDT","t":6486989486,"p":"63551.02000000","q":"0.00008000","T":1783465200315,"m":true,"M":true}}
{"stream":"btcusdt@trade","data":{"e":"trade","E":1783465200316,"s":"BTCUSDT","t":6486989487,"p":"63551.02000000","q":"0.00271000","T":1783465200315,"m":true,"M":true}}
{"stream":"btcusdt@trade","data":{"e":"trade","E":1783465200316,"s":"BTCUSDT","t":6486989488,"p":"63551.02000000","q":"0.00008000","T":1783465200315,"m":true,"M":true}}
{"stream":"btcusdt@trade","data":{"e":"trade","E":1783465200316,"s":"BTCUSDT","t":6486989489,"p":"63551.02000000","q":"0.00271000","T":1783465200315,"m":true,"M":true}}
{"stream":"btcusdt@trade","data":{"e":"trade","E":1783465200316,"s":"BTCUSDT","t":6486989490,"p":"63551.02000000","q":"0.00008000","T":1783465200315,"m":true,"M":true}}
{"stream":"btcusdt@trade","data":{"e":"trade","E":1783465200316,"s":"BTCUSDT","t":6486989491,"p":"63551.02000000","q":"0.00271000","T":1783465200315,"m":true,"M":true}}
{"stream":"btcusdt@trade","data":{"e":"trade","E":1783465200316,"s":"BTCUSDT","t":6486989492,"p":"63551.02000000","q":"0.00008000","T":1783465200315,"m":true,"M":true}}
{"stream":"btcusdt@trade","data":{"e":"trade","E":1783465200316,"s":"BTCUSDT","t":6486989493,"p":"63551.02000000","q":"0.00271000","T":1783465200315,"m":true,"M":true}}
{"stream":"btcusdt@trade","data":{"e":"trade","E":1783465200316,"s":"BTCUSDT","t":6486989494,"p":"63551.02000000","q":"0.00006000","T":1783465200315,"m":true,"M":true}}
{"stream":"btcusdt@trade","data":{"e":"trade","E":1783465200316,"s":"BTCUSDT","t":6486989495,"p":"63551.02000000","q":"0.00271000","T":1783465200315,"m":true,"M":true}}
{"stream":"btcusdt@trade","data":{"e":"trade","E":1783465200316,"s":"BTCUSDT","t":6486989496,"p":"63551.02000000","q":"0.00271000","T":1783465200315,"m":true,"M":true}}
{"stream":"btcusdt@trade","data":{"e":"trade","E":1783465200316,"s":"BTCUSDT","t":6486989497,"p":"63551.02000000","q":"0.00271000","T":1783465200315,"m":true,"M":true}}
{"stream":"btcusdt@trade","data":{"e":"trade","E":1783465200316,"s":"BTCUSDT","t":6486989498,"p":"63551.02000000","q":"0.00271000","T":1783465200315,"m":true,"M":true}}
{"stream":"btcusdt@trade","data":{"e":"trade","E":1783465200316,"s":"BTCUSDT","t":6486989499,"p":"63551.02000000","q":"0.00271000","T":1783465200315,"m":true,"M":true}}
{"stream":"btcusdt@trade","data":{"e":"trade","E":1783465200316,"s":"BTCUSDT","t":6486989500,"p":"63551.02000000","q":"0.00271000","T":1783465200315,"m":true,"M":true}}
{"stream":"btcusdt@trade","data":{"e":"trade","E":1783465200316,"s":"BTCUSDT","t":6486989501,"p":"63551.02000000","q":"0.00271000","T":1783465200315,"m":true,"M":true}}
{"stream":"btcusdt@trade","data":{"e":"trade","E":1783465200316,"s":"BTCUSDT","t":6486989502,"p":"63551.02000000","q":"0.00271000","T":1783465200315,"m":true,"M":true}}
{"stream":"btcusdt@trade","data":{"e":"trade","E":1783465200316,"s":"BTCUSDT","t":6486989503,"p":"63551.02000000","q":"0.00271000","T":1783465200315,"m":true,"M":true}}
{"stream":"btcusdt@trade","data":{"e":"trade","E":1783465200316,"s":"BTCUSDT","t":6486989504,"p":"63551.02000000","q":"0.00271000","T":1783465200315,"m":true,"M":true}}
{"stream":"btcusdt@trade","data":{"e":"trade","E":1783465200316,"s":"BTCUSDT","t":6486989505,"p":"63551.02000000","q":"0.00271000","T":1783465200315,"m":true,"M":true}}
{"stream":"btcusdt@trade","data":{"e":"trade","E":1783465200316,"s":"BTCUSDT","t":6486989506,"p":"63551.02000000","q":"0.00271000","T":1783465200315,"m":true,"M":true}}
{"stream":"btcusdt@trade","data":{"e":"trade","E":1783465200316,"s":"BTCUSDT","t":6486989507,"p":"63551.02000000","q":"0.00271000","T":1783465200315,"m":true,"M":true}}
{"stream":"btcusdt@trade","data":{"e":"trade","E":1783465200316,"s":"BTCUSDT","t":6486989508,"p":"63551.02000000","q":"0.00271000","T":1783465200315,"m":true,"M":true}}
{"stream":"btcusdt@trade","data":{"e":"trade","E":1783465200316,"s":"BTCUSDT","t":6486989509,"p":"63551.02000000","q":"0.00271000","T":1783465200315,"m":true,"M":true}}
{"stream":"btcusdt@trade","data":{"e":"trade","E":1783465200316,"s":"BTCUSDT","t":6486989510,"p":"63551.02000000","q":"0.00271000","T":1783465200315,"m":true,"M":true}}
{"stream":"btcusdt@trade","data":{"e":"trade","E":1783465200316,"s":"BTCUSDT","t":6486989511,"p":"63551.02000000","q":"0.00271000","T":1783465200315,"m":true,"M":true}}
{"stream":"btcusdt@trade","data":{"e":"trade","E":1783465200316,"s":"BTCUSDT","t":6486989512,"p":"63551.02000000","q":"0.00271000","T":1783465200315,"m":true,"M":true}}
{"stream":"btcusdt@trade","data":{"e":"trade","E":1783465200316,"s":"BTCUSDT","t":6486989513,"p":"63551.02000000","q":"0.00271000","T":1783465200315,"m":true,"M":true}}
{"stream":"btcusdt@trade","data":{"e":"trade","E":1783465200316,"s":"BTCUSDT","t":6486989514,"p":"63551.02000000","q":"0.00271000","T":1783465200315,"m":true,"M":true}}
{"stream":"btcusdt@trade","data":{"e":"trade","E":1783465200316,"s":"BTCUSDT","t":6486989515,"p":"63551.02000000","q":"0.00271000","T":1783465200315,"m":true,"M":true}}
{"stream":"btcusdt@trade","data":{"e":"trade","E":1783465200316,"s":"BTCUSDT","t":6486989516,"p":"63551.02000000","q":"0.00271000","T":1783465200315,"m":true,"M":true}}
{"stream":"btcusdt@trade","data":{"e":"trade","E":1783465200316,"s":"BTCUSDT","t":6486989517,"p":"63551.02000000","q":"0.00271000","T":1783465200315,"m":true,"M":true}}
{"stream":"btcusdt@trade","data":{"e":"trade","E":1783465200316,"s":"BTCUSDT","t":6486989518,"p":"63551.02000000","q":"0.00271000","T":1783465200315,"m":true,"M":true}}
{"stream":"btcusdt@trade","data":{"e":"trade","E":1783465200316,"s":"BTCUSDT","t":6486989519,"p":"63551.02000000","q":"0.00271000","T":1783465200315,"m":true,"M":true}}
{"stream":"btcusdt@trade","data":{"e":"trade","E":1783465200316,"s":"BTCUSDT","t":6486989520,"p":"63551.02000000","q":"0.00271000","T":1783465200315,"m":true,"M":true}}
{"stream":"btcusdt@trade","data":{"e":"trade","E":1783465200316,"s":"BTCUSDT","t":6486989521,"p":"63551.02000000","q":"0.00271000","T":1783465200315,"m":true,"M":true}}
{"stream":"btcusdt@trade","data":{"e":"trade","E":1783465200316,"s":"BTCUSDT","t":6486989522,"p":"63551.02000000","q":"0.00271000","T":1783465200315,"m":true,"M":true}}
{"stream":"btcusdt@trade","data":{"e":"trade","E":1783465200316,"s":"BTCUSDT","t":6486989523,"p":"63551.02000000","q":"0.00271000","T":1783465200315,"m":true,"M":true}}
{"stream":"btcusdt@trade","data":{"e":"trade","E":1783465200316,"s":"BTCUSDT","t":6486989524,"p":"63551.02000000","q":"0.00271000","T":1783465200315,"m":true,"M":true}}
{"stream":"btcusdt@trade","data":{"e":"trade","E":1783465200316,"s":"BTCUSDT","t":6486989525,"p":"63551.02000000","q":"0.00271000","T":1783465200315,"m":true,"M":true}}
{"stream":"btcusdt@trade","data":{"e":"trade","E":1783465200316,"s":"BTCUSDT","t":6486989526,"p":"63551.02000000","q":"0.00271000","T":1783465200315,"m":true,"M":true}}
{"stream":"btcusdt@trade","data":{"e":"trade","E":1783465200316,"s":"BTCUSDT","t":6486989527,"p":"63551.02000000","q":"0.00271000","T":1783465200315,"m":true,"M":true}}
{"stream":"btcusdt@trade","data":{"e":"trade","E":1783465200316,"s":"BTCUSDT","t":6486989528,"p":"63551.02000000","q":"0.00271000","T":1783465200315,"m":true,"M":true}}
{"stream":"btcusdt@trade","data":{"e":"trade","E":1783465200316,"s":"BTCUSDT","t":6486989529,"p":"63551.02000000","q":"0.00271000","T":1783465200315,"m":true,"M":true}}
{"stream":"btcusdt@trade","data":{"e":"trade","E":1783465200316,"s":"BTCUSDT","t":6486989530,"p":"63551.02000000","q":"0.00271000","T":1783465200315,"m":true,"M":true}}
{"stream":"btcusdt@trade","data":{"e":"trade","E":1783465200316,"s":"BTCUSDT","t":6486989531,"p":"63551.02000000","q":"0.00271000","T":1783465200315,"m":true,"M":true}}
{"stream":"btcusdt@trade","data":{"e":"trade","E":1783465200316,"s":"BTCUSDT","t":6486989532,"p":"63551.02000000","q":"0.00271000","T":1783465200315,"m":true,"M":true}}
{"stream":"btcusdt@trade","data":{"e":"trade","E":1783465200316,"s":"BTCUSDT","t":6486989533,"p":"63551.02000000","q":"0.00271000","T":1783465200315,"m":true,"M":true}}
{"stream":"btcusdt@trade","data":{"e":"trade","E":1783465200316,"s":"BTCUSDT","t":6486989534,"p":"63551.02000000","q":"0.00271000","T":1783465200315,"m":true,"M":true}}
{"stream":"btcusdt@trade","data":{"e":"trade","E":1783465200316,"s":"BTCUSDT","t":6486989535,"p":"63551.02000000","q":"0.00271000","T":1783465200315,"m":true,"M":true}}
{"stream":"btcusdt@trade","data":{"e":"trade","E":1783465200316,"s":"BTCUSDT","t":6486989536,"p":"63551.02000000","q":"0.00271000","T":1783465200315,"m":true,"M":true}}
{"stream":"btcusdt@trade","data":{"e":"trade","E":1783465200316,"s":"BTCUSDT","t":6486989537,"p":"63551.02000000","q":"0.00271000","T":1783465200315,"m":true,"M":true}}
{"stream":"btcusdt@trade","data":{"e":"trade","E":1783465200316,"s":"BTCUSDT","t":6486989538,"p":"63551.02000000","q":"0.00271000","T":1783465200315,"m":true,"M":true}}
{"stream":"btcusdt@trade","data":{"e":"trade","E":1783465200316,"s":"BTCUSDT","t":6486989539,"p":"63551.02000000","q":"0.00271000","T":1783465200315,"m":true,"M":true}}
{"stream":"btcusdt@trade","data":{"e":"trade","E":1783465200316,"s":"BTCUSDT","t":6486989540,"p":"63551.02000000","q":"0.00271000","T":1783465200315,"m":true,"M":true}}
{"stream":"btcusdt@trade","data":{"e":"trade","E":1783465200316,"s":"BTCUSDT","t":6486989541,"p":"63551.02000000","q":"0.00271000","T":1783465200315,"m":true,"M":true}}
{"stream":"btcusdt@trade","data":{"e":"trade","E":1783465200316,"s":"BTCUSDT","t":6486989542,"p":"63551.02000000","q":"0.00271000","T":1783465200315,"m":true,"M":true}}
{"stream":"btcusdt@trade","data":{"e":"trade","E":1783465200316,"s":"BTCUSDT","t":6486989543,"p":"63551.02000000","q":"0.00271000","T":1783465200315,"m":true,"M":true}}
{"stream":"btcusdt@trade","data":{"e":"trade","E":1783465200316,"s":"BTCUSDT","t":6486989544,"p":"63551.02000000","q":"0.00271000","T":1783465200315,"m":true,"M":true}}
{"stream":"btcusdt@trade","data":{"e":"trade","E":1783465200316,"s":"BTCUSDT","t":6486989545,"p":"63551.02000000","q":"0.00271000","T":1783465200315,"m":true,"M":true}}
{"stream":"btcusdt@trade","data":{"e":"trade","E":1783465200316,"s":"BTCUSDT","t":6486989546,"p":"63551.02000000","q":"0.00271000","T":1783465200315,"m":true,"M":true}}
{"stream":"btcusdt@trade","data":{"e":"trade","E":1783465200316,"s":"BTCUSDT","t":6486989547,"p":"63551.02000000","q":"0.00271000","T":1783465200315,"m":true,"M":true}}
{"stream":"btcusdt@trade","data":{"e":"trade","E":1783465200316,"s":"BTCUSDT","t":6486989548,"p":"63551.02000000","q":"0.00271000","T":1783465200315,"m":true,"M":true}}
{"stream":"btcusdt@trade","data":{"e":"trade","E":1783465200316,"s":"BTCUSDT","t":6486989549,"p":"63551.02000000","q":"0.00271000","T":1783465200315,"m":true,"M":true}}
{"stream":"btcusdt@trade","data":{"e":"trade","E":1783465200316,"s":"BTCUSDT","t":6486989550,"p":"63551.02000000","q":"0.00271000","T":1783465200315,"m":true,"M":true}}
{"stream":"btcusdt@trade","data":{"e":"trade","E":1783465200316,"s":"BTCUSDT","t":6486989551,"p":"63551.02000000","q":"0.00271000","T":1783465200315,"m":true,"M":true}}
{"stream":"btcusdt@trade","data":{"e":"trade","E":1783465200316,"s":"BTCUSDT","t":6486989552,"p":"63551.02000000","q":"0.00271000","T":1783465200315,"m":true,"M":true}}
{"stream":"btcusdt@trade","data":{"e":"trade","E":1783465200316,"s":"BTCUSDT","t":6486989553,"p":"63551.02000000","q":"0.00271000","T":1783465200315,"m":true,"M":true}}
{"stream":"btcusdt@trade","data":{"e":"trade","E":1783465200316,"s":"BTCUSDT","t":6486989554,"p":"63551.02000000","q":"0.00255000","T":1783465200315,"m":true,"M":true}}
{"stream":"btcusdt@trade","data":{"e":"trade","E":1783465200316,"s":"BTCUSDT","t":6486989555,"p":"63551.01000000","q":"0.00009000","T":1783465200315,"m":true,"M":true}}
{"stream":"btcusdt@trade","data":{"e":"trade","E":1783465200316,"s":"BTCUSDT","t":6486989556,"p":"63551.01000000","q":"0.00009000","T":1783465200315,"m":true,"M":true}}
{"stream":"btcusdt@trade","data":{"e":"trade","E":1783465200316,"s":"BTCUSDT","t":6486989557,"p":"63551.01000000","q":"0.00016000","T":1783465200315,"m":true,"M":true}}
{"stream":"btcusdt@trade","data":{"e":"trade","E":1783465200316,"s":"BTCUSDT","t":6486989558,"p":"63551.01000000","q":"0.00009000","T":1783465200315,"m":true,"M":true}}
{"stream":"btcusdt@trade","data":{"e":"trade","E":1783465200316,"s":"BTCUSDT","t":6486989559,"p":"63551.01000000","q":"0.00009000","T":1783465200315,"m":true,"M":true}}
{"stream":"btcusdt@trade","data":{"e":"trade","E":1783465200316,"s":"BTCUSDT","t":6486989560,"p":"63551.01000000","q":"0.00009000","T":1783465200315,"m":true,"M":true}}
{"stream":"btcusdt@trade","data":{"e":"trade","E":1783465200316,"s":"BTCUSDT","t":6486989561,"p":"63551.01000000","q":"0.00009000","T":1783465200315,"m":true,"M":true}}
{"stream":"btcusdt@trade","data":{"e":"trade","E":1783465200316,"s":"BTCUSDT","t":6486989562,"p":"63551.01000000","q":"0.00009000","T":1783465200315,"m":true,"M":true}}
{"stream":"btcusdt@trade","data":{"e":"trade","E":1783465200316,"s":"BTCUSDT","t":6486989563,"p":"63551.01000000","q":"0.00216000","T":1783465200315,"m":true,"M":true}}
{"stream":"btcusdt@trade","data":{"e":"trade","E":1783465200316,"s":"BTCUSDT","t":6486989564,"p":"63551.01000000","q":"0.00271000","T":1783465200315,"m":true,"M":true}}
{"stream":"btcusdt@trade","data":{"e":"trade","E":1783465200316,"s":"BTCUSDT","t":6486989565,"p":"63551.01000000","q":"0.00271000","T":1783465200315,"m":true,"M":true}}
{"stream":"btcusdt@trade","data":{"e":"trade","E":1783465200316,"s":"BTCUSDT","t":6486989566,"p":"63551.01000000","q":"0.00271000","T":1783465200315,"m":true,"M":true}}
{"stream":"btcusdt@trade","data":{"e":"trade","E":1783465200316,"s":"BTCUSDT","t":6486989567,"p":"63551.01000000","q":"0.00271000","T":1783465200315,"m":true,"M":true}}
{"stream":"btcusdt@trade","data":{"e":"trade","E":1783465200316,"s":"BTCUSDT","t":6486989568,"p":"63551.01000000","q":"0.00009000","T":1783465200315,"m":true,"M":true}}
{"stream":"btcusdt@trade","data":{"e":"trade","E":1783465200316,"s":"BTCUSDT","t":6486989569,"p":"63551.01000000","q":"0.00009000","T":1783465200315,"m":true,"M":true}}
{"stream":"btcusdt@trade","data":{"e":"trade","E":1783465200316,"s":"BTCUSDT","t":6486989570,"p":"63551.01000000","q":"0.00009000","T":1783465200315,"m":true,"M":true}}
{"stream":"btcusdt@trade","data":{"e":"trade","E":1783465200316,"s":"BTCUSDT","t":6486989571,"p":"63551.01000000","q":"0.00008000","T":1783465200315,"m":true,"M":true}}
{"stream":"btcusdt@trade","data":{"e":"trade","E":1783465200316,"s":"BTCUSDT","t":6486989572,"p":"63551.01000000","q":"0.00271000","T":1783465200315,"m":true,"M":true}}
{"stream":"btcusdt@trade","data":{"e":"trade","E":1783465200316,"s":"BTCUSDT","t":6486989573,"p":"63551.01000000","q":"0.00271000","T":1783465200315,"m":true,"M":true}}
{"stream":"btcusdt@trade","data":{"e":"trade","E":1783465200316,"s":"BTCUSDT","t":6486989574,"p":"63551.01000000","q":"0.00271000","T":1783465200315,"m":true,"M":true}}
{"stream":"btcusdt@trade","data":{"e":"trade","E":1783465200316,"s":"BTCUSDT","t":6486989575,"p":"63551.01000000","q":"0.00271000","T":1783465200315,"m":true,"M":true}}
{"stream":"btcusdt@trade","data":{"e":"trade","E":1783465200316,"s":"BTCUSDT","t":6486989576,"p":"63551.01000000","q":"0.00008000","T":1783465200315,"m":true,"M":true}}
{"stream":"btcusdt@trade","data":{"e":"trade","E":1783465200316,"s":"BTCUSDT","t":6486989577,"p":"63551.01000000","q":"0.00271000","T":1783465200315,"m":true,"M":true}}
{"stream":"btcusdt@trade","data":{"e":"trade","E":1783465200316,"s":"BTCUSDT","t":6486989578,"p":"63551.01000000","q":"0.00271000","T":1783465200315,"m":true,"M":true}}
{"stream":"btcusdt@trade","data":{"e":"trade","E":1783465200316,"s":"BTCUSDT","t":6486989579,"p":"63551.01000000","q":"0.00271000","T":1783465200315,"m":true,"M":true}}
{"stream":"btcusdt@trade","data":{"e":"trade","E":1783465200316,"s":"BTCUSDT","t":6486989580,"p":"63551.01000000","q":"0.00271000","T":1783465200315,"m":true,"M":true}}
{"stream":"btcusdt@trade","data":{"e":"trade","E":1783465200316,"s":"BTCUSDT","t":6486989581,"p":"63551.01000000","q":"0.00271000","T":1783465200315,"m":true,"M":true}}
{"stream":"btcusdt@trade","data":{"e":"trade","E":1783465200316,"s":"BTCUSDT","t":6486989582,"p":"63551.01000000","q":"0.00271000","T":1783465200315,"m":true,"M":true}}
{"stream":"btcusdt@trade","data":{"e":"trade","E":1783465200316,"s":"BTCUSDT","t":6486989583,"p":"63551.01000000","q":"0.00271000","T":1783465200315,"m":true,"M":true}}
{"stream":"btcusdt@trade","data":{"e":"trade","E":1783465200316,"s":"BTCUSDT","t":6486989584,"p":"63551.01000000","q":"0.00271000","T":1783465200315,"m":true,"M":true}}
{"stream":"btcusdt@trade","data":{"e":"trade","E":1783465200316,"s":"BTCUSDT","t":6486989585,"p":"63551.01000000","q":"0.00271000","T":1783465200315,"m":true,"M":true}}
{"stream":"btcusdt@trade","data":{"e":"trade","E":1783465200316,"s":"BTCUSDT","t":6486989586,"p":"63551.01000000","q":"0.00271000","T":1783465200315,"m":true,"M":true}}
{"stream":"btcusdt@trade","data":{"e":"trade","E":1783465200316,"s":"BTCUSDT","t":6486989587,"p":"63551.01000000","q":"0.00271000","T":1783465200315,"m":true,"M":true}}
{"stream":"btcusdt@trade","data":{"e":"trade","E":1783465200316,"s":"BTCUSDT","t":6486989588,"p":"63551.01000000","q":"0.00271000","T":1783465200315,"m":true,"M":true}}
{"stream":"btcusdt@trade","data":{"e":"trade","E":1783465200316,"s":"BTCUSDT","t":6486989589,"p":"63551.01000000","q":"0.00271000","T":1783465200315,"m":true,"M":true}}
{"stream":"btcusdt@trade","data":{"e":"trade","E":1783465200316,"s":"BTCUSDT","t":6486989590,"p":"63551.01000000","q":"0.00271000","T":1783465200315,"m":true,"M":true}}
{"stream":"btcusdt@trade","data":{"e":"trade","E":1783465200316,"s":"BTCUSDT","t":6486989591,"p":"63551.01000000","q":"0.00271000","T":1783465200315,"m":true,"M":true}}
{"stream":"btcusdt@trade","data":{"e":"trade","E":1783465200316,"s":"BTCUSDT","t":6486989592,"p":"63551.01000000","q":"0.00271000","T":1783465200315,"m":true,"M":true}}
{"stream":"btcusdt@trade","data":{"e":"trade","E":1783465200316,"s":"BTCUSDT","t":6486989593,"p":"63551.01000000","q":"0.00271000","T":1783465200315,"m":true,"M":true}}
{"stream":"btcusdt@trade","data":{"e":"trade","E":1783465200316,"s":"BTCUSDT","t":6486989594,"p":"63551.01000000","q":"0.00271000","T":1783465200315,"m":true,"M":true}}
{"stream":"btcusdt@trade","data":{"e":"trade","E":1783465200316,"s":"BTCUSDT","t":6486989595,"p":"63551.01000000","q":"0.00271000","T":1783465200315,"m":true,"M":true}}
{"stream":"btcusdt@trade","data":{"e":"trade","E":1783465200316,"s":"BTCUSDT","t":6486989596,"p":"63551.01000000","q":"0.00271000","T":1783465200315,"m":true,"M":true}}
{"stream":"btcusdt@trade","data":{"e":"trade","E":1783465200316,"s":"BTCUSDT","t":6486989597,"p":"63551.01000000","q":"0.00271000","T":1783465200315,"m":true,"M":true}}
{"stream":"btcusdt@trade","data":{"e":"trade","E":1783465200316,"s":"BTCUSDT","t":6486989598,"p":"63551.01000000","q":"0.00271000","T":1783465200315,"m":true,"M":true}}
{"stream":"btcusdt@trade","data":{"e":"trade","E":1783465200316,"s":"BTCUSDT","t":6486989599,"p":"63551.01000000","q":"0.00271000","T":1783465200315,"m":true,"M":true}}
{"stream":"btcusdt@trade","data":{"e":"trade","E":1783465200316,"s":"BTCUSDT","t":6486989600,"p":"63551.01000000","q":"0.00271000","T":1783465200315,"m":true,"M":true}}
{"stream":"btcusdt@trade","data":{"e":"trade","E":1783465200316,"s":"BTCUSDT","t":6486989601,"p":"63551.01000000","q":"0.00271000","T":1783465200315,"m":true,"M":true}}
{"stream":"btcusdt@trade","data":{"e":"trade","E":1783465200316,"s":"BTCUSDT","t":6486989602,"p":"63551.01000000","q":"0.00271000","T":1783465200315,"m":true,"M":true}}
{"stream":"btcusdt@trade","data":{"e":"trade","E":1783465200316,"s":"BTCUSDT","t":6486989603,"p":"63551.01000000","q":"0.00271000","T":1783465200315,"m":true,"M":true}}
{"stream":"btcusdt@trade","data":{"e":"trade","E":1783465200316,"s":"BTCUSDT","t":6486989604,"p":"63551.01000000","q":"0.00271000","T":1783465200315,"m":true,"M":true}}
{"stream":"btcusdt@trade","data":{"e":"trade","E":1783465200316,"s":"BTCUSDT","t":6486989605,"p":"63551.01000000","q":"0.00271000","T":1783465200315,"m":true,"M":true}}
{"stream":"btcusdt@trade","data":{"e":"trade","E":1783465200316,"s":"BTCUSDT","t":6486989606,"p":"63551.01000000","q":"0.00271000","T":1783465200315,"m":true,"M":true}}
{"stream":"btcusdt@trade","data":{"e":"trade","E":1783465200316,"s":"BTCUSDT","t":6486989607,"p":"63551.01000000","q":"0.00271000","T":1783465200315,"m":true,"M":true}}
{"stream":"btcusdt@trade","data":{"e":"trade","E":1783465200316,"s":"BTCUSDT","t":6486989608,"p":"63551.01000000","q":"0.00271000","T":1783465200315,"m":true,"M":true}}
{"stream":"btcusdt@trade","data":{"e":"trade","E":1783465200316,"s":"BTCUSDT","t":6486989609,"p":"63551.01000000","q":"0.00271000","T":1783465200315,"m":true,"M":true}}
{"stream":"btcusdt@trade","data":{"e":"trade","E":1783465200316,"s":"BTCUSDT","t":6486989610,"p":"63551.01000000","q":"0.00271000","T":1783465200315,"m":true,"M":true}}
{"stream":"btcusdt@trade","data":{"e":"trade","E":1783465200316,"s":"BTCUSDT","t":6486989611,"p":"63551.01000000","q":"0.00271000","T":1783465200315,"m":true,"M":true}}
{"stream":"btcusdt@trade","data":{"e":"trade","E":1783465200316,"s":"BTCUSDT","t":6486989612,"p":"63551.01000000","q":"0.00271000","T":1783465200315,"m":true,"M":true}}
{"stream":"btcusdt@trade","data":{"e":"trade","E":1783465200316,"s":"BTCUSDT","t":6486989613,"p":"63551.01000000","q":"0.00271000","T":1783465200315,"m":true,"M":true}}
{"stream":"btcusdt@trade","data":{"e":"trade","E":1783465200316,"s":"BTCUSDT","t":6486989614,"p":"63551.01000000","q":"0.00271000","T":1783465200315,"m":true,"M":true}}
{"stream":"btcusdt@trade","data":{"e":"trade","E":1783465200316,"s":"BTCUSDT","t":6486989615,"p":"63551.01000000","q":"0.00271000","T":1783465200315,"m":true,"M":true}}
{"stream":"btcusdt@trade","data":{"e":"trade","E":1783465200316,"s":"BTCUSDT","t":6486989616,"p":"63551.01000000","q":"0.00271000","T":1783465200315,"m":true,"M":true}}
{"stream":"btcusdt@trade","data":{"e":"trade","E":1783465200316,"s":"BTCUSDT","t":6486989617,"p":"63551.01000000","q":"0.00271000","T":1783465200315,"m":true,"M":true}}
{"stream":"btcusdt@trade","data":{"e":"trade","E":1783465200316,"s":"BTCUSDT","t":6486989618,"p":"63551.01000000","q":"0.00271000","T":1783465200315,"m":true,"M":true}}
{"stream":"btcusdt@trade","data":{"e":"trade","E":1783465200316,"s":"BTCUSDT","t":6486989619,"p":"63551.01000000","q":"0.00271000","T":1783465200315,"m":true,"M":true}}
{"stream":"btcusdt@trade","data":{"e":"trade","E":1783465200316,"s":"BTCUSDT","t":6486989620,"p":"63551.01000000","q":"0.00271000","T":1783465200315,"m":true,"M":true}}
{"stream":"btcusdt@trade","data":{"e":"trade","E":1783465200316,"s":"BTCUSDT","t":6486989621,"p":"63551.01000000","q":"0.00271000","T":1783465200315,"m":true,"M":true}}
{"stream":"btcusdt@trade","data":{"e":"trade","E":1783465200316,"s":"BTCUSDT","t":6486989622,"p":"63551.01000000","q":"0.00271000","T":1783465200315,"m":true,"M":true}}
{"stream":"btcusdt@trade","data":{"e":"trade","E":1783465200316,"s":"BTCUSDT","t":6486989623,"p":"63551.01000000","q":"0.00271000","T":1783465200315,"m":true,"M":true}}
{"stream":"btcusdt@trade","data":{"e":"trade","E":1783465200316,"s":"BTCUSDT","t":6486989624,"p":"63551.01000000","q":"0.00271000","T":1783465200315,"m":true,"M":true}}
{"stream":"btcusdt@trade","data":{"e":"trade","E":1783465200316,"s":"BTCUSDT","t":6486989625,"p":"63551.01000000","q":"0.00271000","T":1783465200315,"m":true,"M":true}}
{"stream":"btcusdt@trade","data":{"e":"trade","E":1783465200316,"s":"BTCUSDT","t":6486989626,"p":"63551.01000000","q":"0.00271000","T":1783465200315,"m":true,"M":true}}
{"stream":"btcusdt@trade","data":{"e":"trade","E":1783465200316,"s":"BTCUSDT","t":6486989627,"p":"63551.01000000","q":"0.00271000","T":1783465200315,"m":true,"M":true}}
{"stream":"btcusdt@trade","data":{"e":"trade","E":1783465200316,"s":"BTCUSDT","t":6486989628,"p":"63551.01000000","q":"0.00271000","T":1783465200315,"m":true,"M":true}}
{"stream":"btcusdt@trade","data":{"e":"trade","E":1783465200316,"s":"BTCUSDT","t":6486989629,"p":"63551.01000000","q":"0.00271000","T":1783465200315,"m":true,"M":true}}
{"stream":"btcusdt@trade","data":{"e":"trade","E":1783465200316,"s":"BTCUSDT","t":6486989630,"p":"63551.01000000","q":"0.00271000","T":1783465200315,"m":true,"M":true}}
{"stream":"btcusdt@trade","data":{"e":"trade","E":1783465200316,"s":"BTCUSDT","t":6486989631,"p":"63551.01000000","q":"0.00271000","T":1783465200315,"m":true,"M":true}}
{"stream":"btcusdt@trade","data":{"e":"trade","E":1783465200316,"s":"BTCUSDT","t":6486989632,"p":"63551.01000000","q":"0.00271000","T":1783465200315,"m":true,"M":true}}
{"stream":"btcusdt@trade","data":{"e":"trade","E":1783465200316,"s":"BTCUSDT","t":6486989633,"p":"63551.01000000","q":"0.00271000","T":1783465200315,"m":true,"M":true}}
{"stream":"btcusdt@trade","data":{"e":"trade","E":1783465200316,"s":"BTCUSDT","t":6486989634,"p":"63551.01000000","q":"0.00271000","T":1783465200315,"m":true,"M":true}}
{"stream":"btcusdt@trade","data":{"e":"trade","E":1783465200316,"s":"BTCUSDT","t":6486989635,"p":"63551.01000000","q":"0.00271000","T":1783465200315,"m":true,"M":true}}
{"stream":"btcusdt@trade","data":{"e":"trade","E":1783465200316,"s":"BTCUSDT","t":6486989636,"p":"63551.01000000","q":"0.00271000","T":1783465200315,"m":true,"M":true}}
{"stream":"btcusdt@trade","data":{"e":"trade","E":1783465200316,"s":"BTCUSDT","t":6486989637,"p":"63551.01000000","q":"0.00271000","T":1783465200315,"m":true,"M":true}}
{"stream":"btcusdt@trade","data":{"e":"trade","E":1783465200316,"s":"BTCUSDT","t":6486989638,"p":"63551.01000000","q":"0.00271000","T":1783465200315,"m":true,"M":true}}
{"stream":"btcusdt@trade","data":{"e":"trade","E":1783465200316,"s":"BTCUSDT","t":6486989639,"p":"63551.01000000","q":"0.00271000","T":1783465200315,"m":true,"M":true}}
{"stream":"btcusdt@trade","data":{"e":"trade","E":1783465200316,"s":"BTCUSDT","t":6486989640,"p":"63551.01000000","q":"0.00271000","T":1783465200315,"m":true,"M":true}}
{"stream":"btcusdt@trade","data":{"e":"trade","E":1783465200316,"s":"BTCUSDT","t":6486989641,"p":"63551.01000000","q":"0.00271000","T":1783465200315,"m":true,"M":true}}
{"stream":"btcusdt@trade","data":{"e":"trade","E":1783465200316,"s":"BTCUSDT","t":6486989642,"p":"63551.01000000","q":"0.00271000","T":1783465200315,"m":true,"M":true}}
{"stream":"btcusdt@trade","data":{"e":"trade","E":1783465200316,"s":"BTCUSDT","t":6486989643,"p":"63551.01000000","q":"0.00271000","T":1783465200315,"m":true,"M":true}}
{"stream":"btcusdt@trade","data":{"e":"trade","E":1783465200316,"s":"BTCUSDT","t":6486989644,"p":"63551.01000000","q":"0.00271000","T":1783465200315,"m":true,"M":true}}
{"stream":"btcusdt@trade","data":{"e":"trade","E":1783465200316,"s":"BTCUSDT","t":6486989645,"p":"63551.01000000","q":"0.00271000","T":1783465200315,"m":true,"M":true}}
{"stream":"btcusdt@trade","data":{"e":"trade","E":1783465200316,"s":"BTCUSDT","t":6486989646,"p":"63551.01000000","q":"0.00271000","T":1783465200315,"m":true,"M":true}}
{"stream":"btcusdt@trade","data":{"e":"trade","E":1783465200316,"s":"BTCUSDT","t":6486989647,"p":"63551.01000000","q":"0.00271000","T":1783465200315,"m":true,"M":true}}
{"stream":"btcusdt@trade","data":{"e":"trade","E":1783465200316,"s":"BTCUSDT","t":6486989648,"p":"63551.01000000","q":"0.00271000","T":1783465200315,"m":true,"M":true}}
{"stream":"btcusdt@trade","data":{"e":"trade","E":1783465200316,"s":"BTCUSDT","t":6486989649,"p":"63551.01000000","q":"0.00271000","T":1783465200315,"m":true,"M":true}}
{"stream":"btcusdt@trade","data":{"e":"trade","E":1783465200316,"s":"BTCUSDT","t":6486989650,"p":"63551.01000000","q":"0.00271000","T":1783465200315,"m":true,"M":true}}
{"stream":"btcusdt@trade","data":{"e":"trade","E":1783465200316,"s":"BTCUSDT","t":6486989651,"p":"63551.01000000","q":"0.00271000","T":1783465200315,"m":true,"M":true}}
{"stream":"btcusdt@trade","data":{"e":"trade","E":1783465200316,"s":"BTCUSDT","t":6486989652,"p":"63551.01000000","q":"0.00271000","T":1783465200315,"m":true,"M":true}}
{"stream":"btcusdt@trade","data":{"e":"trade","E":1783465200316,"s":"BTCUSDT","t":6486989653,"p":"63551.01000000","q":"0.00271000","T":1783465200315,"m":true,"M":true}}
{"stream":"btcusdt@trade","data":{"e":"trade","E":1783465200316,"s":"BTCUSDT","t":6486989654,"p":"63551.01000000","q":"0.00271000","T":1783465200315,"m":true,"M":true}}
{"stream":"btcusdt@trade","data":{"e":"trade","E":1783465200316,"s":"BTCUSDT","t":6486989655,"p":"63551.01000000","q":"0.00271000","T":1783465200315,"m":true,"M":true}}
{"stream":"btcusdt@trade","data":{"e":"trade","E":1783465200316,"s":"BTCUSDT","t":6486989656,"p":"63551.01000000","q":"0.00271000","T":1783465200315,"m":true,"M":true}}
{"stream":"btcusdt@trade","data":{"e":"trade","E":1783465200316,"s":"BTCUSDT","t":6486989657,"p":"63551.01000000","q":"0.00271000","T":1783465200315,"m":true,"M":true}}
{"stream":"btcusdt@trade","data":{"e":"trade","E":1783465200316,"s":"BTCUSDT","t":6486989658,"p":"63551.01000000","q":"0.00271000","T":1783465200315,"m":true,"M":true}}
{"stream":"btcusdt@trade","data":{"e":"trade","E":1783465200316,"s":"BTCUSDT","t":6486989659,"p":"63551.01000000","q":"0.00271000","T":1783465200315,"m":true,"M":true}}
{"stream":"btcusdt@trade","data":{"e":"trade","E":1783465200316,"s":"BTCUSDT","t":6486989660,"p":"63551.01000000","q":"0.00271000","T":1783465200315,"m":true,"M":true}}
{"stream":"btcusdt@trade","data":{"e":"trade","E":1783465200316,"s":"BTCUSDT","t":6486989661,"p":"63551.01000000","q":"0.00271000","T":1783465200315,"m":true,"M":true}}
{"stream":"btcusdt@trade","data":{"e":"trade","E":1783465200316,"s":"BTCUSDT","t":6486989662,"p":"63551.01000000","q":"0.00271000","T":1783465200315,"m":true,"M":true}}
{"stream":"btcusdt@trade","data":{"e":"trade","E":1783465200316,"s":"BTCUSDT","t":6486989663,"p":"63551.01000000","q":"0.00271000","T":1783465200315,"m":true,"M":true}}
{"stream":"btcusdt@trade","data":{"e":"trade","E":1783465200316,"s":"BTCUSDT","t":6486989664,"p":"63551.01000000","q":"0.00246000","T":1783465200315,"m":true,"M":true}}
{"stream":"btcusdt@trade","data":{"e":"trade","E":1783465200316,"s":"BTCUSDT","t":6486989665,"p":"63551.01000000","q":"0.00025000","T":1783465200315,"m":true,"M":true}}
{"stream":"btcusdt@trade","data":{"e":"trade","E":1783465200316,"s":"BTCUSDT","t":6486989666,"p":"63551.01000000","q":"0.00271000","T":1783465200315,"m":true,"M":true}}
{"stream":"btcusdt@trade","data":{"e":"trade","E":1783465200316,"s":"BTCUSDT","t":6486989667,"p":"63551.01000000","q":"0.00271000","T":1783465200315,"m":true,"M":true}}
{"stream":"btcusdt@trade","data":{"e":"trade","E":1783465200316,"s":"BTCUSDT","t":6486989668,"p":"63551.01000000","q":"0.00271000","T":1783465200315,"m":true,"M":true}}
{"stream":"btcusdt@trade","data":{"e":"trade","E":1783465200316,"s":"BTCUSDT","t":6486989669,"p":"63551.01000000","q":"0.00271000","T":1783465200315,"m":true,"M":true}}
{"stream":"btcusdt@trade","data":{"e":"trade","E":1783465200316,"s":"BTCUSDT","t":6486989670,"p":"63551.01000000","q":"0.00271000","T":1783465200315,"m":true,"M":true}}
{"stream":"btcusdt@trade","data":{"e":"trade","E":1783465200316,"s":"BTCUSDT","t":6486989671,"p":"63551.01000000","q":"0.00271000","T":1783465200315,"m":true,"M":true}}
{"stream":"btcusdt@trade","data":{"e":"trade","E":1783465200316,"s":"BTCUSDT","t":6486989672,"p":"63551.01000000","q":"0.00271000","T":1783465200315,"m":true,"M":true}}
{"stream":"btcusdt@trade","data":{"e":"trade","E":1783465200316,"s":"BTCUSDT","t":6486989673,"p":"63551.01000000","q":"0.00271000","T":1783465200315,"m":true,"M":true}}
{"stream":"btcusdt@trade","data":{"e":"trade","E":1783465200316,"s":"BTCUSDT","t":6486989674,"p":"63551.01000000","q":"0.00271000","T":1783465200315,"m":true,"M":true}}
{"stream":"btcusdt@trade","data":{"e":"trade","E":1783465200316,"s":"BTCUSDT","t":6486989675,"p":"63551.01000000","q":"0.00271000","T":1783465200315,"m":true,"M":true}}
{"stream":"btcusdt@trade","data":{"e":"trade","E":1783465200316,"s":"BTCUSDT","t":6486989676,"p":"63551.01000000","q":"0.00271000","T":1783465200315,"m":true,"M":true}}
{"stream":"btcusdt@trade","data":{"e":"trade","E":1783465200316,"s":"BTCUSDT","t":6486989677,"p":"63551.01000000","q":"0.00271000","T":1783465200315,"m":true,"M":true}}
{"stream":"btcusdt@trade","data":{"e":"trade","E":1783465200316,"s":"BTCUSDT","t":6486989678,"p":"63551.01000000","q":"0.00271000","T":1783465200315,"m":true,"M":true}}
{"stream":"btcusdt@trade","data":{"e":"trade","E":1783465200316,"s":"BTCUSDT","t":6486989679,"p":"63551.01000000","q":"0.00271000","T":1783465200315,"m":true,"M":true}}
{"stream":"btcusdt@trade","data":{"e":"trade","E":1783465200316,"s":"BTCUSDT","t":6486989680,"p":"63551.01000000","q":"0.00271000","T":1783465200315,"m":true,"M":true}}
{"stream":"btcusdt@trade","data":{"e":"trade","E":1783465200316,"s":"BTCUSDT","t":6486989681,"p":"63551.01000000","q":"0.00271000","T":1783465200315,"m":true,"M":true}}
{"stream":"btcusdt@trade","data":{"e":"trade","E":1783465200316,"s":"BTCUSDT","t":6486989682,"p":"63551.01000000","q":"0.00271000","T":1783465200315,"m":true,"M":true}}
{"stream":"btcusdt@trade","data":{"e":"trade","E":1783465200316,"s":"BTCUSDT","t":6486989683,"p":"63551.01000000","q":"0.00271000","T":1783465200315,"m":true,"M":true}}
{"stream":"btcusdt@trade","data":{"e":"trade","E":1783465200316,"s":"BTCUSDT","t":6486989684,"p":"63551.01000000","q":"0.00271000","T":1783465200315,"m":true,"M":true}}
{"stream":"btcusdt@trade","data":{"e":"trade","E":1783465200316,"s":"BTCUSDT","t":6486989685,"p":"63551.01000000","q":"0.00271000","T":1783465200315,"m":true,"M":true}}
{"stream":"btcusdt@trade","data":{"e":"trade","E":1783465200316,"s":"BTCUSDT","t":6486989686,"p":"63551.01000000","q":"0.00271000","T":1783465200315,"m":true,"M":true}}
{"stream":"btcusdt@trade","data":{"e":"trade","E":1783465200316,"s":"BTCUSDT","t":6486989687,"p":"63551.01000000","q":"0.00271000","T":1783465200315,"m":true,"M":true}}
{"stream":"btcusdt@trade","data":{"e":"trade","E":1783465200316,"s":"BTCUSDT","t":6486989688,"p":"63551.01000000","q":"0.00271000","T":1783465200315,"m":true,"M":true}}
{"stream":"btcusdt@trade","data":{"e":"trade","E":1783465200316,"s":"BTCUSDT","t":6486989689,"p":"63551.01000000","q":"0.00271000","T":1783465200315,"m":true,"M":true}}
{"stream":"btcusdt@trade","data":{"e":"trade","E":1783465200316,"s":"BTCUSDT","t":6486989690,"p":"63551.01000000","q":"0.00271000","T":1783465200315,"m":true,"M":true}}
{"stream":"btcusdt@trade","data":{"e":"trade","E":1783465200316,"s":"BTCUSDT","t":6486989691,"p":"63551.01000000","q":"0.00271000","T":1783465200315,"m":true,"M":true}}
{"stream":"btcusdt@trade","data":{"e":"trade","E":1783465200316,"s":"BTCUSDT","t":6486989692,"p":"63551.01000000","q":"0.00271000","T":1783465200315,"m":true,"M":true}}
{"stream":"btcusdt@trade","data":{"e":"trade","E":1783465200316,"s":"BTCUSDT","t":6486989693,"p":"63551.01000000","q":"0.00271000","T":1783465200315,"m":true,"M":true}}
{"stream":"btcusdt@trade","data":{"e":"trade","E":1783465200316,"s":"BTCUSDT","t":6486989694,"p":"63551.01000000","q":"0.00271000","T":1783465200315,"m":true,"M":true}}
{"stream":"btcusdt@trade","data":{"e":"trade","E":1783465200316,"s":"BTCUSDT","t":6486989695,"p":"63551.01000000","q":"0.00271000","T":1783465200315,"m":true,"M":true}}
{"stream":"btcusdt@trade","data":{"e":"trade","E":1783465200316,"s":"BTCUSDT","t":6486989696,"p":"63551.01000000","q":"0.00271000","T":1783465200315,"m":true,"M":true}}
{"stream":"btcusdt@trade","data":{"e":"trade","E":1783465200316,"s":"BTCUSDT","t":6486989697,"p":"63551.01000000","q":"0.00271000","T":1783465200315,"m":true,"M":true}}
{"stream":"btcusdt@trade","data":{"e":"trade","E":1783465200316,"s":"BTCUSDT","t":6486989698,"p":"63551.01000000","q":"0.00271000","T":1783465200315,"m":true,"M":true}}
{"stream":"btcusdt@trade","data":{"e":"trade","E":1783465200316,"s":"BTCUSDT","t":6486989699,"p":"63551.01000000","q":"0.00271000","T":1783465200315,"m":true,"M":true}}
{"stream":"btcusdt@trade","data":{"e":"trade","E":1783465200316,"s":"BTCUSDT","t":6486989700,"p":"63551.01000000","q":"0.00271000","T":1783465200315,"m":true,"M":true}}
{"stream":"btcusdt@trade","data":{"e":"trade","E":1783465200316,"s":"BTCUSDT","t":6486989701,"p":"63551.01000000","q":"0.00271000","T":1783465200315,"m":true,"M":true}}
{"stream":"btcusdt@trade","data":{"e":"trade","E":1783465200316,"s":"BTCUSDT","t":6486989702,"p":"63551.01000000","q":"0.00271000","T":1783465200315,"m":true,"M":true}}
{"stream":"btcusdt@trade","data":{"e":"trade","E":1783465200316,"s":"BTCUSDT","t":6486989703,"p":"63551.01000000","q":"0.00271000","T":1783465200315,"m":true,"M":true}}
{"stream":"btcusdt@trade","data":{"e":"trade","E":1783465200316,"s":"BTCUSDT","t":6486989704,"p":"63551.01000000","q":"0.00271000","T":1783465200315,"m":true,"M":true}}
{"stream":"btcusdt@trade","data":{"e":"trade","E":1783465200316,"s":"BTCUSDT","t":6486989705,"p":"63551.01000000","q":"0.00271000","T":1783465200315,"m":true,"M":true}}
{"stream":"btcusdt@trade","data":{"e":"trade","E":1783465200316,"s":"BTCUSDT","t":6486989706,"p":"63551.01000000","q":"0.00271000","T":1783465200315,"m":true,"M":true}}
{"stream":"btcusdt@trade","data":{"e":"trade","E":1783465200316,"s":"BTCUSDT","t":6486989707,"p":"63551.01000000","q":"0.00271000","T":1783465200315,"m":true,"M":true}}
{"stream":"btcusdt@trade","data":{"e":"trade","E":1783465200316,"s":"BTCUSDT","t":6486989708,"p":"63551.01000000","q":"0.00271000","T":1783465200315,"m":true,"M":true}}
{"stream":"btcusdt@trade","data":{"e":"trade","E":1783465200316,"s":"BTCUSDT","t":6486989709,"p":"63551.01000000","q":"0.00271000","T":1783465200315,"m":true,"M":true}}
{"stream":"btcusdt@trade","data":{"e":"trade","E":1783465200316,"s":"BTCUSDT","t":6486989710,"p":"63551.01000000","q":"0.00271000","T":1783465200315,"m":true,"M":true}}
{"stream":"btcusdt@trade","data":{"e":"trade","E":1783465200316,"s":"BTCUSDT","t":6486989711,"p":"63551.01000000","q":"0.00271000","T":1783465200315,"m":true,"M":true}}
{"stream":"btcusdt@trade","data":{"e":"trade","E":1783465200316,"s":"BTCUSDT","t":6486989712,"p":"63551.01000000","q":"0.00271000","T":1783465200315,"m":true,"M":true}}
{"stream":"btcusdt@trade","data":{"e":"trade","E":1783465200316,"s":"BTCUSDT","t":6486989713,"p":"63551.01000000","q":"0.00271000","T":1783465200315,"m":true,"M":true}}
{"stream":"btcusdt@trade","data":{"e":"trade","E":1783465200316,"s":"BTCUSDT","t":6486989714,"p":"63551.01000000","q":"0.00271000","T":1783465200315,"m":true,"M":true}}
{"stream":"btcusdt@trade","data":{"e":"trade","E":1783465200316,"s":"BTCUSDT","t":6486989715,"p":"63551.01000000","q":"0.00271000","T":1783465200315,"m":true,"M":true}}
{"stream":"btcusdt@trade","data":{"e":"trade","E":1783465200316,"s":"BTCUSDT","t":6486989716,"p":"63551.01000000","q":"0.00271000","T":1783465200315,"m":true,"M":true}}
{"stream":"btcusdt@trade","data":{"e":"trade","E":1783465200316,"s":"BTCUSDT","t":6486989717,"p":"63551.01000000","q":"0.00271000","T":1783465200315,"m":true,"M":true}}
{"stream":"btcusdt@trade","data":{"e":"trade","E":1783465200316,"s":"BTCUSDT","t":6486989718,"p":"63551.01000000","q":"0.00271000","T":1783465200315,"m":true,"M":true}}
{"stream":"btcusdt@trade","data":{"e":"trade","E":1783465200316,"s":"BTCUSDT","t":6486989719,"p":"63551.01000000","q":"0.00271000","T":1783465200315,"m":true,"M":true}}
{"stream":"btcusdt@trade","data":{"e":"trade","E":1783465200316,"s":"BTCUSDT","t":6486989720,"p":"63551.01000000","q":"0.00271000","T":1783465200315,"m":true,"M":true}}
{"stream":"btcusdt@trade","data":{"e":"trade","E":1783465200316,"s":"BTCUSDT","t":6486989721,"p":"63551.01000000","q":"0.00271000","T":1783465200315,"m":true,"M":true}}
{"stream":"btcusdt@trade","data":{"e":"trade","E":1783465200316,"s":"BTCUSDT","t":6486989722,"p":"63551.01000000","q":"0.00271000","T":1783465200315,"m":true,"M":true}}
{"stream":"btcusdt@trade","data":{"e":"trade","E":1783465200316,"s":"BTCUSDT","t":6486989723,"p":"63551.01000000","q":"0.00271000","T":1783465200315,"m":true,"M":true}}
{"stream":"btcusdt@trade","data":{"e":"trade","E":1783465200316,"s":"BTCUSDT","t":6486989724,"p":"63551.01000000","q":"0.00271000","T":1783465200315,"m":true,"M":true}}
{"stream":"btcusdt@trade","data":{"e":"trade","E":1783465200316,"s":"BTCUSDT","t":6486989725,"p":"63551.01000000","q":"0.00271000","T":1783465200315,"m":true,"M":true}}
{"stream":"btcusdt@trade","data":{"e":"trade","E":1783465200316,"s":"BTCUSDT","t":6486989726,"p":"63551.01000000","q":"0.00271000","T":1783465200315,"m":true,"M":true}}
{"stream":"btcusdt@trade","data":{"e":"trade","E":1783465200316,"s":"BTCUSDT","t":6486989727,"p":"63551.01000000","q":"0.00271000","T":1783465200315,"m":true,"M":true}}
{"stream":"btcusdt@trade","data":{"e":"trade","E":1783465200316,"s":"BTCUSDT","t":6486989728,"p":"63551.01000000","q":"0.00271000","T":1783465200315,"m":true,"M":true}}
{"stream":"btcusdt@trade","data":{"e":"trade","E":1783465200316,"s":"BTCUSDT","t":6486989729,"p":"63551.01000000","q":"0.00271000","T":1783465200315,"m":true,"M":true}}
{"stream":"btcusdt@trade","data":{"e":"trade","E":1783465200316,"s":"BTCUSDT","t":6486989730,"p":"63551.01000000","q":"0.00271000","T":1783465200315,"m":true,"M":true}}
{"stream":"btcusdt@trade","data":{"e":"trade","E":1783465200316,"s":"BTCUSDT","t":6486989731,"p":"63551.01000000","q":"0.00271000","T":1783465200315,"m":true,"M":true}}
{"stream":"btcusdt@trade","data":{"e":"trade","E":1783465200316,"s":"BTCUSDT","t":6486989732,"p":"63551.01000000","q":"0.00271000","T":1783465200315,"m":true,"M":true}}
{"stream":"btcusdt@trade","data":{"e":"trade","E":1783465200316,"s":"BTCUSDT","t":6486989733,"p":"63551.01000000","q":"0.00271000","T":1783465200315,"m":true,"M":true}}
{"stream":"btcusdt@trade","data":{"e":"trade","E":1783465200316,"s":"BTCUSDT","t":6486989734,"p":"63551.01000000","q":"0.00271000","T":1783465200315,"m":true,"M":true}}
{"stream":"btcusdt@trade","data":{"e":"trade","E":1783465200316,"s":"BTCUSDT","t":6486989735,"p":"63551.01000000","q":"0.00271000","T":1783465200315,"m":true,"M":true}}
{"stream":"btcusdt@trade","data":{"e":"trade","E":1783465200316,"s":"BTCUSDT","t":6486989736,"p":"63551.01000000","q":"0.00271000","T":1783465200315,"m":true,"M":true}}
{"stream":"btcusdt@trade","data":{"e":"trade","E":1783465200316,"s":"BTCUSDT","t":6486989737,"p":"63551.01000000","q":"0.00271000","T":1783465200315,"m":true,"M":true}}
{"stream":"btcusdt@trade","data":{"e":"trade","E":1783465200316,"s":"BTCUSDT","t":6486989738,"p":"63551.01000000","q":"0.00271000","T":1783465200315,"m":true,"M":true}}
{"stream":"btcusdt@trade","data":{"e":"trade","E":1783465200316,"s":"BTCUSDT","t":6486989739,"p":"63551.01000000","q":"0.00271000","T":1783465200315,"m":true,"M":true}}
{"stream":"btcusdt@trade","data":{"e":"trade","E":1783465200316,"s":"BTCUSDT","t":6486989740,"p":"63551.01000000","q":"0.00271000","T":1783465200315,"m":true,"M":true}}
{"stream":"btcusdt@trade","data":{"e":"trade","E":1783465200316,"s":"BTCUSDT","t":6486989741,"p":"63551.01000000","q":"0.00271000","T":1783465200315,"m":true,"M":true}}
{"stream":"btcusdt@trade","data":{"e":"trade","E":1783465200316,"s":"BTCUSDT","t":6486989742,"p":"63551.01000000","q":"0.00271000","T":1783465200315,"m":true,"M":true}}
{"stream":"btcusdt@trade","data":{"e":"trade","E":1783465200316,"s":"BTCUSDT","t":6486989743,"p":"63551.01000000","q":"0.00271000","T":1783465200315,"m":true,"M":true}}
{"stream":"btcusdt@trade","data":{"e":"trade","E":1783465200316,"s":"BTCUSDT","t":6486989744,"p":"63551.01000000","q":"0.00271000","T":1783465200315,"m":true,"M":true}}
{"stream":"btcusdt@trade","data":{"e":"trade","E":1783465200316,"s":"BTCUSDT","t":6486989745,"p":"63551.01000000","q":"0.00271000","T":1783465200315,"m":true,"M":true}}
{"stream":"btcusdt@trade","data":{"e":"trade","E":1783465200316,"s":"BTCUSDT","t":6486989746,"p":"63551.01000000","q":"0.00271000","T":1783465200315,"m":true,"M":true}}
{"stream":"btcusdt@trade","data":{"e":"trade","E":1783465200316,"s":"BTCUSDT","t":6486989747,"p":"63551.01000000","q":"0.00271000","T":1783465200315,"m":true,"M":true}}
{"stream":"btcusdt@trade","data":{"e":"trade","E":1783465200316,"s":"BTCUSDT","t":6486989748,"p":"63551.01000000","q":"0.00271000","T":1783465200315,"m":true,"M":true}}
{"stream":"btcusdt@trade","data":{"e":"trade","E":1783465200316,"s":"BTCUSDT","t":6486989749,"p":"63551.01000000","q":"0.00271000","T":1783465200315,"m":true,"M":true}}
{"stream":"btcusdt@trade","data":{"e":"trade","E":1783465200316,"s":"BTCUSDT","t":6486989750,"p":"63551.01000000","q":"0.00271000","T":1783465200315,"m":true,"M":true}}
{"stream":"btcusdt@trade","data":{"e":"trade","E":1783465200316,"s":"BTCUSDT","t":6486989751,"p":"63551.01000000","q":"0.00271000","T":1783465200315,"m":true,"M":true}}
{"stream":"btcusdt@trade","data":{"e":"trade","E":1783465200316,"s":"BTCUSDT","t":6486989752,"p":"63551.01000000","q":"0.00271000","T":1783465200315,"m":true,"M":true}}
{"stream":"btcusdt@trade","data":{"e":"trade","E":1783465200316,"s":"BTCUSDT","t":6486989753,"p":"63551.01000000","q":"0.00271000","T":1783465200315,"m":true,"M":true}}
{"stream":"btcusdt@trade","data":{"e":"trade","E":1783465200316,"s":"BTCUSDT","t":6486989754,"p":"63551.01000000","q":"0.00271000","T":1783465200315,"m":true,"M":true}}
{"stream":"btcusdt@trade","data":{"e":"trade","E":1783465200316,"s":"BTCUSDT","t":6486989755,"p":"63551.01000000","q":"0.00271000","T":1783465200315,"m":true,"M":true}}
{"stream":"btcusdt@trade","data":{"e":"trade","E":1783465200316,"s":"BTCUSDT","t":6486989756,"p":"63551.01000000","q":"0.00271000","T":1783465200315,"m":true,"M":true}}
{"stream":"btcusdt@trade","data":{"e":"trade","E":1783465200316,"s":"BTCUSDT","t":6486989757,"p":"63551.01000000","q":"0.00271000","T":1783465200315,"m":true,"M":true}}
{"stream":"btcusdt@trade","data":{"e":"trade","E":1783465200316,"s":"BTCUSDT","t":6486989758,"p":"63551.01000000","q":"0.00223000","T":1783465200315,"m":true,"M":true}}
{"stream":"btcusdt@trade","data":{"e":"trade","E":1783465200316,"s":"BTCUSDT","t":6486989759,"p":"63551.01000000","q":"0.00048000","T":1783465200315,"m":true,"M":true}}
{"stream":"btcusdt@trade","data":{"e":"trade","E":1783465200316,"s":"BTCUSDT","t":6486989760,"p":"63551.01000000","q":"0.00271000","T":1783465200315,"m":true,"M":true}}
{"stream":"btcusdt@trade","data":{"e":"trade","E":1783465200316,"s":"BTCUSDT","t":6486989761,"p":"63551.01000000","q":"0.00271000","T":1783465200315,"m":true,"M":true}}
{"stream":"btcusdt@trade","data":{"e":"trade","E":1783465200316,"s":"BTCUSDT","t":6486989762,"p":"63551.01000000","q":"0.00271000","T":1783465200315,"m":true,"M":true}}
{"stream":"btcusdt@trade","data":{"e":"trade","E":1783465200316,"s":"BTCUSDT","t":6486989763,"p":"63551.01000000","q":"0.00271000","T":1783465200315,"m":true,"M":true}}
{"stream":"btcusdt@trade","data":{"e":"trade","E":1783465200316,"s":"BTCUSDT","t":6486989764,"p":"63551.01000000","q":"0.00271000","T":1783465200315,"m":true,"M":true}}
{"stream":"btcusdt@trade","data":{"e":"trade","E":1783465200316,"s":"BTCUSDT","t":6486989765,"p":"63551.01000000","q":"0.00271000","T":1783465200315,"m":true,"M":true}}
{"stream":"btcusdt@trade","data":{"e":"trade","E":1783465200316,"s":"BTCUSDT","t":6486989766,"p":"63551.01000000","q":"0.00271000","T":1783465200315,"m":true,"M":true}}
{"stream":"btcusdt@trade","data":{"e":"trade","E":1783465200316,"s":"BTCUSDT","t":6486989767,"p":"63551.01000000","q":"0.00271000","T":1783465200315,"m":true,"M":true}}
{"stream":"btcusdt@trade","data":{"e":"trade","E":1783465200316,"s":"BTCUSDT","t":6486989768,"p":"63551.01000000","q":"0.00271000","T":1783465200315,"m":true,"M":true}}
{"stream":"btcusdt@trade","data":{"e":"trade","E":1783465200316,"s":"BTCUSDT","t":6486989769,"p":"63551.01000000","q":"0.00271000","T":1783465200315,"m":true,"M":true}}
{"stream":"btcusdt@trade","data":{"e":"trade","E":1783465200316,"s":"BTCUSDT","t":6486989770,"p":"63551.01000000","q":"0.00271000","T":1783465200315,"m":true,"M":true}}
{"stream":"btcusdt@trade","data":{"e":"trade","E":1783465200316,"s":"BTCUSDT","t":6486989771,"p":"63551.01000000","q":"0.00271000","T":1783465200315,"m":true,"M":true}}
{"stream":"btcusdt@trade","data":{"e":"trade","E":1783465200316,"s":"BTCUSDT","t":6486989772,"p":"63551.01000000","q":"0.00271000","T":1783465200315,"m":true,"M":true}}
{"stream":"btcusdt@trade","data":{"e":"trade","E":1783465200316,"s":"BTCUSDT","t":6486989773,"p":"63551.01000000","q":"0.00271000","T":1783465200315,"m":true,"M":true}}
{"stream":"btcusdt@trade","data":{"e":"trade","E":1783465200316,"s":"BTCUSDT","t":6486989774,"p":"63551.01000000","q":"0.00271000","T":1783465200315,"m":true,"M":true}}
{"stream":"btcusdt@trade","data":{"e":"trade","E":1783465200316,"s":"BTCUSDT","t":6486989775,"p":"63551.01000000","q":"0.00271000","T":1783465200315,"m":true,"M":true}}
{"stream":"btcusdt@trade","data":{"e":"trade","E":1783465200316,"s":"BTCUSDT","t":6486989776,"p":"63551.01000000","q":"0.00271000","T":1783465200315,"m":true,"M":true}}
{"stream":"btcusdt@trade","data":{"e":"trade","E":1783465200316,"s":"BTCUSDT","t":6486989777,"p":"63551.01000000","q":"0.00271000","T":1783465200315,"m":true,"M":true}}
{"stream":"btcusdt@trade","data":{"e":"trade","E":1783465200316,"s":"BTCUSDT","t":6486989778,"p":"63551.01000000","q":"0.00271000","T":1783465200315,"m":true,"M":true}}
{"stream":"btcusdt@trade","data":{"e":"trade","E":1783465200316,"s":"BTCUSDT","t":6486989779,"p":"63551.01000000","q":"0.00271000","T":1783465200315,"m":true,"M":true}}
{"stream":"btcusdt@trade","data":{"e":"trade","E":1783465200316,"s":"BTCUSDT","t":6486989780,"p":"63551.01000000","q":"0.00271000","T":1783465200315,"m":true,"M":true}}
{"stream":"btcusdt@trade","data":{"e":"trade","E":1783465200316,"s":"BTCUSDT","t":6486989781,"p":"63551.01000000","q":"0.00106000","T":1783465200315,"m":true,"M":true}}
{"stream":"btcusdt@trade","data":{"e":"trade","E":1783465200316,"s":"BTCUSDT","t":6486989782,"p":"63551.01000000","q":"0.00271000","T":1783465200315,"m":true,"M":true}}
{"stream":"btcusdt@trade","data":{"e":"trade","E":1783465200316,"s":"BTCUSDT","t":6486989783,"p":"63551.01000000","q":"0.00271000","T":1783465200315,"m":true,"M":true}}
{"stream":"btcusdt@trade","data":{"e":"trade","E":1783465200316,"s":"BTCUSDT","t":6486989784,"p":"63551.01000000","q":"0.00127000","T":1783465200315,"m":true,"M":true}}
{"stream":"btcusdt@trade","data":{"e":"trade","E":1783465200316,"s":"BTCUSDT","t":6486989785,"p":"63551.01000000","q":"0.00271000","T":1783465200315,"m":true,"M":true}}
{"stream":"btcusdt@trade","data":{"e":"trade","E":1783465200316,"s":"BTCUSDT","t":6486989786,"p":"63551.01000000","q":"0.00271000","T":1783465200315,"m":true,"M":true}}
{"stream":"btcusdt@trade","data":{"e":"trade","E":1783465200316,"s":"BTCUSDT","t":6486989787,"p":"63551.01000000","q":"0.00271000","T":1783465200315,"m":true,"M":true}}
{"stream":"btcusdt@trade","data":{"e":"trade","E":1783465200316,"s":"BTCUSDT","t":6486989788,"p":"63551.01000000","q":"0.00271000","T":1783465200315,"m":true,"M":true}}
{"stream":"btcusdt@trade","data":{"e":"trade","E":1783465200316,"s":"BTCUSDT","t":6486989789,"p":"63551.01000000","q":"0.00271000","T":1783465200315,"m":true,"M":true}}
{"stream":"btcusdt@trade","data":{"e":"trade","E":1783465200316,"s":"BTCUSDT","t":6486989790,"p":"63551.01000000","q":"0.00271000","T":1783465200315,"m":true,"M":true}}
{"stream":"btcusdt@trade","data":{"e":"trade","E":1783465200316,"s":"BTCUSDT","t":6486989791,"p":"63551.01000000","q":"0.00271000","T":1783465200315,"m":true,"M":true}}
{"stream":"btcusdt@trade","data":{"e":"trade","E":1783465200316,"s":"BTCUSDT","t":6486989792,"p":"63551.01000000","q":"0.00271000","T":1783465200315,"m":true,"M":true}}
{"stream":"btcusdt@trade","data":{"e":"trade","E":1783465200316,"s":"BTCUSDT","t":6486989793,"p":"63551.01000000","q":"0.00271000","T":1783465200315,"m":true,"M":true}}
{"stream":"btcusdt@trade","data":{"e":"trade","E":1783465200316,"s":"BTCUSDT","t":6486989794,"p":"63551.01000000","q":"0.00271000","T":1783465200315,"m":true,"M":true}}
{"stream":"btcusdt@trade","data":{"e":"trade","E":1783465200316,"s":"BTCUSDT","t":6486989795,"p":"63551.01000000","q":"0.00271000","T":1783465200315,"m":true,"M":true}}
{"stream":"btcusdt@trade","data":{"e":"trade","E":1783465200316,"s":"BTCUSDT","t":6486989796,"p":"63551.01000000","q":"0.00152000","T":1783465200315,"m":true,"M":true}}
{"stream":"btcusdt@trade","data":{"e":"trade","E":1783465200316,"s":"BTCUSDT","t":6486989797,"p":"63551.01000000","q":"0.00271000","T":1783465200315,"m":true,"M":true}}
{"stream":"btcusdt@trade","data":{"e":"trade","E":1783465200316,"s":"BTCUSDT","t":6486989798,"p":"63551.01000000","q":"0.00271000","T":1783465200315,"m":true,"M":true}}
{"stream":"btcusdt@trade","data":{"e":"trade","E":1783465200316,"s":"BTCUSDT","t":6486989799,"p":"63551.01000000","q":"0.00271000","T":1783465200315,"m":true,"M":true}}
{"stream":"btcusdt@trade","data":{"e":"trade","E":1783465200316,"s":"BTCUSDT","t":6486989800,"p":"63551.01000000","q":"0.00271000","T":1783465200315,"m":true,"M":true}}
{"stream":"btcusdt@trade","data":{"e":"trade","E":1783465200316,"s":"BTCUSDT","t":6486989801,"p":"63551.01000000","q":"0.00271000","T":1783465200315,"m":true,"M":true}}
{"stream":"btcusdt@trade","data":{"e":"trade","E":1783465200316,"s":"BTCUSDT","t":6486989802,"p":"63551.01000000","q":"0.00271000","T":1783465200315,"m":true,"M":true}}
{"stream":"btcusdt@trade","data":{"e":"trade","E":1783465200316,"s":"BTCUSDT","t":6486989803,"p":"63551.01000000","q":"0.00163000","T":1783465200315,"m":true,"M":true}}
{"stream":"btcusdt@trade","data":{"e":"trade","E":1783465200316,"s":"BTCUSDT","t":6486989804,"p":"63551.00000000","q":"0.00016000","T":1783465200315,"m":true,"M":true}}
{"stream":"btcusdt@trade","data":{"e":"trade","E":1783465200316,"s":"BTCUSDT","t":6486989805,"p":"63550.47000000","q":"0.00030000","T":1783465200315,"m":true,"M":true}}
{"stream":"btcusdt@trade","data":{"e":"trade","E":1783465200317,"s":"BTCUSDT","t":6486989806,"p":"63550.47000000","q":"0.00002000","T":1783465200315,"m":true,"M":true}}
{"stream":"btcusdt@trade","data":{"e":"trade","E":1783465200317,"s":"BTCUSDT","t":6486989807,"p":"63550.01000000","q":"0.00009000","T":1783465200315,"m":true,"M":true}}
{"stream":"btcusdt@trade","data":{"e":"trade","E":1783465200317,"s":"BTCUSDT","t":6486989808,"p":"63550.01000000","q":"0.00009000","T":1783465200315,"m":true,"M":true}}
{"stream":"btcusdt@trade","data":{"e":"trade","E":1783465200317,"s":"BTCUSDT","t":6486989809,"p":"63550.01000000","q":"0.00009000","T":1783465200315,"m":true,"M":true}}
{"stream":"btcusdt@trade","data":{"e":"trade","E":1783465200317,"s":"BTCUSDT","t":6486989810,"p":"63550.00000000","q":"0.01000000","T":1783465200315,"m":true,"M":true}}
{"stream":"btcusdt@trade","data":{"e":"trade","E":1783465200317,"s":"BTCUSDT","t":6486989811,"p":"63550.00000000","q":"0.00511000","T":1783465200315,"m":true,"M":true}}
{"stream":"btcusdt@trade","data":{"e":"trade","E":1783465200317,"s":"BTCUSDT","t":6486989812,"p":"63550.00000000","q":"0.00389000","T":1783465200316,"m":true,"M":true}}
{"stream":"btcusdt@trade","data":{"e":"trade","E":1783465200317,"s":"BTCUSDT","t":6486989813,"p":"63550.00000000","q":"0.00800000","T":1783465200316,"m":true,"M":true}}
{"stream":"btcusdt@trade","data":{"e":"trade","E":1783465200317,"s":"BTCUSDT","t":6486989814,"p":"63550.00000000","q":"0.00171000","T":1783465200316,"m":true,"M":true}}
{"stream":"btcusdt@trade","data":{"e":"trade","E":1783465200317,"s":"BTCUSDT","t":6486989815,"p":"63550.00000000","q":"0.00329000","T":1783465200316,"m":true,"M":true}}
{"stream":"btcusdt@trade","data":{"e":"trade","E":1783465200317,"s":"BTCUSDT","t":6486989816,"p":"63550.00000000","q":"0.00600000","T":1783465200316,"m":true,"M":true}}
{"stream":"btcusdt@trade","data":{"e":"trade","E":1783465200317,"s":"BTCUSDT","t":6486989817,"p":"63550.00000000","q":"0.00059000","T":1783465200316,"m":true,"M":true}}
{"stream":"btcusdt@trade","data":{"e":"trade","E":1783465200317,"s":"BTCUSDT","t":6486989818,"p":"63550.00000000","q":"0.00009000","T":1783465200316,"m":true,"M":true}}
{"stream":"btcusdt@trade","data":{"e":"trade","E":1783465200317,"s":"BTCUSDT","t":6486989819,"p":"63550.00000000","q":"0.00009000","T":1783465200316,"m":true,"M":true}}
{"stream":"btcusdt@trade","data":{"e":"trade","E":1783465200317,"s":"BTCUSDT","t":6486989820,"p":"63549.13000000","q":"0.00008000","T":1783465200316,"m":true,"M":true}}
{"stream":"btcusdt@trade","data":{"e":"trade","E":1783465200317,"s":"BTCUSDT","t":6486989821,"p":"63549.13000000","q":"0.00008000","T":1783465200316,"m":true,"M":true}}
{"stream":"btcusdt@trade","data":{"e":"trade","E":1783465200317,"s":"BTCUSDT","t":6486989822,"p":"63549.13000000","q":"0.00008000","T":1783465200316,"m":true,"M":true}}
{"stream":"btcusdt@trade","data":{"e":"trade","E":1783465200317,"s":"BTCUSDT","t":6486989823,"p":"63549.13000000","q":"0.00008000","T":1783465200316,"m":true,"M":true}}
{"stream":"btcusdt@trade","data":{"e":"trade","E":1783465200317,"s":"BTCUSDT","t":6486989824,"p":"63549.13000000","q":"0.00008000","T":1783465200316,"m":true,"M":true}}
{"stream":"btcusdt@trade","data":{"e":"trade","E":1783465200317,"s":"BTCUSDT","t":6486989825,"p":"63549.13000000","q":"0.00008000","T":1783465200316,"m":true,"M":true}}
{"stream":"btcusdt@trade","data":{"e":"trade","E":1783465200317,"s":"BTCUSDT","t":6486989826,"p":"63548.99000000","q":"0.00009000","T":1783465200316,"m":true,"M":true}}
{"stream":"btcusdt@trade","data":{"e":"trade","E":1783465200317,"s":"BTCUSDT","t":6486989827,"p":"63548.56000000","q":"0.00032000","T":1783465200316,"m":true,"M":true}}
{"stream":"btcusdt@trade","data":{"e":"trade","E":1783465200317,"s":"BTCUSDT","t":6486989828,"p":"63548.39000000","q":"0.00008000","T":1783465200316,"m":true,"M":true}}
{"stream":"btcusdt@trade","data":{"e":"trade","E":1783465200317,"s":"BTCUSDT","t":6486989829,"p":"63548.23000000","q":"0.00008000","T":1783465200316,"m":true,"M":true}}
{"stream":"btcusdt@trade","data":{"e":"trade","E":1783465200317,"s":"BTCUSDT","t":6486989830,"p":"63548.01000000","q":"0.00009000","T":1783465200316,"m":true,"M":true}}
{"stream":"btcusdt@trade","data":{"e":"trade","E":1783465200317,"s":"BTCUSDT","t":6486989831,"p":"63548.01000000","q":"0.00009000","T":1783465200316,"m":true,"M":true}}
{"stream":"btcusdt@trade","data":{"e":"trade","E":1783465200317,"s":"BTCUSDT","t":6486989832,"p":"63548.01000000","q":"0.00009000","T":1783465200316,"m":true,"M":true}}
{"stream":"btcusdt@trade","data":{"e":"trade","E":1783465200317,"s":"BTCUSDT","t":6486989833,"p":"63548.00000000","q":"0.00868000","T":1783465200316,"m":true,"M":true}}
{"stream":"btcusdt@trade","data":{"e":"trade","E":1783465200317,"s":"BTCUSDT","t":6486989834,"p":"63548.00000000","q":"0.00032000","T":1783465200317,"m":true,"M":true}}
{"stream":"btcusdt@trade","data":{"e":"trade","E":1783465200317,"s":"BTCUSDT","t":6486989835,"p":"63548.00000000","q":"0.00800000","T":1783465200317,"m":true,"M":true}}
{"stream":"btcusdt@trade","data":{"e":"trade","E":1783465200317,"s":"BTCUSDT","t":6486989836,"p":"63548.00000000","q":"0.00500000","T":1783465200317,"m":true,"M":true}}
{"stream":"btcusdt@trade","data":{"e":"trade","E":1783465200317,"s":"BTCUSDT","t":6486989837,"p":"63548.00000000","q":"0.00600000","T":1783465200317,"m":true,"M":true}}
{"stream":"btcusdt@trade","data":{"e":"trade","E":1783465200317,"s":"BTCUSDT","t":6486989838,"p":"63548.00000000","q":"0.00009000","T":1783465200317,"m":true,"M":true}}
{"stream":"btcusdt@trade","data":{"e":"trade","E":1783465200317,"s":"BTCUSDT","t":6486989839,"p":"63548.00000000","q":"0.00009000","T":1783465200317,"m":true,"M":true}}
{"stream":"btcusdt@trade","data":{"e":"trade","E":1783465200317,"s":"BTCUSDT","t":6486989840,"p":"63547.90000000","q":"0.00008000","T":1783465200317,"m":true,"M":true}}
{"stream":"btcusdt@trade","data":{"e":"trade","E":1783465200317,"s":"BTCUSDT","t":6486989841,"p":"63547.90000000","q":"0.00008000","T":1783465200317,"m":true,"M":true}}
{"stream":"btcusdt@trade","data":{"e":"trade","E":1783465200317,"s":"BTCUSDT","t":6486989842,"p":"63547.84000000","q":"0.00010000","T":1783465200317,"m":true,"M":true}}
{"stream":"btcusdt@trade","data":{"e":"trade","E":1783465200317,"s":"BTCUSDT","t":6486989843,"p":"63547.74000000","q":"0.00008000","T":1783465200317,"m":true,"M":true}}
{"stream":"btcusdt@trade","data":{"e":"trade","E":1783465200317,"s":"BTCUSDT","t":6486989844,"p":"63547.74000000","q":"0.00008000","T":1783465200317,"m":true,"M":true}}
{"stream":"btcusdt@trade","data":{"e":"trade","E":1783465200317,"s":"BTCUSDT","t":6486989845,"p":"63547.57000000","q":"0.00008000","T":1783465200317,"m":true,"M":true}}
{"stream":"ethusdt@trade","data":{"e":"trade","E":1783465200318,"s":"ETHUSDT","t":4197008665,"p":"1775.28000000","q":"0.00290000","T":1783465200317,"m":true,"M":true}}
{"stream":"ethusdt@trade","data":{"e":"trade","E":1783465200318,"s":"ETHUSDT","t":4197008666,"p":"1775.28000000","q":"0.00290000","T":1783465200317,"m":true,"M":true}}
{"stream":"ethusdt@trade","data":{"e":"trade","E":1783465200318,"s":"ETHUSDT","t":4197008667,"p":"1775.28000000","q":"0.00290000","T":1783465200317,"m":true,"M":true}}
{"stream":"ethusdt@trade","data":{"e":"trade","E":1783465200318,"s":"ETHUSDT","t":4197008668,"p":"1775.28000000","q":"0.00290000","T":1783465200317,"m":true,"M":true}}
{"stream":"ethusdt@trade","data":{"e":"trade","E":1783465200318,"s":"ETHUSDT","t":4197008669,"p":"1775.28000000","q":"0.00290000","T":1783465200317,"m":true,"M":true}}
{"stream":"ethusdt@trade","data":{"e":"trade","E":1783465200318,"s":"ETHUSDT","t":4197008670,"p":"1775.28000000","q":"0.00300000","T":1783465200317,"m":true,"M":true}}
{"stream":"ethusdt@trade","data":{"e":"trade","E":1783465200318,"s":"ETHUSDT","t":4197008671,"p":"1775.27000000","q":"0.00300000","T":1783465200317,"m":true,"M":true}}
{"stream":"ethusdt@trade","data":{"e":"trade","E":1783465200318,"s":"ETHUSDT","t":4197008672,"p":"1775.27000000","q":"0.00290000","T":1783465200317,"m":true,"M":true}}
{"stream":"ethusdt@trade","data":{"e":"trade","E":1783465200318,"s":"ETHUSDT","t":4197008673,"p":"1775.27000000","q":"0.00290000","T":1783465200317,"m":true,"M":true}}
{"stream":"ethusdt@trade","data":{"e":"trade","E":1783465200318,"s":"ETHUSDT","t":4197008674,"p":"1775.26000000","q":"0.00300000","T":1783465200317,"m":true,"M":true}}
{"stream":"ethusdt@trade","data":{"e":"trade","E":1783465200318,"s":"ETHUSDT","t":4197008675,"p":"1775.25000000","q":"0.00400000","T":1783465200317,"m":true,"M":true}}
{"stream":"ethusdt@trade","data":{"e":"trade","E":1783465200318,"s":"ETHUSDT","t":4197008676,"p":"1775.25000000","q":"0.00300000","T":1783465200317,"m":true,"M":true}}
{"stream":"ethusdt@trade","data":{"e":"trade","E":1783465200318,"s":"ETHUSDT","t":4197008677,"p":"1775.25000000","q":"0.00300000","T":1783465200317,"m":true,"M":true}}
{"stream":"ethusdt@trade","data":{"e":"trade","E":1783465200318,"s":"ETHUSDT","t":4197008678,"p":"1775.25000000","q":"0.00300000","T":1783465200317,"m":true,"M":true}}
{"stream":"ethusdt@trade","data":{"e":"trade","E":1783465200318,"s":"ETHUSDT","t":4197008679,"p":"1775.25000000","q":"0.00300000","T":1783465200317,"m":true,"M":true}}
{"stream":"ethusdt@trade","data":{"e":"trade","E":1783465200318,"s":"ETHUSDT","t":4197008680,"p":"1775.24000000","q":"0.04420000","T":1783465200317,"m":true,"M":true}}
{"stream":"ethusdt@trade","data":{"e":"trade","E":1783465200318,"s":"ETHUSDT","t":4197008681,"p":"1775.24000000","q":"0.04420000","T":1783465200317,"m":true,"M":true}}
{"stream":"ethusdt@trade","data":{"e":"trade","E":1783465200318,"s":"ETHUSDT","t":4197008682,"p":"1775.24000000","q":"0.04420000","T":1783465200317,"m":true,"M":true}}
{"stream":"ethusdt@trade","data":{"e":"trade","E":1783465200318,"s":"ETHUSDT","t":4197008683,"p":"1775.24000000","q":"0.00300000","T":1783465200317,"m":true,"M":true}}
{"stream":"ethusdt@trade","data":{"e":"trade","E":1783465200318,"s":"ETHUSDT","t":4197008684,"p":"1775.24000000","q":"0.00300000","T":1783465200317,"m":true,"M":true}}
{"stream":"ethusdt@trade","data":{"e":"trade","E":1783465200318,"s":"ETHUSDT","t":4197008685,"p":"1775.24000000","q":"0.00300000","T":1783465200317,"m":true,"M":true}}
{"stream":"ethusdt@trade","data":{"e":"trade","E":1783465200318,"s":"ETHUSDT","t":4197008686,"p":"1775.24000000","q":"0.00300000","T":1783465200317,"m":true,"M":true}}
{"stream":"ethusdt@trade","data":{"e":"trade","E":1783465200318,"s":"ETHUSDT","t":4197008687,"p":"1775.23000000","q":"0.01140000","T":1783465200317,"m":true,"M":true}}
{"stream":"ethusdt@trade","data":{"e":"trade","E":1783465200318,"s":"ETHUSDT","t":4197008688,"p":"1775.23000000","q":"0.01290000","T":1783465200317,"m":true,"M":true}}
{"stream":"ethusdt@trade","data":{"e":"trade","E":1783465200318,"s":"ETHUSDT","t":4197008689,"p":"1775.23000000","q":"0.03200000","T":1783465200317,"m":true,"M":true}}
{"stream":"ethusdt@trade","data":{"e":"trade","E":1783465200318,"s":"ETHUSDT","t":4197008690,"p":"1775.23000000","q":"0.14000000","T":1783465200317,"m":true,"M":true}}
{"stream":"ethusdt@trade","data":{"e":"trade","E":1783465200318,"s":"ETHUSDT","t":4197008691,"p":"1775.23000000","q":"0.00300000","T":1783465200317,"m":true,"M":true}}
{"stream":"ethusdt@trade","data":{"e":"trade","E":1783465200318,"s":"ETHUSDT","t":4197008692,"p":"1775.23000000","q":"0.00300000","T":1783465200317,"m":true,"M":true}}
{"stream":"ethusdt@trade","data":{"e":"trade","E":1783465200318,"s":"ETHUSDT","t":4197008693,"p":"1775.23000000","q":"0.00300000","T":1783465200317,"m":true,"M":true}}
{"stream":"ethusdt@trade","data":{"e":"trade","E":1783465200318,"s":"ETHUSDT","t":4197008694,"p":"1775.23000000","q":"0.00300000","T":1783465200317,"m":true,"M":true}}
{"stream":"ethusdt@trade","data":{"e":"trade","E":1783465200318,"s":"ETHUSDT","t":4197008695,"p":"1775.22000000","q":"0.00180000","T":1783465200317,"m":true,"M":true}}
{"stream":"ethusdt@trade","data":{"e":"trade","E":1783465200318,"s":"ETHUSDT","t":4197008696,"p":"1775.22000000","q":"0.00120000","T":1783465200317,"m":true,"M":true}}
{"stream":"ethusdt@trade","data":{"e":"trade","E":1783465200318,"s":"ETHUSDT","t":4197008697,"p":"1775.22000000","q":"0.00300000","T":1783465200317,"m":true,"M":true}}
{"stream":"ethusdt@trade","data":{"e":"trade","E":1783465200318,"s":"ETHUSDT","t":4197008698,"p":"1775.22000000","q":"0.00300000","T":1783465200317,"m":true,"M":true}}
{"stream":"ethusdt@trade","data":{"e":"trade","E":1783465200318,"s":"ETHUSDT","t":4197008699,"p":"1775.22000000","q":"0.19280000","T":1783465200317,"m":true,"M":true}}
{"stream":"btcusdt@trade","data":{"e":"trade","E":1783465200318,"s":"BTCUSDT","t":6486989846,"p":"63547.57000000","q":"0.00509000","T":1783465200318,"m":true,"M":true}}
{"stream":"ethusdt@trade","data":{"e":"trade","E":1783465200319,"s":"ETHUSDT","t":4197008700,"p":"1775.22000000","q":"0.20000000","T":1783465200318,"m":true,"M":true}}
{"stream":"btcusdt@trade","data":{"e":"trade","E":1783465200320,"s":"BTCUSDT","t":6486989847,"p":"63547.57000000","q":"0.00140000","T":1783465200319,"m":true,"M":true}}
{"stream":"btcusdt@trade","data":{"e":"trade","E":1783465200320,"s":"BTCUSDT","t":6486989848,"p":"63547.57000000","q":"0.00008000","T":1783465200319,"m":true,"M":true}}
{"stream":"btcusdt@trade","data":{"e":"trade","E":1783465200320,"s":"BTCUSDT","t":6486989849,"p":"63547.57000000","q":"0.00008000","T":1783465200319,"m":true,"M":true}}
{"stream":"btcusdt@trade","data":{"e":"trade","E":1783465200320,"s":"BTCUSDT","t":6486989850,"p":"63547.57000000","q":"0.00008000","T":1783465200319,"m":true,"M":true}}
{"stream":"btcusdt@trade","data":{"e":"trade","E":1783465200320,"s":"BTCUSDT","t":6486989851,"p":"63547.57000000","q":"0.00008000","T":1783465200319,"m":true,"M":true}}
{"stream":"btcusdt@trade","data":{"e":"trade","E":1783465200320,"s":"BTCUSDT","t":6486989852,"p":"63546.86000000","q":"0.00008000","T":1783465200319,"m":true,"M":true}}
{"stream":"btcusdt@trade","data":{"e":"trade","E":1783465200320,"s":"BTCUSDT","t":6486989853,"p":"63546.86000000","q":"0.00008000","T":1783465200319,"m":true,"M":true}}
{"stream":"btcusdt@trade","data":{"e":"trade","E":1783465200320,"s":"BTCUSDT","t":6486989854,"p":"63546.67000000","q":"0.00008000","T":1783465200319,"m":true,"M":true}}
{"stream":"btcusdt@trade","data":{"e":"trade","E":1783465200320,"s":"BTCUSDT","t":6486989855,"p":"63546.67000000","q":"0.00008000","T":1783465200319,"m":true,"M":true}}
{"stream":"btcusdt@trade","data":{"e":"trade","E":1783465200320,"s":"BTCUSDT","t":6486989856,"p":"63546.65000000","q":"0.00032000","T":1783465200319,"m":true,"M":true}}
{"stream":"btcusdt@trade","data":{"e":"trade","E":1783465200320,"s":"BTCUSDT","t":6486989857,"p":"63546.01000000","q":"0.00009000","T":1783465200319,"m":true,"M":true}}
{"stream":"btcusdt@trade","data":{"e":"trade","E":1783465200320,"s":"BTCUSDT","t":6486989858,"p":"63546.01000000","q":"0.00009000","T":1783465200319,"m":true,"M":true}}
{"stream":"btcusdt@trade","data":{"e":"trade","E":1783465200320,"s":"BTCUSDT","t":6486989859,"p":"63546.01000000","q":"0.00009000","T":1783465200319,"m":true,"M":true}}
{"stream":"btcusdt@trade","data":{"e":"trade","E":1783465200320,"s":"BTCUSDT","t":6486989860,"p":"63546.00000000","q":"0.00037000","T":1783465200319,"m":true,"M":true}}
{"stream":"btcusdt@trade","data":{"e":"trade","E":1783465200321,"s":"BTCUSDT","t":6486989861,"p":"63546.00000000","q":"0.00863000","T":1783465200319,"m":true,"M":true}}
{"stream":"btcusdt@trade","data":{"e":"trade","E":1783465200321,"s":"BTCUSDT","t":6486989862,"p":"63546.00000000","q":"0.00800000","T":1783465200319,"m":true,"M":true}}
{"stream":"btcusdt@trade","data":{"e":"trade","E":1783465200321,"s":"BTCUSDT","t":6486989863,"p":"63546.00000000","q":"0.00500000","T":1783465200319,"m":true,"M":true}}
{"stream":"btcusdt@trade","data":{"e":"trade","E":1783465200321,"s":"BTCUSDT","t":6486989864,"p":"63546.00000000","q":"0.00600000","T":1783465200319,"m":true,"M":true}}
{"stream":"btcusdt@trade","data":{"e":"trade","E":1783465200321,"s":"BTCUSDT","t":6486989865,"p":"63546.00000000","q":"0.00009000","T":1783465200319,"m":true,"M":true}}
{"stream":"btcusdt@trade","data":{"e":"trade","E":1783465200321,"s":"BTCUSDT","t":6486989866,"p":"63545.82000000","q":"0.00009000","T":1783465200319,"m":true,"M":true}}
{"stream":"btcusdt@trade","data":{"e":"trade","E":1783465200321,"s":"BTCUSDT","t":6486989867,"p":"63545.82000000","q":"0.00008000","T":1783465200319,"m":true,"M":true}}
{"stream":"btcusdt@trade","data":{"e":"trade","E":1783465200321,"s":"BTCUSDT","t":6486989868,"p":"63545.82000000","q":"0.00008000","T":1783465200319,"m":true,"M":true}}
{"stream":"btcusdt@trade","data":{"e":"trade","E":1783465200321,"s":"BTCUSDT","t":6486989869,"p":"63545.51000000","q":"0.00009000","T":1783465200319,"m":true,"M":true}}
{"stream":"btcusdt@trade","data":{"e":"trade","E":1783465200321,"s":"BTCUSDT","t":6486989870,"p":"63545.34000000","q":"0.00009000","T":1783465200319,"m":true,"M":true}}
{"stream":"btcusdt@trade","data":{"e":"trade","E":1783465200321,"s":"BTCUSDT","t":6486989871,"p":"63545.34000000","q":"0.00009000","T":1783465200319,"m":true,"M":true}}
{"stream":"btcusdt@trade","data":{"e":"trade","E":1783465200321,"s":"BTCUSDT","t":6486989872,"p":"63545.34000000","q":"0.00009000","T":1783465200319,"m":true,"M":true}}
{"stream":"btcusdt@trade","data":{"e":"trade","E":1783465200321,"s":"BTCUSDT","t":6486989873,"p":"63545.33000000","q":"0.00867000","T":1783465200319,"m":true,"M":true}}
{"stream":"ethusdt@trade","data":{"e":"trade","E":1783465200324,"s":"ETHUSDT","t":4197008701,"p":"1775.22000000","q":"0.00300000","T":1783465200322,"m":true,"M":true}}
{"stream":"btcusdt@trade","data":{"e":"trade","E":1783465200324,"s":"BTCUSDT","t":6486989874,"p":"63545.33000000","q":"0.02000000","T":1783465200323,"m":true,"M":true}}
{"stream":"btcusdt@trade","data":{"e":"trade","E":1783465200348,"s":"BTCUSDT","t":6486989875,"p":"63545.33000000","q":"0.02054000","T":1783465200347,"m":true,"M":true}}
{"stream":"btcusdt@trade","data":{"e":"trade","E":1783465200348,"s":"BTCUSDT","t":6486989876,"p":"63545.33000000","q":"0.00009000","T":1783465200347,"m":true,"M":true}}
{"stream":"btcusdt@trade","data":{"e":"trade","E":1783465200348,"s":"BTCUSDT","t":6486989877,"p":"63545.33000000","q":"0.00009000","T":1783465200347,"m":true,"M":true}}
{"stream":"btcusdt@trade","data":{"e":"trade","E":1783465200348,"s":"BTCUSDT","t":6486989878,"p":"63545.33000000","q":"0.00008000","T":1783465200347,"m":true,"M":true}}
{"stream":"btcusdt@trade","data":{"e":"trade","E":1783465200348,"s":"BTCUSDT","t":6486989879,"p":"63545.33000000","q":"0.00008000","T":1783465200347,"m":true,"M":true}}
{"stream":"btcusdt@trade","data":{"e":"trade","E":1783465200348,"s":"BTCUSDT","t":6486989880,"p":"63545.33000000","q":"0.00009000","T":1783465200347,"m":true,"M":true}}
{"stream":"btcusdt@trade","data":{"e":"trade","E":1783465200348,"s":"BTCUSDT","t":6486989881,"p":"63545.33000000","q":"0.00009000","T":1783465200347,"m":true,"M":true}}
{"stream":"btcusdt@trade","data":{"e":"trade","E":1783465200348,"s":"BTCUSDT","t":6486989882,"p":"63545.33000000","q":"0.00009000","T":1783465200347,"m":true,"M":true}}
{"stream":"btcusdt@trade","data":{"e":"trade","E":1783465200348,"s":"BTCUSDT","t":6486989883,"p":"63545.33000000","q":"0.00009000","T":1783465200347,"m":true,"M":true}}
{"stream":"btcusdt@trade","data":{"e":"trade","E":1783465200348,"s":"BTCUSDT","t":6486989884,"p":"63545.33000000","q":"0.00009000","T":1783465200347,"m":true,"M":true}}
{"stream":"btcusdt@trade","data":{"e":"trade","E":1783465200348,"s":"BTCUSDT","t":6486989885,"p":"63545.33000000","q":"0.00009000","T":1783465200347,"m":true,"M":true}}
{"stream":"btcusdt@trade","data":{"e":"trade","E":1783465200348,"s":"BTCUSDT","t":6486989886,"p":"63545.33000000","q":"0.00009000","T":1783465200347,"m":true,"M":true}}
{"stream":"btcusdt@trade","data":{"e":"trade","E":1783465200348,"s":"BTCUSDT","t":6486989887,"p":"63545.33000000","q":"0.00009000","T":1783465200347,"m":true,"M":true}}
{"stream":"btcusdt@trade","data":{"e":"trade","E":1783465200348,"s":"BTCUSDT","t":6486989888,"p":"63545.33000000","q":"0.00008000","T":1783465200347,"m":true,"M":true}}
{"stream":"btcusdt@trade","data":{"e":"trade","E":1783465200348,"s":"BTCUSDT","t":6486989889,"p":"63545.33000000","q":"0.00009000","T":1783465200347,"m":true,"M":true}}
{"stream":"btcusdt@trade","data":{"e":"trade","E":1783465200348,"s":"BTCUSDT","t":6486989890,"p":"63545.33000000","q":"0.00009000","T":1783465200347,"m":true,"M":true}}
{"stream":"btcusdt@trade","data":{"e":"trade","E":1783465200348,"s":"BTCUSDT","t":6486989891,"p":"63545.33000000","q":"0.00009000","T":1783465200347,"m":true,"M":true}}
{"stream":"btcusdt@trade","data":{"e":"trade","E":1783465200348,"s":"BTCUSDT","t":6486989892,"p":"63545.33000000","q":"0.00008000","T":1783465200347,"m":true,"M":true}}
{"stream":"btcusdt@trade","data":{"e":"trade","E":1783465200348,"s":"BTCUSDT","t":6486989893,"p":"63545.33000000","q":"0.00009000","T":1783465200347,"m":true,"M":true}}
{"stream":"btcusdt@trade","data":{"e":"trade","E":1783465200348,"s":"BTCUSDT","t":6486989894,"p":"63545.33000000","q":"0.00786000","T":1783465200347,"m":true,"M":true}}
{"stream":"btcusdt@trade","data":{"e":"trade","E":1783465200348,"s":"BTCUSDT","t":6486989895,"p":"63545.33000000","q":"0.00009000","T":1783465200347,"m":true,"M":true}}
{"stream":"btcusdt@trade","data":{"e":"trade","E":1783465200348,"s":"BTCUSDT","t":6486989896,"p":"63545.33000000","q":"0.00009000","T":1783465200347,"m":true,"M":true}}
{"stream":"btcusdt@trade","data":{"e":"trade","E":1783465200348,"s":"BTCUSDT","t":6486989897,"p":"63545.33000000","q":"0.00009000","T":1783465200347,"m":true,"M":true}}
{"stream":"btcusdt@trade","data":{"e":"trade","E":1783465200348,"s":"BTCUSDT","t":6486989898,"p":"63545.33000000","q":"0.00008000","T":1783465200347,"m":true,"M":true}}
{"stream":"btcusdt@trade","data":{"e":"trade","E":1783465200348,"s":"BTCUSDT","t":6486989899,"p":"63545.33000000","q":"0.00008000","T":1783465200347,"m":true,"M":true}}
{"stream":"btcusdt@trade","data":{"e":"trade","E":1783465200348,"s":"BTCUSDT","t":6486989900,"p":"63545.33000000","q":"0.00008000","T":1783465200347,"m":true,"M":true}}
{"stream":"btcusdt@trade","data":{"e":"trade","E":1783465200348,"s":"BTCUSDT","t":6486989901,"p":"63545.32000000","q":"0.00009000","T":1783465200347,"m":true,"M":true}}
{"stream":"btcusdt@trade","data":{"e":"trade","E":1783465200348,"s":"BTCUSDT","t":6486989902,"p":"63545.32000000","q":"0.00009000","T":1783465200347,"m":true,"M":true}}
{"stream":"btcusdt@trade","data":{"e":"trade","E":1783465200348,"s":"BTCUSDT","t":6486989903,"p":"63545.32000000","q":"0.00009000","T":1783465200347,"m":true,"M":true}}
{"stream":"btcusdt@trade","data":{"e":"trade","E":1783465200348,"s":"BTCUSDT","t":6486989904,"p":"63545.32000000","q":"0.00009000","T":1783465200347,"m":true,"M":true}}
{"stream":"btcusdt@trade","data":{"e":"trade","E":1783465200348,"s":"BTCUSDT","t":6486989905,"p":"63545.32000000","q":"0.00009000","T":1783465200347,"m":true,"M":true}}
{"stream":"btcusdt@trade","data":{"e":"trade","E":1783465200348,"s":"BTCUSDT","t":6486989906,"p":"63545.32000000","q":"0.00009000","T":1783465200347,"m":true,"M":true}}
{"stream":"btcusdt@trade","data":{"e":"trade","E":1783465200348,"s":"BTCUSDT","t":6486989907,"p":"63545.32000000","q":"0.00009000","T":1783465200347,"m":true,"M":true}}
{"stream":"btcusdt@trade","data":{"e":"trade","E":1783465200348,"s":"BTCUSDT","t":6486989908,"p":"63545.32000000","q":"0.00009000","T":1783465200347,"m":true,"M":true}}
{"stream":"btcusdt@trade","data":{"e":"trade","E":1783465200348,"s":"BTCUSDT","t":6486989909,"p":"63545.32000000","q":"0.00009000","T":1783465200347,"m":true,"M":true}}
{"stream":"btcusdt@trade","data":{"e":"trade","E":1783465200348,"s":"BTCUSDT","t":6486989910,"p":"63545.26000000","q":"0.00008000","T":1783465200347,"m":true,"M":true}}
{"stream":"btcusdt@trade","data":{"e":"trade","E":1783465200348,"s":"BTCUSDT","t":6486989911,"p":"63545.04000000","q":"0.00009000","T":1783465200347,"m":true,"M":true}}
{"stream":"btcusdt@trade","data":{"e":"trade","E":1783465200348,"s":"BTCUSDT","t":6486989912,"p":"63544.84000000","q":"0.00009000","T":1783465200347,"m":true,"M":true}}
{"stream":"btcusdt@trade","data":{"e":"trade","E":1783465200348,"s":"BTCUSDT","t":6486989913,"p":"63544.84000000","q":"0.00009000","T":1783465200347,"m":true,"M":true}}
{"stream":"btcusdt@trade","data":{"e":"trade","E":1783465200348,"s":"BTCUSDT","t":6486989914,"p":"63544.84000000","q":"0.00009000","T":1783465200347,"m":true,"M":true}}
{"stream":"btcusdt@trade","data":{"e":"trade","E":1783465200348,"s":"BTCUSDT","t":6486989915,"p":"63544.83000000","q":"0.04826000","T":1783465200347,"m":true,"M":true}}
{"stream":"btcusdt@trade","data":{"e":"trade","E":1783465200348,"s":"BTCUSDT","t":6486989916,"p":"63544.83000000","q":"0.02000000","T":1783465200347,"m":true,"M":true}}
{"stream":"btcusdt@trade","data":{"e":"trade","E":1783465200348,"s":"BTCUSDT","t":6486989917,"p":"63544.83000000","q":"0.02304000","T":1783465200347,"m":true,"M":true}}
{"stream":"btcusdt@trade","data":{"e":"trade","E":1783465200348,"s":"BTCUSDT","t":6486989918,"p":"63544.83000000","q":"0.00009000","T":1783465200347,"m":true,"M":true}}
{"stream":"btcusdt@trade","data":{"e":"trade","E":1783465200348,"s":"BTCUSDT","t":6486989919,"p":"63544.83000000","q":"0.00009000","T":1783465200347,"m":true,"M":true}}
{"stream":"btcusdt@trade","data":{"e":"trade","E":1783465200348,"s":"BTCUSDT","t":6486989920,"p":"63544.83000000","q":"0.00008000","T":1783465200347,"m":true,"M":true}}
{"stream":"btcusdt@trade","data":{"e":"trade","E":1783465200348,"s":"BTCUSDT","t":6486989921,"p":"63544.83000000","q":"0.00008000","T":1783465200347,"m":true,"M":true}}
{"stream":"btcusdt@trade","data":{"e":"trade","E":1783465200348,"s":"BTCUSDT","t":6486989922,"p":"63544.78000000","q":"0.00008000","T":1783465200347,"m":true,"M":true}}
{"stream":"btcusdt@trade","data":{"e":"trade","E":1783465200348,"s":"BTCUSDT","t":6486989923,"p":"63544.78000000","q":"0.00009000","T":1783465200347,"m":true,"M":true}}
{"stream":"btcusdt@trade","data":{"e":"trade","E":1783465200348,"s":"BTCUSDT","t":6486989924,"p":"63544.78000000","q":"0.00009000","T":1783465200347,"m":true,"M":true}}
{"stream":"btcusdt@trade","data":{"e":"trade","E":1783465200348,"s":"BTCUSDT","t":6486989925,"p":"63544.78000000","q":"0.00008000","T":1783465200347,"m":true,"M":true}}
{"stream":"btcusdt@trade","data":{"e":"trade","E":1783465200348,"s":"BTCUSDT","t":6486989926,"p":"63544.75000000","q":"0.00032000","T":1783465200347,"m":true,"M":true}}
{"stream":"btcusdt@trade","data":{"e":"trade","E":1783465200348,"s":"BTCUSDT","t":6486989927,"p":"63544.54000000","q":"0.01000000","T":1783465200347,"m":true,"M":true}}
{"stream":"btcusdt@trade","data":{"e":"trade","E":1783465200348,"s":"BTCUSDT","t":6486989928,"p":"63544.54000000","q":"0.00009000","T":1783465200347,"m":true,"M":true}}
{"stream":"btcusdt@trade","data":{"e":"trade","E":1783465200348,"s":"BTCUSDT","t":6486989929,"p":"63544.54000000","q":"0.00009000","T":1783465200347,"m":true,"M":true}}
{"stream":"btcusdt@trade","data":{"e":"trade","E":1783465200348,"s":"BTCUSDT","t":6486989930,"p":"63544.44000000","q":"0.00578000","T":1783465200347,"m":true,"M":true}}
{"stream":"btcusdt@trade","data":{"e":"trade","E":1783465200389,"s":"BTCUSDT","t":6486989931,"p":"63544.44000000","q":"0.00008000","T":1783465200388,"m":true,"M":true}}
{"stream":"btcusdt@trade","data":{"e":"trade","E":1783465200389,"s":"BTCUSDT","t":6486989932,"p":"63544.44000000","q":"0.00008000","T":1783465200388,"m":true,"M":true}}
{"stream":"btcusdt@trade","data":{"e":"trade","E":1783465200389,"s":"BTCUSDT","t":6486989933,"p":"63544.44000000","q":"0.00009000","T":1783465200388,"m":true,"M":true}}
{"stream":"btcusdt@trade","data":{"e":"trade","E":1783465200389,"s":"BTCUSDT","t":6486989934,"p":"63544.44000000","q":"0.00009000","T":1783465200388,"m":true,"M":true}}
{"stream":"btcusdt@trade","data":{"e":"trade","E":1783465200389,"s":"BTCUSDT","t":6486989935,"p":"63544.44000000","q":"0.00009000","T":1783465200388,"m":true,"M":true}}
{"stream":"btcusdt@trade","data":{"e":"trade","E":1783465200389,"s":"BTCUSDT","t":6486989936,"p":"63544.44000000","q":"0.00009000","T":1783465200388,"m":true,"M":true}}
{"stream":"btcusdt@trade","data":{"e":"trade","E":1783465200389,"s":"BTCUSDT","t":6486989937,"p":"63544.44000000","q":"0.00009000","T":1783465200388,"m":true,"M":true}}
{"stream":"btcusdt@trade","data":{"e":"trade","E":1783465200389,"s":"BTCUSDT","t":6486989938,"p":"63544.44000000","q":"0.00009000","T":1783465200388,"m":true,"M":true}}
{"stream":"btcusdt@trade","data":{"e":"trade","E":1783465200389,"s":"BTCUSDT","t":6486989939,"p":"63544.44000000","q":"0.00009000","T":1783465200388,"m":true,"M":true}}
{"stream":"btcusdt@trade","data":{"e":"trade","E":1783465200389,"s":"BTCUSDT","t":6486989940,"p":"63544.44000000","q":"0.00008000","T":1783465200388,"m":true,"M":true}}
{"stream":"btcusdt@trade","data":{"e":"trade","E":1783465200389,"s":"BTCUSDT","t":6486989941,"p":"63544.44000000","q":"0.00009000","T":1783465200388,"m":true,"M":true}}
{"stream":"btcusdt@trade","data":{"e":"trade","E":1783465200389,"s":"BTCUSDT","t":6486989942,"p":"63544.44000000","q":"0.00009000","T":1783465200388,"m":true,"M":true}}
{"stream":"btcusdt@trade","data":{"e":"trade","E":1783465200389,"s":"BTCUSDT","t":6486989943,"p":"63544.44000000","q":"0.00009000","T":1783465200388,"m":true,"M":true}}
{"stream":"btcusdt@trade","data":{"e":"trade","E":1783465200389,"s":"BTCUSDT","t":6486989944,"p":"63544.44000000","q":"0.00009000","T":1783465200388,"m":true,"M":true}}
{"stream":"btcusdt@trade","data":{"e":"trade","E":1783465200389,"s":"BTCUSDT","t":6486989945,"p":"63544.44000000","q":"0.00008000","T":1783465200388,"m":true,"M":true}}
{"stream":"btcusdt@trade","data":{"e":"trade","E":1783465200389,"s":"BTCUSDT","t":6486989946,"p":"63544.44000000","q":"0.00008000","T":1783465200388,"m":true,"M":true}}
{"stream":"btcusdt@trade","data":{"e":"trade","E":1783465200389,"s":"BTCUSDT","t":6486989947,"p":"63544.43000000","q":"0.00009000","T":1783465200388,"m":true,"M":true}}
{"stream":"btcusdt@trade","data":{"e":"trade","E":1783465200389,"s":"BTCUSDT","t":6486989948,"p":"63544.43000000","q":"0.00009000","T":1783465200388,"m":true,"M":true}}
{"stream":"btcusdt@trade","data":{"e":"trade","E":1783465200389,"s":"BTCUSDT","t":6486989949,"p":"63544.43000000","q":"0.00009000","T":1783465200388,"m":true,"M":true}}
{"stream":"btcusdt@trade","data":{"e":"trade","E":1783465200389,"s":"BTCUSDT","t":6486989950,"p":"63544.43000000","q":"0.00009000","T":1783465200388,"m":true,"M":true}}
{"stream":"btcusdt@trade","data":{"e":"trade","E":1783465200389,"s":"BTCUSDT","t":6486989951,"p":"63544.43000000","q":"0.00009000","T":1783465200388,"m":true,"M":true}}
{"stream":"btcusdt@trade","data":{"e":"trade","E":1783465200389,"s":"BTCUSDT","t":6486989952,"p":"63544.43000000","q":"0.00009000","T":1783465200388,"m":true,"M":true}}
{"stream":"btcusdt@trade","data":{"e":"trade","E":1783465200389,"s":"BTCUSDT","t":6486989953,"p":"63544.43000000","q":"0.00009000","T":1783465200388,"m":true,"M":true}}
{"stream":"btcusdt@trade","data":{"e":"trade","E":1783465200389,"s":"BTCUSDT","t":6486989954,"p":"63544.43000000","q":"0.00009000","T":1783465200388,"m":true,"M":true}}
{"stream":"btcusdt@trade","data":{"e":"trade","E":1783465200389,"s":"BTCUSDT","t":6486989955,"p":"63544.43000000","q":"0.00009000","T":1783465200388,"m":true,"M":true}}
{"stream":"btcusdt@trade","data":{"e":"trade","E":1783465200389,"s":"BTCUSDT","t":6486989956,"p":"63544.37000000","q":"0.00008000","T":1783465200388,"m":true,"M":true}}
{"stream":"btcusdt@trade","data":{"e":"trade","E":1783465200389,"s":"BTCUSDT","t":6486989957,"p":"63544.01000000","q":"0.00009000","T":1783465200388,"m":true,"M":true}}
{"stream":"btcusdt@trade","data":{"e":"trade","E":1783465200389,"s":"BTCUSDT","t":6486989958,"p":"63544.01000000","q":"0.00009000","T":1783465200388,"m":true,"M":true}}
{"stream":"btcusdt@trade","data":{"e":"trade","E":1783465200389,"s":"BTCUSDT","t":6486989959,"p":"63544.01000000","q":"0.00009000","T":1783465200388,"m":true,"M":true}}
{"stream":"btcusdt@trade","data":{"e":"trade","E":1783465200389,"s":"BTCUSDT","t":6486989960,"p":"63544.00000000","q":"0.00900000","T":1783465200388,"m":true,"M":true}}
{"stream":"btcusdt@trade","data":{"e":"trade","E":1783465200389,"s":"BTCUSDT","t":6486989961,"p":"63544.00000000","q":"0.00800000","T":1783465200388,"m":true,"M":true}}
{"stream":"btcusdt@trade","data":{"e":"trade","E":1783465200389,"s":"BTCUSDT","t":6486989962,"p":"63544.00000000","q":"0.00500000","T":1783465200388,"m":true,"M":true}}
{"stream":"btcusdt@trade","data":{"e":"trade","E":1783465200389,"s":"BTCUSDT","t":6486989963,"p":"63544.00000000","q":"0.00600000","T":1783465200388,"m":true,"M":true}}
{"stream":"btcusdt@trade","data":{"e":"trade","E":1783465200389,"s":"BTCUSDT","t":6486989964,"p":"63544.00000000","q":"0.00009000","T":1783465200388,"m":true,"M":true}}
{"stream":"btcusdt@trade","data":{"e":"trade","E":1783465200389,"s":"BTCUSDT","t":6486989965,"p":"63544.00000000","q":"0.00009000","T":1783465200388,"m":true,"M":true}}
{"stream":"btcusdt@trade","data":{"e":"trade","E":1783465200389,"s":"BTCUSDT","t":6486989966,"p":"63543.88000000","q":"0.00009000","T":1783465200388,"m":true,"M":true}}
{"stream":"btcusdt@trade","data":{"e":"trade","E":1783465200389,"s":"BTCUSDT","t":6486989967,"p":"63543.88000000","q":"0.00009000","T":1783465200388,"m":true,"M":true}}
{"stream":"btcusdt@trade","data":{"e":"trade","E":1783465200389,"s":"BTCUSDT","t":6486989968,"p":"63543.84000000","q":"0.00009000","T":1783465200388,"m":true,"M":true}}
{"stream":"btcusdt@trade","data":{"e":"trade","E":1783465200389,"s":"BTCUSDT","t":6486989969,"p":"63543.84000000","q":"0.00009000","T":1783465200388,"m":true,"M":true}}
{"stream":"btcusdt@trade","data":{"e":"trade","E":1783465200389,"s":"BTCUSDT","t":6486989970,"p":"63543.82000000","q":"0.00009000","T":1783465200388,"m":true,"M":true}}
{"stream":"btcusdt@trade","data":{"e":"trade","E":1783465200389,"s":"BTCUSDT","t":6486989971,"p":"63543.82000000","q":"0.00009000","T":1783465200388,"m":true,"M":true}}
{"stream":"btcusdt@trade","data":{"e":"trade","E":1783465200389,"s":"BTCUSDT","t":6486989972,"p":"63543.81000000","q":"0.00009000","T":1783465200388,"m":true,"M":true}}
{"stream":"btcusdt@trade","data":{"e":"trade","E":1783465200389,"s":"BTCUSDT","t":6486989973,"p":"63543.81000000","q":"0.00009000","T":1783465200388,"m":true,"M":true}}
{"stream":"btcusdt@trade","data":{"e":"trade","E":1783465200389,"s":"BTCUSDT","t":6486989974,"p":"63543.81000000","q":"0.00009000","T":1783465200388,"m":true,"M":true}}
{"stream":"btcusdt@trade","data":{"e":"trade","E":1783465200389,"s":"BTCUSDT","t":6486989975,"p":"63543.80000000","q":"0.00236000","T":1783465200388,"m":true,"M":true}}
{"stream":"btcusdt@trade","data":{"e":"trade","E":1783465200389,"s":"BTCUSDT","t":6486989976,"p":"63543.80000000","q":"0.00610000","T":1783465200388,"m":true,"M":true}}
{"stream":"btcusdt@trade","data":{"e":"trade","E":1783465200389,"s":"BTCUSDT","t":6486989977,"p":"63543.80000000","q":"0.01000000","T":1783465200389,"m":true,"M":true}}
{"stream":"btcusdt@trade","data":{"e":"trade","E":1783465200389,"s":"BTCUSDT","t":6486989978,"p":"63543.80000000","q":"0.00514000","T":1783465200389,"m":true,"M":true}}
{"stream":"btcusdt@trade","data":{"e":"trade","E":1783465200389,"s":"BTCUSDT","t":6486989979,"p":"63543.80000000","q":"0.00009000","T":1783465200389,"m":true,"M":true}}
{"stream":"btcusdt@trade","data":{"e":"trade","E":1783465200389,"s":"BTCUSDT","t":6486989980,"p":"63543.80000000","q":"0.00009000","T":1783465200389,"m":true,"M":true}}
{"stream":"btcusdt@trade","data":{"e":"trade","E":1783465200389,"s":"BTCUSDT","t":6486989981,"p":"63543.79000000","q":"0.00009000","T":1783465200389,"m":true,"M":true}}
{"stream":"btcusdt@trade","data":{"e":"trade","E":1783465200389,"s":"BTCUSDT","t":6486989982,"p":"63543.79000000","q":"0.00009000","T":1783465200389,"m":true,"M":true}}
{"stream":"btcusdt@trade","data":{"e":"trade","E":1783465200389,"s":"BTCUSDT","t":6486989983,"p":"63543.58000000","q":"0.00031000","T":1783465200389,"m":true,"M":true}}
{"stream":"btcusdt@trade","data":{"e":"trade","E":1783465200389,"s":"BTCUSDT","t":6486989984,"p":"63542.84000000","q":"0.00032000","T":1783465200389,"m":true,"M":true}}
{"stream":"btcusdt@trade","data":{"e":"trade","E":1783465200389,"s":"BTCUSDT","t":6486989985,"p":"63542.65000000","q":"0.00009000","T":1783465200389,"m":true,"M":true}}
{"stream":"btcusdt@trade","data":{"e":"trade","E":1783465200389,"s":"BTCUSDT","t":6486989986,"p":"63542.39000000","q":"0.00012000","T":1783465200389,"m":true,"M":true}}
{"stream":"btcusdt@trade","data":{"e":"trade","E":1783465200389,"s":"BTCUSDT","t":6486989987,"p":"63542.16000000","q":"0.00009000","T":1783465200389,"m":true,"M":true}}
{"stream":"btcusdt@trade","data":{"e":"trade","E":1783465200389,"s":"BTCUSDT","t":6486989988,"p":"63542.13000000","q":"0.00008000","T":1783465200389,"m":true,"M":true}}
{"stream":"btcusdt@trade","data":{"e":"trade","E":1783465200389,"s":"BTCUSDT","t":6486989989,"p":"63542.03000000","q":"0.07349000","T":1783465200389,"m":true,"M":true}}
{"stream":"btcusdt@trade","data":{"e":"trade","E":1783465200389,"s":"BTCUSDT","t":6486989990,"p":"63542.03000000","q":"0.01723000","T":1783465200389,"m":true,"M":true}}
{"stream":"btcusdt@trade","data":{"e":"trade","E":1783465200389,"s":"BTCUSDT","t":6486989991,"p":"63542.01000000","q":"0.00009000","T":1783465200389,"m":true,"M":true}}
{"stream":"btcusdt@trade","data":{"e":"trade","E":1783465200389,"s":"BTCUSDT","t":6486989992,"p":"63542.00000000","q":"0.00268000","T":1783465200389,"m":true,"M":true}}
{"stream":"ethusdt@trade","data":{"e":"trade","E":1783465200392,"s":"ETHUSDT","t":4197008702,"p":"1775.21000000","q":"0.00300000","T":1783465200391,"m":true,"M":true}}
{"stream":"ethusdt@trade","data":{"e":"trade","E":1783465200392,"s":"ETHUSDT","t":4197008703,"p":"1775.21000000","q":"0.00290000","T":1783465200391,"m":true,"M":true}}
{"stream":"ethusdt@trade","data":{"e":"trade","E":1783465200392,"s":"ETHUSDT","t":4197008704,"p":"1775.21000000","q":"0.00290000","T":1783465200391,"m":true,"M":true}}
{"stream":"ethusdt@trade","data":{"e":"trade","E":1783465200392,"s":"ETHUSDT","t":4197008705,"p":"1775.21000000","q":"0.00290000","T":1783465200391,"m":true,"M":true}}
{"stream":"ethusdt@trade","data":{"e":"trade","E":1783465200392,"s":"ETHUSDT","t":4197008706,"p":"1775.21000000","q":"0.00290000","T":1783465200391,"m":true,"M":true}}
{"stream":"ethusdt@trade","data":{"e":"trade","E":1783465200392,"s":"ETHUSDT","t":4197008707,"p":"1775.21000000","q":"0.00290000","T":1783465200391,"m":true,"M":true}}
{"stream":"ethusdt@trade","data":{"e":"trade","E":1783465200392,"s":"ETHUSDT","t":4197008708,"p":"1775.21000000","q":"0.00290000","T":1783465200391,"m":true,"M":true}}
{"stream":"ethusdt@trade","data":{"e":"trade","E":1783465200392,"s":"ETHUSDT","t":4197008709,"p":"1775.21000000","q":"0.00290000","T":1783465200391,"m":true,"M":true}}
{"stream":"ethusdt@trade","data":{"e":"trade","E":1783465200392,"s":"ETHUSDT","t":4197008710,"p":"1775.21000000","q":"0.00290000","T":1783465200391,"m":true,"M":true}}
{"stream":"ethusdt@trade","data":{"e":"trade","E":1783465200392,"s":"ETHUSDT","t":4197008711,"p":"1775.20000000","q":"0.00290000","T":1783465200391,"m":true,"M":true}}
{"stream":"ethusdt@trade","data":{"e":"trade","E":1783465200392,"s":"ETHUSDT","t":4197008712,"p":"1775.20000000","q":"0.00300000","T":1783465200391,"m":true,"M":true}}
{"stream":"ethusdt@trade","data":{"e":"trade","E":1783465200392,"s":"ETHUSDT","t":4197008713,"p":"1775.19000000","q":"0.00290000","T":1783465200391,"m":true,"M":true}}
{"stream":"ethusdt@trade","data":{"e":"trade","E":1783465200392,"s":"ETHUSDT","t":4197008714,"p":"1775.19000000","q":"0.00300000","T":1783465200391,"m":true,"M":true}}
{"stream":"ethusdt@trade","data":{"e":"trade","E":1783465200392,"s":"ETHUSDT","t":4197008715,"p":"1775.17000000","q":"0.00300000","T":1783465200391,"m":true,"M":true}}
{"stream":"ethusdt@trade","data":{"e":"trade","E":1783465200392,"s":"ETHUSDT","t":4197008716,"p":"1775.16000000","q":"0.00400000","T":1783465200391,"m":true,"M":true}}
{"stream":"ethusdt@trade","data":{"e":"trade","E":1783465200392,"s":"ETHUSDT","t":4197008717,"p":"1775.16000000","q":"0.00300000","T":1783465200391,"m":true,"M":true}}
{"stream":"ethusdt@trade","data":{"e":"trade","E":1783465200392,"s":"ETHUSDT","t":4197008718,"p":"1775.15000000","q":"0.00300000","T":1783465200391,"m":true,"M":true}}
{"stream":"ethusdt@trade","data":{"e":"trade","E":1783465200392,"s":"ETHUSDT","t":4197008719,"p":"1775.14000000","q":"0.00840000","T":1783465200391,"m":true,"M":true}}
{"stream":"ethusdt@trade","data":{"e":"trade","E":1783465200392,"s":"ETHUSDT","t":4197008720,"p":"1775.14000000","q":"0.00300000","T":1783465200391,"m":true,"M":true}}
{"stream":"ethusdt@trade","data":{"e":"trade","E":1783465200392,"s":"ETHUSDT","t":4197008721,"p":"1775.13000000","q":"0.00840000","T":1783465200391,"m":true,"M":true}}
{"stream":"ethusdt@trade","data":{"e":"trade","E":1783465200392,"s":"ETHUSDT","t":4197008722,"p":"1775.13000000","q":"0.00300000","T":1783465200391,"m":true,"M":true}}
{"stream":"ethusdt@trade","data":{"e":"trade","E":1783465200392,"s":"ETHUSDT","t":4197008723,"p":"1775.12000000","q":"0.00290000","T":1783465200391,"m":true,"M":true}}
{"stream":"ethusdt@trade","data":{"e":"trade","E":1783465200392,"s":"ETHUSDT","t":4197008724,"p":"1775.12000000","q":"0.00300000","T":1783465200391,"m":true,"M":true}}
{"stream":"ethusdt@trade","data":{"e":"trade","E":1783465200392,"s":"ETHUSDT","t":4197008725,"p":"1775.12000000","q":"0.00300000","T":1783465200391,"m":true,"M":true}}
{"stream":"ethusdt@trade","data":{"e":"trade","E":1783465200392,"s":"ETHUSDT","t":4197008726,"p":"1775.11000000","q":"0.00300000","T":1783465200391,"m":true,"M":true}}
{"stream":"ethusdt@trade","data":{"e":"trade","E":1783465200392,"s":"ETHUSDT","t":4197008727,"p":"1775.10000000","q":"0.00300000","T":1783465200391,"m":true,"M":true}}
{"stream":"ethusdt@trade","data":{"e":"trade","E":1783465200392,"s":"ETHUSDT","t":4197008728,"p":"1775.10000000","q":"0.00300000","T":1783465200391,"m":true,"M":true}}
{"stream":"ethusdt@trade","data":{"e":"trade","E":1783465200392,"s":"ETHUSDT","t":4197008729,"p":"1775.10000000","q":"0.00300000","T":1783465200391,"m":true,"M":true}}
{"stream":"btcusdt@trade","data":{"e":"trade","E":1783465200407,"s":"BTCUSDT","t":6486989993,"p":"63542.01000000","q":"0.00017000","T":1783465200407,"m":false,"M":true}}
{"stream":"btcusdt@depth@100ms","data":{"e":"depthUpdate","E":1783465200414,"s":"BTCUSDT","U":97109089582,"u":97109091408,"b":[["63551.02000000","0.00000000"],["63551.01000000","0.00000000"],["63551.00000000","0.00000000"],["63550.47000000","0.00000000"],["63550.01000000","0.00000000"],["63550.00000000","0.00000000"],["63549.13000000","0.00000000"],["63548.99000000","0.00000000"],["63548.56000000","0.00000000"],["63548.39000000","0.00000000"],["63548.23000000","0.00000000"],["63548.01000000","0.00000000"],["63548.00000000","0.00000000"],["63547.90000000","0.00000000"],["63547.84000000","0.00000000"],["63547.74000000","0.00000000"],["63547.57000000","0.00000000"],["63546.86000000","0.00000000"],["63546.83000000","0.00000000"],["63546.67000000","0.00000000"],["63546.65000000","0.00000000"],["63546.38000000","0.00000000"],["63546.01000000","0.00000000"],["63546.00000000","0.00000000"],["63545.83000000","0.00000000"],["63545.82000000","0.00000000"],["63545.51000000","0.00000000"],["63545.34000000","0.00000000"],["63545.33000000","0.00000000"],["63545.32000000","0.00000000"],["63545.26000000","0.00000000"],["63545.12000000","0.00000000"],["63545.04000000","0.00000000"],["63544.84000000","0.00000000"],["63544.83000000","0.00000000"],["63544.79000000","0.00000000"],["63544.78000000","0.00000000"],["63544.77000000","0.00000000"],["63544.75000000","0.00000000"],["63544.66000000","0.00000000"],["63544.54000000","0.00000000"],["63544.52000000","0.00000000"],["63544.44000000","0.00000000"],["63544.43000000","0.00000000"],["63544.37000000","0.00000000"],["63544.35000000","0.00000000"],["63544.29000000","0.00000000"],["63544.01000000","0.00000000"],["63544.00000000","0.00000000"],["63543.88000000","0.00000000"],["63543.84000000","0.00000000"],["63543.83000000","0.00000000"],["63543.82000000","0.00000000"],["63543.81000000","0.00000000"],["63543.80000000","0.00000000"],["63543.79000000","0.00000000"],["63543.77000000","0.00000000"],["63543.76000000","0.00000000"],["63543.65000000","0.00000000"],["63543.58000000","0.00000000"],["63543.15000000","0.00000000"],["63543.13000000","0.00000000"],["63542.84000000","0.00000000"],["63542.77000000","0.00000000"],["63542.76000000","0.00000000"],["63542.74000000","0.00000000"],["63542.70000000","0.00000000"],["63542.65000000","0.00000000"],["63542.59000000","0.00000000"],["63542.39000000","0.00000000"],["63542.16000000","0.00000000"],["63542.15000000","0.00000000"],["63542.13000000","0.00000000"],["63542.03000000","0.00000000"],["63542.01000000","0.00000000"],["63542.00000000","0.02646000"],["63541.99000000","0.00063000"],["63541.97000000","0.00000000"],["63541.89000000","0.00000000"],["63541.75000000","0.00000000"],["63541.67000000","0.00000000"],["63541.66000000","0.00000000"],["63541.33000000","0.00000000"],["63541.30000000","0.00000000"],["63541.28000000","0.00000000"],["63541.17000000","0.00000000"],["63541.00000000","0.00000000"],["63540.67000000","0.00000000"],["63540.66000000","0.00000000"],["63540.63000000","0.00000000"],["63540.62000000","0.00000000"],["63540.60000000","0.00236000"],["63540.58000000","0.00000000"],["63540.54000000","0.00000000"],["63540.01000000","0.00018000"],["63539.99000000","0.00000000"],["63539.75000000","0.00000000"],["63539.58000000","0.00000000"],["63539.21000000","0.00000000"],["63539.16000000","0.00000000"],["63538.98000000","0.00000000"],["63538.97000000","0.00000000"],["63538.75000000","0.00000000"],["63538.68000000","0.00000000"],["63538.67000000","0.00000000"],["63538.66000000","0.00000000"],["63538.46000000","0.00018000"],["63538.45000000","0.00000000"],["63538.25000000","0.00000000"],["63538.18000000","0.00000000"],["63538.13000000","0.00520000"],["63538.08000000","0.00000000"],["63538.07000000","0.00000000"],["63537.99000000","0.00000000"],["63537.43000000","0.02124000"],["63537.38000000","0.00069000"],["63537.27000000","0.00000000"],["63537.07000000","0.00000000"],["63537.00000000","0.00000000"],["63536.79000000","0.00000000"],["63536.70000000","0.00000000"],["63536.67000000","0.00008000"],["63536.58000000","0.00000000"],["63536.29000000","0.00000000"],["63535.98000000","0.00000000"],["63535.96000000","0.00000000"],["63535.95000000","0.00000000"],["63535.79000000","0.00000000"],["63535.65000000","0.00009000"],["63535.48000000","0.00000000"],["63535.46000000","0.00018000"],["63535.45000000","0.50170000"],["63535.29000000","0.00000000"],["63534.92000000","0.00000000"],["63534.13000000","0.00026000"],["63534.12000000","0.00008000"],["63534.00000000","0.02800000"],["63533.62000000","0.00000000"],["63533.37000000","0.00000000"],["63533.12000000","0.02477000"],["63533.08000000","0.00008000"],["63533.07000000","0.00000000"],["63532.80000000","0.00000000"],["63532.72000000","0.00000000"],["63532.69000000","0.00000000"],["63532.68000000","0.00000000"],["63532.54000000","0.00000000"],["63532.44000000","0.00048000"],["63532.34000000","0.00026000"],["63532.28000000","0.02000000"],["63532.18000000","0.00048000"],["63532.11000000","0.00000000"],["63532.01000000","0.00000000"],["63531.82000000","0.00000000"],["63531.74000000","0.00000000"],["63531.73000000","0.00009000"],["63531.72000000","0.22508000"],["63531.59000000","0.00008000"],["63531.42000000","0.00032000"],["63530.85000000","0.06464000"],["63530.84000000","0.00000000"],["63530.50000000","0.05900000"],["63530.49000000","0.45627000"],["63530.48000000","0.00000000"],["63530.04000000","0.00400000"],["63529.72000000","0.00787000"],["63529.63000000","0.00012000"],["63529.51000000","0.00032000"],["63529.42000000","0.00400000"],["63529.34000000","0.00000000"],["63529.30000000","0.00009000"],["63529.04000000","0.00000000"],["63528.94000000","0.00000000"],["63528.84000000","0.00000000"],["63528.67000000","0.00000000"],["63528.55000000","0.00009000"],["63528.36000000","0.00000000"],["63527.98000000","0.00008000"],["63527.80000000","0.00000000"],["63527.61000000","0.00032000"],["63527.58000000","0.00000000"],["63527.57000000","4.06315000"],["63527.56000000","0.00000000"],["63527.29000000","0.00000000"],["63527.14000000","0.03000000"],["63526.97000000","0.00000000"],["63526.72000000","0.55112000"],["63526.45000000","0.00000000"],["63525.97000000","0.01574000"],["63525.76000000","0.00000000"],["63525.71000000","0.00032000"],["63525.70000000","0.00000000"],["63525.38000000","0.00009000"],["63525.15000000","1.00000000"],["63525.03000000","0.12000000"],["63524.84000000","0.22500000"],["63524.58000000","0.00000000"],["63524.07000000","0.00008000"],["63523.81000000","0.00032000"],["63523.27000000","0.00000000"],["63523.26000000","0.42510000"],["63523.18000000","0.00000000"],["63522.94000000","0.00157000"],["63522.58000000","0.00000000"],["63522.20000000","0.00009000"],["63521.33000000","0.00000000"],["63520.58000000","0.00000000"],["63520.16000000","0.47367000"],["63520.09000000","0.00000000"],["63519.40000000","0.00000000"],["63519.02000000","0.00009000"],["63519.00000000","0.00000000"],["63518.95000000","0.00000000"],["63518.00000000","0.02800000"],["63517.93000000","0.01000000"],["63517.32000000","0.00400000"],["63517.09000000","0.00008000"],["63516.80000000","0.00000000"],["63516.23000000","0.00000000"],["63516.21000000","0.56718000"],["63515.85000000","0.00009000"],["63515.53000000","0.00012000"],["63514.14000000","0.00400000"],["63513.96000000","0.00008000"],["63513.00000000","0.00000000"],["63512.67000000","0.00009000"],["63512.55000000","0.00400000"],["63512.43000000","0.00000000"],["63512.00000000","0.02800000"],["63511.18000000","0.00060000"],["63510.96000000","0.01323000"],["63510.83000000","0.00008000"],["63510.00000000","0.04809000"],["63509.68000000","0.00000000"],["63509.37000000","0.00400000"],["63508.53000000","0.00000000"],["63507.31000000","0.00255000"],["63505.49000000","0.00000000"],["63501.97000000","0.00008000"],["63500.87000000","0.00000000"],["63500.21000000","0.00000000"],["63499.42000000","0.00000000"],["63499.21000000","0.00000000"],["63498.02000000","0.00000000"],["63497.55000000","0.00000000"],["63496.56000000","1.33315000"],["63496.01000000","0.00000000"],["63495.61000000","0.00000000"],["63494.81000000","0.00000000"],["63494.61000000","0.00390000"],["63494.60000000","0.00000000"],["63493.33000000","0.00621000"],["63493.27000000","0.85266000"],["63493.10000000","0.00000000"],["63492.80000000","0.13078000"],["63492.29000000","1.56033000"],["63491.81000000","0.00000000"],["63490.80000000","0.00391000"],["63489.71000000","0.00000000"],["63489.34000000","0.00000000"],["63486.45000000","0.00000000"],["63486.11000000","0.00000000"],["63484.73000000","0.94488000"],["63483.67000000","0.00000000"],["63480.64000000","0.35298000"],["63478.46000000","0.00009000"],["63476.56000000","1.26579000"],["63475.31000000","0.00000000"],["63474.61000000","0.00000000"],["63472.36000000","0.00000000"],["63470.65000000","0.00000000"],["63469.51000000","0.00000000"],["63468.96000000","0.00000000"],["63468.93000000","2.83475000"],["63468.92000000","0.00000000"],["63468.37000000","0.00000000"],["63467.87000000","0.00000000"],["63466.97000000","0.00000000"],["63465.83000000","0.07057000"],["63461.30000000","0.00000000"],["63436.39000000","2.35399000"],["63436.37000000","0.00000000"],["63434.01000000","0.00157000"],["63430.20000000","0.00000000"],["63429.55000000","0.00000000"],["63427.35000000","0.00157000"],["63422.90000000","0.00000000"],["63421.66000000","0.00000000"],["63414.92000000","0.00009000"],["63389.56000000","0.00008000"],["63386.39000000","0.00008000"],["63365.99000000","0.00000000"],["63359.35000000","0.00052000"],["63351.37000000","0.00009000"],["63301.64000000","0.00000000"],["63293.81000000","0.00009000"],["63284.96000000","0.00000000"],["63273.50000000","0.00033000"],["63236.23000000","0.00000000"],["63229.83000000","0.00009000"],["63213.27000000","0.00019000"],["63175.32000000","0.00000000"],["63168.70000000","0.00000000"],["63160.75000000","0.00009000"],["63111.76000000","0.00011000"],["63105.15000000","0.00000000"],["63097.21000000","0.00009000"],["63047.41000000","0.00000000"],["63039.62000000","0.00009000"],["62062.27000000","0.05691000"],["57195.92000000","0.00040000"],["57190.00000000","1.10034000"],["40000.00000000","260.73952000"]],"a":[["63542.01000000","3.94303000"],["63542.02000000","0.00034000"],["63542.03000000","0.00016000"],["63542.13000000","0.00008000"],["63542.16000000","0.00786000"],["63542.17000000","3.69781000"],["63542.29000000","0.00126000"],["63542.76000000","0.00400000"],["63543.26000000","0.00126000"],["63543.77000000","0.12546000"],["63543.80000000","0.00786000"],["63543.81000000","0.00794000"],["63543.83000000","0.00008000"],["63543.85000000","0.00008000"],["63543.89000000","0.00008000"],["63544.01000000","0.00000000"],["63544.02000000","0.00000000"],["63544.30000000","0.00000000"],["63544.35000000","0.00400000"],["63544.36000000","0.00000000"],["63544.38000000","0.00008000"],["63544.44000000","0.07508000"],["63544.45000000","0.86154000"],["63544.46000000","0.00000000"],["63544.47000000","0.00000000"],["63544.55000000","0.00000000"],["63544.67000000","0.00000000"],["63544.76000000","0.00000000"],["63544.78000000","0.00000000"],["63544.79000000","0.00000000"],["63544.80000000","0.00000000"],["63544.82000000","0.00000000"],["63544.83000000","0.45635000"],["63544.84000000","0.00000000"],["63545.00000000","0.00000000"],["63545.05000000","0.00000000"],["63545.13000000","0.00000000"],["63545.26000000","0.00008000"],["63545.27000000","0.00000000"],["63545.33000000","0.66555000"],["63545.34000000","0.49877000"],["63545.35000000","0.00000000"],["63545.36000000","0.00000000"],["63545.52000000","0.00000000"],["63545.74000000","0.00000000"],["63545.83000000","0.00000000"],["63545.84000000","0.00000000"],["63545.92000000","0.00023000"],["63545.94000000","0.00400000"],["63545.98000000","0.00000000"],["63546.00000000","0.35059000"],["63546.01000000","1.45366000"],["63546.02000000","0.00000000"],["63546.39000000","0.00000000"],["63546.51000000","0.00000000"],["63546.66000000","0.00000000"],["63546.68000000","0.00000000"],["63546.84000000","0.00000000"],["63546.87000000","0.00010000"],["63547.05000000","0.00000000"],["63547.37000000","0.00000000"],["63547.53000000","0.00400000"],["63547.57000000","0.00000000"],["63547.58000000","0.13018000"],["63547.59000000","0.00000000"],["63547.60000000","0.00000000"],["63547.75000000","0.00000000"],["63547.85000000","0.00000000"],["63547.91000000","0.00000000"],["63548.00000000","0.07500000"],["63548.01000000","0.15830000"],["63548.02000000","0.00000000"],["63548.24000000","0.00000000"],["63548.36000000","0.00009000"],["63548.37000000","0.00400000"],["63548.39000000","0.00008000"],["63548.40000000","0.00000000"],["63548.57000000","0.00000000"],["63548.63000000","0.13714000"],["63548.64000000","0.00000000"],["63548.90000000","0.00000000"],["63549.00000000","0.00000000"],["63549.05000000","0.00000000"],["63549.12000000","0.00400000"],["63549.13000000","0.00000000"],["63549.14000000","2.83475000"],["63549.49000000","0.00008000"],["63549.68000000","0.04000000"],["63550.00000000","0.00000000"],["63550.01000000","0.22526000"],["63550.02000000","0.00000000"],["63550.04000000","0.00000000"],["63550.31000000","0.00000000"],["63550.48000000","0.00000000"],["63550.63000000","0.00032000"],["63550.71000000","0.00400000"],["63550.81000000","0.00400000"],["63550.94000000","0.00000000"],["63551.00000000","0.00000000"],["63551.01000000","0.78745000"],["63551.02000000","0.02386000"],["63551.03000000","2.98282000"],["63551.04000000","0.00064000"],["63551.05000000","0.00000000"],["63551.51000000","0.00845000"],["63551.66000000","0.00000000"],["63551.67000000","1.68467000"],["63551.69000000","0.00311000"],["63551.70000000","0.00000000"],["63551.71000000","0.00000000"],["63551.75000000","0.00000000"],["63551.84000000","0.00000000"],["63551.88000000","0.00000000"],["63552.03000000","0.00008000"],["63552.38000000","0.00008000"],["63552.44000000","0.00000000"],["63552.50000000","0.00000000"],["63552.99000000","0.00032000"],["63553.00000000","0.00000000"],["63553.17000000","0.03951000"],["63553.28000000","0.04802000"],["63553.29000000","0.00000000"],["63553.38000000","0.00000000"],["63553.54000000","0.00000000"],["63553.93000000","0.00000000"],["63554.01000000","0.00044000"],["63554.02000000","0.56684000"],["63554.34000000","0.00000000"],["63554.35000000","0.00000000"],["63554.36000000","0.00000000"],["63554.45000000","0.00008000"],["63554.57000000","0.00008000"],["63554.69000000","0.00146000"],["63554.77000000","0.00012000"],["63554.89000000","0.00000000"],["63554.96000000","0.00032000"],["63554.97000000","0.00000000"],["63554.98000000","0.00000000"],["63554.99000000","0.00000000"],["63555.33000000","0.00009000"],["63555.55000000","0.00008000"],["63555.82000000","0.00029000"],["63555.99000000","0.00000000"],["63556.37000000","0.00000000"],["63556.93000000","0.00032000"],["63556.94000000","0.00000000"],["63556.95000000","0.00000000"],["63556.97000000","0.00000000"],["63557.11000000","0.00000000"],["63557.16000000","0.00009000"],["63557.38000000","0.00000000"],["63557.39000000","0.22500000"],["63557.56000000","0.00000000"],["63557.97000000","0.00000000"],["63557.98000000","2.83475000"],["63558.07000000","0.00000000"],["63558.24000000","0.00000000"],["63558.68000000","0.00000000"],["63558.70000000","0.00000000"],["63558.91000000","0.00032000"],["63558.92000000","0.00000000"],["63558.93000000","0.00000000"],["63558.96000000","0.00008000"],["63559.08000000","0.00009000"],["63559.50000000","0.56679000"],["63559.53000000","0.00010000"],["63559.65000000","0.00000000"],["63559.97000000","0.00000000"],["63560.00000000","0.03800000"],["63560.34000000","0.00009000"],["63560.36000000","0.00000000"],["63560.72000000","0.00000000"],["63560.88000000","0.00032000"],["63560.89000000","0.00000000"],["63560.91000000","0.00008000"],["63560.94000000","0.00000000"],["63561.02000000","0.00000000"],["63561.25000000","0.00000000"],["63561.49000000","0.00000000"],["63561.81000000","0.00000000"],["63561.95000000","0.00000000"],["63561.98000000","0.00157000"],["63562.00000000","0.15207000"],["63562.05000000","0.28788000"],["63562.19000000","0.02400000"],["63562.43000000","0.00000000"],["63562.56000000","0.00000000"],["63562.85000000","0.00032000"],["63562.87000000","0.00000000"],["63562.89000000","0.00000000"],["63562.93000000","0.00000000"],["63563.51000000","0.00009000"],["63563.90000000","0.00000000"],["63563.94000000","0.00000000"],["63563.99000000","0.46173000"],["63564.59000000","0.00000000"],["63564.73000000","0.00000000"],["63564.82000000","0.00032000"],["63564.84000000","0.00009000"],["63564.87000000","0.00000000"],["63564.91000000","0.00000000"],["63565.07000000","0.00419000"],["63565.28000000","0.00000000"],["63565.93000000","0.00000000"],["63566.69000000","0.00009000"],["63566.79000000","0.00032000"],["63566.80000000","0.56473000"],["63566.82000000","0.00000000"],["63566.85000000","0.00000000"],["63566.90000000","0.00000000"],["63567.07000000","0.00000000"],["63567.30000000","0.00000000"],["63567.33000000","0.00000000"],["63567.76000000","0.00000000"],["63567.77000000","0.00000000"],["63567.92000000","0.00000000"],["63568.20000000","0.00000000"],["63568.76000000","0.00032000"],["63568.79000000","0.00000000"],["63568.82000000","0.00000000"],["63568.88000000","0.22500000"],["63569.79000000","0.00000000"],["63569.87000000","0.00009000"],["63569.91000000","0.00000000"],["63570.16000000","0.00000000"],["63570.25000000","0.00000000"],["63570.74000000","0.00032000"],["63570.77000000","0.00000000"],["63570.80000000","0.00000000"],["63570.87000000","0.00000000"],["63570.95000000","0.00000000"],["63571.38000000","0.00000000"],["63571.50000000","0.00621000"],["63571.90000000","0.00000000"],["63572.84000000","0.00000000"],["63572.85000000","0.00000000"],["63572.97000000","0.00000000"],["63573.05000000","2.83484000"],["63573.43000000","0.00016000"],["63573.89000000","0.00000000"],["63574.12000000","0.00000000"],["63574.56000000","0.00000000"],["63574.61000000","0.00000000"],["63574.95000000","0.00000000"],["63575.23000000","0.00015000"],["63575.31000000","0.00000000"],["63576.15000000","0.00000000"],["63576.22000000","0.00009000"],["63576.56000000","0.00000000"],["63576.61000000","0.00000000"],["63576.64000000","1.55826000"],["63577.30000000","0.00000000"],["63579.69000000","0.00000000"],["63579.78000000","0.00000000"],["63580.40000000","0.00000000"],["63580.48000000","0.00000000"],["63581.25000000","0.00000000"],["63582.00000000","0.03800000"],["63582.06000000","0.00157000"],["63582.07000000","0.00000000"],["63583.00000000","0.00000000"],["63583.66000000","0.00000000"],["63584.69000000","0.00533000"],["63585.16000000","0.00000000"],["63585.38000000","0.01568000"],["63593.05000000","1.91828000"],["63595.02000000","0.02600000"],["63598.27000000","0.07247000"],["63598.43000000","0.00391000"],["63598.99000000","0.00000000"],["63599.32000000","0.00000000"],["63601.93000000","0.00000000"],["63601.94000000","0.00008000"],["63602.18000000","3.76301000"],["63605.55000000","0.00391000"],["63608.00000000","0.02800000"],["63609.38000000","0.94488000"],["63611.56000000","0.00009000"],["63616.13000000","0.00000000"],["63616.14000000","0.00000000"],["63619.43000000","0.00000000"],["63619.55000000","0.00000000"],["63622.84000000","0.02648000"],["63623.10000000","0.00000000"],["63627.80000000","0.00000000"],["63641.71000000","0.00000000"],["63643.17000000","0.00010000"],["63647.94000000","0.00000000"],["63658.38000000","0.00000000"],["63661.56000000","0.00157000"],["63665.08000000","0.00000000"],["63668.77000000","0.00157000"],["63671.99000000","0.00000000"],["63672.43000000","0.00009000"],["63678.98000000","0.00000000"],["63680.38000000","0.00000000"],["63693.17000000","0.18102000"],["63697.51000000","0.02465000"],["63707.12000000","0.00000000"],["63709.19000000","0.00000000"],["63725.75000000","0.00000000"],["63728.92000000","0.00000000"],["63735.98000000","0.00009000"],["63742.54000000","0.00000000"],["63789.58000000","0.00000000"],["63799.52000000","1.20007000"],["63806.09000000","0.00000000"],["63865.75000000","0.00009000"],["63873.65000000","0.00000000"],["63929.30000000","0.00009000"],["63937.21000000","0.00000000"],["63990.16000000","0.00009000"],["63996.74000000","0.00000000"],["64053.70000000","0.00009000"],["64060.30000000","0.00010000"],["64464.42000000","0.00000000"],["64486.82000000","1.70870000"]]}}
{"stream":"ethusdt@depth@100ms","data":{"e":"depthUpdate","E":1783465200415,"s":"ETHUSDT","U":78545072214,"u":78545072919,"b":[["1775.28000000","0.00000000"],["1775.27000000","0.00000000"],["1775.26000000","0.00000000"],["1775.25000000","0.00000000"],["1775.24000000","0.00000000"],["1775.23000000","0.00000000"],["1775.22000000","0.00000000"],["1775.21000000","0.00000000"],["1775.20000000","0.00000000"],["1775.19000000","0.00000000"],["1775.17000000","0.00000000"],["1775.16000000","0.00000000"],["1775.15000000","0.00000000"],["1775.14000000","0.00000000"],["1775.13000000","0.00000000"],["1775.12000000","0.00000000"],["1775.11000000","0.00000000"],["1775.10000000","0.00000000"],["1775.09000000","10.66790000"],["1775.08000000","0.44870000"],["1775.07000000","0.01330000"],["1775.06000000","0.00600000"],["1775.05000000","0.28580000"],["1775.04000000","0.04190000"],["1775.03000000","0.44600000"],["1775.02000000","0.44840000"],["1775.01000000","0.01220000"],["1775.00000000","0.19900000"],["1774.99000000","0.00730000"],["1774.98000000","0.01580000"],["1774.97000000","0.56080000"],["1774.96000000","0.47280000"],["1774.95000000","0.00580000"],["1774.93000000","2.48640000"],["1774.92000000","0.00950000"],["1774.91000000","0.43700000"],["1774.90000000","0.48700000"],["1774.89000000","0.01320000"],["1774.88000000","1.11550000"],["1774.87000000","4.13080000"],["1774.86000000","0.00290000"],["1774.85000000","0.00290000"],["1774.84000000","6.88940000"],["1774.82000000","0.14660000"],["1774.81000000","0.00430000"],["1774.80000000","0.04030000"],["1774.78000000","0.87710000"],["1774.76000000","0.00290000"],["1774.74000000","0.28470000"],["1774.73000000","1.07060000"],["1774.72000000","7.94380000"],["1774.71000000","34.96210000"],["1774.68000000","0.00000000"],["1774.63000000","17.84600000"],["1774.62000000","0.44440000"],["1774.61000000","14.79550000"],["1774.59000000","16.92130000"],["1774.55000000","1.40180000"],["1774.48000000","0.60990000"],["1774.46000000","1.12940000"],["1774.45000000","0.76620000"],["1774.43000000","10.52810000"],["1774.40000000","0.46990000"],["1774.39000000","9.66180000"],["1774.36000000","15.77250000"],["1774.32000000","0.43290000"],["1774.27000000","0.44980000"],["1774.24000000","10.38250000"],["1774.10000000","0.01130000"],["1773.97000000","0.43990000"],["1773.93000000","0.66350000"],["1773.92000000","0.22600000"],["1773.88000000","4.60540000"],["1773.84000000","9.49180000"],["1773.78000000","0.00580000"],["1773.68000000","24.53110000"],["1773.60000000","16.20660000"],["1773.59000000","0.00000000"],["1773.57000000","0.56240000"],["1773.55000000","0.12140000"],["1773.44000000","27.47570000"],["1773.42000000","9.89880000"],["1773.38000000","0.56950000"],["1773.36000000","8.32920000"],["1773.32000000","0.43990000"],["1773.30000000","2.91200000"],["1773.26000000","0.43700000"],["1773.24000000","0.44540000"],["1773.20000000","0.13540000"],["1773.18000000","0.00740000"],["1773.13000000","7.88480000"],["1773.12000000","15.76960000"],["1772.95000000","13.96810000"],["1772.86000000","0.00000000"],["1772.85000000","7.88480000"],["1772.72000000","7.88940000"],["1772.71000000","18.41160000"],["1772.60000000","0.02000000"],["1771.76000000","35.30490000"],["1770.43000000","0.00290000"],["1770.21000000","0.14680000"],["1770.13000000","0.00720000"],["1770.03000000","0.01410000"],["1767.86000000","0.00000000"],["1766.93000000","8.77730000"],["1597.76000000","0.01400000"],["1597.69000000","0.02530000"]],"a":[["1775.10000000","47.99740000"],["1775.11000000","0.00570000"],["1775.12000000","0.00860000"],["1775.13000000","0.00000000"],["1775.14000000","0.00000000"],["1775.15000000","0.00000000"],["1775.16000000","0.00000000"],["1775.17000000","0.00000000"],["1775.18000000","0.00000000"],["1775.20000000","0.03290000"],["1775.21000000","15.30470000"],["1775.22000000","5.86750000"],["1775.23000000","2.20000000"],["1775.24000000","0.00000000"],["1775.25000000","0.00000000"],["1775.26000000","0.00000000"],["1775.27000000","0.00000000"],["1775.28000000","0.03290000"],["1775.29000000","2.20290000"],["1775.30000000","0.00000000"],["1775.31000000","0.00000000"],["1775.32000000","0.00290000"],["1775.33000000","0.00000000"],["1775.34000000","6.76880000"],["1775.35000000","23.36630000"],["1775.36000000","17.38380000"],["1775.37000000","26.22720000"],["1775.39000000","0.53990000"],["1775.41000000","0.00290000"],["1775.42000000","2.48690000"],["1775.43000000","0.00340000"],["1775.44000000","7.91770000"],["1775.46000000","0.85900000"],["1775.47000000","0.00000000"],["1775.51000000","1.52790000"],["1775.53000000","0.00290000"],["1775.56000000","2.69210000"],["1775.57000000","0.00000000"],["1775.58000000","0.00000000"],["1775.59000000","1.37870000"],["1775.60000000","0.03290000"],["1775.61000000","5.03450000"],["1775.63000000","0.00000000"],["1775.64000000","0.27960000"],["1775.65000000","1.09670000"],["1775.67000000","0.00840000"],["1775.77000000","8.92100000"],["1775.78000000","0.32200000"],["1775.88000000","9.06840000"],["1775.91000000","1.68200000"],["1775.94000000","0.00290000"],["1775.98000000","0.00290000"],["1776.00000000","15.04870000"],["1776.01000000","10.91330000"],["1776.07000000","0.00000000"],["1776.08000000","16.62420000"],["1776.09000000","13.32990000"],["1776.16000000","19.42760000"],["1776.19000000","0.08570000"],["1776.20000000","18.12960000"],["1776.25000000","8.80770000"],["1776.26000000","8.23730000"],["1776.35000000","16.09480000"],["1776.39000000","27.97480000"],["1776.40000000","1.20400000"],["1776.41000000","0.90700000"],["1776.45000000","22.38400000"],["1776.48000000","0.00890000"],["1776.50000000","0.29400000"],["1776.55000000","18.14280000"],["1776.58000000","0.00000000"],["1776.59000000","0.78390000"],["1776.64000000","0.00000000"],["1776.77000000","0.29410000"],["1776.91000000","7.96100000"],["1776.96000000","35.31070000"],["1777.03000000","0.43750000"],["1777.05000000","7.88590000"],["1777.19000000","5.71100000"],["1777.25000000","0.00000000"],["1777.28000000","0.00000000"],["1777.51000000","0.00000000"],["1777.54000000","4.48200000"],["1777.55000000","0.01740000"],["1777.71000000","0.00000000"],["1778.79000000","0.05060000"],["1778.89000000","0.02630000"],["1778.96000000","0.00000000"],["1778.99000000","0.00000000"],["1779.33000000","8.28520000"],["1779.47000000","65.18410000"],["1779.78000000","0.00290000"],["1780.12000000","0.00000000"],["1780.17000000","0.25000000"],["1781.50000000","0.00000000"],["1801.55000000","38.60610000"],["1801.94000000","0.00470000"]]}}
{"stream":"ethusdt@trade","data":{"e":"trade","E":1783465200440,"s":"ETHUSDT","t":4197008730,"p":"1775.09000000","q":"0.00300000","T":1783465200440,"m":true,"M":true}}
{"stream":"ethusdt@trade","data":{"e":"trade","E":1783465200440,"s":"ETHUSDT","t":4197008731,"p":"1775.09000000","q":"0.00300000","T":1783465200440,"m":true,"M":true}}
{"stream":"ethusdt@trade","data":{"e":"trade","E":1783465200440,"s":"ETHUSDT","t":4197008732,"p":"1775.09000000","q":"0.46200000","T":1783465200440,"m":true,"M":true}}
{"stream":"ethusdt@trade","data":{"e":"trade","E":1783465200441,"s":"ETHUSDT","t":4197008733,"p":"1775.09000000","q":"0.46800000","T":1783465200440,"m":true,"M":true}}
{"stream":"btcusdt@trade","data":{"e":"trade","E":1783465200441,"s":"BTCUSDT","t":6486989994,"p":"63542.00000000","q":"0.00632000","T":1783465200441,"m":true,"M":true}}
{"stream":"btcusdt@trade","data":{"e":"trade","E":1783465200441,"s":"BTCUSDT","t":6486989995,"p":"63542.00000000","q":"0.00368000","T":1783465200441,"m":true,"M":true}}
{"stream":"ethusdt@trade","data":{"e":"trade","E":1783465200442,"s":"ETHUSDT","t":4197008734,"p":"1775.09000000","q":"0.46800000","T":1783465200442,"m":true,"M":true}}
{"stream":"ethusdt@trade","data":{"e":"trade","E":1783465200444,"s":"ETHUSDT","t":4197008735,"p":"1775.09000000","q":"0.46800000","T":1783465200443,"m":true,"M":true}}
{"stream":"ethusdt@trade","data":{"e":"trade","E":1783465200476,"s":"ETHUSDT","t":4197008736,"p":"1775.09000000","q":"0.03440000","T":1783465200476,"m":true,"M":true}}
{"stream":"ethusdt@trade","data":{"e":"trade","E":1783465200483,"s":"ETHUSDT","t":4197008737,"p":"1775.09000000","q":"0.00290000","T":1783465200482,"m":true,"M":true}}
{"stream":"ethusdt@trade","data":{"e":"trade","E":1783465200483,"s":"ETHUSDT","t":4197008738,"p":"1775.09000000","q":"0.00300000","T":1783465200482,"m":true,"M":true}}
{"stream":"ethusdt@trade","data":{"e":"trade","E":1783465200483,"s":"ETHUSDT","t":4197008739,"p":"1775.09000000","q":"0.00290000","T":1783465200482,"m":true,"M":true}}
{"stream":"ethusdt@trade","data":{"e":"trade","E":1783465200483,"s":"ETHUSDT","t":4197008740,"p":"1775.09000000","q":"0.00290000","T":1783465200482,"m":true,"M":true}}
{"stream":"ethusdt@trade","data":{"e":"trade","E":1783465200483,"s":"ETHUSDT","t":4197008741,"p":"1775.09000000","q":"0.00290000","T":1783465200482,"m":true,"M":true}}
{"stream":"ethusdt@trade","data":{"e":"trade","E":1783465200483,"s":"ETHUSDT","t":4197008742,"p":"1775.09000000","q":"0.00290000","T":1783465200482,"m":true,"M":true}}
{"stream":"ethusdt@trade","data":{"e":"trade","E":1783465200483,"s":"ETHUSDT","t":4197008743,"p":"1775.09000000","q":"0.00290000","T":1783465200482,"m":true,"M":true}}
{"stream":"ethusdt@trade","data":{"e":"trade","E":1783465200483,"s":"ETHUSDT","t":4197008744,"p":"1775.09000000","q":"0.44760000","T":1783465200482,"m":true,"M":true}}
{"stream":"btcusdt@depth@100ms","data":{"e":"depthUpdate","E":1783465200514,"s":"BTCUSDT","U":97109091409,"u":97109091679,"b":[["63542.00000000","0.10742000"],["63541.99000000","0.00072000"],["63540.00000000","0.03818000"],["63538.72000000","0.00000000"],["63538.46000000","0.00000000"],["63538.13000000","0.00538000"],["63538.01000000","0.00018000"],["63538.00000000","0.02818000"],["63537.44000000","0.00018000"],["63537.43000000","0.02142000"],["63536.40000000","0.00000000"],["63536.01000000","0.00030000"],["63536.00000000","0.02818000"],["63535.64000000","0.00319000"],["63535.47000000","0.00009000"],["63535.46000000","0.06552000"],["63535.45000000","0.50196000"],["63535.42000000","0.00000000"],["63535.05000000","0.04545000"],["63534.95000000","0.00018000"],["63534.81000000","0.00418000"],["63534.62000000","0.00048000"],["63534.13000000","0.00008000"],["63533.60000000","0.06571000"],["63533.12000000","0.00000000"],["63533.01000000","0.00000000"],["63532.55000000","0.06563000"],["63532.28000000","0.00000000"],["63531.87000000","0.04546000"],["63531.73000000","0.06572000"],["63531.04000000","0.01000000"],["63530.82000000","0.00000000"],["63530.51000000","0.00000000"],["63530.49000000","0.00000000"],["63530.37000000","0.01000000"],["63530.09000000","0.00000000"],["63530.03000000","0.06563000"],["63529.88000000","0.00000000"],["63529.75000000","0.01000000"],["63529.34000000","0.00000000"],["63529.32000000","0.00959000"],["63528.91000000","0.01000000"],["63528.83000000","0.00000000"],["63528.69000000","0.03030000"],["63528.35000000","0.06408000"],["63528.28000000","0.02000000"],["63528.13000000","0.00872000"],["63527.58000000","0.06563000"],["63527.14000000","0.00000000"],["63526.72000000","0.55232000"],["63525.65000000","0.00881000"],["63525.53000000","0.03000000"],["63525.51000000","0.03031000"],["63525.03000000","0.00000000"],["63524.62000000","0.01100000"],["63523.73000000","0.00977000"],["63522.47000000","0.00861000"],["63522.43000000","0.12000000"],["63519.29000000","0.00845000"],["63517.37000000","0.00967000"],["63516.11000000","0.00869000"],["63511.07000000","0.00188000"],["63511.01000000","0.00970000"],["63507.78000000","0.00409000"],["63504.65000000","0.00943000"],["63501.43000000","0.00000000"],["63492.80000000","0.00000000"],["63491.13000000","0.01151000"],["63484.73000000","0.00000000"],["63484.15000000","0.00000000"],["63483.72000000","0.01000000"],["63483.05000000","0.01000000"],["63482.57000000","0.94488000"],["63482.42000000","0.01009000"],["63482.38000000","0.01000000"],["63469.55000000","0.01715000"],["63468.36000000","0.00000000"],["63467.89000000","0.00008000"],["63465.83000000","0.00012000"],["63448.95000000","0.04623000"],["63412.87000000","0.00000000"],["63383.56000000","0.00008000"],["63381.67000000","0.00157000"],["63381.66000000","0.19081000"],["63380.39000000","0.00000000"],["57187.80000000","0.00040000"]],"a":[["63542.01000000","4.04005000"],["63542.15000000","1.22840000"],["63542.16000000","0.00018000"],["63542.17000000","0.00018000"],["63542.52000000","0.09072000"],["63542.97000000","0.00868000"],["63543.26000000","0.00000000"],["63543.77000000","0.11778000"],["63543.80000000","0.00018000"],["63543.81000000","0.00026000"],["63544.44000000","0.07526000"],["63544.45000000","0.85858000"],["63544.83000000","0.45652000"],["63545.19000000","0.06785000"],["63545.32000000","2.83475000"],["63545.34000000","0.50723000"],["63546.00000000","0.54219000"],["63546.01000000","1.45348000"],["63547.58000000","0.13863000"],["63548.01000000","0.15812000"],["63548.37000000","0.04923000"],["63548.84000000","0.02000000"],["63549.94000000","0.00008000"],["63550.01000000","0.00000000"],["63550.76000000","0.00862000"],["63551.02000000","0.02360000"],["63551.03000000","0.14781000"],["63551.55000000","0.04523000"],["63553.28000000","0.00000000"],["63553.41000000","0.00008000"],["63554.01000000","0.00000000"],["63555.28000000","0.00000000"],["63555.62000000","0.02400000"],["63555.67000000","0.00000000"],["63555.82000000","0.00000000"],["63556.22000000","0.02900000"],["63556.82000000","0.03500000"],["63556.86000000","0.02800000"],["63558.38000000","0.00000000"],["63560.25000000","0.09530000"],["63562.19000000","0.00000000"],["63563.57000000","0.00314000"],["63565.78000000","0.00008000"],["63568.59000000","0.00000000"],["63571.57000000","0.00431000"],["63571.62000000","0.00000000"],["63572.11000000","0.00000000"],["63572.27000000","0.00000000"],["63572.58000000","0.03082000"],["63572.65000000","0.01133000"],["63574.00000000","0.03800000"],["63576.76000000","0.00000000"],["63577.00000000","0.00000000"],["63579.51000000","0.00000000"],["63579.58000000","0.01146000"],["63579.73000000","0.00000000"],["63582.00000000","0.02800000"],["63590.67000000","0.00000000"],["63597.08000000","0.00000000"],["63600.20000000","0.00000000"],["63607.60000000","0.00000000"],["63609.98000000","0.04569000"],["63610.40000000","0.00000000"],["63622.84000000","0.00000000"],["63625.65000000","0.00000000"],["63628.13000000","0.00000000"],["63638.83000000","0.00000000"],["63719.41000000","0.00000000"],["63722.58000000","0.00000000"]]}}
{"stream":"ethusdt@depth@100ms","data":{"e":"depthUpdate","E":1783465200515,"s":"ETHUSDT","U":78545072920,"u":78545073169,"b":[["1775.09000000","6.45680000"],["1775.08000000","0.01170000"],["1775.07000000","0.01330000"],["1775.06000000","0.07730000"],["1775.05000000","0.44000000"],["1775.04000000","0.00880000"],["1775.03000000","0.00300000"],["1775.02000000","0.01140000"],["1775.01000000","0.01520000"],["1775.00000000","0.19900000"],["1774.99000000","0.00430000"],["1774.98000000","0.45880000"],["1774.97000000","0.16980000"],["1774.96000000","0.47280000"],["1774.94000000","0.00300000"],["1774.92000000","0.14000000"],["1774.91000000","0.53700000"],["1774.88000000","0.04790000"],["1774.87000000","0.76350000"],["1774.85000000","0.00290000"],["1774.84000000","5.38940000"],["1774.78000000","1.31710000"],["1774.74000000","0.28760000"],["1774.73000000","0.00290000"],["1774.71000000","32.83420000"],["1774.65000000","10.26180000"],["1774.64000000","0.44130000"],["1774.63000000","2.82730000"],["1774.62000000","0.44440000"],["1774.59000000","16.20950000"],["1774.55000000","0.99700000"],["1774.45000000","1.38630000"],["1774.43000000","27.11510000"],["1774.39000000","9.46180000"],["1774.35000000","0.00740000"],["1774.33000000","0.63700000"],["1774.32000000","0.03290000"],["1774.27000000","0.84980000"],["1774.15000000","1.26060000"],["1774.12000000","2.35130000"],["1773.98000000","24.59370000"],["1773.93000000","0.43700000"],["1773.92000000","0.25600000"],["1773.70000000","0.10150000"],["1773.61000000","0.14000000"],["1773.59000000","0.14000000"],["1773.58000000","8.02450000"],["1773.57000000","0.28790000"],["1773.46000000","43.86920000"],["1773.36000000","8.55940000"],["1773.33000000","0.09420000"],["1773.31000000","0.00290000"],["1773.20000000","0.57240000"],["1773.18000000","0.44440000"],["1773.14000000","0.00000000"],["1773.12000000","15.76960000"],["1772.90000000","0.00000000"],["1772.85000000","8.44850000"],["1772.60000000","15.03870000"],["1770.09000000","0.06350000"],["1770.03000000","0.01120000"],["1767.15000000","0.01080000"],["1765.17000000","10.69190000"],["1597.59000000","0.54980000"]],"a":[["1775.10000000","57.65190000"],["1775.12000000","0.03860000"],["1775.18000000","8.05250000"],["1775.19000000","0.00600000"],["1775.20000000","25.26430000"],["1775.21000000","0.56080000"],["1775.22000000","4.23710000"],["1775.25000000","0.00340000"],["1775.27000000","0.00000000"],["1775.28000000","2.71180000"],["1775.29000000","1.16050000"],["1775.30000000","0.00290000"],["1775.31000000","0.28530000"],["1775.33000000","7.88480000"],["1775.34000000","0.00340000"],["1775.37000000","24.59080000"],["1775.46000000","0.86190000"],["1775.51000000","0.43700000"],["1775.56000000","2.41340000"],["1775.59000000","0.04670000"],["1775.64000000","0.00000000"],["1775.65000000","0.00580000"],["1775.70000000","8.18510000"],["1775.73000000","7.99750000"],["1775.92000000","0.03290000"],["1776.03000000","2.82320000"],["1776.12000000","43.80390000"],["1776.14000000","0.41680000"],["1776.32000000","0.00000000"],["1776.62000000","2.50340000"],["1776.74000000","0.00290000"],["1776.89000000","0.23420000"],["1776.91000000","0.07620000"],["1777.07000000","0.01430000"],["1777.12000000","0.00000000"],["1777.20000000","0.98580000"],["1777.33000000","0.27850000"],["1777.34000000","0.00860000"],["1777.45000000","0.56370000"],["1777.49000000","0.09650000"],["1777.81000000","15.02090000"],["1780.00000000","6.78030000"],["1780.04000000","0.00780000"],["1781.51000000","0.00000000"]]}}
{"stream":"btcusdt@depth@100ms","data":{"e":"depthUpdate","E":1783465200614,"s":"BTCUSDT","U":97109091680,"u":97109091777,"b":[["63542.00000000","0.10750000"],["63538.14000000","0.00018000"],["63538.13000000","0.14135000"],["63536.00000000","0.02818000"],["63535.70000000","0.06563000"],["63535.47000000","0.00000000"],["63535.46000000","0.06561000"],["63535.45000000","0.50204000"],["63535.05000000","0.04563000"],["63534.95000000","0.00000000"],["63534.81000000","0.00400000"],["63534.13000000","0.09138000"],["63531.72000000","0.22500000"],["63530.85000000","0.06456000"],["63527.66000000","0.00189000"],["63520.42000000","1.09563000"],["63520.16000000","0.00000000"],["63503.59000000","1.57505000"],["63483.72000000","0.00000000"],["63482.42000000","0.00009000"],["63482.38000000","0.00000000"],["63479.88000000","0.01148000"],["63459.65000000","0.00000000"],["63457.82000000","0.00000000"],["63451.41000000","0.00000000"],["63370.64000000","0.00000000"],["63362.47000000","0.00987000"],["57187.80000000","0.00080000"],["50834.00000000","0.00200000"]],"a":[["63542.01000000","4.04813000"],["63542.15000000","1.22858000"],["63542.16000000","0.00000000"],["63542.17000000","0.00000000"],["63542.29000000","0.00000000"],["63542.52000000","0.00018000"],["63542.94000000","0.00009000"],["63542.97000000","0.00886000"],["63543.54000000","0.09324000"],["63543.77000000","0.11778000"],["63543.80000000","0.00000000"],["63543.81000000","0.00008000"],["63544.83000000","0.45661000"],["63545.19000000","0.06794000"],["63545.33000000","0.07500000"],["63545.34000000","0.28223000"],["63551.83000000","0.00000000"],["63552.46000000","0.00000000"],["63554.72000000","0.00009000"],["63562.79000000","0.00000000"],["63563.43000000","0.00200000"],["63568.36000000","0.00427000"],["63568.57000000","0.00000000"],["63571.75000000","0.00433000"],["63585.17000000","0.03011000"],["63594.75000000","0.10433000"],["63598.44000000","0.00000000"],["63598.49000000","0.00000000"],["63605.97000000","3.66686000"],["63617.47000000","0.04557000"],["63648.59000000","0.02465000"],["63662.18000000","0.00000000"],["63682.28000000","0.00000000"]]}}
{"stream":"ethusdt@depth@100ms","data":{"e":"depthUpdate","E":1783465200615,"s":"ETHUSDT","U":78545073170,"u":78545073348,"b":[["1775.09000000","11.42290000"],["1775.08000000","0.00880000"],["1775.05000000","0.87700000"],["1775.04000000","0.01480000"],["1775.03000000","6.76870000"],["1775.01000000","0.00920000"],["1775.00000000","0.58100000"],["1774.99000000","0.01030000"],["1774.98000000","0.45280000"],["1774.97000000","0.14600000"],["1774.94000000","0.00300000"],["1774.91000000","0.43700000"],["1774.85000000","1.67150000"],["1774.82000000","0.14660000"],["1774.76000000","1.07060000"],["1774.61000000","15.86330000"],["1774.60000000","15.03010000"],["1774.54000000","7.88480000"],["1774.47000000","0.85190000"],["1774.45000000","1.38630000"],["1774.33000000","1.34900000"],["1773.92000000","0.04130000"],["1773.61000000","0.00000000"],["1773.58000000","7.88450000"],["1773.57000000","0.14790000"],["1773.45000000","22.52900000"],["1773.44000000","21.17340000"],["1773.18000000","0.00740000"],["1773.09000000","0.00690000"],["1772.87000000","7.88480000"],["1772.72000000","0.00460000"],["1772.60000000","0.02000000"],["1772.48000000","0.00580000"],["1772.01000000","0.80570000"],["1768.44000000","141.46610000"],["1768.26000000","0.57520000"],["1597.59000000","0.56380000"]],"a":[["1775.10000000","37.22290000"],["1775.11000000","0.02310000"],["1775.12000000","0.00860000"],["1775.17000000","0.00600000"],["1775.18000000","0.65940000"],["1775.19000000","0.00000000"],["1775.20000000","0.03890000"],["1775.22000000","1.40580000"],["1775.23000000","0.20000000"],["1775.24000000","0.00300000"],["1775.25000000","1.63990000"],["1775.27000000","0.00600000"],["1775.28000000","10.01110000"],["1775.33000000","0.00000000"],["1775.34000000","25.23880000"],["1775.35000000","8.27760000"],["1775.36000000","8.70920000"],["1775.39000000","1.53090000"],["1775.42000000","2.51070000"],["1775.43000000","0.00340000"],["1775.44000000","0.03290000"],["1775.47000000","0.10000000"],["1775.49000000","0.43700000"],["1775.50000000","0.00000000"],["1775.51000000","15.45570000"],["1775.53000000","1.09390000"],["1775.54000000","0.78840000"],["1775.61000000","0.19050000"],["1775.62000000","0.55370000"],["1775.71000000","15.30020000"],["1775.72000000","8.89650000"],["1775.74000000","0.00000000"],["1776.03000000","0.00290000"],["1776.40000000","1.23400000"],["1776.69000000","2.82360000"],["1776.99000000","7.88480000"],["1777.91000000","2.26140000"],["1778.31000000","15.02090000"],["1778.45000000","0.00580000"],["1778.48000000","0.00290000"],["1779.35000000","0.00290000"],["1780.45000000","0.39560000"]]}}
{"stream":"btcusdt@depth@100ms","data":{"e":"depthUpdate","E":1783465200714,"s":"BTCUSDT","U":97109091778,"u":97109091823,"b":[["63542.00000000","0.10759000"],["63541.99000000","0.00081000"],["63538.48000000","0.00647000"],["63536.00000000","0.02818000"],["63535.70000000","0.06572000"],["63535.05000000","0.04545000"],["63524.62000000","0.00000000"],["63521.92000000","0.56712000"],["63511.82000000","0.56721000"],["63500.86000000","0.00000000"],["63459.99000000","0.00000000"],["63448.01000000","0.00015000"],["63410.11000000","0.00000000"],["63403.06000000","0.00820000"],["57187.80000000","0.00120000"],["50834.00000000","0.00000000"]],"a":[["63542.01000000","4.04813000"],["63542.15000000","1.22858000"],["63542.52000000","0.00000000"],["63542.97000000","0.00886000"],["63543.54000000","0.09342000"],["63544.21000000","0.00009000"],["63545.19000000","0.06803000"],["63548.99000000","0.00009000"],["63556.75000000","0.56681000"],["63559.86000000","0.00000000"],["63563.39000000","0.00000000"],["63648.59000000","0.00000000"],["63655.64000000","0.00000000"],["63707.81000000","0.00000000"],["63988.00000000","0.03100000"]]}}
{"stream":"ethusdt@depth@100ms","data":{"e":"depthUpdate","E":1783465200715,"s":"ETHUSDT","U":78545073349,"u":78545073427,"b":[["1775.09000000","11.84180000"],["1775.06000000","0.00300000"],["1775.05000000","0.00300000"],["1775.04000000","0.01480000"],["1775.03000000","7.21170000"],["1775.02000000","0.45130000"],["1775.01000000","0.00920000"],["1775.00000000","0.19900000"],["1774.99000000","0.00430000"],["1774.98000000","0.01580000"],["1774.97000000","0.14600000"],["1774.94000000","0.00600000"],["1774.91000000","0.44000000"],["1774.90000000","0.48700000"],["1774.88000000","0.14790000"],["1774.86000000","4.02320000"],["1774.85000000","0.00290000"],["1774.83000000","0.02380000"],["1774.46000000","0.98940000"],["1774.18000000","0.49570000"],["1774.05000000","0.90500000"],["1773.63000000","0.21850000"],["1773.20000000","0.13540000"],["1773.18000000","0.44440000"],["1773.12000000","15.76960000"],["1772.87000000","7.88480000"],["1772.86000000","2.92720000"],["1597.59000000","0.57780000"]],"a":[["1775.10000000","48.54770000"],["1775.22000000","1.41180000"],["1775.23000000","0.48180000"],["1775.27000000","0.00000000"],["1775.50000000","4.62560000"],["1775.68000000","0.81690000"],["1775.70000000","23.80890000"],["1775.72000000","0.00430000"],["1776.32000000","0.03000000"],["1776.40000000","1.20400000"],["1777.24000000","31.97710000"]]}}
{"stream":"btcusdt@depth@100ms","data":{"e":"depthUpdate","E":1783465200814,"s":"BTCUSDT","U":97109091824,"u":97109091870,"b":[["63542.00000000","0.12869000"],["63540.02000000","0.14196000"],["63540.00000000","0.03818000"],["63539.14000000","0.00000000"],["63538.48000000","0.00665000"],["63538.13000000","0.00546000"],["63535.45000000","0.50186000"],["63532.81000000","0.01000000"],["63532.16000000","0.01000000"],["63529.61000000","0.01016000"],["63529.29000000","0.01000000"],["63528.95000000","0.01000000"],["63522.80000000","0.00000000"],["63510.48000000","0.56723000"],["63508.96000000","0.00000000"],["63490.03000000","0.00427000"],["63486.30000000","0.01000000"],["63485.64000000","0.01000000"],["63483.09000000","0.01000000"],["63483.05000000","0.00000000"],["63482.76000000","0.01000000"],["63482.41000000","0.01000000"],["63475.32000000","0.00000000"],["63445.84000000","0.00023000"],["63437.85000000","0.04564000"],["57187.80000000","0.00160000"]],"a":[["63544.44000000","0.00026000"],["63548.28000000","0.02300000"],["63548.97000000","0.02000000"],["63551.43000000","0.02600000"],["63551.81000000","0.02200000"],["63552.11000000","0.02600000"],["63554.02000000","0.00000000"],["63563.22000000","0.00000000"],["63567.70000000","0.00000000"],["63571.08000000","0.56669000"],["63572.46000000","0.00000000"],["63587.09000000","0.00000000"],["63666.05000000","0.00000000"]]}}
{"stream":"ethusdt@depth@100ms","data":{"e":"depthUpdate","E":1783465200815,"s":"ETHUSDT","U":78545073428,"u":78545073487,"b":[["1775.09000000","11.52480000"],["1775.08000000","0.00880000"],["1775.05000000","0.00600000"],["1775.04000000","0.45180000"],["1775.03000000","7.20570000"],["1775.02000000","0.01430000"],["1774.98000000","0.02180000"],["1774.97000000","0.58300000"],["1774.96000000","0.44280000"],["1774.91000000","0.43700000"],["1774.88000000","0.23110000"],["1774.87000000","0.90350000"],["1774.86000000","3.71400000"],["1774.85000000","7.88770000"],["1774.81000000","0.14430000"],["1774.78000000","1.45710000"],["1774.77000000","0.14000000"],["1774.61000000","21.39490000"],["1774.50000000","0.17950000"],["1774.05000000","0.61100000"],["1773.68000000","24.70110000"],["1773.66000000","27.64280000"],["1773.61000000","0.14000000"],["1773.58000000","8.02450000"],["1773.57000000","0.28790000"],["1773.20000000","0.13540000"],["1773.18000000","0.00740000"],["1773.12000000","15.76960000"],["1772.88000000","0.00290000"],["1772.87000000","0.00000000"],["1597.59000000","0.58480000"]],"a":[["1775.12000000","0.03860000"],["1775.17000000","0.01140000"],["1775.18000000","0.00000000"],["1775.21000000","1.61640000"],["1775.24000000","0.00600000"],["1775.27000000","0.00300000"],["1775.29000000","1.26050000"],["1775.42000000","2.97270000"],["1775.44000000","0.34090000"],["1775.47000000","0.00000000"],["1775.49000000","0.78700000"],["1775.52000000","17.86740000"],["1775.53000000","1.40190000"],["1776.32000000","0.00000000"]]}}
{"stream":"btcusdt@depth@100ms","data":{"e":"depthUpdate","E":1783465200914,"s":"BTCUSDT","U":97109091871,"u":97109091908,"b":[["63542.00000000","0.12904000"],["63541.99000000","0.00090000"],["63540.03000000","0.00018000"],["63538.14000000","0.00000000"],["63535.46000000","0.06543000"],["63530.77000000","0.01000000"],["63485.67000000","0.00000000"],["63482.41000000","0.00000000"],["63439.43000000","0.00039000"],["57187.80000000","0.00200000"]],"a":[["63543.77000000","0.11778000"],["63544.44000000","0.00008000"],["63545.32000000","2.83493000"],["63547.95000000","0.02800000"],["63560.17000000","0.03000000"],["63560.86000000","0.00000000"],["63563.71000000","0.00000000"],["63564.00000000","0.02800000"],["63567.35000000","1.57347000"],["63611.27000000","0.00000000"],["63643.62000000","0.00015000"],["63697.51000000","0.00000000"],["70947.60000000","0.00925000"]]}}
{"stream":"ethusdt@depth@100ms","data":{"e":"depthUpdate","E":1783465200915,"s":"ETHUSDT","U":78545073488,"u":78545073517,"b":[["1775.09000000","11.84170000"],["1775.08000000","0.01170000"],["1774.94000000","0.07430000"],["1774.86000000","3.85400000"],["1774.57000000","0.14000000"],["1774.55000000","0.71700000"],["1774.47000000","0.71190000"],["1774.46000000","0.84940000"],["1774.21000000","0.60070000"],["1773.76000000","0.47280000"],["1773.68000000","24.67110000"],["1773.66000000","27.64280000"],["1773.00000000","0.97450000"],["1770.23000000","0.00000000"],["1597.59000000","0.59880000"]],"a":[["1775.12000000","0.04150000"],["1775.35000000","7.88480000"],["1775.43000000","0.00740000"],["1775.44000000","0.77490000"],["1775.68000000","0.36890000"],["1775.70000000","23.51490000"],["1775.78000000","0.00000000"],["1775.79000000","1.13040000"],["1775.82000000","23.46160000"],["1777.20000000","0.56580000"]]}}
{"stream":"btcusdt@trade","data":{"e":"trade","E":1783465200927,"s":"BTCUSDT","t":6486989996,"p":"63542.00000000","q":"0.00018000","T":1783465200927,"m":true,"M":true}}
{"stream":"btcusdt@trade","data":{"e":"trade","E":1783465201010,"s":"BTCUSDT","t":6486989997,"p":"63542.00000000","q":"0.00104000","T":1783465201010,"m":true,"M":true}}
{"stream":"btcusdt@depth@100ms","data":{"e":"depthUpdate","E":1783465201014,"s":"BTCUSDT","U":97109091909,"u":97109091943,"b":[["63542.00000000","0.12782000"],["63532.45000000","0.00787000"],["63532.35000000","0.46021000"],["63530.83000000","0.01014000"],["63530.80000000","0.01000000"],["63529.72000000","0.00000000"],["63527.61000000","0.01032000"],["63527.59000000","0.42507000"],["63523.26000000","0.00000000"],["63492.28000000","0.13295000"],["63485.74000000","0.01000000"],["63485.71000000","0.01027000"],["63482.52000000","0.01000000"],["63476.20000000","0.00037000"],["63465.31000000","0.07028000"],["63412.69000000","0.00014000"],["57195.90000000","0.00000000"],["57187.80000000","0.00240000"],["50833.60000000","0.00039000"]],"a":[["63542.14000000","1.80204000"],["63544.44000000","0.59068000"],["63547.91000000","0.03000000"],["63547.93000000","0.02500000"],["63548.63000000","0.00000000"],["63549.13000000","0.11112000"],["63551.01000000","0.00000000"],["63551.13000000","0.02700000"],["63551.66000000","0.78746000"],["63552.16000000","0.00009000"],["63554.52000000","0.75565000"],["63583.67000000","0.00392000"],["63592.34000000","0.00000000"],["63647.99000000","0.00157000"],["63650.16000000","0.00023000"],["70947.60000000","0.00075000"]]}}
{"stream":"ethusdt@depth@100ms","data":{"e":"depthUpdate","E":1783465201015,"s":"ETHUSDT","U":78545073518,"u":78545073546,"b":[["1775.05000000","0.00900000"],["1774.86000000","4.13400000"],["1774.77000000","0.56180000"],["1774.74000000","0.00580000"],["1774.63000000","0.00860000"],["1774.58000000","2.82150000"],["1773.66000000","27.92280000"],["1773.57000000","0.42790000"],["1773.49000000","1.13840000"],["1771.87000000","0.90550000"],["1769.79000000","181.85820000"],["1597.59000000","0.62660000"]],"a":[["1775.16000000","0.39280000"],["1775.27000000","0.28180000"],["1775.28000000","10.01400000"],["1775.35000000","8.47400000"],["1775.44000000","4.27950000"],["1775.45000000","0.00000000"],["1775.53000000","1.69590000"],["1775.81000000","0.00000000"],["1776.51000000","0.00400000"],["1776.69000000","2.82020000"],["1778.83000000","0.00000000"]]}}
{"stream":"btcusdt@trade","data":{"e":"trade","E":1783465201074,"s":"BTCUSDT","t":6486989998,"p":"63542.00000000","q":"0.00045000","T":1783465201073,"m":true,"M":true}}
{"stream":"btcusdt@depth@100ms","data":{"e":"depthUpdate","E":1783465201114,"s":"BTCUSDT","U":97109091944,"u":97109091999,"b":[["63542.00000000","0.10619000"],["63541.68000000","0.00009000"],["63540.03000000","0.00000000"],["63540.02000000","0.00000000"],["63535.71000000","0.00009000"],["63535.45000000","0.50178000"],["63534.12000000","0.00000000"],["63533.08000000","0.00000000"],["63532.45000000","0.00000000"],["63532.01000000","0.00787000"],["63531.42000000","0.01032000"],["63526.72000000","0.81741000"],["63525.97000000","0.00000000"],["63520.43000000","0.77983000"],["63508.96000000","0.00419000"],["63488.01000000","0.02931000"],["63486.30000000","0.00000000"],["63486.14000000","0.01000000"],["63485.71000000","0.00027000"],["63476.56000000","0.66425000"],["63476.20000000","0.00000000"],["57187.80000000","0.00260000"],["50833.60000000","0.00059000"]],"a":[["63542.01000000","4.04813000"],["63542.14000000","1.80222000"],["63543.77000000","0.11778000"],["63544.44000000","0.59086000"],["63545.19000000","0.06785000"],["63545.32000000","2.83475000"],["63546.01000000","1.22848000"],["63547.32000000","0.02700000"],["63548.01000000","0.15804000"],["63549.13000000","1.81203000"],["63554.51000000","0.07776000"],["63560.17000000","0.00000000"],["63560.20000000","0.00000000"],["63563.45000000","0.00000000"],["63583.67000000","0.00392000"],["63611.24000000","0.00000000"],["63647.99000000","0.00157000"],["63670.27000000","0.00039000"]]}}
{"stream":"ethusdt@depth@100ms","data":{"e":"depthUpdate","E":1783465201115,"s":"ETHUSDT","U":78545073547,"u":78545073605,"b":[["1775.09000000","8.19890000"],["1775.08000000","0.44870000"],["1775.05000000","0.00300000"],["1775.04000000","0.01480000"],["1775.03000000","6.77470000"],["1775.02000000","0.45130000"],["1775.00000000","0.20200000"],["1774.99000000","0.44130000"],["1774.98000000","0.01580000"],["1774.97000000","0.14600000"],["1774.94000000","0.06830000"],["1774.93000000","2.48640000"],["1774.92000000","0.57700000"],["1774.91000000","0.00000000"],["1774.87000000","1.04350000"],["1774.86000000","0.56290000"],["1774.85000000","7.88980000"],["1774.84000000","5.39910000"],["1774.77000000","0.28000000"],["1774.73000000","0.28470000"],["1774.55000000","0.43700000"],["1774.46000000","0.70940000"],["1774.45000000","0.05430000"],["1774.32000000","0.59650000"],["1773.68000000","24.81110000"],["1773.66000000","27.78280000"],["1773.25000000","12.07510000"],["1773.20000000","0.13540000"],["1773.18000000","0.44440000"],["1773.14000000","0.00000000"],["1773.12000000","15.76960000"],["1772.87000000","0.00000000"],["1597.59000000","0.64060000"]],"a":[["1775.10000000","48.65970000"],["1775.15000000","0.00300000"],["1775.42000000","3.32270000"],["1777.14000000","24.59820000"]]}}
{"stream":"btcusdt@depth@100ms","data":{"e":"depthUpdate","E":1783465201214,"s":"BTCUSDT","U":97109092000,"u":97109092021,"b":[["63542.00000000","0.10610000"],["63541.99000000","0.00081000"],["63514.01000000","0.66457000"],["63512.35000000","0.53575000"],["63488.01000000","0.02035000"],["63485.74000000","0.00000000"],["63485.64000000","0.00000000"],["63483.09000000","0.00000000"],["63482.80000000","0.45537000"],["63482.76000000","0.00000000"],["63476.56000000","0.00000000"],["57187.80000000","0.00300000"],["50833.60000000","0.00020000"],["33000.00000000","35.16979000"]],"a":[["63543.54000000","0.09090000"],["63557.67000000","0.55834000"]]}}
{"stream":"ethusdt@depth@100ms","data":{"e":"depthUpdate","E":1783465201215,"s":"ETHUSDT","U":78545073606,"u":78545073632,"b":[["1775.09000000","8.20470000"],["1775.08000000","0.45160000"],["1775.06000000","0.00600000"],["1775.05000000","0.44000000"],["1774.97000000","0.14300000"],["1774.88000000","0.24170000"],["1774.86000000","4.63270000"],["1774.84000000","5.39900000"],["1774.32000000","0.03290000"],["1774.12000000","0.28580000"],["1773.18000000","0.00740000"],["1772.91000000","0.00400000"],["1769.70000000","1.47740000"],["1768.61000000","2.71620000"],["1597.59000000","0.65460000"]],"a":[["1775.61000000","0.19450000"],["1776.88000000","9.65360000"],["1777.20000000","0.22980000"],["1778.03000000","24.73740000"],["1778.05000000","5.72360000"],["1778.13000000","0.00000000"]]}}
{"stream":"btcusdt@trade","data":{"e":"trade","E":1783465201269,"s":"BTCUSDT","t":6486989999,"p":"63542.01000000","q":"0.00078000","T":1783465201269,"m":false,"M":true}}
{"stream":"btcusdt@depth@100ms","data":{"e":"depthUpdate","E":1783465201314,"s":"BTCUSDT","U":97109092022,"u":97109092055,"b":[["63542.00000000","0.12735000"],["63541.99000000","0.00106000"],["63541.98000000","0.00016000"],["63540.17000000","0.00163000"],["63539.11000000","0.00018000"],["63539.10000000","0.11337000"],["63536.76000000","0.00009000"],["63536.75000000","0.06046000"],["63536.01000000","0.00021000"],["63535.71000000","0.00000000"],["63535.70000000","0.06581000"],["63535.46000000","0.06552000"],["63486.14000000","0.00000000"],["63466.21000000","1.02675000"],["57187.80000000","0.00340000"],["57187.00000000","0.15020000"],["50833.60000000","0.00000000"]],"a":[["63542.01000000","4.04735000"],["63551.66000000","0.00000000"],["63554.50000000","0.07776000"],["63554.51000000","0.78746000"],["63559.63000000","0.00000000"]]}}
{"stream":"ethusdt@depth@100ms","data":{"e":"depthUpdate","E":1783465201315,"s":"ETHUSDT","U":78545073633,"u":78545073649,"b":[["1775.09000000","8.22000000"],["1775.08000000","0.45730000"],["1775.07000000","0.01900000"],["1774.88000000","0.52040000"],["1774.84000000","5.38940000"],["1774.57000000","0.00000000"],["1774.44000000","1.34230000"],["1772.54000000","1.69820000"],["1597.59000000","0.66860000"]],"a":[["1775.30000000","0.00580000"],["1775.42000000","3.32560000"],["1775.68000000","0.03290000"],["1777.34000000","1.65970000"],["1777.94000000","0.14080000"],["1778.03000000","24.59660000"]]}}
{"stream":"btcusdt@depth@100ms","data":{"e":"depthUpdate","E":1783465201414,"s":"BTCUSDT","U":97109092056,"u":97109092089,"b":[["63542.00000000","0.12752000"],["63541.99000000","0.00115000"],["63540.78000000","0.00018000"],["63540.77000000","0.12913000"],["63540.00000000","0.03818000"],["63539.11000000","0.00000000"],["63539.10000000","0.00026000"],["63537.43000000","0.02142000"],["63536.75000000","0.06055000"],["63535.70000000","0.06563000"],["63535.46000000","0.06543000"],["63528.42000000","0.01574000"],["63518.91000000","0.00400000"],["63507.78000000","0.00009000"],["57187.80000000","0.00380000"],["57187.00000000","0.15000000"],["40000.00000000","260.73952000"]],"a":[["63548.22000000","0.00008000"],["63551.03000000","0.14771000"],["63551.34000000","0.00008000"]]}}
{"stream":"ethusdt@depth@100ms","data":{"e":"depthUpdate","E":1783465201415,"s":"ETHUSDT","U":78545073650,"u":78545073654,"b":[["1775.09000000","9.06550000"],["1597.59000000","0.68940000"]],"a":[["1775.40000000","0.93700000"]]}}
{"stream":"btcusdt@depth@100ms","data":{"e":"depthUpdate","E":1783465201514,"s":"BTCUSDT","U":97109092090,"u":97109092113,"b":[["63542.00000000","0.12752000"],["63540.77000000","0.12931000"],["63540.00000000","0.03818000"],["63539.10000000","0.00008000"],["63527.98000000","0.00008000"],["63482.52000000","0.00000000"],["62979.06000000","0.00000000"],["57187.80000000","0.00420000"]],"a":[["63544.83000000","0.45653000"],["63545.33000000","0.00000000"],["63549.68000000","0.00000000"],["63553.41000000","0.00008000"],["63598.43000000","0.03891000"],["63598.49000000","0.02800000"]]}}
{"stream":"ethusdt@depth@100ms","data":{"e":"depthUpdate","E":1783465201515,"s":"ETHUSDT","U":78545073655,"u":78545073674,"b":[["1774.79000000","0.14000000"],["1774.74000000","0.00580000"],["1774.24000000","10.23750000"],["1774.17000000","0.00400000"],["1773.68000000","24.76050000"],["1773.67000000","0.00290000"],["1773.57000000","0.42290000"],["1773.52000000","0.05360000"],["1773.10000000","35.33270000"],["1772.97000000","0.00000000"],["1772.53000000","0.12580000"],["1772.38000000","24.76200000"],["1771.97000000","0.00000000"],["1771.78000000","0.00000000"],["1771.40000000","1.48500000"],["1771.18000000","0.00000000"],["1770.83000000","0.00290000"],["1770.58000000","0.00680000"],["1770.26000000","0.00000000"],["1769.98000000","0.17700000"],["1769.70000000","1.33200000"],["1769.38000000","0.00000000"],["1597.59000000","0.70340000"],["1067.00000000","6.86000000"]],"a":[["1775.46000000","0.86190000"],["1775.49000000","1.08100000"],["1775.50000000","5.08760000"],["1775.53000000","2.38190000"],["1775.54000000","0.79130000"],["1775.75000000","18.02800000"],["1777.03000000","0.14350000"],["1778.64000000","0.05780000"],["1778.79000000","0.00000000"]]}}
{"stream":"btcusdt@depth@100ms","data":{"e":"depthUpdate","E":1783465201630,"s":"BTCUSDT","U":97109092114,"u":97109092136,"b":[["63542.00000000","0.12752000"],["63541.99000000","0.00115000"],["63540.17000000","0.00000000"],["63538.13000000","0.00026000"],["63533.43000000","0.00000000"],["63524.05000000","0.00000000"],["63514.67000000","0.00000000"],["63514.13000000","0.00000000"],["63509.98000000","0.00000000"],["63505.48000000","0.00000000"],["63497.34000000","0.00000000"],["63495.90000000","0.00009000"],["63494.61000000","0.00000000"],["63492.01000000","0.00392000"],["63490.80000000","0.00000000"],["63484.91000000","0.00390000"],["63484.37000000","0.00000000"],["63481.83000000","0.00000000"],["63480.55000000","0.00000000"],["63477.13000000","0.00000000"],["63467.75000000","0.00000000"],["63463.77000000","0.00000000"],["63463.26000000","0.00000000"],["63458.37000000","0.00000000"],["63453.68000000","0.00000000"],["63446.98000000","0.00000000"],["63442.15000000","0.00000000"],["63439.60000000","0.00000000"],["63434.01000000","0.00000000"],["63430.19000000","0.00000000"],["63428.63000000","0.00157000"],["63427.35000000","0.00000000"],["63425.53000000","0.00000000"],["63422.01000000","0.00157000"],["63421.03000000","0.00000000"],["63420.83000000","0.00000000"],["63413.41000000","0.00000000"],["63411.45000000","0.00000000"],["63402.07000000","0.00000000"],["63399.92000000","0.00000000"],["63396.62000000","0.00000000"],["63383.30000000","0.00000000"],["63379.84000000","0.00000000"],["63378.81000000","0.00000000"],["63364.54000000","0.00000000"],["63363.05000000","0.00000000"],["63357.70000000","0.00000000"],["63346.26000000","0.00000000"],["63336.59000000","0.00000000"],["63329.48000000","0.00000000"],["63315.48000000","0.00000000"],["63312.69000000","0.00000000"],["63295.90000000","0.00000000"],["63294.37000000","0.00000000"],["63273.26000000","0.00000000"],["63252.15000000","0.00000000"],["63231.04000000","0.00000000"],["57187.80000000","0.00460000"]],"a":[["63542.13000000","0.59068000"],["63544.44000000","0.00026000"],["63549.13000000","1.70091000"],["63550.75000000","0.50577000"],["63566.27000000","0.00000000"],["63570.97000000","0.00000000"],["63580.35000000","0.00000000"],["63589.73000000","0.00000000"],["63592.59000000","0.00392000"],["63594.42000000","0.00000000"],["63598.43000000","0.03500000"],["63599.77000000","0.00390000"],["63605.55000000","0.00000000"],["63608.50000000","0.00000000"],["63622.57000000","0.00000000"],["63627.27000000","0.00000000"],["63636.65000000","0.00000000"],["63646.03000000","0.00000000"],["63650.72000000","0.00000000"],["63655.99000000","0.00157000"],["63661.56000000","0.00000000"],["63662.66000000","0.00157000"],["63664.80000000","0.00000000"],["63668.77000000","0.00000000"],["63678.87000000","0.00000000"],["63683.57000000","0.00000000"],["63692.95000000","0.00000000"],["63702.33000000","0.00000000"],["63721.10000000","0.00009000"],["63739.86000000","0.00000000"]]}}
{"stream":"ethusdt@depth@100ms","data":{"e":"depthUpdate","E":1783465201630,"s":"ETHUSDT","U":78545073675,"u":78545073692,"b":[["1774.48000000","0.46990000"],["1774.46000000","0.57700000"],["1774.25000000","2.06220000"],["1774.02000000","3.04640000"],["1773.95000000","0.00290000"],["1773.56000000","0.43700000"],["1773.35000000","8.30670000"],["1773.20000000","0.00290000"],["1772.68000000","0.00000000"],["1772.67000000","0.00000000"],["1772.46000000","0.00340000"],["1772.00000000","0.95880000"],["1771.77000000","65.24050000"],["1771.71000000","0.00450000"],["1771.33000000","0.00000000"],["1770.96000000","0.00000000"],["1770.87000000","0.52560000"],["1770.65000000","0.00000000"],["1770.21000000","0.01410000"],["1769.98000000","0.00000000"],["1769.97000000","0.00000000"],["1769.46000000","0.00000000"],["1769.31000000","0.00000000"],["1769.07000000","0.00000000"],["1768.71000000","0.01130000"],["1768.63000000","0.00000000"],["1768.26000000","0.00000000"],["1768.17000000","0.00000000"],["1767.97000000","0.57530000"],["1767.96000000","0.00740000"],["1767.29000000","0.00000000"],["1767.28000000","0.00000000"],["1767.22000000","0.00000000"],["1766.61000000","0.04640000"],["1766.47000000","0.02820000"],["1766.38000000","1.41890000"],["1765.94000000","0.00000000"],["1765.72000000","0.07070000"],["1765.48000000","0.00000000"],["1765.27000000","0.00000000"],["1764.97000000","0.00000000"],["1764.59000000","0.13540000"],["1764.58000000","0.11330000"],["1764.22000000","0.00000000"],["1763.92000000","0.00000000"],["1763.68000000","0.15650000"],["1763.24000000","0.00000000"],["1762.79000000","0.03700000"],["1762.57000000","0.00000000"],["1761.90000000","0.00860000"],["1761.89000000","0.01580000"],["1760.99000000","0.01700000"],["1760.09000000","0.00000000"],["1759.19000000","0.00000000"],["1758.29000000","0.00000000"],["1757.40000000","0.00000000"],["1597.59000000","0.71740000"]],"a":[["1775.36000000","15.47490000"],["1775.70000000","23.51890000"],["1775.77000000","8.45900000"],["1775.79000000","0.83640000"],["1776.26000000","8.10500000"],["1776.90000000","15.55130000"],["1777.81000000","15.16170000"],["1777.94000000","0.00000000"],["1778.04000000","0.00340000"],["1778.05000000","5.58280000"]]}}
{"stream":"ethusdt@trade","data":{"e":"trade","E":1783465201692,"s":"ETHUSDT","t":4197008745,"p":"1775.10000000","q":"0.00290000","T":1783465201692,"m":false,"M":true}}
{"stream":"ethusdt@trade","data":{"e":"trade","E":1783465201692,"s":"ETHUSDT","t":4197008746,"p":"1775.10000000","q":"0.43700000","T":1783465201692,"m":false,"M":true}}
{"stream":"ethusdt@trade","data":{"e":"trade","E":1783465201692,"s":"ETHUSDT","t":4197008747,"p":"1775.10000000","q":"0.43700000","T":1783465201692,"m":false,"M":true}}
{"stream":"ethusdt@trade","data":{"e":"trade","E":1783465201692,"s":"ETHUSDT","t":4197008748,"p":"1775.10000000","q":"0.00570000","T":1783465201692,"m":false,"M":true}}
{"stream":"ethusdt@trade","data":{"e":"trade","E":1783465201692,"s":"ETHUSDT","t":4197008749,"p":"1775.10000000","q":"0.00290000","T":1783465201692,"m":false,"M":true}}
{"stream":"ethusdt@trade","data":{"e":"trade","E":1783465201692,"s":"ETHUSDT","t":4197008750,"p":"1775.10000000","q":"0.62060000","T":1783465201692,"m":false,"M":true}}
{"stream":"ethusdt@trade","data":{"e":"trade","E":1783465201692,"s":"ETHUSDT","t":4197008751,"p":"1775.10000000","q":"0.00290000","T":1783465201692,"m":false,"M":true}}
{"stream":"ethusdt@trade","data":{"e":"trade","E":1783465201692,"s":"ETHUSDT","t":4197008752,"p":"1775.10000000","q":"0.00960000","T":1783465201692,"m":false,"M":true}}
{"stream":"ethusdt@trade","data":{"e":"trade","E":1783465201692,"s":"ETHUSDT","t":4197008753,"p":"1775.10000000","q":"0.00290000","T":1783465201692,"m":false,"M":true}}
{"stream":"ethusdt@trade","data":{"e":"trade","E":1783465201692,"s":"ETHUSDT","t":4197008754,"p":"1775.10000000","q":"0.97300000","T":1783465201692,"m":false,"M":true}}
{"stream":"ethusdt@trade","data":{"e":"trade","E":1783465201692,"s":"ETHUSDT","t":4197008755,"p":"1775.10000000","q":"1.63650000","T":1783465201692,"m":false,"M":true}}
{"stream":"ethusdt@trade","data":{"e":"trade","E":1783465201692,"s":"ETHUSDT","t":4197008756,"p":"1775.10000000","q":"0.16200000","T":1783465201692,"m":false,"M":true}}
{"stream":"ethusdt@trade","data":{"e":"trade","E":1783465201692,"s":"ETHUSDT","t":4197008757,"p":"1775.10000000","q":"0.11200000","T":1783465201692,"m":false,"M":true}}
{"stream":"ethusdt@trade","data":{"e":"trade","E":1783465201694,"s":"ETHUSDT","t":4197008758,"p":"1775.11000000","q":"0.00570000","T":1783465201693,"m":false,"M":true}}
{"stream":"ethusdt@trade","data":{"e":"trade","E":1783465201694,"s":"ETHUSDT","t":4197008759,"p":"1775.11000000","q":"0.01740000","T":1783465201693,"m":false,"M":true}}
{"stream":"ethusdt@trade","data":{"e":"trade","E":1783465201700,"s":"ETHUSDT","t":4197008760,"p":"1775.12000000","q":"0.00570000","T":1783465201699,"m":false,"M":true}}
{"stream":"ethusdt@trade","data":{"e":"trade","E":1783465201700,"s":"ETHUSDT","t":4197008761,"p":"1775.12000000","q":"0.00290000","T":1783465201699,"m":false,"M":true}}
{"stream":"ethusdt@trade","data":{"e":"trade","E":1783465201700,"s":"ETHUSDT","t":4197008762,"p":"1775.12000000","q":"0.43700000","T":1783465201699,"m":false,"M":true}}
{"stream":"ethusdt@trade","data":{"e":"trade","E":1783465201700,"s":"ETHUSDT","t":4197008763,"p":"1775.12000000","q":"0.43700000","T":1783465201699,"m":false,"M":true}}
{"stream":"ethusdt@trade","data":{"e":"trade","E":1783465201711,"s":"ETHUSDT","t":4197008764,"p":"1775.16000000","q":"0.00300000","T":1783465201711,"m":false,"M":true}}
{"stream":"btcusdt@depth@100ms","data":{"e":"depthUpdate","E":1783465201714,"s":"BTCUSDT","U":97109092137,"u":97109092441,"b":[["63542.00000000","2.07614000"],["63541.99000000","0.00034000"],["63541.68000000","0.00000000"],["63541.49000000","0.00000000"],["63540.95000000","0.06549000"],["63540.78000000","0.06637000"],["63540.77000000","0.12939000"],["63540.01000000","0.00000000"],["63539.92000000","0.00032000"],["63539.90000000","0.06557000"],["63539.58000000","0.00400000"],["63538.85000000","0.06557000"],["63538.48000000","0.00665000"],["63538.13000000","0.00008000"],["63538.01000000","0.00000000"],["63537.99000000","0.00400000"],["63537.80000000","0.06094000"],["63537.44000000","0.00000000"],["63536.76000000","0.00000000"],["63536.75000000","0.06064000"],["63536.40000000","0.00400000"],["63536.01000000","0.00012000"],["63535.47000000","0.81245000"],["63535.46000000","0.06543000"],["63534.88000000","0.02000000"],["63534.22000000","0.00000000"],["63533.43000000","0.03951000"],["63532.37000000","1.21774000"],["63532.36000000","3.29102000"],["63532.35000000","0.00000000"],["63532.01000000","0.00000000"],["63531.73000000","0.00009000"],["63530.85000000","0.00000000"],["63530.50000000","0.00850000"],["63530.16000000","1.22840000"],["63530.03000000","0.00000000"],["63528.42000000","0.00000000"],["63528.35000000","0.00000000"],["63528.28000000","0.00000000"],["63528.17000000","0.03145000"],["63527.59000000","0.00000000"],["63527.58000000","0.00000000"],["63527.54000000","0.56707000"],["63517.24000000","1.55971000"],["63516.21000000","0.00000000"],["63515.73000000","0.00400000"],["63514.14000000","0.00000000"],["63512.55000000","0.00000000"],["63511.82000000","0.00000000"],["63510.96000000","0.00923000"],["63510.48000000","0.00000000"],["63509.37000000","0.00000000"],["63493.27000000","0.00000000"],["63490.51000000","0.00000000"],["63488.01000000","0.00000000"],["63482.80000000","0.00000000"],["63468.93000000","0.00000000"],["63406.50000000","0.00000000"],["63304.87000000","0.00160000"],["57187.80000000","0.00440000"]],"a":[["63542.01000000","0.25219000"],["63542.11000000","0.00018000"],["63542.12000000","0.00000000"],["63542.13000000","0.00044000"],["63542.14000000","0.00018000"],["63542.15000000","0.00018000"],["63542.76000000","0.00000000"],["63542.97000000","0.00018000"],["63543.53000000","0.00000000"],["63543.54000000","0.00018000"],["63543.57000000","0.00009000"],["63543.77000000","0.00018000"],["63544.35000000","0.00000000"],["63544.40000000","0.00000000"],["63544.44000000","0.00026000"],["63544.45000000","0.04049000"],["63544.82000000","0.00000000"],["63544.83000000","0.00026000"],["63545.32000000","0.00000000"],["63545.34000000","0.00352000"],["63545.91000000","0.00000000"],["63545.99000000","0.00018000"],["63546.00000000","0.00009000"],["63546.01000000","0.00008000"],["63547.58000000","0.09854000"],["63547.73000000","0.00000000"],["63548.00000000","0.00000000"],["63548.01000000","0.00000000"],["63548.37000000","0.27023000"],["63548.41000000","0.00012000"],["63548.84000000","0.00000000"],["63549.12000000","1.23240000"],["63549.13000000","0.76467000"],["63549.14000000","0.00000000"],["63550.63000000","0.00000000"],["63550.75000000","0.00000000"],["63550.81000000","0.00000000"],["63551.03000000","0.02579000"],["63551.44000000","0.00000000"],["63551.67000000","1.22840000"],["63552.33000000","0.00000000"],["63552.60000000","0.15000000"],["63553.15000000","0.00400000"],["63553.65000000","0.00000000"],["63554.51000000","0.00000000"],["63554.52000000","0.74245000"],["63555.97000000","0.00000000"],["63556.75000000","0.00000000"],["63556.85000000","0.02000000"],["63557.97000000","1.67741000"],["63558.69000000","0.00000000"],["63559.50000000","0.00400000"],["63562.21000000","0.00000000"],["63566.80000000","0.00000000"],["63570.19000000","0.56669000"],["63571.38000000","0.00400000"],["63574.56000000","0.00400000"],["63576.64000000","0.00000000"],["63576.98000000","0.56663000"],["63581.98000000","0.56480000"],["63583.67000000","0.00000000"],["63594.20000000","0.00000000"],["63594.55000000","0.07286000"],["63598.27000000","0.00000000"],["63600.69000000","0.00000000"],["63608.44000000","0.00000000"],["63609.31000000","2.83475000"],["63621.82000000","0.00000000"],["63647.99000000","0.00000000"],["63672.65000000","4.71488000"]]}}
