{"stream":"btcusdt@depth@100ms","data":{"e":"depthUpdate","E":1783465182115,"s":"BTCUSDT","U":97109086309,"u":97109086321,"b":[["57195.92000000","0.00510000"]],"a":[["63557.28000000","0.09450000"],["63563.44000000","0.00000000"],["63655.81000000","0.00157000"],["63655.82000000","0.00000000"],["77811.66000000","0.00019000"]]}}
{"stream":"btcusdt@depth@100ms","data":{"e":"depthUpdate","E":1783465182214,"s":"BTCUSDT","U":97109086322,"u":97109086347,"b":[["63551.02000000","1.04224000"],["63551.01000000","0.00386000"],["63549.13000000","0.09172000"],["63547.50000000","0.00009000"],["63547.49000000","0.70848000"],["63546.67000000","0.00008000"],["63546.01000000","0.00000000"],["63545.79000000","0.46014000"],["63541.20000000","0.41672000"],["63541.19000000","1.22840000"],["63541.18000000","0.00000000"],["63540.64000000","0.00000000"],["63540.39000000","0.00000000"],["63540.38000000","0.00000000"],["63389.85000000","0.00000000"],["63382.14000000","0.01874000"],["62597.75000000","0.00030000"],["57195.92000000","0.00510000"],["50840.82000000","0.00044000"]],"a":[["63554.89000000","0.06416000"]]}}
{"stream":"ethusdt@depth@100ms","data":{"e":"depthUpdate","E":1783465182215,"s":"ETHUSDT","U":78545068670,"u":78545068673,"b":[["1598.00000000","2.60010000"]],"a":[]}}
{"stream":"ethusdt@depth@100ms","data":{"e":"depthUpdate","E":1783465182315,"s":"ETHUSDT","U":78545068674,"u":78545068679,"b":[["1598.00000000","2.58630000"]],"a":[]}}
{"stream":"btcusdt@depth@100ms","data":{"e":"depthUpdate","E":1783465182315,"s":"BTCUSDT","U":97109086348,"u":97109086370,"b":[["63547.57000000","0.00675000"],["63547.49000000","0.70866000"],["63546.00000000","0.02818000"],["63545.79000000","0.46032000"],["63545.33000000","0.04921000"],["63544.78000000","0.06321000"],["57195.92000000","0.00510000"],["57195.00000000","0.00087000"]],"a":[["63606.69000000","0.00000000"]]}}
{"stream":"ethusdt@depth@100ms","data":{"e":"depthUpdate","E":1783465182415,"s":"ETHUSDT","U":78545068680,"u":78545068685,"b":[["1598.00000000","2.60010000"]],"a":[]}}
{"stream":"btcusdt@depth@100ms","data":{"e":"depthUpdate","E":1783465182415,"s":"BTCUSDT","U":97109086371,"u":97109086395,"b":[["63551.02000000","1.04215000"],["63551.01000000","0.00377000"],["63547.50000000","0.00000000"],["63547.49000000","0.00026000"],["63546.01000000","0.00009000"],["63545.79000000","0.00018000"],["63544.94000000","0.70840000"],["63541.21000000","0.46014000"],["62979.06000000","0.00000000"],["57195.92000000","0.00490000"],["40000.00000000","260.73952000"]],"a":[["63551.03000000","3.43446000"],["63551.04000000","0.00123000"]]}}
{"stream":"btcusdt@depth@100ms","data":{"e":"depthUpdate","E":1783465182514,"s":"BTCUSDT","U":97109086396,"u":97109086420,"b":[["63551.02000000","1.04206000"],["63549.13000000","0.09164000"],["63547.57000000","0.00675000"],["63547.49000000","0.00000000"],["63546.00000000","0.02818000"],["63545.79000000","0.00000000"],["63545.33000000","0.04939000"],["63544.94000000","0.70858000"],["57195.92000000","0.00490000"]],"a":[["63621.59000000","1.91970000"],["64064.18000000","0.00000000"]]}}
{"stream":"ethusdt@depth@100ms","data":{"e":"depthUpdate","E":1783465182515,"s":"ETHUSDT","U":78545068686,"u":78545068691,"b":[["1598.00000000","2.60710000"]],"a":[["1776.02000000","24.48000000"],["1776.06000000","8.18760000"],["1776.15000000","0.00740000"]]}}
{"stream":"btcusdt@depth@100ms","data":{"e":"depthUpdate","E":1783465182615,"s":"BTCUSDT","U":97109086421,"u":97109086429,"b":[["63537.00000000","0.00008000"],["57195.92000000","0.00490000"],["50841.00000000","0.23623000"]],"a":[["63562.43000000","0.00008000"]]}}
{"stream":"ethusdt@depth@100ms","data":{"e":"depthUpdate","E":1783465182616,"s":"ETHUSDT","U":78545068692,"u":78545068695,"b":[["1598.00000000","2.60710000"]],"a":[]}}
{"stream":"btcusdt@trade","data":{"e":"trade","E":1783465182683,"s":"BTCUSDT","t":6486989346,"p":"63551.03000000","q":"0.00084000","T":1783465182682,"m":false,"M":true}}
{"stream":"btcusdt@depth@100ms","data":{"e":"depthUpdate","E":1783465182714,"s":"BTCUSDT","U":97109086430,"u":97109086438,"b":[["63549.13000000","0.09172000"],["57195.92000000","0.00480000"],["57195.91000000","0.00010000"]],"a":[["63551.03000000","3.43362000"],["64504.30000000","0.00030000"]]}}
{"stream":"ethusdt@depth@100ms","data":{"e":"depthUpdate","E":1783465182715,"s":"ETHUSDT","U":78545068696,"u":78545068699,"b":[["1598.00000000","2.60010000"]],"a":[["1782.05000000","0.00920000"]]}}
{"stream":"btcusdt@trade","data":{"e":"trade","E":1783465182749,"s":"BTCUSDT","t":6486989347,"p":"63551.03000000","q":"0.00314000","T":1783465182749,"m":false,"M":true}}
{"stream":"btcusdt@depth@100ms","data":{"e":"depthUpdate","E":1783465182814,"s":"BTCUSDT","U":97109086439,"u":97109086445,"b":[["57195.92000000","0.00500000"],["50840.82000000","0.00064000"],["50000.00000000","542.70415000"]],"a":[["63551.03000000","3.43048000"],["63599.61000000","0.07054000"]]}}
{"stream":"ethusdt@depth@100ms","data":{"e":"depthUpdate","E":1783465182815,"s":"ETHUSDT","U":78545068700,"u":78545068706,"b":[["1598.00000000","2.58630000"]],"a":[["1779.15000000","0.00000000"]]}}
{"stream":"ethusdt@depth@100ms","data":{"e":"depthUpdate","E":1783465182919,"s":"ETHUSDT","U":78545068707,"u":78545068720,"b":[["1775.55000000","13.06790000"],["1774.66000000","0.00930000"],["1598.00000000","2.60010000"]],"a":[["1775.59000000","0.03230000"],["1776.45000000","44.80790000"],["1782.70000000","0.00000000"]]}}
{"stream":"btcusdt@depth@100ms","data":{"e":"depthUpdate","E":1783465182919,"s":"BTCUSDT","U":97109086446,"u":97109086454,"b":[["57195.92000000","0.00500000"],["50840.82000000","0.00044000"]],"a":[["63557.28000000","0.00000000"],["63557.38000000","0.09450000"]]}}
{"stream":"btcusdt@depth@100ms","data":{"e":"depthUpdate","E":1783465183014,"s":"BTCUSDT","U":97109086455,"u":97109086461,"b":[["57195.92000000","0.00480000"],["50840.82000000","0.00083000"]],"a":[["63655.80000000","0.00157000"],["63655.81000000","0.00000000"],["63655.82000000","0.00000000"]]}}
{"stream":"ethusdt@depth@100ms","data":{"e":"depthUpdate","E":1783465183015,"s":"ETHUSDT","U":78545068721,"u":78545068727,"b":[["1775.20000000","0.03580000"],["1598.00000000","2.60010000"]],"a":[["1775.92000000","0.32980000"]]}}
{"stream":"ethusdt@depth@100ms","data":{"e":"depthUpdate","E":1783465183115,"s":"ETHUSDT","U":78545068728,"u":78545068732,"b":[["1598.00000000","2.60710000"]],"a":[["1775.72000000","0.10000000"],["1786.25000000","0.00000000"]]}}
{"stream":"btcusdt@depth@100ms","data":{"e":"depthUpdate","E":1783465183115,"s":"BTCUSDT","U":97109086462,"u":97109086475,"b":[["63519.33000000","0.00000000"],["63500.27000000","0.00000000"],["57195.92000000","0.00480000"]],"a":[["63565.46000000","0.00000000"],["63584.53000000","0.00000000"],["63655.79000000","0.00157000"],["63655.80000000","0.00000000"],["63655.82000000","0.00000000"]]}}
{"stream":"btcusdt@depth@100ms","data":{"e":"depthUpdate","E":1783465183214,"s":"BTCUSDT","U":97109086476,"u":97109086485,"b":[["63551.02000000","1.04194000"],["62597.75000000","0.00030000"],["57195.92000000","0.00480000"],["50840.82000000","0.00044000"]],"a":[["63554.89000000","0.06416000"]]}}
{"stream":"ethusdt@depth@100ms","data":{"e":"depthUpdate","E":1783465183217,"s":"ETHUSDT","U":78545068733,"u":78545068739,"b":[["1598.00000000","2.59330000"]],"a":[["1776.77000000","15.61860000"]]}}
{"stream":"ethusdt@depth@100ms","data":{"e":"depthUpdate","E":1783465183315,"s":"ETHUSDT","U":78545068740,"u":78545068748,"b":[["1773.49000000","1.13840000"],["1598.00000000","2.60710000"]],"a":[["1778.83000000","0.00000000"],["1789.80000000","0.00280000"]]}}
{"stream":"btcusdt@depth@100ms","data":{"e":"depthUpdate","E":1783465183315,"s":"BTCUSDT","U":97109086486,"u":97109086489,"b":[["57195.92000000","0.00480000"]],"a":[]}}
{"stream":"btcusdt@depth@100ms","data":{"e":"depthUpdate","E":1783465183414,"s":"BTCUSDT","U":97109086490,"u":97109086510,"b":[["63544.94000000","0.00018000"],["63523.05000000","0.55727000"],["63503.99000000","1.03421000"],["63440.78000000","0.02465000"],["62979.06000000","0.00010000"],["57195.92000000","0.00480000"],["40000.00000000","260.73952000"]],"a":[["63551.03000000","3.43048000"],["63551.04000000","0.00123000"],["63568.15000000","0.00699000"],["63570.03000000","0.53811000"],["63574.11000000","0.00000000"],["63589.10000000","0.99843000"]]}}
{"stream":"ethusdt@depth@100ms","data":{"e":"depthUpdate","E":1783465183415,"s":"ETHUSDT","U":78545068749,"u":78545068753,"b":[["1773.16000000","15.88470000"],["1598.00000000","2.60010000"]],"a":[["1778.50000000","0.61540000"]]}}
{"stream":"btcusdt@depth@100ms","data":{"e":"depthUpdate","E":1783465183514,"s":"BTCUSDT","U":97109086511,"u":97109086530,"b":[["63545.33000000","0.04939000"],["63544.94000000","0.00000000"],["63544.78000000","0.06339000"],["63541.22000000","0.06455000"],["63532.89000000","0.70848000"],["63469.32000000","0.00000000"],["63335.24000000","0.02465000"],["63303.12000000","0.00000000"],["57195.92000000","0.00500000"],["57195.00000000","0.00087000"]],"a":[["63551.03000000","3.43058000"],["63660.02000000","0.00000000"]]}}
{"stream":"ethusdt@depth@100ms","data":{"e":"depthUpdate","E":1783465183515,"s":"ETHUSDT","U":78545068754,"u":78545068760,"b":[["1598.00000000","2.60010000"],["1067.00000000","6.86000000"]],"a":[["1779.11000000","0.00340000"]]}}
{"stream":"btcusdt@depth@100ms","data":{"e":"depthUpdate","E":1783465183614,"s":"BTCUSDT","U":97109086531,"u":97109086547,"b":[["63551.02000000","1.04160000"],["63549.13000000","0.09172000"],["63544.90000000","0.70840000"],["63537.00000000","0.00008000"],["63532.89000000","0.00008000"],["63506.85000000","0.00000000"],["63485.73000000","0.00000000"],["63477.84000000","0.04882000"],["63464.61000000","0.00000000"],["63443.48000000","0.00000000"],["63422.36000000","0.00000000"],["63401.24000000","0.00000000"],["63380.11000000","0.00000000"],["63358.99000000","0.00000000"],["63337.87000000","0.00000000"],["63316.74000000","0.00000000"],["63295.62000000","0.00000000"],["63274.50000000","0.00000000"],["63253.37000000","0.00000000"],["63232.25000000","0.00000000"],["57195.92000000","0.00500000"],["50841.00000000","0.23623000"]],"a":[["63562.43000000","0.00008000"],["63668.57000000","0.05069000"]]}}
{"stream":"ethusdt@depth@100ms","data":{"e":"depthUpdate","E":1783465183615,"s":"ETHUSDT","U":78545068761,"u":78545068765,"b":[["1598.00000000","2.60010000"]],"a":[["1775.56000000","61.96100000"]]}}
{"stream":"ethusdt@depth@100ms","data":{"e":"depthUpdate","E":1783465183715,"s":"ETHUSDT","U":78545068766,"u":78545068773,"b":[["1598.00000000","2.58630000"]],"a":[["1775.56000000","61.96790000"],["1782.66000000","0.01460000"]]}}
{"stream":"btcusdt@depth@100ms","data":{"e":"depthUpdate","E":1783465183715,"s":"BTCUSDT","U":97109086548,"u":97109086559,"b":[["63551.02000000","1.04194000"],["63545.33000000","0.04939000"],["63544.90000000","0.70858000"],["63544.78000000","0.06321000"],["57195.92000000","0.00480000"]],"a":[]}}
{"stream":"btcusdt@trade","data":{"e":"trade","E":1783465183773,"s":"BTCUSDT","t":6486989348,"p":"63551.02000000","q":"0.00163000","T":1783465183773,"m":true,"M":true}}
{"stream":"btcusdt@trade","data":{"e":"trade","E":1783465183773,"s":"BTCUSDT","t":6486989349,"p":"63551.02000000","q":"0.00016000","T":1783465183773,"m":true,"M":true}}
{"stream":"btcusdt@trade","data":{"e":"trade","E":1783465183773,"s":"BTCUSDT","t":6486989350,"p":"63551.02000000","q":"0.00271000","T":1783465183773,"m":true,"M":true}}
{"stream":"btcusdt@trade","data":{"e":"trade","E":1783465183773,"s":"BTCUSDT","t":6486989351,"p":"63551.02000000","q":"0.00008000","T":1783465183773,"m":true,"M":true}}
{"stream":"btcusdt@trade","data":{"e":"trade","E":1783465183773,"s":"BTCUSDT","t":6486989352,"p":"63551.02000000","q":"0.00271000","T":1783465183773,"m":true,"M":true}}
{"stream":"btcusdt@trade","data":{"e":"trade","E":1783465183773,"s":"BTCUSDT","t":6486989353,"p":"63551.02000000","q":"0.00271000","T":1783465183773,"m":true,"M":true}}
{"stream":"btcusdt@trade","data":{"e":"trade","E":1783465183773,"s":"BTCUSDT","t":6486989354,"p":"63551.02000000","q":"0.00201000","T":1783465183773,"m":true,"M":true}}
{"stream":"btcusdt@trade","data":{"e":"trade","E":1783465183773,"s":"BTCUSDT","t":6486989355,"p":"63551.02000000","q":"0.00008000","T":1783465183773,"m":true,"M":true}}
{"stream":"btcusdt@trade","data":{"e":"trade","E":1783465183773,"s":"BTCUSDT","t":6486989356,"p":"63551.02000000","q":"0.00008000","T":1783465183773,"m":true,"M":true}}
{"stream":"btcusdt@trade","data":{"e":"trade","E":1783465183773,"s":"BTCUSDT","t":6486989357,"p":"63551.02000000","q":"0.00009000","T":1783465183773,"m":true,"M":true}}
{"stream":"btcusdt@trade","data":{"e":"trade","E":1783465183773,"s":"BTCUSDT","t":6486989358,"p":"63551.02000000","q":"0.00009000","T":1783465183773,"m":true,"M":true}}
{"stream":"btcusdt@trade","data":{"e":"trade","E":1783465183773,"s":"BTCUSDT","t":6486989359,"p":"63551.02000000","q":"0.00009000","T":1783465183773,"m":true,"M":true}}
{"stream":"btcusdt@trade","data":{"e":"trade","E":1783465183773,"s":"BTCUSDT","t":6486989360,"p":"63551.02000000","q":"0.00009000","T":1783465183773,"m":true,"M":true}}
{"stream":"btcusdt@trade","data":{"e":"trade","E":1783465183773,"s":"BTCUSDT","t":6486989361,"p":"63551.02000000","q":"0.00008000","T":1783465183773,"m":true,"M":true}}
{"stream":"btcusdt@trade","data":{"e":"trade","E":1783465183773,"s":"BTCUSDT","t":6486989362,"p":"63551.02000000","q":"0.00009000","T":1783465183773,"m":true,"M":true}}
{"stream":"btcusdt@trade","data":{"e":"trade","E":1783465183773,"s":"BTCUSDT","t":6486989363,"p":"63551.02000000","q":"0.00009000","T":1783465183773,"m":true,"M":true}}
{"stream":"btcusdt@trade","data":{"e":"trade","E":1783465183773,"s":"BTCUSDT","t":6486989364,"p":"63551.02000000","q":"0.00009000","T":1783465183773,"m":true,"M":true}}
{"stream":"btcusdt@trade","data":{"e":"trade","E":1783465183773,"s":"BTCUSDT","t":6486989365,"p":"63551.02000000","q":"0.00009000","T":1783465183773,"m":true,"M":true}}
{"stream":"btcusdt@trade","data":{"e":"trade","E":1783465183773,"s":"BTCUSDT","t":6486989366,"p":"63551.02000000","q":"0.00009000","T":1783465183773,"m":true,"M":true}}
{"stream":"btcusdt@trade","data":{"e":"trade","E":1783465183773,"s":"BTCUSDT","t":6486989367,"p":"63551.02000000","q":"0.00786000","T":1783465183773,"m":true,"M":true}}
{"stream":"btcusdt@trade","data":{"e":"trade","E":1783465183773,"s":"BTCUSDT","t":6486989368,"p":"63551.02000000","q":"0.00350000","T":1783465183773,"m":true,"M":true}}
{"stream":"btcusdt@trade","data":{"e":"trade","E":1783465183773,"s":"BTCUSDT","t":6486989369,"p":"63551.02000000","q":"0.02594000","T":1783465183773,"m":true,"M":true}}
{"stream":"ethusdt@depth@100ms","data":{"e":"depthUpdate","E":1783465183815,"s":"ETHUSDT","U":78545068774,"u":78545068779,"b":[["1598.00000000","2.60710000"]],"a":[["1953.12000000","0.00710000"]]}}
{"stream":"btcusdt@depth@100ms","data":{"e":"depthUpdate","E":1783465183815,"s":"BTCUSDT","U":97109086560,"u":97109086582,"b":[["63551.02000000","1.01149000"],["63539.58000000","0.00400000"],["57195.92000000","0.00480000"],["57195.91000000","0.00000000"]],"a":[["63551.03000000","3.43066000"],["64504.30000000","0.00030000"]]}}
{"stream":"ethusdt@trade","data":{"e":"trade","E":1783465183854,"s":"ETHUSDT","t":4197008394,"p":"1775.55000000","q":"0.00290000","T":1783465183853,"m":true,"M":true}}
{"stream":"ethusdt@trade","data":{"e":"trade","E":1783465183854,"s":"ETHUSDT","t":4197008395,"p":"1775.55000000","q":"0.00300000","T":1783465183853,"m":true,"M":true}}
{"stream":"ethusdt@trade","data":{"e":"trade","E":1783465183854,"s":"ETHUSDT","t":4197008396,"p":"1775.55000000","q":"0.00290000","T":1783465183853,"m":true,"M":true}}
{"stream":"ethusdt@trade","data":{"e":"trade","E":1783465183854,"s":"ETHUSDT","t":4197008397,"p":"1775.55000000","q":"0.00290000","T":1783465183853,"m":true,"M":true}}
{"stream":"ethusdt@trade","data":{"e":"trade","E":1783465183854,"s":"ETHUSDT","t":4197008398,"p":"1775.55000000","q":"0.00290000","T":1783465183853,"m":true,"M":true}}
{"stream":"ethusdt@trade","data":{"e":"trade","E":1783465183854,"s":"ETHUSDT","t":4197008399,"p":"1775.55000000","q":"0.00290000","T":1783465183853,"m":true,"M":true}}
{"stream":"ethusdt@trade","data":{"e":"trade","E":1783465183854,"s":"ETHUSDT","t":4197008400,"p":"1775.55000000","q":"0.78250000","T":1783465183853,"m":true,"M":true}}
{"stream":"ethusdt@trade","data":{"e":"trade","E":1783465183854,"s":"ETHUSDT","t":4197008401,"p":"1775.55000000","q":"0.40000000","T":1783465183854,"m":true,"M":true}}
{"stream":"ethusdt@trade","data":{"e":"trade","E":1783465183855,"s":"ETHUSDT","t":4197008402,"p":"1775.55000000","q":"0.00290000","T":1783465183855,"m":true,"M":true}}
{"stream":"ethusdt@trade","data":{"e":"trade","E":1783465183855,"s":"ETHUSDT","t":4197008403,"p":"1775.55000000","q":"0.00010000","T":1783465183855,"m":true,"M":true}}
{"stream":"btcusdt@depth@100ms","data":{"e":"depthUpdate","E":1783465183914,"s":"BTCUSDT","U":97109086583,"u":97109086628,"b":[["63551.02000000","0.71126000"],["63551.01000000","0.00368000"],["63550.59000000","0.00000000"],["63550.58000000","0.00018000"],["63546.01000000","0.00018000"],["63545.34000000","0.00009000"],["63544.01000000","0.00000000"],["63542.85000000","0.00787000"],["63541.20000000","0.00000000"],["63538.62000000","0.42499000"],["63538.60000000","0.00000000"],["63538.55000000","0.00000000"],["63537.77000000","0.00000000"],["63534.31000000","0.01574000"],["63499.19000000","0.00000000"],["63488.75000000","0.03541000"],["63476.72000000","2.83475000"],["57195.92000000","0.00480000"],["50840.82000000","0.00044000"]],"a":[["63551.03000000","3.43048000"],["63551.04000000","0.00114000"],["63551.82000000","0.00787000"],["63553.16000000","0.00018000"],["63553.81000000","0.00000000"],["63562.79000000","0.78732000"],["63565.24000000","0.00000000"]]}}
{"stream":"ethusdt@depth@100ms","data":{"e":"depthUpdate","E":1783465183915,"s":"ETHUSDT","U":78545068780,"u":78545069001,"b":[["1775.55000000","10.43400000"],["1775.54000000","0.01740000"],["1775.51000000","0.44600000"],["1775.50000000","6.80270000"],["1775.49000000","0.00300000"],["1775.48000000","0.00590000"],["1775.46000000","0.08160000"],["1775.45000000","0.58600000"],["1775.44000000","1.84420000"],["1775.43000000","0.15360000"],["1775.42000000","0.00000000"],["1775.41000000","0.00000000"],["1775.40000000","0.00600000"],["1775.39000000","0.44290000"],["1775.38000000","0.72000000"],["1775.37000000","0.78100000"],["1775.35000000","0.00720000"],["1775.33000000","0.14000000"],["1775.31000000","0.87690000"],["1775.29000000","2.24920000"],["1775.28000000","1.09330000"],["1775.27000000","0.06570000"],["1775.26000000","0.00290000"],["1775.25000000","2.92230000"],["1775.24000000","0.27260000"],["1775.21000000","0.00000000"],["1775.16000000","0.28910000"],["1775.11000000","0.43700000"],["1775.10000000","25.23430000"],["1775.09000000","32.91260000"],["1775.08000000","0.00000000"],["1775.05000000","2.08510000"],["1775.04000000","0.03290000"],["1774.97000000","17.11170000"],["1774.94000000","33.11620000"],["1774.93000000","2.48640000"],["1774.85000000","6.57700000"],["1774.82000000","16.58990000"],["1774.80000000","0.47730000"],["1774.77000000","48.30320000"],["1774.76000000","0.00850000"],["1774.75000000","0.43990000"],["1774.74000000","0.00290000"],["1774.71000000","25.69360000"],["1774.69000000","0.20630000"],["1774.65000000","0.00000000"],["1774.62000000","0.44440000"],["1774.58000000","15.42160000"],["1774.57000000","0.57400000"],["1774.55000000","17.17140000"],["1774.54000000","0.00000000"],["1774.50000000","9.53630000"],["1774.49000000","11.11700000"],["1774.42000000","0.61270000"],["1774.36000000","15.77250000"],["1774.35000000","0.00400000"],["1774.34000000","0.43990000"],["1774.23000000","17.34950000"],["1774.22000000","15.23530000"],["1774.19000000","0.43700000"],["1774.18000000","0.00290000"],["1774.13000000","15.76960000"],["1774.12000000","0.28580000"],["1774.11000000","0.99700000"],["1774.10000000","0.00290000"],["1774.04000000","0.14000000"],["1774.01000000","17.35240000"],["1774.00000000","5.62280000"],["1773.90000000","15.46310000"],["1773.79000000","0.00000000"],["1773.72000000","0.56730000"],["1773.68000000","15.01870000"],["1773.67000000","0.14790000"],["1773.60000000","8.32160000"],["1773.56000000","0.56950000"],["1773.54000000","1.00140000"],["1773.50000000","0.02820000"],["1773.48000000","2.47500000"],["1773.44000000","6.31360000"],["1773.42000000","0.00000000"],["1773.38000000","0.13250000"],["1773.37000000","0.00720000"],["1773.36000000","7.89200000"],["1773.12000000","0.00000000"],["1773.01000000","0.00290000"],["1772.87000000","0.00000000"],["1772.86000000","0.00000000"],["1772.85000000","0.00000000"],["1772.79000000","15.01870000"],["1772.72000000","0.00460000"],["1772.66000000","0.00290000"],["1772.60000000","0.02000000"],["1772.28000000","0.00740000"],["1771.96000000","0.01140000"],["1598.00000000","2.60710000"]],"a":[["1775.56000000","61.99180000"],["1775.57000000","5.27400000"],["1775.60000000","0.32690000"],["1775.62000000","0.60620000"],["1775.68000000","0.88340000"],["1775.69000000","15.30440000"],["1775.72000000","6.86320000"],["1775.80000000","0.01980000"],["1775.81000000","0.00580000"],["1775.88000000","22.10670000"],["1775.93000000","1.76900000"],["1775.94000000","0.00580000"],["1775.99000000","8.34660000"],["1777.45000000","0.00000000"],["1786.21000000","0.04290000"],["1953.12000000","0.00420000"]]}}
{"stream":"btcusdt@depth@100ms","data":{"e":"depthUpdate","E":1783465184014,"s":"BTCUSDT","U":97109086629,"u":97109086657,"b":[["63551.02000000","0.71136000"],["63550.58000000","0.00000000"],["63543.75000000","0.00787000"],["63542.85000000","0.00000000"],["63541.22000000","0.60901000"],["63538.61000000","1.38328000"],["63335.24000000","0.00000000"],["63318.08000000","0.02465000"],["57195.92000000","0.00480000"],["50840.82000000","0.00083000"]],"a":[["63551.71000000","0.06434000"],["63551.82000000","0.00018000"],["63553.16000000","0.00787000"],["63562.79000000","0.00000000"],["63565.24000000","0.78732000"],["63592.34000000","0.00393000"],["63655.79000000","0.00000000"]]}}
{"stream":"ethusdt@depth@100ms","data":{"e":"depthUpdate","E":1783465184015,"s":"ETHUSDT","U":78545069002,"u":78545069025,"b":[["1775.52000000","0.01190000"],["1775.50000000","7.23970000"],["1775.39000000","0.43990000"],["1775.38000000","0.71700000"],["1775.18000000","0.28180000"],["1775.16000000","0.00740000"],["1775.13000000","0.00840000"],["1775.12000000","5.02310000"],["1775.11000000","17.82680000"],["1775.05000000","6.45540000"],["1774.98000000","15.03450000"],["1773.54000000","0.56440000"],["1773.49000000","1.75850000"],["1773.16000000","14.03850000"],["1772.79000000","0.00000000"],["1598.00000000","2.60710000"]],"a":[["1775.57000000","0.89080000"],["1775.69000000","0.56750000"],["1775.75000000","15.78060000"],["1778.50000000","0.05000000"],["1778.83000000","0.56540000"]]}}
{"stream":"btcusdt@depth@100ms","data":{"e":"depthUpdate","E":1783465184114,"s":"BTCUSDT","U":97109086658,"u":97109086676,"b":[["63539.21000000","0.00000000"],["63490.51000000","0.64771000"],["57195.92000000","0.00500000"]],"a":[["63551.71000000","0.06434000"],["63551.82000000","0.00000000"],["63553.16000000","0.00805000"],["63592.34000000","0.00393000"]]}}
{"stream":"ethusdt@depth@100ms","data":{"e":"depthUpdate","E":1783465184115,"s":"ETHUSDT","U":78545069026,"u":78545069039,"b":[["1775.20000000","0.03580000"],["1774.78000000","22.03780000"],["1774.24000000","10.37960000"],["1598.00000000","2.58630000"]],"a":[["1775.92000000","0.32980000"],["1775.93000000","0.43700000"],["1779.87000000","0.00000000"],["1779.95000000","0.88220000"],["1789.76000000","0.00720000"]]}}
{"stream":"btcusdt@depth@100ms","data":{"e":"depthUpdate","E":1783465184214,"s":"BTCUSDT","U":97109086677,"u":97109086686,"b":[["63548.53000000","0.14426000"],["63544.90000000","0.00018000"],["63534.05000000","0.70840000"],["62597.75000000","0.00030000"],["57195.92000000","0.00500000"],["50840.82000000","0.00044000"]],"a":[]}}
{"stream":"ethusdt@depth@100ms","data":{"e":"depthUpdate","E":1783465184215,"s":"ETHUSDT","U":78545069040,"u":78545069045,"b":[["1598.00000000","2.60010000"]],"a":[]}}
{"stream":"btcusdt@depth@100ms","data":{"e":"depthUpdate","E":1783465184314,"s":"BTCUSDT","U":97109086687,"u":97109086709,"b":[["63551.02000000","0.71145000"],["63551.01000000","0.00377000"],["63549.13000000","0.09172000"],["63548.54000000","0.00018000"],["63548.53000000","0.14444000"],["63545.34000000","0.00000000"],["63545.33000000","0.04939000"],["63544.90000000","0.00000000"],["57195.92000000","0.00500000"]],"a":[]}}
{"stream":"ethusdt@depth@100ms","data":{"e":"depthUpdate","E":1783465184316,"s":"ETHUSDT","U":78545069046,"u":78545069049,"b":[["1598.00000000","2.60010000"]],"a":[]}}
{"stream":"ethusdt@depth@100ms","data":{"e":"depthUpdate","E":1783465184415,"s":"ETHUSDT","U":78545069050,"u":78545069055,"b":[["1598.00000000","2.60010000"],["1035.00000000","46.09940000"]],"a":[["1775.69000000","0.28570000"],["1775.71000000","0.28180000"]]}}
{"stream":"btcusdt@depth@100ms","data":{"e":"depthUpdate","E":1783465184415,"s":"BTCUSDT","U":97109086710,"u":97109086723,"b":[["63551.02000000","0.71157000"],["57195.92000000","0.00480000"],["50841.00000000","0.23623000"],["40000.00000000","260.73952000"]],"a":[["63617.50000000","0.00807000"],["63623.77000000","0.00000000"]]}}
{"stream":"btcusdt@trade","data":{"e":"trade","E":1783465184421,"s":"BTCUSDT","t":6486989370,"p":"63551.02000000","q":"0.00015000","T":1783465184421,"m":true,"M":true}}
{"stream":"btcusdt@depth@100ms","data":{"e":"depthUpdate","E":1783465184514,"s":"BTCUSDT","U":97109086724,"u":97109086729,"b":[["63551.02000000","0.71142000"],["57195.92000000","0.00480000"],["57195.00000000","0.00107000"]],"a":[]}}
{"stream":"ethusdt@depth@100ms","data":{"e":"depthUpdate","E":1783465184515,"s":"ETHUSDT","U":78545069056,"u":78545069058,"b":[["1598.00000000","2.60710000"]],"a":[]}}
{"stream":"btcusdt@depth@100ms","data":{"e":"depthUpdate","E":1783465184615,"s":"BTCUSDT","U":97109086730,"u":97109086736,"b":[["63537.00000000","0.00000000"],["63231.04000000","0.00522000"],["57195.92000000","0.00480000"],["57195.00000000","0.00087000"]],"a":[["63562.43000000","0.00000000"]]}}
{"stream":"ethusdt@depth@100ms","data":{"e":"depthUpdate","E":1783465184615,"s":"ETHUSDT","U":78545069059,"u":78545069064,"b":[["1598.00000000","2.59330000"]],"a":[]}}
{"stream":"btcusdt@depth@100ms","data":{"e":"depthUpdate","E":1783465184714,"s":"BTCUSDT","U":97109086737,"u":97109086775,"b":[["63551.02000000","0.94081000"],["63550.48000000","0.13860000"],["63548.53000000","0.00018000"],["63538.63000000","2.83475000"],["63537.00000000","0.00008000"],["63534.05000000","0.00000000"],["63476.72000000","0.00000000"],["63406.23000000","0.00000000"],["63252.15000000","0.00522000"],["57195.92000000","0.00480000"]],"a":[["63551.03000000","3.42182000"],["63551.04000000","0.00123000"],["63551.52000000","0.00008000"],["63553.16000000","0.00018000"],["63553.81000000","0.00018000"],["63553.82000000","0.00018000"],["63554.50000000","0.00000000"],["63554.65000000","0.00108000"],["63557.56000000","0.00008000"],["63557.78000000","0.00008000"],["63560.91000000","0.00008000"],["63562.43000000","0.00008000"],["63562.80000000","0.00000000"],["63564.04000000","0.00008000"],["63578.03000000","0.56662000"],["63599.61000000","0.00000000"]]}}
{"stream":"ethusdt@depth@100ms","data":{"e":"depthUpdate","E":1783465184715,"s":"ETHUSDT","U":78545069065,"u":78545069296,"b":[["1775.55000000","18.05540000"],["1775.54000000","0.00870000"],["1775.51000000","3.40530000"],["1775.50000000","7.33970000"],["1775.44000000","1.87420000"],["1775.40000000","0.00300000"],["1775.33000000","0.43200000"],["1775.32000000","0.84470000"],["1775.31000000","25.46770000"],["1775.28000000","0.99330000"],["1775.26000000","25.23430000"],["1775.18000000","0.00000000"],["1775.11000000","20.64490000"],["1775.02000000","2.54900000"],["1774.97000000","14.29350000"],["1774.24000000","10.34960000"],["1773.85000000","0.00000000"],["1773.84000000","0.00000000"],["1773.79000000","12.07510000"],["1773.67000000","0.14790000"],["1773.62000000","0.43990000"],["1773.61000000","0.00000000"],["1773.60000000","0.43700000"],["1773.37000000","7.89200000"],["1773.36000000","0.00740000"],["1598.00000000","2.60010000"]],"a":[["1775.56000000","12.47780000"],["1775.57000000","1.21740000"],["1775.60000000","0.04480000"],["1775.61000000","0.90410000"],["1775.70000000","13.41350000"],["1775.71000000","0.00000000"],["1775.72000000","0.00000000"],["1775.75000000","0.01140000"],["1775.76000000","0.03580000"],["1775.77000000","0.00290000"],["1775.80000000","0.00000000"],["1775.83000000","8.26660000"],["1775.84000000","24.62370000"],["1775.85000000","0.00000000"],["1775.86000000","10.55380000"],["1775.87000000","0.00000000"],["1775.88000000","1.94250000"],["1775.97000000","25.53280000"],["1775.98000000","0.16660000"],["1775.99000000","15.48070000"],["1776.01000000","0.99690000"],["1776.02000000","49.07100000"],["1776.03000000","0.87190000"],["1776.06000000","7.57760000"],["1776.11000000","9.46180000"],["1776.13000000","23.65730000"],["1776.14000000","0.00290000"],["1776.19000000","0.00000000"],["1776.20000000","15.01870000"],["1776.22000000","9.46470000"],["1776.24000000","7.92510000"],["1776.25000000","12.30210000"],["1776.26000000","8.07770000"],["1776.27000000","0.00000000"],["1776.33000000","9.47210000"],["1776.35000000","15.49480000"],["1776.36000000","38.18570000"],["1776.37000000","0.30250000"],["1776.38000000","0.65400000"],["1776.43000000","8.32470000"],["1776.44000000","31.13420000"],["1776.48000000","3.41980000"],["1776.49000000","0.00290000"],["1776.54000000","31.22530000"],["1776.55000000","17.99940000"],["1776.59000000","14.11160000"],["1776.60000000","0.00740000"],["1776.66000000","10.24280000"],["1776.71000000","20.42350000"],["1776.72000000","0.03580000"],["1776.73000000","0.87400000"],["1776.76000000","24.59620000"],["1776.77000000","0.60500000"],["1776.79000000","0.00000000"],["1776.80000000","17.50090000"],["1776.83000000","0.73100000"],["1776.84000000","0.00580000"],["1776.88000000","10.00360000"],["1776.91000000","2.89200000"],["1776.92000000","15.80170000"],["1776.94000000","0.00000000"],["1776.95000000","0.00000000"],["1776.98000000","2.77620000"],["1777.04000000","15.25140000"],["1777.10000000","0.00000000"],["1777.26000000","2.81810000"],["1777.29000000","15.01870000"],["1777.42000000","0.00000000"],["1777.43000000","0.00000000"],["1777.47000000","9.75580000"],["1777.49000000","7.98180000"],["1777.55000000","7.90220000"],["1777.61000000","7.88480000"],["1777.69000000","13.90910000"],["1777.71000000","7.88480000"],["1777.77000000","7.89460000"],["1777.84000000","0.00000000"],["1777.87000000","0.00000000"],["1777.93000000","7.88480000"],["1777.99000000","7.88480000"],["1778.02000000","0.00000000"],["1778.09000000","0.00000000"],["1778.15000000","7.93470000"],["1778.20000000","15.23340000"],["1778.25000000","0.01140000"],["1778.26000000","33.23450000"],["1778.37000000","0.00000000"],["1778.48000000","0.92570000"],["1778.56000000","15.01870000"],["1778.80000000","15.03010000"],["1779.02000000","22.35990000"],["1779.27000000","16.35360000"],["1779.95000000","0.00000000"],["1780.76000000","0.95670000"]]}}
{"stream":"ethusdt@trade","data":{"e":"trade","E":1783465184743,"s":"ETHUSDT","t":4197008404,"p":"1775.56000000","q":"0.00300000","T":1783465184743,"m":false,"M":true}}
{"stream":"btcusdt@trade","data":{"e":"trade","E":1783465184764,"s":"BTCUSDT","t":6486989371,"p":"63551.02000000","q":"0.00135000","T":1783465184763,"m":true,"M":true}}
{"stream":"btcusdt@trade","data":{"e":"trade","E":1783465184764,"s":"BTCUSDT","t":6486989372,"p":"63551.02000000","q":"0.00227000","T":1783465184763,"m":true,"M":true}}
{"stream":"btcusdt@depth@100ms","data":{"e":"depthUpdate","E":1783465184814,"s":"BTCUSDT","U":97109086776,"u":97109086939,"b":[["63551.02000000","1.73754000"],["63551.01000000","0.00377000"],["63550.49000000","0.00018000"],["63550.48000000","0.13878000"],["63549.13000000","0.09146000"],["63548.54000000","0.00000000"],["63548.53000000","0.00000000"],["63546.01000000","0.00000000"],["63545.82000000","0.06464000"],["63545.13000000","0.00787000"],["63544.78000000","0.22880000"],["63544.35000000","0.00400000"],["63543.75000000","1.22840000"],["63541.23000000","0.42498000"],["63538.64000000","1.86515000"],["63538.62000000","0.00000000"],["63538.61000000","0.00000000"],["63538.59000000","0.00000000"],["63536.49000000","0.03024000"],["63532.72000000","0.45627000"],["63530.37000000","0.00000000"],["63518.91000000","0.00000000"],["63517.09000000","0.00000000"],["63490.51000000","0.00000000"],["63273.26000000","0.00522000"],["57195.92000000","0.00500000"],["50000.00000000","542.70395000"]],"a":[["63551.03000000","2.10300000"],["63551.04000000","0.01017000"],["63551.68000000","0.07680000"],["63551.69000000","0.00018000"],["63551.70000000","0.00054000"],["63551.71000000","0.06434000"],["63552.13000000","0.00018000"],["63552.14000000","0.00000000"],["63552.44000000","0.06000000"],["63553.16000000","0.00018000"],["63553.17000000","0.03969000"],["63553.54000000","0.08000000"],["63553.81000000","0.00000000"],["63553.82000000","0.00000000"],["63554.35000000","0.00018000"],["63554.52000000","0.01338000"],["63554.75000000","0.00996000"],["63554.87000000","0.00787000"],["63554.88000000","0.00000000"],["63554.89000000","0.06408000"],["63556.11000000","0.00000000"],["63556.12000000","0.00000000"],["63557.38000000","0.00000000"],["63557.47000000","0.09323000"],["63557.56000000","0.09458000"],["63557.95000000","0.59048000"],["63560.85000000","0.00000000"],["63561.81000000","0.00000000"],["63561.95000000","0.53329000"],["63562.55000000","0.07874000"],["63563.21000000","0.00000000"],["63565.24000000","0.00000000"],["63565.28000000","1.20884000"],["63567.75000000","0.78729000"],["63579.62000000","0.00010000"],["63591.81000000","0.00216000"],["63599.74000000","0.00000000"],["63613.00000000","0.00000000"],["63613.35000000","0.00000000"],["63614.04000000","0.00000000"],["63615.25000000","0.94482000"],["64504.30000000","0.00030000"]]}}
{"stream":"ethusdt@depth@100ms","data":{"e":"depthUpdate","E":1783465184815,"s":"ETHUSDT","U":78545069297,"u":78545069415,"b":[["1775.55000000","17.14620000"],["1775.54000000","0.00870000"],["1775.52000000","0.04190000"],["1775.49000000","0.00900000"],["1775.48000000","0.85060000"],["1775.40000000","0.00000000"],["1775.39000000","0.43990000"],["1775.32000000","18.65990000"],["1775.31000000","0.87690000"],["1775.29000000","1.40440000"],["1775.28000000","0.96920000"],["1775.27000000","7.94110000"],["1775.02000000","1.21700000"],["1774.96000000","1.80190000"],["1774.69000000","1.00630000"],["1774.49000000","10.31700000"],["1774.32000000","0.00000000"],["1773.86000000","0.00290000"],["1773.69000000","12.10110000"],["1773.44000000","4.53890000"],["1773.37000000","0.00720000"],["1772.45000000","0.88220000"],["1772.38000000","24.90710000"],["1598.00000000","2.60010000"]],"a":[["1775.56000000","11.26120000"],["1775.57000000","1.21740000"],["1775.59000000","0.03230000"],["1775.60000000","11.28050000"],["1775.61000000","0.17920000"],["1775.62000000","0.60020000"],["1775.63000000","0.36690000"],["1775.64000000","0.28280000"],["1775.67000000","0.00600000"],["1775.69000000","0.28870000"],["1775.70000000","1.47990000"],["1775.74000000","1.30180000"],["1775.78000000","2.48000000"],["1775.79000000","0.44440000"],["1775.83000000","7.91670000"],["1775.85000000","0.00960000"],["1775.86000000","1.09200000"],["1775.88000000","9.03310000"],["1775.89000000","1.58640000"],["1775.99000000","0.46200000"],["1776.01000000","16.01560000"],["1776.04000000","0.46520000"],["1776.05000000","5.54010000"],["1776.11000000","9.46180000"],["1776.36000000","15.76960000"],["1776.44000000","9.93240000"],["1776.56000000","7.83220000"],["1776.58000000","0.60000000"],["1776.64000000","2.30820000"],["1776.78000000","25.07120000"],["1776.88000000","10.03360000"],["1776.91000000","10.77680000"],["1776.93000000","0.44700000"],["1777.09000000","0.00000000"],["1777.41000000","13.71440000"],["1777.59000000","0.00400000"],["1777.61000000","7.88480000"],["1778.20000000","7.34860000"],["1778.87000000","46.98760000"]]}}
{"stream":"btcusdt@depth@100ms","data":{"e":"depthUpdate","E":1783465184914,"s":"BTCUSDT","U":97109086940,"u":97109087069,"b":[["63551.02000000","2.44632000"],["63551.01000000","0.00584000"],["63549.13000000","0.09164000"],["63546.01000000","0.00009000"],["63546.00000000","0.02818000"],["63545.94000000","0.00400000"],["63545.33000000","0.04921000"],["63544.62000000","0.00000000"],["63543.76000000","0.06455000"],["63543.74000000","0.00000000"],["63542.70000000","0.00000000"],["63541.24000000","0.00000000"],["63541.22000000","0.54446000"],["63541.21000000","0.00000000"],["63537.82000000","0.03079000"],["63536.49000000","0.00000000"],["63520.50000000","0.00000000"],["63294.37000000","0.00522000"],["57195.92000000","0.00500000"],["50840.82000000","0.00044000"]],"a":[["63551.03000000","2.09327000"],["63551.04000000","0.00159000"],["63551.68000000","0.11115000"],["63551.69000000","0.00000000"],["63551.71000000","0.06434000"],["63552.13000000","0.00000000"],["63552.43000000","0.00018000"],["63552.44000000","0.07026000"],["63553.17000000","0.03969000"],["63553.53000000","0.00009000"],["63553.54000000","0.08018000"],["63554.35000000","0.00009000"],["63554.52000000","0.01320000"],["63554.75000000","0.00978000"],["63554.87000000","0.00000000"],["63557.04000000","0.00787000"],["63557.27000000","0.06455000"],["63557.38000000","0.06455000"],["63557.56000000","0.00008000"],["63557.63000000","0.00000000"],["63557.73000000","0.00000000"],["63557.96000000","0.00008000"],["63558.69000000","0.45627000"],["63562.55000000","0.00000000"],["63565.24000000","0.26327000"],["63565.28000000","1.17449000"],["63568.15000000","0.00000000"],["63600.27000000","0.00008000"],["63607.20000000","0.00000000"],["63615.25000000","0.00000000"],["63615.26000000","0.94482000"],["63617.50000000","0.00000000"],["64064.18000000","0.00264000"]]}}
{"stream":"ethusdt@depth@100ms","data":{"e":"depthUpdate","E":1783465184915,"s":"ETHUSDT","U":78545069416,"u":78545069449,"b":[["1775.55000000","17.00520000"],["1775.32000000","19.16670000"],["1775.31000000","0.95030000"],["1775.28000000","25.56000000"],["1774.97000000","14.85710000"],["1598.00000000","2.60010000"]],"a":[["1775.56000000","11.26410000"],["1775.57000000","1.22030000"],["1775.58000000","0.01760000"],["1775.59000000","4.17780000"],["1775.60000000","0.00880000"],["1775.61000000","0.17320000"],["1775.63000000","11.89330000"],["1775.64000000","0.28280000"],["1775.67000000","0.00900000"],["1775.68000000","0.85040000"],["1775.98000000","6.92980000"],["1776.34000000","17.79870000"],["1776.80000000","17.53090000"],["1780.76000000","0.07450000"]]}}
{"stream":"btcusdt@depth@100ms","data":{"e":"depthUpdate","E":1783465185014,"s":"BTCUSDT","U":97109087070,"u":97109087135,"b":[["63551.02000000","2.03169000"],["63551.01000000","0.00593000"],["63547.53000000","0.00400000"],["63546.87000000","0.00787000"],["63545.13000000","0.00000000"],["63541.22000000","0.40711000"],["63540.60000000","0.03118000"],["63540.54000000","0.00010000"],["63537.82000000","0.00000000"],["63522.09000000","0.00000000"],["63478.81000000","1.02661000"],["63476.71000000","0.00000000"],["63315.48000000","0.00522000"],["57195.92000000","0.00500000"],["50840.82000000","0.00083000"]],"a":[["63551.03000000","2.10181000"],["63551.04000000","0.00123000"],["63551.16000000","0.00863000"],["63554.52000000","0.01338000"],["63554.89000000","0.06416000"],["63555.81000000","0.00787000"],["63557.04000000","0.00000000"],["63557.73000000","0.00000000"],["63557.74000000","0.00000000"],["63557.75000000","0.00000000"],["63559.36000000","0.00000000"],["63559.45000000","0.09450000"],["63565.28000000","1.75687000"],["63577.33000000","0.00699000"],["63581.05000000","0.00000000"],["63585.16000000","0.03084000"],["63592.34000000","0.00393000"],["63615.26000000","0.00000000"],["63615.27000000","0.00000000"],["63616.12000000","0.94482000"]]}}
{"stream":"ethusdt@depth@100ms","data":{"e":"depthUpdate","E":1783465185015,"s":"ETHUSDT","U":78545069450,"u":78545069479,"b":[["1775.55000000","17.00810000"],["1775.54000000","0.01160000"],["1775.51000000","0.44600000"],["1768.54000000","0.57510000"],["1768.26000000","0.00000000"],["1598.00000000","2.58630000"]],"a":[["1775.56000000","11.79950000"],["1775.59000000","4.17480000"],["1775.60000000","0.55980000"],["1775.61000000","0.17920000"],["1775.62000000","0.60320000"],["1775.63000000","11.63830000"],["1775.67000000","0.00600000"],["1775.69000000","0.28570000"],["1775.82000000","16.11830000"],["1775.83000000","17.72830000"],["1775.89000000","1.30470000"],["1776.21000000","25.92280000"],["1776.50000000","0.37980000"],["1777.61000000","0.00000000"]]}}
{"stream":"btcusdt@depth@100ms","data":{"e":"depthUpdate","E":1783465185115,"s":"BTCUSDT","U":97109087136,"u":97109087181,"b":[["63551.02000000","1.53321000"],["63549.94000000","0.00000000"],["63547.57000000","0.00657000"],["63546.87000000","0.00000000"],["63546.02000000","0.00787000"],["63544.78000000","0.06321000"],["63544.77000000","0.14114000"],["63544.68000000","0.46013000"],["63544.67000000","0.30326000"],["63543.81000000","0.00068000"],["63543.71000000","0.00000000"],["63543.62000000","0.00000000"],["63541.23000000","0.00000000"],["63539.76000000","0.42499000"],["63336.59000000","0.00521000"],["57195.92000000","0.00480000"]],"a":[["63551.03000000","2.10181000"],["63551.16000000","0.00881000"],["63554.52000000","0.01320000"],["63563.35000000","0.08016000"],["63565.24000000","0.00000000"],["63565.38000000","0.78728000"],["63567.75000000","0.00000000"],["63592.34000000","0.00393000"],["63616.12000000","0.00000000"],["63616.14000000","0.94482000"]]}}
{"stream":"ethusdt@depth@100ms","data":{"e":"depthUpdate","E":1783465185115,"s":"ETHUSDT","U":78545069480,"u":78545069518,"b":[["1775.55000000","17.08410000"],["1775.52000000","0.01190000"],["1775.50000000","6.90270000"],["1775.32000000","18.88490000"],["1775.31000000","0.95030000"],["1775.30000000","3.03160000"],["1775.20000000","0.03580000"],["1774.71000000","26.53000000"],["1774.24000000","10.37960000"],["1773.80000000","25.51620000"],["1773.54000000","1.00140000"],["1598.00000000","2.60710000"]],"a":[["1775.56000000","13.00350000"],["1775.58000000","3.09810000"],["1775.59000000","11.29800000"],["1775.61000000","0.17320000"],["1775.62000000","0.60020000"],["1775.63000000","0.36690000"],["1775.67000000","0.00900000"],["1775.68000000","0.88040000"],["1775.69000000","0.29170000"],["1775.73000000","0.00000000"],["1775.83000000","25.61310000"],["1775.92000000","0.32980000"],["1775.98000000","0.16660000"],["1775.99000000","3.28010000"],["1776.05000000","2.72230000"],["1776.88000000","10.00360000"],["1776.90000000","15.55130000"]]}}
{"stream":"btcusdt@depth@100ms","data":{"e":"depthUpdate","E":1783465185214,"s":"BTCUSDT","U":97109087182,"u":97109087190,"b":[["63543.88000000","0.01047000"],["63357.70000000","0.00521000"],["62597.75000000","0.00030000"],["57195.92000000","0.00480000"],["50840.82000000","0.00044000"]],"a":[]}}
{"stream":"ethusdt@depth@100ms","data":{"e":"depthUpdate","E":1783465185215,"s":"ETHUSDT","U":78545069519,"u":78545069525,"b":[["1775.50000000","7.33970000"],["1773.54000000","0.56440000"],["1598.00000000","2.60710000"]],"a":[["1775.57000000","1.22330000"]]}}
{"stream":"btcusdt@depth@100ms","data":{"e":"depthUpdate","E":1783465185314,"s":"BTCUSDT","U":97109087191,"u":97109087197,"b":[["63378.81000000","0.00521000"],["57195.92000000","0.00480000"]],"a":[["63551.03000000","2.10172000"],["63551.04000000","0.00114000"]]}}
{"stream":"ethusdt@depth@100ms","data":{"e":"depthUpdate","E":1783465185315,"s":"ETHUSDT","U":78545069526,"u":78545069532,"b":[["1768.83000000","0.57510000"],["1768.54000000","0.00000000"],["1598.00000000","2.60710000"],["1067.00000000","6.86000000"]],"a":[]}}
{"stream":"btcusdt@depth@100ms","data":{"e":"depthUpdate","E":1783465185414,"s":"BTCUSDT","U":97109087198,"u":97109087209,"b":[["63551.02000000","0.82481000"],["63546.02000000","0.00000000"],["63544.79000000","0.00787000"],["63399.92000000","0.00521000"],["57195.92000000","0.00480000"],["40000.00000000","260.73952000"]],"a":[["63553.88000000","0.00787000"],["63555.81000000","0.00000000"],["63601.94000000","0.07123000"],["63608.43000000","0.13194000"]]}}
{"stream":"ethusdt@depth@100ms","data":{"e":"depthUpdate","E":1783465185415,"s":"ETHUSDT","U":78545069533,"u":78545069538,"b":[["1773.49000000","1.13840000"],["1598.00000000","2.60010000"]],"a":[["1777.69000000","18.14280000"],["1778.83000000","0.00000000"]]}}
{"stream":"btcusdt@depth@100ms","data":{"e":"depthUpdate","E":1783465185514,"s":"BTCUSDT","U":97109087210,"u":97109087228,"b":[["63551.02000000","0.82472000"],["63539.76000000","0.00000000"],["63539.00000000","0.70856000"],["63538.65000000","0.42499000"],["63477.84000000","0.00000000"],["63421.03000000","0.00521000"],["57195.92000000","0.00500000"]],"a":[["63551.03000000","2.10180000"],["63553.54000000","0.08018000"],["63553.88000000","0.00805000"],["63554.36000000","0.04004000"],["63601.93000000","0.00391000"],["63601.99000000","0.00000000"],["63668.57000000","0.00000000"]]}}
{"stream":"ethusdt@depth@100ms","data":{"e":"depthUpdate","E":1783465185515,"s":"ETHUSDT","U":78545069539,"u":78545069552,"b":[["1774.32000000","0.03000000"],["1774.24000000","10.34960000"],["1773.22000000","1.63480000"],["1598.00000000","2.58630000"]],"a":[["1775.87000000","15.01870000"],["1777.47000000","9.46180000"],["1778.54000000","11.79270000"],["1778.56000000","15.58410000"],["1779.27000000","1.33490000"]]}}
{"stream":"btcusdt@depth@100ms","data":{"e":"depthUpdate","E":1783465185614,"s":"BTCUSDT","U":97109087229,"u":97109087237,"b":[["63470.27000000","0.17283000"],["63442.15000000","0.00521000"],["57195.92000000","0.00500000"],["33000.00000000","35.16979000"]],"a":[["63660.98000000","0.05327000"]]}}
{"stream":"ethusdt@depth@100ms","data":{"e":"depthUpdate","E":1783465185615,"s":"ETHUSDT","U":78545069553,"u":78545069560,"b":[["1768.83000000","0.00000000"],["1768.55000000","1.69230000"],["1598.00000000","2.60010000"]],"a":[["1775.86000000","8.97680000"]]}}
{"stream":"btcusdt@depth@100ms","data":{"e":"depthUpdate","E":1783465185714,"s":"BTCUSDT","U":97109087238,"u":97109087248,"b":[["63537.00000000","0.00008000"],["63463.26000000","0.00520000"],["58466.94000000","0.00018000"],["57195.92000000","0.00480000"],["57195.00000000","0.00087000"]],"a":[["63562.43000000","0.00008000"],["63582.81000000","0.00000000"]]}}
{"stream":"ethusdt@depth@100ms","data":{"e":"depthUpdate","E":1783465185715,"s":"ETHUSDT","U":78545069561,"u":78545069564,"b":[["1598.00000000","2.60010000"]],"a":[]}}
{"stream":"btcusdt@trade","data":{"e":"trade","E":1783465185740,"s":"BTCUSDT","t":6486989373,"p":"63551.02000000","q":"0.00110000","T":1783465185739,"m":true,"M":true}}
{"stream":"btcusdt@depth@100ms","data":{"e":"depthUpdate","E":1783465185814,"s":"BTCUSDT","U":97109087249,"u":97109087262,"b":[["63551.02000000","0.82362000"],["63484.37000000","0.00520000"],["63470.27000000","0.00000000"],["57195.92000000","0.00480000"],["57195.91000000","0.00010000"]],"a":[["63556.24000000","0.00252000"],["63557.47000000","0.00252000"],["63660.98000000","0.00000000"],["64504.30000000","0.00030000"]]}}
{"stream":"ethusdt@depth@100ms","data":{"e":"depthUpdate","E":1783465185815,"s":"ETHUSDT","U":78545069565,"u":78545069589,"b":[["1775.50000000","7.23970000"],["1775.37000000","0.88100000"],["1775.35000000","0.29190000"],["1598.00000000","2.60710000"]],"a":[["1775.56000000","24.27540000"],["1775.57000000","1.22630000"],["1775.58000000","0.96490000"],["1775.59000000","0.03230000"],["1775.60000000","0.56280000"],["1775.61000000","0.17920000"],["1775.62000000","0.60020000"],["1775.67000000","0.00300000"],["1775.69000000","0.28570000"],["1776.41000000","0.35000000"]]}}
{"stream":"btcusdt@depth@100ms","data":{"e":"depthUpdate","E":1783465185914,"s":"BTCUSDT","U":97109087263,"u":97109087273,"b":[["63505.48000000","0.00520000"],["63477.84000000","0.04882000"],["57195.92000000","0.00480000"],["50840.82000000","0.00044000"]],"a":[["63668.57000000","0.05069000"]]}}
{"stream":"ethusdt@depth@100ms","data":{"e":"depthUpdate","E":1783465185915,"s":"ETHUSDT","U":78545069590,"u":78545069595,"b":[["1598.00000000","2.59330000"]],"a":[]}}
{"stream":"btcusdt@depth@100ms","data":{"e":"depthUpdate","E":1783465186014,"s":"BTCUSDT","U":97109087274,"u":97109087284,"b":[["63551.02000000","0.82091000"],["63539.00000000","0.00016000"],["63532.32000000","0.70840000"],["57195.92000000","0.00480000"],["50840.82000000","0.00083000"]],"a":[["63557.96000000","0.00000000"],["63592.34000000","0.00393000"]]}}
{"stream":"ethusdt@depth@100ms","data":{"e":"depthUpdate","E":1783465186015,"s":"ETHUSDT","U":78545069596,"u":78545069604,"b":[["1775.39000000","1.09960000"],["1775.30000000","2.74990000"],["1775.28000000","25.84170000"],["1598.00000000","2.60710000"]],"a":[["1775.58000000","0.01160000"]]}}
{"stream":"ethusdt@trade","data":{"e":"trade","E":1783465186061,"s":"ETHUSDT","t":4197008405,"p":"1775.56000000","q":"0.04220000","T":1783465186061,"m":false,"M":true}}
{"stream":"btcusdt@depth@100ms","data":{"e":"depthUpdate","E":1783465186114,"s":"BTCUSDT","U":97109087285,"u":97109087296,"b":[["63515.51000000","0.01000000"],["63498.71000000","0.00000000"],["63481.92000000","0.00000000"],["63465.12000000","0.00000000"],["63448.33000000","0.00000000"],["63431.53000000","0.00000000"],["63414.73000000","0.00000000"],["63397.94000000","0.00000000"],["63381.14000000","0.00000000"],["63364.35000000","0.00000000"],["63347.55000000","0.00000000"],["63330.75000000","0.00000000"],["63313.96000000","0.00000000"],["63297.16000000","0.00000000"],["57195.92000000","0.00500000"]],"a":[["63592.34000000","0.00393000"],["63619.59000000","0.00807000"]]}}
{"stream":"ethusdt@depth@100ms","data":{"e":"depthUpdate","E":1783465186115,"s":"ETHUSDT","U":78545069605,"u":78545069619,"b":[["1775.20000000","0.03580000"],["1774.31000000","7.64670000"],["1598.00000000","2.60010000"]],"a":[["1775.56000000","24.23320000"],["1775.57000000","1.22030000"],["1775.60000000","1.34330000"],["1775.62000000","0.60320000"],["1775.92000000","0.32980000"],["1776.24000000","15.78980000"],["1776.25000000","7.88770000"]]}}
{"stream":"ethusdt@depth@100ms","data":{"e":"depthUpdate","E":1783465186215,"s":"ETHUSDT","U":78545069620,"u":78545069625,"b":[["1598.00000000","2.60010000"]],"a":[["1776.79000000","5.84190000"],["1777.73000000","1.66680000"]]}}
{"stream":"btcusdt@depth@100ms","data":{"e":"depthUpdate","E":1783465186215,"s":"BTCUSDT","U":97109087297,"u":97109087307,"b":[["63480.91000000","1.02661000"],["63478.81000000","0.00000000"],["63409.28000000","0.09462000"],["62597.75000000","0.00030000"],["58466.94000000","0.00000000"],["57195.92000000","0.00500000"],["50840.82000000","0.00044000"]],"a":[]}}
{"stream":"btcusdt@depth@100ms","data":{"e":"depthUpdate","E":1783465186314,"s":"BTCUSDT","U":97109087308,"u":97109087312,"b":[["57195.92000000","0.00500000"]],"a":[["63556.18000000","0.09071000"]]}}
{"stream":"ethusdt@depth@100ms","data":{"e":"depthUpdate","E":1783465186316,"s":"ETHUSDT","U":78545069626,"u":78545069630,"b":[["1598.00000000","2.60010000"]],"a":[["1775.90000000","7.55150000"]]}}
{"stream":"btcusdt@depth@100ms","data":{"e":"depthUpdate","E":1783465186414,"s":"BTCUSDT","U":97109087313,"u":97109087329,"b":[["63551.02000000","1.04769000"],["63544.77000000","0.14122000"],["63541.23000000","0.57586000"],["63541.22000000","0.70840000"],["63532.32000000","0.00000000"],["63500.01000000","0.58143000"],["57195.92000000","0.00480000"],["40000.00000000","260.73952000"]],"a":[["63554.89000000","0.06424000"],["63557.56000000","0.00000000"],["63615.07000000","0.03109000"],["63741.26000000","0.06310000"]]}}
{"stream":"ethusdt@depth@100ms","data":{"e":"depthUpdate","E":1783465186415,"s":"ETHUSDT","U":78545069631,"u":78545069679,"b":[["1775.55000000","17.51820000"],["1775.54000000","0.00870000"],["1775.52000000","0.00590000"],["1775.51000000","0.00900000"],["1775.50000000","7.23970000"],["1775.44000000","1.87420000"],["1775.40000000","0.00300000"],["1775.31000000","1.23200000"],["1775.28000000","0.96920000"],["1775.27000000","32.53190000"],["1773.54000000","0.56440000"],["1773.50000000","0.02820000"],["1773.48000000","2.47500000"],["1598.00000000","2.58630000"]],"a":[["1775.56000000","17.53150000"],["1775.82000000","24.00310000"],["1775.83000000","0.38170000"],["1775.85000000","7.89440000"],["1775.86000000","18.43860000"],["1775.87000000","0.00000000"],["1777.61000000","0.00000000"],["1777.79000000","17.94400000"]]}}
{"stream":"btcusdt@depth@100ms","data":{"e":"depthUpdate","E":1783465186514,"s":"BTCUSDT","U":97109087330,"u":97109087339,"b":[["57195.92000000","0.00480000"]],"a":[["63562.19000000","0.02408000"],["63562.79000000","0.02900000"],["63563.39000000","0.03500000"],["63563.43000000","0.03000000"],["63568.56000000","0.00000000"],["63569.16000000","0.00000000"]]}}
{"stream":"ethusdt@depth@100ms","data":{"e":"depthUpdate","E":1783465186515,"s":"ETHUSDT","U":78545069680,"u":78545069687,"b":[["1774.06000000","0.14000000"],["1773.31000000","0.56640000"],["1772.56000000","0.00000000"],["1771.82000000","0.00000000"],["1771.07000000","0.00000000"],["1770.32000000","0.01390000"],["1769.57000000","0.00000000"],["1768.82000000","0.16830000"],["1768.07000000","2.47500000"],["1767.32000000","0.00000000"],["1766.57000000","0.01220000"],["1765.83000000","0.00000000"],["1765.08000000","0.04530000"],["1764.33000000","0.00000000"],["1695.60000000","3.62710000"],["1598.00000000","2.60710000"]],"a":[["1777.61000000","0.13460000"]]}}
{"stream":"btcusdt@depth@100ms","data":{"e":"depthUpdate","E":1783465186614,"s":"BTCUSDT","U":97109087340,"u":97109087347,"b":[["57195.92000000","0.00480000"]],"a":[["63569.77000000","0.00008000"],["63569.81000000","0.02700000"],["63604.17000000","0.00000000"],["63604.24000000","0.00000000"]]}}
{"stream":"ethusdt@depth@100ms","data":{"e":"depthUpdate","E":1783465186615,"s":"ETHUSDT","U":78545069688,"u":78545069691,"b":[["1598.00000000","2.60710000"]],"a":[]}}
{"stream":"btcusdt@trade","data":{"e":"trade","E":1783465186670,"s":"BTCUSDT","t":6486989374,"p":"63551.02000000","q":"0.00084000","T":1783465186670,"m":true,"M":true}}
{"stream":"btcusdt@depth@100ms","data":{"e":"depthUpdate","E":1783465186714,"s":"BTCUSDT","U":97109087348,"u":97109087362,"b":[["63551.02000000","1.04685000"],["63537.00000000","0.00008000"],["57195.92000000","0.00480000"],["57195.00000000","0.00107000"]],"a":[["63557.39000000","0.22500000"],["63559.44000000","0.00000000"],["63559.45000000","0.00000000"],["63559.46000000","0.00000000"],["63562.43000000","0.00008000"]]}}
{"stream":"ethusdt@depth@100ms","data":{"e":"depthUpdate","E":1783465186715,"s":"ETHUSDT","U":78545069692,"u":78545069694,"b":[["1598.00000000","2.60010000"]],"a":[]}}
{"stream":"btcusdt@depth@100ms","data":{"e":"depthUpdate","E":1783465186814,"s":"BTCUSDT","U":97109087363,"u":97109087384,"b":[["63541.23000000","0.40708000"],["63541.22000000","0.00000000"],["63537.15000000","0.70840000"],["57195.92000000","0.00510000"],["57195.00000000","0.00087000"]],"a":[["63559.46000000","0.00000000"],["63571.34000000","0.00000000"],["63577.96000000","0.02080000"],["63580.39000000","0.00000000"],["63582.81000000","0.00010000"],["64504.30000000","0.00030000"]]}}
{"stream":"ethusdt@depth@100ms","data":{"e":"depthUpdate","E":1783465186815,"s":"ETHUSDT","U":78545069695,"u":78545069701,"b":[["1768.55000000","1.11720000"],["1768.45000000","0.57520000"],["1598.00000000","2.58630000"]],"a":[]}}
{"stream":"btcusdt@depth@100ms","data":{"e":"depthUpdate","E":1783465186914,"s":"BTCUSDT","U":97109087385,"u":97109087402,"b":[["57195.92000000","0.00500000"],["50840.82000000","0.00044000"]],"a":[["63553.88000000","0.00018000"],["63554.34000000","0.00787000"],["63559.46000000","0.00000000"]]}}
{"stream":"ethusdt@depth@100ms","data":{"e":"depthUpdate","E":1783465186915,"s":"ETHUSDT","U":78545069702,"u":78545069717,"b":[["1775.40000000","0.29280000"],["1598.00000000","2.60010000"]],"a":[["1775.56000000","18.16740000"],["1775.57000000","1.22320000"],["1775.58000000","0.01760000"],["1775.59000000","0.34430000"],["1775.60000000","1.33730000"]]}}
{"stream":"btcusdt@depth@100ms","data":{"e":"depthUpdate","E":1783465187014,"s":"BTCUSDT","U":97109087403,"u":97109087438,"b":[["63483.01000000","1.02661000"],["63480.91000000","0.00000000"],["63409.28000000","0.00000000"],["58389.00000000","0.00000000"],["57195.92000000","0.00500000"],["50840.82000000","0.00083000"]],"a":[["63553.54000000","0.08018000"],["63553.88000000","0.00000000"],["63554.07000000","0.00895000"],["63554.34000000","0.00805000"],["63559.46000000","0.00000000"],["63563.45000000","0.02700000"],["63592.34000000","0.00393000"],["63615.07000000","0.00000000"],["63741.26000000","0.00000000"]]}}
{"stream":"ethusdt@depth@100ms","data":{"e":"depthUpdate","E":1783465187015,"s":"ETHUSDT","U":78545069718,"u":78545069723,"b":[["1774.96000000","0.46990000"],["1598.00000000","2.60010000"]],"a":[["1775.87000000","15.01870000"]]}}
{"stream":"btcusdt@depth@100ms","data":{"e":"depthUpdate","E":1783465187114,"s":"BTCUSDT","U":97109087439,"u":97109087461,"b":[["63490.51000000","0.58258000"],["63295.90000000","0.00522000"],["57195.92000000","0.00480000"]],"a":[["63559.46000000","0.00000000"],["63559.55000000","0.09450000"],["63559.63000000","0.02700000"],["63569.81000000","0.00000000"],["63592.33000000","0.00010000"],["63592.34000000","0.00393000"]]}}
{"stream":"ethusdt@depth@100ms","data":{"e":"depthUpdate","E":1783465187115,"s":"ETHUSDT","U":78545069724,"u":78545069757,"b":[["1775.52000000","0.01190000"],["1775.51000000","0.44600000"],["1775.50000000","6.80270000"],["1775.40000000","0.28980000"],["1775.28000000","18.31580000"],["1775.26000000","7.88770000"],["1775.11000000","35.66360000"],["1775.05000000","2.08510000"],["1774.98000000","0.01580000"],["1774.51000000","6.00610000"],["1773.84000000","0.00000000"],["1773.60000000","0.43700000"],["1773.54000000","0.56440000"],["1772.79000000","0.00000000"],["1598.00000000","2.60010000"],["1067.00000000","6.86000000"]],"a":[["1775.87000000","0.00000000"],["1775.88000000","14.54740000"],["1775.96000000","15.01870000"],["1776.01000000","0.99690000"],["1776.06000000","11.61240000"]]}}
{"stream":"btcusdt@depth@100ms","data":{"e":"depthUpdate","E":1783465187214,"s":"BTCUSDT","U":97109087462,"u":97109087483,"b":[["63312.69000000","0.00522000"],["62597.75000000","0.00030000"],["57195.92000000","0.00480000"],["50840.82000000","0.00044000"]],"a":[["63558.70000000","0.93944000"],["63559.55000000","0.00000000"],["63560.01000000","0.00000000"],["63566.00000000","0.02800000"]]}}
{"stream":"ethusdt@depth@100ms","data":{"e":"depthUpdate","E":1783465187216,"s":"ETHUSDT","U":78545069758,"u":78545069763,"b":[["1775.20000000","0.03580000"],["1598.00000000","2.60710000"]],"a":[["1775.92000000","0.32980000"]]}}
{"stream":"btcusdt@depth@100ms","data":{"e":"depthUpdate","E":1783465187315,"s":"BTCUSDT","U":97109087484,"u":97109087494,"b":[["63551.01000000","0.00864000"],["63329.48000000","0.00521000"],["57195.92000000","0.00480000"]],"a":[["63559.55000000","0.09450000"]]}}
{"stream":"ethusdt@depth@100ms","data":{"e":"depthUpdate","E":1783465187316,"s":"ETHUSDT","U":78545069764,"u":78545069772,"b":[["1774.94000000","49.70320000"],["1774.85000000","0.00290000"],["1774.82000000","0.00290000"],["1598.00000000","2.59330000"]],"a":[]}}
{"stream":"btcusdt@depth@100ms","data":{"e":"depthUpdate","E":1783465187414,"s":"BTCUSDT","U":97109087495,"u":97109087503,"b":[["63475.40000000","0.00177000"],["63473.31000000","0.00000000"],["63346.26000000","0.00521000"],["57195.92000000","0.00480000"],["40000.00000000","260.73952000"]],"a":[]}}
{"stream":"ethusdt@depth@100ms","data":{"e":"depthUpdate","E":1783465187415,"s":"ETHUSDT","U":78545069773,"u":78545069777,"b":[["1598.00000000","2.60010000"]],"a":[]}}
{"stream":"btcusdt@depth@100ms","data":{"e":"depthUpdate","E":1783465187514,"s":"BTCUSDT","U":97109087504,"u":97109087514,"b":[["63551.02000000","1.04694000"],["63545.82000000","0.06472000"],["63545.53000000","0.70840000"],["63537.15000000","0.00000000"],["63363.05000000","0.00521000"],["57195.92000000","0.00500000"]],"a":[["63561.47000000","0.23660000"],["63598.44000000","0.03500000"],["63598.49000000","0.02800000"]]}}
{"stream":"ethusdt@depth@100ms","data":{"e":"depthUpdate","E":1783465187515,"s":"ETHUSDT","U":78545069778,"u":78545069782,"b":[["1764.22000000","0.13320000"],["1598.00000000","2.60010000"]],"a":[]}}
{"stream":"btcusdt@depth@100ms","data":{"e":"depthUpdate","E":1783465187614,"s":"BTCUSDT","U":97109087515,"u":97109087524,"b":[["63541.66000000","0.00000000"],["63477.84000000","0.00000000"],["63469.82000000","0.17283000"],["63379.84000000","0.00521000"],["57195.92000000","0.00500000"]],"a":[["63660.52000000","0.05138000"],["63668.57000000","0.00000000"]]}}
{"stream":"ethusdt@depth@100ms","data":{"e":"depthUpdate","E":1783465187615,"s":"ETHUSDT","U":78545069783,"u":78545069787,"b":[["1764.97000000","0.13310000"],["1598.00000000","2.60010000"]],"a":[]}}
{"stream":"btcusdt@depth@100ms","data":{"e":"depthUpdate","E":1783465187714,"s":"BTCUSDT","U":97109087525,"u":97109087529,"b":[["63537.00000000","0.00000000"],["63396.62000000","0.00521000"],["57195.92000000","0.00480000"]],"a":[["63562.43000000","0.00000000"]]}}
{"stream":"ethusdt@depth@100ms","data":{"e":"depthUpdate","E":1783465187715,"s":"ETHUSDT","U":78545069788,"u":78545069796,"b":[["1765.72000000","0.20370000"],["1598.00000000","2.58630000"]],"a":[["1776.61000000","4.48410000"],["1780.06000000","0.90330000"]]}}
{"stream":"btcusdt@depth@100ms","data":{"e":"depthUpdate","E":1783465187814,"s":"BTCUSDT","U":97109087530,"u":97109087539,"b":[["63537.00000000","0.00008000"],["63413.41000000","0.00521000"],["57195.92000000","0.00480000"],["50000.00000000","542.70415000"]],"a":[["63562.43000000","0.00008000"],["64504.30000000","0.00030000"]]}}
{"stream":"ethusdt@depth@100ms","data":{"e":"depthUpdate","E":1783465187816,"s":"ETHUSDT","U":78545069797,"u":78545069805,"b":[["1766.47000000","0.16120000"],["1598.00000000","2.60710000"]],"a":[["1777.54000000","6.31680000"],["1777.55000000","8.03680000"],["1777.61000000","0.00000000"]]}}
{"stream":"ethusdt@depth@100ms","data":{"e":"depthUpdate","E":1783465187918,"s":"ETHUSDT","U":78545069806,"u":78545069810,"b":[["1767.22000000","0.13290000"],["1598.00000000","2.60710000"]],"a":[]}}
{"stream":"btcusdt@depth@100ms","data":{"e":"depthUpdate","E":1783465187918,"s":"BTCUSDT","U":97109087540,"u":97109087556,"b":[["63523.05000000","0.00000000"],["63503.99000000","0.00000000"],["63469.82000000","0.00000000"],["63430.19000000","0.00521000"],["57195.92000000","0.00480000"],["57195.00000000","0.00087000"],["50840.82000000","0.00044000"]],"a":[["63551.03000000","2.11014000"],["63560.20000000","0.02500000"],["63570.03000000","0.00000000"],["63589.10000000","0.00000000"],["63660.52000000","0.00000000"]]}}
{"stream":"btcusdt@depth@100ms","data":{"e":"depthUpdate","E":1783465188014,"s":"BTCUSDT","U":97109087557,"u":97109087573,"b":[["63551.02000000","1.04685000"],["63545.82000000","0.06464000"],["63545.53000000","0.00000000"],["63537.50000000","0.70840000"],["63477.84000000","0.04882000"],["63446.98000000","0.00520000"],["57195.92000000","0.00480000"],["50840.82000000","0.00083000"]],"a":[["63560.17000000","0.05200000"],["63592.34000000","0.00393000"],["63668.57000000","0.05069000"]]}}
{"stream":"ethusdt@depth@100ms","data":{"e":"depthUpdate","E":1783465188015,"s":"ETHUSDT","U":78545069811,"u":78545069815,"b":[["1767.96000000","0.31750000"],["1598.00000000","2.60710000"]],"a":[]}}
{"stream":"btcusdt@depth@100ms","data":{"e":"depthUpdate","E":1783465188114,"s":"BTCUSDT","U":97109087574,"u":97109087586,"b":[["63463.77000000","0.00520000"],["57195.92000000","0.00500000"]],"a":[["63566.56000000","0.00000000"],["63566.59000000","0.00000000"],["63592.33000000","0.00403000"],["63592.34000000","0.00000000"]]}}
{"stream":"ethusdt@depth@100ms","data":{"e":"depthUpdate","E":1783465188117,"s":"ETHUSDT","U":78545069816,"u":78545069821,"b":[["1774.97000000","14.29350000"],["1774.80000000","1.04080000"],["1768.71000000","0.14410000"],["1598.00000000","2.60010000"]],"a":[]}}
{"stream":"btcusdt@depth@100ms","data":{"e":"depthUpdate","E":1783465188214,"s":"BTCUSDT","U":97109087587,"u":97109087599,"b":[["63523.49000000","0.54517000"],["63504.43000000","1.02835000"],["63480.55000000","0.00520000"],["62597.75000000","0.00030000"],["57195.92000000","0.00500000"],["50840.82000000","0.00044000"]],"a":[["63569.83000000","0.55815000"],["63578.60000000","0.49645000"],["63588.90000000","1.03241000"]]}}
{"stream":"ethusdt@depth@100ms","data":{"e":"depthUpdate","E":1783465188215,"s":"ETHUSDT","U":78545069822,"u":78545069841,"b":[["1775.20000000","0.03580000"],["1774.97000000","22.00530000"],["1769.46000000","0.13280000"],["1598.00000000","2.58630000"]],"a":[["1775.92000000","0.32980000"],["1776.53000000","26.43650000"],["1776.56000000","0.03000000"],["1776.76000000","23.99040000"],["1776.98000000","3.40970000"],["1777.07000000","10.41180000"],["1777.44000000","17.94060000"],["1777.79000000","0.00630000"],["1778.64000000","0.00710000"],["1778.84000000","36.11620000"]]}}
{"stream":"btcusdt@depth@100ms","data":{"e":"depthUpdate","E":1783465188315,"s":"BTCUSDT","U":97109087600,"u":97109087604,"b":[["63497.34000000","0.00520000"],["57195.92000000","0.00500000"]],"a":[]}}
{"stream":"ethusdt@depth@100ms","data":{"e":"depthUpdate","E":1783465188315,"s":"ETHUSDT","U":78545069842,"u":78545069852,"b":[["1775.52000000","0.04190000"],["1774.42000000","4.94690000"],["1774.32000000","0.00000000"],["1770.21000000","0.14390000"],["1598.00000000","2.60010000"]],"a":[["1777.44000000","0.00290000"]]}}
{"stream":"ethusdt@trade","data":{"e":"trade","E":1783465188399,"s":"ETHUSDT","t":4197008406,"p":"1775.56000000","q":"0.36550000","T":1783465188399,"m":false,"M":true}}
{"stream":"btcusdt@depth@100ms","data":{"e":"depthUpdate","E":1783465188414,"s":"BTCUSDT","U":97109087605,"u":97109087615,"b":[["63551.02000000","0.82007000"],["63537.50000000","0.00000000"],["63533.83000000","0.70840000"],["63524.96000000","0.00938000"],["63514.13000000","0.00520000"],["63508.92000000","0.00000000"],["57195.92000000","0.00480000"],["40000.00000000","260.73952000"]],"a":[]}}
{"stream":"ethusdt@depth@100ms","data":{"e":"depthUpdate","E":1783465188415,"s":"ETHUSDT","U":78545069853,"u":78545069860,"b":[["1775.55000000","17.61530000"],["1773.84000000","4.96530000"],["1770.96000000","0.13270000"],["1598.00000000","2.60010000"]],"a":[["1775.56000000","17.80190000"]]}}
{"stream":"btcusdt@depth@100ms","data":{"e":"depthUpdate","E":1783465188514,"s":"BTCUSDT","U":97109087616,"u":97109087619,"b":[["57195.92000000","0.00480000"]],"a":[]}}
{"stream":"ethusdt@depth@100ms","data":{"e":"depthUpdate","E":1783465188517,"s":"ETHUSDT","U":78545069861,"u":78545069864,"b":[["1771.71000000","0.23710000"],["1598.00000000","2.60710000"]],"a":[]}}
{"stream":"btcusdt@depth@100ms","data":{"e":"depthUpdate","E":1783465188614,"s":"BTCUSDT","U":97109087620,"u":97109087625,"b":[["57195.92000000","0.00480000"],["50841.00000000","0.23623000"]],"a":[]}}
{"stream":"ethusdt@depth@100ms","data":{"e":"depthUpdate","E":1783465188619,"s":"ETHUSDT","U":78545069865,"u":78545069871,"b":[["1772.46000000","0.13590000"],["1598.00000000","2.59330000"]],"a":[]}}
{"stream":"btcusdt@trade","data":{"e":"trade","E":1783465188634,"s":"BTCUSDT","t":6486989375,"p":"63551.02000000","q":"0.00190000","T":1783465188634,"m":true,"M":true}}
{"stream":"btcusdt@depth@100ms","data":{"e":"depthUpdate","E":1783465188714,"s":"BTCUSDT","U":97109087626,"u":97109087631,"b":[["63551.02000000","0.81817000"],["57195.92000000","0.00480000"],["57195.91000000","0.00000000"],["57195.90000000","0.00010000"]],"a":[]}}
{"stream":"ethusdt@depth@100ms","data":{"e":"depthUpdate","E":1783465188716,"s":"ETHUSDT","U":78545069872,"u":78545069877,"b":[["1773.20000000","0.13540000"],["1598.00000000","2.60010000"]],"a":[]}}
{"stream":"btcusdt@trade","data":{"e":"trade","E":1783465188719,"s":"BTCUSDT","t":6486989376,"p":"63551.03000000","q":"0.00011000","T":1783465188718,"m":false,"M":true}}
{"stream":"btcusdt@depth@100ms","data":{"e":"depthUpdate","E":1783465188814,"s":"BTCUSDT","U":97109087632,"u":97109087656,"b":[["63551.02000000","0.81763000"],["63551.01000000","0.00882000"],["63547.57000000","0.00675000"],["63545.82000000","0.06482000"],["63544.28000000","0.70840000"],["63537.00000000","0.00008000"],["63533.83000000","0.00000000"],["57195.92000000","0.00500000"],["50841.00000000","0.23623000"]],"a":[["63551.03000000","2.11003000"],["63562.43000000","0.00008000"],["64504.30000000","0.00030000"]]}}
{"stream":"ethusdt@depth@100ms","data":{"e":"depthUpdate","E":1783465188815,"s":"ETHUSDT","U":78545069878,"u":78545069883,"b":[["1773.95000000","0.13530000"],["1598.00000000","2.60010000"],["1597.99000000","0.00870000"]],"a":[]}}
{"stream":"ethusdt@depth@100ms","data":{"e":"depthUpdate","E":1783465188915,"s":"ETHUSDT","U":78545069884,"u":78545069890,"b":[["1598.00000000","2.60010000"],["1597.99000000","0.00520000"],["1067.00000000","6.86000000"]],"a":[]}}
{"stream":"btcusdt@depth@100ms","data":{"e":"depthUpdate","E":1783465188915,"s":"BTCUSDT","U":97109087657,"u":97109087664,"b":[["57195.92000000","0.00500000"],["57195.00000000","0.00107000"],["50840.82000000","0.00044000"]],"a":[["63608.43000000","0.00000000"]]}}
{"stream":"ethusdt@trade","data":{"e":"trade","E":1783465188928,"s":"ETHUSDT","t":4197008407,"p":"1775.55000000","q":"0.00430000","T":1783465188927,"m":true,"M":true}}
{"stream":"btcusdt@depth@100ms","data":{"e":"depthUpdate","E":1783465189014,"s":"BTCUSDT","U":97109087665,"u":97109087674,"b":[["57195.92000000","0.00500000"],["57195.00000000","0.00087000"],["50840.82000000","0.00083000"]],"a":[["63592.33000000","0.00010000"],["63592.34000000","0.00393000"]]}}
{"stream":"ethusdt@depth@100ms","data":{"e":"depthUpdate","E":1783465189016,"s":"ETHUSDT","U":78545069891,"u":78545069895,"b":[["1775.55000000","17.61100000"],["1598.00000000","2.60010000"]],"a":[]}}
{"stream":"btcusdt@depth@100ms","data":{"e":"depthUpdate","E":1783465189114,"s":"BTCUSDT","U":97109087675,"u":97109087677,"b":[["57195.92000000","0.00480000"]],"a":[]}}
{"stream":"ethusdt@depth@100ms","data":{"e":"depthUpdate","E":1783465189115,"s":"ETHUSDT","U":78545069896,"u":78545069901,"b":[["1598.00000000","2.58630000"]],"a":[]}}
{"stream":"btcusdt@depth@100ms","data":{"e":"depthUpdate","E":1783465189214,"s":"BTCUSDT","U":97109087678,"u":97109087685,"b":[["62597.75000000","0.00030000"],["57195.92000000","0.00480000"],["50840.82000000","0.00044000"]],"a":[["63551.03000000","2.10994000"]]}}
{"stream":"ethusdt@depth@100ms","data":{"e":"depthUpdate","E":1783465189215,"s":"ETHUSDT","U":78545069902,"u":78545069907,"b":[["1775.20000000","0.03290000"],["1598.00000000","2.60710000"]],"a":[["1775.92000000","0.32690000"]]}}
{"stream":"btcusdt@depth@100ms","data":{"e":"depthUpdate","E":1783465189314,"s":"BTCUSDT","U":97109087686,"u":97109087692,"b":[["63551.02000000","0.81492000"],["57195.92000000","0.00480000"]],"a":[["63559.55000000","0.00000000"],["63559.58000000","0.09450000"]]}}
{"stream":"ethusdt@depth@100ms","data":{"e":"depthUpdate","E":1783465189315,"s":"ETHUSDT","U":78545069908,"u":78545069916,"b":[["1775.20000000","0.03580000"],["1774.87000000","2.98980000"],["1770.19000000","0.00000000"],["1598.00000000","2.60710000"]],"a":[["1775.92000000","0.32980000"],["1776.43000000","25.89220000"]]}}
{"stream":"btcusdt@depth@100ms","data":{"e":"depthUpdate","E":1783465189415,"s":"BTCUSDT","U":97109087693,"u":97109087699,"b":[["57195.92000000","0.00480000"],["40000.00000000","260.73952000"]],"a":[["63608.44000000","0.13576000"]]}}
{"stream":"ethusdt@depth@100ms","data":{"e":"depthUpdate","E":1783465189415,"s":"ETHUSDT","U":78545069917,"u":78545069920,"b":[["1770.23000000","42.23110000"],["1598.00000000","2.60010000"]],"a":[]}}
{"stream":"btcusdt@depth@100ms","data":{"e":"depthUpdate","E":1783465189514,"s":"BTCUSDT","U":97109087700,"u":97109087707,"b":[["63551.02000000","0.81501000"],["63545.82000000","0.06490000"],["63545.14000000","0.70840000"],["63544.28000000","0.00000000"],["57195.92000000","0.00500000"]],"a":[["77811.66000000","0.00000000"]]}}
{"stream":"ethusdt@depth@100ms","data":{"e":"depthUpdate","E":1783465189515,"s":"ETHUSDT","U":78545069921,"u":78545069929,"b":[["1774.90000000","25.64130000"],["1774.80000000","0.47730000"],["1770.50000000","0.02820000"],["1598.00000000","2.58630000"]],"a":[]}}
{"stream":"btcusdt@depth@100ms","data":{"e":"depthUpdate","E":1783465189614,"s":"BTCUSDT","U":97109087708,"u":97109087714,"b":[["63551.02000000","0.81467000"],["63477.84000000","0.00000000"],["57195.92000000","0.00500000"]],"a":[["63668.57000000","0.00000000"]]}}
{"stream":"ethusdt@depth@100ms","data":{"e":"depthUpdate","E":1783465189615,"s":"ETHUSDT","U":78545069930,"u":78545069936,"b":[["1598.00000000","2.60010000"]],"a":[["1775.56000000","17.79500000"]]}}
{"stream":"ethusdt@trade","data":{"e":"trade","E":1783465189678,"s":"ETHUSDT","t":4197008408,"p":"1775.55000000","q":"0.00140000","T":1783465189678,"m":true,"M":true}}
{"stream":"ethusdt@trade","data":{"e":"trade","E":1783465189678,"s":"ETHUSDT","t":4197008409,"p":"1775.55000000","q":"0.27080000","T":1783465189678,"m":true,"M":true}}
{"stream":"btcusdt@depth@100ms","data":{"e":"depthUpdate","E":1783465189715,"s":"BTCUSDT","U":97109087715,"u":97109087720,"b":[["63551.02000000","0.81501000"],["63469.38000000","0.17283000"],["57195.92000000","0.00480000"]],"a":[["63660.09000000","0.05138000"]]}}
{"stream":"ethusdt@depth@100ms","data":{"e":"depthUpdate","E":1783465189715,"s":"ETHUSDT","U":78545069937,"u":78545069943,"b":[["1775.55000000","17.34450000"],["1598.00000000","2.60010000"]],"a":[["1775.56000000","17.80190000"]]}}
{"stream":"ethusdt@depth@100ms","data":{"e":"depthUpdate","E":1783465189815,"s":"ETHUSDT","U":78545069944,"u":78545069947,"b":[["1598.00000000","2.60710000"]],"a":[["1802.76000000","0.00590000"]]}}
{"stream":"btcusdt@depth@100ms","data":{"e":"depthUpdate","E":1783465189815,"s":"BTCUSDT","U":97109087721,"u":97109087731,"b":[["63551.02000000","1.02130000"],["63537.00000000","0.00008000"],["57195.92000000","0.00480000"],["50000.00000000","542.70395000"]],"a":[["63562.43000000","0.00008000"],["64504.30000000","0.00030000"]]}}
{"stream":"btcusdt@depth@100ms","data":{"e":"depthUpdate","E":1783465189914,"s":"BTCUSDT","U":97109087732,"u":97109087738,"b":[["63551.02000000","1.01966000"],["63549.14000000","0.00179000"],["57195.92000000","0.00480000"]],"a":[]}}
{"stream":"ethusdt@depth@100ms","data":{"e":"depthUpdate","E":1783465189915,"s":"ETHUSDT","U":78545069948,"u":78545069952,"b":[["1775.55000000","17.44160000"],["1598.00000000","2.60710000"]],"a":[]}}
{"stream":"btcusdt@depth@100ms","data":{"e":"depthUpdate","E":1783465190014,"s":"BTCUSDT","U":97109087739,"u":97109087755,"b":[["63477.49000000","0.00177000"],["63475.40000000","0.00000000"],["57195.92000000","0.00480000"],["57195.00000000","0.00087000"],["50840.82000000","0.00083000"]],"a":[["63577.96000000","0.00000000"],["63582.81000000","0.00000000"],["63595.34000000","0.00000000"],["63661.76000000","0.00000000"]]}}
{"stream":"ethusdt@depth@100ms","data":{"e":"depthUpdate","E":1783465190015,"s":"ETHUSDT","U":78545069953,"u":78545069968,"b":[["1775.02000000","0.44540000"],["1774.66000000","0.00580000"],["1774.56000000","0.03290000"],["1774.49000000","9.46180000"],["1772.62000000","0.00290000"],["1598.00000000","2.59330000"]],"a":[["1776.38000000","0.01140000"],["1776.45000000","44.80440000"],["1776.64000000","0.83000000"],["1776.98000000","2.77620000"],["1778.84000000","35.16590000"]]}}
{"stream":"btcusdt@depth@100ms","data":{"e":"depthUpdate","E":1783465190114,"s":"BTCUSDT","U":97109087756,"u":97109087768,"b":[["63551.02000000","1.01957000"],["63545.82000000","0.06482000"],["63545.14000000","0.00000000"],["63538.51000000","0.70840000"],["63483.01000000","0.00000000"],["63480.91000000","1.02661000"],["63413.29000000","0.00000000"],["63237.58000000","0.00000000"],["57195.92000000","0.00500000"]],"a":[["63681.36000000","0.00000000"],["63860.04000000","0.00000000"]]}}
{"stream":"ethusdt@depth@100ms","data":{"e":"depthUpdate","E":1783465190115,"s":"ETHUSDT","U":78545069969,"u":78545069975,"b":[["1775.05000000","1.20290000"],["1598.00000000","2.60010000"]],"a":[["1777.50000000","18.08510000"]]}}
{"stream":"btcusdt@depth@100ms","data":{"e":"depthUpdate","E":1783465190214,"s":"BTCUSDT","U":97109087769,"u":97109087775,"b":[["62597.75000000","0.00030000"],["57195.92000000","0.00500000"],["50840.82000000","0.00044000"]],"a":[]}}
{"stream":"ethusdt@depth@100ms","data":{"e":"depthUpdate","E":1783465190215,"s":"ETHUSDT","U":78545069976,"u":78545069983,"b":[["1773.49000000","1.75850000"],["1773.22000000","0.00000000"],["1598.00000000","2.60010000"]],"a":[["1778.56000000","15.01870000"],["1778.83000000","0.56540000"]]}}
{"stream":"btcusdt@trade","data":{"e":"trade","E":1783465190228,"s":"BTCUSDT","t":6486989377,"p":"63551.02000000","q":"0.00500000","T":1783465190228,"m":true,"M":true}}
{"stream":"btcusdt@depth@100ms","data":{"e":"depthUpdate","E":1783465190314,"s":"BTCUSDT","U":97109087776,"u":97109087783,"b":[["63551.02000000","1.01457000"],["57195.92000000","0.00500000"],["57195.90000000","0.00000000"],["50841.00000000","0.24023000"]],"a":[["63591.81000000","0.00000000"]]}}
{"stream":"ethusdt@depth@100ms","data":{"e":"depthUpdate","E":1783465190315,"s":"ETHUSDT","U":78545069984,"u":78545069991,"b":[["1775.20000000","0.03580000"],["1775.06000000","1.01100000"],["1598.00000000","2.60010000"]],"a":[["1775.92000000","0.32980000"]]}}
{"stream":"btcusdt@trade","data":{"e":"trade","E":1783465190326,"s":"BTCUSDT","t":6486989378,"p":"63551.03000000","q":"0.00089000","T":1783465190326,"m":false,"M":true}}
{"stream":"ethusdt@depth@100ms","data":{"e":"depthUpdate","E":1783465190415,"s":"ETHUSDT","U":78545069992,"u":78545069997,"b":[["1598.00000000","2.58630000"]],"a":[]}}
{"stream":"btcusdt@depth@100ms","data":{"e":"depthUpdate","E":1783465190415,"s":"BTCUSDT","U":97109087784,"u":97109087798,"b":[["63551.02000000","1.72306000"],["63545.95000000","0.00787000"],["63544.79000000","0.00000000"],["63538.51000000","0.00000000"],["63469.38000000","0.00000000"],["57195.92000000","0.00480000"],["50841.00000000","0.23623000"],["40000.00000000","260.73952000"]],"a":[["63551.03000000","2.10897000"],["63554.34000000","0.00018000"],["63555.47000000","0.00787000"],["63660.09000000","0.00000000"]]}}
{"stream":"ethusdt@depth@100ms","data":{"e":"depthUpdate","E":1783465190515,"s":"ETHUSDT","U":78545069998,"u":78545070009,"b":[["1774.14000000","5.24880000"],["1771.02000000","0.00000000"],["1768.95000000","0.00300000"],["1598.00000000","2.59330000"]],"a":[["1777.94000000","0.00000000"],["1781.95000000","0.03540000"],["1784.45000000","0.00000000"],["1784.80000000","0.02760000"],["1787.73000000","0.20350000"],["1788.44000000","0.00000000"]]}}
{"stream":"btcusdt@depth@100ms","data":{"e":"depthUpdate","E":1783465190515,"s":"BTCUSDT","U":97109087799,"u":97109087827,"b":[["63546.00000000","0.02818000"],["63545.95000000","0.00805000"],["63545.82000000","0.06464000"],["63468.13000000","0.16811000"],["63464.21000000","0.00000000"],["63352.90000000","0.00000000"],["63236.53000000","0.00000000"],["57195.92000000","0.00480000"]],"a":[["63551.03000000","2.10905000"],["63554.07000000","0.00895000"],["63554.34000000","0.00000000"],["63554.36000000","0.04022000"],["63623.28000000","0.00000000"],["63658.83000000","0.05139000"],["63713.21000000","0.00000000"],["63791.90000000","0.00000000"]]}}
{"stream":"ethusdt@depth@100ms","data":{"e":"depthUpdate","E":1783465190617,"s":"ETHUSDT","U":78545070010,"u":78545070017,"b":[["1774.76000000","0.40850000"],["1774.58000000","15.02160000"],["1598.00000000","2.60710000"]],"a":[]}}
{"stream":"btcusdt@depth@100ms","data":{"e":"depthUpdate","E":1783465190617,"s":"BTCUSDT","U":97109087828,"u":97109087835,"b":[["63483.01000000","1.02661000"],["63480.91000000","0.00000000"],["57195.92000000","0.00480000"],["33000.00000000","35.16979000"]],"a":[]}}
{"stream":"btcusdt@depth@100ms","data":{"e":"depthUpdate","E":1783465190715,"s":"BTCUSDT","U":97109087836,"u":97109087839,"b":[["57195.92000000","0.00480000"]],"a":[]}}
{"stream":"ethusdt@depth@100ms","data":{"e":"depthUpdate","E":1783465190715,"s":"ETHUSDT","U":78545070018,"u":78545070022,"b":[["1598.00000000","2.60010000"],["1067.00000000","6.86000000"]],"a":[]}}
{"stream":"ethusdt@depth@100ms","data":{"e":"depthUpdate","E":1783465190817,"s":"ETHUSDT","U":78545070023,"u":78545070027,"b":[["1768.71000000","0.71920000"],["1768.45000000","0.00000000"],["1598.00000000","2.60010000"]],"a":[]}}
{"stream":"btcusdt@depth@100ms","data":{"e":"depthUpdate","E":1783465190817,"s":"BTCUSDT","U":97109087840,"u":97109087846,"b":[["63551.02000000","1.72577000"],["63537.00000000","0.00000000"],["57195.92000000","0.00500000"]],"a":[["63562.43000000","0.00000000"],["64504.30000000","0.00030000"]]}}
{"stream":"btcusdt@depth@100ms","data":{"e":"depthUpdate","E":1783465190914,"s":"BTCUSDT","U":97109087847,"u":97109087854,"b":[["63551.02000000","1.51948000"],["63543.75000000","0.00000000"],["63537.00000000","0.00008000"],["57195.92000000","0.00500000"]],"a":[["63562.43000000","0.00008000"]]}}
{"stream":"ethusdt@depth@100ms","data":{"e":"depthUpdate","E":1783465190915,"s":"ETHUSDT","U":78545070028,"u":78545070038,"b":[["1775.55000000","17.45450000"],["1775.54000000","0.01160000"],["1775.31000000","0.95030000"],["1775.30000000","2.74990000"],["1775.29000000","1.68610000"],["1598.00000000","2.58630000"]],"a":[]}}
{"stream":"btcusdt@trade","data":{"e":"trade","E":1783465190986,"s":"BTCUSDT","t":6486989379,"p":"63551.03000000","q":"0.00012000","T":1783465190986,"m":false,"M":true}}
{"stream":"btcusdt@depth@100ms","data":{"e":"depthUpdate","E":1783465191014,"s":"BTCUSDT","U":97109087855,"u":97109087900,"b":[["63551.02000000","0.17027000"],["63550.49000000","0.00000000"],["63550.48000000","0.00018000"],["63549.14000000","0.00018000"],["63546.01000000","0.00018000"],["63545.95000000","0.00018000"],["63545.83000000","0.00009000"],["63544.79000000","0.00000000"],["63544.77000000","0.14106000"],["63544.68000000","0.00000000"],["63544.67000000","0.00000000"],["63543.16000000","0.00787000"],["63542.70000000","0.06455000"],["63541.66000000","0.06455000"],["63541.24000000","0.52261000"],["63483.01000000","0.00000000"],["63480.91000000","1.02661000"],["57195.92000000","0.00500000"],["50840.82000000","0.00083000"]],"a":[["63551.03000000","2.10884000"],["63552.29000000","0.00787000"],["63553.53000000","0.00000000"],["63553.88000000","0.00000000"],["63554.35000000","0.00000000"],["63554.89000000","0.06432000"],["63555.19000000","0.06455000"],["63555.47000000","0.00000000"],["63556.17000000","0.06455000"],["63560.80000000","0.22764000"],["63563.35000000","0.00000000"]]}}
{"stream":"ethusdt@depth@100ms","data":{"e":"depthUpdate","E":1783465191015,"s":"ETHUSDT","U":78545070039,"u":78545070046,"b":[["1774.90000000","25.07780000"],["1774.79000000","0.56350000"],["1598.00000000","2.60010000"]],"a":[]}}
{"stream":"btcusdt@trade","data":{"e":"trade","E":1783465191071,"s":"BTCUSDT","t":6486989380,"p":"63551.03000000","q":"0.00171000","T":1783465191070,"m":false,"M":true}}
{"stream":"btcusdt@trade","data":{"e":"trade","E":1783465191071,"s":"BTCUSDT","t":6486989381,"p":"63551.03000000","q":"0.00150000","T":1783465191070,"m":false,"M":true}}
{"stream":"btcusdt@trade","data":{"e":"trade","E":1783465191071,"s":"BTCUSDT","t":6486989382,"p":"63551.03000000","q":"0.00686000","T":1783465191070,"m":false,"M":true}}
{"stream":"btcusdt@depth@100ms","data":{"e":"depthUpdate","E":1783465191114,"s":"BTCUSDT","U":97109087901,"u":97109087951,"b":[["63551.02000000","1.05125000"],["63551.01000000","0.00873000"],["63550.48000000","0.00000000"],["63546.00000000","0.02818000"],["63545.95000000","0.00000000"],["63545.82000000","0.06482000"],["63545.33000000","0.04939000"],["63544.34000000","0.70840000"],["63541.26000000","0.69930000"],["63541.25000000","0.45627000"],["63541.23000000","0.00000000"],["63538.65000000","0.42499000"],["63468.13000000","0.00000000"],["57195.92000000","0.00480000"],["57195.00000000","0.00087000"]],"a":[["63551.03000000","2.09886000"],["63551.71000000","0.06434000"],["63552.29000000","0.00018000"],["63553.88000000","0.00787000"],["63554.36000000","0.04004000"],["63554.89000000","0.06440000"],["63560.19000000","0.00000000"],["63560.80000000","0.00000000"],["63561.47000000","0.00000000"],["63561.81000000","0.17193000"],["63658.83000000","0.00000000"]]}}
{"stream":"ethusdt@depth@100ms","data":{"e":"depthUpdate","E":1783465191115,"s":"ETHUSDT","U":78545070047,"u":78545070052,"b":[["1774.90000000","25.64130000"],["1774.79000000","0.00000000"],["1598.00000000","2.60010000"]],"a":[]}}
{"stream":"ethusdt@depth@100ms","data":{"e":"depthUpdate","E":1783465191215,"s":"ETHUSDT","U":78545070053,"u":78545070056,"b":[["1774.26000000","0.44730000"],["1598.00000000","2.60710000"]],"a":[]}}
{"stream":"btcusdt@depth@100ms","data":{"e":"depthUpdate","E":1783465191215,"s":"BTCUSDT","U":97109087952,"u":97109087973,"b":[["63475.32000000","0.04882000"],["62597.75000000","0.00030000"],["57195.92000000","0.00480000"],["50840.82000000","0.00044000"]],"a":[["63551.71000000","0.06434000"],["63552.29000000","0.00000000"],["63553.53000000","0.00009000"],["63553.54000000","0.08018000"],["63553.88000000","0.00805000"],["63666.05000000","0.05069000"]]}}
{"stream":"btcusdt@depth@100ms","data":{"e":"depthUpdate","E":1783465191315,"s":"BTCUSDT","U":97109087974,"u":97109087980,"b":[["63548.99000000","0.00160000"],["58466.94000000","0.00018000"],["57195.92000000","0.00480000"]],"a":[["63716.56000000","0.00000000"],["63751.40000000","0.01866000"]]}}
{"stream":"ethusdt@depth@100ms","data":{"e":"depthUpdate","E":1783465191316,"s":"ETHUSDT","U":78545070057,"u":78545070067,"b":[["1775.20000000","0.03580000"],["1772.45000000","0.00000000"],["1772.20000000","35.34430000"],["1772.00000000","1.13560000"],["1598.00000000","2.60710000"]],"a":[["1775.92000000","0.32980000"]]}}
{"stream":"btcusdt@depth@100ms","data":{"e":"depthUpdate","E":1783465191414,"s":"BTCUSDT","U":97109087981,"u":97109087993,"b":[["63551.02000000","1.05151000"],["57195.92000000","0.00480000"],["50841.00000000","0.23623000"],["40000.00000000","260.73952000"]],"a":[["63559.58000000","0.00000000"],["63559.61000000","0.09450000"],["63561.47000000","0.25215000"],["82071.40000000","0.00000000"]]}}
{"stream":"ethusdt@depth@100ms","data":{"e":"depthUpdate","E":1783465191415,"s":"ETHUSDT","U":78545070068,"u":78545070075,"b":[["1775.40000000","0.00000000"],["1775.33000000","0.14000000"],["1772.00000000","0.25340000"],["1598.00000000","2.58630000"]],"a":[]}}
{"stream":"btcusdt@depth@100ms","data":{"e":"depthUpdate","E":1783465191514,"s":"BTCUSDT","U":97109087994,"u":97109087996,"b":[["57195.92000000","0.00500000"]],"a":[]}}
{"stream":"ethusdt@depth@100ms","data":{"e":"depthUpdate","E":1783465191515,"s":"ETHUSDT","U":78545070076,"u":78545070082,"b":[["1598.00000000","2.60010000"]],"a":[["1780.06000000","0.89340000"]]}}
{"stream":"btcusdt@trade","data":{"e":"trade","E":1783465191580,"s":"BTCUSDT","t":6486989383,"p":"63551.02000000","q":"0.00649000","T":1783465191580,"m":true,"M":true}}
{"stream":"btcusdt@trade","data":{"e":"trade","E":1783465191580,"s":"BTCUSDT","t":6486989384,"p":"63551.02000000","q":"0.00008000","T":1783465191580,"m":true,"M":true}}
{"stream":"btcusdt@trade","data":{"e":"trade","E":1783465191580,"s":"BTCUSDT","t":6486989385,"p":"63551.02000000","q":"0.00161000","T":1783465191580,"m":true,"M":true}}
{"stream":"ethusdt@depth@100ms","data":{"e":"depthUpdate","E":1783465191616,"s":"ETHUSDT","U":78545070083,"u":78545070086,"b":[["1598.00000000","2.60010000"]],"a":[]}}
{"stream":"btcusdt@depth@100ms","data":{"e":"depthUpdate","E":1783465191616,"s":"BTCUSDT","U":97109087997,"u":97109088011,"b":[["63551.02000000","1.04367000"],["63549.25000000","0.00018000"],["63549.24000000","0.11998000"],["63549.13000000","0.09325000"],["63548.99000000","0.00009000"],["63545.83000000","0.00000000"],["63427.34000000","0.00000000"],["57195.92000000","0.00500000"],["57195.91000000","0.00010000"]],"a":[["63672.10000000","0.00000000"]]}}
{"stream":"btcusdt@depth@100ms","data":{"e":"depthUpdate","E":1783465191714,"s":"BTCUSDT","U":97109088012,"u":97109088033,"b":[["63551.02000000","1.75242000"],["63551.01000000","0.00882000"],["63550.00000000","0.03877000"],["63549.24000000","0.12016000"],["63545.33000000","0.04921000"],["63544.34000000","0.00000000"],["63541.24000000","0.46013000"],["63475.32000000","0.00000000"],["63427.34000000","0.00066000"],["57195.92000000","0.00480000"]],"a":[["63553.88000000","0.00018000"],["63555.18000000","0.00787000"],["63666.05000000","0.00000000"],["63672.10000000","0.00066000"]]}}
{"stream":"ethusdt@depth@100ms","data":{"e":"depthUpdate","E":1783465191715,"s":"ETHUSDT","U":78545070087,"u":78545070090,"b":[["1598.00000000","2.60010000"]],"a":[]}}
{"stream":"btcusdt@depth@100ms","data":{"e":"depthUpdate","E":1783465191814,"s":"BTCUSDT","U":97109088034,"u":97109088058,"b":[["63551.02000000","1.75349000"],["63467.22000000","0.16811000"],["63405.72000000","0.09462000"],["58466.94000000","0.00000000"],["57195.92000000","0.00480000"]],"a":[["63553.54000000","0.08018000"],["63553.88000000","0.00000000"],["63554.36000000","0.04022000"],["63615.07000000","0.03109000"],["63657.91000000","0.05139000"],["63741.26000000","0.06310000"],["64504.30000000","0.00030000"],["69906.13000000","0.00008000"]]}}
{"stream":"ethusdt@depth@100ms","data":{"e":"depthUpdate","E":1783465191816,"s":"ETHUSDT","U":78545070091,"u":78545070095,"b":[["1598.00000000","2.59330000"]],"a":[]}}
{"stream":"btcusdt@depth@100ms","data":{"e":"depthUpdate","E":1783465191914,"s":"BTCUSDT","U":97109088059,"u":97109088069,"b":[["63537.00000000","0.00008000"],["57195.92000000","0.00480000"],["50841.00000000","0.23623000"]],"a":[["63562.43000000","0.00008000"],["69906.13000000","0.00000000"],["82071.40000000","0.00010000"]]}}
{"stream":"ethusdt@depth@100ms","data":{"e":"depthUpdate","E":1783465191915,"s":"ETHUSDT","U":78545070096,"u":78545070102,"b":[["1775.51000000","0.72710000"],["1598.00000000","2.60710000"]],"a":[]}}
{"stream":"ethusdt@depth@100ms","data":{"e":"depthUpdate","E":1783465192015,"s":"ETHUSDT","U":78545070103,"u":78545070108,"b":[["1773.96000000","0.43300000"],["1768.61000000","2.48620000"],["1598.00000000","2.60710000"]],"a":[]}}
{"stream":"btcusdt@depth@100ms","data":{"e":"depthUpdate","E":1783465192015,"s":"BTCUSDT","U":97109088070,"u":97109088082,"b":[["63551.02000000","1.75078000"],["63549.13000000","0.09164000"],["63545.95000000","0.00787000"],["63543.16000000","0.00000000"],["63541.27000000","0.42498000"],["63538.65000000","0.00000000"],["57195.92000000","0.00480000"],["50840.82000000","0.00083000"]],"a":[]}}
{"stream":"btcusdt@depth@100ms","data":{"e":"depthUpdate","E":1783465192114,"s":"BTCUSDT","U":97109088083,"u":97109088094,"b":[["63551.02000000","1.75087000"],["63546.00000000","0.02818000"],["63545.95000000","0.00805000"],["63545.82000000","0.06464000"],["57195.92000000","0.00500000"]],"a":[]}}
{"stream":"ethusdt@depth@100ms","data":{"e":"depthUpdate","E":1783465192115,"s":"ETHUSDT","U":78545070109,"u":78545070120,"b":[["1773.49000000","1.13840000"],["1769.34000000","0.88220000"],["1598.00000000","2.60010000"]],"a":[["1776.00000000","0.35490000"],["1776.02000000","32.48400000"],["1776.06000000","16.04780000"],["1776.08000000","16.90860000"],["1778.83000000","0.00000000"]]}}
{"stream":"btcusdt@depth@100ms","data":{"e":"depthUpdate","E":1783465192214,"s":"BTCUSDT","U":97109088095,"u":97109088104,"b":[["63551.02000000","1.74816000"],["62597.75000000","0.00030000"],["57195.92000000","0.00500000"],["57195.00000000","0.00087000"],["50840.82000000","0.00044000"]],"a":[]}}
{"stream":"ethusdt@depth@100ms","data":{"e":"depthUpdate","E":1783465192215,"s":"ETHUSDT","U":78545070121,"u":78545070127,"b":[["1773.22000000","0.59250000"],["1773.21000000","1.84610000"],["1598.00000000","2.60010000"]],"a":[["1778.55000000","0.57680000"]]}}
{"stream":"btcusdt@depth@100ms","data":{"e":"depthUpdate","E":1783465192314,"s":"BTCUSDT","U":97109088105,"u":97109088109,"b":[["63551.01000000","0.00611000"],["57195.92000000","0.00500000"]],"a":[]}}
{"stream":"ethusdt@depth@100ms","data":{"e":"depthUpdate","E":1783465192317,"s":"ETHUSDT","U":78545070128,"u":78545070137,"b":[["1775.20000000","0.03290000"],["1598.00000000","2.58630000"]],"a":[["1775.92000000","0.32690000"],["1777.44000000","17.94060000"],["1777.50000000","0.14740000"],["1802.76000000","0.05040000"]]}}
{"stream":"ethusdt@depth@100ms","data":{"e":"depthUpdate","E":1783465192417,"s":"ETHUSDT","U":78545070138,"u":78545070146,"b":[["1775.20000000","0.03580000"],["1768.71000000","0.14410000"],["1768.45000000","0.57520000"],["1598.00000000","2.60010000"]],"a":[["1775.92000000","0.32980000"]]}}
{"stream":"btcusdt@depth@100ms","data":{"e":"depthUpdate","E":1783465192417,"s":"BTCUSDT","U":97109088110,"u":97109088119,"b":[["63405.72000000","0.00000000"],["57195.92000000","0.00480000"],["40000.00000000","260.73952000"]],"a":[["63559.61000000","0.00000000"],["63559.65000000","0.09458000"],["63615.07000000","0.00000000"],["63741.26000000","0.00000000"]]}}
{"stream":"btcusdt@depth@100ms","data":{"e":"depthUpdate","E":1783465192514,"s":"BTCUSDT","U":97109088120,"u":97109088123,"b":[["57195.92000000","0.00480000"]],"a":[]}}
{"stream":"ethusdt@depth@100ms","data":{"e":"depthUpdate","E":1783465192515,"s":"ETHUSDT","U":78545070147,"u":78545070154,"b":[["1773.10000000","35.47780000"],["1773.05000000","0.00000000"],["1769.34000000","0.00000000"],["1598.00000000","2.60710000"],["1067.00000000","6.86000000"]],"a":[["1777.79000000","0.00000000"]]}}
{"stream":"btcusdt@depth@100ms","data":{"e":"depthUpdate","E":1783465192614,"s":"BTCUSDT","U":97109088124,"u":97109088130,"b":[["63551.01000000","0.00882000"],["57195.92000000","0.00480000"]],"a":[["63559.65000000","0.00008000"],["63559.66000000","0.09450000"]]}}
{"stream":"ethusdt@depth@100ms","data":{"e":"depthUpdate","E":1783465192615,"s":"ETHUSDT","U":78545070155,"u":78545070160,"b":[["1768.79000000","3.35720000"],["1598.00000000","2.60710000"]],"a":[["1777.79000000","0.00630000"]]}}
{"stream":"btcusdt@depth@100ms","data":{"e":"depthUpdate","E":1783465192714,"s":"BTCUSDT","U":97109088131,"u":97109088137,"b":[["63551.02000000","1.03976000"],["63545.95000000","0.00018000"],["63545.13000000","0.00787000"],["63541.28000000","0.06455000"],["57195.92000000","0.00480000"]],"a":[]}}
{"stream":"ethusdt@depth@100ms","data":{"e":"depthUpdate","E":1783465192715,"s":"ETHUSDT","U":78545070161,"u":78545070167,"b":[["1775.55000000","17.55160000"],["1768.54000000","0.57510000"],["1768.45000000","0.00000000"],["1598.00000000","2.58630000"]],"a":[]}}
{"stream":"ethusdt@trade","data":{"e":"trade","E":1783465192775,"s":"ETHUSDT","t":4197008410,"p":"1775.56000000","q":"0.00390000","T":1783465192775,"m":false,"M":true}}
{"stream":"ethusdt@depth@100ms","data":{"e":"depthUpdate","E":1783465192815,"s":"ETHUSDT","U":78545070168,"u":78545070174,"b":[["1598.00000000","2.60010000"]],"a":[["1775.56000000","17.79800000"]]}}
{"stream":"btcusdt@depth@100ms","data":{"e":"depthUpdate","E":1783465192815,"s":"BTCUSDT","U":97109088138,"u":97109088179,"b":[["63551.02000000","0.81573000"],["63551.01000000","0.01153000"],["63549.13000000","0.09172000"],["63546.84000000","0.46013000"],["63546.83000000","0.70848000"],["63546.01000000","0.00000000"],["63546.00000000","0.02818000"],["63545.95000000","0.00000000"],["63545.82000000","0.06482000"],["63544.30000000","0.00000000"],["63544.01000000","0.00000000"],["63541.27000000","0.00000000"],["63541.24000000","0.00000000"],["63538.65000000","0.42499000"],["57195.92000000","0.00500000"],["50000.00000000","542.70415000"]],"a":[["63553.28000000","0.00000000"],["63555.21000000","0.00126000"],["63556.24000000","0.00126000"],["64504.30000000","0.00030000"]]}}
{"stream":"btcusdt@depth@100ms","data":{"e":"depthUpdate","E":1783465192914,"s":"BTCUSDT","U":97109088180,"u":97109088198,"b":[["63547.57000000","0.00675000"],["63546.84000000","0.46031000"],["63546.83000000","0.70866000"],["63546.00000000","0.02800000"],["63545.82000000","0.06464000"],["63537.00000000","0.00008000"],["57195.92000000","0.00500000"]],"a":[["63562.43000000","0.00008000"]]}}
{"stream":"ethusdt@depth@100ms","data":{"e":"depthUpdate","E":1783465192915,"s":"ETHUSDT","U":78545070175,"u":78545070182,"b":[["1775.55000000","17.64870000"],["1775.35000000","0.00720000"],["1775.28000000","18.03070000"],["1598.00000000","2.60010000"]],"a":[["1775.64000000","0.56240000"]]}}
{"stream":"btcusdt@depth@100ms","data":{"e":"depthUpdate","E":1783465193014,"s":"BTCUSDT","U":97109088199,"u":97109088223,"b":[["63545.13000000","0.00000000"],["63544.78000000","0.07108000"],["63544.55000000","0.00000000"],["57195.92000000","0.00500000"],["50840.82000000","0.00083000"]],"a":[["63553.52000000","0.00000000"],["63553.53000000","0.00009000"],["63553.88000000","0.00787000"],["63555.18000000","0.00000000"]]}}
{"stream":"ethusdt@depth@100ms","data":{"e":"depthUpdate","E":1783465193015,"s":"ETHUSDT","U":78545070183,"u":78545070186,"b":[["1598.00000000","2.60010000"]],"a":[]}}
{"stream":"btcusdt@depth@100ms","data":{"e":"depthUpdate","E":1783465193114,"s":"BTCUSDT","U":97109088224,"u":97109088235,"b":[["63551.02000000","0.81564000"],["57195.92000000","0.00480000"]],"a":[["63553.54000000","0.08018000"],["63553.88000000","0.00805000"],["63554.36000000","0.04004000"]]}}
{"stream":"ethusdt@depth@100ms","data":{"e":"depthUpdate","E":1783465193115,"s":"ETHUSDT","U":78545070187,"u":78545070190,"b":[["1598.00000000","2.60010000"]],"a":[]}}
{"stream":"btcusdt@depth@100ms","data":{"e":"depthUpdate","E":1783465193214,"s":"BTCUSDT","U":97109088236,"u":97109088244,"b":[["62597.75000000","0.00030000"],["57195.92000000","0.00480000"],["57195.00000000","0.00087000"],["50840.82000000","0.00044000"]],"a":[]}}
{"stream":"ethusdt@depth@100ms","data":{"e":"depthUpdate","E":1783465193215,"s":"ETHUSDT","U":78545070191,"u":78545070195,"b":[["1598.00000000","2.59330000"]],"a":[]}}
{"stream":"btcusdt@depth@100ms","data":{"e":"depthUpdate","E":1783465193314,"s":"BTCUSDT","U":97109088245,"u":97109088258,"b":[["57195.92000000","0.00480000"],["50841.00000000","0.23623000"]],"a":[]}}
{"stream":"ethusdt@depth@100ms","data":{"e":"depthUpdate","E":1783465193316,"s":"ETHUSDT","U":78545070196,"u":78545070201,"b":[["1598.00000000","2.60710000"]],"a":[]}}
{"stream":"btcusdt@depth@100ms","data":{"e":"depthUpdate","E":1783465193414,"s":"BTCUSDT","U":97109088259,"u":97109088266,"b":[["63445.12000000","0.02465000"],["63440.78000000","0.00000000"],["57195.92000000","0.00480000"],["40000.00000000","260.73952000"]],"a":[]}}
{"stream":"ethusdt@depth@100ms","data":{"e":"depthUpdate","E":1783465193415,"s":"ETHUSDT","U":78545070202,"u":78545070209,"b":[["1775.46000000","0.36470000"],["1775.20000000","0.03580000"],["1598.00000000","2.60010000"]],"a":[["1775.92000000","0.32980000"],["1776.01000000","11.90730000"]]}}
{"stream":"btcusdt@depth@100ms","data":{"e":"depthUpdate","E":1783465193514,"s":"BTCUSDT","U":97109088267,"u":97109088269,"b":[["57195.92000000","0.00500000"]],"a":[]}}
{"stream":"ethusdt@depth@100ms","data":{"e":"depthUpdate","E":1783465193515,"s":"ETHUSDT","U":78545070210,"u":78545070220,"b":[["1775.47000000","0.00600000"],["1775.45000000","0.58000000"],["1773.22000000","0.00000000"],["1773.21000000","0.00000000"],["1598.00000000","2.60010000"]],"a":[["1778.55000000","0.01140000"]]}}
{"stream":"ethusdt@depth@100ms","data":{"e":"depthUpdate","E":1783465193617,"s":"ETHUSDT","U":78545070221,"u":78545070234,"b":[["1775.48000000","0.85060000"],["1775.47000000","0.00900000"],["1775.45000000","0.57700000"],["1773.49000000","1.75850000"],["1598.00000000","2.58630000"]],"a":[["1777.44000000","0.00290000"],["1777.49000000","25.91950000"],["1778.83000000","0.56540000"]]}}
{"stream":"btcusdt@depth@100ms","data":{"e":"depthUpdate","E":1783465193617,"s":"BTCUSDT","U":97109088270,"u":97109088274,"b":[["63549.14000000","0.00154000"],["57195.92000000","0.00500000"]],"a":[]}}
{"stream":"btcusdt@depth@100ms","data":{"e":"depthUpdate","E":1783465193715,"s":"BTCUSDT","U":97109088275,"u":97109088292,"b":[["63551.02000000","0.81564000"],["63551.01000000","0.01153000"],["63550.85000000","0.00018000"],["63550.84000000","0.13787000"],["63549.25000000","0.00000000"],["63549.24000000","0.00018000"],["63445.12000000","0.00000000"],["63437.78000000","0.00000000"],["63422.74000000","0.00000000"],["57195.92000000","0.00480000"]],"a":[]}}
{"stream":"ethusdt@depth@100ms","data":{"e":"depthUpdate","E":1783465193715,"s":"ETHUSDT","U":78545070235,"u":78545070242,"b":[["1768.71000000","0.71920000"],["1768.54000000","0.00000000"],["1600.00000000","872.21790000"],["1598.00000000","2.60010000"]],"a":[]}}
{"stream":"ethusdt@depth@100ms","data":{"e":"depthUpdate","E":1783465193816,"s":"ETHUSDT","U":78545070243,"u":78545070246,"b":[["1598.00000000","2.60710000"]],"a":[["1953.12000000","0.00710000"]]}}
{"stream":"btcusdt@depth@100ms","data":{"e":"depthUpdate","E":1783465193816,"s":"BTCUSDT","U":97109088293,"u":97109088311,"b":[["63551.02000000","0.81556000"],["63551.01000000","0.01153000"],["63550.84000000","0.13805000"],["63550.00000000","0.03877000"],["63549.24000000","0.00000000"],["57195.92000000","0.00480000"]],"a":[["64504.30000000","0.00030000"]]}}
{"stream":"ethusdt@depth@100ms","data":{"e":"depthUpdate","E":1783465193916,"s":"ETHUSDT","U":78545070247,"u":78545070251,"b":[["1598.00000000","2.60710000"]],"a":[["1953.12000000","0.00420000"]]}}
{"stream":"btcusdt@depth@100ms","data":{"e":"depthUpdate","E":1783465193916,"s":"BTCUSDT","U":97109088312,"u":97109088316,"b":[["63537.00000000","0.00000000"],["57195.92000000","0.00480000"]],"a":[["63562.43000000","0.00000000"]]}}
{"stream":"ethusdt@depth@100ms","data":{"e":"depthUpdate","E":1783465194016,"s":"ETHUSDT","U":78545070252,"u":78545070255,"b":[["1598.00000000","2.60710000"]],"a":[]}}
{"stream":"btcusdt@depth@100ms","data":{"e":"depthUpdate","E":1783465194016,"s":"BTCUSDT","U":97109088317,"u":97109088339,"b":[["63544.55000000","0.00000000"],["63537.00000000","0.00008000"],["63318.08000000","0.00000000"],["57195.92000000","0.00480000"],["50840.82000000","0.00083000"]],"a":[["63553.87000000","0.00000000"],["63562.43000000","0.00008000"]]}}
{"stream":"btcusdt@depth@100ms","data":{"e":"depthUpdate","E":1783465194114,"s":"BTCUSDT","U":97109088340,"u":97109088353,"b":[["63551.02000000","1.03987000"],["63549.13000000","0.09180000"],["63546.83000000","0.00026000"],["63545.27000000","0.00787000"],["63544.78000000","0.06321000"],["63543.52000000","0.70840000"],["63345.41000000","0.02465000"],["57195.92000000","0.00480000"],["50840.82000000","0.00083000"]],"a":[["63553.88000000","0.00018000"],["63554.35000000","0.00787000"]]}}
{"stream":"ethusdt@depth@100ms","data":{"e":"depthUpdate","E":1783465194115,"s":"ETHUSDT","U":78545070256,"u":78545070260,"b":[["1598.00000000","2.58630000"]],"a":[]}}
{"stream":"btcusdt@depth@100ms","data":{"e":"depthUpdate","E":1783465194215,"s":"BTCUSDT","U":97109088354,"u":97109088386,"b":[["63551.02000000","1.74818000"],["63546.84000000","0.00018000"],["63546.83000000","0.00008000"],["63546.00000000","0.02818000"],["63543.53000000","0.46013000"],["63543.52000000","0.00000000"],["63541.29000000","0.42498000"],["63538.65000000","0.00000000"],["62597.75000000","0.00030000"],["57195.92000000","0.00500000"],["50840.82000000","0.00044000"]],"a":[["63553.54000000","0.08018000"],["63553.88000000","0.00000000"],["63554.07000000","0.00895000"],["63554.35000000","0.00805000"]]}}
{"stream":"ethusdt@depth@100ms","data":{"e":"depthUpdate","E":1783465194215,"s":"ETHUSDT","U":78545070261,"u":78545070272,"b":[["1774.99000000","1.33630000"],["1773.49000000","1.13840000"],["1598.00000000","2.60010000"]],"a":[["1775.87000000","15.01870000"],["1775.96000000","0.00000000"],["1776.00000000","15.37360000"],["1778.83000000","0.00000000"]]}}
{"stream":"btcusdt@depth@100ms","data":{"e":"depthUpdate","E":1783465194314,"s":"BTCUSDT","U":97109088387,"u":97109088402,"b":[["63551.01000000","0.01424000"],["63549.13000000","0.09172000"],["63547.57000000","0.00675000"],["63546.84000000","0.00000000"],["63545.82000000","0.06482000"],["57195.92000000","0.00500000"],["57195.00000000","0.00087000"]],"a":[]}}
{"stream":"ethusdt@depth@100ms","data":{"e":"depthUpdate","E":1783465194315,"s":"ETHUSDT","U":78545070273,"u":78545070284,"b":[["1773.86000000","8.57260000"],["1773.85000000","12.07510000"],["1773.84000000","0.00000000"],["1773.79000000","0.00000000"],["1773.20000000","1.98150000"],["1598.00000000","2.60010000"],["1067.00000000","6.86000000"]],"a":[["1778.54000000","12.35810000"]]}}
{"stream":"btcusdt@depth@100ms","data":{"e":"depthUpdate","E":1783465194415,"s":"BTCUSDT","U":97109088403,"u":97109088410,"b":[["63467.22000000","0.00000000"],["57195.92000000","0.00480000"],["50841.00000000","0.23623000"],["40000.00000000","260.73952000"]],"a":[]}}
{"stream":"ethusdt@depth@100ms","data":{"e":"depthUpdate","E":1783465194415,"s":"ETHUSDT","U":78545070285,"u":78545070294,"b":[["1775.55000000","17.74590000"],["1775.20000000","0.03580000"],["1773.21000000","0.59250000"],["1772.00000000","1.13560000"],["1598.00000000","2.60010000"]],"a":[["1775.92000000","0.32980000"]]}}
{"stream":"btcusdt@depth@100ms","data":{"e":"depthUpdate","E":1783465194514,"s":"BTCUSDT","U":97109088411,"u":97109088418,"b":[["63467.22000000","0.16055000"],["57195.92000000","0.00480000"]],"a":[["63559.66000000","0.00000000"],["63559.70000000","0.09450000"],["63561.81000000","0.00000000"],["63562.78000000","0.12314000"]]}}
{"stream":"ethusdt@depth@100ms","data":{"e":"depthUpdate","E":1783465194515,"s":"ETHUSDT","U":78545070295,"u":78545070299,"b":[["1598.00000000","2.59330000"]],"a":[]}}
{"stream":"btcusdt@depth@100ms","data":{"e":"depthUpdate","E":1783465194614,"s":"BTCUSDT","U":97109088419,"u":97109088426,"b":[["63475.32000000","0.04882000"],["63467.22000000","0.00000000"],["57195.92000000","0.00480000"]],"a":[["63657.91000000","0.00000000"],["63666.05000000","0.05069000"]]}}
{"stream":"ethusdt@depth@100ms","data":{"e":"depthUpdate","E":1783465194615,"s":"ETHUSDT","U":78545070300,"u":78545070310,"b":[["1773.49000000","1.75850000"],["1773.21000000","0.00000000"],["1773.20000000","0.13540000"],["1598.00000000","2.60710000"]],"a":[["1778.54000000","11.79270000"],["1778.83000000","0.56540000"]]}}
{"stream":"ethusdt@depth@100ms","data":{"e":"depthUpdate","E":1783465194715,"s":"ETHUSDT","U":78545070311,"u":78545070314,"b":[["1768.71000000","0.14410000"],["1768.44000000","142.04130000"],["1598.00000000","2.60010000"]],"a":[]}}
{"stream":"btcusdt@depth@100ms","data":{"e":"depthUpdate","E":1783465194715,"s":"BTCUSDT","U":97109088427,"u":97109088430,"b":[["57195.92000000","0.00480000"]],"a":[]}}
{"stream":"ethusdt@depth@100ms","data":{"e":"depthUpdate","E":1783465194816,"s":"ETHUSDT","U":78545070315,"u":78545070318,"b":[["1598.00000000","2.60010000"]],"a":[]}}
{"stream":"btcusdt@depth@100ms","data":{"e":"depthUpdate","E":1783465194816,"s":"BTCUSDT","U":97109088431,"u":97109088438,"b":[["63345.41000000","0.00000000"],["63318.08000000","0.02465000"],["57195.92000000","0.00500000"],["50000.00000000","542.70395000"]],"a":[["64504.30000000","0.00030000"]]}}
{"stream":"ethusdt@depth@100ms","data":{"e":"depthUpdate","E":1783465194918,"s":"ETHUSDT","U":78545070319,"u":78545070322,"b":[["1598.00000000","2.60010000"]],"a":[]}}
{"stream":"btcusdt@depth@100ms","data":{"e":"depthUpdate","E":1783465194918,"s":"BTCUSDT","U":97109088439,"u":97109088443,"b":[["63551.02000000","1.52395000"],["57195.92000000","0.00500000"]],"a":[]}}
{"stream":"ethusdt@trade","data":{"e":"trade","E":1783465194994,"s":"ETHUSDT","t":4197008411,"p":"1775.56000000","q":"0.00560000","T":1783465194994,"m":false,"M":true}}
{"stream":"btcusdt@depth@100ms","data":{"e":"depthUpdate","E":1783465195014,"s":"BTCUSDT","U":97109088444,"u":97109088468,"b":[["63545.83000000","0.00787000"],["63545.34000000","0.00000000"],["63545.27000000","0.00000000"],["63537.00000000","0.00008000"],["57195.92000000","0.00500000"],["50840.82000000","0.00083000"]],"a":[["63554.35000000","0.00018000"],["63554.51000000","0.00000000"],["63554.88000000","0.00787000"],["63562.43000000","0.00008000"]]}}
{"stream":"ethusdt@depth@100ms","data":{"e":"depthUpdate","E":1783465195015,"s":"ETHUSDT","U":78545070323,"u":78545070330,"b":[["1773.96000000","0.01000000"],["1598.00000000","2.58630000"]],"a":[["1775.56000000","17.79240000"]]}}
{"stream":"btcusdt@depth@100ms","data":{"e":"depthUpdate","E":1783465195114,"s":"BTCUSDT","U":97109088469,"u":97109088492,"b":[["63551.02000000","1.53338000"],["63546.00000000","0.02818000"],["63545.83000000","0.00805000"],["63545.82000000","0.06464000"],["57195.92000000","0.00480000"],["50840.82000000","0.00083000"]],"a":[["63554.07000000","0.00895000"],["63554.35000000","0.00000000"],["63554.36000000","0.04022000"]]}}
{"stream":"ethusdt@depth@100ms","data":{"e":"depthUpdate","E":1783465195115,"s":"ETHUSDT","U":78545070331,"u":78545070336,"b":[["1598.00000000","2.60010000"]],"a":[]}}
{"stream":"btcusdt@trade","data":{"e":"trade","E":1783465195119,"s":"BTCUSDT","t":6486989386,"p":"63551.02000000","q":"0.00102000","T":1783465195119,"m":true,"M":true}}
{"stream":"btcusdt@depth@100ms","data":{"e":"depthUpdate","E":1783465195215,"s":"BTCUSDT","U":97109088493,"u":97109088501,"b":[["63551.02000000","1.53236000"],["62597.75000000","0.00030000"],["57195.92000000","0.00480000"],["57195.91000000","0.00000000"],["57195.90000000","0.00010000"],["50840.82000000","0.00044000"]],"a":[]}}
{"stream":"ethusdt@depth@100ms","data":{"e":"depthUpdate","E":1783465195215,"s":"ETHUSDT","U":78545070337,"u":78545070339,"b":[["1598.00000000","2.60710000"]],"a":[]}}
{"stream":"btcusdt@depth@100ms","data":{"e":"depthUpdate","E":1783465195314,"s":"BTCUSDT","U":97109088502,"u":97109088509,"b":[["63540.60000000","0.00000000"],["63538.25000000","0.03090000"],["63318.08000000","0.00000000"],["63303.12000000","0.02465000"],["57195.92000000","0.00480000"]],"a":[]}}
{"stream":"ethusdt@depth@100ms","data":{"e":"depthUpdate","E":1783465195315,"s":"ETHUSDT","U":78545070340,"u":78545070346,"b":[["1775.24000000","1.70080000"],["1775.21000000","3.38110000"],["1775.12000000","1.64190000"],["1598.00000000","2.60710000"]],"a":[]}}
{"stream":"btcusdt@depth@100ms","data":{"e":"depthUpdate","E":1783465195414,"s":"BTCUSDT","U":97109088510,"u":97109088519,"b":[["63537.92000000","0.01574000"],["63534.31000000","0.00000000"],["57195.92000000","0.00480000"],["40000.00000000","260.73952000"]],"a":[["63571.54000000","0.00699000"],["63577.33000000","0.00000000"]]}}
{"stream":"ethusdt@depth@100ms","data":{"e":"depthUpdate","E":1783465195416,"s":"ETHUSDT","U":78545070347,"u":78545070352,"b":[["1775.20000000","0.03290000"],["1598.00000000","2.58630000"]],"a":[["1775.92000000","0.32690000"]]}}
{"stream":"btcusdt@depth@100ms","data":{"e":"depthUpdate","E":1783465195514,"s":"BTCUSDT","U":97109088520,"u":97109088525,"b":[["57195.92000000","0.00500000"],["57195.00000000","0.00087000"]],"a":[["63551.03000000","2.10067000"]]}}
{"stream":"ethusdt@depth@100ms","data":{"e":"depthUpdate","E":1783465195515,"s":"ETHUSDT","U":78545070353,"u":78545070364,"b":[["1775.20000000","0.03580000"],["1773.86000000","4.96820000"],["1773.85000000","0.00000000"],["1773.79000000","12.07510000"],["1598.00000000","2.60010000"]],"a":[["1775.92000000","0.32980000"]]}}
{"stream":"btcusdt@depth@100ms","data":{"e":"depthUpdate","E":1783465195615,"s":"BTCUSDT","U":97109088526,"u":97109088532,"b":[["63551.02000000","1.53202000"],["57195.92000000","0.00500000"],["50841.00000000","0.23623000"]],"a":[]}}
{"stream":"ethusdt@depth@100ms","data":{"e":"depthUpdate","E":1783465195616,"s":"ETHUSDT","U":78545070365,"u":78545070369,"b":[["1598.00000000","2.60010000"]],"a":[["1775.56000000","17.78550000"]]}}
{"stream":"ethusdt@depth@100ms","data":{"e":"depthUpdate","E":1783465195715,"s":"ETHUSDT","U":78545070370,"u":78545070374,"b":[["1598.00000000","2.60010000"]],"a":[["2821.03000000","0.00590000"]]}}
{"stream":"btcusdt@depth@100ms","data":{"e":"depthUpdate","E":1783465195715,"s":"BTCUSDT","U":97109088533,"u":97109088535,"b":[["57195.92000000","0.00480000"]],"a":[]}}
{"stream":"ethusdt@depth@100ms","data":{"e":"depthUpdate","E":1783465195816,"s":"ETHUSDT","U":78545070375,"u":78545070378,"b":[["1598.00000000","2.60710000"]],"a":[["1775.56000000","17.79240000"]]}}
{"stream":"btcusdt@depth@100ms","data":{"e":"depthUpdate","E":1783465195816,"s":"BTCUSDT","U":97109088536,"u":97109088542,"b":[["63551.02000000","1.53236000"],["57195.92000000","0.00480000"]],"a":[["64504.30000000","0.00030000"]]}}
{"stream":"btcusdt@depth@100ms","data":{"e":"depthUpdate","E":1783465195914,"s":"BTCUSDT","U":97109088543,"u":97109088568,"b":[["63551.02000000","0.16555000"],["63550.85000000","0.00000000"],["63550.84000000","0.00018000"],["63546.01000000","0.00009000"],["63545.83000000","0.00018000"],["63544.79000000","0.00000000"],["63543.16000000","0.00787000"],["63542.68000000","0.00000000"],["63541.29000000","0.00000000"],["63538.65000000","0.42499000"],["63537.15000000","0.70840000"],["57195.92000000","0.00480000"]],"a":[["63551.03000000","2.10444000"],["63553.53000000","0.00000000"]]}}
{"stream":"ethusdt@depth@100ms","data":{"e":"depthUpdate","E":1783465195915,"s":"ETHUSDT","U":78545070379,"u":78545070401,"b":[["1775.55000000","14.69840000"],["1775.52000000","0.47890000"],["1775.51000000","0.00900000"],["1775.46000000","0.08160000"],["1775.39000000","1.38500000"],["1775.27000000","7.94110000"],["1774.99000000","0.00430000"],["1774.90000000","25.07780000"],["1774.79000000","0.56350000"],["1773.85000000","12.07510000"],["1773.79000000","0.00000000"],["1773.54000000","1.00140000"],["1773.50000000","0.02820000"],["1598.00000000","2.59330000"]],"a":[["1775.56000000","18.40670000"]]}}
{"stream":"btcusdt@trade","data":{"e":"trade","E":1783465195982,"s":"BTCUSDT","t":6486989387,"p":"63551.02000000","q":"0.00008000","T":1783465195981,"m":true,"M":true}}
{"stream":"btcusdt@trade","data":{"e":"trade","E":1783465195982,"s":"BTCUSDT","t":6486989388,"p":"63551.02000000","q":"0.00008000","T":1783465195981,"m":true,"M":true}}
{"stream":"btcusdt@trade","data":{"e":"trade","E":1783465195982,"s":"BTCUSDT","t":6486989389,"p":"63551.02000000","q":"0.00008000","T":1783465195981,"m":true,"M":true}}
{"stream":"btcusdt@trade","data":{"e":"trade","E":1783465195982,"s":"BTCUSDT","t":6486989390,"p":"63551.02000000","q":"0.00008000","T":1783465195981,"m":true,"M":true}}
{"stream":"btcusdt@trade","data":{"e":"trade","E":1783465195982,"s":"BTCUSDT","t":6486989391,"p":"63551.02000000","q":"0.00008000","T":1783465195981,"m":true,"M":true}}
{"stream":"btcusdt@trade","data":{"e":"trade","E":1783465195982,"s":"BTCUSDT","t":6486989392,"p":"63551.02000000","q":"0.00009000","T":1783465195981,"m":true,"M":true}}
{"stream":"btcusdt@trade","data":{"e":"trade","E":1783465195982,"s":"BTCUSDT","t":6486989393,"p":"63551.02000000","q":"0.00009000","T":1783465195981,"m":true,"M":true}}
{"stream":"btcusdt@trade","data":{"e":"trade","E":1783465195982,"s":"BTCUSDT","t":6486989394,"p":"63551.02000000","q":"0.00009000","T":1783465195981,"m":true,"M":true}}
{"stream":"btcusdt@trade","data":{"e":"trade","E":1783465195982,"s":"BTCUSDT","t":6486989395,"p":"63551.02000000","q":"0.00016000","T":1783465195981,"m":true,"M":true}}
{"stream":"btcusdt@trade","data":{"e":"trade","E":1783465195982,"s":"BTCUSDT","t":6486989396,"p":"63551.02000000","q":"0.00009000","T":1783465195981,"m":true,"M":true}}
{"stream":"btcusdt@trade","data":{"e":"trade","E":1783465195982,"s":"BTCUSDT","t":6486989397,"p":"63551.02000000","q":"0.00009000","T":1783465195981,"m":true,"M":true}}
{"stream":"btcusdt@trade","data":{"e":"trade","E":1783465195982,"s":"BTCUSDT","t":6486989398,"p":"63551.02000000","q":"0.00009000","T":1783465195981,"m":true,"M":true}}
{"stream":"btcusdt@trade","data":{"e":"trade","E":1783465195982,"s":"BTCUSDT","t":6486989399,"p":"63551.02000000","q":"0.00009000","T":1783465195981,"m":true,"M":true}}
{"stream":"btcusdt@trade","data":{"e":"trade","E":1783465195982,"s":"BTCUSDT","t":6486989400,"p":"63551.02000000","q":"0.00009000","T":1783465195981,"m":true,"M":true}}
{"stream":"btcusdt@trade","data":{"e":"trade","E":1783465195982,"s":"BTCUSDT","t":6486989401,"p":"63551.02000000","q":"0.00381000","T":1783465195981,"m":true,"M":true}}
{"stream":"btcusdt@depth@100ms","data":{"e":"depthUpdate","E":1783465196014,"s":"BTCUSDT","U":97109088569,"u":97109088653,"b":[["63551.02000000","0.13703000"],["63551.01000000","0.01415000"],["63550.84000000","0.00000000"],["63549.14000000","0.00018000"],["63549.13000000","0.09315000"],["63547.53000000","0.00000000"],["63546.00000000","0.02818000"],["63545.83000000","0.00000000"],["63545.82000000","0.06482000"],["63545.33000000","0.04939000"],["63544.66000000","0.00316000"],["63543.53000000","0.00000000"],["63543.16000000","0.00000000"],["63542.40000000","0.00787000"],["63542.16000000","0.11115000"],["63541.49000000","0.00787000"],["63541.26000000","0.00000000"],["63541.25000000","0.00000000"],["63541.19000000","0.00000000"],["63539.58000000","0.06855000"],["63538.66000000","0.52471000"],["63538.63000000","0.00000000"],["63537.92000000","0.00000000"],["63537.00000000","0.00008000"],["63534.92000000","0.01574000"],["63518.91000000","0.00400000"],["63476.55000000","2.83475000"],["63406.23000000","0.22500000"],["57195.92000000","0.00480000"],["50840.82000000","0.00103000"]],"a":[["63551.03000000","2.10444000"],["63551.51000000","0.00787000"],["63553.16000000","0.00000000"],["63553.54000000","0.08026000"],["63554.15000000","0.05878000"],["63554.70000000","0.00126000"],["63554.88000000","0.00000000"],["63556.18000000","0.00000000"],["63556.24000000","0.00000000"],["63557.47000000","0.00126000"],["63559.69000000","0.08047000"],["63561.81000000","0.78734000"],["63562.43000000","0.00008000"],["63562.78000000","0.00000000"],["63562.86000000","0.56676000"],["63565.38000000","0.00000000"],["63578.03000000","0.00000000"]]}}
{"stream":"ethusdt@depth@100ms","data":{"e":"depthUpdate","E":1783465196015,"s":"ETHUSDT","U":78545070402,"u":78545070507,"b":[["1775.55000000","10.60270000"],["1775.54000000","0.01450000"],["1775.53000000","0.01160000"],["1775.52000000","0.00590000"],["1775.51000000","0.00900000"],["1775.47000000","0.00300000"],["1775.45000000","0.58300000"],["1775.44000000","1.40720000"],["1775.40000000","0.00300000"],["1775.39000000","0.43990000"],["1775.37000000","0.78100000"],["1775.32000000","0.56290000"],["1775.31000000","1.05030000"],["1775.29000000","1.40440000"],["1775.28000000","0.68410000"],["1775.27000000","0.05630000"],["1775.26000000","0.00290000"],["1775.21000000","0.28180000"],["1775.19000000","3.38690000"],["1775.11000000","17.82680000"],["1775.06000000","5.36480000"],["1775.05000000","4.02100000"],["1774.98000000","15.03450000"],["1774.24000000","10.37960000"],["1774.16000000","0.03000000"],["1773.85000000","0.00000000"],["1773.84000000","9.46180000"],["1773.60000000","16.20660000"],["1773.50000000","0.46520000"],["1773.48000000","2.91200000"],["1773.36000000","7.89220000"],["1598.00000000","2.60710000"]],"a":[["1775.56000000","17.75340000"],["1775.57000000","1.20870000"],["1775.60000000","3.70490000"],["1775.64000000","1.16140000"],["1775.65000000","0.00000000"],["1775.70000000","16.50750000"],["1775.72000000","0.28180000"],["1775.73000000","7.88480000"],["1775.75000000","17.35800000"],["1775.83000000","0.10000000"],["1775.85000000","7.88480000"],["1775.88000000","9.03310000"],["1775.89000000","4.12280000"],["1775.90000000","0.78830000"],["1775.99000000","0.46200000"],["1776.80000000","17.50090000"],["1776.99000000","2.81570000"],["1777.26000000","0.00290000"],["1777.33000000","0.27850000"],["1777.38000000","0.00000000"],["1777.69000000","8.68100000"],["1777.99000000","0.00000000"],["1778.15000000","0.04990000"]]}}
{"stream":"btcusdt@depth@100ms","data":{"e":"depthUpdate","E":1783465196114,"s":"BTCUSDT","U":97109088654,"u":97109088705,"b":[["63551.02000000","0.13903000"],["63551.01000000","0.01424000"],["63549.13000000","0.09323000"],["63547.46000000","0.00009000"],["63547.45000000","0.11897000"],["63541.49000000","0.00000000"],["57195.92000000","0.00480000"],["50840.82000000","0.00083000"],["33000.00000000","35.16979000"]],"a":[["63551.16000000","0.00881000"],["63551.51000000","0.00805000"],["63551.68000000","0.89068000"],["63553.54000000","0.08018000"],["63554.07000000","0.00895000"],["63554.14000000","2.83475000"],["63554.15000000","0.00000000"],["63554.36000000","0.04004000"],["63554.89000000","0.06416000"],["63555.19000000","0.00000000"],["63556.17000000","0.00000000"],["63557.27000000","0.00000000"],["63557.38000000","0.00000000"],["63557.47000000","0.00000000"],["63565.28000000","1.17449000"],["63578.60000000","0.00000000"]]}}
{"stream":"ethusdt@depth@100ms","data":{"e":"depthUpdate","E":1783465196115,"s":"ETHUSDT","U":78545070508,"u":78545070531,"b":[["1775.53000000","0.01760000"],["1775.52000000","0.44290000"],["1775.45000000","1.02000000"],["1775.40000000","0.00000000"],["1775.30000000","2.75930000"],["1775.25000000","2.94620000"],["1773.50000000","0.02820000"],["1773.48000000","2.47500000"],["1598.00000000","2.60010000"],["1067.00000000","6.86000000"]],"a":[["1775.56000000","17.76280000"],["1775.64000000","0.56240000"],["1775.70000000","20.16150000"],["1775.74000000","16.32050000"],["1775.88000000","9.00940000"],["1776.56000000","2.84630000"],["1776.99000000","0.00000000"],["1779.02000000","7.34120000"]]}}
{"stream":"btcusdt@depth@100ms","data":{"e":"depthUpdate","E":1783465196214,"s":"BTCUSDT","U":97109088706,"u":97109088743,"b":[["63547.57000000","0.00675000"],["63547.45000000","0.11915000"],["63545.33000000","0.04921000"],["62597.75000000","0.00030000"],["57195.92000000","0.00500000"],["50840.82000000","0.00044000"]],"a":[["63551.03000000","2.10452000"],["63551.66000000","1.18980000"],["63551.67000000","1.68467000"],["63551.68000000","0.00018000"],["63551.70000000","0.00036000"],["63552.43000000","0.00000000"],["63552.44000000","0.07034000"],["63553.07000000","0.09197000"],["63553.59000000","0.00126000"],["63554.07000000","0.00895000"],["63554.89000000","0.06408000"],["63565.28000000","1.17449000"]]}}
{"stream":"ethusdt@depth@100ms","data":{"e":"depthUpdate","E":1783465196215,"s":"ETHUSDT","U":78545070532,"u":78545070537,"b":[["1598.00000000","2.60010000"]],"a":[["1775.56000000","17.78660000"],["1775.72000000","0.00000000"],["1775.73000000","8.16660000"]]}}
{"stream":"ethusdt@depth@100ms","data":{"e":"depthUpdate","E":1783465196315,"s":"ETHUSDT","U":78545070538,"u":78545070549,"b":[["1775.52000000","0.44890000"],["1775.51000000","0.44600000"],["1775.45000000","1.01400000"],["1773.54000000","0.56440000"],["1598.00000000","2.58630000"]],"a":[]}}
{"stream":"btcusdt@depth@100ms","data":{"e":"depthUpdate","E":1783465196315,"s":"BTCUSDT","U":97109088744,"u":97109088771,"b":[["63549.13000000","0.09180000"],["57195.92000000","0.00500000"]],"a":[["63551.03000000","2.10444000"],["63551.51000000","0.00018000"],["63551.66000000","1.18998000"],["63551.67000000","1.68485000"],["63551.68000000","0.00000000"],["63551.82000000","0.00787000"],["63552.44000000","0.07034000"],["63553.07000000","0.09089000"],["63553.54000000","0.08000000"],["63554.07000000","0.00877000"]]}}
{"stream":"btcusdt@depth@100ms","data":{"e":"depthUpdate","E":1783465196414,"s":"BTCUSDT","U":97109088772,"u":97109088794,"b":[["57195.92000000","0.00480000"],["50841.00000000","0.23623000"],["40000.00000000","260.73952000"]],"a":[["63551.16000000","0.00881000"],["63551.51000000","0.00000000"],["63551.71000000","0.06434000"],["63551.82000000","0.00805000"]]}}
{"stream":"ethusdt@depth@100ms","data":{"e":"depthUpdate","E":1783465196416,"s":"ETHUSDT","U":78545070550,"u":78545070555,"b":[["1598.00000000","2.60010000"]],"a":[]}}
{"stream":"btcusdt@depth@100ms","data":{"e":"depthUpdate","E":1783465196514,"s":"BTCUSDT","U":97109088795,"u":97109088802,"b":[["63483.01000000","1.02661000"],["63480.91000000","0.00000000"],["63377.48000000","0.00000000"],["63367.45000000","0.00354000"],["57195.92000000","0.00480000"]],"a":[]}}
{"stream":"ethusdt@depth@100ms","data":{"e":"depthUpdate","E":1783465196515,"s":"ETHUSDT","U":78545070556,"u":78545070562,"b":[["1775.20000000","0.03580000"],["1598.00000000","2.60710000"]],"a":[["1775.92000000","0.32980000"],["1777.33000000","3.23840000"]]}}
{"stream":"btcusdt@depth@100ms","data":{"e":"depthUpdate","E":1783465196614,"s":"BTCUSDT","U":97109088803,"u":97109088812,"b":[["63548.99000000","0.00150000"],["63544.66000000","0.22816000"],["63500.01000000","1.18109000"],["57195.92000000","0.00480000"],["57195.00000000","0.00087000"]],"a":[["77811.66000000","0.00019000"]]}}
{"stream":"ethusdt@depth@100ms","data":{"e":"depthUpdate","E":1783465196616,"s":"ETHUSDT","U":78545070563,"u":78545070566,"b":[["1598.00000000","2.60710000"]],"a":[]}}
{"stream":"btcusdt@depth@100ms","data":{"e":"depthUpdate","E":1783465196714,"s":"BTCUSDT","U":97109088813,"u":97109088817,"b":[["57195.92000000","0.00480000"]],"a":[["63553.59000000","0.00000000"]]}}
{"stream":"ethusdt@depth@100ms","data":{"e":"depthUpdate","E":1783465196715,"s":"ETHUSDT","U":78545070567,"u":78545070571,"b":[["1598.00000000","2.60710000"]],"a":[["1775.73000000","7.88480000"],["1775.74000000","16.60230000"]]}}
{"stream":"btcusdt@trade","data":{"e":"trade","E":1783465196747,"s":"BTCUSDT","t":6486989402,"p":"63551.02000000","q":"0.00089000","T":1783465196747,"m":true,"M":true}}
{"stream":"btcusdt@depth@100ms","data":{"e":"depthUpdate","E":1783465196815,"s":"BTCUSDT","U":97109088818,"u":97109088826,"b":[["63551.02000000","0.13814000"],["63423.92000000","0.02489000"],["57195.92000000","0.00510000"],["57195.90000000","0.00000000"]],"a":[["64504.30000000","0.00030000"]]}}
{"stream":"ethusdt@depth@100ms","data":{"e":"depthUpdate","E":1783465196815,"s":"ETHUSDT","U":78545070572,"u":78545070577,"b":[["1598.00000000","2.58630000"]],"a":[["2000.00000000","867.66870000"]]}}
{"stream":"btcusdt@depth@100ms","data":{"e":"depthUpdate","E":1783465196914,"s":"BTCUSDT","U":97109088827,"u":97109088833,"b":[["63483.01000000","0.00000000"],["58466.94000000","0.00018000"],["57195.92000000","0.00500000"]],"a":[]}}
{"stream":"ethusdt@depth@100ms","data":{"e":"depthUpdate","E":1783465196915,"s":"ETHUSDT","U":78545070578,"u":78545070585,"b":[["1774.94000000","33.11620000"],["1774.86000000","20.58990000"],["1598.00000000","2.60010000"]],"a":[]}}
{"stream":"ethusdt@depth@100ms","data":{"e":"depthUpdate","E":1783465197015,"s":"ETHUSDT","U":78545070586,"u":78545070592,"b":[["1775.27000000","0.33970000"],["1598.00000000","2.60010000"]],"a":[["1776.39000000","28.38430000"],["1776.48000000","0.03890000"]]}}
{"stream":"btcusdt@depth@100ms","data":{"e":"depthUpdate","E":1783465197015,"s":"BTCUSDT","U":97109088834,"u":97109088853,"b":[["63542.17000000","0.00000000"],["63537.00000000","0.00000000"],["57195.92000000","0.00500000"],["50840.82000000","0.00083000"]],"a":[["63551.15000000","0.00000000"],["63551.82000000","0.00018000"],["63552.29000000","0.00787000"],["63562.43000000","0.00000000"]]}}
{"stream":"btcusdt@trade","data":{"e":"trade","E":1783465197048,"s":"BTCUSDT","t":6486989403,"p":"63551.02000000","q":"0.00316000","T":1783465197047,"m":true,"M":true}}
{"stream":"btcusdt@trade","data":{"e":"trade","E":1783465197048,"s":"BTCUSDT","t":6486989404,"p":"63551.02000000","q":"0.00193000","T":1783465197047,"m":true,"M":true}}
{"stream":"btcusdt@depth@100ms","data":{"e":"depthUpdate","E":1783465197114,"s":"BTCUSDT","U":97109088854,"u":97109088879,"b":[["63551.02000000","0.13925000"],["63551.01000000","0.01415000"],["63547.46000000","0.00000000"],["63547.45000000","0.00018000"],["63544.66000000","0.00316000"],["63542.16000000","0.00000000"],["63537.00000000","0.00008000"],["57195.92000000","0.00480000"],["50840.82000000","0.00083000"]],"a":[["63551.71000000","0.06434000"],["63551.82000000","0.00000000"],["63552.29000000","0.00805000"],["63562.43000000","0.00008000"]]}}
{"stream":"ethusdt@depth@100ms","data":{"e":"depthUpdate","E":1783465197115,"s":"ETHUSDT","U":78545070593,"u":78545070661,"b":[["1775.55000000","1.95860000"],["1775.54000000","0.02050000"],["1775.53000000","0.44860000"],["1775.52000000","0.00590000"],["1775.51000000","0.00900000"],["1775.47000000","0.00900000"],["1775.46000000","0.51860000"],["1775.45000000","0.57700000"],["1775.31000000","0.95030000"],["1775.27000000","0.43970000"],["1775.21000000","0.00000000"],["1775.19000000","0.00580000"],["1775.18000000","0.00000000"],["1775.17000000","3.82240000"],["1775.13000000","8.17500000"],["1775.12000000","1.64190000"],["1775.11000000","18.65070000"],["1775.10000000","17.34950000"],["1775.09000000","25.02780000"],["1775.05000000","1.20290000"],["1775.01000000","0.94260000"],["1774.99000000","15.02300000"],["1774.98000000","0.01580000"],["1774.97000000","24.82340000"],["1774.79000000","0.00000000"],["1774.73000000","0.56640000"],["1773.61000000","0.00000000"],["1773.54000000","1.00140000"],["1773.50000000","0.02820000"],["1773.48000000","2.47500000"],["1773.37000000","0.00720000"],["1773.12000000","0.00000000"],["1772.79000000","0.00000000"],["1598.00000000","2.60010000"]],"a":[["1775.56000000","19.86470000"],["1775.64000000","0.66240000"],["1775.67000000","0.28480000"],["1775.73000000","14.64810000"],["1775.74000000","16.32050000"],["1775.83000000","0.00000000"]]}}
{"stream":"btcusdt@depth@100ms","data":{"e":"depthUpdate","E":1783465197214,"s":"BTCUSDT","U":97109088880,"u":97109088898,"b":[["63549.13000000","0.09172000"],["63547.57000000","0.00675000"],["63547.45000000","0.00000000"],["63545.33000000","0.04939000"],["63405.72000000","0.09462000"],["62597.75000000","0.00030000"],["57195.92000000","0.00480000"],["50840.82000000","0.00044000"]],"a":[["63615.07000000","0.03109000"],["63741.26000000","0.06310000"]]}}
{"stream":"ethusdt@depth@100ms","data":{"e":"depthUpdate","E":1783465197216,"s":"ETHUSDT","U":78545070662,"u":78545070676,"b":[["1775.55000000","1.96150000"],["1775.54000000","0.02340000"],["1775.36000000","0.14290000"],["1775.31000000","0.87690000"],["1774.76000000","0.00850000"],["1774.70000000","0.78210000"],["1774.69000000","0.20630000"],["1774.51000000","6.80610000"],["1774.08000000","0.11740000"],["1598.00000000","2.59330000"]],"a":[["1775.66000000","0.67000000"]]}}
{"stream":"btcusdt@depth@100ms","data":{"e":"depthUpdate","E":1783465197314,"s":"BTCUSDT","U":97109088899,"u":97109088904,"b":[["57195.92000000","0.00480000"]],"a":[["63559.70000000","0.00000000"],["63559.71000000","0.09450000"]]}}
{"stream":"ethusdt@depth@100ms","data":{"e":"depthUpdate","E":1783465197315,"s":"ETHUSDT","U":78545070677,"u":78545070684,"b":[["1598.00000000","2.60710000"]],"a":[["1775.64000000","0.65940000"],["1775.67000000","0.28180000"]]}}
{"stream":"btcusdt@depth@100ms","data":{"e":"depthUpdate","E":1783465197415,"s":"BTCUSDT","U":97109088905,"u":97109088913,"b":[["63544.66000000","0.22816000"],["58466.94000000","0.00000000"],["57195.92000000","0.00480000"],["40000.00000000","260.73952000"]],"a":[["63554.20000000","0.00136000"]]}}
{"stream":"ethusdt@depth@100ms","data":{"e":"depthUpdate","E":1783465197416,"s":"ETHUSDT","U":78545070685,"u":78545070687,"b":[["1598.00000000","2.60010000"]],"a":[]}}
{"stream":"btcusdt@depth@100ms","data":{"e":"depthUpdate","E":1783465197514,"s":"BTCUSDT","U":97109088914,"u":97109088920,"b":[["63523.49000000","0.00000000"],["63504.43000000","0.00000000"],["57195.92000000","0.00500000"]],"a":[["63569.83000000","0.00000000"],["63588.90000000","0.00000000"]]}}
{"stream":"ethusdt@depth@100ms","data":{"e":"depthUpdate","E":1783465197515,"s":"ETHUSDT","U":78545070688,"u":78545070696,"b":[["1775.20000000","0.03580000"],["1774.87000000","7.39090000"],["1773.67000000","12.22300000"],["1598.00000000","2.60010000"]],"a":[["1775.92000000","0.32980000"]]}}
{"stream":"btcusdt@depth@100ms","data":{"e":"depthUpdate","E":1783465197614,"s":"BTCUSDT","U":97109088921,"u":97109088924,"b":[["57195.92000000","0.00500000"]],"a":[]}}
{"stream":"ethusdt@depth@100ms","data":{"e":"depthUpdate","E":1783465197615,"s":"ETHUSDT","U":78545070697,"u":78545070705,"b":[["1774.32000000","0.03000000"],["1774.08000000","0.08740000"],["1773.86000000","7.15780000"],["1598.00000000","2.60010000"]],"a":[["1775.56000000","19.86470000"]]}}
{"stream":"btcusdt@depth@100ms","data":{"e":"depthUpdate","E":1783465197714,"s":"BTCUSDT","U":97109088925,"u":97109088929,"b":[["57195.92000000","0.00480000"],["57195.00000000","0.00087000"]],"a":[]}}
{"stream":"ethusdt@depth@100ms","data":{"e":"depthUpdate","E":1783465197715,"s":"ETHUSDT","U":78545070706,"u":78545070713,"b":[["1598.00000000","2.58630000"]],"a":[["1779.81000000","0.88220000"],["1780.06000000","0.01120000"]]}}
{"stream":"btcusdt@depth@100ms","data":{"e":"depthUpdate","E":1783465197814,"s":"BTCUSDT","U":97109088930,"u":97109088944,"b":[["63522.80000000","0.53665000"],["63503.74000000","1.02306000"],["63456.71000000","0.11162000"],["63405.72000000","0.00000000"],["57195.92000000","0.00480000"],["50000.00000000","542.70415000"]],"a":[["63568.01000000","0.55984000"],["63587.09000000","1.06314000"],["63615.07000000","0.00000000"],["63741.26000000","0.00000000"],["64504.30000000","0.00030000"]]}}
{"stream":"ethusdt@depth@100ms","data":{"e":"depthUpdate","E":1783465197815,"s":"ETHUSDT","U":78545070714,"u":78545070718,"b":[["1598.00000000","2.60710000"]],"a":[]}}
{"stream":"ethusdt@trade","data":{"e":"trade","E":1783465197863,"s":"ETHUSDT","t":4197008412,"p":"1775.55000000","q":"0.00290000","T":1783465197863,"m":true,"M":true}}
{"stream":"ethusdt@trade","data":{"e":"trade","E":1783465197863,"s":"ETHUSDT","t":4197008413,"p":"1775.55000000","q":"0.00290000","T":1783465197863,"m":true,"M":true}}
{"stream":"ethusdt@trade","data":{"e":"trade","E":1783465197863,"s":"ETHUSDT","t":4197008414,"p":"1775.55000000","q":"0.00290000","T":1783465197863,"m":true,"M":true}}
{"stream":"ethusdt@trade","data":{"e":"trade","E":1783465197863,"s":"ETHUSDT","t":4197008415,"p":"1775.55000000","q":"0.00300000","T":1783465197863,"m":true,"M":true}}
{"stream":"ethusdt@trade","data":{"e":"trade","E":1783465197863,"s":"ETHUSDT","t":4197008416,"p":"1775.55000000","q":"0.07600000","T":1783465197863,"m":true,"M":true}}
{"stream":"ethusdt@trade","data":{"e":"trade","E":1783465197863,"s":"ETHUSDT","t":4197008417,"p":"1775.55000000","q":"0.09710000","T":1783465197863,"m":true,"M":true}}
{"stream":"ethusdt@trade","data":{"e":"trade","E":1783465197863,"s":"ETHUSDT","t":4197008418,"p":"1775.55000000","q":"0.00570000","T":1783465197863,"m":true,"M":true}}
{"stream":"ethusdt@trade","data":{"e":"trade","E":1783465197863,"s":"ETHUSDT","t":4197008419,"p":"1775.55000000","q":"0.00950000","T":1783465197863,"m":true,"M":true}}
{"stream":"ethusdt@trade","data":{"e":"trade","E":1783465197863,"s":"ETHUSDT","t":4197008420,"p":"1775.55000000","q":"0.08760000","T":1783465197863,"m":true,"M":true}}
{"stream":"ethusdt@trade","data":{"e":"trade","E":1783465197863,"s":"ETHUSDT","t":4197008421,"p":"1775.55000000","q":"0.01000000","T":1783465197863,"m":true,"M":true}}
{"stream":"ethusdt@trade","data":{"e":"trade","E":1783465197863,"s":"ETHUSDT","t":4197008422,"p":"1775.55000000","q":"0.00240000","T":1783465197863,"m":true,"M":true}}
{"stream":"ethusdt@trade","data":{"e":"trade","E":1783465197910,"s":"ETHUSDT","t":4197008423,"p":"1775.55000000","q":"0.00050000","T":1783465197910,"m":true,"M":true}}
{"stream":"ethusdt@trade","data":{"e":"trade","E":1783465197910,"s":"ETHUSDT","t":4197008424,"p":"1775.55000000","q":"0.00250000","T":1783465197910,"m":true,"M":true}}
{"stream":"btcusdt@depth@100ms","data":{"e":"depthUpdate","E":1783465197914,"s":"BTCUSDT","U":97109088945,"u":97109088954,"b":[["63551.02000000","0.13934000"],["63549.13000000","0.09180000"],["63545.86000000","0.14041000"],["63544.66000000","0.00316000"],["57195.92000000","0.00480000"]],"a":[]}}
{"stream":"ethusdt@depth@100ms","data":{"e":"depthUpdate","E":1783465197915,"s":"ETHUSDT","U":78545070719,"u":78545070780,"b":[["1775.55000000","0.50920000"],["1775.49000000","0.00300000"],["1775.48000000","0.00590000"],["1775.45000000","0.58000000"],["1775.29000000","2.24920000"],["1775.24000000","0.27260000"],["1775.13000000","0.00840000"],["1775.12000000","1.64190000"],["1775.11000000","7.94160000"],["1775.10000000","8.16950000"],["1774.99000000","0.00430000"],["1774.98000000","15.03450000"],["1774.97000000","22.00530000"],["1774.92000000","2.81810000"],["1773.92000000","0.00290000"],["1773.68000000","24.48050000"],["1773.67000000","0.14790000"],["1773.37000000","15.77680000"],["1773.27000000","0.00400000"],["1773.12000000","0.00000000"],["1772.79000000","0.00000000"],["1598.00000000","2.60710000"],["1067.00000000","6.86000000"]],"a":[["1775.56000000","21.05870000"],["1775.57000000","0.00870000"],["1775.62000000","0.60620000"],["1775.63000000","0.36990000"],["1775.91000000","1.68200000"]]}}
{"stream":"btcusdt@depth@100ms","data":{"e":"depthUpdate","E":1783465198014,"s":"BTCUSDT","U":97109088955,"u":97109088981,"b":[["63546.00000000","0.02818000"],["63545.86000000","0.14059000"],["63545.33000000","0.04921000"],["63541.34000000","0.00000000"],["63476.71000000","1.02661000"],["57195.92000000","0.00480000"],["50840.82000000","0.00083000"]],"a":[["63551.03000000","2.10444000"]]}}
{"stream":"ethusdt@depth@100ms","data":{"e":"depthUpdate","E":1783465198015,"s":"ETHUSDT","U":78545070781,"u":78545070876,"b":[["1775.55000000","0.50340000"],["1775.54000000","0.01740000"],["1775.53000000","0.01160000"],["1775.52000000","0.01190000"],["1775.51000000","0.44000000"],["1775.50000000","0.03950000"],["1775.47000000","0.00300000"],["1775.46000000","0.08160000"],["1775.45000000","0.44300000"],["1775.44000000","1.84420000"],["1775.43000000","0.15070000"],["1775.40000000","0.00600000"],["1775.39000000","0.44590000"],["1775.38000000","0.43700000"],["1775.36000000","0.00290000"],["1775.34000000","0.00740000"],["1775.30000000","0.01230000"],["1775.18000000","0.50920000"],["1775.17000000","0.44130000"],["1775.10000000","0.28470000"],["1775.06000000","1.01100000"],["1774.98000000","0.01580000"],["1774.73000000","0.00290000"],["1774.68000000","3.95310000"],["1774.57000000","0.28000000"],["1773.50000000","0.02820000"],["1773.48000000","2.47500000"],["1773.12000000","7.88480000"],["1772.80000000","5.22870000"],["1772.79000000","15.01870000"],["1772.76000000","0.00730000"],["1598.00000000","2.60710000"]],"a":[["1775.56000000","22.34070000"],["1775.57000000","0.01470000"],["1775.58000000","6.18210000"],["1775.59000000","8.22310000"],["1775.60000000","0.58980000"],["1775.61000000","0.45840000"],["1775.62000000","0.60020000"],["1775.63000000","0.36690000"],["1775.65000000","0.00000000"],["1775.67000000","0.01440000"],["1775.73000000","7.88480000"],["1775.78000000","5.29820000"],["1775.89000000","1.30470000"],["1776.92000000","15.79330000"],["1776.99000000","2.81570000"],["1777.17000000","0.00000000"],["1777.43000000","35.18770000"],["1777.49000000","26.05410000"],["1777.55000000","7.90220000"],["1777.93000000","0.00000000"],["1781.63000000","0.47750000"],["1782.32000000","0.00290000"],["1782.62000000","0.00290000"]]}}
{"stream":"ethusdt@trade","data":{"e":"trade","E":1783465198018,"s":"ETHUSDT","t":4197008425,"p":"1775.56000000","q":"0.06370000","T":1783465198018,"m":false,"M":true}}
{"stream":"btcusdt@depth@100ms","data":{"e":"depthUpdate","E":1783465198114,"s":"BTCUSDT","U":97109088982,"u":97109088992,"b":[["63537.00000000","0.00008000"],["57195.92000000","0.00480000"],["50840.82000000","0.00083000"]],"a":[["63562.43000000","0.00008000"]]}}
{"stream":"ethusdt@depth@100ms","data":{"e":"depthUpdate","E":1783465198115,"s":"ETHUSDT","U":78545070877,"u":78545070900,"b":[["1775.28000000","0.65410000"],["1775.23000000","1.05330000"],["1774.00000000","5.65280000"],["1773.68000000","24.62050000"],["1598.00000000","2.58630000"]],"a":[["1775.56000000","22.28300000"],["1775.57000000","25.24610000"],["1775.61000000","0.17660000"],["1775.62000000","0.88200000"],["1775.67000000","0.00840000"],["1775.78000000","2.48000000"],["1775.81000000","2.82400000"],["1777.14000000","24.93420000"],["1777.15000000","0.05290000"],["1777.41000000","28.13060000"],["1777.47000000","0.00000000"],["1777.77000000","0.00980000"]]}}
{"stream":"ethusdt@trade","data":{"e":"trade","E":1783465198130,"s":"ETHUSDT","t":4197008426,"p":"1775.55000000","q":"0.09460000","T":1783465198129,"m":true,"M":true}}
{"stream":"ethusdt@trade","data":{"e":"trade","E":1783465198130,"s":"ETHUSDT","t":4197008427,"p":"1775.55000000","q":"0.09710000","T":1783465198129,"m":true,"M":true}}
{"stream":"ethusdt@trade","data":{"e":"trade","E":1783465198130,"s":"ETHUSDT","t":4197008428,"p":"1775.55000000","q":"0.00830000","T":1783465198129,"m":true,"M":true}}
{"stream":"ethusdt@trade","data":{"e":"trade","E":1783465198130,"s":"ETHUSDT","t":4197008429,"p":"1775.55000000","q":"0.08890000","T":1783465198130,"m":true,"M":true}}
{"stream":"ethusdt@trade","data":{"e":"trade","E":1783465198130,"s":"ETHUSDT","t":4197008430,"p":"1775.55000000","q":"0.00290000","T":1783465198130,"m":true,"M":true}}
{"stream":"ethusdt@trade","data":{"e":"trade","E":1783465198130,"s":"ETHUSDT","t":4197008431,"p":"1775.55000000","q":"0.00290000","T":1783465198130,"m":true,"M":true}}
{"stream":"ethusdt@trade","data":{"e":"trade","E":1783465198130,"s":"ETHUSDT","t":4197008432,"p":"1775.55000000","q":"0.00290000","T":1783465198130,"m":true,"M":true}}
{"stream":"ethusdt@trade","data":{"e":"trade","E":1783465198130,"s":"ETHUSDT","t":4197008433,"p":"1775.55000000","q":"0.09710000","T":1783465198130,"m":true,"M":true}}
{"stream":"ethusdt@trade","data":{"e":"trade","E":1783465198130,"s":"ETHUSDT","t":4197008434,"p":"1775.55000000","q":"0.00530000","T":1783465198130,"m":true,"M":true}}
{"stream":"ethusdt@trade","data":{"e":"trade","E":1783465198131,"s":"ETHUSDT","t":4197008435,"p":"1775.55000000","q":"0.09180000","T":1783465198131,"m":true,"M":true}}
{"stream":"ethusdt@trade","data":{"e":"trade","E":1783465198131,"s":"ETHUSDT","t":4197008436,"p":"1775.55000000","q":"0.00570000","T":1783465198131,"m":true,"M":true}}
{"stream":"ethusdt@trade","data":{"e":"trade","E":1783465198131,"s":"ETHUSDT","t":4197008437,"p":"1775.55000000","q":"0.00300000","T":1783465198131,"m":true,"M":true}}
{"stream":"ethusdt@trade","data":{"e":"trade","E":1783465198131,"s":"ETHUSDT","t":4197008438,"p":"1775.55000000","q":"0.00290000","T":1783465198131,"m":true,"M":true}}
{"stream":"ethusdt@trade","data":{"e":"trade","E":1783465198131,"s":"ETHUSDT","t":4197008439,"p":"1775.55000000","q":"0.09710000","T":1783465198131,"m":true,"M":true}}
{"stream":"ethusdt@trade","data":{"e":"trade","E":1783465198131,"s":"ETHUSDT","t":4197008440,"p":"1775.55000000","q":"0.09710000","T":1783465198131,"m":true,"M":true}}
{"stream":"ethusdt@trade","data":{"e":"trade","E":1783465198131,"s":"ETHUSDT","t":4197008441,"p":"1775.55000000","q":"0.09720000","T":1783465198131,"m":true,"M":true}}
{"stream":"ethusdt@trade","data":{"e":"trade","E":1783465198131,"s":"ETHUSDT","t":4197008442,"p":"1775.55000000","q":"0.00520000","T":1783465198131,"m":true,"M":true}}
{"stream":"btcusdt@trade","data":{"e":"trade","E":1783465198134,"s":"BTCUSDT","t":6486989405,"p":"63551.02000000","q":"0.00008000","T":1783465198134,"m":true,"M":true}}
{"stream":"btcusdt@trade","data":{"e":"trade","E":1783465198134,"s":"BTCUSDT","t":6486989406,"p":"63551.02000000","q":"0.00002000","T":1783465198134,"m":true,"M":true}}
{"stream":"btcusdt@trade","data":{"e":"trade","E":1783465198139,"s":"BTCUSDT","t":6486989407,"p":"63551.02000000","q":"0.00006000","T":1783465198138,"m":true,"M":true}}
{"stream":"btcusdt@trade","data":{"e":"trade","E":1783465198139,"s":"BTCUSDT","t":6486989408,"p":"63551.02000000","q":"0.00009000","T":1783465198138,"m":true,"M":true}}
{"stream":"btcusdt@trade","data":{"e":"trade","E":1783465198139,"s":"BTCUSDT","t":6486989409,"p":"63551.02000000","q":"0.00085000","T":1783465198138,"m":true,"M":true}}
{"stream":"btcusdt@depth@100ms","data":{"e":"depthUpdate","E":1783465198214,"s":"BTCUSDT","U":97109088993,"u":97109089048,"b":[["63551.02000000","0.11455000"],["63551.01000000","0.01415000"],["63546.38000000","0.00032000"],["63546.35000000","0.00000000"],["63545.94000000","0.00000000"],["63545.86000000","0.00018000"],["63545.26000000","0.00008000"],["63544.77000000","0.00008000"],["63544.35000000","0.00000000"],["63543.80000000","0.02360000"],["63542.40000000","0.00000000"],["63541.01000000","0.00787000"],["63538.64000000","0.00000000"],["63538.58000000","0.00000000"],["63538.52000000","0.00000000"],["63538.46000000","0.06455000"],["63537.15000000","0.00000000"],["63523.18000000","0.56711000"],["63522.81000000","1.24062000"],["63522.19000000","0.00000000"],["63522.09000000","0.00400000"],["63520.97000000","0.70840000"],["63515.73000000","0.00400000"],["63477.49000000","0.00000000"],["63476.71000000","0.00000000"],["63475.40000000","0.00000000"],["57195.92000000","0.00500000"],["57195.91000000","0.00010000"],["50840.82000000","0.00044000"]],"a":[["63551.03000000","4.94721000"],["63551.20000000","0.00000000"],["63551.65000000","0.00000000"],["63552.03000000","0.00252000"],["63552.29000000","0.00018000"],["63553.07000000","0.00018000"],["63554.20000000","0.00010000"],["63554.70000000","0.00000000"],["63555.21000000","0.00000000"],["63555.28000000","0.02000000"],["63561.89000000","0.00000000"],["63608.00000000","0.02800000"],["63608.43000000","0.00391000"]]}}
{"stream":"ethusdt@depth@100ms","data":{"e":"depthUpdate","E":1783465198215,"s":"ETHUSDT","U":78545070901,"u":78545071024,"b":[["1775.55000000","4.40980000"],["1775.52000000","0.01190000"],["1775.51000000","0.44600000"],["1775.50000000","0.46810000"],["1775.44000000","1.84420000"],["1775.43000000","0.14780000"],["1775.39000000","0.43990000"],["1775.38000000","0.43700000"],["1775.37000000","0.00000000"],["1775.34000000","0.00740000"],["1775.33000000","6.90330000"],["1775.27000000","0.05630000"],["1775.26000000","0.00290000"],["1775.21000000","0.00000000"],["1775.18000000","0.00000000"],["1775.17000000","0.54130000"],["1775.16000000","1.10380000"],["1775.12000000","1.44190000"],["1775.11000000","0.94040000"],["1775.10000000","7.88770000"],["1775.09000000","0.43700000"],["1775.07000000","0.39210000"],["1775.06000000","1.21100000"],["1774.98000000","15.03450000"],["1774.77000000","48.13490000"],["1774.70000000","0.21840000"],["1774.64000000","0.43840000"],["1774.62000000","0.61270000"],["1774.28000000","0.00000000"],["1774.25000000","0.00840000"],["1774.22000000","15.01870000"],["1774.08000000","0.11740000"],["1774.00000000","5.62280000"],["1773.98000000","24.67910000"],["1773.92000000","0.21760000"],["1773.85000000","0.42100000"],["1773.54000000","0.56440000"],["1773.50000000","0.02820000"],["1773.48000000","2.47500000"],["1773.12000000","0.00000000"],["1772.93000000","2.47790000"],["1772.79000000","0.00000000"],["1771.89000000","0.00000000"],["1770.97000000","8.30550000"],["1598.00000000","2.58630000"]],"a":[["1775.56000000","61.08280000"],["1775.58000000","12.56380000"],["1775.62000000","0.88200000"],["1775.64000000","0.65940000"],["1775.67000000","0.00840000"],["1775.69000000","0.00600000"],["1775.72000000","0.00000000"],["1775.73000000","22.90350000"],["1775.74000000","1.30180000"],["1775.92000000","6.08570000"],["1777.42000000","15.01870000"],["1777.64000000","6.07890000"],["1777.69000000","4.44730000"],["1777.73000000","0.00000000"],["1778.80000000","0.01140000"]]}}
{"stream":"btcusdt@depth@100ms","data":{"e":"depthUpdate","E":1783465198314,"s":"BTCUSDT","U":97109089049,"u":97109089143,"b":[["63551.02000000","0.76918000"],["63551.01000000","0.01424000"],["63549.13000000","0.09172000"],["63546.87000000","0.00009000"],["63546.86000000","0.06463000"],["63546.00000000","0.02818000"],["63545.86000000","0.00000000"],["63545.33000000","0.04939000"],["63544.66000000","0.22816000"],["63544.35000000","0.00400000"],["63542.16000000","0.13276000"],["63538.68000000","1.41560000"],["63538.67000000","4.06315000"],["63538.66000000","0.46016000"],["63538.46000000","0.00000000"],["63535.95000000","0.00000000"],["63523.19000000","1.22840000"],["63520.97000000","0.00000000"],["63520.50000000","0.00400000"],["63518.91000000","0.00000000"],["63515.73000000","0.00000000"],["63476.55000000","0.00000000"],["63456.71000000","0.00000000"],["62597.75000000","0.00030000"],["57195.92000000","0.00500000"]],"a":[["63551.03000000","2.10468000"],["63551.16000000","0.00018000"],["63551.51000000","0.00845000"],["63551.65000000","0.00018000"],["63551.66000000","0.59450000"],["63551.71000000","0.06434000"],["63552.03000000","0.00000000"],["63552.29000000","0.00000000"],["63552.44000000","0.07026000"],["63553.07000000","0.00000000"],["63553.16000000","0.00787000"],["63553.54000000","0.08018000"],["63554.07000000","0.00895000"],["63554.13000000","0.00000000"],["63554.14000000","0.00000000"],["63554.38000000","0.00252000"],["63559.69000000","0.00000000"],["63561.81000000","0.14010000"],["63562.86000000","0.00000000"],["63565.24000000","0.78735000"],["63565.28000000","1.77015000"],["63574.61000000","0.56665000"],["63616.13000000","2.83475000"],["63619.59000000","0.00000000"],["63621.59000000","0.00000000"]]}}
{"stream":"ethusdt@depth@100ms","data":{"e":"depthUpdate","E":1783465198315,"s":"ETHUSDT","U":78545071025,"u":78545071105,"b":[["1775.51000000","7.20930000"],["1775.35000000","0.10720000"],["1775.33000000","0.14000000"],["1775.32000000","2.59210000"],["1775.28000000","0.68410000"],["1775.24000000","0.84730000"],["1775.21000000","0.28180000"],["1775.17000000","0.44130000"],["1775.16000000","15.86260000"],["1775.11000000","50.76260000"],["1775.07000000","0.11030000"],["1775.06000000","4.02890000"],["1774.92000000","0.00000000"],["1774.83000000","0.56350000"],["1774.68000000","3.38960000"],["1774.47000000","0.30370000"],["1774.08000000","0.08740000"],["1773.68000000","15.01870000"],["1773.37000000","0.00720000"],["1772.83000000","1.70400000"],["1772.80000000","0.00290000"],["1770.47000000","0.26250000"],["1770.39000000","0.00000000"],["1598.00000000","2.60010000"]],"a":[["1775.56000000","30.24800000"],["1775.57000000","0.01470000"],["1775.58000000","3.53280000"],["1775.59000000","0.34430000"],["1775.61000000","0.18260000"],["1775.62000000","0.60320000"],["1775.64000000","0.55940000"],["1775.65000000","0.00000000"],["1775.66000000","0.00000000"],["1775.69000000","0.00000000"],["1775.70000000","7.88820000"],["1775.72000000","8.89220000"],["1775.73000000","7.88480000"],["1775.74000000","1.58360000"],["1775.81000000","0.00580000"],["1775.82000000","24.10310000"],["1775.88000000","9.00940000"],["1775.91000000","0.35000000"],["1775.92000000","0.32980000"],["1775.94000000","2.84350000"],["1776.04000000","0.44540000"],["1776.67000000","0.10910000"],["1777.26000000","7.88770000"],["1777.49000000","7.98180000"]]}}
{"stream":"btcusdt@depth@100ms","data":{"e":"depthUpdate","E":1783465198414,"s":"BTCUSDT","U":97109089144,"u":97109089208,"b":[["63551.02000000","0.14376000"],["63549.41000000","0.00018000"],["63549.40000000","0.10839000"],["63549.13000000","0.00210000"],["63548.99000000","0.00009000"],["63547.57000000","0.00675000"],["63546.87000000","0.00000000"],["63546.86000000","0.06481000"],["63546.01000000","0.00000000"],["63545.33000000","0.04921000"],["63542.16000000","0.00000000"],["63541.51000000","0.70840000"],["63538.68000000","1.99788000"],["63538.67000000","0.00000000"],["63537.86000000","0.00000000"],["63500.01000000","0.58143000"],["63490.51000000","0.00000000"],["63476.55000000","2.83475000"],["57195.92000000","0.00480000"],["40000.00000000","260.73952000"]],"a":[["63551.03000000","4.93952000"],["63551.16000000","0.00000000"],["63551.51000000","0.00863000"],["63552.44000000","0.07026000"],["63553.16000000","0.00805000"],["63554.07000000","0.00877000"],["63555.09000000","0.09071000"],["63608.00000000","0.03193000"],["63608.43000000","0.00000000"]]}}
{"stream":"ethusdt@depth@100ms","data":{"e":"depthUpdate","E":1783465198415,"s":"ETHUSDT","U":78545071106,"u":78545071113,"b":[["1775.36000000","0.03290000"],["1775.24000000","4.48880000"],["1774.16000000","0.00000000"],["1598.00000000","2.60010000"]],"a":[["1775.76000000","6.79910000"]]}}
{"stream":"btcusdt@depth@100ms","data":{"e":"depthUpdate","E":1783465198515,"s":"BTCUSDT","U":97109089209,"u":97109089246,"b":[["63551.02000000","0.14026000"],["63550.00000000","0.03877000"],["63549.41000000","0.00000000"],["63549.40000000","0.00018000"],["63549.14000000","0.00000000"],["63549.13000000","0.00192000"],["63546.87000000","0.00018000"],["63546.01000000","0.00009000"],["63544.83000000","0.09130000"],["63541.51000000","0.00000000"],["63538.69000000","0.65755000"],["63538.68000000","0.06455000"],["63534.48000000","0.00000000"],["63530.48000000","1.09563000"],["63370.64000000","0.00000000"],["63362.47000000","0.00987000"],["57195.92000000","0.00480000"]],"a":[["63551.03000000","4.94739000"],["63553.16000000","0.00018000"],["63554.89000000","0.06416000"]]}}
{"stream":"ethusdt@depth@100ms","data":{"e":"depthUpdate","E":1783465198516,"s":"ETHUSDT","U":78545071114,"u":78545071133,"b":[["1775.20000000","0.03290000"],["1775.16000000","16.00260000"],["1775.14000000","0.15150000"],["1775.12000000","1.58190000"],["1775.06000000","8.38270000"],["1774.64000000","0.03840000"],["1774.57000000","0.68000000"],["1773.61000000","0.14000000"],["1773.59000000","19.92160000"],["1773.58000000","8.02450000"],["1768.44000000","141.46610000"],["1768.26000000","0.57520000"],["1598.00000000","2.60710000"]],"a":[["1775.75000000","17.65200000"],["1775.77000000","0.46490000"],["1775.79000000","1.13040000"],["1775.92000000","0.32690000"],["1775.97000000","25.23880000"],["1775.99000000","0.00000000"]]}}
{"stream":"btcusdt@depth@100ms","data":{"e":"depthUpdate","E":1783465198614,"s":"BTCUSDT","U":97109089247,"u":97109089272,"b":[["63551.02000000","0.14018000"],["63550.00000000","0.03877000"],["63549.40000000","0.00000000"],["63545.82000000","0.06490000"],["63545.33000000","0.04939000"],["63533.07000000","0.94869000"],["57195.92000000","0.00480000"]],"a":[["63552.44000000","0.07026000"],["63553.16000000","0.00000000"],["63554.07000000","0.00895000"],["63555.09000000","0.00000000"]]}}
{"stream":"ethusdt@depth@100ms","data":{"e":"depthUpdate","E":1783465198615,"s":"ETHUSDT","U":78545071134,"u":78545071149,"b":[["1775.20000000","0.03580000"],["1775.06000000","5.56480000"],["1774.99000000","2.82240000"],["1773.61000000","0.00000000"],["1773.58000000","7.88450000"],["1773.44000000","6.31370000"],["1598.00000000","2.59330000"]],"a":[["1775.92000000","0.32980000"],["1776.01000000","11.22130000"],["1776.98000000","2.48220000"],["1777.31000000","0.74790000"]]}}
{"stream":"btcusdt@depth@100ms","data":{"e":"depthUpdate","E":1783465198714,"s":"BTCUSDT","U":97109089273,"u":97109089295,"b":[["63551.02000000","0.11473000"],["63551.01000000","0.01433000"],["63549.13000000","0.00024000"],["63546.86000000","0.06489000"],["63546.29000000","0.00009000"],["63546.28000000","0.14227000"],["63538.65000000","0.00000000"],["63535.95000000","0.42501000"],["57195.92000000","0.00480000"]],"a":[["63551.65000000","0.00000000"],["63551.66000000","0.59432000"],["63551.71000000","0.06442000"],["63551.75000000","0.09071000"],["63552.69000000","0.00252000"],["63554.38000000","0.00000000"],["63554.89000000","0.06408000"]]}}
{"stream":"ethusdt@depth@100ms","data":{"e":"depthUpdate","E":1783465198715,"s":"ETHUSDT","U":78545071150,"u":78545071167,"b":[["1775.55000000","4.44150000"],["1775.54000000","0.02030000"],["1775.24000000","0.84730000"],["1598.00000000","2.60710000"]],"a":[["1775.91000000","1.68200000"],["1779.81000000","0.00000000"],["1781.00000000","0.89600000"]]}}
{"stream":"btcusdt@depth@100ms","data":{"e":"depthUpdate","E":1783465198814,"s":"BTCUSDT","U":97109089296,"u":97109089332,"b":[["63551.02000000","0.11813000"],["63551.01000000","0.01415000"],["63547.85000000","0.00018000"],["63547.84000000","0.12362000"],["63546.86000000","0.06489000"],["63546.29000000","0.00000000"],["63546.28000000","0.00018000"],["63546.01000000","0.00000000"],["63545.33000000","0.04921000"],["63500.01000000","1.19273000"],["63476.56000000","1.09672000"],["63370.64000000","0.00987000"],["63362.47000000","0.00000000"],["57195.92000000","0.00500000"]],"a":[["63551.71000000","0.06442000"],["63551.75000000","0.09089000"],["63554.07000000","0.00877000"],["64504.30000000","0.00000000"]]}}
{"stream":"ethusdt@depth@100ms","data":{"e":"depthUpdate","E":1783465198815,"s":"ETHUSDT","U":78545071168,"u":78545071184,"b":[["1775.21000000","0.56510000"],["1775.16000000","16.14260000"],["1774.83000000","0.00000000"],["1773.61000000","0.14000000"],["1773.59000000","19.78160000"],["1768.44000000","142.04130000"],["1768.26000000","0.00000000"],["1598.00000000","2.60010000"],["1597.99000000","0.00870000"]],"a":[["1775.68000000","1.32840000"],["1775.70000000","8.18220000"],["1775.75000000","18.32200000"],["1775.78000000","2.80200000"],["1775.79000000","1.43840000"],["1779.11000000","0.00000000"],["1781.00000000","0.01380000"]]}}
{"stream":"btcusdt@depth@100ms","data":{"e":"depthUpdate","E":1783465198914,"s":"BTCUSDT","U":97109089333,"u":97109089354,"b":[["63551.02000000","0.11822000"],["63551.01000000","0.01424000"],["63548.00000000","0.02818000"],["63547.84000000","0.12380000"],["63546.86000000","0.06481000"],["63546.28000000","0.00000000"],["57195.92000000","0.00500000"],["57195.00000000","0.00087000"]],"a":[["64504.30000000","0.00030000"]]}}
{"stream":"ethusdt@depth@100ms","data":{"e":"depthUpdate","E":1783465198915,"s":"ETHUSDT","U":78545071185,"u":78545071195,"b":[["1773.67000000","12.22300000"],["1598.00000000","2.60010000"],["1597.99000000","0.00520000"]],"a":[["1775.90000000","0.34030000"],["1775.92000000","0.03580000"],["1776.00000000","15.05160000"],["1776.01000000","10.91330000"],["1782.66000000","0.01120000"]]}}
{"stream":"btcusdt@depth@100ms","data":{"e":"depthUpdate","E":1783465199014,"s":"BTCUSDT","U":97109089355,"u":97109089361,"b":[["57195.92000000","0.00500000"],["50840.82000000","0.00083000"]],"a":[["63558.68000000","0.10400000"],["63561.46000000","0.78734000"],["63561.81000000","0.00000000"],["63565.24000000","0.00000000"]]}}
{"stream":"ethusdt@depth@100ms","data":{"e":"depthUpdate","E":1783465199015,"s":"ETHUSDT","U":78545071196,"u":78545071204,"b":[["1775.21000000","0.28330000"],["1775.18000000","0.28180000"],["1598.00000000","2.58630000"]],"a":[["1775.69000000","0.28180000"],["1775.74000000","1.30180000"],["1775.85000000","10.70300000"],["1775.94000000","0.02560000"]]}}
{"stream":"btcusdt@depth@100ms","data":{"e":"depthUpdate","E":1783465199114,"s":"BTCUSDT","U":97109089362,"u":97109089372,"b":[["63537.19000000","0.00000000"],["63537.00000000","0.00008000"],["57195.92000000","0.00480000"],["50840.82000000","0.00083000"]],"a":[["63562.43000000","0.00008000"]]}}
{"stream":"ethusdt@depth@100ms","data":{"e":"depthUpdate","E":1783465199115,"s":"ETHUSDT","U":78545071205,"u":78545071210,"b":[["1598.00000000","2.58630000"]],"a":[["1775.68000000","1.66440000"],["1786.21000000","0.03950000"]]}}
{"stream":"btcusdt@depth@100ms","data":{"e":"depthUpdate","E":1783465199215,"s":"BTCUSDT","U":97109089373,"u":97109089378,"b":[["63543.58000000","0.00031000"],["57195.92000000","0.00480000"],["50840.82000000","0.00044000"]],"a":[]}}
{"stream":"ethusdt@depth@100ms","data":{"e":"depthUpdate","E":1783465199215,"s":"ETHUSDT","U":78545071211,"u":78545071218,"b":[["1773.61000000","0.00000000"],["1773.20000000","4.61520000"],["1598.00000000","2.60710000"]],"a":[["1775.90000000","0.00430000"]]}}
{"stream":"btcusdt@depth@100ms","data":{"e":"depthUpdate","E":1783465199314,"s":"BTCUSDT","U":97109089379,"u":97109089382,"b":[["57195.92000000","0.00480000"]],"a":[]}}
{"stream":"ethusdt@depth@100ms","data":{"e":"depthUpdate","E":1783465199315,"s":"ETHUSDT","U":78545071219,"u":78545071234,"b":[["1775.55000000","5.81460000"],["1775.32000000","0.56290000"],["1775.25000000","0.47120000"],["1775.24000000","1.65090000"],["1775.19000000","2.48080000"],["1774.82000000","0.56640000"],["1598.00000000","2.60710000"]],"a":[["1775.72000000","14.99160000"],["1775.74000000","16.32050000"],["1789.76000000","0.00380000"]]}}
{"stream":"ethusdt@depth@100ms","data":{"e":"depthUpdate","E":1783465199415,"s":"ETHUSDT","U":78545071235,"u":78545071237,"b":[["1598.00000000","2.60010000"]],"a":[]}}
{"stream":"btcusdt@depth@100ms","data":{"e":"depthUpdate","E":1783465199415,"s":"BTCUSDT","U":97109089383,"u":97109089390,"b":[["63524.96000000","0.00000000"],["63524.84000000","0.23471000"],["57195.92000000","0.00480000"],["40000.00000000","260.73952000"]],"a":[]}}
{"stream":"btcusdt@depth@100ms","data":{"e":"depthUpdate","E":1783465199514,"s":"BTCUSDT","U":97109089391,"u":97109089394,"b":[["63548.56000000","0.00171000"],["57195.92000000","0.00500000"]],"a":[]}}
{"stream":"ethusdt@depth@100ms","data":{"e":"depthUpdate","E":1783465199515,"s":"ETHUSDT","U":78545071238,"u":78545071247,"b":[["1598.00000000","2.58630000"]],"a":[["1776.20000000","15.31270000"],["1776.90000000","16.23730000"],["1779.11000000","0.00340000"]]}}
{"stream":"btcusdt@depth@100ms","data":{"e":"depthUpdate","E":1783465199614,"s":"BTCUSDT","U":97109089395,"u":97109089399,"b":[["63474.61000000","1.02661000"],["57195.92000000","0.00500000"]],"a":[]}}
{"stream":"ethusdt@depth@100ms","data":{"e":"depthUpdate","E":1783465199615,"s":"ETHUSDT","U":78545071248,"u":78545071259,"b":[["1775.20000000","0.03580000"],["1773.21000000","1.37870000"],["1598.00000000","2.60010000"]],"a":[["1775.92000000","0.03580000"],["1777.15000000","6.99770000"],["1777.20000000","1.00960000"]]}}
{"stream":"btcusdt@depth@100ms","data":{"e":"depthUpdate","E":1783465199714,"s":"BTCUSDT","U":97109089400,"u":97109089406,"b":[["63551.02000000","0.11472000"],["63542.14000000","0.00787000"],["63541.01000000","0.00000000"],["57195.92000000","0.00480000"]],"a":[["63551.03000000","4.93952000"],["63551.50000000","0.00787000"],["63561.47000000","0.00000000"]]}}
{"stream":"ethusdt@depth@100ms","data":{"e":"depthUpdate","E":1783465199715,"s":"ETHUSDT","U":78545071260,"u":78545071266,"b":[["1598.00000000","2.60010000"],["1067.00000000","6.86000000"]],"a":[["1782.66000000","0.01460000"]]}}
{"stream":"btcusdt@trade","data":{"e":"trade","E":1783465199803,"s":"BTCUSDT","t":6486989410,"p":"63551.02000000","q":"0.00100000","T":1783465199803,"m":true,"M":true}}
{"stream":"btcusdt@depth@100ms","data":{"e":"depthUpdate","E":1783465199814,"s":"BTCUSDT","U":97109089407,"u":97109089424,"b":[["63551.02000000","0.11372000"],["63490.51000000","1.09672000"],["63476.56000000","0.00000000"],["57195.92000000","0.00480000"],["57195.91000000","0.00000000"],["57195.90000000","0.00010000"],["50000.00000000","542.70395000"]],"a":[["63551.03000000","4.94739000"],["63551.50000000","0.00018000"],["63553.54000000","0.08000000"]]}}
{"stream":"ethusdt@depth@100ms","data":{"e":"depthUpdate","E":1783465199815,"s":"ETHUSDT","U":78545071267,"u":78545071272,"b":[["1775.55000000","6.05750000"],["1598.00000000","2.60710000"]],"a":[["1776.23000000","0.30800000"]]}}
{"stream":"btcusdt@trade","data":{"e":"trade","E":1783465199913,"s":"BTCUSDT","t":6486989411,"p":"63551.02000000","q":"0.00116000","T":1783465199912,"m":true,"M":true}}
{"stream":"btcusdt@depth@100ms","data":{"e":"depthUpdate","E":1783465199914,"s":"BTCUSDT","U":97109089425,"u":97109089439,"b":[["63551.02000000","0.11256000"],["63518.95000000","0.00255000"],["57195.92000000","0.00480000"],["57195.00000000","0.00107000"]],"a":[["63551.03000000","4.94739000"],["63551.50000000","0.00000000"],["63553.54000000","0.08018000"]]}}
{"stream":"ethusdt@depth@100ms","data":{"e":"depthUpdate","E":1783465199916,"s":"ETHUSDT","U":78545071273,"u":78545071284,"b":[["1775.21000000","0.28330000"],["1775.18000000","0.28180000"],["1598.00000000","2.60710000"]],"a":[["1775.69000000","0.00000000"],["1775.71000000","0.28180000"],["1775.74000000","16.32050000"],["1775.85000000","7.88480000"],["1775.88000000","11.82760000"],["1777.31000000","0.43990000"],["1786.21000000","0.04290000"]]}}
{"stream":"btcusdt@depth@100ms","data":{"e":"depthUpdate","E":1783465200014,"s":"BTCUSDT","U":97109089440,"u":97109089454,"b":[["63484.91000000","0.00037000"],["63430.20000000","0.00157000"],["63430.01000000","0.00000000"],["63421.66000000","0.00014000"],["57195.92000000","0.00480000"],["57195.00000000","0.00087000"],["50840.82000000","0.00083000"]],"a":[["63557.56000000","0.59053000"],["63557.95000000","0.00000000"],["63559.86000000","0.77000000"],["63561.45000000","0.78734000"],["63561.46000000","0.00000000"],["63561.81000000","0.00000000"],["63592.34000000","0.00393000"],["63655.82000000","0.00157000"]]}}
{"stream":"ethusdt@depth@100ms","data":{"e":"depthUpdate","E":1783465200015,"s":"ETHUSDT","U":78545071285,"u":78545071292,"b":[["1775.01000000","3.76080000"],["1774.99000000","0.00430000"],["1598.00000000","2.59330000"]],"a":[["1775.69000000","0.28180000"],["1775.71000000","0.00000000"]]}}
{"stream":"btcusdt@trade","data":{"e":"trade","E":1783465200103,"s":"BTCUSDT","t":6486989412,"p":"63551.02000000","q":"0.00900000","T":1783465200102,"m":true,"M":true}}
{"stream":"btcusdt@depth@100ms","data":{"e":"depthUpdate","E":1783465200114,"s":"BTCUSDT","U":97109089455,"u":97109089487,"b":[["63551.02000000","0.10356000"],["63547.85000000","0.00000000"],["63547.84000000","0.00028000"],["63546.01000000","0.00009000"],["63538.70000000","0.42499000"],["63537.00000000","0.00000000"],["63535.95000000","0.00000000"],["63484.91000000","0.00000000"],["63421.66000000","0.00014000"],["58040.97000000","0.00000000"],["57195.92000000","0.00480000"],["50840.82000000","0.00103000"]],"a":[["63557.39000000","0.22508000"],["63558.68000000","0.10630000"],["63558.70000000","1.31365000"],["63559.52000000","0.00000000"],["63561.45000000","0.00000000"],["63561.81000000","0.78734000"],["63562.43000000","0.00000000"],["63565.28000000","1.39594000"],["63592.34000000","0.00393000"],["63655.82000000","0.00000000"]]}}
{"stream":"ethusdt@depth@100ms","data":{"e":"depthUpdate","E":1783465200115,"s":"ETHUSDT","U":78545071293,"u":78545071303,"b":[["1775.55000000","4.52500000"],["1598.00000000","2.60010000"]],"a":[["1775.69000000","0.00000000"],["1775.71000000","0.28180000"],["1776.22000000","9.80070000"],["1789.76000000","0.00720000"]]}}
{"stream":"ethusdt@trade","data":{"e":"trade","E":1783465200176,"s":"ETHUSDT","t":4197008443,"p":"1775.55000000","q":"0.09190000","T":1783465200176,"m":true,"M":true}}
{"stream":"ethusdt@trade","data":{"e":"trade","E":1783465200176,"s":"ETHUSDT","t":4197008444,"p":"1775.55000000","q":"0.09710000","T":1783465200176,"m":true,"M":true}}
{"stream":"ethusdt@trade","data":{"e":"trade","E":1783465200176,"s":"ETHUSDT","t":4197008445,"p":"1775.55000000","q":"0.09710000","T":1783465200176,"m":true,"M":true}}
{"stream":"ethusdt@trade","data":{"e":"trade","E":1783465200176,"s":"ETHUSDT","t":4197008446,"p":"1775.55000000","q":"0.09710000","T":1783465200176,"m":true,"M":true}}
{"stream":"ethusdt@trade","data":{"e":"trade","E":1783465200176,"s":"ETHUSDT","t":4197008447,"p":"1775.55000000","q":"0.01680000","T":1783465200176,"m":true,"M":true}}
{"stream":"ethusdt@trade","data":{"e":"trade","E":1783465200177,"s":"ETHUSDT","t":4197008448,"p":"1775.55000000","q":"0.08040000","T":1783465200176,"m":true,"M":true}}
{"stream":"ethusdt@trade","data":{"e":"trade","E":1783465200177,"s":"ETHUSDT","t":4197008449,"p":"1775.55000000","q":"0.00290000","T":1783465200176,"m":true,"M":true}}
{"stream":"ethusdt@trade","data":{"e":"trade","E":1783465200177,"s":"ETHUSDT","t":4197008450,"p":"1775.55000000","q":"0.00290000","T":1783465200176,"m":true,"M":true}}
{"stream":"ethusdt@trade","data":{"e":"trade","E":1783465200177,"s":"ETHUSDT","t":4197008451,"p":"1775.55000000","q":"0.00290000","T":1783465200176,"m":true,"M":true}}
{"stream":"ethusdt@trade","data":{"e":"trade","E":1783465200177,"s":"ETHUSDT","t":4197008452,"p":"1775.55000000","q":"0.00300000","T":1783465200176,"m":true,"M":true}}
{"stream":"ethusdt@trade","data":{"e":"trade","E":1783465200177,"s":"ETHUSDT","t":4197008453,"p":"1775.55000000","q":"0.00570000","T":1783465200176,"m":true,"M":true}}
{"stream":"ethusdt@trade","data":{"e":"trade","E":1783465200177,"s":"ETHUSDT","t":4197008454,"p":"1775.55000000","q":"0.00290000","T":1783465200176,"m":true,"M":true}}
{"stream":"ethusdt@trade","data":{"e":"trade","E":1783465200177,"s":"ETHUSDT","t":4197008455,"p":"1775.55000000","q":"0.00290000","T":1783465200176,"m":true,"M":true}}
{"stream":"ethusdt@trade","data":{"e":"trade","E":1783465200177,"s":"ETHUSDT","t":4197008456,"p":"1775.55000000","q":"0.00290000","T":1783465200176,"m":true,"M":true}}
{"stream":"ethusdt@trade","data":{"e":"trade","E":1783465200177,"s":"ETHUSDT","t":4197008457,"p":"1775.55000000","q":"0.00290000","T":1783465200176,"m":true,"M":true}}
{"stream":"ethusdt@trade","data":{"e":"trade","E":1783465200177,"s":"ETHUSDT","t":4197008458,"p":"1775.55000000","q":"0.00290000","T":1783465200176,"m":true,"M":true}}
{"stream":"ethusdt@trade","data":{"e":"trade","E":1783465200177,"s":"ETHUSDT","t":4197008459,"p":"1775.55000000","q":"0.09710000","T":1783465200176,"m":true,"M":true}}
{"stream":"ethusdt@trade","data":{"e":"trade","E":1783465200177,"s":"ETHUSDT","t":4197008460,"p":"1775.55000000","q":"0.09710000","T":1783465200176,"m":true,"M":true}}
{"stream":"ethusdt@trade","data":{"e":"trade","E":1783465200177,"s":"ETHUSDT","t":4197008461,"p":"1775.55000000","q":"0.09350000","T":1783465200176,"m":true,"M":true}}
{"stream":"ethusdt@trade","data":{"e":"trade","E":1783465200177,"s":"ETHUSDT","t":4197008462,"p":"1775.55000000","q":"0.00360000","T":1783465200177,"m":true,"M":true}}
{"stream":"ethusdt@trade","data":{"e":"trade","E":1783465200177,"s":"ETHUSDT","t":4197008463,"p":"1775.55000000","q":"0.09710000","T":1783465200177,"m":true,"M":true}}
{"stream":"ethusdt@trade","data":{"e":"trade","E":1783465200177,"s":"ETHUSDT","t":4197008464,"p":"1775.55000000","q":"0.09720000","T":1783465200177,"m":true,"M":true}}
{"stream":"ethusdt@trade","data":{"e":"trade","E":1783465200177,"s":"ETHUSDT","t":4197008465,"p":"1775.55000000","q":"0.09710000","T":1783465200177,"m":true,"M":true}}
{"stream":"ethusdt@trade","data":{"e":"trade","E":1783465200177,"s":"ETHUSDT","t":4197008466,"p":"1775.55000000","q":"0.09710000","T":1783465200177,"m":true,"M":true}}
{"stream":"ethusdt@trade","data":{"e":"trade","E":1783465200177,"s":"ETHUSDT","t":4197008467,"p":"1775.55000000","q":"0.00790000","T":1783465200177,"m":true,"M":true}}
{"stream":"ethusdt@trade","data":{"e":"trade","E":1783465200178,"s":"ETHUSDT","t":4197008468,"p":"1775.55000000","q":"0.08920000","T":1783465200178,"m":true,"M":true}}
{"stream":"ethusdt@trade","data":{"e":"trade","E":1783465200178,"s":"ETHUSDT","t":4197008469,"p":"1775.55000000","q":"0.09710000","T":1783465200178,"m":true,"M":true}}
{"stream":"ethusdt@trade","data":{"e":"trade","E":1783465200178,"s":"ETHUSDT","t":4197008470,"p":"1775.55000000","q":"0.09720000","T":1783465200178,"m":true,"M":true}}
{"stream":"ethusdt@trade","data":{"e":"trade","E":1783465200178,"s":"ETHUSDT","t":4197008471,"p":"1775.55000000","q":"0.09710000","T":1783465200178,"m":true,"M":true}}
{"stream":"ethusdt@trade","data":{"e":"trade","E":1783465200178,"s":"ETHUSDT","t":4197008472,"p":"1775.55000000","q":"0.09710000","T":1783465200178,"m":true,"M":true}}
{"stream":"ethusdt@trade","data":{"e":"trade","E":1783465200178,"s":"ETHUSDT","t":4197008473,"p":"1775.55000000","q":"0.00290000","T":1783465200178,"m":true,"M":true}}
{"stream":"ethusdt@trade","data":{"e":"trade","E":1783465200178,"s":"ETHUSDT","t":4197008474,"p":"1775.55000000","q":"0.00290000","T":1783465200178,"m":true,"M":true}}
{"stream":"ethusdt@trade","data":{"e":"trade","E":1783465200178,"s":"ETHUSDT","t":4197008475,"p":"1775.55000000","q":"0.00570000","T":1783465200178,"m":true,"M":true}}
{"stream":"ethusdt@trade","data":{"e":"trade","E":1783465200178,"s":"ETHUSDT","t":4197008476,"p":"1775.55000000","q":"0.09710000","T":1783465200178,"m":true,"M":true}}
{"stream":"ethusdt@trade","data":{"e":"trade","E":1783465200178,"s":"ETHUSDT","t":4197008477,"p":"1775.55000000","q":"0.03770000","T":1783465200178,"m":true,"M":true}}
{"stream":"ethusdt@trade","data":{"e":"trade","E":1783465200179,"s":"ETHUSDT","t":4197008478,"p":"1775.55000000","q":"0.05940000","T":1783465200179,"m":true,"M":true}}
{"stream":"ethusdt@trade","data":{"e":"trade","E":1783465200179,"s":"ETHUSDT","t":4197008479,"p":"1775.55000000","q":"0.09720000","T":1783465200179,"m":true,"M":true}}
{"stream":"ethusdt@trade","data":{"e":"trade","E":1783465200179,"s":"ETHUSDT","t":4197008480,"p":"1775.55000000","q":"0.09710000","T":1783465200179,"m":true,"M":true}}
{"stream":"ethusdt@trade","data":{"e":"trade","E":1783465200179,"s":"ETHUSDT","t":4197008481,"p":"1775.55000000","q":"0.09710000","T":1783465200179,"m":true,"M":true}}
{"stream":"ethusdt@trade","data":{"e":"trade","E":1783465200179,"s":"ETHUSDT","t":4197008482,"p":"1775.55000000","q":"0.09710000","T":1783465200179,"m":true,"M":true}}
{"stream":"ethusdt@trade","data":{"e":"trade","E":1783465200179,"s":"ETHUSDT","t":4197008483,"p":"1775.55000000","q":"0.00300000","T":1783465200179,"m":true,"M":true}}
{"stream":"ethusdt@trade","data":{"e":"trade","E":1783465200179,"s":"ETHUSDT","t":4197008484,"p":"1775.55000000","q":"0.00110000","T":1783465200179,"m":true,"M":true}}
{"stream":"ethusdt@trade","data":{"e":"trade","E":1783465200182,"s":"ETHUSDT","t":4197008485,"p":"1775.55000000","q":"0.00180000","T":1783465200181,"m":true,"M":true}}
{"stream":"ethusdt@trade","data":{"e":"trade","E":1783465200182,"s":"ETHUSDT","t":4197008486,"p":"1775.55000000","q":"0.00290000","T":1783465200181,"m":true,"M":true}}
{"stream":"ethusdt@trade","data":{"e":"trade","E":1783465200182,"s":"ETHUSDT","t":4197008487,"p":"1775.55000000","q":"0.00290000","T":1783465200181,"m":true,"M":true}}
{"stream":"ethusdt@trade","data":{"e":"trade","E":1783465200182,"s":"ETHUSDT","t":4197008488,"p":"1775.55000000","q":"0.00290000","T":1783465200181,"m":true,"M":true}}
{"stream":"ethusdt@trade","data":{"e":"trade","E":1783465200182,"s":"ETHUSDT","t":4197008489,"p":"1775.55000000","q":"0.09710000","T":1783465200181,"m":true,"M":true}}
{"stream":"ethusdt@trade","data":{"e":"trade","E":1783465200182,"s":"ETHUSDT","t":4197008490,"p":"1775.55000000","q":"0.09720000","T":1783465200181,"m":true,"M":true}}
{"stream":"ethusdt@trade","data":{"e":"trade","E":1783465200182,"s":"ETHUSDT","t":4197008491,"p":"1775.55000000","q":"0.09710000","T":1783465200181,"m":true,"M":true}}
{"stream":"ethusdt@trade","data":{"e":"trade","E":1783465200182,"s":"ETHUSDT","t":4197008492,"p":"1775.55000000","q":"0.09710000","T":1783465200181,"m":true,"M":true}}
{"stream":"ethusdt@trade","data":{"e":"trade","E":1783465200182,"s":"ETHUSDT","t":4197008493,"p":"1775.55000000","q":"0.09710000","T":1783465200181,"m":true,"M":true}}
{"stream":"ethusdt@trade","data":{"e":"trade","E":1783465200182,"s":"ETHUSDT","t":4197008494,"p":"1775.55000000","q":"0.00570000","T":1783465200181,"m":true,"M":true}}
{"stream":"ethusdt@trade","data":{"e":"trade","E":1783465200182,"s":"ETHUSDT","t":4197008495,"p":"1775.55000000","q":"0.00290000","T":1783465200181,"m":true,"M":true}}
{"stream":"ethusdt@trade","data":{"e":"trade","E":1783465200182,"s":"ETHUSDT","t":4197008496,"p":"1775.55000000","q":"0.00300000","T":1783465200181,"m":true,"M":true}}
{"stream":"ethusdt@trade","data":{"e":"trade","E":1783465200182,"s":"ETHUSDT","t":4197008497,"p":"1775.55000000","q":"0.01630000","T":1783465200181,"m":true,"M":true}}
{"stream":"ethusdt@trade","data":{"e":"trade","E":1783465200187,"s":"ETHUSDT","t":4197008498,"p":"1775.55000000","q":"0.08080000","T":1783465200187,"m":true,"M":true}}
{"stream":"ethusdt@trade","data":{"e":"trade","E":1783465200187,"s":"ETHUSDT","t":4197008499,"p":"1775.55000000","q":"0.09720000","T":1783465200187,"m":true,"M":true}}
{"stream":"ethusdt@trade","data":{"e":"trade","E":1783465200187,"s":"ETHUSDT","t":4197008500,"p":"1775.55000000","q":"0.09710000","T":1783465200187,"m":true,"M":true}}
{"stream":"ethusdt@trade","data":{"e":"trade","E":1783465200187,"s":"ETHUSDT","t":4197008501,"p":"1775.55000000","q":"0.09710000","T":1783465200187,"m":true,"M":true}}
{"stream":"ethusdt@trade","data":{"e":"trade","E":1783465200187,"s":"ETHUSDT","t":4197008502,"p":"1775.55000000","q":"0.09710000","T":1783465200187,"m":true,"M":true}}
{"stream":"ethusdt@trade","data":{"e":"trade","E":1783465200187,"s":"ETHUSDT","t":4197008503,"p":"1775.55000000","q":"0.00290000","T":1783465200187,"m":true,"M":true}}
{"stream":"ethusdt@trade","data":{"e":"trade","E":1783465200187,"s":"ETHUSDT","t":4197008504,"p":"1775.55000000","q":"0.00570000","T":1783465200187,"m":true,"M":true}}
{"stream":"ethusdt@trade","data":{"e":"trade","E":1783465200187,"s":"ETHUSDT","t":4197008505,"p":"1775.55000000","q":"0.00290000","T":1783465200187,"m":true,"M":true}}
{"stream":"ethusdt@trade","data":{"e":"trade","E":1783465200187,"s":"ETHUSDT","t":4197008506,"p":"1775.55000000","q":"0.00300000","T":1783465200187,"m":true,"M":true}}
{"stream":"ethusdt@trade","data":{"e":"trade","E":1783465200187,"s":"ETHUSDT","t":4197008507,"p":"1775.55000000","q":"0.00290000","T":1783465200187,"m":true,"M":true}}
{"stream":"ethusdt@trade","data":{"e":"trade","E":1783465200187,"s":"ETHUSDT","t":4197008508,"p":"1775.55000000","q":"0.00290000","T":1783465200187,"m":true,"M":true}}
{"stream":"ethusdt@trade","data":{"e":"trade","E":1783465200187,"s":"ETHUSDT","t":4197008509,"p":"1775.55000000","q":"0.00290000","T":1783465200187,"m":true,"M":true}}
{"stream":"ethusdt@trade","data":{"e":"trade","E":1783465200187,"s":"ETHUSDT","t":4197008510,"p":"1775.55000000","q":"0.09710000","T":1783465200187,"m":true,"M":true}}
{"stream":"ethusdt@trade","data":{"e":"trade","E":1783465200187,"s":"ETHUSDT","t":4197008511,"p":"1775.55000000","q":"0.07940000","T":1783465200187,"m":true,"M":true}}
{"stream":"ethusdt@trade","data":{"e":"trade","E":1783465200191,"s":"ETHUSDT","t":4197008512,"p":"1775.55000000","q":"0.01780000","T":1783465200191,"m":true,"M":true}}
{"stream":"ethusdt@trade","data":{"e":"trade","E":1783465200191,"s":"ETHUSDT","t":4197008513,"p":"1775.55000000","q":"0.09710000","T":1783465200191,"m":true,"M":true}}
{"stream":"ethusdt@trade","data":{"e":"trade","E":1783465200191,"s":"ETHUSDT","t":4197008514,"p":"1775.55000000","q":"0.09710000","T":1783465200191,"m":true,"M":true}}
{"stream":"ethusdt@trade","data":{"e":"trade","E":1783465200191,"s":"ETHUSDT","t":4197008515,"p":"1775.55000000","q":"0.09710000","T":1783465200191,"m":true,"M":true}}
{"stream":"ethusdt@trade","data":{"e":"trade","E":1783465200191,"s":"ETHUSDT","t":4197008516,"p":"1775.55000000","q":"0.09710000","T":1783465200191,"m":true,"M":true}}
{"stream":"ethusdt@trade","data":{"e":"trade","E":1783465200191,"s":"ETHUSDT","t":4197008517,"p":"1775.55000000","q":"0.00290000","T":1783465200191,"m":true,"M":true}}
{"stream":"ethusdt@trade","data":{"e":"trade","E":1783465200191,"s":"ETHUSDT","t":4197008518,"p":"1775.55000000","q":"0.00290000","T":1783465200191,"m":true,"M":true}}
{"stream":"ethusdt@trade","data":{"e":"trade","E":1783465200191,"s":"ETHUSDT","t":4197008519,"p":"1775.55000000","q":"0.00300000","T":1783465200191,"m":true,"M":true}}
{"stream":"ethusdt@trade","data":{"e":"trade","E":1783465200191,"s":"ETHUSDT","t":4197008520,"p":"1775.55000000","q":"0.00290000","T":1783465200191,"m":true,"M":true}}
{"stream":"ethusdt@trade","data":{"e":"trade","E":1783465200191,"s":"ETHUSDT","t":4197008521,"p":"1775.55000000","q":"0.00570000","T":1783465200191,"m":true,"M":true}}
{"stream":"ethusdt@trade","data":{"e":"trade","E":1783465200191,"s":"ETHUSDT","t":4197008522,"p":"1775.55000000","q":"0.00290000","T":1783465200191,"m":true,"M":true}}
{"stream":"ethusdt@trade","data":{"e":"trade","E":1783465200191,"s":"ETHUSDT","t":4197008523,"p":"1775.55000000","q":"0.00290000","T":1783465200191,"m":true,"M":true}}
{"stream":"ethusdt@trade","data":{"e":"trade","E":1783465200191,"s":"ETHUSDT","t":4197008524,"p":"1775.55000000","q":"0.09720000","T":1783465200191,"m":true,"M":true}}
{"stream":"ethusdt@trade","data":{"e":"trade","E":1783465200191,"s":"ETHUSDT","t":4197008525,"p":"1775.55000000","q":"0.09710000","T":1783465200191,"m":true,"M":true}}
{"stream":"ethusdt@trade","data":{"e":"trade","E":1783465200191,"s":"ETHUSDT","t":4197008526,"p":"1775.55000000","q":"0.04530000","T":1783465200191,"m":true,"M":true}}
{"stream":"ethusdt@trade","data":{"e":"trade","E":1783465200208,"s":"ETHUSDT","t":4197008527,"p":"1775.55000000","q":"0.05180000","T":1783465200208,"m":true,"M":true}}
{"stream":"ethusdt@trade","data":{"e":"trade","E":1783465200208,"s":"ETHUSDT","t":4197008528,"p":"1775.55000000","q":"0.09710000","T":1783465200208,"m":true,"M":true}}
{"stream":"ethusdt@trade","data":{"e":"trade","E":1783465200208,"s":"ETHUSDT","t":4197008529,"p":"1775.55000000","q":"0.09710000","T":1783465200208,"m":true,"M":true}}
{"stream":"ethusdt@trade","data":{"e":"trade","E":1783465200208,"s":"ETHUSDT","t":4197008530,"p":"1775.55000000","q":"0.09720000","T":1783465200208,"m":true,"M":true}}
{"stream":"ethusdt@trade","data":{"e":"trade","E":1783465200208,"s":"ETHUSDT","t":4197008531,"p":"1775.55000000","q":"0.09710000","T":1783465200208,"m":true,"M":true}}
{"stream":"ethusdt@trade","data":{"e":"trade","E":1783465200208,"s":"ETHUSDT","t":4197008532,"p":"1775.55000000","q":"0.00290000","T":1783465200208,"m":true,"M":true}}
{"stream":"ethusdt@trade","data":{"e":"trade","E":1783465200208,"s":"ETHUSDT","t":4197008533,"p":"1775.55000000","q":"0.00290000","T":1783465200208,"m":true,"M":true}}
{"stream":"ethusdt@trade","data":{"e":"trade","E":1783465200208,"s":"ETHUSDT","t":4197008534,"p":"1775.55000000","q":"0.00290000","T":1783465200208,"m":true,"M":true}}
{"stream":"ethusdt@trade","data":{"e":"trade","E":1783465200208,"s":"ETHUSDT","t":4197008535,"p":"1775.55000000","q":"0.00290000","T":1783465200208,"m":true,"M":true}}
{"stream":"ethusdt@trade","data":{"e":"trade","E":1783465200208,"s":"ETHUSDT","t":4197008536,"p":"1775.55000000","q":"0.00570000","T":1783465200208,"m":true,"M":true}}
{"stream":"ethusdt@trade","data":{"e":"trade","E":1783465200208,"s":"ETHUSDT","t":4197008537,"p":"1775.55000000","q":"0.00300000","T":1783465200208,"m":true,"M":true}}
{"stream":"ethusdt@trade","data":{"e":"trade","E":1783465200208,"s":"ETHUSDT","t":4197008538,"p":"1775.55000000","q":"0.00290000","T":1783465200208,"m":true,"M":true}}
{"stream":"ethusdt@trade","data":{"e":"trade","E":1783465200208,"s":"ETHUSDT","t":4197008539,"p":"1775.55000000","q":"0.09710000","T":1783465200208,"m":true,"M":true}}
{"stream":"ethusdt@trade","data":{"e":"trade","E":1783465200208,"s":"ETHUSDT","t":4197008540,"p":"1775.55000000","q":"0.09710000","T":1783465200208,"m":true,"M":true}}
{"stream":"ethusdt@trade","data":{"e":"trade","E":1783465200208,"s":"ETHUSDT","t":4197008541,"p":"1775.55000000","q":"0.09710000","T":1783465200208,"m":true,"M":true}}
{"stream":"ethusdt@trade","data":{"e":"trade","E":1783465200208,"s":"ETHUSDT","t":4197008542,"p":"1775.55000000","q":"0.09720000","T":1783465200208,"m":true,"M":true}}
{"stream":"ethusdt@trade","data":{"e":"trade","E":1783465200208,"s":"ETHUSDT","t":4197008543,"p":"1775.55000000","q":"0.09710000","T":1783465200208,"m":true,"M":true}}
{"stream":"ethusdt@trade","data":{"e":"trade","E":1783465200208,"s":"ETHUSDT","t":4197008544,"p":"1775.55000000","q":"0.09710000","T":1783465200208,"m":true,"M":true}}
{"stream":"ethusdt@trade","data":{"e":"trade","E":1783465200208,"s":"ETHUSDT","t":4197008545,"p":"1775.55000000","q":"0.09710000","T":1783465200208,"m":true,"M":true}}
{"stream":"ethusdt@trade","data":{"e":"trade","E":1783465200208,"s":"ETHUSDT","t":4197008546,"p":"1775.55000000","q":"0.09710000","T":1783465200208,"m":true,"M":true}}
{"stream":"ethusdt@trade","data":{"e":"trade","E":1783465200208,"s":"ETHUSDT","t":4197008547,"p":"1775.55000000","q":"0.09720000","T":1783465200208,"m":true,"M":true}}
{"stream":"ethusdt@trade","data":{"e":"trade","E":1783465200208,"s":"ETHUSDT","t":4197008548,"p":"1775.55000000","q":"0.09710000","T":1783465200208,"m":true,"M":true}}
{"stream":"ethusdt@trade","data":{"e":"trade","E":1783465200208,"s":"ETHUSDT","t":4197008549,"p":"1775.55000000","q":"0.09710000","T":1783465200208,"m":true,"M":true}}
{"stream":"ethusdt@trade","data":{"e":"trade","E":1783465200208,"s":"ETHUSDT","t":4197008550,"p":"1775.55000000","q":"0.09710000","T":1783465200208,"m":true,"M":true}}
{"stream":"ethusdt@trade","data":{"e":"trade","E":1783465200208,"s":"ETHUSDT","t":4197008551,"p":"1775.55000000","q":"0.09710000","T":1783465200208,"m":true,"M":true}}
{"stream":"ethusdt@trade","data":{"e":"trade","E":1783465200208,"s":"ETHUSDT","t":4197008552,"p":"1775.55000000","q":"0.09720000","T":1783465200208,"m":true,"M":true}}
{"stream":"ethusdt@trade","data":{"e":"trade","E":1783465200208,"s":"ETHUSDT","t":4197008553,"p":"1775.55000000","q":"0.09710000","T":1783465200208,"m":true,"M":true}}
{"stream":"ethusdt@trade","data":{"e":"trade","E":1783465200208,"s":"ETHUSDT","t":4197008554,"p":"1775.55000000","q":"0.09710000","T":1783465200208,"m":true,"M":true}}
{"stream":"ethusdt@trade","data":{"e":"trade","E":1783465200208,"s":"ETHUSDT","t":4197008555,"p":"1775.55000000","q":"0.09710000","T":1783465200208,"m":true,"M":true}}
{"stream":"ethusdt@trade","data":{"e":"trade","E":1783465200208,"s":"ETHUSDT","t":4197008556,"p":"1775.55000000","q":"0.09710000","T":1783465200208,"m":true,"M":true}}
{"stream":"ethusdt@trade","data":{"e":"trade","E":1783465200208,"s":"ETHUSDT","t":4197008557,"p":"1775.55000000","q":"0.09720000","T":1783465200208,"m":true,"M":true}}
{"stream":"ethusdt@trade","data":{"e":"trade","E":1783465200208,"s":"ETHUSDT","t":4197008558,"p":"1775.55000000","q":"0.09710000","T":1783465200208,"m":true,"M":true}}
{"stream":"ethusdt@trade","data":{"e":"trade","E":1783465200208,"s":"ETHUSDT","t":4197008559,"p":"1775.55000000","q":"0.09710000","T":1783465200208,"m":true,"M":true}}
{"stream":"ethusdt@trade","data":{"e":"trade","E":1783465200208,"s":"ETHUSDT","t":4197008560,"p":"1775.55000000","q":"0.09710000","T":1783465200208,"m":true,"M":true}}
{"stream":"ethusdt@trade","data":{"e":"trade","E":1783465200208,"s":"ETHUSDT","t":4197008561,"p":"1775.55000000","q":"0.09710000","T":1783465200208,"m":true,"M":true}}
{"stream":"ethusdt@trade","data":{"e":"trade","E":1783465200208,"s":"ETHUSDT","t":4197008562,"p":"1775.55000000","q":"0.09720000","T":1783465200208,"m":true,"M":true}}
{"stream":"ethusdt@trade","data":{"e":"trade","E":1783465200208,"s":"ETHUSDT","t":4197008563,"p":"1775.55000000","q":"0.09710000","T":1783465200208,"m":true,"M":true}}
{"stream":"ethusdt@trade","data":{"e":"trade","E":1783465200208,"s":"ETHUSDT","t":4197008564,"p":"1775.55000000","q":"0.09710000","T":1783465200208,"m":true,"M":true}}
{"stream":"ethusdt@trade","data":{"e":"trade","E":1783465200208,"s":"ETHUSDT","t":4197008565,"p":"1775.55000000","q":"0.09710000","T":1783465200208,"m":true,"M":true}}
{"stream":"ethusdt@trade","data":{"e":"trade","E":1783465200208,"s":"ETHUSDT","t":4197008566,"p":"1775.55000000","q":"0.09710000","T":1783465200208,"m":true,"M":true}}
{"stream":"ethusdt@trade","data":{"e":"trade","E":1783465200208,"s":"ETHUSDT","t":4197008567,"p":"1775.55000000","q":"0.01720000","T":1783465200208,"m":true,"M":true}}
{"stream":"ethusdt@trade","data":{"e":"trade","E":1783465200209,"s":"ETHUSDT","t":4197008568,"p":"1775.55000000","q":"0.08000000","T":1783465200208,"m":true,"M":true}}
{"stream":"ethusdt@trade","data":{"e":"trade","E":1783465200209,"s":"ETHUSDT","t":4197008569,"p":"1775.55000000","q":"0.09710000","T":1783465200208,"m":true,"M":true}}
{"stream":"ethusdt@trade","data":{"e":"trade","E":1783465200209,"s":"ETHUSDT","t":4197008570,"p":"1775.55000000","q":"0.09710000","T":1783465200208,"m":true,"M":true}}
{"stream":"ethusdt@trade","data":{"e":"trade","E":1783465200209,"s":"ETHUSDT","t":4197008571,"p":"1775.55000000","q":"0.01290000","T":1783465200208,"m":true,"M":true}}
{"stream":"ethusdt@trade","data":{"e":"trade","E":1783465200209,"s":"ETHUSDT","t":4197008572,"p":"1775.55000000","q":"0.09710000","T":1783465200208,"m":true,"M":true}}
{"stream":"ethusdt@trade","data":{"e":"trade","E":1783465200209,"s":"ETHUSDT","t":4197008573,"p":"1775.55000000","q":"0.09720000","T":1783465200208,"m":true,"M":true}}
{"stream":"ethusdt@trade","data":{"e":"trade","E":1783465200209,"s":"ETHUSDT","t":4197008574,"p":"1775.55000000","q":"0.09710000","T":1783465200208,"m":true,"M":true}}
{"stream":"ethusdt@trade","data":{"e":"trade","E":1783465200209,"s":"ETHUSDT","t":4197008575,"p":"1775.55000000","q":"0.09710000","T":1783465200208,"m":true,"M":true}}
{"stream":"ethusdt@trade","data":{"e":"trade","E":1783465200209,"s":"ETHUSDT","t":4197008576,"p":"1775.55000000","q":"0.09710000","T":1783465200208,"m":true,"M":true}}
{"stream":"ethusdt@trade","data":{"e":"trade","E":1783465200209,"s":"ETHUSDT","t":4197008577,"p":"1775.55000000","q":"0.09720000","T":1783465200208,"m":true,"M":true}}
{"stream":"ethusdt@trade","data":{"e":"trade","E":1783465200209,"s":"ETHUSDT","t":4197008578,"p":"1775.55000000","q":"0.09710000","T":1783465200208,"m":true,"M":true}}
{"stream":"ethusdt@trade","data":{"e":"trade","E":1783465200209,"s":"ETHUSDT","t":4197008579,"p":"1775.55000000","q":"0.09710000","T":1783465200208,"m":true,"M":true}}
{"stream":"ethusdt@trade","data":{"e":"trade","E":1783465200209,"s":"ETHUSDT","t":4197008580,"p":"1775.55000000","q":"0.09710000","T":1783465200208,"m":true,"M":true}}
{"stream":"ethusdt@trade","data":{"e":"trade","E":1783465200209,"s":"ETHUSDT","t":4197008581,"p":"1775.55000000","q":"0.08580000","T":1783465200208,"m":true,"M":true}}
{"stream":"ethusdt@trade","data":{"e":"trade","E":1783465200209,"s":"ETHUSDT","t":4197008582,"p":"1775.55000000","q":"0.09710000","T":1783465200208,"m":true,"M":true}}
{"stream":"ethusdt@trade","data":{"e":"trade","E":1783465200209,"s":"ETHUSDT","t":4197008583,"p":"1775.55000000","q":"0.09710000","T":1783465200208,"m":true,"M":true}}
{"stream":"ethusdt@trade","data":{"e":"trade","E":1783465200209,"s":"ETHUSDT","t":4197008584,"p":"1775.55000000","q":"0.09710000","T":1783465200208,"m":true,"M":true}}
{"stream":"ethusdt@trade","data":{"e":"trade","E":1783465200209,"s":"ETHUSDT","t":4197008585,"p":"1775.55000000","q":"0.09710000","T":1783465200208,"m":true,"M":true}}
{"stream":"ethusdt@trade","data":{"e":"trade","E":1783465200209,"s":"ETHUSDT","t":4197008586,"p":"1775.55000000","q":"0.09710000","T":1783465200208,"m":true,"M":true}}
{"stream":"ethusdt@trade","data":{"e":"trade","E":1783465200209,"s":"ETHUSDT","t":4197008587,"p":"1775.55000000","q":"0.06860000","T":1783465200208,"m":true,"M":true}}
{"stream":"ethusdt@trade","data":{"e":"trade","E":1783465200209,"s":"ETHUSDT","t":4197008588,"p":"1775.55000000","q":"0.09710000","T":1783465200208,"m":true,"M":true}}
{"stream":"ethusdt@trade","data":{"e":"trade","E":1783465200209,"s":"ETHUSDT","t":4197008589,"p":"1775.55000000","q":"0.09710000","T":1783465200208,"m":true,"M":true}}
{"stream":"ethusdt@trade","data":{"e":"trade","E":1783465200209,"s":"ETHUSDT","t":4197008590,"p":"1775.55000000","q":"0.03780000","T":1783465200208,"m":true,"M":true}}
{"stream":"ethusdt@trade","data":{"e":"trade","E":1783465200209,"s":"ETHUSDT","t":4197008591,"p":"1775.55000000","q":"0.05240000","T":1783465200208,"m":true,"M":true}}
{"stream":"ethusdt@trade","data":{"e":"trade","E":1783465200209,"s":"ETHUSDT","t":4197008592,"p":"1775.54000000","q":"0.00300000","T":1783465200208,"m":true,"M":true}}
{"stream":"ethusdt@trade","data":{"e":"trade","E":1783465200209,"s":"ETHUSDT","t":4197008593,"p":"1775.54000000","q":"0.00570000","T":1783465200208,"m":true,"M":true}}
{"stream":"ethusdt@trade","data":{"e":"trade","E":1783465200209,"s":"ETHUSDT","t":4197008594,"p":"1775.54000000","q":"0.00290000","T":1783465200208,"m":true,"M":true}}
{"stream":"ethusdt@trade","data":{"e":"trade","E":1783465200209,"s":"ETHUSDT","t":4197008595,"p":"1775.54000000","q":"0.00290000","T":1783465200208,"m":true,"M":true}}
{"stream":"ethusdt@trade","data":{"e":"trade","E":1783465200209,"s":"ETHUSDT","t":4197008596,"p":"1775.54000000","q":"0.00290000","T":1783465200208,"m":true,"M":true}}
{"stream":"ethusdt@trade","data":{"e":"trade","E":1783465200209,"s":"ETHUSDT","t":4197008597,"p":"1775.54000000","q":"0.00290000","T":1783465200208,"m":true,"M":true}}
{"stream":"ethusdt@trade","data":{"e":"trade","E":1783465200209,"s":"ETHUSDT","t":4197008598,"p":"1775.54000000","q":"0.00300000","T":1783465200208,"m":true,"M":true}}
{"stream":"ethusdt@trade","data":{"e":"trade","E":1783465200209,"s":"ETHUSDT","t":4197008599,"p":"1775.54000000","q":"0.00300000","T":1783465200208,"m":true,"M":true}}
{"stream":"ethusdt@trade","data":{"e":"trade","E":1783465200209,"s":"ETHUSDT","t":4197008600,"p":"1775.54000000","q":"0.00300000","T":1783465200208,"m":true,"M":true}}
{"stream":"ethusdt@trade","data":{"e":"trade","E":1783465200209,"s":"ETHUSDT","t":4197008601,"p":"1775.53000000","q":"0.00300000","T":1783465200208,"m":true,"M":true}}
{"stream":"ethusdt@trade","data":{"e":"trade","E":1783465200209,"s":"ETHUSDT","t":4197008602,"p":"1775.53000000","q":"0.00290000","T":1783465200208,"m":true,"M":true}}
{"stream":"ethusdt@trade","data":{"e":"trade","E":1783465200209,"s":"ETHUSDT","t":4197008603,"p":"1775.53000000","q":"0.00570000","T":1783465200208,"m":true,"M":true}}
{"stream":"ethusdt@trade","data":{"e":"trade","E":1783465200209,"s":"ETHUSDT","t":4197008604,"p":"1775.52000000","q":"0.00290000","T":1783465200208,"m":true,"M":true}}
{"stream":"ethusdt@trade","data":{"e":"trade","E":1783465200209,"s":"ETHUSDT","t":4197008605,"p":"1775.52000000","q":"0.00300000","T":1783465200208,"m":true,"M":true}}
{"stream":"ethusdt@trade","data":{"e":"trade","E":1783465200209,"s":"ETHUSDT","t":4197008606,"p":"1775.52000000","q":"0.00300000","T":1783465200208,"m":true,"M":true}}
{"stream":"ethusdt@trade","data":{"e":"trade","E":1783465200209,"s":"ETHUSDT","t":4197008607,"p":"1775.52000000","q":"0.00300000","T":1783465200208,"m":true,"M":true}}
{"stream":"ethusdt@trade","data":{"e":"trade","E":1783465200209,"s":"ETHUSDT","t":4197008608,"p":"1775.52000000","q":"0.00300000","T":1783465200208,"m":true,"M":true}}
{"stream":"ethusdt@trade","data":{"e":"trade","E":1783465200209,"s":"ETHUSDT","t":4197008609,"p":"1775.51000000","q":"0.00300000","T":1783465200208,"m":true,"M":true}}
{"stream":"ethusdt@trade","data":{"e":"trade","E":1783465200209,"s":"ETHUSDT","t":4197008610,"p":"1775.51000000","q":"3.05570000","T":1783465200208,"m":true,"M":true}}
{"stream":"ethusdt@trade","data":{"e":"trade","E":1783465200209,"s":"ETHUSDT","t":4197008611,"p":"1775.51000000","q":"3.50000000","T":1783465200208,"m":true,"M":true}}
{"stream":"ethusdt@trade","data":{"e":"trade","E":1783465200209,"s":"ETHUSDT","t":4197008612,"p":"1775.51000000","q":"0.20760000","T":1783465200208,"m":true,"M":true}}
{"stream":"ethusdt@trade","data":{"e":"trade","E":1783465200209,"s":"ETHUSDT","t":4197008613,"p":"1775.50000000","q":"0.02810000","T":1783465200208,"m":true,"M":true}}
{"stream":"ethusdt@trade","data":{"e":"trade","E":1783465200209,"s":"ETHUSDT","t":4197008614,"p":"1775.50000000","q":"0.00300000","T":1783465200208,"m":true,"M":true}}
{"stream":"ethusdt@trade","data":{"e":"trade","E":1783465200209,"s":"ETHUSDT","t":4197008615,"p":"1775.49000000","q":"0.00300000","T":1783465200208,"m":true,"M":true}}
{"stream":"ethusdt@trade","data":{"e":"trade","E":1783465200209,"s":"ETHUSDT","t":4197008616,"p":"1775.48000000","q":"0.00290000","T":1783465200208,"m":true,"M":true}}
{"stream":"ethusdt@trade","data":{"e":"trade","E":1783465200209,"s":"ETHUSDT","t":4197008617,"p":"1775.48000000","q":"0.00300000","T":1783465200208,"m":true,"M":true}}
{"stream":"ethusdt@trade","data":{"e":"trade","E":1783465200209,"s":"ETHUSDT","t":4197008618,"p":"1775.47000000","q":"0.00300000","T":1783465200208,"m":true,"M":true}}
{"stream":"ethusdt@trade","data":{"e":"trade","E":1783465200209,"s":"ETHUSDT","t":4197008619,"p":"1775.47000000","q":"0.00300000","T":1783465200208,"m":true,"M":true}}
{"stream":"ethusdt@trade","data":{"e":"trade","E":1783465200209,"s":"ETHUSDT","t":4197008620,"p":"1775.47000000","q":"0.00300000","T":1783465200208,"m":true,"M":true}}
{"stream":"ethusdt@trade","data":{"e":"trade","E":1783465200209,"s":"ETHUSDT","t":4197008621,"p":"1775.47000000","q":"0.00300000","T":1783465200208,"m":true,"M":true}}
{"stream":"ethusdt@trade","data":{"e":"trade","E":1783465200209,"s":"ETHUSDT","t":4197008622,"p":"1775.46000000","q":"0.07260000","T":1783465200208,"m":true,"M":true}}
{"stream":"ethusdt@trade","data":{"e":"trade","E":1783465200209,"s":"ETHUSDT","t":4197008623,"p":"1775.46000000","q":"0.00300000","T":1783465200208,"m":true,"M":true}}
{"stream":"ethusdt@trade","data":{"e":"trade","E":1783465200209,"s":"ETHUSDT","t":4197008624,"p":"1775.46000000","q":"0.00300000","T":1783465200208,"m":true,"M":true}}
{"stream":"ethusdt@trade","data":{"e":"trade","E":1783465200209,"s":"ETHUSDT","t":4197008625,"p":"1775.46000000","q":"0.00300000","T":1783465200208,"m":true,"M":true}}
{"stream":"ethusdt@trade","data":{"e":"trade","E":1783465200209,"s":"ETHUSDT","t":4197008626,"p":"1775.46000000","q":"0.00300000","T":1783465200208,"m":true,"M":true}}
{"stream":"ethusdt@trade","data":{"e":"trade","E":1783465200209,"s":"ETHUSDT","t":4197008627,"p":"1775.45000000","q":"0.00300000","T":1783465200208,"m":true,"M":true}}
{"stream":"ethusdt@trade","data":{"e":"trade","E":1783465200209,"s":"ETHUSDT","t":4197008628,"p":"1775.45000000","q":"0.00300000","T":1783465200208,"m":true,"M":true}}
{"stream":"ethusdt@trade","data":{"e":"trade","E":1783465200209,"s":"ETHUSDT","t":4197008629,"p":"1775.45000000","q":"0.00300000","T":1783465200208,"m":true,"M":true}}
{"stream":"ethusdt@trade","data":{"e":"trade","E":1783465200209,"s":"ETHUSDT","t":4197008630,"p":"1775.44000000","q":"0.00290000","T":1783465200208,"m":true,"M":true}}
{"stream":"ethusdt@trade","data":{"e":"trade","E":1783465200209,"s":"ETHUSDT","t":4197008631,"p":"1775.44000000","q":"1.40430000","T":1783465200208,"m":true,"M":true}}
{"stream":"ethusdt@trade","data":{"e":"trade","E":1783465200209,"s":"ETHUSDT","t":4197008632,"p":"1775.43000000","q":"0.00400000","T":1783465200208,"m":true,"M":true}}
{"stream":"ethusdt@trade","data":{"e":"trade","E":1783465200209,"s":"ETHUSDT","t":4197008633,"p":"1775.43000000","q":"0.00290000","T":1783465200208,"m":true,"M":true}}
{"stream":"ethusdt@trade","data":{"e":"trade","E":1783465200209,"s":"ETHUSDT","t":4197008634,"p":"1775.43000000","q":"0.14090000","T":1783465200208,"m":true,"M":true}}
{"stream":"ethusdt@trade","data":{"e":"trade","E":1783465200209,"s":"ETHUSDT","t":4197008635,"p":"1775.39000000","q":"0.00290000","T":1783465200208,"m":true,"M":true}}
{"stream":"ethusdt@trade","data":{"e":"trade","E":1783465200209,"s":"ETHUSDT","t":4197008636,"p":"1775.36000000","q":"0.00290000","T":1783465200208,"m":true,"M":true}}
{"stream":"ethusdt@trade","data":{"e":"trade","E":1783465200209,"s":"ETHUSDT","t":4197008637,"p":"1775.35000000","q":"0.00430000","T":1783465200208,"m":true,"M":true}}
{"stream":"ethusdt@trade","data":{"e":"trade","E":1783465200209,"s":"ETHUSDT","t":4197008638,"p":"1775.35000000","q":"0.00290000","T":1783465200208,"m":true,"M":true}}
{"stream":"ethusdt@trade","data":{"e":"trade","E":1783465200209,"s":"ETHUSDT","t":4197008639,"p":"1775.34000000","q":"0.00400000","T":1783465200208,"m":true,"M":true}}
{"stream":"ethusdt@trade","data":{"e":"trade","E":1783465200209,"s":"ETHUSDT","t":4197008640,"p":"1775.33000000","q":"0.14000000","T":1783465200208,"m":true,"M":true}}
{"stream":"ethusdt@trade","data":{"e":"trade","E":1783465200209,"s":"ETHUSDT","t":4197008641,"p":"1775.32000000","q":"0.14000000","T":1783465200208,"m":true,"M":true}}
{"stream":"ethusdt@trade","data":{"e":"trade","E":1783465200209,"s":"ETHUSDT","t":4197008642,"p":"1775.32000000","q":"0.14000000","T":1783465200208,"m":true,"M":true}}
{"stream":"ethusdt@trade","data":{"e":"trade","E":1783465200209,"s":"ETHUSDT","t":4197008643,"p":"1775.32000000","q":"0.14000000","T":1783465200208,"m":true,"M":true}}
