{"stream":"ethusdt@depth@100ms","data":{"e":"depthUpdate","E":1783465201715,"s":"ETHUSDT","U":78545073693,"u":78545074150,"b":[["1775.15000000","57.26060000"],["1775.14000000","0.44270000"],["1775.13000000","0.01170000"],["1775.12000000","37.10420000"],["1775.11000000","34.27750000"],["1775.10000000","0.10900000"],["1775.09000000","2.41190000"],["1775.08000000","0.44000000"],["1775.07000000","0.01330000"],["1775.06000000","0.00300000"],["1775.05000000","0.44000000"],["1775.04000000","0.03880000"],["1775.03000000","0.00000000"],["1775.02000000","0.44830000"],["1775.01000000","0.00620000"],["1775.00000000","10.82990000"],["1774.97000000","0.14000000"],["1774.96000000","0.47280000"],["1774.95000000","2.75280000"],["1774.93000000","2.76980000"],["1774.90000000","7.83130000"],["1774.89000000","24.60400000"],["1774.88000000","0.42040000"],["1774.87000000","26.28150000"],["1774.79000000","15.16260000"],["1774.75000000","1.33490000"],["1774.44000000","21.76580000"],["1774.42000000","0.00580000"],["1774.38000000","0.00000000"],["1774.33000000","1.35460000"],["1774.27000000","0.84420000"],["1774.24000000","10.23460000"],["1773.92000000","0.00290000"],["1773.88000000","4.47300000"],["1773.84000000","9.46180000"],["1773.76000000","0.44280000"],["1773.42000000","0.43700000"],["1773.38000000","0.43700000"],["1773.20000000","0.43990000"],["1773.18000000","0.44440000"],["1773.13000000","0.00000000"],["1773.12000000","7.88480000"],["1772.89000000","0.00000000"],["1772.88000000","4.33250000"],["1772.86000000","0.00000000"],["1772.85000000","0.56370000"],["1772.82000000","2.46660000"],["1772.79000000","0.00000000"],["1772.39000000","2.47790000"],["1771.90000000","0.01410000"],["1771.40000000","1.35240000"],["1770.90000000","0.00370000"],["1770.41000000","0.00290000"],["1770.09000000","0.06060000"],["1766.09000000","0.00000000"],["1765.91000000","0.00000000"],["1597.59000000","0.52200000"]],"a":[["1775.10000000","0.00000000"],["1775.11000000","0.00000000"],["1775.12000000","0.00000000"],["1775.15000000","0.00000000"],["1775.16000000","1.26670000"],["1775.17000000","0.00000000"],["1775.19000000","0.00600000"],["1775.20000000","0.00890000"],["1775.21000000","0.56080000"],["1775.22000000","0.00600000"],["1775.23000000","0.20000000"],["1775.27000000","0.00000000"],["1775.28000000","0.00580000"],["1775.29000000","1.16050000"],["1775.33000000","0.00000000"],["1775.34000000","0.00740000"],["1775.35000000","4.38210000"],["1775.36000000","1.43720000"],["1775.37000000","0.00000000"],["1775.40000000","0.00000000"],["1775.41000000","0.00290000"],["1775.42000000","3.32560000"],["1775.43000000","0.00740000"],["1775.44000000","1.46090000"],["1775.46000000","1.36190000"],["1775.49000000","1.36280000"],["1775.50000000","0.46200000"],["1775.51000000","0.43700000"],["1775.54000000","0.01030000"],["1775.55000000","24.59080000"],["1775.56000000","0.00580000"],["1775.58000000","0.10000000"],["1775.61000000","0.17470000"],["1775.62000000","0.43700000"],["1775.64000000","0.43700000"],["1775.69000000","33.12490000"],["1775.70000000","15.63410000"],["1775.71000000","0.28150000"],["1775.73000000","0.11270000"],["1775.74000000","15.02260000"],["1775.75000000","0.68140000"],["1775.79000000","0.44440000"],["1775.88000000","8.62580000"],["1775.90000000","0.44130000"],["1775.91000000","0.35000000"],["1775.93000000","0.00000000"],["1775.95000000","0.29960000"],["1776.00000000","15.05160000"],["1776.20000000","15.31270000"],["1776.40000000","1.23400000"],["1776.48000000","0.03890000"],["1776.56000000","2.84630000"],["1776.63000000","0.00290000"],["1776.69000000","0.00400000"],["1776.84000000","2.82170000"],["1776.96000000","38.12640000"],["1777.01000000","0.00000000"],["1777.02000000","0.76190000"],["1777.03000000","0.14350000"],["1777.06000000","7.88190000"],["1777.08000000","0.00290000"],["1777.10000000","9.46420000"],["1777.15000000","6.99770000"],["1777.22000000","7.88690000"],["1777.40000000","24.79070000"],["1777.62000000","7.88690000"],["1777.64000000","0.00000000"],["1777.78000000","0.00000000"],["1777.81000000","15.02090000"],["1778.34000000","1.12040000"]]}}
{"stream":"btcusdt@trade","data":{"e":"trade","E":1783465201715,"s":"BTCUSDT","t":6486990000,"p":"63542.01000000","q":"0.00008000","T":1783465201714,"m":false,"M":true}}
{"stream":"btcusdt@trade","data":{"e":"trade","E":1783465201715,"s":"BTCUSDT","t":6486990001,"p":"63542.01000000","q":"0.00002000","T":1783465201714,"m":false,"M":true}}
{"stream":"btcusdt@depth@100ms","data":{"e":"depthUpdate","E":1783465201814,"s":"BTCUSDT","U":97109092442,"u":97109092666,"b":[["63542.00000000","1.99279000"],["63541.99000000","0.00061000"],["63541.17000000","0.00400000"],["63540.95000000","0.00026000"],["63540.79000000","0.00018000"],["63540.78000000","0.06673000"],["63540.01000000","0.00018000"],["63540.00000000","0.03818000"],["63539.91000000","0.00018000"],["63539.90000000","0.06583000"],["63539.14000000","0.00009000"],["63538.87000000","0.00009000"],["63538.86000000","0.07546000"],["63538.00000000","0.02800000"],["63537.43000000","0.02124000"],["63537.38000000","0.00000000"],["63536.75000000","0.06046000"],["63536.00000000","0.02800000"],["63535.70000000","0.06587000"],["63535.49000000","0.06549000"],["63535.48000000","1.73043000"],["63535.47000000","0.42501000"],["63535.46000000","0.00000000"],["63535.45000000","0.50170000"],["63534.62000000","0.00000000"],["63533.60000000","0.00000000"],["63532.55000000","0.00000000"],["63532.37000000","1.46499000"],["63531.94000000","0.70840000"],["63531.77000000","0.03057000"],["63528.17000000","0.00000000"],["63526.40000000","0.00255000"],["63516.11000000","0.00000000"],["63515.73000000","0.00000000"],["63507.31000000","0.00000000"],["63490.51000000","0.31497000"],["63482.57000000","0.00000000"],["62597.75000000","0.00000000"],["57187.80000000","0.00440000"]],"a":[["63542.01000000","1.18524000"],["63542.11000000","0.00000000"],["63542.13000000","0.00008000"],["63542.14000000","0.00000000"],["63542.15000000","0.00000000"],["63542.97000000","0.00000000"],["63543.54000000","0.00000000"],["63543.77000000","0.00000000"],["63544.21000000","0.00000000"],["63544.43000000","0.00018000"],["63544.44000000","0.02169000"],["63544.45000000","0.00034000"],["63544.83000000","0.00008000"],["63545.18000000","0.00018000"],["63545.19000000","0.06803000"],["63545.34000000","0.00344000"],["63545.94000000","0.00000000"],["63545.99000000","0.00018000"],["63546.00000000","0.03000000"],["63547.31000000","0.00018000"],["63547.32000000","0.02718000"],["63547.53000000","0.00000000"],["63547.57000000","0.00018000"],["63547.58000000","0.09888000"],["63547.90000000","0.00000000"],["63547.91000000","0.03018000"],["63547.93000000","0.02518000"],["63547.95000000","0.02818000"],["63548.27000000","0.06549000"],["63548.28000000","0.02318000"],["63548.36000000","0.45468000"],["63548.37000000","0.27023000"],["63549.11000000","0.06549000"],["63549.13000000","0.43385000"],["63550.37000000","0.00032000"],["63551.36000000","0.00000000"],["63552.60000000","0.12000000"],["63553.16000000","0.00000000"],["63554.50000000","0.21676000"],["63554.57000000","0.09332000"],["63557.15000000","0.59053000"],["63557.66000000","1.22114000"],["63557.97000000","0.45627000"],["63559.70000000","0.15305000"],["63561.99000000","0.78734000"],["63562.05000000","0.00000000"],["63565.38000000","2.03712000"],["63566.83000000","0.02300000"],["63567.52000000","0.02000000"],["63569.99000000","0.02600000"],["63570.36000000","0.02200000"],["63570.66000000","0.02600000"],["63572.58000000","0.00000000"],["63572.97000000","0.00400000"],["63573.04000000","0.39968000"],["63574.89000000","0.28787000"],["63576.15000000","0.00400000"],["63576.33000000","0.03058000"],["63589.04000000","0.00000000"],["63594.55000000","0.00000000"],["63595.07000000","0.00000000"],["63595.52000000","0.00010000"],["63601.44000000","0.00000000"],["63601.91000000","0.00000000"],["63602.64000000","0.13136000"],["63609.38000000","0.00000000"],["63609.57000000","0.00000000"],["63617.67000000","0.94482000"],["64504.30000000","0.00000000"],["69896.21000000","0.00008000"]]}}
{"stream":"ethusdt@depth@100ms","data":{"e":"depthUpdate","E":1783465201815,"s":"ETHUSDT","U":78545074151,"u":78545074332,"b":[["1775.15000000","57.91460000"],["1775.14000000","11.56750000"],["1775.13000000","24.60550000"],["1775.12000000","2.52530000"],["1775.11000000","9.68070000"],["1775.10000000","0.00300000"],["1775.09000000","2.51430000"],["1775.05000000","0.43700000"],["1775.04000000","0.03580000"],["1775.02000000","0.44540000"],["1775.01000000","3.37540000"],["1774.96000000","0.97280000"],["1774.95000000","4.08480000"],["1774.88000000","12.13080000"],["1774.86000000","0.56290000"],["1774.83000000","0.00000000"],["1774.80000000","13.88430000"],["1774.76000000","0.00290000"],["1774.73000000","0.00290000"],["1774.72000000","0.46990000"],["1774.61000000","20.32710000"],["1774.47000000","0.00000000"],["1774.33000000","0.64260000"],["1773.53000000","0.40960000"],["1773.49000000","14.21830000"],["1773.20000000","1.00360000"],["1772.85000000","0.00000000"],["1770.07000000","0.00290000"],["1769.99000000","0.06710000"],["1597.64000000","0.08230000"]],"a":[["1775.16000000","1.31970000"],["1775.19000000","0.00300000"],["1775.20000000","0.02330000"],["1775.21000000","0.00300000"],["1775.22000000","0.01190000"],["1775.23000000","0.20300000"],["1775.24000000","0.00300000"],["1775.25000000","0.00640000"],["1775.28000000","0.01480000"],["1775.29000000","1.08540000"],["1775.30000000","0.00580000"],["1775.31000000","0.00000000"],["1775.32000000","0.53750000"],["1775.33000000","11.27340000"],["1775.34000000","0.01340000"],["1775.35000000","0.58920000"],["1775.36000000","0.00720000"],["1775.38000000","0.00600000"],["1775.39000000","0.72000000"],["1775.40000000","0.00000000"],["1775.42000000","0.03260000"],["1775.43000000","0.90650000"],["1775.44000000","0.03290000"],["1775.46000000","0.86190000"],["1775.47000000","1.20000000"],["1775.49000000","0.43700000"],["1775.50000000","0.00000000"],["1775.52000000","0.04030000"],["1775.53000000","0.00290000"],["1775.54000000","0.01030000"],["1775.55000000","0.00000000"],["1775.58000000","0.38180000"],["1775.64000000","0.89900000"],["1775.68000000","18.62010000"],["1775.69000000","7.88690000"],["1775.70000000","0.01030000"],["1775.71000000","0.63150000"],["1775.73000000","15.88650000"],["1775.74000000","0.32200000"],["1775.75000000","3.80760000"],["1775.81000000","0.01980000"],["1775.91000000","0.00000000"],["1776.06000000","30.00930000"],["1776.14000000","0.00290000"],["1776.58000000","4.46120000"],["1776.64000000","0.03000000"],["1776.85000000","0.35000000"],["1777.09000000","10.16760000"],["1777.25000000","0.46200000"],["1777.31000000","0.31090000"],["1777.34000000","0.00860000"],["1777.45000000","0.00000000"],["1777.46000000","26.24770000"],["1777.63000000","0.00290000"],["1777.81000000","15.58460000"],["1780.02000000","0.05030000"],["1780.10000000","0.00000000"],["1780.78000000","0.89930000"]]}}
{"stream":"btcusdt@depth@100ms","data":{"e":"depthUpdate","E":1783465201914,"s":"BTCUSDT","U":97109092667,"u":97109092757,"b":[["63542.00000000","1.99516000"],["63541.99000000","0.00034000"],["63540.95000000","0.00008000"],["63539.90000000","0.06583000"],["63538.87000000","0.00000000"],["63537.08000000","0.00000000"],["63536.57000000","0.04035000"],["63535.49000000","0.56773000"],["63535.48000000","1.22840000"],["63535.45000000","0.50162000"],["63532.44000000","0.00000000"],["63532.18000000","0.00000000"],["63527.66000000","0.00000000"],["63518.02000000","0.00000000"],["63498.95000000","0.00000000"],["63484.81000000","0.00015000"],["63479.88000000","0.01133000"],["63465.75000000","0.00015000"],["57187.80000000","0.00440000"]],"a":[["63542.01000000","0.59128000"],["63544.44000000","0.02187000"],["63544.45000000","0.00016000"],["63545.19000000","0.06803000"],["63546.00000000","0.03018000"],["63547.95000000","0.02818000"],["63548.28000000","0.02300000"],["63548.65000000","0.00009000"],["63561.81000000","0.39968000"],["63568.01000000","0.00009000"],["63568.36000000","0.00000000"],["63573.04000000","0.00000000"],["63575.23000000","0.00000000"],["63594.29000000","0.00000000"],["63599.20000000","0.00015000"],["63611.69000000","0.00000000"],["63613.36000000","0.00000000"],["63637.32000000","0.00015000"],["63651.49000000","0.00000000"],["69896.21000000","0.00000000"]]}}
{"stream":"ethusdt@depth@100ms","data":{"e":"depthUpdate","E":1783465201915,"s":"ETHUSDT","U":78545074333,"u":78545074379,"b":[["1775.13000000","24.59950000"],["1775.12000000","0.05030000"],["1775.11000000","7.20570000"],["1775.09000000","2.40230000"],["1775.02000000","0.45140000"],["1774.99000000","1.77890000"],["1774.95000000","2.75280000"],["1774.84000000","6.72710000"],["1774.70000000","1.11030000"],["1774.56000000","0.92770000"],["1774.25000000","4.53720000"],["1773.66000000","27.92280000"],["1772.96000000","4.91320000"],["1597.64000000","0.11010000"]],"a":[["1775.29000000","1.09140000"],["1775.30000000","1.37210000"],["1775.31000000","0.00600000"],["1775.32000000","3.91260000"],["1775.34000000","0.00740000"],["1775.38000000","0.00000000"],["1775.42000000","0.02960000"],["1775.45000000","1.36630000"],["1775.59000000","0.95750000"],["1775.66000000","25.02480000"],["1775.67000000","7.42640000"],["1775.68000000","16.26280000"],["1775.73000000","16.79730000"],["1775.74000000","15.34460000"],["1775.86000000","18.01860000"],["1776.89000000","0.23420000"],["1777.31000000","0.00290000"],["1779.96000000","0.05950000"],["1780.02000000","0.04740000"]]}}
{"stream":"ethusdt@trade","data":{"e":"trade","E":1783465201957,"s":"ETHUSDT","t":4197008765,"p":"1775.15000000","q":"0.02670000","T":1783465201956,"m":true,"M":true}}
{"stream":"ethusdt@trade","data":{"e":"trade","E":1783465201963,"s":"ETHUSDT","t":4197008766,"p":"1775.15000000","q":"0.00690000","T":1783465201963,"m":true,"M":true}}
{"stream":"btcusdt@trade","data":{"e":"trade","E":1783465202050,"s":"BTCUSDT","t":6486990002,"p":"63542.01000000","q":"0.00006000","T":1783465202033,"m":false,"M":true}}
{"stream":"btcusdt@trade","data":{"e":"trade","E":1783465202050,"s":"BTCUSDT","t":6486990003,"p":"63542.01000000","q":"0.00008000","T":1783465202033,"m":false,"M":true}}
{"stream":"btcusdt@trade","data":{"e":"trade","E":1783465202050,"s":"BTCUSDT","t":6486990004,"p":"63542.01000000","q":"0.00350000","T":1783465202033,"m":false,"M":true}}
{"stream":"btcusdt@trade","data":{"e":"trade","E":1783465202050,"s":"BTCUSDT","t":6486990005,"p":"63542.01000000","q":"0.00009000","T":1783465202033,"m":false,"M":true}}
{"stream":"btcusdt@trade","data":{"e":"trade","E":1783465202050,"s":"BTCUSDT","t":6486990006,"p":"63542.01000000","q":"0.00150000","T":1783465202033,"m":false,"M":true}}
{"stream":"btcusdt@trade","data":{"e":"trade","E":1783465202050,"s":"BTCUSDT","t":6486990007,"p":"63542.01000000","q":"0.00008000","T":1783465202033,"m":false,"M":true}}
{"stream":"btcusdt@trade","data":{"e":"trade","E":1783465202050,"s":"BTCUSDT","t":6486990008,"p":"63542.01000000","q":"0.00016000","T":1783465202033,"m":false,"M":true}}
{"stream":"btcusdt@trade","data":{"e":"trade","E":1783465202050,"s":"BTCUSDT","t":6486990009,"p":"63542.01000000","q":"0.00008000","T":1783465202033,"m":false,"M":true}}
{"stream":"btcusdt@trade","data":{"e":"trade","E":1783465202050,"s":"BTCUSDT","t":6486990010,"p":"63542.01000000","q":"0.00070000","T":1783465202033,"m":false,"M":true}}
{"stream":"btcusdt@trade","data":{"e":"trade","E":1783465202050,"s":"BTCUSDT","t":6486990011,"p":"63542.01000000","q":"0.00008000","T":1783465202033,"m":false,"M":true}}
{"stream":"btcusdt@trade","data":{"e":"trade","E":1783465202050,"s":"BTCUSDT","t":6486990012,"p":"63542.01000000","q":"0.00047000","T":1783465202033,"m":false,"M":true}}
{"stream":"btcusdt@trade","data":{"e":"trade","E":1783465202050,"s":"BTCUSDT","t":6486990013,"p":"63542.01000000","q":"0.00786000","T":1783465202033,"m":false,"M":true}}
{"stream":"btcusdt@trade","data":{"e":"trade","E":1783465202050,"s":"BTCUSDT","t":6486990014,"p":"63542.01000000","q":"0.00048000","T":1783465202033,"m":false,"M":true}}
{"stream":"btcusdt@trade","data":{"e":"trade","E":1783465202050,"s":"BTCUSDT","t":6486990015,"p":"63542.01000000","q":"0.02046000","T":1783465202033,"m":false,"M":true}}
{"stream":"btcusdt@depth@100ms","data":{"e":"depthUpdate","E":1783465202050,"s":"BTCUSDT","U":97109092758,"u":97109092799,"b":[["63542.00000000","1.98776000"],["63540.02000000","0.00787000"],["63522.94000000","0.00172000"],["63503.87000000","0.00015000"],["63475.31000000","0.00037000"],["63412.69000000","0.00000000"],["63412.01000000","0.00014000"],["63370.64000000","0.00987000"],["63362.47000000","0.00000000"],["57187.80000000","0.00440000"],["50833.60000000","0.00039000"]],"a":[["63545.19000000","0.06811000"],["63547.25000000","0.00018000"],["63547.26000000","0.06549000"],["63547.57000000","0.00000000"],["63549.48000000","0.00787000"],["63552.59000000","0.08574000"],["63554.50000000","0.00000000"],["63554.52000000","0.00000000"],["63555.61000000","0.59055000"],["63556.71000000","0.06549000"],["63557.14000000","0.14425000"],["63557.15000000","0.00000000"],["63557.38000000","0.00000000"],["63559.70000000","0.78736000"],["63561.07000000","0.00015000"],["63561.99000000","0.00000000"],["63567.42000000","0.03000000"],["63567.45000000","0.02500000"],["63570.65000000","0.02700000"],["63573.04000000","0.00000000"],["63576.05000000","0.00429000"],["63580.14000000","0.00024000"],["63584.32000000","0.00393000"],["63608.24000000","0.03000000"],["63647.99000000","0.00157000"]]}}
{"stream":"ethusdt@depth@100ms","data":{"e":"depthUpdate","E":1783465202050,"s":"ETHUSDT","U":78545074380,"u":78545074402,"b":[["1775.15000000","57.71120000"],["1775.05000000","0.71880000"],["1775.02000000","0.59140000"],["1774.90000000","7.84050000"],["1774.88000000","14.94910000"],["1774.75000000","1.33780000"],["1774.58000000","0.00290000"],["1773.66000000","28.06280000"],["1597.64000000","0.12410000"]],"a":[["1775.17000000","0.00290000"],["1775.28000000","0.01190000"],["1775.57000000","0.28180000"],["1775.58000000","0.10000000"],["1775.65000000","13.95180000"],["1775.66000000","25.72480000"],["1775.67000000","2.46340000"],["1775.74000000","18.16290000"],["1775.75000000","1.28340000"],["1776.94000000","0.29400000"],["1777.14000000","25.29820000"]]}}
{"stream":"btcusdt@depth@100ms","data":{"e":"depthUpdate","E":1783465202114,"s":"BTCUSDT","U":97109092800,"u":97109092875,"b":[["63540.77000000","0.12939000"],["63540.01000000","0.00000000"],["63539.92000000","0.00000000"],["63539.91000000","0.00000000"],["63535.05000000","0.00000000"],["63531.87000000","0.00000000"],["63528.69000000","0.00000000"],["63525.51000000","0.00000000"],["63511.09000000","0.00950000"],["63510.96000000","0.00000000"],["63494.38000000","0.94482000"],["63475.31000000","0.00037000"],["63471.57000000","0.00000000"],["63462.57000000","0.00030000"],["63412.01000000","0.00000000"],["62620.56000000","0.00000000"],["62588.87000000","0.00046000"],["57187.80000000","0.00450000"]],"a":[["63542.01000000","0.51726000"],["63544.44000000","0.00026000"],["63545.18000000","0.00000000"],["63545.19000000","0.00026000"],["63546.00000000","0.03018000"],["63547.26000000","0.06567000"],["63547.57000000","0.00009000"],["63547.95000000","0.02800000"],["63548.37000000","0.22500000"],["63549.35000000","0.00048000"],["63549.48000000","0.00000000"],["63549.77000000","0.00047000"],["63550.36000000","0.00787000"],["63551.55000000","0.00000000"],["63551.94000000","0.00252000"],["63552.59000000","0.05790000"],["63553.16000000","0.00000000"],["63553.17000000","0.03951000"],["63554.57000000","0.00008000"],["63555.61000000","0.00000000"],["63556.21000000","0.59055000"],["63568.31000000","0.02700000"],["63571.75000000","0.00000000"],["63573.04000000","0.13102000"],["63584.32000000","0.00000000"],["63602.64000000","0.00000000"],["63608.24000000","0.00000000"],["63610.58000000","0.13123000"],["63610.66000000","0.00000000"],["63647.99000000","0.00157000"],["64495.15000000","0.00030000"]]}}
{"stream":"ethusdt@depth@100ms","data":{"e":"depthUpdate","E":1783465202115,"s":"ETHUSDT","U":78545074403,"u":78545074421,"b":[["1775.12000000","0.19030000"],["1774.77000000","0.14000000"],["1774.72000000","1.03350000"],["1772.82000000","1.33940000"],["1767.07000000","0.00000000"],["1758.19000000","2.49340000"],["1749.31000000","0.00000000"],["1740.43000000","0.01890000"],["1731.55000000","15.41160000"],["1597.64000000","0.13110000"]],"a":[["1775.16000000","1.31970000"],["1775.17000000","0.00590000"],["1775.29000000","1.08840000"],["1775.64000000","1.24900000"],["1775.86000000","17.34660000"],["1775.95000000","0.00560000"],["1776.32000000","0.03000000"],["1776.64000000","0.00000000"],["1777.14000000","24.94820000"],["1777.21000000","8.23190000"],["1777.25000000","0.00000000"],["1784.83000000","0.00000000"],["1793.71000000","0.01670000"],["1802.59000000","0.00000000"],["1811.47000000","0.00810000"],["1820.35000000","0.00000000"]]}}
{"stream":"btcusdt@trade","data":{"e":"trade","E":1783465202175,"s":"BTCUSDT","t":6486990016,"p":"63542.01000000","q":"0.00008000","T":1783465202174,"m":false,"M":true}}
{"stream":"btcusdt@trade","data":{"e":"trade","E":1783465202175,"s":"BTCUSDT","t":6486990017,"p":"63542.01000000","q":"0.00029000","T":1783465202174,"m":false,"M":true}}
{"stream":"btcusdt@trade","data":{"e":"trade","E":1783465202175,"s":"BTCUSDT","t":6486990018,"p":"63542.01000000","q":"0.00052000","T":1783465202174,"m":false,"M":true}}
{"stream":"btcusdt@depth@100ms","data":{"e":"depthUpdate","E":1783465202214,"s":"BTCUSDT","U":97109092876,"u":97109092923,"b":[["63537.80000000","0.06102000"],["63536.79000000","0.05062000"],["63533.61000000","0.05063000"],["63530.43000000","0.03375000"],["63527.25000000","0.03375000"],["57187.80000000","0.00470000"],["50833.60000000","0.00020000"]],"a":[["63542.01000000","0.51671000"],["63543.15000000","0.02028000"],["63543.16000000","0.06276000"],["63544.43000000","0.00000000"],["63544.44000000","0.00008000"],["63545.19000000","0.00008000"],["63546.33000000","0.00018000"],["63546.34000000","0.06268000"],["63547.57000000","0.00000000"],["63547.90000000","0.00000000"],["63547.95000000","0.02818000"],["63549.52000000","0.04179000"],["63552.70000000","0.04179000"],["63571.57000000","0.00000000"],["63579.15000000","0.00434000"],["63579.37000000","0.00436000"],["63584.39000000","1.04673000"],["63596.47000000","0.07167000"],["63611.26000000","0.00000000"],["63611.35000000","0.00000000"],["63613.91000000","0.00000000"],["63614.20000000","0.00000000"],["63859.72000000","0.00078000"]]}}
{"stream":"ethusdt@depth@100ms","data":{"e":"depthUpdate","E":1783465202215,"s":"ETHUSDT","U":78545074422,"u":78545074427,"b":[["1597.64000000","0.14510000"]],"a":[["1777.46000000","25.92570000"],["1777.53000000","0.14080000"],["1777.55000000","0.15820000"],["1778.30000000","4.48370000"]]}}
{"stream":"btcusdt@trade","data":{"e":"trade","E":1783465202221,"s":"BTCUSDT","t":6486990019,"p":"63542.01000000","q":"0.00060000","T":1783465202221,"m":false,"M":true}}
{"stream":"btcusdt@depth@100ms","data":{"e":"depthUpdate","E":1783465202314,"s":"BTCUSDT","U":97109092924,"u":97109092950,"b":[["63533.01000000","0.00874000"],["63532.68000000","0.00958000"],["57187.80000000","0.00470000"],["50833.60000000","0.00040000"]],"a":[["63542.01000000","0.51629000"],["63542.94000000","0.00000000"],["63543.14000000","0.00018000"],["63543.15000000","0.02046000"],["63543.16000000","0.06294000"],["63546.00000000","0.03000000"],["63546.18000000","0.00029000"],["63547.31000000","0.00000000"],["63547.93000000","0.02500000"],["63547.95000000","0.02800000"],["63609.91000000","0.00000000"]]}}
{"stream":"ethusdt@depth@100ms","data":{"e":"depthUpdate","E":1783465202315,"s":"ETHUSDT","U":78545074428,"u":78545074445,"b":[["1775.08000000","0.71980000"],["1774.93000000","2.48640000"],["1774.87000000","26.14150000"],["1774.25000000","2.48340000"],["1771.62000000","0.00290000"],["1771.59000000","0.00290000"],["1597.64000000","0.17290000"]],"a":[["1775.30000000","1.37810000"],["1775.31000000","0.25500000"],["1775.32000000","3.90660000"],["1775.33000000","11.55160000"],["1775.93000000","0.41670000"],["1777.21000000","7.88190000"]]}}
{"stream":"btcusdt@depth@100ms","data":{"e":"depthUpdate","E":1783465202414,"s":"BTCUSDT","U":97109092951,"u":97109092974,"b":[["63532.44000000","0.00000000"],["63449.34000000","0.00000000"],["63441.64000000","0.00008000"],["63417.61000000","0.00000000"],["62970.12000000","0.00010000"],["58466.94000000","0.00018000"],["57187.80000000","0.00450000"],["40000.00000000","260.73952000"]],"a":[["63542.01000000","0.51639000"],["63544.09000000","0.00018000"],["63544.10000000","0.02360000"],["63547.25000000","0.00000000"],["63551.02000000","0.00000000"],["63553.42000000","0.00009000"],["63569.79000000","0.00400000"],["63576.15000000","0.00000000"]]}}
{"stream":"ethusdt@depth@100ms","data":{"e":"depthUpdate","E":1783465202415,"s":"ETHUSDT","U":78545074446,"u":78545074448,"b":[["1744.46000000","0.22840000"],["1597.64000000","0.18690000"]],"a":[]}}
{"stream":"btcusdt@trade","data":{"e":"trade","E":1783465202434,"s":"BTCUSDT","t":6486990020,"p":"63542.01000000","q":"0.00129000","T":1783465202434,"m":false,"M":true}}
{"stream":"btcusdt@depth@100ms","data":{"e":"depthUpdate","E":1783465202514,"s":"BTCUSDT","U":97109092975,"u":97109092992,"b":[["63527.98000000","0.00008000"],["63407.62000000","0.09462000"],["57187.80000000","0.00450000"]],"a":[["63542.01000000","0.51510000"],["63543.16000000","0.06294000"],["63544.10000000","0.02378000"],["63547.91000000","0.03000000"],["63553.41000000","0.00008000"],["63614.47000000","0.00000000"]]}}
{"stream":"ethusdt@depth@100ms","data":{"e":"depthUpdate","E":1783465202516,"s":"ETHUSDT","U":78545074449,"u":78545074461,"b":[["1775.03000000","0.14000000"],["1775.01000000","3.51540000"],["1774.80000000","13.88720000"],["1774.74000000","0.00290000"],["1597.64000000","0.20090000"]],"a":[["1775.46000000","0.85900000"],["1775.52000000","0.04320000"],["1775.71000000","0.92550000"],["1775.73000000","17.25930000"],["1775.75000000","1.96940000"],["1777.20000000","0.52380000"],["1777.41000000","27.71860000"]]}}
{"stream":"btcusdt@depth@100ms","data":{"e":"depthUpdate","E":1783465202614,"s":"BTCUSDT","U":97109092993,"u":97109093005,"b":[["63540.01000000","0.00018000"],["63539.91000000","0.00018000"],["63538.87000000","0.00009000"],["63494.39000000","0.31476000"],["63492.29000000","0.00000000"],["63490.51000000","0.00000000"],["63300.04000000","4.74264000"],["57187.80000000","0.00450000"]],"a":[]}}
{"stream":"ethusdt@depth@100ms","data":{"e":"depthUpdate","E":1783465202615,"s":"ETHUSDT","U":78545074462,"u":78545074499,"b":[["1775.15000000","55.31190000"],["1775.05000000","0.43700000"],["1775.02000000","0.87320000"],["1775.01000000","3.51840000"],["1774.88000000","12.13080000"],["1774.83000000","2.81840000"],["1774.79000000","15.02260000"],["1774.72000000","0.46990000"],["1774.41000000","17.55220000"],["1773.57000000","0.28290000"],["1769.35000000","0.88230000"],["1768.79000000","2.47500000"],["1597.64000000","0.21490000"]],"a":[["1775.16000000","7.80460000"],["1775.17000000","0.00300000"],["1775.20000000","0.02620000"],["1775.26000000","0.00600000"],["1775.27000000","4.35850000"],["1775.28000000","11.28560000"],["1775.30000000","1.37210000"],["1775.31000000","0.00000000"],["1775.32000000","0.53750000"],["1775.33000000","0.27820000"],["1775.36000000","0.01010000"],["1775.60000000","0.03580000"],["1777.20000000","0.22980000"],["1777.43000000","36.84960000"],["1779.92000000","0.00000000"],["1779.96000000","0.05660000"]]}}
{"stream":"ethusdt@trade","data":{"e":"trade","E":1783465202702,"s":"ETHUSDT","t":4197008767,"p":"1775.15000000","q":"0.33360000","T":1783465202702,"m":true,"M":true}}
{"stream":"btcusdt@depth@100ms","data":{"e":"depthUpdate","E":1783465202714,"s":"BTCUSDT","U":97109093006,"u":97109093016,"b":[["63535.49000000","0.88249000"],["63533.75000000","0.56702000"],["63494.39000000","0.00000000"],["57187.80000000","0.00450000"]],"a":[["63579.46000000","0.56661000"],["63609.59000000","0.03109000"],["63734.77000000","0.06310000"],["64064.18000000","0.00000000"]]}}
{"stream":"ethusdt@depth@100ms","data":{"e":"depthUpdate","E":1783465202715,"s":"ETHUSDT","U":78545074500,"u":78545074516,"b":[["1775.15000000","54.97830000"],["1774.78000000","1.31710000"],["1774.51000000","0.78300000"],["1768.44000000","142.04130000"],["1767.97000000","0.00000000"],["1597.64000000","0.22890000"]],"a":[["1775.25000000","0.00640000"],["1775.26000000","0.00900000"],["1775.28000000","11.28260000"],["1775.68000000","9.49710000"],["1776.47000000","0.28690000"],["1777.33000000","0.41930000"],["1777.35000000","0.14080000"],["1777.53000000","0.00000000"],["1777.55000000","0.01740000"],["1778.86000000","0.00000000"]]}}
{"stream":"btcusdt@depth@100ms","data":{"e":"depthUpdate","E":1783465202814,"s":"BTCUSDT","U":97109093017,"u":97109093022,"b":[["63542.00000000","1.98788000"],["57187.80000000","0.00470000"],["50000.00000000","542.70415000"]],"a":[["64509.99000000","0.01767000"],["64959.99000000","0.00000000"]]}}
{"stream":"ethusdt@depth@100ms","data":{"e":"depthUpdate","E":1783465202815,"s":"ETHUSDT","U":78545074517,"u":78545074531,"b":[["1775.12000000","0.33030000"],["1775.11000000","7.49430000"],["1775.10000000","0.14300000"],["1775.05000000","0.57700000"],["1775.02000000","1.01320000"],["1775.01000000","3.65840000"],["1774.81000000","0.00430000"],["1597.64000000","0.24970000"]],"a":[["1775.66000000","26.03280000"],["1775.72000000","13.83400000"],["1777.25000000","17.93600000"],["1777.27000000","8.19400000"],["1777.41000000","27.25660000"]]}}
