{"stream":"btcusdt@trade","data":{"e":"trade","E":1783465157897,"s":"BTCUSDT","t":6486989273,"p":"63551.02000000","q":"0.00317000","T":1783465157897,"m":true,"M":true}}
{"stream":"ethusdt@depth@100ms","data":{"e":"depthUpdate","E":1783465157917,"s":"ETHUSDT","U":78545066029,"u":78545066046,"b":[["1773.38000000","1.97860000"],["1598.04000000","0.24400000"]],"a":[["1775.60000000","8.54500000"],["1775.61000000","4.10540000"],["1775.62000000","0.62190000"],["1775.63000000","11.28330000"],["1775.65000000","0.00590000"],["1775.66000000","0.00300000"],["1777.54000000","11.32830000"]]}}
{"stream":"btcusdt@depth@100ms","data":{"e":"depthUpdate","E":1783465157917,"s":"BTCUSDT","U":97109082200,"u":97109082205,"b":[["63551.02000000","1.87857000"],["57195.92000000","0.00480000"]],"a":[]}}
{"stream":"btcusdt@depth@100ms","data":{"e":"depthUpdate","E":1783465158014,"s":"BTCUSDT","U":97109082206,"u":97109082242,"b":[["63551.02000000","1.87857000"],["63551.01000000","0.00323000"],["63549.22000000","0.04026000"],["63549.21000000","0.00018000"],["63548.01000000","0.00018000"],["63543.89000000","0.70840000"],["63540.33000000","0.00000000"],["63510.80000000","2.26261000"],["63484.01000000","0.00037000"],["63421.66000000","0.00000000"],["63421.06000000","0.00014000"],["62597.75000000","0.00030000"],["57195.92000000","0.00480000"],["57195.00000000","0.00087000"],["50840.82000000","0.00083000"]],"a":[["63593.99000000","0.00389000"],["63606.69000000","0.07009000"],["63655.99000000","0.00000000"],["63657.33000000","0.00157000"]]}}
{"stream":"ethusdt@depth@100ms","data":{"e":"depthUpdate","E":1783465158015,"s":"ETHUSDT","U":78545066047,"u":78545066056,"b":[["1775.46000000","0.35340000"],["1775.23000000","0.47630000"],["1775.21000000","2.81790000"],["1598.04000000","0.25080000"]],"a":[["1775.74000000","0.78780000"],["1775.91000000","0.38170000"],["1775.92000000","0.32690000"],["1776.08000000","3.13950000"],["1776.10000000","0.19030000"]]}}
{"stream":"ethusdt@depth@100ms","data":{"e":"depthUpdate","E":1783465158116,"s":"ETHUSDT","U":78545066057,"u":78545066060,"b":[["1598.04000000","0.25080000"]],"a":[]}}
{"stream":"btcusdt@depth@100ms","data":{"e":"depthUpdate","E":1783465158116,"s":"BTCUSDT","U":97109082243,"u":97109082260,"b":[["63551.02000000","1.87849000"],["63549.22000000","0.04026000"],["63549.21000000","0.00000000"],["63547.92000000","1.12839000"],["63484.01000000","0.00037000"],["63421.06000000","0.00014000"],["63396.22000000","4.49591000"],["57195.92000000","0.00500000"]],"a":[["63657.33000000","0.00157000"],["63708.43000000","6.36591000"]]}}
{"stream":"ethusdt@depth@100ms","data":{"e":"depthUpdate","E":1783465158216,"s":"ETHUSDT","U":78545066061,"u":78545066064,"b":[["1598.04000000","0.25080000"]],"a":[]}}
{"stream":"btcusdt@depth@100ms","data":{"e":"depthUpdate","E":1783465158216,"s":"BTCUSDT","U":97109082261,"u":97109082274,"b":[["63551.02000000","1.87927000"],["63528.12000000","0.00000000"],["63509.06000000","0.00000000"],["63410.11000000","0.00820000"],["63404.90000000","0.00000000"],["57195.92000000","0.00500000"],["50840.82000000","0.00044000"]],"a":[["63551.03000000","0.69747000"],["63558.46000000","0.00000000"],["63573.25000000","0.00000000"],["63592.32000000","0.00000000"]]}}
{"stream":"btcusdt@depth@100ms","data":{"e":"depthUpdate","E":1783465158315,"s":"BTCUSDT","U":97109082275,"u":97109082283,"b":[["63352.72000000","0.01874000"],["63277.78000000","0.00000000"],["58466.94000000","0.00000000"],["57195.92000000","0.00480000"]],"a":[["63551.03000000","0.69712000"],["63558.43000000","0.00048000"],["63580.25000000","0.00000000"]]}}
{"stream":"ethusdt@depth@100ms","data":{"e":"depthUpdate","E":1783465158315,"s":"ETHUSDT","U":78545066065,"u":78545066080,"b":[["1775.44000000","0.31460000"],["1775.40000000","1.76570000"],["1775.37000000","0.78100000"],["1775.32000000","0.99990000"],["1775.24000000","0.27550000"],["1598.04000000","0.23700000"],["1067.00000000","6.86000000"]],"a":[["1775.60000000","2.06300000"],["1775.91000000","0.10000000"],["1775.96000000","0.28460000"]]}}
{"stream":"ethusdt@depth@100ms","data":{"e":"depthUpdate","E":1783465158416,"s":"ETHUSDT","U":78545066081,"u":78545066085,"b":[["1598.04000000","0.25780000"]],"a":[]}}
{"stream":"btcusdt@depth@100ms","data":{"e":"depthUpdate","E":1783465158416,"s":"BTCUSDT","U":97109082284,"u":97109082291,"b":[["57195.92000000","0.00480000"],["50841.00000000","0.23623000"],["40000.00000000","260.73952000"]],"a":[]}}
{"stream":"btcusdt@depth@100ms","data":{"e":"depthUpdate","E":1783465158514,"s":"BTCUSDT","U":97109082292,"u":97109082303,"b":[["63529.20000000","0.55241000"],["63510.15000000","1.06124000"],["57195.92000000","0.00480000"],["50840.82000000","0.00044000"]],"a":[["63575.46000000","0.55442000"],["63594.54000000","1.07851000"]]}}
{"stream":"ethusdt@depth@100ms","data":{"e":"depthUpdate","E":1783465158515,"s":"ETHUSDT","U":78545066086,"u":78545066089,"b":[["1598.04000000","0.25780000"]],"a":[]}}
{"stream":"btcusdt@trade","data":{"e":"trade","E":1783465158576,"s":"BTCUSDT","t":6486989274,"p":"63551.02000000","q":"0.00023000","T":1783465158576,"m":true,"M":true}}
{"stream":"btcusdt@trade","data":{"e":"trade","E":1783465158577,"s":"BTCUSDT","t":6486989275,"p":"63551.03000000","q":"0.00023000","T":1783465158577,"m":false,"M":true}}
{"stream":"btcusdt@depth@100ms","data":{"e":"depthUpdate","E":1783465158614,"s":"BTCUSDT","U":97109082304,"u":97109082311,"b":[["63551.02000000","1.87904000"],["57195.92000000","0.00480000"]],"a":[["63551.03000000","0.69689000"],["64504.30000000","0.00030000"]]}}
{"stream":"ethusdt@depth@100ms","data":{"e":"depthUpdate","E":1783465158615,"s":"ETHUSDT","U":78545066090,"u":78545066093,"b":[["1598.04000000","0.25780000"]],"a":[]}}
{"stream":"btcusdt@depth@100ms","data":{"e":"depthUpdate","E":1783465158714,"s":"BTCUSDT","U":97109082312,"u":97109082320,"b":[["63548.75000000","0.00018000"],["63546.65000000","0.00032000"],["57195.92000000","0.00480000"]],"a":[["63551.03000000","0.69736000"],["63558.43000000","0.00000000"],["63561.17000000","0.09070000"]]}}
{"stream":"ethusdt@depth@100ms","data":{"e":"depthUpdate","E":1783465158715,"s":"ETHUSDT","U":78545066094,"u":78545066097,"b":[["1767.65000000","0.00000000"],["1598.04000000","0.25080000"]],"a":[]}}
{"stream":"ethusdt@depth@100ms","data":{"e":"depthUpdate","E":1783465158815,"s":"ETHUSDT","U":78545066098,"u":78545066105,"b":[["1775.51000000","0.28610000"],["1598.04000000","0.23700000"],["1598.03000000","0.00350000"]],"a":[]}}
{"stream":"btcusdt@depth@100ms","data":{"e":"depthUpdate","E":1783465158815,"s":"BTCUSDT","U":97109082321,"u":97109082336,"b":[["63549.13000000","0.09164000"],["63548.75000000","0.00000000"],["63547.91000000","1.22858000"],["63537.00000000","0.00000000"],["57195.92000000","0.00500000"]],"a":[["63551.03000000","0.69736000"],["63558.43000000","0.00000000"],["63562.43000000","0.00000000"]]}}
{"stream":"ethusdt@depth@100ms","data":{"e":"depthUpdate","E":1783465158915,"s":"ETHUSDT","U":78545066106,"u":78545066119,"b":[["1775.52000000","0.04180000"],["1775.51000000","0.28910000"],["1775.49000000","0.43700000"],["1775.48000000","0.00000000"],["1767.60000000","0.58360000"],["1598.04000000","0.25080000"],["1598.03000000","0.00000000"]],"a":[]}}
{"stream":"btcusdt@depth@100ms","data":{"e":"depthUpdate","E":1783465158915,"s":"BTCUSDT","U":97109082337,"u":97109082350,"b":[["63547.93000000","0.42528000"],["63547.05000000","0.70840000"],["63543.89000000","0.00000000"],["63537.00000000","0.00008000"],["57195.92000000","0.00500000"],["50841.00000000","0.23623000"]],"a":[["63551.03000000","0.69689000"],["63558.44000000","0.00048000"],["63562.43000000","0.00008000"],["63627.13000000","0.03000000"]]}}
{"stream":"ethusdt@trade","data":{"e":"trade","E":1783465158947,"s":"ETHUSDT","t":4197008353,"p":"1775.59000000","q":"0.00290000","T":1783465158947,"m":true,"M":true}}
{"stream":"ethusdt@trade","data":{"e":"trade","E":1783465158947,"s":"ETHUSDT","t":4197008354,"p":"1775.59000000","q":"0.27930000","T":1783465158947,"m":true,"M":true}}
{"stream":"btcusdt@depth@100ms","data":{"e":"depthUpdate","E":1783465159014,"s":"BTCUSDT","U":97109082351,"u":97109082377,"b":[["63551.02000000","1.87797000"],["63551.01000000","0.00305000"],["63550.02000000","0.00000000"],["63549.24000000","0.00787000"],["63549.23000000","0.00000000"],["63549.22000000","0.00018000"],["63549.15000000","0.00018000"],["63543.36000000","0.00000000"],["63510.80000000","2.46052000"],["63484.91000000","0.00037000"],["63484.01000000","0.00000000"],["63471.35000000","0.00000000"],["63421.66000000","0.00014000"],["63421.06000000","0.00000000"],["62597.75000000","0.00030000"],["57195.92000000","0.00480000"],["50840.82000000","0.00083000"]],"a":[["63558.76000000","0.00000000"],["63559.52000000","0.00787000"],["63566.55000000","0.10192000"],["63567.95000000","0.00000000"],["63568.87000000","0.00000000"],["63570.15000000","0.78724000"],["63592.59000000","0.00392000"],["63593.99000000","0.00000000"],["63655.82000000","0.00157000"],["63657.33000000","0.00000000"]]}}
{"stream":"ethusdt@depth@100ms","data":{"e":"depthUpdate","E":1783465159015,"s":"ETHUSDT","U":78545066120,"u":78545066127,"b":[["1775.59000000","18.61040000"],["1775.44000000","0.03290000"],["1775.40000000","2.04740000"],["1598.04000000","0.25080000"]],"a":[["1775.60000000","8.54500000"],["1775.91000000","0.38170000"],["1775.96000000","0.00290000"]]}}
{"stream":"btcusdt@depth@100ms","data":{"e":"depthUpdate","E":1783465159114,"s":"BTCUSDT","U":97109082378,"u":97109082411,"b":[["63551.02000000","1.87981000"],["63550.00000000","0.03818000"],["63549.24000000","0.00805000"],["63549.22000000","0.00000000"],["63549.15000000","0.00000000"],["63547.57000000","0.00675000"],["63484.91000000","0.00000000"],["63471.35000000","0.16051000"],["63421.66000000","0.00014000"],["63420.14000000","0.09460000"],["57195.92000000","0.00480000"],["57195.00000000","0.00087000"]],"a":[["63551.03000000","0.69712000"],["63558.69000000","0.00787000"],["63559.52000000","0.00000000"],["63568.87000000","0.78724000"],["63570.15000000","0.00000000"],["63592.59000000","0.00392000"],["63618.27000000","0.03289000"],["63655.82000000","0.00000000"],["63742.61000000","0.06352000"]]}}
{"stream":"ethusdt@depth@100ms","data":{"e":"depthUpdate","E":1783465159115,"s":"ETHUSDT","U":78545066128,"u":78545066130,"b":[["1598.04000000","0.25780000"]],"a":[]}}
{"stream":"btcusdt@depth@100ms","data":{"e":"depthUpdate","E":1783465159214,"s":"BTCUSDT","U":97109082412,"u":97109082416,"b":[["57195.92000000","0.00480000"],["50840.82000000","0.00044000"]],"a":[]}}
{"stream":"ethusdt@depth@100ms","data":{"e":"depthUpdate","E":1783465159216,"s":"ETHUSDT","U":78545066131,"u":78545066136,"b":[["1598.04000000","0.24400000"]],"a":[]}}
{"stream":"btcusdt@depth@100ms","data":{"e":"depthUpdate","E":1783465159314,"s":"BTCUSDT","U":97109082417,"u":97109082435,"b":[["63551.02000000","1.87981000"],["63551.01000000","0.00305000"],["63550.01000000","0.04038000"],["57195.92000000","0.00480000"]],"a":[]}}
{"stream":"ethusdt@depth@100ms","data":{"e":"depthUpdate","E":1783465159315,"s":"ETHUSDT","U":78545066137,"u":78545066151,"b":[["1775.44000000","0.31460000"],["1775.40000000","1.76570000"],["1775.26000000","29.66050000"],["1775.24000000","0.27550000"],["1775.21000000","0.00000000"],["1598.04000000","0.25780000"]],"a":[["1775.60000000","2.06300000"],["1775.91000000","0.10000000"],["1775.94000000","0.00580000"],["1775.96000000","0.28460000"],["1776.08000000","0.32160000"],["1776.13000000","2.82080000"]]}}
{"stream":"btcusdt@depth@100ms","data":{"e":"depthUpdate","E":1783465159414,"s":"BTCUSDT","U":97109082436,"u":97109082459,"b":[["63551.02000000","1.87981000"],["63550.48000000","0.00787000"],["63550.01000000","0.04056000"],["63549.24000000","0.00018000"],["63548.01000000","0.00000000"],["63547.94000000","0.00000000"],["63547.93000000","0.42519000"],["63547.57000000","0.00657000"],["57195.92000000","0.00500000"],["40000.00000000","260.73952000"]],"a":[["63551.03000000","0.36721000"],["63558.69000000","0.00000000"],["63558.82000000","0.01800000"],["63559.52000000","0.00787000"],["63566.55000000","0.00000000"],["63567.95000000","0.36510000"],["63568.87000000","0.00000000"],["63570.15000000","0.78724000"],["65600.00000000","6.58080000"]]}}
{"stream":"ethusdt@depth@100ms","data":{"e":"depthUpdate","E":1783465159415,"s":"ETHUSDT","U":78545066152,"u":78545066154,"b":[["1598.04000000","0.25080000"]],"a":[]}}
{"stream":"btcusdt@depth@100ms","data":{"e":"depthUpdate","E":1783465159514,"s":"BTCUSDT","U":97109082460,"u":97109082489,"b":[["63551.02000000","1.87981000"],["63550.48000000","0.00805000"],["63550.00000000","0.03818000"],["63549.24000000","0.00000000"],["63549.13000000","0.09172000"],["63547.94000000","0.06455000"],["57195.92000000","0.00500000"],["50840.82000000","0.00044000"]],"a":[["63551.03000000","0.36720000"],["63551.69000000","0.00000000"],["63551.70000000","0.00072000"],["63555.79000000","0.06482000"],["63627.89000000","0.00000000"],["63629.99000000","1.91970000"]]}}
{"stream":"ethusdt@depth@100ms","data":{"e":"depthUpdate","E":1783465159515,"s":"ETHUSDT","U":78545066155,"u":78545066158,"b":[["1598.04000000","0.25080000"]],"a":[]}}
{"stream":"btcusdt@depth@100ms","data":{"e":"depthUpdate","E":1783465159614,"s":"BTCUSDT","U":97109082490,"u":97109082521,"b":[["63548.00000000","0.02818000"],["63547.94000000","0.06473000"],["63547.91000000","1.22840000"],["63471.35000000","0.00000000"],["57195.92000000","0.00500000"],["50841.00000000","0.23623000"]],"a":[["63551.04000000","0.04197000"],["63551.70000000","0.00054000"],["63557.27000000","0.06473000"],["63558.72000000","0.00048000"],["63560.99000000","0.00000000"],["63561.17000000","0.00000000"],["63562.17000000","0.00252000"],["63662.06000000","0.00000000"],["64504.30000000","0.00030000"]]}}
{"stream":"ethusdt@depth@100ms","data":{"e":"depthUpdate","E":1783465159615,"s":"ETHUSDT","U":78545066159,"u":78545066164,"b":[["1769.38000000","1.02760000"],["1768.61000000","2.48620000"],["1598.04000000","0.25080000"]],"a":[]}}
{"stream":"btcusdt@depth@100ms","data":{"e":"depthUpdate","E":1783465159714,"s":"BTCUSDT","U":97109082522,"u":97109082531,"b":[["63479.92000000","0.04881000"],["63420.14000000","0.00000000"],["57195.92000000","0.00480000"]],"a":[["63566.34000000","0.00000000"],["63568.88000000","0.24500000"],["63618.27000000","0.00000000"],["63670.66000000","0.07658000"],["63742.61000000","0.00223000"]]}}
{"stream":"ethusdt@depth@100ms","data":{"e":"depthUpdate","E":1783465159716,"s":"ETHUSDT","U":78545066165,"u":78545066171,"b":[["1770.27000000","0.70920000"],["1598.04000000","0.23700000"]],"a":[]}}
{"stream":"btcusdt@depth@100ms","data":{"e":"depthUpdate","E":1783465159814,"s":"BTCUSDT","U":97109082532,"u":97109082537,"b":[["57195.92000000","0.00480000"],["50000.00000000","542.70395000"]],"a":[["82071.40000000","0.00000000"]]}}
{"stream":"ethusdt@depth@100ms","data":{"e":"depthUpdate","E":1783465159815,"s":"ETHUSDT","U":78545066172,"u":78545066176,"b":[["1598.04000000","0.25780000"]],"a":[]}}
{"stream":"btcusdt@depth@100ms","data":{"e":"depthUpdate","E":1783465159914,"s":"BTCUSDT","U":97109082538,"u":97109082544,"b":[["63537.00000000","0.00008000"],["57195.92000000","0.00480000"]],"a":[["63562.43000000","0.00008000"]]}}
{"stream":"ethusdt@depth@100ms","data":{"e":"depthUpdate","E":1783465159915,"s":"ETHUSDT","U":78545066177,"u":78545066182,"b":[["1770.32000000","41.50710000"],["1768.56000000","0.57510000"],["1768.54000000","0.00000000"],["1598.04000000","0.25780000"]],"a":[]}}
{"stream":"btcusdt@depth@100ms","data":{"e":"depthUpdate","E":1783465160014,"s":"BTCUSDT","U":97109082545,"u":97109082564,"b":[["63484.91000000","0.00037000"],["63421.66000000","0.00014000"],["62597.75000000","0.00030000"],["57195.92000000","0.00480000"],["50840.82000000","0.00083000"]],"a":[["63551.03000000","0.36702000"],["63551.04000000","0.00095000"],["63554.35000000","0.00018000"],["63554.36000000","0.04004000"],["63592.59000000","0.00392000"],["63627.89000000","1.91970000"],["63629.99000000","0.00000000"],["63655.82000000","0.00157000"]]}}
{"stream":"ethusdt@depth@100ms","data":{"e":"depthUpdate","E":1783465160015,"s":"ETHUSDT","U":78545066183,"u":78545066186,"b":[["1775.45000000","0.42170000"],["1775.44000000","0.03290000"],["1598.04000000","0.25080000"]],"a":[]}}
{"stream":"ethusdt@depth@100ms","data":{"e":"depthUpdate","E":1783465160116,"s":"ETHUSDT","U":78545066187,"u":78545066199,"b":[["1775.59000000","18.61040000"],["1775.45000000","0.14000000"],["1775.44000000","0.31460000"],["1769.38000000","0.14540000"],["1768.61000000","3.36840000"],["1598.04000000","0.23700000"],["1067.00000000","6.86000000"]],"a":[]}}
{"stream":"btcusdt@depth@100ms","data":{"e":"depthUpdate","E":1783465160116,"s":"BTCUSDT","U":97109082565,"u":97109082585,"b":[["63550.48000000","0.00018000"],["63550.02000000","0.00787000"],["63484.91000000","0.00037000"],["63421.66000000","0.00000000"],["57195.92000000","0.00500000"]],"a":[["63551.03000000","0.36720000"],["63551.04000000","0.00077000"],["63551.71000000","0.06426000"],["63559.52000000","0.00000000"],["63559.96000000","0.00787000"],["63562.00000000","0.25207000"],["63592.59000000","0.00392000"],["63655.82000000","0.00000000"]]}}
{"stream":"ethusdt@depth@100ms","data":{"e":"depthUpdate","E":1783465160216,"s":"ETHUSDT","U":78545066200,"u":78545066205,"b":[["1598.04000000","0.25080000"]],"a":[]}}
{"stream":"btcusdt@depth@100ms","data":{"e":"depthUpdate","E":1783465160216,"s":"BTCUSDT","U":97109082586,"u":97109082601,"b":[["63551.02000000","1.87981000"],["63550.48000000","0.00000000"],["57195.92000000","0.00500000"],["50840.82000000","0.00044000"]],"a":[["63551.03000000","0.36728000"],["63554.36000000","0.04022000"],["63661.76000000","0.03131000"],["77811.66000000","0.00000000"]]}}
{"stream":"btcusdt@depth@100ms","data":{"e":"depthUpdate","E":1783465160314,"s":"BTCUSDT","U":97109082602,"u":97109082607,"b":[["57195.92000000","0.00480000"],["57195.00000000","0.00087000"]],"a":[["82071.40000000","0.00010000"]]}}
{"stream":"ethusdt@depth@100ms","data":{"e":"depthUpdate","E":1783465160316,"s":"ETHUSDT","U":78545066206,"u":78545066210,"b":[["1775.24000000","0.27260000"],["1598.04000000","0.25080000"]],"a":[["1775.96000000","0.28170000"]]}}
{"stream":"ethusdt@depth@100ms","data":{"e":"depthUpdate","E":1783465160415,"s":"ETHUSDT","U":78545066211,"u":78545066216,"b":[["1775.24000000","0.27550000"],["1768.56000000","0.00000000"],["1768.54000000","0.57510000"],["1598.04000000","0.25780000"]],"a":[["1775.96000000","0.28460000"]]}}
{"stream":"btcusdt@depth@100ms","data":{"e":"depthUpdate","E":1783465160415,"s":"BTCUSDT","U":97109082608,"u":97109082622,"b":[["57195.92000000","0.00480000"],["50841.00000000","0.23623000"],["40000.00000000","260.73952000"]],"a":[["63562.17000000","0.09322000"],["63627.89000000","0.00000000"],["63629.99000000","1.91970000"]]}}
{"stream":"btcusdt@depth@100ms","data":{"e":"depthUpdate","E":1783465160514,"s":"BTCUSDT","U":97109082623,"u":97109082630,"b":[["57195.92000000","0.00480000"],["50840.82000000","0.00044000"]],"a":[]}}
{"stream":"ethusdt@depth@100ms","data":{"e":"depthUpdate","E":1783465160516,"s":"ETHUSDT","U":78545066217,"u":78545066224,"b":[["1773.86000000","8.57250000"],["1773.85000000","12.07480000"],["1773.84000000","0.00000000"],["1773.61000000","0.00000000"],["1598.04000000","0.25780000"]],"a":[]}}
{"stream":"btcusdt@depth@100ms","data":{"e":"depthUpdate","E":1783465160614,"s":"BTCUSDT","U":97109082631,"u":97109082636,"b":[["57195.92000000","0.00480000"]],"a":[["64504.30000000","0.00030000"]]}}
{"stream":"ethusdt@depth@100ms","data":{"e":"depthUpdate","E":1783465160616,"s":"ETHUSDT","U":78545066225,"u":78545066238,"b":[["1598.04000000","0.24400000"]],"a":[["1775.60000000","2.06010000"],["1775.61000000","4.10250000"],["1775.62000000","0.61590000"],["1775.63000000","0.01190000"],["1775.65000000","0.01190000"],["1775.66000000","11.27430000"]]}}
{"stream":"ethusdt@depth@100ms","data":{"e":"depthUpdate","E":1783465160717,"s":"ETHUSDT","U":78545066239,"u":78545066244,"b":[["1768.56000000","0.57510000"],["1768.54000000","0.00000000"],["1598.04000000","0.25080000"]],"a":[]}}
{"stream":"btcusdt@depth@100ms","data":{"e":"depthUpdate","E":1783465160717,"s":"BTCUSDT","U":97109082637,"u":97109082640,"b":[["57195.92000000","0.00480000"]],"a":[]}}
{"stream":"btcusdt@depth@100ms","data":{"e":"depthUpdate","E":1783465160815,"s":"BTCUSDT","U":97109082641,"u":97109082643,"b":[["57195.92000000","0.00500000"]],"a":[]}}
{"stream":"ethusdt@depth@100ms","data":{"e":"depthUpdate","E":1783465160816,"s":"ETHUSDT","U":78545066245,"u":78545066248,"b":[["1598.04000000","0.25080000"]],"a":[]}}
{"stream":"btcusdt@depth@100ms","data":{"e":"depthUpdate","E":1783465160914,"s":"BTCUSDT","U":97109082644,"u":97109082650,"b":[["63537.00000000","0.00008000"],["57195.92000000","0.00500000"]],"a":[["63562.43000000","0.00008000"]]}}
{"stream":"ethusdt@depth@100ms","data":{"e":"depthUpdate","E":1783465160916,"s":"ETHUSDT","U":78545066249,"u":78545066258,"b":[["1775.52000000","0.04480000"],["1598.04000000","0.25080000"]],"a":[["1775.64000000","12.77440000"],["1775.65000000","0.00590000"],["1775.66000000","0.00300000"],["1775.72000000","1.10960000"]]}}
{"stream":"btcusdt@depth@100ms","data":{"e":"depthUpdate","E":1783465161014,"s":"BTCUSDT","U":97109082651,"u":97109082660,"b":[["63484.91000000","0.00037000"],["63421.66000000","0.00014000"],["62597.75000000","0.00030000"],["57195.92000000","0.00480000"],["50840.82000000","0.00083000"]],"a":[["63592.59000000","0.00392000"],["63655.82000000","0.00157000"]]}}
{"stream":"ethusdt@depth@100ms","data":{"e":"depthUpdate","E":1783465161015,"s":"ETHUSDT","U":78545066259,"u":78545066267,"b":[["1775.46000000","0.63510000"],["1775.44000000","0.03290000"],["1598.04000000","0.23700000"]],"a":[["1775.96000000","0.00290000"],["1775.97000000","0.58310000"],["1776.13000000","0.00290000"],["1776.14000000","18.59140000"]]}}
{"stream":"btcusdt@trade","data":{"e":"trade","E":1783465161081,"s":"BTCUSDT","t":6486989276,"p":"63551.03000000","q":"0.00024000","T":1783465161081,"m":false,"M":true}}
{"stream":"ethusdt@depth@100ms","data":{"e":"depthUpdate","E":1783465161115,"s":"ETHUSDT","U":78545066268,"u":78545066272,"b":[["1598.04000000","0.25780000"]],"a":[]}}
{"stream":"btcusdt@depth@100ms","data":{"e":"depthUpdate","E":1783465161115,"s":"BTCUSDT","U":97109082661,"u":97109082673,"b":[["63484.91000000","0.00000000"],["63421.66000000","0.00014000"],["57195.92000000","0.00480000"],["57195.90000000","0.00000000"]],"a":[["63551.03000000","0.36704000"],["63592.59000000","0.00000000"],["63655.82000000","0.00157000"]]}}
{"stream":"btcusdt@depth@100ms","data":{"e":"depthUpdate","E":1783465161214,"s":"BTCUSDT","U":97109082674,"u":97109082680,"b":[["63338.03000000","0.02464000"],["63303.12000000","0.00000000"],["57195.92000000","0.00480000"],["50840.82000000","0.00044000"]],"a":[]}}
{"stream":"ethusdt@depth@100ms","data":{"e":"depthUpdate","E":1783465161215,"s":"ETHUSDT","U":78545066273,"u":78545066276,"b":[["1598.04000000","0.25780000"]],"a":[]}}
{"stream":"btcusdt@trade","data":{"e":"trade","E":1783465161305,"s":"BTCUSDT","t":6486989277,"p":"63551.03000000","q":"0.00029000","T":1783465161305,"m":false,"M":true}}
{"stream":"btcusdt@depth@100ms","data":{"e":"depthUpdate","E":1783465161314,"s":"BTCUSDT","U":97109082681,"u":97109082685,"b":[["57195.92000000","0.00480000"]],"a":[["63551.03000000","0.36675000"]]}}
{"stream":"ethusdt@depth@100ms","data":{"e":"depthUpdate","E":1783465161315,"s":"ETHUSDT","U":78545066277,"u":78545066280,"b":[["1598.04000000","0.25780000"]],"a":[]}}
{"stream":"btcusdt@depth@100ms","data":{"e":"depthUpdate","E":1783465161414,"s":"BTCUSDT","U":97109082686,"u":97109082695,"b":[["63429.87000000","0.01000000"],["57195.92000000","0.00500000"],["57195.00000000","0.00087000"],["40000.00000000","260.73952000"]],"a":[["63576.88000000","0.00000000"],["63577.11000000","0.00699000"]]}}
{"stream":"ethusdt@depth@100ms","data":{"e":"depthUpdate","E":1783465161415,"s":"ETHUSDT","U":78545066281,"u":78545066286,"b":[["1775.24000000","0.27550000"],["1598.04000000","0.25080000"]],"a":[["1775.96000000","0.00290000"]]}}
{"stream":"btcusdt@depth@100ms","data":{"e":"depthUpdate","E":1783465161515,"s":"BTCUSDT","U":97109082696,"u":97109082701,"b":[["57195.92000000","0.00500000"],["50840.82000000","0.00044000"]],"a":[]}}
{"stream":"ethusdt@depth@100ms","data":{"e":"depthUpdate","E":1783465161515,"s":"ETHUSDT","U":78545066287,"u":78545066292,"b":[["1598.04000000","0.23700000"]],"a":[]}}
{"stream":"btcusdt@depth@100ms","data":{"e":"depthUpdate","E":1783465161614,"s":"BTCUSDT","U":97109082702,"u":97109082713,"b":[["63432.63000000","0.00066000"],["63429.94000000","0.00000000"],["57195.92000000","0.00500000"],["50841.00000000","0.23623000"],["50840.82000000","0.00044000"]],"a":[["63674.71000000","0.00000000"],["64504.30000000","0.00030000"]]}}
{"stream":"ethusdt@depth@100ms","data":{"e":"depthUpdate","E":1783465161615,"s":"ETHUSDT","U":78545066293,"u":78545066298,"b":[["1598.04000000","0.25080000"]],"a":[]}}
{"stream":"btcusdt@depth@100ms","data":{"e":"depthUpdate","E":1783465161714,"s":"BTCUSDT","U":97109082714,"u":97109082721,"b":[["57195.92000000","0.00480000"],["33000.00000000","35.16979000"]],"a":[["63670.03000000","0.03541000"],["63676.32000000","0.00000000"],["63677.41000000","0.00103000"]]}}
{"stream":"ethusdt@depth@100ms","data":{"e":"depthUpdate","E":1783465161715,"s":"ETHUSDT","U":78545066299,"u":78545066304,"b":[["1775.59000000","18.75540000"],["1768.56000000","0.00000000"],["1768.54000000","0.57510000"],["1598.04000000","0.25080000"]],"a":[]}}
{"stream":"btcusdt@depth@100ms","data":{"e":"depthUpdate","E":1783465161814,"s":"BTCUSDT","U":97109082722,"u":97109082732,"b":[["63479.92000000","0.00000000"],["63472.33000000","0.16051000"],["57195.92000000","0.00480000"],["55000.00000000","602.26909000"]],"a":[["63566.58000000","0.08054000"],["63567.95000000","0.00000000"],["63663.05000000","0.05327000"],["63670.66000000","0.00000000"],["69906.13000000","0.00008000"]]}}
{"stream":"ethusdt@depth@100ms","data":{"e":"depthUpdate","E":1783465161815,"s":"ETHUSDT","U":78545066305,"u":78545066308,"b":[["1775.59000000","18.61040000"],["1598.04000000","0.25780000"]],"a":[]}}
{"stream":"btcusdt@depth@100ms","data":{"e":"depthUpdate","E":1783465161914,"s":"BTCUSDT","U":97109082733,"u":97109082750,"b":[["63551.02000000","2.58821000"],["63547.93000000","0.42511000"],["63547.05000000","0.00000000"],["63541.05000000","0.00000000"],["63537.00000000","0.00000000"],["63423.91000000","0.01000000"],["57195.92000000","0.00480000"]],"a":[["63551.03000000","0.36728000"],["63551.70000000","0.03985000"],["63558.95000000","0.00000000"],["63559.64000000","0.00787000"],["63559.96000000","0.00000000"],["63562.43000000","0.00000000"],["63627.89000000","1.91970000"],["63629.99000000","0.00000000"],["69906.13000000","0.00000000"]]}}
{"stream":"ethusdt@depth@100ms","data":{"e":"depthUpdate","E":1783465161915,"s":"ETHUSDT","U":78545066309,"u":78545066316,"b":[["1598.04000000","0.24400000"],["1067.00000000","6.86000000"]],"a":[]}}
{"stream":"btcusdt@depth@100ms","data":{"e":"depthUpdate","E":1783465162014,"s":"BTCUSDT","U":97109082751,"u":97109082774,"b":[["63551.02000000","1.87981000"],["63546.60000000","0.70840000"],["63537.00000000","0.00008000"],["63484.91000000","0.00037000"],["63421.66000000","0.00014000"],["62597.75000000","0.00030000"],["57195.92000000","0.00480000"],["50840.82000000","0.00083000"]],"a":[["63551.03000000","0.36746000"],["63551.69000000","0.00018000"],["63555.79000000","0.06473000"],["63557.27000000","0.06455000"],["63562.43000000","0.00008000"],["63566.58000000","0.00000000"],["63567.95000000","0.34189000"],["63592.59000000","0.00392000"],["63655.82000000","0.00157000"]]}}
{"stream":"ethusdt@depth@100ms","data":{"e":"depthUpdate","E":1783465162015,"s":"ETHUSDT","U":78545066317,"u":78545066321,"b":[["1598.04000000","0.25080000"]],"a":[]}}
{"stream":"btcusdt@depth@100ms","data":{"e":"depthUpdate","E":1783465162114,"s":"BTCUSDT","U":97109082775,"u":97109082783,"b":[["63484.91000000","0.00037000"],["63421.66000000","0.00000000"],["57195.92000000","0.00500000"]],"a":[["63592.59000000","0.00000000"],["63655.82000000","0.00157000"]]}}
{"stream":"ethusdt@depth@100ms","data":{"e":"depthUpdate","E":1783465162115,"s":"ETHUSDT","U":78545066322,"u":78545066326,"b":[["1775.59000000","18.75540000"],["1598.04000000","0.25080000"]],"a":[]}}
{"stream":"btcusdt@depth@100ms","data":{"e":"depthUpdate","E":1783465162214,"s":"BTCUSDT","U":97109082784,"u":97109082789,"b":[["57195.92000000","0.00500000"],["50840.82000000","0.00044000"]],"a":[["63558.82000000","0.01351000"]]}}
{"stream":"ethusdt@depth@100ms","data":{"e":"depthUpdate","E":1783465162217,"s":"ETHUSDT","U":78545066327,"u":78545066330,"b":[["1598.04000000","0.25080000"]],"a":[]}}
{"stream":"btcusdt@depth@100ms","data":{"e":"depthUpdate","E":1783465162314,"s":"BTCUSDT","U":97109082790,"u":97109082799,"b":[["63546.90000000","0.45643000"],["63338.03000000","0.00000000"],["57195.92000000","0.00480000"]],"a":[["63551.03000000","0.37194000"],["63551.69000000","0.00000000"],["63551.70000000","0.00054000"],["63555.79000000","0.06482000"]]}}
{"stream":"ethusdt@depth@100ms","data":{"e":"depthUpdate","E":1783465162315,"s":"ETHUSDT","U":78545066331,"u":78545066341,"b":[["1775.47000000","0.71870000"],["1775.46000000","0.35340000"],["1598.04000000","0.25080000"]],"a":[["1775.60000000","1.44390000"],["1777.54000000","6.84920000"],["1777.56000000","15.02670000"],["1777.60000000","16.77570000"],["1777.61000000","25.82230000"],["1777.64000000","4.42390000"]]}}
{"stream":"ethusdt@depth@100ms","data":{"e":"depthUpdate","E":1783465162415,"s":"ETHUSDT","U":78545066342,"u":78545066350,"b":[["1775.24000000","0.27550000"],["1773.09000000","0.00290000"],["1598.04000000","0.24400000"]],"a":[["1775.96000000","0.00290000"],["1777.78000000","0.00000000"]]}}
{"stream":"btcusdt@depth@100ms","data":{"e":"depthUpdate","E":1783465162415,"s":"BTCUSDT","U":97109082800,"u":97109082806,"b":[["63303.12000000","0.02464000"],["57195.92000000","0.00480000"],["40000.00000000","260.73952000"]],"a":[]}}
{"stream":"btcusdt@depth@100ms","data":{"e":"depthUpdate","E":1783465162514,"s":"BTCUSDT","U":97109082807,"u":97109082813,"b":[["57195.92000000","0.00480000"],["57195.00000000","0.00107000"],["50840.82000000","0.00044000"]],"a":[]}}
{"stream":"ethusdt@depth@100ms","data":{"e":"depthUpdate","E":1783465162515,"s":"ETHUSDT","U":78545066351,"u":78545066361,"b":[["1773.05000000","0.00630000"],["1598.04000000","0.25780000"]],"a":[["1777.61000000","25.95690000"],["1777.83000000","1.89360000"],["1777.99000000","0.00000000"],["1778.15000000","0.04990000"]]}}
{"stream":"btcusdt@depth@100ms","data":{"e":"depthUpdate","E":1783465162614,"s":"BTCUSDT","U":97109082814,"u":97109082825,"b":[["57195.92000000","0.00480000"],["57195.00000000","0.00087000"],["50840.82000000","0.00044000"]],"a":[["63623.77000000","0.00807000"],["63627.95000000","0.00000000"],["64064.18000000","0.00000000"],["64504.30000000","0.00030000"]]}}
{"stream":"ethusdt@depth@100ms","data":{"e":"depthUpdate","E":1783465162615,"s":"ETHUSDT","U":78545066362,"u":78545066366,"b":[["1770.32000000","0.14660000"],["1598.04000000","0.25780000"]],"a":[]}}
{"stream":"btcusdt@depth@100ms","data":{"e":"depthUpdate","E":1783465162714,"s":"BTCUSDT","U":97109082826,"u":97109082829,"b":[["57195.92000000","0.00480000"]],"a":[]}}
{"stream":"ethusdt@depth@100ms","data":{"e":"depthUpdate","E":1783465162715,"s":"ETHUSDT","U":78545066367,"u":78545066369,"b":[["1598.04000000","0.25080000"]],"a":[]}}
{"stream":"btcusdt@depth@100ms","data":{"e":"depthUpdate","E":1783465162814,"s":"BTCUSDT","U":97109082830,"u":97109082833,"b":[["57195.92000000","0.00500000"],["50000.00000000","542.70415000"]],"a":[]}}
{"stream":"ethusdt@depth@100ms","data":{"e":"depthUpdate","E":1783465162815,"s":"ETHUSDT","U":78545066370,"u":78545066376,"b":[["1770.27000000","41.47930000"],["1598.04000000","0.23700000"]],"a":[]}}
{"stream":"btcusdt@depth@100ms","data":{"e":"depthUpdate","E":1783465162914,"s":"BTCUSDT","U":97109082834,"u":97109082837,"b":[["57195.92000000","0.00500000"]],"a":[]}}
{"stream":"ethusdt@depth@100ms","data":{"e":"depthUpdate","E":1783465162916,"s":"ETHUSDT","U":78545066377,"u":78545066385,"b":[["1765.00000000","167.55880000"],["1598.04000000","0.25080000"]],"a":[["1780.06000000","0.89340000"],["1780.98000000","0.01100000"]]}}
{"stream":"btcusdt@depth@100ms","data":{"e":"depthUpdate","E":1783465163014,"s":"BTCUSDT","U":97109082838,"u":97109082854,"b":[["63537.00000000","0.00008000"],["63484.91000000","0.00037000"],["63421.66000000","0.00014000"],["62597.75000000","0.00030000"],["57195.92000000","0.00480000"],["50840.82000000","0.00083000"]],"a":[["63562.43000000","0.00008000"],["63592.59000000","0.00392000"],["63655.82000000","0.00157000"]]}}
{"stream":"ethusdt@depth@100ms","data":{"e":"depthUpdate","E":1783465163016,"s":"ETHUSDT","U":78545066386,"u":78545066390,"b":[["1775.29000000","2.81790000"],["1775.26000000","26.84260000"],["1598.04000000","0.25080000"]],"a":[]}}
{"stream":"btcusdt@depth@100ms","data":{"e":"depthUpdate","E":1783465163114,"s":"BTCUSDT","U":97109082855,"u":97109082861,"b":[["63484.91000000","0.00037000"],["63421.66000000","0.00000000"],["57195.92000000","0.00480000"]],"a":[["63655.82000000","0.00000000"]]}}
{"stream":"ethusdt@depth@100ms","data":{"e":"depthUpdate","E":1783465163115,"s":"ETHUSDT","U":78545066391,"u":78545066393,"b":[["1598.04000000","0.25780000"]],"a":[]}}
{"stream":"btcusdt@trade","data":{"e":"trade","E":1783465163155,"s":"BTCUSDT","t":6486989278,"p":"63551.02000000","q":"0.00020000","T":1783465163155,"m":true,"M":true}}
{"stream":"btcusdt@depth@100ms","data":{"e":"depthUpdate","E":1783465163214,"s":"BTCUSDT","U":97109082862,"u":97109082880,"b":[["63551.02000000","1.87961000"],["63550.02000000","0.00805000"],["57195.92000000","0.00480000"],["57195.91000000","0.00010000"],["50840.82000000","0.00044000"]],"a":[["63551.03000000","0.37158000"],["63551.69000000","0.00018000"],["63551.70000000","0.03985000"],["63555.79000000","0.06473000"],["63557.27000000","0.06473000"]]}}
{"stream":"ethusdt@depth@100ms","data":{"e":"depthUpdate","E":1783465163215,"s":"ETHUSDT","U":78545066394,"u":78545066397,"b":[["1598.04000000","0.25780000"]],"a":[]}}
{"stream":"ethusdt@depth@100ms","data":{"e":"depthUpdate","E":1783465163315,"s":"ETHUSDT","U":78545066398,"u":78545066402,"b":[["1598.04000000","0.23700000"]],"a":[]}}
{"stream":"btcusdt@depth@100ms","data":{"e":"depthUpdate","E":1783465163315,"s":"BTCUSDT","U":97109082881,"u":97109082892,"b":[["57195.92000000","0.00480000"]],"a":[["63551.03000000","0.37158000"],["63551.70000000","0.04003000"],["63557.27000000","0.06455000"]]}}
{"stream":"ethusdt@depth@100ms","data":{"e":"depthUpdate","E":1783465163415,"s":"ETHUSDT","U":78545066403,"u":78545066411,"b":[["1775.24000000","0.27260000"],["1773.18000000","0.00340000"],["1598.04000000","0.25080000"]],"a":[["1775.96000000","0.00000000"],["1780.06000000","0.01120000"]]}}
{"stream":"btcusdt@depth@100ms","data":{"e":"depthUpdate","E":1783465163415,"s":"BTCUSDT","U":97109082893,"u":97109082901,"b":[["63551.02000000","1.87949000"],["58466.94000000","0.00018000"],["57195.92000000","0.00500000"],["40000.00000000","260.73952000"]],"a":[["63627.89000000","0.00000000"],["63629.99000000","1.91970000"]]}}
{"stream":"btcusdt@depth@100ms","data":{"e":"depthUpdate","E":1783465163514,"s":"BTCUSDT","U":97109082902,"u":97109082905,"b":[["57195.92000000","0.00500000"]],"a":[]}}
{"stream":"ethusdt@depth@100ms","data":{"e":"depthUpdate","E":1783465163515,"s":"ETHUSDT","U":78545066412,"u":78545066418,"b":[["1775.24000000","0.27550000"],["1773.50000000","0.46520000"],["1598.04000000","0.25080000"]],"a":[["1775.96000000","0.00290000"]]}}
{"stream":"btcusdt@depth@100ms","data":{"e":"depthUpdate","E":1783465163614,"s":"BTCUSDT","U":97109082906,"u":97109082917,"b":[["57195.92000000","0.00500000"],["57195.00000000","0.00087000"],["50840.82000000","0.00044000"]],"a":[["64504.30000000","0.00030000"]]}}
{"stream":"ethusdt@depth@100ms","data":{"e":"depthUpdate","E":1783465163617,"s":"ETHUSDT","U":78545066419,"u":78545066422,"b":[["1598.04000000","0.25080000"]],"a":[]}}
{"stream":"btcusdt@depth@100ms","data":{"e":"depthUpdate","E":1783465163714,"s":"BTCUSDT","U":97109082918,"u":97109082920,"b":[["57195.92000000","0.00480000"]],"a":[]}}
{"stream":"ethusdt@depth@100ms","data":{"e":"depthUpdate","E":1783465163715,"s":"ETHUSDT","U":78545066423,"u":78545066432,"b":[["1775.59000000","18.61040000"],["1598.04000000","0.23700000"],["1067.00000000","6.86000000"]],"a":[["1775.60000000","7.92590000"]]}}
{"stream":"btcusdt@trade","data":{"e":"trade","E":1783465163781,"s":"BTCUSDT","t":6486989279,"p":"63551.02000000","q":"0.03079000","T":1783465163781,"m":true,"M":true}}
{"stream":"btcusdt@trade","data":{"e":"trade","E":1783465163781,"s":"BTCUSDT","t":6486989280,"p":"63551.02000000","q":"0.00350000","T":1783465163781,"m":true,"M":true}}
{"stream":"btcusdt@trade","data":{"e":"trade","E":1783465163781,"s":"BTCUSDT","t":6486989281,"p":"63551.02000000","q":"0.00150000","T":1783465163781,"m":true,"M":true}}
{"stream":"btcusdt@trade","data":{"e":"trade","E":1783465163781,"s":"BTCUSDT","t":6486989282,"p":"63551.02000000","q":"0.00008000","T":1783465163781,"m":true,"M":true}}
{"stream":"btcusdt@trade","data":{"e":"trade","E":1783465163781,"s":"BTCUSDT","t":6486989283,"p":"63551.02000000","q":"0.00008000","T":1783465163781,"m":true,"M":true}}
{"stream":"btcusdt@trade","data":{"e":"trade","E":1783465163781,"s":"BTCUSDT","t":6486989284,"p":"63551.02000000","q":"0.00008000","T":1783465163781,"m":true,"M":true}}
{"stream":"btcusdt@trade","data":{"e":"trade","E":1783465163781,"s":"BTCUSDT","t":6486989285,"p":"63551.02000000","q":"0.00008000","T":1783465163781,"m":true,"M":true}}
{"stream":"btcusdt@trade","data":{"e":"trade","E":1783465163781,"s":"BTCUSDT","t":6486989286,"p":"63551.02000000","q":"0.02309000","T":1783465163781,"m":true,"M":true}}
{"stream":"btcusdt@depth@100ms","data":{"e":"depthUpdate","E":1783465163814,"s":"BTCUSDT","U":97109082921,"u":97109082928,"b":[["63551.02000000","1.82037000"],["57195.92000000","0.00480000"]],"a":[["63551.03000000","0.37206000"],["63558.72000000","0.00000000"],["63566.55000000","0.07913000"],["63567.95000000","0.00000000"]]}}
{"stream":"ethusdt@depth@100ms","data":{"e":"depthUpdate","E":1783465163816,"s":"ETHUSDT","U":78545066433,"u":78545066444,"b":[["1775.59000000","18.75840000"],["1775.47000000","0.43700000"],["1775.42000000","0.28170000"],["1775.29000000","0.00000000"],["1775.25000000","5.30320000"],["1598.04000000","0.25780000"]],"a":[["1775.94000000","0.28750000"],["1775.97000000","0.30140000"],["1953.16000000","0.00570000"]]}}
{"stream":"btcusdt@depth@100ms","data":{"e":"depthUpdate","E":1783465163914,"s":"BTCUSDT","U":97109082929,"u":97109082935,"b":[["58466.94000000","0.00000000"],["57195.92000000","0.00480000"]],"a":[["63627.89000000","1.91970000"],["63629.99000000","0.00000000"]]}}
{"stream":"ethusdt@depth@100ms","data":{"e":"depthUpdate","E":1783465163915,"s":"ETHUSDT","U":78545066445,"u":78545066451,"b":[["1598.04000000","0.25780000"]],"a":[["1776.18000000","0.00000000"],["1776.38000000","16.41820000"],["1953.16000000","0.00280000"]]}}
{"stream":"btcusdt@depth@100ms","data":{"e":"depthUpdate","E":1783465164014,"s":"BTCUSDT","U":97109082936,"u":97109082957,"b":[["63550.02000000","0.00823000"],["63548.01000000","0.00018000"],["63547.95000000","0.00009000"],["63537.00000000","0.00008000"],["63484.91000000","0.00000000"],["63483.16000000","0.00037000"],["63472.33000000","0.00000000"],["63420.01000000","0.00014000"],["62597.75000000","0.00030000"],["57195.92000000","0.00480000"],["50840.82000000","0.00083000"]],"a":[["63562.43000000","0.00008000"],["63566.55000000","0.00000000"],["63567.95000000","0.41855000"],["63592.59000000","0.00000000"],["63594.53000000","0.00392000"],["63657.99000000","0.00157000"],["63663.05000000","0.00000000"]]}}
{"stream":"ethusdt@depth@100ms","data":{"e":"depthUpdate","E":1783465164015,"s":"ETHUSDT","U":78545066452,"u":78545066457,"b":[["1775.42000000","0.00000000"],["1775.41000000","2.06170000"],["1598.04000000","0.25080000"]],"a":[["1775.92000000","0.60860000"],["1775.94000000","0.00580000"],["1776.09000000","11.29670000"],["1776.14000000","15.77350000"]]}}
{"stream":"btcusdt@trade","data":{"e":"trade","E":1783465164069,"s":"BTCUSDT","t":6486989287,"p":"63551.03000000","q":"0.00010000","T":1783465164069,"m":false,"M":true}}
{"stream":"ethusdt@trade","data":{"e":"trade","E":1783465164069,"s":"ETHUSDT","t":4197008355,"p":"1775.60000000","q":"0.00300000","T":1783465164069,"m":false,"M":true}}
{"stream":"ethusdt@depth@100ms","data":{"e":"depthUpdate","E":1783465164115,"s":"ETHUSDT","U":78545066458,"u":78545066476,"b":[["1775.31000000","11.26840000"],["1775.17000000","25.23510000"],["1773.03000000","7.73320000"],["1772.93000000","4.14380000"],["1598.04000000","0.25080000"]],"a":[["1775.60000000","1.44090000"],["1775.72000000","0.28320000"],["1775.73000000","0.00000000"],["1775.78000000","0.00300000"],["1775.92000000","0.32690000"],["1775.96000000","0.28460000"],["1776.03000000","52.53710000"],["1776.09000000","8.47880000"],["1776.13000000","2.82080000"],["1777.73000000","2.01680000"],["1777.83000000","0.20940000"]]}}
{"stream":"btcusdt@depth@100ms","data":{"e":"depthUpdate","E":1783465164115,"s":"BTCUSDT","U":97109082958,"u":97109082980,"b":[["63548.01000000","0.00000000"],["63547.95000000","0.00000000"],["63483.16000000","0.00000000"],["63479.92000000","0.04881000"],["63420.01000000","0.00014000"],["57195.92000000","0.00500000"]],"a":[["63551.03000000","0.37196000"],["63551.69000000","0.00000000"],["63551.70000000","0.00072000"],["63555.79000000","0.06482000"],["63573.37000000","0.00000000"],["63585.43000000","0.09130000"],["63592.58000000","0.00000000"],["63594.53000000","0.00000000"],["63657.99000000","0.00000000"],["63670.66000000","0.07658000"]]}}
{"stream":"btcusdt@depth@100ms","data":{"e":"depthUpdate","E":1783465164214,"s":"BTCUSDT","U":97109082981,"u":97109082995,"b":[["57195.92000000","0.00500000"],["50840.82000000","0.00044000"]],"a":[["63551.03000000","0.37166000"],["63551.69000000","0.00018000"],["63551.70000000","0.03985000"],["63555.79000000","0.06473000"],["63558.42000000","0.00048000"]]}}
{"stream":"ethusdt@depth@100ms","data":{"e":"depthUpdate","E":1783465164215,"s":"ETHUSDT","U":78545066477,"u":78545066487,"b":[["1775.59000000","18.61040000"],["1598.04000000","0.23700000"]],"a":[["1775.71000000","0.00000000"],["1775.73000000","0.00600000"]]}}
{"stream":"ethusdt@depth@100ms","data":{"e":"depthUpdate","E":1783465164316,"s":"ETHUSDT","U":78545066488,"u":78545066493,"b":[["1598.04000000","0.25080000"]],"a":[]}}
{"stream":"btcusdt@depth@100ms","data":{"e":"depthUpdate","E":1783465164315,"s":"BTCUSDT","U":97109082996,"u":97109083000,"b":[["63429.87000000","0.00000000"],["57195.92000000","0.00500000"]],"a":[]}}
{"stream":"btcusdt@trade","data":{"e":"trade","E":1783465164401,"s":"BTCUSDT","t":6486989288,"p":"63551.02000000","q":"0.00146000","T":1783465164400,"m":true,"M":true}}
{"stream":"ethusdt@depth@100ms","data":{"e":"depthUpdate","E":1783465164415,"s":"ETHUSDT","U":78545066494,"u":78545066498,"b":[["1675.60000000","3.67770000"],["1598.04000000","0.25780000"]],"a":[["1775.87000000","30.78760000"]]}}
{"stream":"btcusdt@depth@100ms","data":{"e":"depthUpdate","E":1783465164415,"s":"BTCUSDT","U":97109083001,"u":97109083015,"b":[["63551.02000000","1.81891000"],["63550.02000000","0.00036000"],["63549.15000000","0.00787000"],["63535.51000000","0.00000000"],["63516.72000000","0.00000000"],["63497.93000000","0.00520000"],["63479.15000000","0.00000000"],["63460.36000000","0.00000000"],["63441.57000000","0.00520000"],["63423.91000000","0.02000000"],["63422.78000000","0.00000000"],["63403.99000000","0.00000000"],["63385.20000000","0.00000000"],["63366.41000000","0.00000000"],["57195.92000000","0.00480000"],["57195.91000000","0.00000000"],["57195.90000000","0.00010000"],["40000.00000000","260.73952000"]],"a":[["63551.03000000","0.37148000"],["63551.70000000","0.04003000"],["63566.55000000","0.09433000"],["63567.95000000","0.00000000"],["63573.09000000","0.00000000"],["63591.88000000","0.00000000"],["63610.67000000","0.00519000"],["63629.45000000","0.00000000"],["63648.24000000","0.00000000"],["63667.03000000","0.00518000"],["63685.82000000","0.00000000"],["63704.61000000","0.00000000"],["63723.40000000","0.00000000"],["63742.19000000","0.00082000"]]}}
{"stream":"btcusdt@depth@100ms","data":{"e":"depthUpdate","E":1783465164514,"s":"BTCUSDT","U":97109083016,"u":97109083036,"b":[["63551.02000000","1.81921000"],["63550.02000000","0.00018000"],["63550.00000000","0.03818000"],["63539.97000000","0.00000000"],["63539.36000000","0.09449000"],["63420.14000000","0.09460000"],["57195.92000000","0.00480000"]],"a":[["63551.03000000","0.37196000"],["63558.42000000","0.00000000"],["63562.59000000","0.00000000"],["63563.43000000","0.09649000"],["63566.55000000","0.00000000"],["63567.95000000","0.46001000"]]}}
{"stream":"ethusdt@depth@100ms","data":{"e":"depthUpdate","E":1783465164515,"s":"ETHUSDT","U":78545066499,"u":78545066534,"b":[["1775.59000000","19.04740000"],["1775.31000000","7.88750000"],["1775.26000000","30.22350000"],["1775.24000000","0.27550000"],["1773.59000000","19.78160000"],["1773.38000000","0.13250000"],["1598.04000000","0.25780000"]],"a":[["1775.60000000","1.44090000"],["1775.61000000","0.19360000"],["1775.62000000","0.62190000"],["1775.63000000","3.84210000"],["1775.64000000","1.50300000"],["1775.67000000","11.27420000"],["1775.68000000","0.00880000"],["1775.73000000","0.00300000"],["1775.78000000","0.00000000"],["1775.87000000","7.88460000"],["1775.96000000","0.00290000"],["1775.99000000","8.64810000"],["1776.03000000","51.53710000"],["1776.43000000","0.44550000"],["1776.47000000","0.00840000"],["1776.48000000","20.76330000"],["1776.80000000","2.51220000"],["1777.61000000","7.88460000"],["1777.68000000","17.95090000"]]}}
{"stream":"btcusdt@depth@100ms","data":{"e":"depthUpdate","E":1783465164614,"s":"BTCUSDT","U":97109083037,"u":97109083054,"b":[["63540.21000000","0.00000000"],["63526.12000000","0.00000000"],["63512.03000000","0.00000000"],["63497.93000000","0.00000000"],["63483.84000000","0.00000000"],["63469.75000000","0.00000000"],["63455.66000000","0.00000000"],["63441.57000000","0.00000000"],["63427.48000000","0.00000000"],["63413.38000000","0.00000000"],["57195.92000000","0.00480000"],["50841.00000000","0.23623000"],["50840.82000000","0.00044000"]],"a":[["63551.03000000","0.37206000"],["63563.43000000","0.09649000"],["63568.39000000","0.00000000"],["63582.48000000","0.00000000"],["63596.57000000","0.00032000"],["63610.67000000","0.00000000"],["63617.96000000","0.03108000"],["63624.76000000","0.00000000"],["63638.85000000","0.00000000"],["63652.94000000","0.00000000"],["63667.03000000","0.00000000"],["63681.12000000","0.00000000"],["63695.22000000","0.00000000"],["63742.69000000","0.06309000"],["64504.30000000","0.00030000"]]}}
{"stream":"ethusdt@depth@100ms","data":{"e":"depthUpdate","E":1783465164615,"s":"ETHUSDT","U":78545066535,"u":78545066543,"b":[["1773.38000000","0.92170000"],["1598.04000000","0.24400000"]],"a":[["1775.60000000","1.44380000"],["1775.61000000","0.19650000"]]}}
{"stream":"btcusdt@depth@100ms","data":{"e":"depthUpdate","E":1783465164714,"s":"BTCUSDT","U":97109083055,"u":97109083073,"b":[["57195.92000000","0.00480000"],["57195.00000000","0.00087000"]],"a":[["63551.03000000","0.37158000"],["63558.49000000","0.00047000"],["63563.43000000","0.00200000"]]}}
{"stream":"ethusdt@depth@100ms","data":{"e":"depthUpdate","E":1783465164715,"s":"ETHUSDT","U":78545066544,"u":78545066549,"b":[["1774.51000000","3.90730000"],["1773.49000000","1.75850000"],["1773.38000000","0.13250000"],["1598.04000000","0.23700000"]],"a":[]}}
{"stream":"btcusdt@depth@100ms","data":{"e":"depthUpdate","E":1783465164815,"s":"BTCUSDT","U":97109083074,"u":97109083078,"b":[["57195.92000000","0.00500000"],["50000.00000000","542.70395000"]],"a":[["63563.44000000","0.09449000"]]}}
{"stream":"ethusdt@depth@100ms","data":{"e":"depthUpdate","E":1783465164816,"s":"ETHUSDT","U":78545066550,"u":78545066555,"b":[["1598.04000000","0.25080000"]],"a":[]}}
{"stream":"btcusdt@depth@100ms","data":{"e":"depthUpdate","E":1783465164914,"s":"BTCUSDT","U":97109083079,"u":97109083082,"b":[["57195.92000000","0.00500000"]],"a":[]}}
{"stream":"ethusdt@depth@100ms","data":{"e":"depthUpdate","E":1783465164916,"s":"ETHUSDT","U":78545066556,"u":78545066560,"b":[["1770.27000000","0.70920000"],["1598.04000000","0.25080000"]],"a":[]}}
{"stream":"btcusdt@depth@100ms","data":{"e":"depthUpdate","E":1783465165014,"s":"BTCUSDT","U":97109083083,"u":97109083093,"b":[["63537.00000000","0.00000000"],["63484.91000000","0.00037000"],["63421.66000000","0.00014000"],["63420.01000000","0.00000000"],["62597.75000000","0.00030000"],["57195.92000000","0.00480000"],["50840.82000000","0.00083000"]],"a":[["63562.43000000","0.00000000"],["63592.59000000","0.00392000"],["63655.82000000","0.00157000"]]}}
{"stream":"ethusdt@depth@100ms","data":{"e":"depthUpdate","E":1783465165015,"s":"ETHUSDT","U":78545066561,"u":78545066567,"b":[["1775.48000000","0.28170000"],["1775.41000000","1.78000000"],["1775.29000000","2.81790000"],["1775.25000000","2.48530000"],["1598.04000000","0.25080000"]],"a":[["1776.13000000","0.00290000"],["1776.16000000","22.24840000"]]}}
{"stream":"btcusdt@depth@100ms","data":{"e":"depthUpdate","E":1783465165115,"s":"BTCUSDT","U":97109083094,"u":97109083109,"b":[["63550.48000000","0.00787000"],["63549.15000000","0.00000000"],["63537.00000000","0.00008000"],["63484.91000000","0.00037000"],["63421.66000000","0.00014000"],["57195.92000000","0.00480000"]],"a":[["63551.69000000","0.00000000"],["63551.70000000","0.00072000"],["63555.79000000","0.06482000"],["63562.43000000","0.00008000"],["63592.59000000","0.00392000"],["63655.82000000","0.00157000"]]}}
{"stream":"ethusdt@depth@100ms","data":{"e":"depthUpdate","E":1783465165116,"s":"ETHUSDT","U":78545066568,"u":78545066575,"b":[["1770.33000000","41.81210000"],["1598.04000000","0.24400000"]],"a":[["1775.67000000","0.00300000"],["1775.70000000","11.27440000"]]}}
{"stream":"ethusdt@depth@100ms","data":{"e":"depthUpdate","E":1783465165215,"s":"ETHUSDT","U":78545066576,"u":78545066588,"b":[["1705.28000000","1.12640000"],["1705.25000000","0.00320000"],["1598.04000000","0.25780000"]],"a":[["1775.68000000","11.27990000"],["1775.70000000","0.00340000"],["1776.73000000","8.75610000"],["1776.98000000","5.59190000"],["1777.19000000","6.14800000"],["1777.36000000","2.82940000"]]}}
{"stream":"btcusdt@depth@100ms","data":{"e":"depthUpdate","E":1783465165215,"s":"BTCUSDT","U":97109083110,"u":97109083132,"b":[["63551.02000000","1.81939000"],["63550.00000000","0.03800000"],["63420.14000000","0.00000000"],["57195.92000000","0.00480000"],["50840.82000000","0.00044000"]],"a":[["63551.03000000","0.37158000"],["63551.70000000","0.00054000"],["63557.27000000","0.06473000"],["63563.44000000","0.09449000"],["63617.96000000","0.00000000"]]}}
{"stream":"btcusdt@depth@100ms","data":{"e":"depthUpdate","E":1783465165314,"s":"BTCUSDT","U":97109083133,"u":97109083140,"b":[["63550.48000000","0.00000000"],["63550.03000000","0.00787000"],["57195.92000000","0.00480000"]],"a":[["63627.89000000","0.00000000"],["63629.99000000","1.91970000"],["63742.69000000","0.00000000"]]}}
{"stream":"ethusdt@depth@100ms","data":{"e":"depthUpdate","E":1783465165317,"s":"ETHUSDT","U":78545066589,"u":78545066592,"b":[["1598.04000000","0.25780000"]],"a":[]}}
{"stream":"btcusdt@depth@100ms","data":{"e":"depthUpdate","E":1783465165414,"s":"BTCUSDT","U":97109083141,"u":97109083146,"b":[["63364.54000000","0.00840000"],["57195.92000000","0.00500000"],["40000.00000000","260.73952000"]],"a":[]}}
{"stream":"ethusdt@depth@100ms","data":{"e":"depthUpdate","E":1783465165415,"s":"ETHUSDT","U":78545066593,"u":78545066597,"b":[["1775.59000000","18.61040000"],["1773.60000000","0.43700000"],["1598.04000000","0.25080000"]],"a":[]}}
{"stream":"btcusdt@depth@100ms","data":{"e":"depthUpdate","E":1783465165514,"s":"BTCUSDT","U":97109083147,"u":97109083151,"b":[["63383.30000000","0.00840000"],["57195.92000000","0.00500000"]],"a":[]}}
{"stream":"ethusdt@depth@100ms","data":{"e":"depthUpdate","E":1783465165515,"s":"ETHUSDT","U":78545066598,"u":78545066611,"b":[["1775.24000000","0.27550000"],["1598.04000000","0.23700000"],["1067.00000000","6.86000000"]],"a":[["1775.69000000","0.28870000"],["1775.96000000","0.00290000"],["1776.01000000","26.69010000"],["1776.02000000","7.89300000"]]}}
{"stream":"btcusdt@depth@100ms","data":{"e":"depthUpdate","E":1783465165614,"s":"BTCUSDT","U":97109083152,"u":97109083165,"b":[["63411.45000000","0.00521000"],["63402.07000000","0.00840000"],["57195.92000000","0.00500000"],["50840.82000000","0.00044000"],["33000.00000000","35.16979000"]],"a":[["64504.30000000","0.00030000"]]}}
{"stream":"ethusdt@depth@100ms","data":{"e":"depthUpdate","E":1783465165615,"s":"ETHUSDT","U":78545066612,"u":78545066615,"b":[["1598.04000000","0.23700000"]],"a":[]}}
{"stream":"btcusdt@depth@100ms","data":{"e":"depthUpdate","E":1783465165714,"s":"BTCUSDT","U":97109083166,"u":97109083172,"b":[["63425.53000000","0.00521000"],["63420.83000000","0.00840000"],["57195.92000000","0.00480000"]],"a":[["63670.66000000","0.05068000"]]}}
{"stream":"ethusdt@depth@100ms","data":{"e":"depthUpdate","E":1783465165715,"s":"ETHUSDT","U":78545066616,"u":78545066623,"b":[["1774.03000000","13.08010000"],["1773.85000000","0.00000000"],["1598.04000000","0.25080000"]],"a":[]}}
{"stream":"btcusdt@depth@100ms","data":{"e":"depthUpdate","E":1783465165814,"s":"BTCUSDT","U":97109083173,"u":97109083181,"b":[["63439.60000000","0.01360000"],["57195.92000000","0.00480000"],["57195.00000000","0.00087000"]],"a":[["64064.18000000","0.00264000"]]}}
{"stream":"ethusdt@depth@100ms","data":{"e":"depthUpdate","E":1783465165815,"s":"ETHUSDT","U":78545066624,"u":78545066628,"b":[["1773.86000000","4.96820000"],["1598.04000000","0.25780000"]],"a":[]}}
{"stream":"btcusdt@depth@100ms","data":{"e":"depthUpdate","E":1783465165914,"s":"BTCUSDT","U":97109083182,"u":97109083213,"b":[["63551.02000000","1.81790000"],["63550.03000000","0.00000000"],["63550.00000000","0.03959000"],["63549.15000000","0.00787000"],["63548.01000000","0.00018000"],["63547.95000000","0.00009000"],["63546.90000000","0.45635000"],["63546.60000000","0.00000000"],["63539.36000000","0.00000000"],["63539.35000000","0.09449000"],["63537.08000000","0.70855000"],["63484.91000000","0.00000000"],["63458.37000000","0.00839000"],["63453.68000000","0.00520000"],["63421.66000000","0.00000000"],["57195.92000000","0.00480000"]],"a":[["63551.03000000","0.38526000"],["63551.69000000","0.00018000"],["63551.70000000","0.03985000"],["63555.79000000","0.06473000"],["63558.49000000","0.00000000"],["63558.70000000","0.93944000"],["63561.81000000","0.06455000"],["63561.82000000","2.83475000"],["63561.83000000","0.00000000"],["63566.55000000","0.12383000"],["63567.95000000","0.00000000"],["63582.63000000","0.00000000"]]}}
{"stream":"ethusdt@depth@100ms","data":{"e":"depthUpdate","E":1783465165915,"s":"ETHUSDT","U":78545066629,"u":78545066633,"b":[["1775.48000000","0.00000000"],["1775.46000000","0.63510000"],["1598.04000000","0.25780000"]],"a":[]}}
{"stream":"ethusdt@trade","data":{"e":"trade","E":1783465165952,"s":"ETHUSDT","t":4197008356,"p":"1775.59000000","q":"0.56660000","T":1783465165952,"m":true,"M":true}}
{"stream":"btcusdt@depth@100ms","data":{"e":"depthUpdate","E":1783465166014,"s":"BTCUSDT","U":97109083214,"u":97109083242,"b":[["63484.91000000","0.00037000"],["63479.92000000","0.00000000"],["63477.13000000","0.00839000"],["63467.75000000","0.00520000"],["63421.66000000","0.00014000"],["62597.75000000","0.00030000"],["57195.92000000","0.00480000"],["50840.82000000","0.00083000"]],"a":[["63551.03000000","0.38526000"],["63551.70000000","0.04003000"],["63557.27000000","0.06455000"],["63561.80000000","0.59046000"],["63565.24000000","0.00000000"],["63566.55000000","0.00000000"],["63567.95000000","0.45945000"],["63592.59000000","0.00392000"],["63627.89000000","1.91970000"],["63629.99000000","0.00000000"],["63655.82000000","0.00157000"],["63670.66000000","0.00000000"]]}}
{"stream":"ethusdt@depth@100ms","data":{"e":"depthUpdate","E":1783465166015,"s":"ETHUSDT","U":78545066634,"u":78545066641,"b":[["1775.59000000","18.04380000"],["1598.04000000","0.23700000"]],"a":[["1775.97000000","0.58310000"],["1775.99000000","8.36640000"],["1777.67000000","0.13460000"]]}}
{"stream":"btcusdt@depth@100ms","data":{"e":"depthUpdate","E":1783465166114,"s":"BTCUSDT","U":97109083243,"u":97109083263,"b":[["63537.00000000","0.00008000"],["63495.90000000","0.00848000"],["63484.91000000","0.00000000"],["63481.83000000","0.00520000"],["63471.32000000","0.16051000"],["63421.66000000","0.00014000"],["57195.92000000","0.00500000"]],"a":[["63551.70000000","0.06930000"],["63555.18000000","0.00009000"],["63555.19000000","0.06463000"],["63555.78000000","0.00009000"],["63562.43000000","0.00008000"],["63566.58000000","0.00000000"],["63567.94000000","0.44772000"],["63567.95000000","0.00000000"],["63592.59000000","0.00392000"],["63655.82000000","0.00157000"],["63662.03000000","0.05327000"]]}}
{"stream":"ethusdt@depth@100ms","data":{"e":"depthUpdate","E":1783465166115,"s":"ETHUSDT","U":78545066642,"u":78545066647,"b":[["1598.04000000","0.25080000"]],"a":[]}}
{"stream":"btcusdt@depth@100ms","data":{"e":"depthUpdate","E":1783465166214,"s":"BTCUSDT","U":97109083264,"u":97109083279,"b":[["63514.67000000","0.00838000"],["63495.90000000","0.01368000"],["57195.92000000","0.00500000"],["50840.82000000","0.00044000"]],"a":[["63554.89000000","0.06434000"],["63555.19000000","0.06481000"],["63555.80000000","0.52429000"],["63582.63000000","0.17981000"]]}}
{"stream":"ethusdt@depth@100ms","data":{"e":"depthUpdate","E":1783465166215,"s":"ETHUSDT","U":78545066648,"u":78545066653,"b":[["1598.04000000","0.25080000"]],"a":[["1775.66000000","11.27430000"],["1775.68000000","0.00880000"]]}}
{"stream":"btcusdt@depth@100ms","data":{"e":"depthUpdate","E":1783465166314,"s":"BTCUSDT","U":97109083280,"u":97109083285,"b":[["63533.43000000","0.00838000"],["63509.98000000","0.00520000"],["57195.92000000","0.00500000"]],"a":[]}}
{"stream":"ethusdt@depth@100ms","data":{"e":"depthUpdate","E":1783465166317,"s":"ETHUSDT","U":78545066654,"u":78545066657,"b":[["1598.04000000","0.25080000"]],"a":[]}}
{"stream":"btcusdt@depth@100ms","data":{"e":"depthUpdate","E":1783465166414,"s":"BTCUSDT","U":97109083286,"u":97109083294,"b":[["63532.20000000","0.00000000"],["63532.19000000","0.00961000"],["63524.05000000","0.00520000"],["57195.92000000","0.00480000"],["40000.00000000","260.73952000"]],"a":[["63570.97000000","0.00838000"]]}}
{"stream":"ethusdt@depth@100ms","data":{"e":"depthUpdate","E":1783465166415,"s":"ETHUSDT","U":78545066658,"u":78545066661,"b":[["1598.04000000","0.25080000"]],"a":[]}}
{"stream":"btcusdt@depth@100ms","data":{"e":"depthUpdate","E":1783465166514,"s":"BTCUSDT","U":97109083295,"u":97109083301,"b":[["63538.13000000","0.01375000"],["63508.80000000","0.00000000"],["57195.92000000","0.00480000"]],"a":[["63589.73000000","0.00837000"]]}}
{"stream":"ethusdt@depth@100ms","data":{"e":"depthUpdate","E":1783465166515,"s":"ETHUSDT","U":78545066662,"u":78545066671,"b":[["1775.24000000","0.27260000"],["1598.04000000","0.24400000"]],"a":[["1775.64000000","1.78280000"],["1775.65000000","0.00890000"],["1775.73000000","0.00000000"],["1775.96000000","0.00000000"],["1779.87000000","0.88210000"]]}}
{"stream":"ethusdt@depth@100ms","data":{"e":"depthUpdate","E":1783465166615,"s":"ETHUSDT","U":78545066672,"u":78545066679,"b":[["1775.24000000","0.27550000"],["1598.04000000","0.25780000"]],"a":[["1775.96000000","0.00290000"]]}}
{"stream":"btcusdt@depth@100ms","data":{"e":"depthUpdate","E":1783465166615,"s":"BTCUSDT","U":97109083302,"u":97109083313,"b":[["57195.92000000","0.00480000"],["50840.82000000","0.00044000"]],"a":[["63566.27000000","0.00520000"],["63608.50000000","0.00837000"],["64504.30000000","0.00030000"]]}}
{"stream":"btcusdt@depth@100ms","data":{"e":"depthUpdate","E":1783465166714,"s":"BTCUSDT","U":97109083314,"u":97109083320,"b":[["57195.92000000","0.00480000"]],"a":[["63580.35000000","0.00519000"],["63592.59000000","0.00000000"],["63627.27000000","0.00837000"]]}}
{"stream":"ethusdt@depth@100ms","data":{"e":"depthUpdate","E":1783465166715,"s":"ETHUSDT","U":78545066680,"u":78545066682,"b":[["1598.04000000","0.25080000"]],"a":[]}}
{"stream":"btcusdt@trade","data":{"e":"trade","E":1783465166736,"s":"BTCUSDT","t":6486989289,"p":"63551.03000000","q":"0.00126000","T":1783465166736,"m":false,"M":true}}
{"stream":"ethusdt@depth@100ms","data":{"e":"depthUpdate","E":1783465166815,"s":"ETHUSDT","U":78545066683,"u":78545066687,"b":[["1598.04000000","0.25080000"]],"a":[["1779.16000000","0.33760000"]]}}
{"stream":"btcusdt@depth@100ms","data":{"e":"depthUpdate","E":1783465166815,"s":"BTCUSDT","U":97109083321,"u":97109083343,"b":[["63551.02000000","1.81754000"],["63550.00000000","0.03818000"],["63549.15000000","0.00957000"],["63452.24000000","0.02464000"],["63447.99000000","0.00472000"],["57195.92000000","0.00510000"],["57195.90000000","0.00000000"],["57195.00000000","0.00107000"]],"a":[["63551.03000000","0.38400000"],["63594.42000000","0.00519000"],["63646.03000000","0.00837000"]]}}
{"stream":"ethusdt@depth@100ms","data":{"e":"depthUpdate","E":1783465166916,"s":"ETHUSDT","U":78545066688,"u":78545066695,"b":[["1773.49000000","1.13840000"],["1773.21000000","1.84610000"],["1598.04000000","0.23700000"]],"a":[]}}
{"stream":"btcusdt@depth@100ms","data":{"e":"depthUpdate","E":1783465166916,"s":"BTCUSDT","U":97109083344,"u":97109083351,"b":[["57195.92000000","0.00500000"],["57195.00000000","0.00087000"]],"a":[["63608.50000000","0.01356000"],["63664.80000000","0.00836000"]]}}
{"stream":"btcusdt@depth@100ms","data":{"e":"depthUpdate","E":1783465167014,"s":"BTCUSDT","U":97109083352,"u":97109083364,"b":[["63482.01000000","0.00037000"],["63452.24000000","0.00000000"],["63444.32000000","0.02464000"],["63421.66000000","0.00000000"],["63418.01000000","0.00014000"],["62597.75000000","0.00000000"],["57195.92000000","0.00480000"],["50840.82000000","0.00083000"]],"a":[["63595.78000000","0.00392000"],["63622.57000000","0.00519000"],["63655.82000000","0.00000000"],["63659.99000000","0.00157000"],["63683.57000000","0.00836000"]]}}
{"stream":"ethusdt@depth@100ms","data":{"e":"depthUpdate","E":1783465167016,"s":"ETHUSDT","U":78545066696,"u":78545066706,"b":[["1598.04000000","0.25080000"]],"a":[["1777.56000000","32.96440000"],["1777.60000000","11.46150000"],["1777.68000000","0.01320000"],["1782.71000000","0.94190000"]]}}
{"stream":"btcusdt@depth@100ms","data":{"e":"depthUpdate","E":1783465167114,"s":"BTCUSDT","U":97109083365,"u":97109083382,"b":[["63537.00000000","0.00008000"],["63482.01000000","0.00000000"],["63444.32000000","0.00000000"],["63418.01000000","0.00014000"],["62597.75000000","0.00030000"],["57195.92000000","0.00480000"]],"a":[["63562.43000000","0.00008000"],["63594.53000000","0.00393000"],["63595.78000000","0.00000000"],["63636.65000000","0.00519000"],["63659.99000000","0.00000000"],["63702.33000000","0.00836000"]]}}
{"stream":"ethusdt@depth@100ms","data":{"e":"depthUpdate","E":1783465167115,"s":"ETHUSDT","U":78545066707,"u":78545066710,"b":[["1598.04000000","0.25780000"]],"a":[["1786.26000000","0.00470000"]]}}
{"stream":"btcusdt@trade","data":{"e":"trade","E":1783465167124,"s":"BTCUSDT","t":6486989290,"p":"63551.03000000","q":"0.00089000","T":1783465167124,"m":false,"M":true}}
{"stream":"btcusdt@depth@100ms","data":{"e":"depthUpdate","E":1783465167214,"s":"BTCUSDT","U":97109083383,"u":97109083405,"b":[["63551.02000000","1.81762000"],["63550.23000000","0.70840000"],["63550.01000000","0.23845000"],["63550.00000000","0.03836000"],["63549.99000000","0.00173000"],["63549.15000000","0.00805000"],["63548.01000000","0.00000000"],["63537.08000000","0.00015000"],["63510.80000000","2.26261000"],["57195.92000000","0.00480000"],["50840.82000000","0.00044000"]],"a":[["63551.03000000","0.38311000"],["63566.55000000","0.08173000"],["63567.94000000","0.00008000"],["63594.81000000","0.00000000"],["63650.72000000","0.00519000"],["63721.10000000","0.00845000"]]}}
{"stream":"ethusdt@depth@100ms","data":{"e":"depthUpdate","E":1783465167215,"s":"ETHUSDT","U":78545066711,"u":78545066715,"b":[["1770.33000000","0.00000000"],["1598.04000000","0.25780000"]],"a":[]}}
{"stream":"ethusdt@depth@100ms","data":{"e":"depthUpdate","E":1783465167317,"s":"ETHUSDT","U":78545066716,"u":78545066727,"b":[["1775.06000000","14.92790000"],["1775.03000000","16.58700000"],["1774.87000000","0.43990000"],["1598.04000000","0.25780000"],["1067.00000000","6.86000000"]],"a":[["1789.81000000","0.00000000"]]}}
{"stream":"btcusdt@depth@100ms","data":{"e":"depthUpdate","E":1783465167317,"s":"BTCUSDT","U":97109083406,"u":97109083437,"b":[["63551.02000000","1.81770000"],["63550.25000000","0.00018000"],["63550.24000000","0.23827000"],["63550.23000000","0.70858000"],["63550.02000000","0.00000000"],["63550.01000000","0.00018000"],["63550.00000000","0.03818000"],["63547.95000000","0.00018000"],["63547.94000000","0.06482000"],["63547.92000000","1.12821000"],["63539.35000000","0.00000000"],["63539.33000000","0.09449000"],["57195.92000000","0.00480000"]],"a":[["63664.80000000","0.01355000"],["63739.86000000","0.00835000"]]}}
{"stream":"btcusdt@depth@100ms","data":{"e":"depthUpdate","E":1783465167414,"s":"BTCUSDT","U":97109083438,"u":97109083459,"b":[["63551.02000000","1.81762000"],["63550.24000000","0.23845000"],["63550.23000000","0.70858000"],["63550.01000000","0.00000000"],["63501.01000000","0.00025000"],["57195.92000000","0.00500000"],["50841.00000000","0.23623000"],["40000.00000000","260.73952000"]],"a":[["63678.87000000","0.00519000"]]}}
{"stream":"ethusdt@depth@100ms","data":{"e":"depthUpdate","E":1783465167415,"s":"ETHUSDT","U":78545066728,"u":78545066733,"b":[["1770.33000000","41.82570000"],["1598.04000000","0.23700000"]],"a":[]}}
{"stream":"ethusdt@depth@100ms","data":{"e":"depthUpdate","E":1783465167515,"s":"ETHUSDT","U":78545066734,"u":78545066742,"b":[["1772.18000000","0.88210000"],["1771.86000000","0.00580000"],["1598.04000000","0.25080000"]],"a":[["1779.15000000","0.00340000"]]}}
{"stream":"btcusdt@depth@100ms","data":{"e":"depthUpdate","E":1783465167515,"s":"BTCUSDT","U":97109083460,"u":97109083464,"b":[["57195.92000000","0.00500000"]],"a":[["63692.95000000","0.00518000"]]}}
{"stream":"btcusdt@depth@100ms","data":{"e":"depthUpdate","E":1783465167614,"s":"BTCUSDT","U":97109083465,"u":97109083475,"b":[["57195.92000000","0.00500000"],["50840.82000000","0.00044000"]],"a":[["64504.30000000","0.00030000"],["77811.66000000","0.00019000"]]}}
{"stream":"ethusdt@depth@100ms","data":{"e":"depthUpdate","E":1783465167616,"s":"ETHUSDT","U":78545066743,"u":78545066749,"b":[["1775.24000000","0.27550000"],["1598.04000000","0.25080000"]],"a":[["1775.96000000","0.00290000"]]}}
{"stream":"btcusdt@depth@100ms","data":{"e":"depthUpdate","E":1783465167714,"s":"BTCUSDT","U":97109083476,"u":97109083485,"b":[["63551.02000000","1.81762000"],["63550.26000000","0.00787000"],["63549.99000000","0.00000000"],["63549.15000000","0.00018000"],["57195.92000000","0.00480000"]],"a":[["63551.03000000","0.38526000"],["63627.89000000","0.00000000"],["63629.99000000","1.91970000"]]}}
{"stream":"ethusdt@depth@100ms","data":{"e":"depthUpdate","E":1783465167715,"s":"ETHUSDT","U":78545066750,"u":78545066756,"b":[["1772.18000000","0.00000000"],["1598.04000000","0.25080000"]],"a":[["1775.97000000","0.30140000"],["1775.98000000","0.44830000"],["1782.70000000","0.00340000"]]}}
{"stream":"btcusdt@depth@100ms","data":{"e":"depthUpdate","E":1783465167814,"s":"BTCUSDT","U":97109083486,"u":97109083503,"b":[["63551.02000000","1.81762000"],["63550.26000000","0.00805000"],["63550.00000000","0.03818000"],["63549.15000000","0.00000000"],["57195.92000000","0.00480000"],["50000.00000000","542.70415000"]],"a":[["63558.82000000","0.01287000"]]}}
{"stream":"ethusdt@depth@100ms","data":{"e":"depthUpdate","E":1783465167815,"s":"ETHUSDT","U":78545066757,"u":78545066761,"b":[["1598.04000000","0.24400000"]],"a":[]}}
{"stream":"btcusdt@depth@100ms","data":{"e":"depthUpdate","E":1783465167915,"s":"BTCUSDT","U":97109083504,"u":97109083520,"b":[["63550.24000000","0.04026000"],["63550.23000000","0.00018000"],["63550.01000000","0.00018000"],["63548.01000000","0.00018000"],["63547.94000000","0.06473000"],["57195.92000000","0.00480000"],["57195.00000000","0.00087000"]],"a":[["63551.04000000","0.00141000"]]}}
{"stream":"ethusdt@depth@100ms","data":{"e":"depthUpdate","E":1783465167915,"s":"ETHUSDT","U":78545066762,"u":78545066768,"b":[["1598.04000000","0.25780000"]],"a":[["1786.25000000","0.00340000"]]}}
{"stream":"btcusdt@depth@100ms","data":{"e":"depthUpdate","E":1783465168014,"s":"BTCUSDT","U":97109083521,"u":97109083540,"b":[["63551.02000000","1.81754000"],["63550.24000000","0.04026000"],["63550.23000000","0.00000000"],["63547.92000000","1.12839000"],["63483.16000000","0.00037000"],["63419.11000000","0.00014000"],["63418.01000000","0.00000000"],["57195.92000000","0.00480000"],["50840.82000000","0.00083000"]],"a":[["63566.55000000","0.00000000"],["63567.95000000","0.39559000"],["63594.53000000","0.00393000"],["63657.99000000","0.00157000"]]}}
{"stream":"ethusdt@depth@100ms","data":{"e":"depthUpdate","E":1783465168015,"s":"ETHUSDT","U":78545066769,"u":78545066781,"b":[["1773.21000000","0.00000000"],["1598.04000000","0.25080000"]],"a":[["1775.60000000","1.44380000"],["1775.62000000","0.61190000"],["1775.63000000","0.63830000"],["1775.65000000","0.00590000"],["1775.66000000","0.00300000"],["1775.68000000","0.01180000"],["1775.71000000","11.27100000"]]}}
{"stream":"ethusdt@depth@100ms","data":{"e":"depthUpdate","E":1783465168115,"s":"ETHUSDT","U":78545066782,"u":78545066788,"b":[["1775.48000000","0.28170000"],["1775.46000000","0.35340000"],["1773.49000000","1.75850000"],["1598.04000000","0.25080000"]],"a":[["1789.80000000","0.00620000"]]}}
{"stream":"btcusdt@depth@100ms","data":{"e":"depthUpdate","E":1783465168115,"s":"BTCUSDT","U":97109083541,"u":97109083558,"b":[["63550.26000000","0.00018000"],["63549.15000000","0.00787000"],["63537.00000000","0.00008000"],["63536.44000000","0.70840000"],["63483.16000000","0.00000000"],["63419.11000000","0.00014000"],["62597.75000000","0.00030000"],["57195.92000000","0.00500000"]],"a":[["63551.03000000","0.37206000"],["63554.52000000","0.01320000"],["63562.43000000","0.00008000"],["63594.53000000","0.00000000"],["63657.99000000","0.00157000"]]}}
{"stream":"btcusdt@depth@100ms","data":{"e":"depthUpdate","E":1783465168214,"s":"BTCUSDT","U":97109083559,"u":97109083587,"b":[["63551.02000000","1.81754000"],["63550.26000000","0.00000000"],["63550.00000000","0.03982000"],["63549.15000000","0.00805000"],["57195.92000000","0.00500000"],["50840.82000000","0.00044000"]],"a":[["63551.03000000","0.37215000"],["63551.04000000","0.00150000"],["63554.36000000","0.04022000"],["63554.52000000","0.01338000"],["63555.79000000","0.06455000"],["63566.55000000","0.08262000"],["63567.95000000","0.00000000"]]}}
{"stream":"ethusdt@depth@100ms","data":{"e":"depthUpdate","E":1783465168216,"s":"ETHUSDT","U":78545066789,"u":78545066795,"b":[["1598.04000000","0.25080000"]],"a":[["1775.70000000","3.83420000"],["1777.61000000","8.01920000"],["1777.67000000","0.00000000"]]}}
{"stream":"btcusdt@depth@100ms","data":{"e":"depthUpdate","E":1783465168314,"s":"BTCUSDT","U":97109083588,"u":97109083594,"b":[["63539.33000000","0.00000000"],["63510.80000000","2.46062000"],["57195.92000000","0.00534000"]],"a":[]}}
{"stream":"ethusdt@depth@100ms","data":{"e":"depthUpdate","E":1783465168317,"s":"ETHUSDT","U":78545066796,"u":78545066801,"b":[["1598.04000000","0.23700000"]],"a":[]}}
{"stream":"btcusdt@depth@100ms","data":{"e":"depthUpdate","E":1783465168414,"s":"BTCUSDT","U":97109083595,"u":97109083703,"b":[["63551.02000000","1.09285000"],["63551.01000000","0.00368000"],["63550.25000000","0.00000000"],["63550.24000000","0.00018000"],["63549.15000000","0.00018000"],["63548.57000000","0.00000000"],["63547.94000000","0.00018000"],["63547.93000000","0.00018000"],["63547.92000000","0.00018000"],["63547.91000000","0.00000000"],["63547.85000000","0.00000000"],["63547.49000000","0.00000000"],["63546.93000000","0.00000000"],["63546.91000000","0.00000000"],["63546.90000000","0.00008000"],["63546.36000000","0.00000000"],["63545.56000000","0.00787000"],["63545.37000000","0.46020000"],["63545.36000000","0.00000000"],["63545.35000000","0.00000000"],["63544.11000000","0.00000000"],["63543.68000000","0.00000000"],["63542.52000000","0.42497000"],["63539.31000000","0.00000000"],["63538.87000000","0.09450000"],["63532.19000000","0.00000000"],["63528.67000000","0.05670000"],["63528.36000000","0.56707000"],["63526.72000000","0.39563000"],["63524.37000000","0.00000000"],["63481.31000000","2.83475000"],["63416.02000000","0.03951000"],["63304.87000000","4.74387000"],["57195.92000000","0.00514000"],["40000.00000000","260.73952000"]],"a":[["63551.03000000","1.60334000"],["63551.04000000","0.00114000"],["63554.74000000","0.00787000"],["63554.88000000","0.00000000"],["63555.18000000","0.00000000"],["63555.78000000","0.00000000"],["63557.07000000","0.00400000"],["63557.77000000","0.00000000"],["63558.44000000","0.00000000"],["63558.69000000","0.45627000"],["63558.89000000","0.00000000"],["63559.64000000","0.00000000"],["63561.13000000","0.00264000"],["63561.81000000","0.00000000"],["63561.89000000","0.02000000"],["63561.95000000","0.61333000"],["63562.17000000","0.00252000"],["63566.55000000","0.00000000"],["63567.76000000","0.56672000"],["63568.88000000","0.22500000"],["63579.42000000","0.00000000"],["63582.49000000","0.00008000"],["63582.51000000","0.00000000"]]}}
{"stream":"ethusdt@depth@100ms","data":{"e":"depthUpdate","E":1783465168415,"s":"ETHUSDT","U":78545066802,"u":78545066842,"b":[["1775.59000000","17.61090000"],["1775.52000000","0.03880000"],["1775.51000000","0.00300000"],["1775.48000000","0.00300000"],["1775.47000000","0.43700000"],["1775.46000000","0.07260000"],["1775.42000000","0.00000000"],["1775.39000000","0.72450000"],["1775.33000000","8.46160000"],["1775.29000000","0.00000000"],["1775.23000000","3.29420000"],["1773.86000000","7.15770000"],["1773.85000000","9.46160000"],["1773.80000000","8.32450000"],["1598.04000000","0.25080000"]],"a":[["1775.60000000","11.27850000"],["1775.61000000","0.18490000"],["1775.63000000","3.92270000"],["1775.67000000","0.00600000"],["1775.68000000","11.27990000"],["1775.70000000","0.00340000"],["1775.71000000","0.00000000"],["1775.87000000","15.76920000"],["1775.90000000","1.07000000"],["1775.98000000","0.16660000"],["1777.56000000","15.02670000"],["1777.61000000","25.95690000"]]}}
{"stream":"btcusdt@depth@100ms","data":{"e":"depthUpdate","E":1783465168514,"s":"BTCUSDT","U":97109083704,"u":97109083792,"b":[["63551.02000000","1.06699000"],["63550.71000000","0.00000000"],["63550.24000000","0.00000000"],["63550.00000000","0.03982000"],["63549.15000000","0.00000000"],["63549.13000000","0.09156000"],["63548.00000000","0.02818000"],["63547.95000000","0.00000000"],["63547.94000000","0.00000000"],["63547.93000000","0.00000000"],["63547.92000000","0.00000000"],["63547.90000000","0.00008000"],["63547.57000000","0.00675000"],["63546.90000000","0.00000000"],["63546.48000000","0.00032000"],["63546.30000000","0.00018000"],["63546.29000000","0.02018000"],["63546.01000000","0.00009000"],["63546.00000000","0.02818000"],["63545.56000000","0.00805000"],["63545.55000000","0.01000000"],["63545.37000000","0.00000000"],["63544.79000000","0.22265000"],["63544.78000000","0.06455000"],["63543.74000000","0.06455000"],["63542.77000000","0.00047000"],["63542.70000000","0.06455000"],["63542.69000000","0.00188000"],["63542.59000000","0.00048000"],["63542.53000000","0.52467000"],["63522.09000000","0.00400000"],["63471.32000000","0.00000000"],["57195.92000000","0.00514000"]],"a":[["63551.03000000","1.62694000"],["63554.52000000","0.01338000"],["63554.74000000","0.00805000"],["63555.48000000","0.00400000"],["63555.67000000","0.00862000"],["63558.45000000","0.00000000"],["63559.48000000","0.00252000"],["63561.13000000","0.00012000"],["63562.17000000","0.00000000"],["63580.92000000","0.00000000"],["63662.03000000","0.00000000"]]}}
{"stream":"ethusdt@depth@100ms","data":{"e":"depthUpdate","E":1783465168515,"s":"ETHUSDT","U":78545066843,"u":78545066871,"b":[["1775.59000000","18.04060000"],["1775.54000000","0.00300000"],["1775.53000000","0.01440000"],["1775.48000000","0.00600000"],["1775.42000000","0.00300000"],["1775.39000000","0.44280000"],["1775.34000000","14.19010000"],["1775.33000000","0.57700000"],["1774.03000000","1.00530000"],["1773.60000000","8.32160000"],["1773.54000000","1.00140000"],["1598.04000000","0.25780000"]],"a":[["1775.60000000","11.90630000"],["1775.61000000","0.19360000"],["1775.64000000","13.05420000"],["1775.67000000","0.00300000"],["1775.68000000","0.00880000"],["1775.78000000","0.00300000"],["1775.87000000","30.78760000"]]}}
{"stream":"btcusdt@depth@100ms","data":{"e":"depthUpdate","E":1783465168614,"s":"BTCUSDT","U":97109083793,"u":97109083820,"b":[["63551.02000000","1.06699000"],["63551.01000000","0.00368000"],["63550.00000000","0.03818000"],["63549.12000000","0.00552000"],["63545.55000000","0.01000000"],["63538.87000000","0.00000000"],["63538.86000000","0.09450000"],["63477.84000000","0.04882000"],["57195.92000000","0.00514000"],["50840.82000000","0.00044000"]],"a":[["63668.57000000","0.07658000"]]}}
{"stream":"ethusdt@depth@100ms","data":{"e":"depthUpdate","E":1783465168615,"s":"ETHUSDT","U":78545066872,"u":78545066883,"b":[["1775.54000000","0.00900000"],["1775.53000000","0.45140000"],["1775.42000000","0.00000000"],["1775.24000000","0.27550000"],["1773.54000000","0.56440000"],["1598.04000000","0.25780000"]],"a":[["1775.96000000","0.00290000"]]}}
{"stream":"ethusdt@trade","data":{"e":"trade","E":1783465168644,"s":"ETHUSDT","t":4197008357,"p":"1775.60000000","q":"0.00980000","T":1783465168644,"m":false,"M":true}}
{"stream":"ethusdt@trade","data":{"e":"trade","E":1783465168657,"s":"ETHUSDT","t":4197008358,"p":"1775.60000000","q":"0.28150000","T":1783465168657,"m":false,"M":true}}
{"stream":"btcusdt@depth@100ms","data":{"e":"depthUpdate","E":1783465168714,"s":"BTCUSDT","U":97109083821,"u":97109083838,"b":[["63549.13000000","0.09156000"],["63549.12000000","0.00570000"],["63545.55000000","0.00982000"],["57195.92000000","0.00514000"],["50840.82000000","0.00044000"]],"a":[["63558.63000000","0.09070000"],["63565.39000000","0.56674000"],["64504.30000000","0.00030000"]]}}
{"stream":"ethusdt@depth@100ms","data":{"e":"depthUpdate","E":1783465168715,"s":"ETHUSDT","U":78545066884,"u":78545066890,"b":[["1598.04000000","0.23700000"]],"a":[["1775.60000000","11.61500000"]]}}
{"stream":"ethusdt@trade","data":{"e":"trade","E":1783465168783,"s":"ETHUSDT","t":4197008359,"p":"1775.60000000","q":"0.08950000","T":1783465168783,"m":false,"M":true}}
{"stream":"btcusdt@depth@100ms","data":{"e":"depthUpdate","E":1783465168814,"s":"BTCUSDT","U":97109083839,"u":97109083841,"b":[["57195.92000000","0.00534000"]],"a":[]}}
{"stream":"ethusdt@depth@100ms","data":{"e":"depthUpdate","E":1783465168815,"s":"ETHUSDT","U":78545066891,"u":78545066898,"b":[["1598.04000000","0.25080000"],["1598.03000000","0.00350000"]],"a":[["1775.60000000","11.52550000"]]}}
{"stream":"ethusdt@depth@100ms","data":{"e":"depthUpdate","E":1783465168916,"s":"ETHUSDT","U":78545066899,"u":78545066905,"b":[["1773.49000000","1.13840000"],["1598.04000000","0.25080000"],["1598.03000000","0.00000000"]],"a":[["1778.72000000","0.00000000"]]}}
{"stream":"btcusdt@depth@100ms","data":{"e":"depthUpdate","E":1783465168916,"s":"BTCUSDT","U":97109083842,"u":97109083847,"b":[["63551.02000000","1.10500000"],["58466.94000000","0.00018000"],["57195.92000000","0.00534000"]],"a":[]}}
{"stream":"btcusdt@depth@100ms","data":{"e":"depthUpdate","E":1783465169014,"s":"BTCUSDT","U":97109083848,"u":97109083861,"b":[["63484.91000000","0.00037000"],["63421.06000000","0.00014000"],["63419.11000000","0.00000000"],["57195.92000000","0.00514000"],["57195.00000000","0.00087000"],["50840.82000000","0.00083000"]],"a":[["63561.95000000","0.53329000"],["63563.21000000","0.24837000"],["63565.24000000","0.78729000"],["63570.15000000","0.00000000"],["63593.99000000","0.00388000"],["63625.79000000","1.91970000"],["63629.99000000","0.00000000"],["63657.33000000","0.00157000"],["63657.99000000","0.00000000"]]}}
{"stream":"ethusdt@depth@100ms","data":{"e":"depthUpdate","E":1783465169015,"s":"ETHUSDT","U":78545066906,"u":78545066915,"b":[["1775.37000000","1.06270000"],["1775.34000000","13.90840000"],["1775.23000000","0.47630000"],["1775.19000000","18.46530000"],["1773.20000000","1.84900000"],["1598.04000000","0.25080000"]],"a":[["1775.87000000","31.06930000"],["1775.90000000","0.78830000"],["1776.04000000","3.26330000"],["1776.16000000","19.43050000"],["1778.54000000","8.75290000"]]}}
{"stream":"btcusdt@depth@100ms","data":{"e":"depthUpdate","E":1783465169114,"s":"BTCUSDT","U":97109083862,"u":97109083876,"b":[["63537.00000000","0.00000000"],["63484.91000000","0.00037000"],["63421.06000000","0.00000000"],["62597.75000000","0.00030000"],["57195.92000000","0.00514000"]],"a":[["63562.43000000","0.00000000"],["63562.55000000","0.09434000"],["63563.21000000","0.00000000"],["63592.59000000","0.00392000"],["63593.99000000","0.00000000"],["63657.33000000","0.00000000"]]}}
{"stream":"ethusdt@depth@100ms","data":{"e":"depthUpdate","E":1783465169115,"s":"ETHUSDT","U":78545066916,"u":78545066921,"b":[["1598.04000000","0.25780000"],["1067.00000000","6.86000000"]],"a":[["1775.87000000","30.78760000"],["1775.88000000","20.76490000"]]}}
{"stream":"btcusdt@depth@100ms","data":{"e":"depthUpdate","E":1783465169214,"s":"BTCUSDT","U":97109083877,"u":97109083885,"b":[["63537.00000000","0.00008000"],["63536.44000000","0.00000000"],["63520.03000000","0.70840000"],["57195.92000000","0.00514000"],["50840.82000000","0.00044000"]],"a":[["63562.43000000","0.00008000"]]}}
{"stream":"ethusdt@depth@100ms","data":{"e":"depthUpdate","E":1783465169215,"s":"ETHUSDT","U":78545066922,"u":78545066927,"b":[["1598.04000000","0.24400000"]],"a":[]}}
{"stream":"ethusdt@depth@100ms","data":{"e":"depthUpdate","E":1783465169315,"s":"ETHUSDT","U":78545066928,"u":78545066933,"b":[["1598.04000000","0.25780000"]],"a":[]}}
{"stream":"btcusdt@depth@100ms","data":{"e":"depthUpdate","E":1783465169315,"s":"BTCUSDT","U":97109083886,"u":97109083899,"b":[["57195.92000000","0.00514000"],["50841.00000000","0.23623000"]],"a":[]}}
{"stream":"btcusdt@depth@100ms","data":{"e":"depthUpdate","E":1783465169414,"s":"BTCUSDT","U":97109083900,"u":97109083905,"b":[["57195.92000000","0.00500000"],["40000.00000000","260.73952000"]],"a":[]}}
{"stream":"ethusdt@depth@100ms","data":{"e":"depthUpdate","E":1783465169415,"s":"ETHUSDT","U":78545066934,"u":78545066936,"b":[["1598.04000000","0.25080000"]],"a":[]}}
{"stream":"btcusdt@depth@100ms","data":{"e":"depthUpdate","E":1783465169514,"s":"BTCUSDT","U":97109083906,"u":97109083910,"b":[["58466.94000000","0.00000000"],["57195.92000000","0.00500000"]],"a":[]}}
{"stream":"ethusdt@depth@100ms","data":{"e":"depthUpdate","E":1783465169515,"s":"ETHUSDT","U":78545066937,"u":78545066941,"b":[["1773.85000000","21.53640000"],["1598.04000000","0.25080000"]],"a":[]}}
{"stream":"btcusdt@depth@100ms","data":{"e":"depthUpdate","E":1783465169614,"s":"BTCUSDT","U":97109083911,"u":97109083920,"b":[["63520.03000000","0.00000000"],["63503.17000000","1.77560000"],["63476.55000000","1.16572000"],["63456.71000000","0.19045000"],["63436.01000000","0.02033000"],["57195.92000000","0.00500000"],["50840.82000000","0.00064000"]],"a":[]}}
{"stream":"ethusdt@depth@100ms","data":{"e":"depthUpdate","E":1783465169615,"s":"ETHUSDT","U":78545066942,"u":78545066956,"b":[["1775.49000000","0.44000000"],["1775.48000000","0.28970000"],["1775.24000000","0.27550000"],["1773.86000000","10.48210000"],["1598.04000000","0.23700000"]],"a":[["1775.96000000","0.00290000"]]}}
{"stream":"btcusdt@depth@100ms","data":{"e":"depthUpdate","E":1783465169714,"s":"BTCUSDT","U":97109083921,"u":97109083929,"b":[["57195.92000000","0.00480000"],["50840.82000000","0.00044000"]],"a":[["63562.55000000","0.00000000"],["63563.21000000","0.25780000"],["64504.30000000","0.00030000"]]}}
{"stream":"ethusdt@depth@100ms","data":{"e":"depthUpdate","E":1783465169715,"s":"ETHUSDT","U":78545066957,"u":78545066962,"b":[["1598.04000000","0.25080000"]],"a":[]}}
{"stream":"btcusdt@depth@100ms","data":{"e":"depthUpdate","E":1783465169814,"s":"BTCUSDT","U":97109083930,"u":97109083937,"b":[["63551.02000000","1.06699000"],["57195.92000000","0.00480000"],["50000.00000000","542.70395000"]],"a":[["63553.89000000","0.00400000"],["63579.33000000","0.00000000"]]}}
{"stream":"ethusdt@depth@100ms","data":{"e":"depthUpdate","E":1783465169815,"s":"ETHUSDT","U":78545066963,"u":78545066966,"b":[["1765.00000000","167.27500000"],["1598.04000000","0.25780000"]],"a":[]}}
{"stream":"btcusdt@trade","data":{"e":"trade","E":1783465169864,"s":"BTCUSDT","t":6486989291,"p":"63551.02000000","q":"0.00027000","T":1783465169864,"m":true,"M":true}}
{"stream":"btcusdt@depth@100ms","data":{"e":"depthUpdate","E":1783465169915,"s":"BTCUSDT","U":97109083938,"u":97109083944,"b":[["63551.02000000","1.06672000"],["57195.92000000","0.00480000"],["57195.91000000","0.00010000"]],"a":[["63562.55000000","0.08348000"],["63563.21000000","0.00000000"]]}}
{"stream":"ethusdt@depth@100ms","data":{"e":"depthUpdate","E":1783465169915,"s":"ETHUSDT","U":78545066967,"u":78545066970,"b":[["1598.04000000","0.25780000"]],"a":[]}}
{"stream":"btcusdt@depth@100ms","data":{"e":"depthUpdate","E":1783465170014,"s":"BTCUSDT","U":97109083945,"u":97109083955,"b":[["63551.02000000","1.06660000"],["63484.91000000","0.00037000"],["63421.66000000","0.00014000"],["57195.92000000","0.00480000"],["50840.82000000","0.00083000"]],"a":[["63562.55000000","0.00000000"],["63563.21000000","0.24192000"],["63592.59000000","0.00392000"],["63655.82000000","0.00157000"]]}}
{"stream":"ethusdt@depth@100ms","data":{"e":"depthUpdate","E":1783465170015,"s":"ETHUSDT","U":78545066971,"u":78545066973,"b":[["1598.04000000","0.25080000"]],"a":[]}}
{"stream":"btcusdt@depth@100ms","data":{"e":"depthUpdate","E":1783465170115,"s":"BTCUSDT","U":97109083956,"u":97109083969,"b":[["63484.91000000","0.00000000"],["63425.71000000","0.02465000"],["63421.66000000","0.00014000"],["62597.75000000","0.00030000"],["57195.92000000","0.00500000"]],"a":[["63592.59000000","0.00000000"],["63655.82000000","0.00157000"]]}}
{"stream":"ethusdt@depth@100ms","data":{"e":"depthUpdate","E":1783465170115,"s":"ETHUSDT","U":78545066974,"u":78545066979,"b":[["1598.04000000","0.23700000"]],"a":[]}}
{"stream":"btcusdt@depth@100ms","data":{"e":"depthUpdate","E":1783465170215,"s":"BTCUSDT","U":97109083970,"u":97109083980,"b":[["63537.00000000","0.00008000"],["63418.13000000","0.09442000"],["57195.92000000","0.00500000"],["57195.00000000","0.00087000"],["50840.82000000","0.00044000"]],"a":[["63562.43000000","0.00008000"]]}}
{"stream":"ethusdt@depth@100ms","data":{"e":"depthUpdate","E":1783465170216,"s":"ETHUSDT","U":78545066980,"u":78545066987,"b":[["1769.38000000","1.02750000"],["1768.61000000","2.48620000"],["1598.04000000","0.25080000"]],"a":[]}}
{"stream":"btcusdt@depth@100ms","data":{"e":"depthUpdate","E":1783465170314,"s":"BTCUSDT","U":97109083981,"u":97109083984,"b":[["57195.92000000","0.00500000"]],"a":[]}}
{"stream":"ethusdt@depth@100ms","data":{"e":"depthUpdate","E":1783465170315,"s":"ETHUSDT","U":78545066988,"u":78545066991,"b":[["1598.04000000","0.25080000"]],"a":[]}}
{"stream":"btcusdt@depth@100ms","data":{"e":"depthUpdate","E":1783465170414,"s":"BTCUSDT","U":97109083985,"u":97109083993,"b":[["63538.86000000","0.00000000"],["63538.85000000","0.09450000"],["57195.92000000","0.00480000"],["40000.00000000","260.73952000"]],"a":[["63620.29000000","0.03108000"],["63743.84000000","0.06309000"]]}}
{"stream":"ethusdt@depth@100ms","data":{"e":"depthUpdate","E":1783465170415,"s":"ETHUSDT","U":78545066992,"u":78545066995,"b":[["1598.04000000","0.25080000"]],"a":[]}}
{"stream":"btcusdt@depth@100ms","data":{"e":"depthUpdate","E":1783465170514,"s":"BTCUSDT","U":97109083994,"u":97109083997,"b":[["57195.92000000","0.00480000"]],"a":[]}}
{"stream":"ethusdt@depth@100ms","data":{"e":"depthUpdate","E":1783465170515,"s":"ETHUSDT","U":78545066996,"u":78545067002,"b":[["1768.56000000","0.57510000"],["1768.54000000","0.00000000"],["1598.04000000","0.24400000"]],"a":[["1802.76000000","0.00590000"]]}}
{"stream":"ethusdt@depth@100ms","data":{"e":"depthUpdate","E":1783465170615,"s":"ETHUSDT","U":78545067003,"u":78545067009,"b":[["1775.24000000","0.27260000"],["1598.04000000","0.25780000"]],"a":[["1775.96000000","0.00000000"]]}}
{"stream":"btcusdt@depth@100ms","data":{"e":"depthUpdate","E":1783465170615,"s":"BTCUSDT","U":97109083998,"u":97109084001,"b":[["57195.92000000","0.00480000"]],"a":[]}}
{"stream":"btcusdt@depth@100ms","data":{"e":"depthUpdate","E":1783465170714,"s":"BTCUSDT","U":97109084002,"u":97109084013,"b":[["57195.92000000","0.00480000"],["50841.00000000","0.23823000"],["50840.82000000","0.00044000"]],"a":[["63562.55000000","0.09788000"],["63563.21000000","0.00000000"],["64504.30000000","0.00030000"]]}}
{"stream":"ethusdt@depth@100ms","data":{"e":"depthUpdate","E":1783465170715,"s":"ETHUSDT","U":78545067010,"u":78545067015,"b":[["1775.24000000","0.27550000"],["1772.38000000","25.78920000"],["1598.04000000","0.25080000"]],"a":[["1775.96000000","0.00290000"]]}}
{"stream":"btcusdt@trade","data":{"e":"trade","E":1783465170789,"s":"BTCUSDT","t":6486989292,"p":"63551.02000000","q":"0.00089000","T":1783465170788,"m":true,"M":true}}
{"stream":"btcusdt@depth@100ms","data":{"e":"depthUpdate","E":1783465170814,"s":"BTCUSDT","U":97109084014,"u":97109084060,"b":[["63551.02000000","0.81850000"],["63545.56000000","0.00018000"],["63544.01000000","0.00787000"],["63542.50000000","0.00000000"],["63542.48000000","0.00000000"],["63538.51000000","4.07889000"],["63538.49000000","0.00000000"],["63534.37000000","2.83475000"],["63510.80000000","2.62352000"],["63490.51000000","0.21135000"],["63476.56000000","0.00000000"],["63456.71000000","0.00000000"],["63436.01000000","0.00000000"],["57195.92000000","0.00500000"],["50841.00000000","0.23623000"]],"a":[["63551.03000000","2.28820000"],["63553.11000000","0.06455000"],["63553.17000000","0.03951000"],["63553.19000000","0.00787000"],["63554.07000000","0.00877000"],["63554.15000000","0.06455000"],["63554.35000000","0.00000000"],["63554.74000000","0.00018000"],["63558.18000000","0.00009000"],["63560.80000000","0.59047000"],["63561.80000000","0.00000000"]]}}
{"stream":"ethusdt@depth@100ms","data":{"e":"depthUpdate","E":1783465170815,"s":"ETHUSDT","U":78545067016,"u":78545067036,"b":[["1775.59000000","18.04350000"],["1775.58000000","0.01160000"],["1775.56000000","0.44600000"],["1775.53000000","0.01440000"],["1775.48000000","0.72670000"],["1775.47000000","0.00000000"],["1775.41000000","0.53700000"],["1775.37000000","1.06270000"],["1775.35000000","0.00430000"],["1773.54000000","1.00140000"],["1773.50000000","0.02820000"],["1773.48000000","2.47500000"],["1598.04000000","0.25080000"]],"a":[["1777.54000000","11.32830000"],["1777.56000000","32.96440000"],["1777.61000000","8.01920000"]]}}
{"stream":"btcusdt@trade","data":{"e":"trade","E":1783465170857,"s":"BTCUSDT","t":6486989293,"p":"63551.03000000","q":"0.00040000","T":1783465170856,"m":false,"M":true}}
{"stream":"btcusdt@depth@100ms","data":{"e":"depthUpdate","E":1783465170915,"s":"BTCUSDT","U":97109084061,"u":97109084212,"b":[["63551.02000000","0.79223000"],["63551.01000000","0.00368000"],["63549.13000000","0.09164000"],["63549.12000000","0.00170000"],["63548.39000000","0.00008000"],["63547.53000000","0.00000000"],["63546.48000000","0.00032000"],["63546.00000000","0.02818000"],["63545.94000000","0.00000000"],["63545.56000000","0.00000000"],["63545.55000000","0.00018000"],["63544.79000000","0.00000000"],["63544.77000000","0.14106000"],["63544.62000000","0.02360000"],["63544.28000000","0.00000000"],["63543.62000000","0.00069000"],["63542.74000000","0.00161000"],["63542.55000000","0.34268000"],["63542.54000000","0.00000000"],["63542.53000000","0.46012000"],["63542.52000000","0.00000000"],["63542.51000000","0.00000000"],["63541.78000000","0.00000000"],["63541.66000000","0.00000000"],["63540.64000000","0.06455000"],["63539.58000000","0.06855000"],["63539.21000000","0.06455000"],["63538.85000000","0.00000000"],["63538.71000000","0.09450000"],["63538.65000000","0.00000000"],["63538.53000000","0.42499000"],["63538.52000000","2.10695000"],["63538.51000000","4.06315000"],["63538.50000000","0.00000000"],["63535.60000000","1.58195000"],["63534.57000000","0.01574000"],["63525.81000000","0.56717000"],["63525.27000000","0.00400000"],["63520.50000000","0.00400000"],["63518.91000000","0.00400000"],["63500.01000000","0.00000000"],["63499.91000000","0.00000000"],["63498.08000000","0.00000000"],["63497.12000000","0.94474000"],["63483.01000000","0.00000000"],["63480.91000000","1.02661000"],["63479.58000000","0.00000000"],["63477.84000000","0.00000000"],["63475.40000000","0.00178000"],["57195.92000000","0.00500000"]],"a":[["63551.03000000","2.28783000"],["63551.70000000","0.12724000"],["63551.71000000","0.06434000"],["63552.30000000","0.00400000"],["63553.11000000","0.06481000"],["63553.17000000","0.03969000"],["63553.19000000","0.00805000"],["63553.61000000","0.00000000"],["63554.07000000","0.00895000"],["63554.15000000","0.06473000"],["63554.51000000","0.00252000"],["63554.52000000","0.01320000"],["63554.74000000","0.00000000"],["63554.75000000","0.00978000"],["63554.89000000","0.06416000"],["63555.19000000","0.06463000"],["63555.24000000","0.00000000"],["63556.17000000","0.00000000"],["63558.02000000","0.00000000"],["63558.63000000","0.00000000"],["63559.48000000","0.00000000"],["63561.02000000","0.00146000"],["63561.43000000","0.00000000"],["63562.80000000","0.56676000"],["63568.30000000","0.00000000"],["63572.96000000","0.00000000"],["63577.74000000","0.00000000"],["63582.63000000","0.00000000"],["63582.82000000","0.00000000"],["63583.68000000","1.55809000"],["63609.82000000","0.00000000"],["63668.57000000","0.00000000"]]}}
{"stream":"ethusdt@depth@100ms","data":{"e":"depthUpdate","E":1783465170915,"s":"ETHUSDT","U":78545067037,"u":78545067169,"b":[["1775.59000000","17.58030000"],["1775.58000000","0.01160000"],["1775.57000000","0.01160000"],["1775.56000000","0.00900000"],["1775.54000000","0.00300000"],["1775.52000000","0.00880000"],["1775.51000000","0.44000000"],["1775.50000000","0.03950000"],["1775.49000000","0.00000000"],["1775.48000000","0.00000000"],["1775.46000000","0.07860000"],["1775.45000000","0.57700000"],["1775.44000000","0.46990000"],["1775.42000000","0.00000000"],["1775.41000000","0.10600000"],["1775.40000000","1.77170000"],["1775.39000000","0.44580000"],["1775.38000000","0.80190000"],["1775.37000000","0.78100000"],["1775.34000000","0.14740000"],["1775.31000000","0.00290000"],["1775.29000000","0.28170000"],["1775.28000000","0.70820000"],["1775.27000000","25.08410000"],["1775.26000000","5.63270000"],["1775.21000000","5.82420000"],["1775.20000000","7.91750000"],["1775.19000000","0.00580000"],["1775.18000000","25.23080000"],["1775.17000000","0.00430000"],["1775.16000000","0.88140000"],["1775.11000000","2.81810000"],["1775.01000000","7.89070000"],["1774.24000000","0.34680000"],["1773.86000000","7.79250000"],["1773.85000000","9.46160000"],["1773.61000000","0.00000000"],["1773.50000000","0.02820000"],["1773.48000000","2.47500000"],["1773.44000000","4.53890000"],["1773.42000000","0.00000000"],["1773.36000000","7.89200000"],["1773.11000000","17.52340000"],["1769.38000000","0.14540000"],["1768.61000000","3.36830000"],["1598.04000000","0.25080000"],["1067.00000000","6.86000000"]],"a":[["1775.60000000","13.96770000"],["1775.61000000","0.19070000"],["1775.62000000","0.61190000"],["1775.63000000","0.63830000"],["1775.64000000","1.78280000"],["1775.68000000","0.04180000"],["1775.76000000","2.99070000"],["1775.77000000","9.46450000"],["1775.78000000","0.00000000"],["1775.86000000","2.05690000"],["1775.88000000","18.07520000"],["1775.89000000","0.61660000"],["1775.95000000","0.00290000"],["1776.74000000","2.81900000"],["1776.80000000","2.48220000"],["1776.88000000","0.54180000"],["1776.98000000","2.77620000"]]}}
{"stream":"btcusdt@depth@100ms","data":{"e":"depthUpdate","E":1783465171014,"s":"BTCUSDT","U":97109084213,"u":97109084251,"b":[["63551.02000000","0.79249000"],["63549.13000000","0.09164000"],["63549.12000000","0.00152000"],["63546.00000000","0.02818000"],["63545.55000000","0.00000000"],["63545.33000000","0.04939000"],["63544.78000000","0.06473000"],["63543.71000000","0.00048000"],["63538.71000000","0.00000000"],["63538.51000000","4.15765000"],["63484.91000000","0.00037000"],["63477.84000000","0.04882000"],["63421.66000000","0.00014000"],["57195.92000000","0.00480000"],["50840.82000000","0.00083000"]],"a":[["63552.46000000","0.00009000"],["63553.19000000","0.00018000"],["63553.88000000","0.00787000"],["63554.51000000","0.00000000"],["63556.06000000","0.09322000"],["63558.18000000","0.59057000"],["63560.80000000","0.00000000"],["63561.24000000","0.10797000"],["63562.55000000","0.00000000"],["63592.59000000","0.00392000"],["63655.82000000","0.00157000"],["63668.57000000","0.07658000"]]}}
{"stream":"ethusdt@depth@100ms","data":{"e":"depthUpdate","E":1783465171015,"s":"ETHUSDT","U":78545067170,"u":78545067215,"b":[["1775.58000000","0.01760000"],["1775.57000000","0.44860000"],["1775.52000000","0.01480000"],["1775.51000000","0.44600000"],["1775.50000000","0.47650000"],["1775.45000000","0.57700000"],["1775.41000000","0.10000000"],["1775.40000000","1.76570000"],["1775.39000000","0.44280000"],["1775.33000000","0.58650000"],["1775.28000000","10.61900000"],["1775.21000000","9.41450000"],["1773.56000000","0.13250000"],["1773.54000000","0.56440000"],["1773.49000000","1.75850000"],["1773.20000000","0.00290000"],["1598.04000000","0.23700000"]],"a":[["1775.60000000","13.65110000"],["1775.61000000","0.19360000"],["1775.74000000","10.81950000"],["1775.75000000","15.78060000"],["1775.76000000","7.91750000"],["1775.81000000","0.28750000"],["1775.88000000","17.79350000"],["1775.98000000","2.98460000"],["1776.04000000","0.44540000"],["1777.55000000","0.01740000"],["1777.61000000","0.13460000"],["1778.54000000","8.18750000"],["1778.83000000","0.56540000"]]}}
{"stream":"btcusdt@depth@100ms","data":{"e":"depthUpdate","E":1783465171114,"s":"BTCUSDT","U":97109084252,"u":97109084278,"b":[["63551.02000000","0.79240000"],["63551.01000000","0.00368000"],["63548.83000000","0.13969000"],["63542.56000000","0.06455000"],["63484.91000000","0.00000000"],["63421.66000000","0.00014000"],["62597.75000000","0.00030000"],["57195.92000000","0.00480000"]],"a":[["63553.17000000","0.03969000"],["63553.19000000","0.00000000"],["63553.88000000","0.00805000"],["63555.80000000","0.52437000"],["63592.59000000","0.00000000"],["63655.82000000","0.00157000"]]}}
{"stream":"ethusdt@depth@100ms","data":{"e":"depthUpdate","E":1783465171115,"s":"ETHUSDT","U":78545067216,"u":78545067220,"b":[["1598.04000000","0.25780000"]],"a":[]}}
{"stream":"btcusdt@depth@100ms","data":{"e":"depthUpdate","E":1783465171214,"s":"BTCUSDT","U":97109084279,"u":97109084319,"b":[["63551.02000000","0.79261000"],["63551.01000000","0.00377000"],["63549.13000000","0.09172000"],["63548.84000000","0.00018000"],["63548.83000000","0.13987000"],["63546.01000000","0.00000000"],["63544.78000000","0.06455000"],["63544.67000000","0.00787000"],["63544.01000000","0.00000000"],["63543.16000000","0.00000000"],["63537.00000000","0.00008000"],["63379.28000000","0.00000000"],["63370.64000000","0.00987000"],["57195.92000000","0.00480000"],["57195.00000000","0.00087000"],["50840.82000000","0.00044000"],["33000.00000000","35.16979000"]],"a":[["63551.03000000","2.28809000"],["63553.10000000","0.00000000"],["63562.43000000","0.00008000"]]}}
{"stream":"ethusdt@depth@100ms","data":{"e":"depthUpdate","E":1783465171215,"s":"ETHUSDT","U":78545067221,"u":78545067231,"b":[["1775.57000000","0.45460000"],["1775.56000000","0.44600000"],["1775.46000000","0.07260000"],["1773.60000000","7.88460000"],["1768.56000000","0.00000000"],["1768.54000000","0.57510000"],["1598.04000000","0.25780000"]],"a":[]}}
{"stream":"ethusdt@trade","data":{"e":"trade","E":1783465171269,"s":"ETHUSDT","t":4197008360,"p":"1775.60000000","q":"0.04970000","T":1783465171269,"m":false,"M":true}}
{"stream":"btcusdt@depth@100ms","data":{"e":"depthUpdate","E":1783465171314,"s":"BTCUSDT","U":97109084320,"u":97109084324,"b":[["57195.92000000","0.00480000"]],"a":[["63668.57000000","0.00000000"]]}}
{"stream":"ethusdt@depth@100ms","data":{"e":"depthUpdate","E":1783465171315,"s":"ETHUSDT","U":78545067232,"u":78545067242,"b":[["1775.59000000","18.00970000"],["1774.32000000","0.03000000"],["1774.24000000","0.31680000"],["1772.62000000","0.00290000"],["1598.04000000","0.25780000"]],"a":[["1775.60000000","13.60430000"],["1775.81000000","0.00580000"],["1775.83000000","0.28170000"]]}}
{"stream":"ethusdt@trade","data":{"e":"trade","E":1783465171336,"s":"ETHUSDT","t":4197008361,"p":"1775.59000000","q":"0.00700000","T":1783465171336,"m":true,"M":true}}
{"stream":"btcusdt@depth@100ms","data":{"e":"depthUpdate","E":1783465171414,"s":"BTCUSDT","U":97109084325,"u":97109084336,"b":[["63551.02000000","0.79287000"],["63418.13000000","0.00000000"],["57195.92000000","0.00500000"],["40000.00000000","260.73952000"]],"a":[["63551.03000000","2.28849000"],["63561.24000000","0.00000000"],["63561.81000000","0.23449000"],["63620.29000000","0.00000000"],["63668.57000000","0.07658000"],["63743.84000000","0.00000000"]]}}
{"stream":"ethusdt@depth@100ms","data":{"e":"depthUpdate","E":1783465171415,"s":"ETHUSDT","U":78545067243,"u":78545067250,"b":[["1775.59000000","18.01220000"],["1775.33000000","0.57700000"],["1598.04000000","0.23700000"]],"a":[]}}
{"stream":"btcusdt@depth@100ms","data":{"e":"depthUpdate","E":1783465171514,"s":"BTCUSDT","U":97109084337,"u":97109084340,"b":[["57195.92000000","0.00500000"]],"a":[]}}
{"stream":"ethusdt@depth@100ms","data":{"e":"depthUpdate","E":1783465171515,"s":"ETHUSDT","U":78545067251,"u":78545067259,"b":[["1774.57000000","16.54340000"],["1774.26000000","0.45730000"],["1598.04000000","0.25080000"]],"a":[["1780.06000000","0.02110000"]]}}
{"stream":"btcusdt@depth@100ms","data":{"e":"depthUpdate","E":1783465171614,"s":"BTCUSDT","U":97109084341,"u":97109084346,"b":[["57195.92000000","0.00500000"],["50841.00000000","0.23623000"]],"a":[]}}
{"stream":"ethusdt@depth@100ms","data":{"e":"depthUpdate","E":1783465171616,"s":"ETHUSDT","U":78545067260,"u":78545067263,"b":[["1598.04000000","0.25080000"]],"a":[]}}
{"stream":"btcusdt@depth@100ms","data":{"e":"depthUpdate","E":1783465171714,"s":"BTCUSDT","U":97109084347,"u":97109084366,"b":[["63548.03000000","0.00000000"],["57195.92000000","0.00480000"],["50840.82000000","0.00044000"]],"a":[["63551.03000000","2.28875000"],["63555.80000000","0.52429000"],["63556.06000000","0.00000000"],["63557.55000000","0.00252000"],["63561.24000000","0.08619000"],["63561.81000000","0.00000000"],["63621.59000000","1.91970000"],["63625.79000000","0.00000000"],["64504.30000000","0.00030000"]]}}
{"stream":"ethusdt@depth@100ms","data":{"e":"depthUpdate","E":1783465171715,"s":"ETHUSDT","U":78545067264,"u":78545067271,"b":[["1775.24000000","0.27550000"],["1598.04000000","0.25080000"]],"a":[["1775.60000000","24.87590000"],["1775.96000000","0.00290000"]]}}
{"stream":"btcusdt@trade","data":{"e":"trade","E":1783465171717,"s":"BTCUSDT","t":6486989294,"p":"63551.02000000","q":"0.00008000","T":1783465171716,"m":true,"M":true}}
{"stream":"btcusdt@trade","data":{"e":"trade","E":1783465171717,"s":"BTCUSDT","t":6486989295,"p":"63551.02000000","q":"0.00008000","T":1783465171716,"m":true,"M":true}}
{"stream":"btcusdt@trade","data":{"e":"trade","E":1783465171717,"s":"BTCUSDT","t":6486989296,"p":"63551.02000000","q":"0.00008000","T":1783465171716,"m":true,"M":true}}
{"stream":"btcusdt@trade","data":{"e":"trade","E":1783465171717,"s":"BTCUSDT","t":6486989297,"p":"63551.02000000","q":"0.00008000","T":1783465171716,"m":true,"M":true}}
{"stream":"btcusdt@trade","data":{"e":"trade","E":1783465171717,"s":"BTCUSDT","t":6486989298,"p":"63551.02000000","q":"0.00008000","T":1783465171716,"m":true,"M":true}}
{"stream":"btcusdt@trade","data":{"e":"trade","E":1783465171717,"s":"BTCUSDT","t":6486989299,"p":"63551.02000000","q":"0.00089000","T":1783465171716,"m":true,"M":true}}
{"stream":"btcusdt@trade","data":{"e":"trade","E":1783465171758,"s":"BTCUSDT","t":6486989300,"p":"63551.02000000","q":"0.00010000","T":1783465171758,"m":true,"M":true}}
{"stream":"btcusdt@depth@100ms","data":{"e":"depthUpdate","E":1783465171814,"s":"BTCUSDT","U":97109084367,"u":97109084497,"b":[["63551.02000000","0.11536000"],["63551.01000000","0.00368000"],["63548.84000000","0.00000000"],["63548.83000000","0.00018000"],["63546.87000000","0.00000000"],["63546.48000000","0.00000000"],["63546.30000000","0.00000000"],["63546.29000000","0.00018000"],["63546.01000000","0.00018000"],["63545.34000000","0.00009000"],["63544.67000000","0.00000000"],["63544.66000000","0.00316000"],["63543.16000000","0.00000000"],["63542.55000000","0.00000000"],["63542.53000000","0.00000000"],["63542.14000000","0.00787000"],["63541.44000000","0.00885000"],["63540.54000000","0.00010000"],["63540.29000000","0.02000000"],["63539.20000000","0.00000000"],["63538.84000000","0.00000000"],["63538.64000000","0.00000000"],["63538.54000000","1.68853000"],["63538.52000000","0.91761000"],["63538.51000000","0.00000000"],["63538.26000000","0.00000000"],["63536.84000000","0.09450000"],["63535.84000000","0.03000000"],["63535.59000000","0.00000000"],["63534.38000000","4.06315000"],["63534.37000000","0.00000000"],["63533.53000000","0.00000000"],["63530.37000000","1.22840000"],["63530.04000000","0.00400000"],["63526.72000000","0.67933000"],["63524.00000000","0.59511000"],["63500.01000000","0.58143000"],["63497.12000000","0.00000000"],["63489.71000000","0.94474000"],["63480.91000000","0.00000000"],["63476.63000000","0.00000000"],["63476.56000000","2.83475000"],["63476.55000000","1.23716000"],["63421.66000000","0.00000000"],["63406.50000000","0.03951000"],["63406.23000000","0.22500000"],["57195.92000000","0.00480000"],["57195.91000000","0.00000000"],["57195.90000000","0.00010000"]],"a":[["63551.03000000","2.29669000"],["63551.04000000","0.00114000"],["63551.69000000","0.00000000"],["63551.70000000","0.12706000"],["63551.71000000","0.06442000"],["63552.07000000","0.06455000"],["63552.53000000","0.09322000"],["63553.88000000","0.00018000"],["63554.03000000","0.00000000"],["63555.12000000","0.00000000"],["63555.14000000","0.02000000"],["63555.80000000","0.64616000"],["63555.93000000","0.00000000"],["63556.59000000","0.00000000"],["63557.55000000","0.00000000"],["63557.97000000","0.06455000"],["63557.98000000","2.83507000"],["63558.19000000","0.00000000"],["63560.05000000","0.56678000"],["63561.81000000","0.78730000"],["63561.88000000","0.04000000"],["63565.24000000","0.00000000"],["63569.80000000","0.00216000"],["63575.85000000","0.00000000"],["63586.42000000","0.00000000"],["63608.00000000","0.02800000"],["63608.49000000","0.00391000"],["63623.09000000","0.00000000"],["63623.32000000","0.00000000"],["63631.53000000","0.00000000"],["69906.13000000","0.00008000"]]}}
{"stream":"ethusdt@depth@100ms","data":{"e":"depthUpdate","E":1783465171815,"s":"ETHUSDT","U":78545067272,"u":78545067356,"b":[["1775.59000000","11.20960000"],["1775.58000000","0.01760000"],["1775.57000000","0.44860000"],["1775.56000000","0.00900000"],["1775.51000000","0.44600000"],["1775.50000000","0.47650000"],["1775.46000000","0.07860000"],["1775.45000000","0.57700000"],["1775.44000000","0.46990000"],["1775.41000000","0.10000000"],["1775.29000000","0.00000000"],["1775.28000000","25.29900000"],["1775.27000000","0.49330000"],["1775.26000000","2.25180000"],["1775.25000000","6.14790000"],["1775.21000000","17.29910000"],["1775.20000000","0.03290000"],["1775.19000000","7.89040000"],["1775.18000000","0.00000000"],["1775.15000000","0.00580000"],["1775.11000000","0.00000000"],["1775.08000000","27.40880000"],["1775.02000000","0.00840000"],["1774.90000000","24.64080000"],["1774.76000000","0.00850000"],["1773.61000000","17.34620000"],["1773.60000000","8.32160000"],["1773.56000000","0.13250000"],["1773.54000000","0.56440000"],["1773.37000000","0.00720000"],["1773.12000000","0.00000000"],["1598.04000000","0.25780000"]],"a":[["1775.60000000","24.86430000"],["1775.61000000","0.18490000"],["1775.72000000","7.04640000"],["1776.35000000","1.80810000"],["1776.58000000","0.20000000"],["1776.72000000","9.49430000"],["1776.77000000","16.51630000"],["1776.98000000","5.59190000"],["1777.36000000","0.01430000"]]}}
{"stream":"btcusdt@depth@100ms","data":{"e":"depthUpdate","E":1783465171914,"s":"BTCUSDT","U":97109084498,"u":97109084612,"b":[["63549.13000000","0.09164000"],["63548.83000000","0.00000000"],["63547.57000000","0.00675000"],["63546.52000000","0.00032000"],["63546.45000000","0.00000000"],["63546.29000000","0.00000000"],["63544.78000000","0.06473000"],["63544.77000000","0.14124000"],["63544.66000000","0.00316000"],["63544.35000000","0.00000000"],["63539.14000000","0.00009000"],["63538.55000000","1.53942000"],["63538.54000000","0.46013000"],["63538.52000000","0.00000000"],["63536.84000000","0.00000000"],["63536.73000000","0.00000000"],["63534.39000000","4.51942000"],["63534.38000000","0.00000000"],["63533.52000000","0.00000000"],["63533.07000000","0.02347000"],["63530.37000000","0.00000000"],["63530.03000000","1.22840000"],["63515.73000000","0.00400000"],["63476.55000000","1.16572000"],["63475.40000000","0.00000000"],["63468.93000000","0.00000000"],["57195.92000000","0.00480000"],["56000.00000000","197.30096000"],["55000.00000000","602.27273000"]],"a":[["63551.03000000","2.29677000"],["63551.69000000","0.00000000"],["63551.70000000","0.98264000"],["63551.71000000","0.06442000"],["63552.07000000","0.06481000"],["63552.53000000","0.00018000"],["63553.11000000","0.06489000"],["63553.17000000","0.03969000"],["63553.54000000","0.00252000"],["63553.88000000","0.00000000"],["63554.01000000","0.00052000"],["63554.13000000","0.65506000"],["63554.14000000","2.83475000"],["63554.15000000","0.00018000"],["63554.34000000","0.01000000"],["63554.36000000","0.04004000"],["63554.89000000","0.06408000"],["63555.19000000","0.00000000"],["63555.79000000","0.00000000"],["63555.80000000","0.00000000"],["63557.27000000","0.00000000"],["63557.39000000","0.22500000"],["63557.96000000","0.45627000"],["63557.97000000","0.94829000"],["63558.18000000","0.00009000"],["63558.69000000","0.00000000"],["63560.98000000","0.00000000"],["63565.28000000","0.79981000"],["63578.60000000","0.00000000"],["63608.00000000","0.03193000"],["63608.49000000","0.00000000"],["69906.13000000","0.00000000"]]}}
{"stream":"ethusdt@depth@100ms","data":{"e":"depthUpdate","E":1783465171915,"s":"ETHUSDT","U":78545067357,"u":78545067384,"b":[["1775.59000000","11.20670000"],["1775.34000000","0.15700000"],["1775.29000000","10.20630000"],["1775.22000000","17.78320000"],["1775.21000000","7.88460000"],["1775.20000000","2.65260000"],["1774.67000000","0.40000000"],["1774.46000000","1.12940000"],["1773.61000000","0.00000000"],["1598.04000000","0.24400000"]],"a":[["1775.76000000","7.91750000"],["1775.84000000","15.05130000"],["1775.87000000","15.76920000"],["1775.98000000","18.00300000"],["1776.01000000","11.67170000"],["1776.45000000","44.80440000"],["1776.58000000","0.60000000"],["1776.65000000","0.00000000"]]}}
{"stream":"btcusdt@depth@100ms","data":{"e":"depthUpdate","E":1783465172014,"s":"BTCUSDT","U":97109084613,"u":97109084682,"b":[["63549.13000000","0.09172000"],["63544.88000000","0.14253000"],["63542.76000000","0.00000000"],["63542.14000000","0.00000000"],["63541.76000000","0.00787000"],["63541.31000000","0.00000000"],["63538.55000000","1.14453000"],["63536.48000000","0.00000000"],["63536.32000000","0.00000000"],["63536.30000000","0.09450000"],["63517.32000000","0.00400000"],["63484.91000000","0.00037000"],["63421.66000000","0.00014000"],["57195.92000000","0.00480000"],["50840.82000000","0.00083000"]],"a":[["63551.03000000","2.29685000"],["63551.68000000","0.98210000"],["63551.69000000","1.22840000"],["63551.70000000","0.00054000"],["63552.07000000","0.00018000"],["63552.53000000","0.00000000"],["63553.11000000","0.00026000"],["63554.07000000","0.00895000"],["63554.13000000","0.06473000"],["63554.14000000","2.83493000"],["63554.15000000","0.00000000"],["63554.89000000","0.06416000"],["63557.04000000","0.59053000"],["63558.69000000","0.16319000"],["63561.24000000","0.00000000"],["63561.95000000","0.78041000"],["63562.62000000","0.48948000"],["63565.28000000","0.55269000"],["63592.34000000","0.00393000"],["63592.35000000","0.03000000"],["63655.82000000","0.00157000"]]}}
{"stream":"ethusdt@depth@100ms","data":{"e":"depthUpdate","E":1783465172015,"s":"ETHUSDT","U":78545067385,"u":78545067400,"b":[["1775.57000000","0.45460000"],["1775.56000000","0.44600000"],["1775.46000000","0.07260000"],["1775.25000000","5.86620000"],["1775.24000000","0.55720000"],["1775.23000000","8.41410000"],["1775.20000000","0.03290000"],["1773.60000000","7.88460000"],["1598.04000000","0.25080000"]],"a":[["1775.75000000","16.06230000"],["1775.83000000","0.00000000"],["1775.92000000","3.14480000"],["1775.98000000","15.18500000"]]}}
{"stream":"btcusdt@depth@100ms","data":{"e":"depthUpdate","E":1783465172114,"s":"BTCUSDT","U":97109084683,"u":97109084734,"b":[["63551.02000000","0.11527000"],["63551.01000000","0.00368000"],["63545.33000000","0.04939000"],["63544.88000000","0.14271000"],["63544.77000000","0.14106000"],["63536.30000000","0.00000000"],["63536.24000000","0.00000000"],["63536.23000000","0.09450000"],["63484.91000000","0.00037000"],["63421.66000000","0.00000000"],["62597.75000000","0.00030000"],["57195.92000000","0.00500000"]],"a":[["63551.03000000","2.29685000"],["63551.68000000","0.98228000"],["63551.69000000","1.22858000"],["63551.70000000","0.00036000"],["63551.71000000","0.06434000"],["63552.07000000","0.00000000"],["63553.11000000","0.00008000"],["63554.34000000","0.01018000"],["63557.04000000","0.00000000"],["63557.56000000","0.59054000"],["63579.51000000","0.00429000"],["63579.73000000","0.00435000"],["63587.14000000","0.00000000"],["63587.48000000","0.00000000"],["63592.34000000","0.00000000"],["63627.13000000","0.00000000"],["63655.82000000","0.00157000"]]}}
{"stream":"ethusdt@depth@100ms","data":{"e":"depthUpdate","E":1783465172115,"s":"ETHUSDT","U":78545067401,"u":78545067410,"b":[["1775.59000000","11.63620000"],["1598.04000000","0.25080000"]],"a":[["1775.89000000","1.38280000"],["1775.92000000","0.32690000"],["1775.96000000","2.82080000"],["1776.03000000","34.95010000"],["1776.06000000","12.91150000"],["1776.15000000","17.69660000"]]}}
{"stream":"btcusdt@depth@100ms","data":{"e":"depthUpdate","E":1783465172214,"s":"BTCUSDT","U":97109084735,"u":97109084746,"b":[["63537.00000000","0.00000000"],["57195.92000000","0.00500000"],["50840.82000000","0.00044000"]],"a":[["63551.03000000","2.30569000"],["63554.89000000","0.06408000"],["63557.39000000","0.22508000"],["63562.43000000","0.00000000"],["63594.54000000","0.00000000"],["63613.00000000","0.94485000"],["63716.56000000","0.01867000"],["63741.63000000","0.00000000"]]}}
{"stream":"ethusdt@depth@100ms","data":{"e":"depthUpdate","E":1783465172216,"s":"ETHUSDT","U":78545067411,"u":78545067418,"b":[["1598.04000000","0.25080000"]],"a":[["1775.60000000","24.87010000"],["1775.61000000","0.19070000"]]}}
{"stream":"btcusdt@depth@100ms","data":{"e":"depthUpdate","E":1783465172314,"s":"BTCUSDT","U":97109084747,"u":97109084757,"b":[["63537.00000000","0.00008000"],["57195.92000000","0.00500000"],["57195.00000000","0.00087000"],["50841.00000000","0.23623000"]],"a":[["63554.13000000","0.00018000"],["63562.43000000","0.00008000"]]}}
{"stream":"ethusdt@depth@100ms","data":{"e":"depthUpdate","E":1783465172315,"s":"ETHUSDT","U":78545067419,"u":78545067424,"b":[["1598.04000000","0.23700000"]],"a":[]}}
{"stream":"btcusdt@depth@100ms","data":{"e":"depthUpdate","E":1783465172414,"s":"BTCUSDT","U":97109084758,"u":97109084783,"b":[["63476.35000000","0.07320000"],["63333.64000000","0.02465000"],["63303.12000000","0.00000000"],["57195.92000000","0.00480000"],["50841.00000000","0.23623000"],["40000.00000000","260.73952000"]],"a":[["63551.71000000","0.06426000"],["63553.11000000","0.00000000"],["63554.07000000","0.00895000"],["63554.13000000","0.00000000"],["63554.36000000","0.04022000"],["63574.11000000","0.00699000"],["63577.11000000","0.00000000"]]}}
{"stream":"ethusdt@depth@100ms","data":{"e":"depthUpdate","E":1783465172415,"s":"ETHUSDT","U":78545067425,"u":78545067432,"b":[["1772.50000000","0.44020000"],["1768.54000000","0.00000000"],["1768.26000000","0.57520000"],["1598.04000000","0.25080000"]],"a":[]}}
{"stream":"ethusdt@trade","data":{"e":"trade","E":1783465172463,"s":"ETHUSDT","t":4197008362,"p":"1775.59000000","q":"0.29790000","T":1783465172463,"m":true,"M":true}}
{"stream":"btcusdt@depth@100ms","data":{"e":"depthUpdate","E":1783465172514,"s":"BTCUSDT","U":97109084784,"u":97109084787,"b":[["57195.92000000","0.00480000"]],"a":[]}}
{"stream":"ethusdt@depth@100ms","data":{"e":"depthUpdate","E":1783465172516,"s":"ETHUSDT","U":78545067433,"u":78545067440,"b":[["1775.59000000","11.33830000"],["1775.45000000","0.85530000"],["1773.67000000","12.22270000"],["1598.04000000","0.25780000"]],"a":[["1775.72000000","0.28320000"],["1802.76000000","0.05040000"]]}}
{"stream":"ethusdt@depth@100ms","data":{"e":"depthUpdate","E":1783465172615,"s":"ETHUSDT","U":78545067441,"u":78545067444,"b":[["1598.04000000","0.25780000"]],"a":[]}}
{"stream":"btcusdt@depth@100ms","data":{"e":"depthUpdate","E":1783465172615,"s":"BTCUSDT","U":97109084788,"u":97109084798,"b":[["60004.28000000","0.00000000"],["57195.92000000","0.00480000"]],"a":[["63551.03000000","2.29782000"],["63551.51000000","0.00787000"],["63558.69000000","0.00000000"],["63559.52000000","0.27664000"],["63562.62000000","0.00000000"],["63568.82000000","0.54866000"],["63572.11000000","0.09130000"],["63585.43000000","0.00000000"]]}}
{"stream":"ethusdt@trade","data":{"e":"trade","E":1783465172622,"s":"ETHUSDT","t":4197008363,"p":"1775.59000000","q":"0.20000000","T":1783465172622,"m":true,"M":true}}
{"stream":"ethusdt@trade","data":{"e":"trade","E":1783465172623,"s":"ETHUSDT","t":4197008364,"p":"1775.59000000","q":"0.10000000","T":1783465172622,"m":true,"M":true}}
{"stream":"ethusdt@trade","data":{"e":"trade","E":1783465172623,"s":"ETHUSDT","t":4197008365,"p":"1775.59000000","q":"0.40000000","T":1783465172622,"m":true,"M":true}}
{"stream":"ethusdt@trade","data":{"e":"trade","E":1783465172623,"s":"ETHUSDT","t":4197008366,"p":"1775.59000000","q":"0.00290000","T":1783465172623,"m":true,"M":true}}
{"stream":"ethusdt@trade","data":{"e":"trade","E":1783465172623,"s":"ETHUSDT","t":4197008367,"p":"1775.59000000","q":"0.00300000","T":1783465172623,"m":true,"M":true}}
{"stream":"ethusdt@trade","data":{"e":"trade","E":1783465172623,"s":"ETHUSDT","t":4197008368,"p":"1775.59000000","q":"0.00570000","T":1783465172623,"m":true,"M":true}}
{"stream":"ethusdt@trade","data":{"e":"trade","E":1783465172623,"s":"ETHUSDT","t":4197008369,"p":"1775.59000000","q":"0.00290000","T":1783465172623,"m":true,"M":true}}
{"stream":"ethusdt@trade","data":{"e":"trade","E":1783465172623,"s":"ETHUSDT","t":4197008370,"p":"1775.59000000","q":"0.00290000","T":1783465172623,"m":true,"M":true}}
{"stream":"ethusdt@trade","data":{"e":"trade","E":1783465172623,"s":"ETHUSDT","t":4197008371,"p":"1775.59000000","q":"0.00290000","T":1783465172623,"m":true,"M":true}}
{"stream":"ethusdt@trade","data":{"e":"trade","E":1783465172623,"s":"ETHUSDT","t":4197008372,"p":"1775.59000000","q":"0.00290000","T":1783465172623,"m":true,"M":true}}
{"stream":"ethusdt@trade","data":{"e":"trade","E":1783465172623,"s":"ETHUSDT","t":4197008373,"p":"1775.59000000","q":"0.00290000","T":1783465172623,"m":true,"M":true}}
{"stream":"ethusdt@trade","data":{"e":"trade","E":1783465172623,"s":"ETHUSDT","t":4197008374,"p":"1775.58000000","q":"0.00300000","T":1783465172623,"m":true,"M":true}}
{"stream":"ethusdt@trade","data":{"e":"trade","E":1783465172623,"s":"ETHUSDT","t":4197008375,"p":"1775.58000000","q":"0.00570000","T":1783465172623,"m":true,"M":true}}
{"stream":"ethusdt@trade","data":{"e":"trade","E":1783465172623,"s":"ETHUSDT","t":4197008376,"p":"1775.58000000","q":"0.00290000","T":1783465172623,"m":true,"M":true}}
{"stream":"ethusdt@trade","data":{"e":"trade","E":1783465172623,"s":"ETHUSDT","t":4197008377,"p":"1775.58000000","q":"0.00300000","T":1783465172623,"m":true,"M":true}}
{"stream":"ethusdt@trade","data":{"e":"trade","E":1783465172623,"s":"ETHUSDT","t":4197008378,"p":"1775.58000000","q":"0.00300000","T":1783465172623,"m":true,"M":true}}
{"stream":"ethusdt@trade","data":{"e":"trade","E":1783465172623,"s":"ETHUSDT","t":4197008379,"p":"1775.58000000","q":"0.00300000","T":1783465172623,"m":true,"M":true}}
{"stream":"ethusdt@trade","data":{"e":"trade","E":1783465172623,"s":"ETHUSDT","t":4197008380,"p":"1775.57000000","q":"0.00300000","T":1783465172623,"m":true,"M":true}}
{"stream":"ethusdt@trade","data":{"e":"trade","E":1783465172623,"s":"ETHUSDT","t":4197008381,"p":"1775.57000000","q":"0.00290000","T":1783465172623,"m":true,"M":true}}
{"stream":"ethusdt@trade","data":{"e":"trade","E":1783465172623,"s":"ETHUSDT","t":4197008382,"p":"1775.57000000","q":"0.00570000","T":1783465172623,"m":true,"M":true}}
{"stream":"ethusdt@trade","data":{"e":"trade","E":1783465172623,"s":"ETHUSDT","t":4197008383,"p":"1775.57000000","q":"0.00300000","T":1783465172623,"m":true,"M":true}}
{"stream":"ethusdt@trade","data":{"e":"trade","E":1783465172623,"s":"ETHUSDT","t":4197008384,"p":"1775.57000000","q":"0.00300000","T":1783465172623,"m":true,"M":true}}
{"stream":"ethusdt@trade","data":{"e":"trade","E":1783465172623,"s":"ETHUSDT","t":4197008385,"p":"1775.57000000","q":"0.00300000","T":1783465172623,"m":true,"M":true}}
{"stream":"ethusdt@trade","data":{"e":"trade","E":1783465172623,"s":"ETHUSDT","t":4197008386,"p":"1775.56000000","q":"0.00300000","T":1783465172623,"m":true,"M":true}}
{"stream":"ethusdt@trade","data":{"e":"trade","E":1783465172623,"s":"ETHUSDT","t":4197008387,"p":"1775.56000000","q":"0.00300000","T":1783465172623,"m":true,"M":true}}
{"stream":"ethusdt@trade","data":{"e":"trade","E":1783465172623,"s":"ETHUSDT","t":4197008388,"p":"1775.56000000","q":"0.00300000","T":1783465172623,"m":true,"M":true}}
{"stream":"ethusdt@trade","data":{"e":"trade","E":1783465172623,"s":"ETHUSDT","t":4197008389,"p":"1775.56000000","q":"0.00300000","T":1783465172623,"m":true,"M":true}}
{"stream":"ethusdt@trade","data":{"e":"trade","E":1783465172623,"s":"ETHUSDT","t":4197008390,"p":"1775.55000000","q":"0.00300000","T":1783465172623,"m":true,"M":true}}
{"stream":"ethusdt@trade","data":{"e":"trade","E":1783465172623,"s":"ETHUSDT","t":4197008391,"p":"1775.55000000","q":"0.71770000","T":1783465172623,"m":true,"M":true}}
{"stream":"ethusdt@trade","data":{"e":"trade","E":1783465172626,"s":"ETHUSDT","t":4197008392,"p":"1775.55000000","q":"0.00300000","T":1783465172626,"m":true,"M":true}}
{"stream":"btcusdt@depth@100ms","data":{"e":"depthUpdate","E":1783465172714,"s":"BTCUSDT","U":97109084799,"u":97109084846,"b":[["63551.02000000","0.02457000"],["63545.26000000","0.00008000"],["63542.16000000","0.00787000"],["63542.13000000","0.00008000"],["63541.76000000","0.00000000"],["63541.44000000","0.00000000"],["63540.46000000","0.00000000"],["63539.80000000","0.00000000"],["63539.00000000","0.00008000"],["63538.55000000","0.42499000"],["63538.53000000","0.00000000"],["63538.46000000","0.06455000"],["63536.61000000","0.00000000"],["63535.87000000","0.00008000"],["63532.74000000","0.00008000"],["63529.61000000","0.00008000"],["63528.67000000","0.04752000"],["63526.48000000","0.00008000"],["63525.12000000","0.00972000"],["63523.35000000","0.00008000"],["63521.34000000","0.56713000"],["63520.22000000","0.00016000"],["57195.92000000","0.00480000"],["50840.82000000","0.00044000"]],"a":[["63551.03000000","2.31534000"],["63551.51000000","0.00018000"],["63553.32000000","0.00252000"],["63553.54000000","0.00000000"],["63554.36000000","0.04004000"],["63558.69000000","0.09019000"],["63559.52000000","0.00000000"],["63581.31000000","0.00000000"],["64504.30000000","0.00030000"]]}}
{"stream":"ethusdt@depth@100ms","data":{"e":"depthUpdate","E":1783465172715,"s":"ETHUSDT","U":78545067445,"u":78545067924,"b":[["1775.59000000","0.00000000"],["1775.58000000","0.00000000"],["1775.57000000","0.00000000"],["1775.56000000","0.00000000"],["1775.55000000","6.49300000"],["1775.54000000","0.00880000"],["1775.53000000","0.00300000"],["1775.52000000","0.00880000"],["1775.51000000","0.00300000"],["1775.50000000","0.03950000"],["1775.49000000","0.43700000"],["1775.46000000","0.08160000"],["1775.45000000","0.14300000"],["1775.44000000","0.01190000"],["1775.43000000","0.59360000"],["1775.42000000","0.43700000"],["1775.41000000","0.10000000"],["1775.40000000","0.00000000"],["1775.39000000","0.00890000"],["1775.38000000","7.04920000"],["1775.37000000","1.21800000"],["1775.36000000","0.17590000"],["1775.35000000","0.44420000"],["1775.34000000","0.14740000"],["1775.33000000","0.14000000"],["1775.32000000","0.56290000"],["1775.31000000","0.43990000"],["1775.29000000","1.28180000"],["1775.28000000","0.70820000"],["1775.27000000","0.06570000"],["1775.26000000","0.00290000"],["1775.25000000","2.92230000"],["1775.24000000","0.27260000"],["1775.23000000","0.91330000"],["1775.22000000","0.00000000"],["1775.21000000","0.00000000"],["1775.20000000","0.03580000"],["1775.19000000","0.00580000"],["1775.17000000","0.72300000"],["1775.16000000","0.00740000"],["1775.15000000","0.44280000"],["1775.12000000","0.23290000"],["1775.11000000","14.51350000"],["1775.10000000","15.77210000"],["1775.09000000","9.89860000"],["1775.08000000","24.59080000"],["1775.07000000","0.11030000"],["1775.06000000","0.00000000"],["1775.04000000","7.91750000"],["1775.03000000","0.43700000"],["1775.02000000","0.44540000"],["1775.01000000","0.00620000"],["1775.00000000","0.30600000"],["1774.97000000","14.29350000"],["1774.96000000","0.46990000"],["1774.94000000","2.81820000"],["1774.93000000","42.73560000"],["1774.92000000","0.00000000"],["1774.91000000","0.43700000"],["1774.90000000","25.07780000"],["1774.89000000","0.01030000"],["1774.87000000","0.00290000"],["1774.84000000","4.95240000"],["1774.82000000","0.00290000"],["1774.81000000","0.00430000"],["1774.80000000","8.36190000"],["1774.76000000","17.28710000"],["1774.75000000","17.78610000"],["1774.74000000","15.02130000"],["1774.73000000","0.00290000"],["1774.72000000","0.03640000"],["1774.67000000","0.00000000"],["1774.63000000","0.00860000"],["1774.61000000","14.79550000"],["1774.58000000","0.40290000"],["1774.56000000","2.15020000"],["1774.16000000","0.03000000"],["1773.68000000","0.00000000"],["1773.67000000","0.14790000"],["1773.61000000","7.88460000"],["1773.60000000","8.32160000"],["1773.56000000","0.56950000"],["1773.54000000","1.00140000"],["1773.50000000","0.02820000"],["1773.48000000","2.47500000"],["1773.44000000","4.53890000"],["1773.42000000","0.00000000"],["1773.38000000","0.13250000"],["1773.37000000","0.00720000"],["1773.36000000","7.89200000"],["1773.32000000","0.00290000"],["1773.30000000","2.47500000"],["1773.26000000","0.03000000"],["1773.24000000","0.00840000"],["1773.20000000","0.00290000"],["1773.18000000","0.00340000"],["1773.12000000","7.88460000"],["1772.87000000","0.00000000"],["1772.85000000","0.00000000"],["1772.79000000","0.00000000"],["1771.98000000","0.00580000"],["1770.47000000","0.26250000"],["1598.04000000","0.01400000"],["1598.00000000","2.37030000"],["1067.00000000","6.86000000"]],"a":[["1775.56000000","60.95490000"],["1775.57000000","2.21420000"],["1775.58000000","0.00570000"],["1775.59000000","0.00600000"],["1775.60000000","4.84680000"],["1775.61000000","0.17920000"],["1775.62000000","0.60020000"],["1775.63000000","0.00590000"],["1775.64000000","0.28280000"],["1775.67000000","0.00900000"],["1775.68000000","1.16510000"],["1775.69000000","0.28570000"],["1775.72000000","0.38320000"],["1775.74000000","10.31860000"],["1775.75000000","15.78060000"],["1775.76000000","7.92040000"],["1775.78000000","0.00000000"],["1775.79000000","21.69570000"],["1775.84000000","17.86940000"],["1775.86000000","0.00000000"],["1775.89000000","0.59240000"],["1775.91000000","0.00000000"],["1775.92000000","0.32980000"],["1775.95000000","0.00000000"],["1775.96000000","0.00000000"],["1775.98000000","16.51700000"],["1776.01000000","10.45930000"],["1776.06000000","13.52150000"],["1776.15000000","16.88840000"],["1776.29000000","0.00290000"],["1776.37000000","32.65770000"],["1776.43000000","0.43990000"],["1776.48000000","20.76040000"],["1777.49000000","8.11640000"],["1777.61000000","0.00000000"]]}}
{"stream":"btcusdt@trade","data":{"e":"trade","E":1783465172775,"s":"BTCUSDT","t":6486989301,"p":"63551.02000000","q":"0.00008000","T":1783465172774,"m":true,"M":true}}
{"stream":"btcusdt@trade","data":{"e":"trade","E":1783465172775,"s":"BTCUSDT","t":6486989302,"p":"63551.02000000","q":"0.00009000","T":1783465172774,"m":true,"M":true}}
{"stream":"btcusdt@trade","data":{"e":"trade","E":1783465172775,"s":"BTCUSDT","t":6486989303,"p":"63551.02000000","q":"0.00004000","T":1783465172774,"m":true,"M":true}}
{"stream":"ethusdt@depth@100ms","data":{"e":"depthUpdate","E":1783465172815,"s":"ETHUSDT","U":78545067925,"u":78545067974,"b":[["1775.55000000","6.93000000"],["1775.52000000","0.00590000"],["1775.50000000","0.04550000"],["1775.49000000","0.87700000"],["1775.48000000","0.00290000"],["1775.45000000","0.14900000"],["1775.44000000","1.41620000"],["1775.43000000","0.59660000"],["1775.39000000","0.00290000"],["1775.38000000","7.04320000"],["1775.36000000","0.17290000"],["1775.29000000","2.68620000"],["1775.26000000","24.59370000"],["1775.15000000","1.37910000"],["1775.12000000","1.64190000"],["1775.05000000","3.92890000"],["1775.01000000","0.94260000"],["1774.82000000","16.58990000"],["1774.81000000","0.56780000"],["1774.77000000","0.16830000"],["1773.56000000","0.13250000"],["1773.54000000","0.56440000"],["1773.44000000","6.31360000"],["1770.47000000","0.25960000"],["1598.00000000","2.38430000"]],"a":[["1775.56000000","59.95490000"],["1775.63000000","0.36690000"],["1775.66000000","0.00000000"],["1775.67000000","0.00600000"],["1775.68000000","1.16210000"],["1775.74000000","11.61750000"],["1775.89000000","1.89130000"],["1775.91000000","0.35000000"],["1776.03000000","35.81600000"],["1776.17000000","3.90950000"],["1776.50000000","0.08580000"],["1776.55000000","23.54850000"],["1776.76000000","0.94180000"],["1776.82000000","0.00000000"],["1780.46000000","0.00000000"]]}}
{"stream":"btcusdt@depth@100ms","data":{"e":"depthUpdate","E":1783465172815,"s":"BTCUSDT","U":97109084847,"u":97109084869,"b":[["63551.02000000","0.02445000"],["63542.69000000","0.00000000"],["63538.55000000","1.29268000"],["63536.23000000","0.00000000"],["63535.42000000","0.00190000"],["63496.56000000","1.29261000"],["63465.66000000","0.00000000"],["57195.92000000","0.00500000"],["57195.90000000","0.00000000"],["50000.00000000","542.70415000"]],"a":[["63551.03000000","2.71534000"],["63551.51000000","0.00000000"],["63554.36000000","0.04022000"]]}}
{"stream":"btcusdt@depth@100ms","data":{"e":"depthUpdate","E":1783465172914,"s":"BTCUSDT","U":97109084870,"u":97109084873,"b":[["57195.92000000","0.00500000"]],"a":[]}}
{"stream":"ethusdt@depth@100ms","data":{"e":"depthUpdate","E":1783465172915,"s":"ETHUSDT","U":78545067975,"u":78545067993,"b":[["1775.55000000","6.93000000"],["1775.54000000","0.01170000"],["1775.49000000","0.87700000"],["1775.48000000","0.00590000"],["1775.44000000","1.41320000"],["1598.00000000","2.41210000"]],"a":[["1775.65000000","0.00290000"],["1775.78000000","0.67000000"],["1775.82000000","0.98140000"],["1775.86000000","0.75600000"],["1776.42000000","1.16630000"]]}}
{"stream":"btcusdt@trade","data":{"e":"trade","E":1783465172927,"s":"BTCUSDT","t":6486989304,"p":"63551.03000000","q":"0.00195000","T":1783465172927,"m":false,"M":true}}
{"stream":"btcusdt@depth@100ms","data":{"e":"depthUpdate","E":1783465173014,"s":"BTCUSDT","U":97109084874,"u":97109084920,"b":[["63551.02000000","0.02954000"],["63551.01000000","0.00377000"],["63549.13000000","0.09180000"],["63546.46000000","0.00018000"],["63546.45000000","0.11771000"],["63545.82000000","0.06464000"],["63545.34000000","0.00000000"],["63544.88000000","0.00018000"],["63544.66000000","0.22816000"],["63542.02000000","0.00000000"],["63538.57000000","1.21073000"],["63538.56000000","1.22840000"],["63538.55000000","0.42499000"],["63484.91000000","0.00000000"],["63484.01000000","0.00037000"],["63477.84000000","0.00000000"],["63421.06000000","0.00014000"],["63299.72000000","0.00046000"],["57195.92000000","0.00480000"],["50840.82000000","0.00083000"]],"a":[["63551.03000000","2.70552000"],["63551.51000000","0.00787000"],["63558.69000000","0.00000000"],["63559.52000000","0.20904000"],["63593.99000000","0.00389000"],["63655.82000000","0.00000000"],["63657.33000000","0.00157000"],["63668.57000000","0.00000000"],["63850.79000000","0.00046000"],["64126.33000000","0.00046000"],["64401.87000000","0.00046000"],["64677.41000000","0.00279000"]]}}
{"stream":"ethusdt@depth@100ms","data":{"e":"depthUpdate","E":1783465173015,"s":"ETHUSDT","U":78545067994,"u":78545068015,"b":[["1775.53000000","0.00590000"],["1775.38000000","0.28000000"],["1775.01000000","3.76070000"],["1774.94000000","0.00000000"],["1774.63000000","2.11440000"],["1774.24000000","0.34680000"],["1774.16000000","0.00000000"],["1773.49000000","1.13840000"],["1598.00000000","2.42610000"]],"a":[["1775.65000000","0.00000000"],["1775.68000000","0.88040000"],["1775.71000000","0.28180000"],["1775.72000000","7.14640000"],["1775.84000000","15.05130000"],["1775.86000000","1.09200000"],["1775.87000000","18.58730000"],["1775.88000000","18.93110000"],["1775.89000000","1.30470000"],["1775.95000000","0.29400000"],["1776.06000000","12.84950000"],["1776.11000000","0.00000000"],["1776.15000000","16.59440000"],["1778.83000000","0.00000000"]]}}
{"stream":"btcusdt@depth@100ms","data":{"e":"depthUpdate","E":1783465173114,"s":"BTCUSDT","U":97109084921,"u":97109084963,"b":[["63551.02000000","0.02813000"],["63549.13000000","0.09172000"],["63547.57000000","0.00675000"],["63546.45000000","0.11789000"],["63546.00000000","0.02818000"],["63545.82000000","0.06482000"],["63545.33000000","0.04921000"],["63544.88000000","0.00000000"],["63544.78000000","0.06455000"],["63538.46000000","0.00000000"],["63484.01000000","0.00000000"],["63466.57000000","0.16249000"],["63421.06000000","0.00014000"],["62597.75000000","0.00030000"],["57195.92000000","0.00480000"]],"a":[["63551.03000000","2.70570000"],["63551.51000000","0.00805000"],["63554.36000000","0.04004000"],["63592.34000000","0.00393000"],["63593.99000000","0.00000000"],["63657.26000000","0.05138000"],["63657.33000000","0.00000000"]]}}
{"stream":"ethusdt@depth@100ms","data":{"e":"depthUpdate","E":1783465173115,"s":"ETHUSDT","U":78545068016,"u":78545068022,"b":[["1775.29000000","11.13070000"],["1773.11000000","19.20040000"],["1598.00000000","2.44010000"]],"a":[["1775.64000000","0.27980000"],["1776.06000000","12.42950000"],["1778.45000000","0.75340000"]]}}
{"stream":"btcusdt@depth@100ms","data":{"e":"depthUpdate","E":1783465173214,"s":"BTCUSDT","U":97109084964,"u":97109084973,"b":[["63551.02000000","0.12033000"],["63532.68000000","0.56703000"],["63521.34000000","0.00000000"],["63024.18000000","0.00046000"],["57195.92000000","0.00480000"],["50840.82000000","0.00044000"]],"a":[]}}
{"stream":"ethusdt@depth@100ms","data":{"e":"depthUpdate","E":1783465173215,"s":"ETHUSDT","U":78545068023,"u":78545068027,"b":[["1774.62000000","8.32910000"],["1770.00000000","24.72750000"],["1598.00000000","2.45410000"]],"a":[["1775.56000000","58.49590000"]]}}
{"stream":"btcusdt@trade","data":{"e":"trade","E":1783465173297,"s":"BTCUSDT","t":6486989305,"p":"63551.02000000","q":"0.00004000","T":1783465173296,"m":true,"M":true}}
{"stream":"btcusdt@trade","data":{"e":"trade","E":1783465173297,"s":"BTCUSDT","t":6486989306,"p":"63551.02000000","q":"0.00271000","T":1783465173296,"m":true,"M":true}}
{"stream":"btcusdt@trade","data":{"e":"trade","E":1783465173297,"s":"BTCUSDT","t":6486989307,"p":"63551.02000000","q":"0.00016000","T":1783465173296,"m":true,"M":true}}
{"stream":"btcusdt@trade","data":{"e":"trade","E":1783465173297,"s":"BTCUSDT","t":6486989308,"p":"63551.02000000","q":"0.00001000","T":1783465173296,"m":true,"M":true}}
{"stream":"btcusdt@depth@100ms","data":{"e":"depthUpdate","E":1783465173314,"s":"BTCUSDT","U":97109084974,"u":97109084997,"b":[["63551.02000000","0.11886000"],["63545.33000000","0.04939000"],["63537.00000000","0.00008000"],["63533.07000000","0.18971000"],["63476.55000000","0.00000000"],["57195.92000000","0.00480000"]],"a":[["63551.03000000","2.70552000"],["63551.52000000","0.00016000"],["63554.65000000","0.00116000"],["63558.70000000","1.43589000"],["63560.01000000","0.59517000"],["63562.43000000","0.00008000"],["63565.28000000","0.00000000"]]}}
{"stream":"ethusdt@depth@100ms","data":{"e":"depthUpdate","E":1783465173315,"s":"ETHUSDT","U":78545068028,"u":78545068029,"b":[["1598.00000000","2.46810000"]],"a":[]}}
{"stream":"btcusdt@depth@100ms","data":{"e":"depthUpdate","E":1783465173414,"s":"BTCUSDT","U":97109084998,"u":97109085019,"b":[["63545.26000000","0.00016000"],["63542.13000000","0.00016000"],["63539.00000000","0.00016000"],["63536.10000000","0.09450000"],["63535.87000000","0.00016000"],["63532.74000000","0.00016000"],["63529.61000000","0.00016000"],["63526.48000000","0.00016000"],["63523.35000000","0.00016000"],["63520.22000000","0.00024000"],["63517.09000000","0.00008000"],["63476.71000000","1.02661000"],["63333.64000000","0.00000000"],["62748.64000000","0.00046000"],["57195.92000000","0.00480000"],["57195.00000000","0.00107000"],["40000.00000000","260.73952000"]],"a":[["64000.00000000","20.95379000"],["74000.00000000","14.23137000"]]}}
{"stream":"ethusdt@depth@100ms","data":{"e":"depthUpdate","E":1783465173415,"s":"ETHUSDT","U":78545068030,"u":78545068034,"b":[["1775.13000000","3.38960000"],["1598.00000000","2.48890000"]],"a":[["1788.44000000","2.23090000"]]}}
{"stream":"ethusdt@depth@100ms","data":{"e":"depthUpdate","E":1783465173516,"s":"ETHUSDT","U":78545068035,"u":78545068036,"b":[["1598.00000000","2.50290000"]],"a":[]}}
{"stream":"btcusdt@depth@100ms","data":{"e":"depthUpdate","E":1783465173516,"s":"BTCUSDT","U":97109085020,"u":97109085042,"b":[["63551.02000000","0.12036000"],["63551.01000000","0.00377000"],["63549.13000000","0.09180000"],["63547.78000000","0.00018000"],["63547.77000000","0.13725000"],["63546.46000000","0.00000000"],["63546.45000000","0.00018000"],["63546.01000000","0.00009000"],["63523.68000000","0.00400000"],["63515.73000000","0.00000000"],["63303.12000000","0.02465000"],["57195.92000000","0.00500000"],["57195.00000000","0.00087000"]],"a":[["63551.03000000","2.70747000"]]}}
{"stream":"btcusdt@depth@100ms","data":{"e":"depthUpdate","E":1783465173614,"s":"BTCUSDT","U":97109085043,"u":97109085059,"b":[["63549.13000000","0.09172000"],["63548.00000000","0.02818000"],["63547.77000000","0.13743000"],["63547.57000000","0.00675000"],["63546.45000000","0.00000000"],["57195.92000000","0.00500000"]],"a":[]}}
{"stream":"ethusdt@depth@100ms","data":{"e":"depthUpdate","E":1783465173615,"s":"ETHUSDT","U":78545068037,"u":78545068051,"b":[["1775.55000000","6.93000000"],["1775.49000000","0.87700000"],["1775.29000000","3.79040000"],["1775.26000000","0.00290000"],["1773.56000000","0.13250000"],["1773.54000000","0.56440000"],["1598.00000000","2.51690000"]],"a":[["1775.58000000","0.00860000"],["1775.68000000","1.16220000"],["1775.71000000","0.00000000"]]}}
{"stream":"btcusdt@depth@100ms","data":{"e":"depthUpdate","E":1783465173714,"s":"BTCUSDT","U":97109085060,"u":97109085070,"b":[["63551.02000000","0.11886000"],["62473.11000000","0.00055000"],["57195.92000000","0.00480000"],["50840.82000000","0.00044000"]],"a":[["64504.30000000","0.00030000"]]}}
{"stream":"ethusdt@depth@100ms","data":{"e":"depthUpdate","E":1783465173715,"s":"ETHUSDT","U":78545068052,"u":78545068059,"b":[["1775.20000000","0.03290000"],["1598.00000000","2.53090000"]],"a":[["1775.56000000","58.49890000"],["1775.57000000","2.21720000"],["1775.58000000","0.01160000"],["1775.59000000","0.00900000"],["1775.64000000","0.28280000"],["1775.92000000","0.32690000"]]}}
{"stream":"ethusdt@depth@100ms","data":{"e":"depthUpdate","E":1783465173816,"s":"ETHUSDT","U":78545068060,"u":78545068068,"b":[["1775.29000000","10.98960000"],["1775.26000000","24.59370000"],["1775.20000000","0.03580000"],["1598.00000000","2.55870000"]],"a":[["1775.92000000","0.32980000"],["1953.12000000","0.00710000"]]}}
{"stream":"btcusdt@depth@100ms","data":{"e":"depthUpdate","E":1783465173816,"s":"BTCUSDT","U":97109085071,"u":97109085074,"b":[["57195.92000000","0.00480000"]],"a":[]}}
{"stream":"btcusdt@depth@100ms","data":{"e":"depthUpdate","E":1783465173914,"s":"BTCUSDT","U":97109085075,"u":97109085085,"b":[["63500.01000000","1.16441000"],["63476.57000000","0.41589000"],["57195.92000000","0.00480000"],["50841.00000000","0.24023000"]],"a":[["63551.71000000","0.06434000"],["63553.83000000","0.09070000"],["63631.53000000","0.00000000"]]}}
{"stream":"ethusdt@depth@100ms","data":{"e":"depthUpdate","E":1783465173915,"s":"ETHUSDT","U":78545068069,"u":78545068081,"b":[["1775.55000000","6.93290000"],["1775.54000000","0.01460000"],["1775.51000000","0.00900000"],["1775.50000000","6.80870000"],["1775.46000000","0.07560000"],["1598.00000000","2.56570000"]],"a":[["1775.78000000","3.15000000"],["1776.03000000","33.34800000"],["1953.12000000","0.00420000"]]}}
{"stream":"btcusdt@depth@100ms","data":{"e":"depthUpdate","E":1783465174014,"s":"BTCUSDT","U":97109085086,"u":97109085134,"b":[["63551.02000000","0.11536000"],["63547.78000000","0.00000000"],["63547.77000000","0.00018000"],["63546.01000000","0.00018000"],["63545.83000000","0.00009000"],["63544.66000000","0.00316000"],["63542.16000000","0.00000000"],["63541.90000000","0.00787000"],["63541.49000000","0.00000000"],["63541.34000000","0.00000000"],["63536.10000000","0.00000000"],["63535.84000000","0.01000000"],["63533.84000000","0.02000000"],["63484.91000000","0.00037000"],["63476.35000000","0.00000000"],["63421.66000000","0.00014000"],["63421.06000000","0.00000000"],["57195.92000000","0.00480000"],["50841.00000000","0.23623000"],["50840.82000000","0.00083000"]],"a":[["63551.03000000","2.71534000"],["63551.51000000","0.00018000"],["63553.17000000","0.03969000"],["63553.83000000","0.09088000"],["63554.34000000","0.01000000"],["63558.69000000","0.12174000"],["63558.81000000","0.00000000"],["63559.52000000","0.00000000"],["63592.34000000","0.00393000"],["63655.82000000","0.00157000"]]}}
{"stream":"ethusdt@depth@100ms","data":{"e":"depthUpdate","E":1783465174015,"s":"ETHUSDT","U":78545068082,"u":78545068089,"b":[["1774.85000000","11.16750000"],["1774.61000000","15.59550000"],["1774.40000000","0.46700000"],["1773.97000000","21.16250000"],["1598.00000000","2.55870000"]],"a":[["1775.68000000","0.88040000"],["1775.71000000","0.28180000"]]}}
{"stream":"btcusdt@depth@100ms","data":{"e":"depthUpdate","E":1783465174115,"s":"BTCUSDT","U":97109085135,"u":97109085159,"b":[["63549.13000000","0.09164000"],["63548.00000000","0.02818000"],["63547.77000000","0.00000000"],["63544.78000000","0.06473000"],["63484.91000000","0.00000000"],["62597.75000000","0.00030000"],["57195.92000000","0.00500000"]],"a":[["63551.03000000","2.71534000"],["63551.51000000","0.00000000"],["63554.34000000","0.01018000"],["63592.34000000","0.00393000"],["63655.82000000","0.00157000"]]}}
{"stream":"ethusdt@depth@100ms","data":{"e":"depthUpdate","E":1783465174115,"s":"ETHUSDT","U":78545068090,"u":78545068093,"b":[["1598.00000000","2.55870000"]],"a":[]}}
{"stream":"btcusdt@trade","data":{"e":"trade","E":1783465174193,"s":"BTCUSDT","t":6486989309,"p":"63551.03000000","q":"0.00089000","T":1783465174193,"m":false,"M":true}}
{"stream":"btcusdt@depth@100ms","data":{"e":"depthUpdate","E":1783465174214,"s":"BTCUSDT","U":97109085160,"u":97109085170,"b":[["63546.37000000","0.14015000"],["63536.09000000","0.09450000"],["63466.57000000","0.05552000"],["57195.92000000","0.00510000"],["50840.82000000","0.00044000"]],"a":[["63551.03000000","2.71445000"]]}}
{"stream":"ethusdt@depth@100ms","data":{"e":"depthUpdate","E":1783465174215,"s":"ETHUSDT","U":78545068094,"u":78545068099,"b":[["1775.01000000","0.94260000"],["1774.98000000","2.83390000"],["1598.00000000","2.55870000"]],"a":[["1775.60000000","4.84970000"]]}}
{"stream":"btcusdt@depth@100ms","data":{"e":"depthUpdate","E":1783465174314,"s":"BTCUSDT","U":97109085171,"u":97109085196,"b":[["63551.02000000","0.11536000"],["63551.01000000","0.00386000"],["63549.13000000","0.09172000"],["63547.57000000","0.00675000"],["63546.38000000","0.00018000"],["63546.37000000","0.14033000"],["63545.83000000","0.00000000"],["63544.78000000","0.06455000"],["63537.00000000","0.00008000"],["57195.92000000","0.00510000"]],"a":[["63562.43000000","0.00008000"],["63740.62000000","0.00354000"],["63751.49000000","0.00000000"]]}}
{"stream":"ethusdt@depth@100ms","data":{"e":"depthUpdate","E":1783465174315,"s":"ETHUSDT","U":78545068100,"u":78545068109,"b":[["1775.55000000","6.93860000"],["1775.54000000","0.02030000"],["1775.53000000","0.01160000"],["1773.67000000","12.22300000"],["1598.00000000","2.57250000"]],"a":[]}}
{"stream":"btcusdt@depth@100ms","data":{"e":"depthUpdate","E":1783465174414,"s":"BTCUSDT","U":97109085197,"u":97109085202,"b":[["57195.92000000","0.00490000"],["40000.00000000","260.73952000"]],"a":[["63558.69000000","0.00000000"],["63559.52000000","0.27663000"]]}}
{"stream":"ethusdt@depth@100ms","data":{"e":"depthUpdate","E":1783465174415,"s":"ETHUSDT","U":78545068110,"u":78545068114,"b":[["1676.97000000","0.08530000"],["1598.00000000","2.57250000"]],"a":[]}}
{"stream":"btcusdt@depth@100ms","data":{"e":"depthUpdate","E":1783465174514,"s":"BTCUSDT","U":97109085203,"u":97109085208,"b":[["63476.29000000","0.07095000"],["58466.94000000","0.00018000"],["57195.92000000","0.00490000"]],"a":[]}}
{"stream":"ethusdt@depth@100ms","data":{"e":"depthUpdate","E":1783465174515,"s":"ETHUSDT","U":78545068115,"u":78545068120,"b":[["1598.00000000","2.57950000"],["1067.00000000","6.86000000"]],"a":[["1775.84000000","0.03290000"]]}}
{"stream":"btcusdt@depth@100ms","data":{"e":"depthUpdate","E":1783465174614,"s":"BTCUSDT","U":97109085209,"u":97109085217,"b":[["63100.00000000","3.64417000"],["57195.92000000","0.00490000"],["57195.00000000","0.00087000"]],"a":[["63558.81000000","0.11127000"],["63559.52000000","0.00000000"],["63592.34000000","0.00000000"]]}}
{"stream":"ethusdt@depth@100ms","data":{"e":"depthUpdate","E":1783465174615,"s":"ETHUSDT","U":78545068121,"u":78545068125,"b":[["1598.00000000","2.57950000"]],"a":[["1775.84000000","15.05160000"]]}}
{"stream":"btcusdt@depth@100ms","data":{"e":"depthUpdate","E":1783465174714,"s":"BTCUSDT","U":97109085218,"u":97109085226,"b":[["57195.92000000","0.00490000"],["50840.82000000","0.00044000"]],"a":[["64504.30000000","0.00030000"],["77811.66000000","0.00000000"]]}}
{"stream":"ethusdt@depth@100ms","data":{"e":"depthUpdate","E":1783465174715,"s":"ETHUSDT","U":78545068126,"u":78545068130,"b":[["1598.00000000","2.58630000"]],"a":[]}}
{"stream":"btcusdt@depth@100ms","data":{"e":"depthUpdate","E":1783465174814,"s":"BTCUSDT","U":97109085227,"u":97109085233,"b":[["57195.92000000","0.00510000"],["50840.82000000","0.00044000"],["50000.00000000","542.70395000"]],"a":[["63551.03000000","2.71534000"]]}}
{"stream":"ethusdt@depth@100ms","data":{"e":"depthUpdate","E":1783465174816,"s":"ETHUSDT","U":78545068131,"u":78545068137,"b":[["1775.20000000","0.03580000"],["1598.00000000","2.58630000"]],"a":[["1775.92000000","0.32980000"]]}}
{"stream":"btcusdt@depth@100ms","data":{"e":"depthUpdate","E":1783465174915,"s":"BTCUSDT","U":97109085234,"u":97109085237,"b":[["57195.92000000","0.00510000"]],"a":[]}}
{"stream":"ethusdt@depth@100ms","data":{"e":"depthUpdate","E":1783465174915,"s":"ETHUSDT","U":78545068138,"u":78545068141,"b":[["1598.00000000","2.58630000"]],"a":[]}}
{"stream":"btcusdt@depth@100ms","data":{"e":"depthUpdate","E":1783465175014,"s":"BTCUSDT","U":97109085238,"u":97109085262,"b":[["63550.00000000","0.03877000"],["63541.76000000","0.00000000"],["63482.80000000","0.03687000"],["63476.57000000","0.00000000"],["63421.66000000","0.00000000"],["63416.67000000","0.00014000"],["57195.92000000","0.00490000"],["50840.82000000","0.00083000"]],"a":[["63551.03000000","2.70747000"],["63551.51000000","0.00787000"],["63558.81000000","0.00000000"],["63559.52000000","0.24960000"],["63631.53000000","0.00000000"],["63655.82000000","0.00000000"],["63661.56000000","0.00157000"]]}}
{"stream":"ethusdt@depth@100ms","data":{"e":"depthUpdate","E":1783465175015,"s":"ETHUSDT","U":78545068142,"u":78545068145,"b":[["1598.00000000","2.58630000"]],"a":[]}}
{"stream":"btcusdt@depth@100ms","data":{"e":"depthUpdate","E":1783465175114,"s":"BTCUSDT","U":97109085263,"u":97109085283,"b":[["63418.01000000","0.00014000"],["63416.67000000","0.00000000"],["62597.75000000","0.00030000"],["58466.94000000","0.00000000"],["57195.92000000","0.00490000"]],"a":[["63551.03000000","2.70765000"],["63554.34000000","0.01000000"],["63558.81000000","0.07904000"],["63559.52000000","0.00000000"],["63659.99000000","0.00157000"],["63661.56000000","0.00000000"]]}}
{"stream":"ethusdt@depth@100ms","data":{"e":"depthUpdate","E":1783465175115,"s":"ETHUSDT","U":78545068146,"u":78545068148,"b":[["1598.00000000","2.59330000"]],"a":[]}}
{"stream":"btcusdt@depth@100ms","data":{"e":"depthUpdate","E":1783465175214,"s":"BTCUSDT","U":97109085284,"u":97109085288,"b":[["57195.92000000","0.00490000"],["50840.82000000","0.00044000"]],"a":[]}}
{"stream":"ethusdt@depth@100ms","data":{"e":"depthUpdate","E":1783465175215,"s":"ETHUSDT","U":78545068149,"u":78545068159,"b":[["1774.49000000","0.85520000"],["1772.76000000","0.74700000"],["1772.73000000","0.00000000"],["1772.62000000","1.09830000"],["1598.00000000","2.60710000"]],"a":[]}}
{"stream":"btcusdt@depth@100ms","data":{"e":"depthUpdate","E":1783465175314,"s":"BTCUSDT","U":97109085289,"u":97109085293,"b":[["63537.00000000","0.00000000"],["57195.92000000","0.00490000"]],"a":[["63562.43000000","0.00000000"]]}}
{"stream":"ethusdt@depth@100ms","data":{"e":"depthUpdate","E":1783465175316,"s":"ETHUSDT","U":78545068160,"u":78545068163,"b":[["1598.00000000","2.60710000"]],"a":[]}}
{"stream":"btcusdt@depth@100ms","data":{"e":"depthUpdate","E":1783465175414,"s":"BTCUSDT","U":97109085294,"u":97109085304,"b":[["63540.58000000","0.00989000"],["63537.00000000","0.00008000"],["63476.71000000","0.00000000"],["63474.61000000","1.02661000"],["57195.92000000","0.00490000"],["40000.00000000","260.73952000"]],"a":[["63562.43000000","0.00008000"]]}}
{"stream":"ethusdt@depth@100ms","data":{"e":"depthUpdate","E":1783465175415,"s":"ETHUSDT","U":78545068164,"u":78545068166,"b":[["1598.00000000","2.60010000"]],"a":[]}}
{"stream":"btcusdt@depth@100ms","data":{"e":"depthUpdate","E":1783465175514,"s":"BTCUSDT","U":97109085305,"u":97109085311,"b":[["57195.92000000","0.00510000"],["50841.00000000","0.23623000"]],"a":[["63612.48000000","0.03109000"],["63739.99000000","0.06310000"]]}}
{"stream":"ethusdt@depth@100ms","data":{"e":"depthUpdate","E":1783465175515,"s":"ETHUSDT","U":78545068167,"u":78545068173,"b":[["1769.70000000","1.70740000"],["1768.75000000","0.00640000"],["1598.00000000","2.58630000"]],"a":[]}}
{"stream":"btcusdt@depth@100ms","data":{"e":"depthUpdate","E":1783465175614,"s":"BTCUSDT","U":97109085312,"u":97109085317,"b":[["57195.92000000","0.00510000"],["33000.00000000","35.16979000"]],"a":[]}}
{"stream":"ethusdt@depth@100ms","data":{"e":"depthUpdate","E":1783465175616,"s":"ETHUSDT","U":78545068174,"u":78545068179,"b":[["1598.00000000","2.60010000"]],"a":[]}}
{"stream":"btcusdt@depth@100ms","data":{"e":"depthUpdate","E":1783465175714,"s":"BTCUSDT","U":97109085318,"u":97109085327,"b":[["63413.77000000","0.09461000"],["57195.92000000","0.00490000"],["57195.00000000","0.00087000"],["50840.82000000","0.00044000"]],"a":[["64504.30000000","0.00030000"]]}}
{"stream":"ethusdt@depth@100ms","data":{"e":"depthUpdate","E":1783465175715,"s":"ETHUSDT","U":78545068180,"u":78545068187,"b":[["1775.37000000","1.49880000"],["1598.00000000","2.60010000"]],"a":[["1775.74000000","11.33350000"],["1777.32000000","17.94800000"],["1777.56000000","15.02670000"]]}}
{"stream":"ethusdt@depth@100ms","data":{"e":"depthUpdate","E":1783465175819,"s":"ETHUSDT","U":78545068188,"u":78545068194,"b":[["1775.20000000","0.03580000"],["1598.00000000","2.60710000"]],"a":[["1775.92000000","0.32980000"],["1777.54000000","4.48200000"]]}}
{"stream":"btcusdt@depth@100ms","data":{"e":"depthUpdate","E":1783465175819,"s":"BTCUSDT","U":97109085328,"u":97109085333,"b":[["57195.92000000","0.00490000"],["50840.82000000","0.00044000"]],"a":[]}}
{"stream":"ethusdt@depth@100ms","data":{"e":"depthUpdate","E":1783465175915,"s":"ETHUSDT","U":78545068195,"u":78545068198,"b":[["1598.00000000","2.60710000"]],"a":[]}}
{"stream":"btcusdt@depth@100ms","data":{"e":"depthUpdate","E":1783465175915,"s":"BTCUSDT","U":97109085334,"u":97109085339,"b":[["63549.12000000","0.00000000"],["63547.23000000","0.00153000"],["57195.92000000","0.00490000"]],"a":[]}}
{"stream":"btcusdt@depth@100ms","data":{"e":"depthUpdate","E":1783465176014,"s":"BTCUSDT","U":97109085340,"u":97109085361,"b":[["63541.49000000","0.00000000"],["63506.93000000","0.37906000"],["63418.01000000","0.00014000"],["57195.92000000","0.00490000"],["50840.82000000","0.00083000"]],"a":[["63551.03000000","2.70765000"],["63558.81000000","0.00000000"],["63559.52000000","0.25356000"],["63631.53000000","0.05624000"],["63659.99000000","0.00157000"]]}}
{"stream":"ethusdt@depth@100ms","data":{"e":"depthUpdate","E":1783465176015,"s":"ETHUSDT","U":78545068199,"u":78545068203,"b":[["1598.00000000","2.58630000"]],"a":[]}}
{"stream":"btcusdt@depth@100ms","data":{"e":"depthUpdate","E":1783465176114,"s":"BTCUSDT","U":97109085362,"u":97109085374,"b":[["63421.66000000","0.00014000"],["63418.01000000","0.00000000"],["62597.75000000","0.00030000"],["57195.92000000","0.00510000"]],"a":[["63631.53000000","0.00000000"],["63655.99000000","0.00157000"],["63659.99000000","0.00000000"]]}}
{"stream":"ethusdt@depth@100ms","data":{"e":"depthUpdate","E":1783465176116,"s":"ETHUSDT","U":78545068204,"u":78545068209,"b":[["1598.00000000","2.60010000"]],"a":[]}}
{"stream":"btcusdt@depth@100ms","data":{"e":"depthUpdate","E":1783465176214,"s":"BTCUSDT","U":97109085375,"u":97109085379,"b":[["57195.92000000","0.00510000"],["50840.82000000","0.00044000"]],"a":[]}}
{"stream":"ethusdt@depth@100ms","data":{"e":"depthUpdate","E":1783465176215,"s":"ETHUSDT","U":78545068210,"u":78545068214,"b":[["1598.00000000","2.60010000"]],"a":[["1775.60000000","5.13780000"]]}}
{"stream":"btcusdt@depth@100ms","data":{"e":"depthUpdate","E":1783465176314,"s":"BTCUSDT","U":97109085380,"u":97109085386,"b":[["63413.77000000","0.00000000"],["57195.92000000","0.00510000"]],"a":[["63612.48000000","0.00000000"],["63739.99000000","0.00000000"]]}}
{"stream":"ethusdt@depth@100ms","data":{"e":"depthUpdate","E":1783465176316,"s":"ETHUSDT","U":78545068215,"u":78545068220,"b":[["1598.00000000","2.60010000"],["1067.00000000","6.86000000"]],"a":[]}}
{"stream":"btcusdt@depth@100ms","data":{"e":"depthUpdate","E":1783465176414,"s":"BTCUSDT","U":97109085387,"u":97109085398,"b":[["63539.75000000","0.00868000"],["63537.00000000","0.00008000"],["63475.40000000","0.00177000"],["57195.92000000","0.00490000"],["50841.00000000","0.23623000"],["40000.00000000","260.73952000"]],"a":[["63562.43000000","0.00008000"]]}}
{"stream":"ethusdt@depth@100ms","data":{"e":"depthUpdate","E":1783465176415,"s":"ETHUSDT","U":78545068221,"u":78545068228,"b":[["1773.11000000","17.52340000"],["1598.00000000","2.58630000"]],"a":[["1778.45000000","0.68060000"]]}}
{"stream":"btcusdt@depth@100ms","data":{"e":"depthUpdate","E":1783465176514,"s":"BTCUSDT","U":97109085399,"u":97109085404,"b":[["57195.92000000","0.00490000"]],"a":[["63551.03000000","2.70481000"]]}}
{"stream":"ethusdt@depth@100ms","data":{"e":"depthUpdate","E":1783465176515,"s":"ETHUSDT","U":78545068229,"u":78545068235,"b":[["1773.49000000","1.75850000"],["1598.00000000","2.60710000"]],"a":[["1778.83000000","0.56540000"]]}}
{"stream":"btcusdt@depth@100ms","data":{"e":"depthUpdate","E":1783465176614,"s":"BTCUSDT","U":97109085405,"u":97109085424,"b":[["63551.02000000","0.11524000"],["63432.63000000","0.00000000"],["57195.92000000","0.00490000"]],"a":[["63551.03000000","2.68209000"],["63619.49000000","1.91970000"],["63621.59000000","0.00000000"],["63677.41000000","0.00037000"]]}}
{"stream":"ethusdt@depth@100ms","data":{"e":"depthUpdate","E":1783465176615,"s":"ETHUSDT","U":78545068236,"u":78545068239,"b":[["1598.00000000","2.60710000"]],"a":[]}}
{"stream":"btcusdt@depth@100ms","data":{"e":"depthUpdate","E":1783465176714,"s":"BTCUSDT","U":97109085425,"u":97109085434,"b":[["63427.34000000","0.00066000"],["57195.92000000","0.00490000"]],"a":[["63551.03000000","2.50765000"],["63672.10000000","0.00066000"],["64504.30000000","0.00030000"]]}}
{"stream":"ethusdt@depth@100ms","data":{"e":"depthUpdate","E":1783465176716,"s":"ETHUSDT","U":78545068240,"u":78545068243,"b":[["1774.81000000","0.00430000"],["1598.00000000","2.60010000"]],"a":[]}}
{"stream":"ethusdt@depth@100ms","data":{"e":"depthUpdate","E":1783465176815,"s":"ETHUSDT","U":78545068244,"u":78545068248,"b":[["1775.20000000","0.03290000"],["1598.00000000","2.60010000"]],"a":[["1775.92000000","0.32690000"]]}}
{"stream":"btcusdt@depth@100ms","data":{"e":"depthUpdate","E":1783465176815,"s":"BTCUSDT","U":97109085435,"u":97109085444,"b":[["57195.92000000","0.00520000"],["57195.00000000","0.00087000"],["50840.82000000","0.00044000"]],"a":[]}}
{"stream":"btcusdt@depth@100ms","data":{"e":"depthUpdate","E":1783465176914,"s":"BTCUSDT","U":97109085445,"u":97109085449,"b":[["57195.92000000","0.00510000"]],"a":[]}}
{"stream":"ethusdt@depth@100ms","data":{"e":"depthUpdate","E":1783465176915,"s":"ETHUSDT","U":78545068249,"u":78545068256,"b":[["1775.20000000","0.03580000"],["1598.00000000","2.58630000"]],"a":[["1775.92000000","0.32980000"]]}}
{"stream":"btcusdt@trade","data":{"e":"trade","E":1783465176947,"s":"BTCUSDT","t":6486989310,"p":"63551.02000000","q":"0.00095000","T":1783465176947,"m":true,"M":true}}
{"stream":"btcusdt@depth@100ms","data":{"e":"depthUpdate","E":1783465177014,"s":"BTCUSDT","U":97109085450,"u":97109085478,"b":[["63551.02000000","0.11429000"],["63541.49000000","0.00000000"],["63535.94000000","0.56700000"],["63525.81000000","0.00008000"],["63421.66000000","0.00014000"],["57195.92000000","0.00480000"],["57195.91000000","0.00010000"],["50840.82000000","0.00083000"]],"a":[["63551.03000000","2.50747000"],["63551.51000000","0.00805000"],["63631.53000000","0.05624000"],["63655.99000000","0.00157000"]]}}
{"stream":"ethusdt@depth@100ms","data":{"e":"depthUpdate","E":1783465177015,"s":"ETHUSDT","U":78545068257,"u":78545068266,"b":[["1775.02000000","1.21700000"],["1774.85000000","9.09880000"],["1773.96000000","0.42300000"],["1598.00000000","2.60010000"]],"a":[["2342.74000000","0.00000000"]]}}
{"stream":"btcusdt@depth@100ms","data":{"e":"depthUpdate","E":1783465177115,"s":"BTCUSDT","U":97109085479,"u":97109085490,"b":[["63421.66000000","0.00014000"],["62597.75000000","0.00030000"],["57195.92000000","0.00480000"]],"a":[["63631.53000000","0.00000000"],["63655.82000000","0.00157000"],["63655.99000000","0.00000000"]]}}
{"stream":"ethusdt@depth@100ms","data":{"e":"depthUpdate","E":1783465177116,"s":"ETHUSDT","U":78545068267,"u":78545068270,"b":[["1598.00000000","2.60710000"]],"a":[["1775.60000000","5.12690000"]]}}
{"stream":"btcusdt@depth@100ms","data":{"e":"depthUpdate","E":1783465177214,"s":"BTCUSDT","U":97109085491,"u":97109085495,"b":[["57195.92000000","0.00480000"],["50840.82000000","0.00044000"]],"a":[]}}
{"stream":"ethusdt@depth@100ms","data":{"e":"depthUpdate","E":1783465177217,"s":"ETHUSDT","U":78545068271,"u":78545068277,"b":[["1775.42000000","0.72530000"],["1598.00000000","2.60710000"]],"a":[["1775.72000000","6.86320000"],["2342.74000000","0.01500000"]]}}
{"stream":"btcusdt@depth@100ms","data":{"e":"depthUpdate","E":1783465177314,"s":"BTCUSDT","U":97109085496,"u":97109085499,"b":[["57195.92000000","0.00480000"]],"a":[]}}
{"stream":"ethusdt@depth@100ms","data":{"e":"depthUpdate","E":1783465177315,"s":"ETHUSDT","U":78545068278,"u":78545068283,"b":[["1598.00000000","2.59330000"]],"a":[]}}
{"stream":"btcusdt@depth@100ms","data":{"e":"depthUpdate","E":1783465177414,"s":"BTCUSDT","U":97109085500,"u":97109085508,"b":[["63537.00000000","0.00008000"],["57195.92000000","0.00480000"],["40000.00000000","260.73952000"]],"a":[["63562.43000000","0.00008000"]]}}
{"stream":"ethusdt@depth@100ms","data":{"e":"depthUpdate","E":1783465177415,"s":"ETHUSDT","U":78545068284,"u":78545068293,"b":[["1775.45000000","0.14300000"],["1775.44000000","0.00890000"],["1775.29000000","9.58520000"],["1775.15000000","0.44280000"],["1775.01000000","0.00620000"],["1598.00000000","2.60010000"]],"a":[["1775.74000000","10.03460000"],["1775.88000000","18.54340000"],["1775.89000000","0.00580000"],["1776.03000000","32.48210000"],["1776.17000000","3.04360000"]]}}
{"stream":"btcusdt@depth@100ms","data":{"e":"depthUpdate","E":1783465177514,"s":"BTCUSDT","U":97109085509,"u":97109085513,"b":[["63476.71000000","1.02661000"],["63474.61000000","0.00000000"],["57195.92000000","0.00500000"]],"a":[]}}
{"stream":"ethusdt@depth@100ms","data":{"e":"depthUpdate","E":1783465177515,"s":"ETHUSDT","U":78545068294,"u":78545068316,"b":[["1775.55000000","6.93570000"],["1775.45000000","0.14600000"],["1775.44000000","1.41320000"],["1775.38000000","0.28000000"],["1775.29000000","10.98960000"],["1775.15000000","1.37910000"],["1775.01000000","0.94260000"],["1774.82000000","17.15340000"],["1773.05000000","0.00630000"],["1598.00000000","2.60010000"]],"a":[["1775.62000000","0.60320000"],["1775.74000000","11.33350000"],["1775.87000000","15.76920000"],["1775.88000000","19.28870000"],["1775.89000000","4.12280000"],["1776.03000000","33.34800000"],["1776.17000000","3.90950000"],["1777.79000000","0.00630000"],["1777.83000000","0.20310000"]]}}
{"stream":"btcusdt@depth@100ms","data":{"e":"depthUpdate","E":1783465177614,"s":"BTCUSDT","U":97109085514,"u":97109085517,"b":[["57195.92000000","0.00500000"]],"a":[]}}
{"stream":"ethusdt@depth@100ms","data":{"e":"depthUpdate","E":1783465177615,"s":"ETHUSDT","U":78545068317,"u":78545068320,"b":[["1598.00000000","2.60010000"]],"a":[]}}
{"stream":"btcusdt@depth@100ms","data":{"e":"depthUpdate","E":1783465177714,"s":"BTCUSDT","U":97109085518,"u":97109085523,"b":[["63551.02000000","0.11463000"],["57195.92000000","0.00480000"]],"a":[["64504.30000000","0.00030000"]]}}
{"stream":"ethusdt@depth@100ms","data":{"e":"depthUpdate","E":1783465177715,"s":"ETHUSDT","U":78545068321,"u":78545068343,"b":[["1775.55000000","5.47960000"],["1775.45000000","0.14900000"],["1774.61000000","14.79550000"],["1774.49000000","1.65520000"],["1598.00000000","2.60010000"]],"a":[["1775.56000000","61.99210000"],["1775.57000000","0.89080000"],["1775.60000000","0.32990000"],["1775.67000000","0.00000000"],["1776.58000000","1.40000000"],["1776.77000000","15.71630000"],["1776.78000000","36.39740000"],["1776.95000000","7.88190000"]]}}
{"stream":"btcusdt@trade","data":{"e":"trade","E":1783465177716,"s":"BTCUSDT","t":6486989311,"p":"63551.02000000","q":"0.00175000","T":1783465177716,"m":true,"M":true}}
{"stream":"btcusdt@trade","data":{"e":"trade","E":1783465177716,"s":"BTCUSDT","t":6486989312,"p":"63551.02000000","q":"0.00008000","T":1783465177716,"m":true,"M":true}}
{"stream":"btcusdt@trade","data":{"e":"trade","E":1783465177716,"s":"BTCUSDT","t":6486989313,"p":"63551.02000000","q":"0.00063000","T":1783465177716,"m":true,"M":true}}
{"stream":"btcusdt@trade","data":{"e":"trade","E":1783465177716,"s":"BTCUSDT","t":6486989314,"p":"63551.02000000","q":"0.00754000","T":1783465177716,"m":true,"M":true}}
{"stream":"btcusdt@trade","data":{"e":"trade","E":1783465177716,"s":"BTCUSDT","t":6486989315,"p":"63551.02000000","q":"0.00032000","T":1783465177716,"m":true,"M":true}}
{"stream":"btcusdt@trade","data":{"e":"trade","E":1783465177716,"s":"BTCUSDT","t":6486989316,"p":"63551.02000000","q":"0.00271000","T":1783465177716,"m":true,"M":true}}
{"stream":"btcusdt@trade","data":{"e":"trade","E":1783465177716,"s":"BTCUSDT","t":6486989317,"p":"63551.02000000","q":"0.00271000","T":1783465177716,"m":true,"M":true}}
{"stream":"btcusdt@trade","data":{"e":"trade","E":1783465177716,"s":"BTCUSDT","t":6486989318,"p":"63551.02000000","q":"0.00271000","T":1783465177716,"m":true,"M":true}}
{"stream":"btcusdt@trade","data":{"e":"trade","E":1783465177716,"s":"BTCUSDT","t":6486989319,"p":"63551.02000000","q":"0.00008000","T":1783465177716,"m":true,"M":true}}
{"stream":"btcusdt@trade","data":{"e":"trade","E":1783465177716,"s":"BTCUSDT","t":6486989320,"p":"63551.02000000","q":"0.00078000","T":1783465177716,"m":true,"M":true}}
{"stream":"btcusdt@trade","data":{"e":"trade","E":1783465177716,"s":"BTCUSDT","t":6486989321,"p":"63551.02000000","q":"0.00008000","T":1783465177716,"m":true,"M":true}}
{"stream":"btcusdt@trade","data":{"e":"trade","E":1783465177716,"s":"BTCUSDT","t":6486989322,"p":"63551.02000000","q":"0.00009000","T":1783465177716,"m":true,"M":true}}
{"stream":"btcusdt@trade","data":{"e":"trade","E":1783465177716,"s":"BTCUSDT","t":6486989323,"p":"63551.02000000","q":"0.00009000","T":1783465177716,"m":true,"M":true}}
{"stream":"btcusdt@trade","data":{"e":"trade","E":1783465177716,"s":"BTCUSDT","t":6486989324,"p":"63551.02000000","q":"0.00009000","T":1783465177716,"m":true,"M":true}}
{"stream":"btcusdt@trade","data":{"e":"trade","E":1783465177716,"s":"BTCUSDT","t":6486989325,"p":"63551.02000000","q":"0.00009000","T":1783465177716,"m":true,"M":true}}
{"stream":"btcusdt@trade","data":{"e":"trade","E":1783465177716,"s":"BTCUSDT","t":6486989326,"p":"63551.02000000","q":"0.00009000","T":1783465177716,"m":true,"M":true}}
{"stream":"btcusdt@trade","data":{"e":"trade","E":1783465177716,"s":"BTCUSDT","t":6486989327,"p":"63551.02000000","q":"0.00009000","T":1783465177716,"m":true,"M":true}}
{"stream":"btcusdt@trade","data":{"e":"trade","E":1783465177716,"s":"BTCUSDT","t":6486989328,"p":"63551.02000000","q":"0.00009000","T":1783465177716,"m":true,"M":true}}
{"stream":"btcusdt@trade","data":{"e":"trade","E":1783465177716,"s":"BTCUSDT","t":6486989329,"p":"63551.02000000","q":"0.00009000","T":1783465177716,"m":true,"M":true}}
{"stream":"btcusdt@trade","data":{"e":"trade","E":1783465177716,"s":"BTCUSDT","t":6486989330,"p":"63551.02000000","q":"0.00009000","T":1783465177716,"m":true,"M":true}}
{"stream":"btcusdt@trade","data":{"e":"trade","E":1783465177716,"s":"BTCUSDT","t":6486989331,"p":"63551.02000000","q":"0.00009000","T":1783465177716,"m":true,"M":true}}
{"stream":"btcusdt@trade","data":{"e":"trade","E":1783465177716,"s":"BTCUSDT","t":6486989332,"p":"63551.02000000","q":"0.00008000","T":1783465177716,"m":true,"M":true}}
{"stream":"btcusdt@trade","data":{"e":"trade","E":1783465177716,"s":"BTCUSDT","t":6486989333,"p":"63551.02000000","q":"0.00009000","T":1783465177716,"m":true,"M":true}}
{"stream":"btcusdt@trade","data":{"e":"trade","E":1783465177716,"s":"BTCUSDT","t":6486989334,"p":"63551.02000000","q":"0.00009000","T":1783465177716,"m":true,"M":true}}
{"stream":"btcusdt@trade","data":{"e":"trade","E":1783465177716,"s":"BTCUSDT","t":6486989335,"p":"63551.02000000","q":"0.02945000","T":1783465177716,"m":true,"M":true}}
{"stream":"btcusdt@trade","data":{"e":"trade","E":1783465177716,"s":"BTCUSDT","t":6486989336,"p":"63551.02000000","q":"0.02000000","T":1783465177716,"m":true,"M":true}}
{"stream":"btcusdt@trade","data":{"e":"trade","E":1783465177718,"s":"BTCUSDT","t":6486989337,"p":"63551.02000000","q":"0.00010000","T":1783465177718,"m":true,"M":true}}
{"stream":"btcusdt@depth@100ms","data":{"e":"depthUpdate","E":1783465177814,"s":"BTCUSDT","U":97109085524,"u":97109085656,"b":[["63551.02000000","0.02272000"],["63551.01000000","0.00368000"],["63549.13000000","0.09164000"],["63546.52000000","0.00000000"],["63546.38000000","0.00000000"],["63546.37000000","0.00018000"],["63545.82000000","0.00027000"],["63545.52000000","0.00000000"],["63545.34000000","0.00009000"],["63544.78000000","0.00000000"],["63543.74000000","0.00000000"],["63542.56000000","0.00000000"],["63541.90000000","0.00000000"],["63541.66000000","0.06455000"],["63540.54000000","0.00000000"],["63540.01000000","0.00787000"],["63538.58000000","1.22840000"],["63538.56000000","0.00000000"],["63536.09000000","0.00000000"],["63535.84000000","0.00000000"],["63534.40000000","4.06315000"],["63534.39000000","0.00000000"],["63533.84000000","0.00000000"],["63533.10000000","0.09450000"],["63533.07000000","0.64857000"],["63532.54000000","0.03000000"],["63530.37000000","0.45627000"],["63530.04000000","1.23240000"],["63530.03000000","0.00000000"],["63530.01000000","0.00000000"],["63529.20000000","0.00000000"],["63527.56000000","2.83475000"],["63526.71000000","0.00000000"],["63525.12000000","0.00000000"],["63523.90000000","0.45627000"],["63516.07000000","0.00000000"],["63510.15000000","0.00000000"],["63508.92000000","0.00950000"],["63504.17000000","0.00000000"],["63503.86000000","0.00000000"],["63500.25000000","0.00000000"],["63496.56000000","0.00000000"],["63494.50000000","0.00434000"],["63494.32000000","0.00433000"],["63490.51000000","0.00000000"],["63482.80000000","0.00000000"],["63476.71000000","0.00000000"],["63476.29000000","0.00000000"],["63475.40000000","0.00000000"],["63468.93000000","0.00000000"],["63421.66000000","0.00000000"],["57195.92000000","0.00480000"],["50840.82000000","0.00044000"],["50000.00000000","542.70415000"]],"a":[["63551.03000000","4.48654000"],["63551.51000000","0.00018000"],["63551.55000000","0.00252000"],["63551.67000000","0.00000000"],["63553.83000000","0.00018000"],["63554.34000000","0.00000000"],["63555.14000000","0.00000000"],["63558.19000000","0.00059000"],["63559.76000000","0.00189000"],["63561.67000000","0.00021000"],["63561.88000000","0.00000000"],["63562.38000000","0.00000000"],["63568.38000000","0.00000000"],["63570.05000000","0.00000000"],["63571.86000000","0.00000000"],["63576.17000000","0.03089000"],["63576.76000000","0.00431000"],["63582.81000000","0.00010000"],["63582.93000000","0.00000000"],["63584.04000000","0.00000000"],["63617.82000000","0.00000000"]]}}
{"stream":"ethusdt@depth@100ms","data":{"e":"depthUpdate","E":1783465177815,"s":"ETHUSDT","U":78545068344,"u":78545068368,"b":[["1775.55000000","5.47960000"],["1775.49000000","0.44000000"],["1775.48000000","0.44290000"],["1775.43000000","0.59060000"],["1775.29000000","3.79040000"],["1775.26000000","0.00290000"],["1773.67000000","0.14790000"],["1773.61000000","19.95970000"],["1773.56000000","0.13250000"],["1773.54000000","0.56440000"],["1598.00000000","2.59330000"]],"a":[["1775.64000000","0.28280000"],["1775.68000000","1.16220000"],["1775.70000000","17.98070000"],["1775.71000000","15.01870000"],["1775.74000000","1.30180000"]]}}
{"stream":"btcusdt@depth@100ms","data":{"e":"depthUpdate","E":1783465177914,"s":"BTCUSDT","U":97109085657,"u":97109085714,"b":[["63551.02000000","0.02622000"],["63549.13000000","0.09156000"],["63547.57000000","0.00675000"],["63546.37000000","0.00000000"],["63546.35000000","0.00032000"],["63546.00000000","0.02818000"],["63545.82000000","0.00009000"],["63545.33000000","0.04939000"],["63544.77000000","0.14124000"],["63544.62000000","0.02378000"],["63543.74000000","0.05951000"],["63537.19000000","0.00030000"],["63536.87000000","0.70840000"],["63466.57000000","0.00009000"],["57195.92000000","0.00480000"],["57195.00000000","0.00087000"]],"a":[["63551.03000000","4.48654000"],["63551.51000000","0.00000000"],["63551.71000000","0.06426000"],["63553.17000000","0.03969000"],["63553.83000000","0.00000000"],["63554.14000000","2.83493000"],["63554.36000000","0.04022000"],["63554.52000000","0.01338000"],["63557.56000000","0.59062000"],["63657.26000000","0.00000000"],["63658.38000000","0.02465000"],["63665.32000000","0.00000000"]]}}
{"stream":"ethusdt@depth@100ms","data":{"e":"depthUpdate","E":1783465177915,"s":"ETHUSDT","U":78545068369,"u":78545068379,"b":[["1775.49000000","0.44600000"],["1775.20000000","0.03580000"],["1598.00000000","2.60710000"]],"a":[["1775.92000000","0.32980000"]]}}
{"stream":"btcusdt@depth@100ms","data":{"e":"depthUpdate","E":1783465178014,"s":"BTCUSDT","U":97109085715,"u":97109085732,"b":[["63541.90000000","0.00787000"],["63540.01000000","0.00000000"],["63533.63000000","0.02622000"],["63533.10000000","0.00000000"],["63519.33000000","0.54979000"],["63500.27000000","1.02151000"],["63477.84000000","0.04882000"],["63474.61000000","1.02661000"],["57195.92000000","0.00480000"],["50840.82000000","0.00083000"]],"a":[["63551.55000000","0.00000000"],["63561.33000000","0.01300000"],["63655.82000000","0.00157000"],["63668.57000000","0.05069000"]]}}
{"stream":"ethusdt@depth@100ms","data":{"e":"depthUpdate","E":1783465178015,"s":"ETHUSDT","U":78545068380,"u":78545068383,"b":[["1598.00000000","2.60710000"]],"a":[]}}
{"stream":"ethusdt@depth@100ms","data":{"e":"depthUpdate","E":1783465178116,"s":"ETHUSDT","U":78545068384,"u":78545068388,"b":[["1598.00000000","2.60010000"],["1067.00000000","6.86000000"]],"a":[]}}
{"stream":"btcusdt@depth@100ms","data":{"e":"depthUpdate","E":1783465178116,"s":"BTCUSDT","U":97109085733,"u":97109085756,"b":[["63533.63000000","0.00000000"],["63533.62000000","0.02622000"],["63508.53000000","1.57029000"],["63499.21000000","0.13549000"],["63496.56000000","1.08101000"],["63370.64000000","0.00000000"],["63362.47000000","0.00987000"],["62597.75000000","0.00030000"],["57195.92000000","0.00500000"]],"a":[["63557.96000000","0.45635000"],["63572.85000000","1.56870000"],["63597.91000000","0.00000000"],["63607.20000000","0.13097000"],["63614.09000000","0.00000000"],["63655.81000000","0.00157000"],["63655.82000000","0.00000000"]]}}
{"stream":"ethusdt@depth@100ms","data":{"e":"depthUpdate","E":1783465178216,"s":"ETHUSDT","U":78545068389,"u":78545068394,"b":[["1598.00000000","2.58630000"]],"a":[]}}
{"stream":"btcusdt@depth@100ms","data":{"e":"depthUpdate","E":1783465178216,"s":"BTCUSDT","U":97109085757,"u":97109085765,"b":[["63551.02000000","0.11693000"],["63544.66000000","0.22816000"],["63536.87000000","0.00000000"],["63532.79000000","0.70840000"],["57195.92000000","0.00500000"],["50840.82000000","0.00044000"]],"a":[]}}
{"stream":"btcusdt@depth@100ms","data":{"e":"depthUpdate","E":1783465178314,"s":"BTCUSDT","U":97109085766,"u":97109085782,"b":[["63544.77000000","0.14124000"],["63544.66000000","0.22834000"],["63544.62000000","0.02360000"],["63519.33000000","0.00000000"],["63500.27000000","0.00000000"],["63472.36000000","0.07260000"],["57195.92000000","0.00500000"]],"a":[["63568.82000000","0.00000000"],["63575.46000000","0.00000000"]]}}
{"stream":"ethusdt@depth@100ms","data":{"e":"depthUpdate","E":1783465178315,"s":"ETHUSDT","U":78545068395,"u":78545068400,"b":[["1598.00000000","2.60010000"]],"a":[]}}
{"stream":"ethusdt@depth@100ms","data":{"e":"depthUpdate","E":1783465178418,"s":"ETHUSDT","U":78545068401,"u":78545068404,"b":[["1598.00000000","2.60010000"]],"a":[]}}
{"stream":"btcusdt@depth@100ms","data":{"e":"depthUpdate","E":1783465178418,"s":"BTCUSDT","U":97109085783,"u":97109085790,"b":[["63537.00000000","0.00000000"],["57195.92000000","0.00480000"],["40000.00000000","260.73952000"]],"a":[["63562.43000000","0.00000000"],["63617.39000000","1.91970000"],["63619.49000000","0.00000000"]]}}
{"stream":"btcusdt@depth@100ms","data":{"e":"depthUpdate","E":1783465178514,"s":"BTCUSDT","U":97109085791,"u":97109085797,"b":[["63537.00000000","0.00008000"],["57195.92000000","0.00480000"]],"a":[["63562.43000000","0.00008000"],["63759.34000000","0.00000000"]]}}
{"stream":"ethusdt@depth@100ms","data":{"e":"depthUpdate","E":1783465178515,"s":"ETHUSDT","U":78545068405,"u":78545068407,"b":[["1598.00000000","2.60710000"]],"a":[]}}
{"stream":"btcusdt@depth@100ms","data":{"e":"depthUpdate","E":1783465178614,"s":"BTCUSDT","U":97109085798,"u":97109085805,"b":[["63519.33000000","0.54101000"],["63500.27000000","1.03963000"],["57195.92000000","0.00480000"]],"a":[["63565.46000000","0.54837000"],["63584.53000000","1.04213000"]]}}
{"stream":"ethusdt@depth@100ms","data":{"e":"depthUpdate","E":1783465178615,"s":"ETHUSDT","U":78545068408,"u":78545068415,"b":[["1773.49000000","1.13840000"],["1598.00000000","2.60710000"]],"a":[["1777.43000000","0.13460000"],["1777.49000000","7.98180000"],["1778.83000000","0.00000000"]]}}
{"stream":"btcusdt@depth@100ms","data":{"e":"depthUpdate","E":1783465178714,"s":"BTCUSDT","U":97109085806,"u":97109085811,"b":[["57195.92000000","0.00480000"]],"a":[["64504.30000000","0.00030000"]]}}
{"stream":"ethusdt@depth@100ms","data":{"e":"depthUpdate","E":1783465178715,"s":"ETHUSDT","U":78545068416,"u":78545068424,"b":[["1773.13000000","1.84620000"],["1598.00000000","2.58630000"]],"a":[["1778.47000000","0.07280000"],["2254.18000000","1.14600000"]]}}
{"stream":"btcusdt@depth@100ms","data":{"e":"depthUpdate","E":1783465178814,"s":"BTCUSDT","U":97109085812,"u":97109085834,"b":[["63551.02000000","0.13612000"],["63551.01000000","0.00377000"],["63549.13000000","0.09164000"],["63546.68000000","0.00018000"],["63546.67000000","0.12773000"],["63545.34000000","0.00000000"],["63544.78000000","0.06321000"],["63538.59000000","0.45627000"],["63532.79000000","0.00000000"],["57195.92000000","0.00500000"],["50840.82000000","0.00044000"]],"a":[["63551.03000000","4.35533000"],["63551.51000000","0.00787000"],["86422.88000000","0.05673000"]]}}
{"stream":"ethusdt@depth@100ms","data":{"e":"depthUpdate","E":1783465178815,"s":"ETHUSDT","U":78545068425,"u":78545068433,"b":[["1598.00000000","2.60010000"],["1597.99000000","0.00870000"]],"a":[["1775.68000000","0.88040000"],["1775.69000000","0.56750000"],["1775.71000000","0.00000000"]]}}
{"stream":"btcusdt@depth@100ms","data":{"e":"depthUpdate","E":1783465178914,"s":"BTCUSDT","U":97109085835,"u":97109085914,"b":[["63551.02000000","0.79943000"],["63551.01000000","0.00368000"],["63549.13000000","0.09172000"],["63548.74000000","0.00018000"],["63548.73000000","0.11735000"],["63547.57000000","0.00675000"],["63547.23000000","0.00000000"],["63546.68000000","0.00000000"],["63546.67000000","0.00034000"],["63545.33000000","0.04939000"],["63545.31000000","0.70848000"],["63544.83000000","0.46014000"],["63544.78000000","0.06339000"],["63544.77000000","0.14106000"],["63544.66000000","0.22816000"],["63542.16000000","0.13273000"],["63538.61000000","2.15880000"],["63538.60000000","2.83475000"],["63538.57000000","0.00000000"],["63538.54000000","0.00000000"],["63538.52000000","0.56698000"],["63538.45000000","1.00000000"],["63526.72000000","0.39563000"],["63524.00000000","0.02800000"],["63496.56000000","0.00000000"],["63476.56000000","0.00000000"],["57195.92000000","0.00500000"]],"a":[["63551.03000000","3.43533000"],["63551.51000000","0.00018000"],["63551.68000000","0.44632000"],["63553.16000000","0.00787000"],["63553.82000000","0.09071000"],["63554.14000000","0.00018000"],["63554.52000000","0.01320000"],["63559.52000000","0.00000000"],["63560.05000000","0.00000000"],["63561.81000000","0.20319000"],["63565.24000000","0.78733000"],["63565.28000000","0.59220000"],["63569.80000000","0.00000000"],["63575.70000000","0.56664000"],["63579.62000000","0.00226000"],["63617.39000000","0.00000000"],["63619.50000000","1.91970000"],["86422.88000000","0.07564000"]]}}
{"stream":"ethusdt@depth@100ms","data":{"e":"depthUpdate","E":1783465178915,"s":"ETHUSDT","U":78545068434,"u":78545068455,"b":[["1775.55000000","5.48560000"],["1775.54000000","0.45730000"],["1775.44000000","1.40720000"],["1775.29000000","10.98960000"],["1775.26000000","24.59370000"],["1775.20000000","0.03580000"],["1773.67000000","12.22300000"],["1773.61000000","7.88460000"],["1773.60000000","7.88460000"],["1598.00000000","2.60010000"],["1597.99000000","0.00520000"]],"a":[["1775.70000000","13.41350000"],["1775.84000000","15.05160000"],["1775.92000000","0.32980000"]]}}
{"stream":"btcusdt@depth@100ms","data":{"e":"depthUpdate","E":1783465179014,"s":"BTCUSDT","U":97109085915,"u":97109085969,"b":[["63551.02000000","0.79952000"],["63551.01000000","0.00377000"],["63549.13000000","0.09172000"],["63548.73000000","0.11753000"],["63547.57000000","0.00675000"],["63546.67000000","0.00016000"],["63545.33000000","0.04939000"],["63545.31000000","0.70866000"],["63544.78000000","0.06321000"],["63544.45000000","0.00787000"],["63541.90000000","0.00000000"],["57195.92000000","0.00480000"],["57195.00000000","0.00107000"],["50840.82000000","0.00083000"]],"a":[["63551.03000000","3.43533000"],["63551.51000000","0.00000000"],["63551.71000000","0.06434000"],["63553.16000000","0.00805000"],["63553.17000000","0.03969000"],["63553.82000000","0.09089000"],["63554.07000000","0.00895000"],["63554.14000000","0.00000000"],["63655.81000000","0.00000000"],["63655.82000000","0.00157000"]]}}
{"stream":"ethusdt@depth@100ms","data":{"e":"depthUpdate","E":1783465179015,"s":"ETHUSDT","U":78545068456,"u":78545068464,"b":[["1775.55000000","5.48850000"],["1775.54000000","0.46020000"],["1774.75000000","17.98610000"],["1774.57000000","16.34340000"],["1598.00000000","2.60010000"]],"a":[["1775.69000000","0.28570000"],["1775.71000000","0.28180000"]]}}
{"stream":"btcusdt@depth@100ms","data":{"e":"depthUpdate","E":1783465179114,"s":"BTCUSDT","U":97109085970,"u":97109085990,"b":[["63490.51000000","0.28401000"],["63454.78000000","0.00000000"],["63444.03000000","0.03541000"],["62597.75000000","0.00030000"],["57195.92000000","0.00480000"],["57195.00000000","0.00087000"]],"a":[["63560.85000000","0.07915000"],["63561.81000000","0.00000000"],["63655.80000000","0.00000000"],["63655.81000000","0.00157000"],["63655.82000000","0.00000000"],["79890.03000000","0.12726000"],["80298.72000000","0.05016000"]]}}
{"stream":"ethusdt@depth@100ms","data":{"e":"depthUpdate","E":1783465179115,"s":"ETHUSDT","U":78545068465,"u":78545068470,"b":[["1771.50000000","0.04130000"],["1598.00000000","2.59330000"]],"a":[]}}
{"stream":"btcusdt@depth@100ms","data":{"e":"depthUpdate","E":1783465179214,"s":"BTCUSDT","U":97109085991,"u":97109086002,"b":[["63544.45000000","0.00000000"],["63544.01000000","0.00787000"],["63370.64000000","0.00987000"],["63362.47000000","0.00000000"],["57195.92000000","0.00480000"],["50840.82000000","0.00044000"]],"a":[["63553.32000000","0.00000000"],["63554.50000000","0.00252000"],["79890.03000000","0.14847000"]]}}
{"stream":"ethusdt@depth@100ms","data":{"e":"depthUpdate","E":1783465179215,"s":"ETHUSDT","U":78545068471,"u":78545068477,"b":[["1775.03000000","3.25510000"],["1774.98000000","0.01580000"],["1598.00000000","2.60710000"]],"a":[]}}
{"stream":"btcusdt@depth@100ms","data":{"e":"depthUpdate","E":1783465179314,"s":"BTCUSDT","U":97109086003,"u":97109086012,"b":[["57195.92000000","0.00480000"]],"a":[["63551.67000000","0.00018000"],["63551.68000000","0.44650000"],["63553.81000000","0.00018000"]]}}
{"stream":"ethusdt@depth@100ms","data":{"e":"depthUpdate","E":1783465179315,"s":"ETHUSDT","U":78545068478,"u":78545068481,"b":[["1598.00000000","2.60710000"]],"a":[]}}
{"stream":"btcusdt@depth@100ms","data":{"e":"depthUpdate","E":1783465179414,"s":"BTCUSDT","U":97109086013,"u":97109086021,"b":[["63551.02000000","0.79978000"],["57195.92000000","0.00480000"],["50841.00000000","0.23623000"],["40000.00000000","260.73952000"]],"a":[]}}
{"stream":"ethusdt@depth@100ms","data":{"e":"depthUpdate","E":1783465179415,"s":"ETHUSDT","U":78545068482,"u":78545068484,"b":[["1598.00000000","2.60010000"]],"a":[]}}
{"stream":"btcusdt@depth@100ms","data":{"e":"depthUpdate","E":1783465179514,"s":"BTCUSDT","U":97109086022,"u":97109086029,"b":[["63537.77000000","0.01574000"],["63537.00000000","0.00008000"],["63534.57000000","0.00000000"],["57195.92000000","0.00500000"]],"a":[["63562.43000000","0.00008000"]]}}
{"stream":"ethusdt@depth@100ms","data":{"e":"depthUpdate","E":1783465179515,"s":"ETHUSDT","U":78545068485,"u":78545068488,"b":[["1598.00000000","2.60010000"]],"a":[]}}
{"stream":"ethusdt@depth@100ms","data":{"e":"depthUpdate","E":1783465179616,"s":"ETHUSDT","U":78545068489,"u":78545068494,"b":[["1598.00000000","2.58630000"]],"a":[]}}
{"stream":"btcusdt@depth@100ms","data":{"e":"depthUpdate","E":1783465179616,"s":"BTCUSDT","U":97109086030,"u":97109086033,"b":[["57195.92000000","0.00500000"]],"a":[]}}
{"stream":"btcusdt@trade","data":{"e":"trade","E":1783465179633,"s":"BTCUSDT","t":6486989338,"p":"63551.02000000","q":"0.00008000","T":1783465179633,"m":true,"M":true}}
{"stream":"btcusdt@trade","data":{"e":"trade","E":1783465179633,"s":"BTCUSDT","t":6486989339,"p":"63551.02000000","q":"0.00081000","T":1783465179633,"m":true,"M":true}}
{"stream":"btcusdt@depth@100ms","data":{"e":"depthUpdate","E":1783465179714,"s":"BTCUSDT","U":97109086034,"u":97109086040,"b":[["63551.02000000","0.79897000"],["57195.92000000","0.00480000"],["57195.91000000","0.00000000"]],"a":[["64504.30000000","0.00030000"]]}}
{"stream":"ethusdt@depth@100ms","data":{"e":"depthUpdate","E":1783465179715,"s":"ETHUSDT","U":78545068495,"u":78545068504,"b":[["1775.21000000","0.28180000"],["1775.18000000","0.00000000"],["1775.17000000","0.44130000"],["1598.00000000","2.60010000"]],"a":[["1775.71000000","0.00000000"],["1775.73000000","0.28180000"]]}}
{"stream":"ethusdt@depth@100ms","data":{"e":"depthUpdate","E":1783465179815,"s":"ETHUSDT","U":78545068505,"u":78545068510,"b":[["1598.00000000","2.60710000"]],"a":[["1777.32000000","0.01030000"],["1777.33000000","10.26710000"],["1777.38000000","25.82240000"]]}}
{"stream":"btcusdt@depth@100ms","data":{"e":"depthUpdate","E":1783465179815,"s":"BTCUSDT","U":97109086041,"u":97109086049,"b":[["57195.92000000","0.00480000"],["50840.82000000","0.00044000"],["50000.00000000","542.70395000"]],"a":[]}}
{"stream":"btcusdt@depth@100ms","data":{"e":"depthUpdate","E":1783465179914,"s":"BTCUSDT","U":97109086050,"u":97109086053,"b":[["57195.92000000","0.00480000"]],"a":[]}}
{"stream":"ethusdt@depth@100ms","data":{"e":"depthUpdate","E":1783465179915,"s":"ETHUSDT","U":78545068511,"u":78545068519,"b":[["1775.20000000","0.03290000"],["1770.33000000","0.00000000"],["1770.00000000","25.01050000"],["1598.00000000","2.60710000"],["1067.00000000","6.86000000"]],"a":[["1775.92000000","0.32690000"]]}}
{"stream":"btcusdt@depth@100ms","data":{"e":"depthUpdate","E":1783465180014,"s":"BTCUSDT","U":97109086054,"u":97109086061,"b":[["63551.02000000","0.79923000"],["57195.92000000","0.00480000"],["50840.82000000","0.00083000"]],"a":[["63655.81000000","0.00000000"],["63655.82000000","0.00157000"]]}}
{"stream":"ethusdt@depth@100ms","data":{"e":"depthUpdate","E":1783465180015,"s":"ETHUSDT","U":78545068520,"u":78545068527,"b":[["1775.20000000","0.03580000"],["1598.00000000","2.59330000"]],"a":[["1775.92000000","0.32980000"]]}}
{"stream":"btcusdt@depth@100ms","data":{"e":"depthUpdate","E":1783465180114,"s":"BTCUSDT","U":97109086062,"u":97109086081,"b":[["63477.84000000","0.00000000"],["63425.71000000","0.00000000"],["62597.75000000","0.00030000"],["58466.94000000","0.00018000"],["57195.92000000","0.00500000"],["57195.00000000","0.00087000"]],"a":[["63655.80000000","0.00000000"],["63655.81000000","0.00000000"],["63655.82000000","0.00157000"],["63668.57000000","0.00000000"],["64125.81000000","0.00000000"],["64200.54000000","0.00066000"]]}}
{"stream":"ethusdt@depth@100ms","data":{"e":"depthUpdate","E":1783465180115,"s":"ETHUSDT","U":78545068528,"u":78545068533,"b":[["1770.19000000","41.70840000"],["1598.00000000","2.60010000"]],"a":[]}}
{"stream":"ethusdt@depth@100ms","data":{"e":"depthUpdate","E":1783465180215,"s":"ETHUSDT","U":78545068534,"u":78545068539,"b":[["1598.00000000","2.60010000"]],"a":[["1775.71000000","0.00000000"],["1775.72000000","7.14500000"],["1775.73000000","0.00000000"]]}}
{"stream":"btcusdt@depth@100ms","data":{"e":"depthUpdate","E":1783465180215,"s":"BTCUSDT","U":97109086082,"u":97109086089,"b":[["63469.32000000","0.17283000"],["63434.88000000","0.02465000"],["57195.92000000","0.00500000"],["50840.82000000","0.00044000"]],"a":[["63660.02000000","0.05138000"]]}}
{"stream":"btcusdt@depth@100ms","data":{"e":"depthUpdate","E":1783465180314,"s":"BTCUSDT","U":97109086090,"u":97109086093,"b":[["57195.92000000","0.00500000"]],"a":[]}}
{"stream":"ethusdt@depth@100ms","data":{"e":"depthUpdate","E":1783465180315,"s":"ETHUSDT","U":78545068540,"u":78545068543,"b":[["1598.00000000","2.60010000"]],"a":[]}}
{"stream":"btcusdt@depth@100ms","data":{"e":"depthUpdate","E":1783465180414,"s":"BTCUSDT","U":97109086094,"u":97109086101,"b":[["63551.02000000","1.02483000"],["63434.88000000","0.00000000"],["57195.92000000","0.00480000"],["40000.00000000","260.73952000"]],"a":[]}}
{"stream":"ethusdt@depth@100ms","data":{"e":"depthUpdate","E":1783465180415,"s":"ETHUSDT","U":78545068544,"u":78545068547,"b":[["1598.00000000","2.60010000"]],"a":[]}}
{"stream":"btcusdt@depth@100ms","data":{"e":"depthUpdate","E":1783465180514,"s":"BTCUSDT","U":97109086102,"u":97109086108,"b":[["63537.00000000","0.00008000"],["57195.92000000","0.00480000"]],"a":[["63562.43000000","0.00008000"]]}}
{"stream":"ethusdt@depth@100ms","data":{"e":"depthUpdate","E":1783465180516,"s":"ETHUSDT","U":78545068548,"u":78545068552,"b":[["1598.00000000","2.59330000"]],"a":[]}}
{"stream":"btcusdt@depth@100ms","data":{"e":"depthUpdate","E":1783465180614,"s":"BTCUSDT","U":97109086109,"u":97109086113,"b":[["63551.02000000","1.02509000"],["57195.92000000","0.00480000"]],"a":[]}}
{"stream":"ethusdt@depth@100ms","data":{"e":"depthUpdate","E":1783465180615,"s":"ETHUSDT","U":78545068553,"u":78545068558,"b":[["1598.00000000","2.60710000"]],"a":[]}}
{"stream":"btcusdt@depth@100ms","data":{"e":"depthUpdate","E":1783465180714,"s":"BTCUSDT","U":97109086114,"u":97109086120,"b":[["58466.94000000","0.00000000"],["57195.92000000","0.00480000"]],"a":[["64504.30000000","0.00030000"]]}}
{"stream":"ethusdt@depth@100ms","data":{"e":"depthUpdate","E":1783465180715,"s":"ETHUSDT","U":78545068559,"u":78545068561,"b":[["1598.00000000","2.60010000"]],"a":[]}}
{"stream":"btcusdt@depth@100ms","data":{"e":"depthUpdate","E":1783465180814,"s":"BTCUSDT","U":97109086121,"u":97109086133,"b":[["63551.02000000","1.02517000"],["63542.76000000","0.00400000"],["63517.32000000","0.00000000"],["57195.92000000","0.00500000"],["50840.82000000","0.00044000"]],"a":[["63551.03000000","3.43551000"],["63551.04000000","0.00123000"],["63615.36000000","0.03109000"],["63741.41000000","0.06310000"]]}}
{"stream":"ethusdt@depth@100ms","data":{"e":"depthUpdate","E":1783465180815,"s":"ETHUSDT","U":78545068562,"u":78545068575,"b":[["1775.55000000","12.68180000"],["1774.72000000","0.03290000"],["1598.00000000","2.60010000"]],"a":[["1775.56000000","61.96790000"],["1775.89000000","1.30470000"],["1775.92000000","3.14790000"],["1776.51000000","0.00740000"]]}}
{"stream":"btcusdt@depth@100ms","data":{"e":"depthUpdate","E":1783465180914,"s":"BTCUSDT","U":97109086134,"u":97109086140,"b":[["63413.77000000","0.09461000"],["57195.92000000","0.00500000"],["50840.82000000","0.00044000"]],"a":[]}}
{"stream":"ethusdt@depth@100ms","data":{"e":"depthUpdate","E":1783465180917,"s":"ETHUSDT","U":78545068576,"u":78545068586,"b":[["1768.61000000","2.48620000"],["1598.00000000","2.58630000"]],"a":[["1775.81000000","0.02960000"],["1777.33000000","5.59200000"],["1777.38000000","7.88470000"],["1777.43000000","18.07230000"]]}}
{"stream":"btcusdt@depth@100ms","data":{"e":"depthUpdate","E":1783465181014,"s":"BTCUSDT","U":97109086141,"u":97109086159,"b":[["63551.02000000","1.02551000"],["63550.59000000","0.00018000"],["63550.58000000","0.14480000"],["63548.74000000","0.00000000"],["63548.73000000","0.00018000"],["63546.01000000","0.00009000"],["63396.22000000","0.00000000"],["57195.92000000","0.00480000"],["50840.82000000","0.00083000"]],"a":[["63655.82000000","0.00157000"],["63708.43000000","0.00000000"]]}}
{"stream":"ethusdt@depth@100ms","data":{"e":"depthUpdate","E":1783465181015,"s":"ETHUSDT","U":78545068587,"u":78545068600,"b":[["1775.25000000","3.20400000"],["1775.21000000","0.00000000"],["1775.20000000","0.03580000"],["1773.13000000","0.00000000"],["1769.30000000","0.88220000"],["1598.00000000","2.60010000"]],"a":[["1775.72000000","6.86320000"],["1775.75000000","16.06230000"],["1775.92000000","3.14790000"],["1778.47000000","0.00000000"]]}}
{"stream":"btcusdt@depth@100ms","data":{"e":"depthUpdate","E":1783465181114,"s":"BTCUSDT","U":97109086160,"u":97109086181,"b":[["63551.02000000","1.02569000"],["63550.58000000","0.14498000"],["63549.13000000","0.09146000"],["63548.73000000","0.00000000"],["62597.75000000","0.00030000"],["57195.92000000","0.00480000"]],"a":[["63655.81000000","0.00000000"],["63655.82000000","0.00157000"]]}}
{"stream":"ethusdt@depth@100ms","data":{"e":"depthUpdate","E":1783465181115,"s":"ETHUSDT","U":78545068601,"u":78545068605,"b":[["1773.49000000","1.75850000"],["1598.00000000","2.60710000"]],"a":[["1778.83000000","0.56540000"]]}}
{"stream":"btcusdt@depth@100ms","data":{"e":"depthUpdate","E":1783465181215,"s":"BTCUSDT","U":97109086182,"u":97109086198,"b":[["63551.02000000","1.02595000"],["63551.01000000","0.00377000"],["63476.71000000","1.02661000"],["63474.61000000","0.00000000"],["63390.31000000","4.49633000"],["57195.92000000","0.00480000"],["57195.00000000","0.00087000"],["50840.82000000","0.00044000"]],"a":[["63619.50000000","0.00000000"],["63702.81000000","6.46493000"]]}}
{"stream":"ethusdt@depth@100ms","data":{"e":"depthUpdate","E":1783465181215,"s":"ETHUSDT","U":78545068606,"u":78545068612,"b":[["1775.27000000","7.95050000"],["1773.12000000","0.00000000"],["1598.00000000","2.60710000"]],"a":[["1775.98000000","15.18500000"]]}}
{"stream":"btcusdt@depth@100ms","data":{"e":"depthUpdate","E":1783465181314,"s":"BTCUSDT","U":97109086199,"u":97109086212,"b":[["57195.92000000","0.00480000"],["50841.00000000","0.23623000"]],"a":[]}}
{"stream":"ethusdt@depth@100ms","data":{"e":"depthUpdate","E":1783465181316,"s":"ETHUSDT","U":78545068613,"u":78545068618,"b":[["1775.08000000","27.40880000"],["1775.03000000","0.43700000"],["1598.00000000","2.60710000"]],"a":[["1775.92000000","0.32980000"],["1775.94000000","2.82380000"]]}}
{"stream":"btcusdt@trade","data":{"e":"trade","E":1783465181333,"s":"BTCUSDT","t":6486989340,"p":"63551.03000000","q":"0.00008000","T":1783465181333,"m":false,"M":true}}
{"stream":"btcusdt@trade","data":{"e":"trade","E":1783465181333,"s":"BTCUSDT","t":6486989341,"p":"63551.03000000","q":"0.00008000","T":1783465181333,"m":false,"M":true}}
{"stream":"btcusdt@trade","data":{"e":"trade","E":1783465181333,"s":"BTCUSDT","t":6486989342,"p":"63551.03000000","q":"0.00010000","T":1783465181333,"m":false,"M":true}}
{"stream":"btcusdt@trade","data":{"e":"trade","E":1783465181333,"s":"BTCUSDT","t":6486989343,"p":"63551.03000000","q":"0.00008000","T":1783465181333,"m":false,"M":true}}
{"stream":"btcusdt@trade","data":{"e":"trade","E":1783465181333,"s":"BTCUSDT","t":6486989344,"p":"63551.03000000","q":"0.00095000","T":1783465181333,"m":false,"M":true}}
{"stream":"ethusdt@trade","data":{"e":"trade","E":1783465181345,"s":"ETHUSDT","t":4197008393,"p":"1775.55000000","q":"0.03220000","T":1783465181345,"m":true,"M":true}}
{"stream":"btcusdt@depth@100ms","data":{"e":"depthUpdate","E":1783465181414,"s":"BTCUSDT","U":97109086213,"u":97109086234,"b":[["63551.02000000","1.02568000"],["63549.13000000","0.09164000"],["63545.31000000","0.00026000"],["63544.21000000","0.70840000"],["57195.92000000","0.00490000"],["40000.00000000","260.73952000"]],"a":[["63551.03000000","3.43446000"],["63551.04000000","0.00123000"]]}}
{"stream":"ethusdt@depth@100ms","data":{"e":"depthUpdate","E":1783465181415,"s":"ETHUSDT","U":78545068619,"u":78545068625,"b":[["1775.55000000","12.64960000"],["1774.63000000","0.00860000"],["1598.00000000","2.58630000"]],"a":[]}}
{"stream":"btcusdt@depth@100ms","data":{"e":"depthUpdate","E":1783465181514,"s":"BTCUSDT","U":97109086235,"u":97109086250,"b":[["63551.02000000","0.80016000"],["63545.33000000","0.04939000"],["63545.31000000","0.00008000"],["63544.83000000","0.46032000"],["63537.00000000","0.00000000"],["63413.77000000","0.00000000"],["57195.92000000","0.00510000"]],"a":[["63562.43000000","0.00000000"],["63615.36000000","0.00000000"],["63741.41000000","0.00000000"]]}}
{"stream":"ethusdt@depth@100ms","data":{"e":"depthUpdate","E":1783465181517,"s":"ETHUSDT","U":78545068626,"u":78545068631,"b":[["1598.00000000","2.60010000"]],"a":[]}}
{"stream":"btcusdt@depth@100ms","data":{"e":"depthUpdate","E":1783465181614,"s":"BTCUSDT","U":97109086251,"u":97109086265,"b":[["63544.83000000","0.00018000"],["63544.21000000","0.00000000"],["63542.16000000","0.00000000"],["63541.18000000","0.41077000"],["63540.39000000","0.46014000"],["63540.38000000","0.70840000"],["63537.00000000","0.00008000"],["63490.51000000","0.00000000"],["63473.31000000","0.00177000"],["57195.92000000","0.00510000"],["33000.00000000","35.17039000"]],"a":[["63562.43000000","0.00008000"]]}}
{"stream":"ethusdt@depth@100ms","data":{"e":"depthUpdate","E":1783465181616,"s":"ETHUSDT","U":78545068632,"u":78545068635,"b":[["1598.00000000","2.60010000"]],"a":[]}}
{"stream":"btcusdt@trade","data":{"e":"trade","E":1783465181645,"s":"BTCUSDT","t":6486989345,"p":"63551.02000000","q":"0.00027000","T":1783465181644,"m":true,"M":true}}
{"stream":"btcusdt@depth@100ms","data":{"e":"depthUpdate","E":1783465181714,"s":"BTCUSDT","U":97109086266,"u":97109086283,"b":[["63551.02000000","0.79989000"],["63545.33000000","0.04939000"],["63545.31000000","0.00000000"],["63544.83000000","0.00000000"],["63544.78000000","0.06339000"],["63390.31000000","0.00000000"],["57195.92000000","0.00490000"],["33000.00000000","35.16979000"]],"a":[["63702.81000000","0.00000000"],["64504.30000000","0.00030000"]]}}
{"stream":"ethusdt@depth@100ms","data":{"e":"depthUpdate","E":1783465181715,"s":"ETHUSDT","U":78545068636,"u":78545068642,"b":[["1675.60000000","0.00730000"],["1598.00000000","2.60010000"],["1067.00000000","6.86000000"]],"a":[]}}
{"stream":"btcusdt@depth@100ms","data":{"e":"depthUpdate","E":1783465181814,"s":"BTCUSDT","U":97109086284,"u":97109086290,"b":[["57195.92000000","0.00490000"],["50840.82000000","0.00044000"]],"a":[["69906.13000000","0.00008000"]]}}
{"stream":"ethusdt@depth@100ms","data":{"e":"depthUpdate","E":1783465181815,"s":"ETHUSDT","U":78545068643,"u":78545068649,"b":[["1775.55000000","13.07690000"],["1774.68000000","3.38960000"],["1598.00000000","2.59330000"]],"a":[]}}
{"stream":"btcusdt@depth@100ms","data":{"e":"depthUpdate","E":1783465181914,"s":"BTCUSDT","U":97109086291,"u":97109086299,"b":[["63389.02000000","4.49642000"],["57195.92000000","0.00490000"],["50840.82000000","0.00044000"]],"a":[["63702.81000000","6.56388000"],["69906.13000000","0.00000000"]]}}
{"stream":"ethusdt@depth@100ms","data":{"e":"depthUpdate","E":1783465181915,"s":"ETHUSDT","U":78545068650,"u":78545068653,"b":[["1598.00000000","2.59330000"]],"a":[]}}
{"stream":"btcusdt@depth@100ms","data":{"e":"depthUpdate","E":1783465182014,"s":"BTCUSDT","U":97109086300,"u":97109086308,"b":[["57195.92000000","0.00490000"],["50840.82000000","0.00083000"]],"a":[["63576.17000000","0.00000000"],["63581.05000000","0.03104000"],["63655.82000000","0.00157000"]]}}
{"stream":"ethusdt@depth@100ms","data":{"e":"depthUpdate","E":1783465182015,"s":"ETHUSDT","U":78545068654,"u":78545068665,"b":[["1775.25000000","2.92230000"],["1775.24000000","0.55430000"],["1775.20000000","0.03580000"],["1769.30000000","0.00000000"],["1768.61000000","3.36840000"],["1598.00000000","2.60710000"]],"a":[["1775.92000000","0.32980000"]]}}
{"stream":"ethusdt@depth@100ms","data":{"e":"depthUpdate","E":1783465182115,"s":"ETHUSDT","U":78545068666,"u":78545068669,"b":[["1775.25000000","3.50670000"],["1598.00000000","2.60010000"]],"a":[]}}
