{"channel":"book","type":"update","data":[{"symbol":"BTC/USD","bids":[],"asks":[{"price":63498.1,"qty":4.48794221},{"price":63498.1,"qty":4.47789513},{"price":63498.1,"qty":4.41799513},{"price":63498.1,"qty":4.30799513},{"price":63498.1,"qty":4.23502486}],"checksum":1723405862,"timestamp":"2026-07-07T23:00:10.859060Z"}]}
{"channel":"book","type":"update","data":[{"symbol":"BTC/USD","bids":[],"asks":[{"price":63498.1,"qty":4.10393084}],"checksum":1137775777,"timestamp":"2026-07-07T23:00:10.861499Z"}]}
{"channel":"book","type":"update","data":[{"symbol":"BTC/USD","bids":[],"asks":[{"price":63498.1,"qty":4.10402918}],"checksum":1331908727,"timestamp":"2026-07-07T23:00:10.861644Z"}]}
{"channel":"book","type":"update","data":[{"symbol":"BTC/USD","bids":[],"asks":[{"price":63498.1,"qty":4.08307980}],"checksum":1351934639,"timestamp":"2026-07-07T23:00:10.861711Z"}]}
{"channel":"book","type":"update","data":[{"symbol":"ETH/USD","bids":[],"asks":[{"price":1773.47,"qty":0.00000000},{"price":1773.82,"qty":6.69695895}],"checksum":1817940552,"timestamp":"2026-07-07T23:00:10.871666Z"}]}
{"channel":"book","type":"update","data":[{"symbol":"ETH/USD","bids":[{"price":1773.25,"qty":1.36287768}],"asks":[],"checksum":3840591409,"timestamp":"2026-07-07T23:00:10.877347Z"}]}
{"channel":"book","type":"update","data":[{"symbol":"ETH/USD","bids":[{"price":1773.24,"qty":0.00000000},{"price":1773.06,"qty":12.67243555}],"asks":[],"checksum":3231137632,"timestamp":"2026-07-07T23:00:10.877890Z"}]}
{"channel":"book","type":"update","data":[{"symbol":"ETH/USD","bids":[],"asks":[{"price":1773.55,"qty":0.00000000},{"price":1773.83,"qty":4.77600128}],"checksum":4029765579,"timestamp":"2026-07-07T23:00:10.878743Z"}]}
{"channel":"book","type":"update","data":[{"symbol":"ETH/USD","bids":[{"price":1773.28,"qty":2.81962855}],"asks":[],"checksum":3867123420,"timestamp":"2026-07-07T23:00:10.880686Z"}]}
{"channel":"book","type":"update","data":[{"symbol":"ETH/USD","bids":[],"asks":[{"price":1773.54,"qty":0.00000000},{"price":1773.84,"qty":15.93800000}],"checksum":1335496986,"timestamp":"2026-07-07T23:00:10.881334Z"}]}
{"channel":"book","type":"update","data":[{"symbol":"ETH/USD","bids":[{"price":1773.25,"qty":0.00000000},{"price":1773.06,"qty":12.67243555}],"asks":[],"checksum":218665016,"timestamp":"2026-07-07T23:00:10.884691Z"}]}
{"channel":"book","type":"update","data":[{"symbol":"ETH/USD","bids":[{"price":1773.29,"qty":0.84165912}],"asks":[],"checksum":1364210518,"timestamp":"2026-07-07T23:00:10.884956Z"}]}
{"channel":"book","type":"update","data":[{"symbol":"ETH/USD","bids":[{"price":1773.20,"qty":0.05639521},{"price":1773.17,"qty":1.68966976}],"asks":[],"checksum":2423723020,"timestamp":"2026-07-07T23:00:10.886264Z"}]}
{"channel":"book","type":"update","data":[{"symbol":"ETH/USD","bids":[],"asks":[{"price":1773.76,"qty":0.00000000},{"price":1773.85,"qty":0.50000000}],"checksum":3040915943,"timestamp":"2026-07-07T23:00:10.896977Z"}]}
{"channel":"book","type":"update","data":[{"symbol":"ETH/USD","bids":[],"asks":[{"price":1773.72,"qty":0.00000000},{"price":1773.87,"qty":0.28137208}],"checksum":1752515880,"timestamp":"2026-07-07T23:00:10.898379Z"}]}
{"channel":"book","type":"update","data":[{"symbol":"ETH/USD","bids":[],"asks":[{"price":1773.60,"qty":2.81912552}],"checksum":637641368,"timestamp":"2026-07-07T23:00:10.898846Z"}]}
{"channel":"book","type":"update","data":[{"symbol":"ETH/USD","bids":[],"asks":[{"price":1773.80,"qty":3.68774879}],"checksum":858293526,"timestamp":"2026-07-07T23:00:10.899497Z"}]}
{"channel":"book","type":"update","data":[{"symbol":"ETH/USD","bids":[],"asks":[{"price":1773.74,"qty":3.82875963}],"checksum":1406593690,"timestamp":"2026-07-07T23:00:10.899931Z"}]}
{"channel":"book","type":"update","data":[{"symbol":"ETH/USD","bids":[],"asks":[{"price":1773.59,"qty":0.84150897}],"checksum":2891678544,"timestamp":"2026-07-07T23:00:10.900284Z"}]}
{"channel":"book","type":"update","data":[{"symbol":"ETH/USD","bids":[],"asks":[{"price":1773.74,"qty":1.53128753}],"checksum":368488219,"timestamp":"2026-07-07T23:00:10.900309Z"}]}
{"channel":"book","type":"update","data":[{"symbol":"ETH/USD","bids":[{"price":1773.29,"qty":0.00000000},{"price":1773.09,"qty":20.30353661}],"asks":[],"checksum":2838758652,"timestamp":"2026-07-07T23:00:10.910135Z"}]}
{"channel":"book","type":"update","data":[{"symbol":"ETH/USD","bids":[],"asks":[{"price":1773.81,"qty":0.00000000},{"price":1773.84,"qty":15.93800000}],"checksum":3938156484,"timestamp":"2026-07-07T23:00:10.924332Z"}]}
{"channel":"book","type":"update","data":[{"symbol":"ETH/USD","bids":[],"asks":[{"price":1773.73,"qty":0.60314538}],"checksum":1744717244,"timestamp":"2026-07-07T23:00:10.925650Z"}]}
{"channel":"book","type":"update","data":[{"symbol":"ETH/USD","bids":[],"asks":[{"price":1773.80,"qty":0.00000000},{"price":1773.84,"qty":15.93800000}],"checksum":1540474411,"timestamp":"2026-07-07T23:00:10.925886Z"}]}
{"channel":"book","type":"update","data":[{"symbol":"BTC/USD","bids":[],"asks":[{"price":63501.2,"qty":0.00000000},{"price":63504.0,"qty":0.00005100}],"checksum":3182247327,"timestamp":"2026-07-07T23:00:10.927856Z"}]}
{"channel":"book","type":"update","data":[{"symbol":"BTC/USD","bids":[],"asks":[{"price":63501.1,"qty":2.71281054}],"checksum":2257555919,"timestamp":"2026-07-07T23:00:10.930007Z"}]}
{"channel":"book","type":"update","data":[{"symbol":"BTC/USD","bids":[],"asks":[{"price":63501.1,"qty":0.77079683}],"checksum":2821555044,"timestamp":"2026-07-07T23:00:10.930029Z"}]}
{"channel":"book","type":"update","data":[{"symbol":"ETH/USD","bids":[],"asks":[{"price":1773.82,"qty":10.32177016}],"checksum":4159712070,"timestamp":"2026-07-07T23:00:10.931875Z"}]}
{"channel":"book","type":"update","data":[{"symbol":"ETH/USD","bids":[{"price":1773.17,"qty":0.00000000},{"price":1773.06,"qty":12.67243555}],"asks":[],"checksum":1643626099,"timestamp":"2026-07-07T23:00:10.958720Z"}]}
{"channel":"book","type":"update","data":[{"symbol":"ETH/USD","bids":[{"price":1773.13,"qty":1.68966976}],"asks":[],"checksum":2110317119,"timestamp":"2026-07-07T23:00:10.960026Z"}]}
{"channel":"book","type":"update","data":[{"symbol":"ETH/USD","bids":[],"asks":[{"price":1773.60,"qty":0.00000000},{"price":1773.85,"qty":0.50000000}],"checksum":1621468311,"timestamp":"2026-07-07T23:00:10.966172Z"}]}
{"channel":"book","type":"update","data":[{"symbol":"ETH/USD","bids":[],"asks":[{"price":1773.66,"qty":2.81904336}],"checksum":536621597,"timestamp":"2026-07-07T23:00:10.967412Z"}]}
{"channel":"book","type":"update","data":[{"symbol":"ETH/USD","bids":[],"asks":[{"price":1773.59,"qty":0.00000000},{"price":1773.85,"qty":0.50000000}],"checksum":2678518007,"timestamp":"2026-07-07T23:00:10.967555Z"}]}
{"channel":"book","type":"update","data":[{"symbol":"ETH/USD","bids":[],"asks":[{"price":1773.65,"qty":0.84148444}],"checksum":4122675606,"timestamp":"2026-07-07T23:00:10.968819Z"}]}
{"channel":"book","type":"update","data":[{"symbol":"ETH/USD","bids":[{"price":1773.20,"qty":0.00000000},{"price":1773.06,"qty":12.67243555},{"price":1773.29,"qty":0.05639235}],"asks":[],"checksum":2238953995,"timestamp":"2026-07-07T23:00:11.028625Z"}]}
{"channel":"book","type":"update","data":[{"symbol":"ETH/USD","bids":[],"asks":[{"price":1773.59,"qty":0.32369692}],"checksum":2143060094,"timestamp":"2026-07-07T23:00:11.052641Z"}]}
{"channel":"book","type":"update","data":[{"symbol":"ETH/USD","bids":[{"price":1773.38,"qty":0.29992284}],"asks":[],"checksum":1123725060,"timestamp":"2026-07-07T23:00:11.052974Z"}]}
{"channel":"book","type":"update","data":[{"symbol":"ETH/USD","bids":[{"price":1773.33,"qty":0.00000000},{"price":1773.09,"qty":20.30353661}],"asks":[],"checksum":107953839,"timestamp":"2026-07-07T23:00:11.053838Z"}]}
{"channel":"book","type":"update","data":[{"symbol":"ETH/USD","bids":[],"asks":[{"price":1773.66,"qty":0.00000000},{"price":1773.84,"qty":15.93800000}],"checksum":3249948358,"timestamp":"2026-07-07T23:00:11.055623Z"}]}
{"channel":"book","type":"update","data":[{"symbol":"ETH/USD","bids":[],"asks":[{"price":1773.82,"qty":3.62481121}],"checksum":1286690549,"timestamp":"2026-07-07T23:00:11.057057Z"}]}
{"channel":"book","type":"update","data":[{"symbol":"ETH/USD","bids":[],"asks":[{"price":1773.65,"qty":0.00000000},{"price":1773.85,"qty":0.50000000}],"checksum":3432962105,"timestamp":"2026-07-07T23:00:11.057342Z"}]}
{"channel":"book","type":"update","data":[{"symbol":"ETH/USD","bids":[],"asks":[{"price":1773.82,"qty":0.00000000},{"price":1773.87,"qty":0.28137208}],"checksum":2608348181,"timestamp":"2026-07-07T23:00:11.057386Z"}]}
{"channel":"book","type":"update","data":[{"symbol":"ETH/USD","bids":[],"asks":[{"price":1773.72,"qty":2.29747210}],"checksum":1408643837,"timestamp":"2026-07-07T23:00:11.057496Z"}]}
{"channel":"book","type":"update","data":[{"symbol":"ETH/USD","bids":[],"asks":[{"price":1773.60,"qty":2.81912887}],"checksum":4014640613,"timestamp":"2026-07-07T23:00:11.057579Z"}]}
{"channel":"book","type":"update","data":[{"symbol":"BTC/USD","bids":[{"price":63477.1,"qty":0.78925968}],"asks":[],"checksum":2189095322,"timestamp":"2026-07-07T23:00:11.058093Z"}]}
{"channel":"book","type":"update","data":[{"symbol":"ETH/USD","bids":[],"asks":[{"price":1773.83,"qty":20.45240713}],"checksum":2544485564,"timestamp":"2026-07-07T23:00:11.058479Z"}]}
{"channel":"book","type":"update","data":[{"symbol":"ETH/USD","bids":[],"asks":[{"price":1773.72,"qty":0.00000000},{"price":1773.85,"qty":0.50000000}],"checksum":2828779504,"timestamp":"2026-07-07T23:00:11.058809Z"}]}
{"channel":"book","type":"update","data":[{"symbol":"ETH/USD","bids":[],"asks":[{"price":1773.59,"qty":1.16520689}],"checksum":2188414289,"timestamp":"2026-07-07T23:00:11.059280Z"}]}
{"channel":"book","type":"update","data":[{"symbol":"ETH/USD","bids":[],"asks":[{"price":1773.71,"qty":0.68579542}],"checksum":2672260298,"timestamp":"2026-07-07T23:00:11.059296Z"}]}
{"channel":"book","type":"update","data":[{"symbol":"ETH/USD","bids":[],"asks":[{"price":1773.71,"qty":0.00000000},{"price":1773.85,"qty":0.50000000}],"checksum":2188414289,"timestamp":"2026-07-07T23:00:11.060721Z"}]}
{"channel":"book","type":"update","data":[{"symbol":"ETH/USD","bids":[{"price":1773.29,"qty":0.89805147}],"asks":[],"checksum":4008047792,"timestamp":"2026-07-07T23:00:11.176651Z"}]}
{"channel":"book","type":"update","data":[{"symbol":"ETH/USD","bids":[],"asks":[{"price":1773.49,"qty":0.00000000},{"price":1773.87,"qty":0.28137208}],"checksum":471343638,"timestamp":"2026-07-07T23:00:11.177993Z"}]}
{"channel":"book","type":"update","data":[{"symbol":"ETH/USD","bids":[],"asks":[{"price":1773.58,"qty":0.47001888}],"checksum":809239482,"timestamp":"2026-07-07T23:00:11.178303Z"}]}
{"channel":"book","type":"update","data":[{"symbol":"ETH/USD","bids":[{"price":1773.09,"qty":0.45737557}],"asks":[],"checksum":2898412129,"timestamp":"2026-07-07T23:00:11.179558Z"}]}
{"channel":"book","type":"update","data":[{"symbol":"ETH/USD","bids":[{"price":1773.14,"qty":2.62805617}],"asks":[],"checksum":2463801255,"timestamp":"2026-07-07T23:00:11.180948Z"}]}
{"channel":"book","type":"update","data":[{"symbol":"ETH/USD","bids":[{"price":1773.10,"qty":0.00000000},{"price":1773.09,"qty":0.45737557}],"asks":[],"checksum":294356224,"timestamp":"2026-07-07T23:00:11.181119Z"}]}
{"channel":"book","type":"update","data":[{"symbol":"ETH/USD","bids":[{"price":1773.11,"qty":0.00000000},{"price":1773.06,"qty":12.67243555},{"price":1773.07,"qty":5.56003448}],"asks":[],"checksum":2541628766,"timestamp":"2026-07-07T23:00:11.182094Z"}]}
{"channel":"book","type":"update","data":[{"symbol":"ETH/USD","bids":[{"price":1773.13,"qty":0.00000000},{"price":1773.06,"qty":12.67243555},{"price":1773.15,"qty":1.68966976}],"asks":[],"checksum":2560584791,"timestamp":"2026-07-07T23:00:11.182336Z"}]}
{"channel":"book","type":"update","data":[{"symbol":"ETH/USD","bids":[{"price":1773.14,"qty":0.00000000},{"price":1773.06,"qty":12.67243555}],"asks":[],"checksum":4155072561,"timestamp":"2026-07-07T23:00:11.183468Z"}]}
{"channel":"book","type":"update","data":[{"symbol":"ETH/USD","bids":[{"price":1773.14,"qty":0.96838588}],"asks":[],"checksum":2960873976,"timestamp":"2026-07-07T23:00:11.183835Z"}]}
{"channel":"book","type":"update","data":[{"symbol":"ETH/USD","bids":[{"price":1773.14,"qty":0.00000000},{"price":1773.06,"qty":12.67243555}],"asks":[],"checksum":4155072561,"timestamp":"2026-07-07T23:00:11.184043Z"}]}
{"channel":"book","type":"update","data":[{"symbol":"ETH/USD","bids":[{"price":1773.17,"qty":1.35643588}],"asks":[],"checksum":367592534,"timestamp":"2026-07-07T23:00:11.184887Z"}]}
{"channel":"book","type":"update","data":[{"symbol":"ETH/USD","bids":[{"price":1773.15,"qty":0.00000000},{"price":1773.06,"qty":12.67243555},{"price":1773.13,"qty":1.68966976}],"asks":[],"checksum":271905250,"timestamp":"2026-07-07T23:00:11.184901Z"}]}
{"channel":"book","type":"update","data":[{"symbol":"ETH/USD","bids":[{"price":1773.29,"qty":0.05639235}],"asks":[],"checksum":2560188879,"timestamp":"2026-07-07T23:00:11.289065Z"}]}
{"channel":"book","type":"update","data":[{"symbol":"ETH/USD","bids":[],"asks":[{"price":1773.52,"qty":1.53128753}],"checksum":338453166,"timestamp":"2026-07-07T23:00:11.290397Z"}]}
{"channel":"book","type":"update","data":[{"symbol":"ETH/USD","bids":[],"asks":[{"price":1773.51,"qty":0.47001888}],"checksum":3754562953,"timestamp":"2026-07-07T23:00:11.291801Z"}]}
{"channel":"book","type":"update","data":[{"symbol":"ETH/USD","bids":[{"price":1773.20,"qty":19.84616104}],"asks":[],"checksum":1851219781,"timestamp":"2026-07-07T23:00:11.292616Z"}]}
{"channel":"book","type":"update","data":[{"symbol":"ETH/USD","bids":[],"asks":[{"price":1773.52,"qty":0.00000000},{"price":1773.84,"qty":15.93800000}],"checksum":199956203,"timestamp":"2026-07-07T23:00:11.292988Z"}]}
{"channel":"book","type":"update","data":[{"symbol":"ETH/USD","bids":[{"price":1773.21,"qty":5.92407907}],"asks":[],"checksum":1021200359,"timestamp":"2026-07-07T23:00:11.293999Z"}]}
{"channel":"book","type":"update","data":[{"symbol":"ETH/USD","bids":[],"asks":[{"price":1773.51,"qty":0.00000000},{"price":1773.85,"qty":0.50000000}],"checksum":4238241716,"timestamp":"2026-07-07T23:00:11.294373Z"}]}
{"channel":"book","type":"update","data":[{"symbol":"ETH/USD","bids":[{"price":1773.22,"qty":5.56003448}],"asks":[],"checksum":1602625161,"timestamp":"2026-07-07T23:00:11.295469Z"}]}
{"channel":"book","type":"update","data":[{"symbol":"ETH/USD","bids":[],"asks":[{"price":1773.52,"qty":1.53128753}],"checksum":3127482720,"timestamp":"2026-07-07T23:00:11.295736Z"}]}
{"channel":"book","type":"update","data":[{"symbol":"ETH/USD","bids":[],"asks":[{"price":1773.51,"qty":0.47001888}],"checksum":2932671612,"timestamp":"2026-07-07T23:00:11.297019Z"}]}
{"channel":"book","type":"update","data":[{"symbol":"ETH/USD","bids":[],"asks":[{"price":1773.52,"qty":0.00000000},{"price":1773.84,"qty":15.93800000}],"checksum":2680567514,"timestamp":"2026-07-07T23:00:11.298090Z"}]}
{"channel":"book","type":"update","data":[{"symbol":"ETH/USD","bids":[],"asks":[{"price":1773.51,"qty":0.00000000},{"price":1773.85,"qty":0.50000000}],"checksum":1602625161,"timestamp":"2026-07-07T23:00:11.299251Z"}]}
{"channel":"book","type":"update","data":[{"symbol":"ETH/USD","bids":[],"asks":[{"price":1773.52,"qty":1.53128753}],"checksum":3127482720,"timestamp":"2026-07-07T23:00:11.300679Z"}]}
{"channel":"book","type":"update","data":[{"symbol":"ETH/USD","bids":[],"asks":[{"price":1773.51,"qty":0.47001888}],"checksum":2932671612,"timestamp":"2026-07-07T23:00:11.301797Z"}]}
{"channel":"book","type":"update","data":[{"symbol":"ETH/USD","bids":[],"asks":[{"price":1773.52,"qty":0.00000000},{"price":1773.84,"qty":15.93800000}],"checksum":2680567514,"timestamp":"2026-07-07T23:00:11.302837Z"}]}
{"channel":"book","type":"update","data":[{"symbol":"ETH/USD","bids":[],"asks":[{"price":1773.51,"qty":0.00000000},{"price":1773.85,"qty":0.50000000}],"checksum":1602625161,"timestamp":"2026-07-07T23:00:11.303868Z"}]}
{"channel":"book","type":"update","data":[{"symbol":"ETH/USD","bids":[],"asks":[{"price":1773.52,"qty":1.53128753}],"checksum":3127482720,"timestamp":"2026-07-07T23:00:11.305050Z"}]}
{"channel":"book","type":"update","data":[{"symbol":"ETH/USD","bids":[],"asks":[{"price":1773.51,"qty":0.47001888}],"checksum":2932671612,"timestamp":"2026-07-07T23:00:11.306429Z"}]}
{"channel":"book","type":"update","data":[{"symbol":"ETH/USD","bids":[],"asks":[{"price":1773.52,"qty":0.00000000},{"price":1773.84,"qty":15.93800000}],"checksum":2680567514,"timestamp":"2026-07-07T23:00:11.308643Z"}]}
{"channel":"book","type":"update","data":[{"symbol":"BTC/USD","bids":[{"price":63477.1,"qty":0.00157500}],"asks":[],"checksum":2821555044,"timestamp":"2026-07-07T23:00:11.310031Z"}]}
{"channel":"book","type":"update","data":[{"symbol":"ETH/USD","bids":[],"asks":[{"price":1773.51,"qty":0.00000000},{"price":1773.85,"qty":0.50000000}],"checksum":1602625161,"timestamp":"2026-07-07T23:00:11.310071Z"}]}
{"channel":"book","type":"update","data":[{"symbol":"ETH/USD","bids":[],"asks":[{"price":1773.52,"qty":1.53128753}],"checksum":3127482720,"timestamp":"2026-07-07T23:00:11.311596Z"}]}
{"channel":"book","type":"update","data":[{"symbol":"BTC/USD","bids":[{"price":63477.7,"qty":0.78767817}],"asks":[],"checksum":4129334200,"timestamp":"2026-07-07T23:00:11.311679Z"}]}
{"channel":"book","type":"update","data":[{"symbol":"ETH/USD","bids":[],"asks":[{"price":1773.60,"qty":0.00000000},{"price":1773.85,"qty":0.50000000}],"checksum":152996449,"timestamp":"2026-07-07T23:00:11.313217Z"}]}
{"channel":"book","type":"update","data":[{"symbol":"ETH/USD","bids":[],"asks":[{"price":1773.51,"qty":0.47001888}],"checksum":3031505066,"timestamp":"2026-07-07T23:00:11.313258Z"}]}
{"channel":"book","type":"update","data":[{"symbol":"ETH/USD","bids":[],"asks":[{"price":1773.59,"qty":0.32369692}],"checksum":792942808,"timestamp":"2026-07-07T23:00:11.314543Z"}]}
{"channel":"book","type":"update","data":[{"symbol":"ETH/USD","bids":[],"asks":[{"price":1773.52,"qty":0.00000000},{"price":1773.85,"qty":0.50000000}],"checksum":2045241274,"timestamp":"2026-07-07T23:00:11.314704Z"}]}
{"channel":"book","type":"update","data":[{"symbol":"ETH/USD","bids":[],"asks":[{"price":1773.56,"qty":2.81919202}],"checksum":1449694725,"timestamp":"2026-07-07T23:00:11.314729Z"}]}
{"channel":"book","type":"update","data":[{"symbol":"ETH/USD","bids":[],"asks":[{"price":1773.77,"qty":28.18860384}],"checksum":1083988218,"timestamp":"2026-07-07T23:00:11.315009Z"}]}
{"channel":"book","type":"update","data":[{"symbol":"ETH/USD","bids":[],"asks":[{"price":1773.51,"qty":0.00000000},{"price":1773.84,"qty":15.93800000}],"checksum":2417134004,"timestamp":"2026-07-07T23:00:11.315815Z"}]}
{"channel":"book","type":"update","data":[{"symbol":"ETH/USD","bids":[],"asks":[{"price":1773.52,"qty":1.53128753}],"checksum":2162246216,"timestamp":"2026-07-07T23:00:11.317024Z"}]}
{"channel":"book","type":"update","data":[{"symbol":"ETH/USD","bids":[],"asks":[{"price":1773.55,"qty":0.47001888}],"checksum":1394646160,"timestamp":"2026-07-07T23:00:11.317104Z"}]}
{"channel":"book","type":"update","data":[{"symbol":"ETH/USD","bids":[],"asks":[{"price":1773.73,"qty":8.94033268}],"checksum":3652009577,"timestamp":"2026-07-07T23:00:11.317182Z"}]}
{"channel":"book","type":"update","data":[{"symbol":"ETH/USD","bids":[],"asks":[{"price":1773.74,"qty":0.00000000},{"price":1773.83,"qty":20.45240713}],"checksum":3101784972,"timestamp":"2026-07-07T23:00:11.391348Z"}]}
{"channel":"book","type":"update","data":[{"symbol":"ETH/USD","bids":[],"asks":[{"price":1773.58,"qty":0.00000000},{"price":1773.84,"qty":15.93800000}],"checksum":3489490463,"timestamp":"2026-07-07T23:00:11.392670Z"}]}
{"channel":"book","type":"update","data":[{"symbol":"ETH/USD","bids":[],"asks":[{"price":1773.51,"qty":0.47001888}],"checksum":3793802053,"timestamp":"2026-07-07T23:00:11.393744Z"}]}
{"channel":"book","type":"update","data":[{"symbol":"ETH/USD","bids":[{"price":1773.21,"qty":34.11900576}],"asks":[],"checksum":1386147826,"timestamp":"2026-07-07T23:00:11.441811Z"}]}
{"channel":"book","type":"update","data":[{"symbol":"ETH/USD","bids":[],"asks":[{"price":1773.55,"qty":0.00000000},{"price":1773.84,"qty":15.93800000}],"checksum":820892229,"timestamp":"2026-07-07T23:00:11.494704Z"}]}
{"channel":"book","type":"update","data":[{"symbol":"ETH/USD","bids":[],"asks":[{"price":1773.53,"qty":0.62908082}],"checksum":211152601,"timestamp":"2026-07-07T23:00:11.515402Z"}]}
{"channel":"book","type":"update","data":[{"symbol":"ETH/USD","bids":[],"asks":[{"price":1773.59,"qty":0.00000000},{"price":1773.85,"qty":0.50000000}],"checksum":2866374011,"timestamp":"2026-07-07T23:00:11.516550Z"}]}
{"channel":"book","type":"update","data":[{"symbol":"ETH/USD","bids":[{"price":1773.21,"qty":5.92407907},{"price":1773.14,"qty":28.19496247}],"asks":[],"checksum":573291803,"timestamp":"2026-07-07T23:00:11.532781Z"}]}
{"channel":"book","type":"update","data":[{"symbol":"BTC/USD","bids":[{"price":63477.7,"qty":0.00000000},{"price":63477.1,"qty":0.00157500}],"asks":[],"checksum":2821555044,"timestamp":"2026-07-07T23:00:11.533907Z"}]}
{"channel":"book","type":"update","data":[{"symbol":"ETH/USD","bids":[{"price":1773.15,"qty":1.68966976}],"asks":[],"checksum":3390718943,"timestamp":"2026-07-07T23:00:11.534049Z"}]}
{"channel":"book","type":"update","data":[{"symbol":"ETH/USD","bids":[{"price":1773.28,"qty":0.00000000},{"price":1773.14,"qty":28.19496247}],"asks":[],"checksum":3301466676,"timestamp":"2026-07-07T23:00:11.538846Z"}]}
{"channel":"book","type":"update","data":[{"symbol":"ETH/USD","bids":[{"price":1773.23,"qty":2.81970105}],"asks":[],"checksum":33941391,"timestamp":"2026-07-07T23:00:11.540673Z"}]}
{"channel":"heartbeat"}
{"channel":"book","type":"update","data":[{"symbol":"ETH/USD","bids":[{"price":1773.29,"qty":0.00000000},{"price":1773.14,"qty":28.19496247}],"asks":[],"checksum":3419292880,"timestamp":"2026-07-07T23:00:11.579274Z"}]}
{"channel":"book","type":"update","data":[{"symbol":"ETH/USD","bids":[{"price":1773.21,"qty":0.00000000},{"price":1773.12,"qty":1.09712847}],"asks":[],"checksum":3788589037,"timestamp":"2026-07-07T23:00:11.585398Z"}]}
{"channel":"book","type":"update","data":[{"symbol":"ETH/USD","bids":[{"price":1773.22,"qty":0.00000000},{"price":1773.09,"qty":0.45737557},{"price":1773.21,"qty":5.56003448}],"asks":[],"checksum":3784928123,"timestamp":"2026-07-07T23:00:11.586572Z"}]}
{"channel":"book","type":"update","data":[{"symbol":"ETH/USD","bids":[],"asks":[{"price":1773.51,"qty":1.11488883}],"checksum":4143465425,"timestamp":"2026-07-07T23:00:11.586829Z"}]}
{"channel":"book","type":"update","data":[{"symbol":"ETH/USD","bids":[{"price":1773.14,"qty":0.00000000},{"price":1773.09,"qty":0.45737557}],"asks":[],"checksum":2187604646,"timestamp":"2026-07-07T23:00:11.607653Z"}]}
{"channel":"book","type":"update","data":[{"symbol":"ETH/USD","bids":[{"price":1773.15,"qty":0.00000000},{"price":1773.07,"qty":28.19540059},{"price":1773.13,"qty":1.68966976}],"asks":[],"checksum":4263709969,"timestamp":"2026-07-07T23:00:11.609212Z"}]}
{"channel":"book","type":"update","data":[{"symbol":"ETH/USD","bids":[{"price":1773.38,"qty":0.00000000},{"price":1773.07,"qty":28.19540059}],"asks":[],"checksum":3615385460,"timestamp":"2026-07-07T23:00:11.628269Z"}]}
{"channel":"book","type":"update","data":[{"symbol":"ETH/USD","bids":[{"price":1773.24,"qty":1.30000000}],"asks":[],"checksum":2519306858,"timestamp":"2026-07-07T23:00:11.630336Z"}]}
{"channel":"book","type":"update","data":[{"symbol":"ETH/USD","bids":[],"asks":[{"price":1773.56,"qty":0.00000000},{"price":1773.87,"qty":0.28137208}],"checksum":2874735704,"timestamp":"2026-07-07T23:00:11.630621Z"}]}
{"channel":"book","type":"update","data":[{"symbol":"ETH/USD","bids":[{"price":1773.21,"qty":0.00000000},{"price":1773.07,"qty":28.19540059},{"price":1773.08,"qty":5.56003448}],"asks":[],"checksum":1288995353,"timestamp":"2026-07-07T23:00:11.631440Z"}]}
{"channel":"book","type":"update","data":[{"symbol":"ETH/USD","bids":[],"asks":[{"price":1773.52,"qty":4.35054789}],"checksum":2435216573,"timestamp":"2026-07-07T23:00:11.632221Z"}]}
{"channel":"book","type":"update","data":[{"symbol":"ETH/USD","bids":[{"price":1773.13,"qty":0.00000000},{"price":1773.07,"qty":28.19540059},{"price":1773.23,"qty":4.50937081}],"asks":[],"checksum":186390368,"timestamp":"2026-07-07T23:00:11.699363Z"}]}
{"channel":"book","type":"update","data":[{"symbol":"ETH/USD","bids":[{"price":1773.17,"qty":0.00000000},{"price":1773.06,"qty":6.68414810}],"asks":[],"checksum":3385991659,"timestamp":"2026-07-07T23:00:11.700628Z"}]}
{"channel":"book","type":"update","data":[{"symbol":"ETH/USD","bids":[{"price":1773.17,"qty":0.85206946}],"asks":[],"checksum":2311529673,"timestamp":"2026-07-07T23:00:11.702161Z"}]}
{"channel":"book","type":"update","data":[{"symbol":"ETH/USD","bids":[],"asks":[{"price":1773.51,"qty":1.87399270}],"checksum":3663915947,"timestamp":"2026-07-07T23:00:11.710317Z"}]}
{"channel":"book","type":"update","data":[{"symbol":"ETH/USD","bids":[{"price":1773.16,"qty":0.00000000},{"price":1773.06,"qty":6.68414810}],"asks":[],"checksum":4286063726,"timestamp":"2026-07-07T23:00:11.731235Z"}]}
{"channel":"book","type":"update","data":[{"symbol":"ETH/USD","bids":[{"price":1773.17,"qty":0.00000000},{"price":1773.04,"qty":0.48930000}],"asks":[],"checksum":2855259596,"timestamp":"2026-07-07T23:00:11.732875Z"}]}
{"channel":"book","type":"update","data":[{"symbol":"ETH/USD","bids":[{"price":1773.08,"qty":15.64526276}],"asks":[],"checksum":2307300589,"timestamp":"2026-07-07T23:00:11.735198Z"}]}
{"channel":"book","type":"update","data":[{"symbol":"ETH/USD","bids":[{"price":1773.06,"qty":0.00000000},{"price":1773.03,"qty":28.20021144}],"asks":[],"checksum":2281619912,"timestamp":"2026-07-07T23:00:11.735255Z"}]}
{"channel":"book","type":"update","data":[{"symbol":"ETH/USD","bids":[{"price":1773.08,"qty":21.25080416}],"asks":[],"checksum":1511234350,"timestamp":"2026-07-07T23:00:11.736496Z"}]}
{"channel":"book","type":"update","data":[{"symbol":"ETH/USD","bids":[{"price":1773.33,"qty":0.31869910}],"asks":[],"checksum":3463667258,"timestamp":"2026-07-07T23:00:11.941165Z"}]}
{"channel":"book","type":"update","data":[{"symbol":"BTC/USD","bids":[],"asks":[{"price":63501.0,"qty":2.36301531}],"checksum":247816370,"timestamp":"2026-07-07T23:00:12.005620Z"}]}
{"channel":"book","type":"update","data":[{"symbol":"BTC/USD","bids":[],"asks":[{"price":63501.1,"qty":0.00000000},{"price":63504.0,"qty":0.00005100}],"checksum":822800795,"timestamp":"2026-07-07T23:00:12.007146Z"}]}
{"channel":"book","type":"update","data":[{"symbol":"BTC/USD","bids":[],"asks":[{"price":63500.9,"qty":1.47615690}],"checksum":3454188825,"timestamp":"2026-07-07T23:00:12.007574Z"}]}
{"channel":"book","type":"update","data":[{"symbol":"ETH/USD","bids":[{"price":1773.25,"qty":0.05639362}],"asks":[],"checksum":240216576,"timestamp":"2026-07-07T23:00:12.074103Z"}]}
{"channel":"book","type":"update","data":[{"symbol":"ETH/USD","bids":[],"asks":[{"price":1773.52,"qty":2.81926036}],"checksum":2293970996,"timestamp":"2026-07-07T23:00:12.075900Z"}]}
{"channel":"book","type":"update","data":[{"symbol":"ETH/USD","bids":[],"asks":[{"price":1773.76,"qty":1.53128753}],"checksum":3198163992,"timestamp":"2026-07-07T23:00:12.076060Z"}]}
{"channel":"book","type":"update","data":[{"symbol":"ETH/USD","bids":[],"asks":[{"price":1773.51,"qty":1.11488883}],"checksum":3976582010,"timestamp":"2026-07-07T23:00:12.078482Z"}]}
{"channel":"book","type":"update","data":[{"symbol":"ETH/USD","bids":[],"asks":[{"price":1773.75,"qty":0.65295893}],"checksum":2801891622,"timestamp":"2026-07-07T23:00:12.375329Z"}]}
{"channel":"heartbeat"}
{"channel":"book","type":"update","data":[{"symbol":"ETH/USD","bids":[],"asks":[{"price":1773.51,"qty":0.47001888}],"checksum":3880456070,"timestamp":"2026-07-07T23:00:12.817395Z"}]}
{"channel":"book","type":"update","data":[{"symbol":"ETH/USD","bids":[{"price":1773.24,"qty":8.57012626}],"asks":[],"checksum":3962657179,"timestamp":"2026-07-07T23:00:12.820722Z"}]}
{"channel":"book","type":"update","data":[{"symbol":"ETH/USD","bids":[{"price":1773.38,"qty":0.33730034}],"asks":[],"checksum":3106339852,"timestamp":"2026-07-07T23:00:12.825536Z"}]}
{"channel":"book","type":"update","data":[{"symbol":"ETH/USD","bids":[{"price":1773.33,"qty":0.00000000},{"price":1773.07,"qty":28.19540059}],"asks":[],"checksum":1937098843,"timestamp":"2026-07-07T23:00:12.826715Z"}]}
{"channel":"book","type":"update","data":[{"symbol":"ETH/USD","bids":[],"asks":[{"price":1773.80,"qty":0.14094909}],"checksum":4267608753,"timestamp":"2026-07-07T23:00:12.828198Z"}]}
{"channel":"book","type":"update","data":[{"symbol":"ETH/USD","bids":[],"asks":[{"price":1773.52,"qty":0.00000000},{"price":1773.85,"qty":0.50000000}],"checksum":578442166,"timestamp":"2026-07-07T23:00:12.828886Z"}]}
{"channel":"book","type":"update","data":[{"symbol":"ETH/USD","bids":[],"asks":[{"price":1773.53,"qty":0.31674471}],"checksum":1891330832,"timestamp":"2026-07-07T23:00:12.829400Z"}]}
{"channel":"book","type":"update","data":[{"symbol":"ETH/USD","bids":[],"asks":[{"price":1773.59,"qty":2.81914148}],"checksum":757054399,"timestamp":"2026-07-07T23:00:12.830380Z"}]}
{"channel":"book","type":"update","data":[{"symbol":"ETH/USD","bids":[],"asks":[{"price":1773.51,"qty":0.00000000},{"price":1773.85,"qty":0.50000000}],"checksum":1275677160,"timestamp":"2026-07-07T23:00:12.831124Z"}]}
{"channel":"book","type":"update","data":[{"symbol":"ETH/USD","bids":[],"asks":[{"price":1773.72,"qty":2.29747210}],"checksum":3265398402,"timestamp":"2026-07-07T23:00:12.831177Z"}]}
{"channel":"book","type":"update","data":[{"symbol":"ETH/USD","bids":[],"asks":[{"price":1773.52,"qty":0.47001888}],"checksum":974827221,"timestamp":"2026-07-07T23:00:12.831329Z"}]}
{"channel":"book","type":"update","data":[{"symbol":"ETH/USD","bids":[],"asks":[{"price":1773.72,"qty":0.00000000},{"price":1773.84,"qty":15.93800000}],"checksum":711761710,"timestamp":"2026-07-07T23:00:12.831890Z"}]}
{"channel":"book","type":"update","data":[{"symbol":"ETH/USD","bids":[{"price":1773.37,"qty":0.18213883}],"asks":[],"checksum":1577046183,"timestamp":"2026-07-07T23:00:12.832941Z"}]}
{"channel":"book","type":"update","data":[{"symbol":"ETH/USD","bids":[{"price":1773.23,"qty":1.68966976}],"asks":[],"checksum":753344774,"timestamp":"2026-07-07T23:00:12.834748Z"}]}
{"channel":"book","type":"update","data":[{"symbol":"ETH/USD","bids":[],"asks":[{"price":1773.59,"qty":0.00000000},{"price":1773.85,"qty":0.50000000}],"checksum":3937390536,"timestamp":"2026-07-07T23:00:12.835645Z"}]}
{"channel":"book","type":"update","data":[{"symbol":"ETH/USD","bids":[{"price":1773.23,"qty":0.00000000},{"price":1773.04,"qty":0.48930000},{"price":1773.21,"qty":1.68966976}],"asks":[],"checksum":1780789601,"timestamp":"2026-07-07T23:00:12.837557Z"}]}
{"channel":"book","type":"update","data":[{"symbol":"ETH/USD","bids":[],"asks":[{"price":1773.72,"qty":2.29747210}],"checksum":4260280544,"timestamp":"2026-07-07T23:00:12.837908Z"}]}
{"channel":"book","type":"update","data":[{"symbol":"ETH/USD","bids":[],"asks":[{"price":1773.77,"qty":0.00000000},{"price":1773.85,"qty":0.50000000}],"checksum":4278170256,"timestamp":"2026-07-07T23:00:12.837933Z"}]}
{"channel":"book","type":"update","data":[{"symbol":"ETH/USD","bids":[{"price":1773.38,"qty":0.82660034}],"asks":[],"checksum":1471164606,"timestamp":"2026-07-07T23:00:12.840458Z"}]}
{"channel":"book","type":"update","data":[{"symbol":"ETH/USD","bids":[],"asks":[{"price":1773.73,"qty":0.60314538}],"checksum":3505787761,"timestamp":"2026-07-07T23:00:12.841017Z"}]}
{"channel":"book","type":"update","data":[{"symbol":"ETH/USD","bids":[{"price":1773.27,"qty":2.81964719}],"asks":[],"checksum":2525060537,"timestamp":"2026-07-07T23:00:12.841490Z"}]}
{"channel":"book","type":"update","data":[{"symbol":"ETH/USD","bids":[{"price":1773.27,"qty":0.00000000},{"price":1773.07,"qty":28.19540059}],"asks":[],"checksum":3505787761,"timestamp":"2026-07-07T23:00:12.842897Z"}]}
{"channel":"book","type":"update","data":[{"symbol":"ETH/USD","bids":[],"asks":[{"price":1773.72,"qty":0.00000000},{"price":1773.86,"qty":28.18726569}],"checksum":3661983400,"timestamp":"2026-07-07T23:00:12.843036Z"}]}
{"channel":"book","type":"update","data":[{"symbol":"ETH/USD","bids":[],"asks":[{"price":1773.71,"qty":0.68579542}],"checksum":1964453598,"timestamp":"2026-07-07T23:00:12.844109Z"}]}
{"channel":"book","type":"update","data":[{"symbol":"ETH/USD","bids":[{"price":1773.28,"qty":0.84166469}],"asks":[],"checksum":11103473,"timestamp":"2026-07-07T23:00:12.844428Z"}]}
{"channel":"book","type":"update","data":[{"symbol":"ETH/USD","bids":[],"asks":[{"price":1773.75,"qty":2.95043103}],"checksum":758563678,"timestamp":"2026-07-07T23:00:12.845298Z"}]}
{"channel":"book","type":"update","data":[{"symbol":"ETH/USD","bids":[],"asks":[{"price":1773.71,"qty":0.00000000},{"price":1773.86,"qty":28.18726569}],"checksum":607703372,"timestamp":"2026-07-07T23:00:12.845472Z"}]}
{"channel":"book","type":"update","data":[{"symbol":"ETH/USD","bids":[{"price":1773.10,"qty":28.19909283}],"asks":[],"checksum":3116422850,"timestamp":"2026-07-07T23:00:12.845656Z"}]}
{"channel":"book","type":"update","data":[{"symbol":"ETH/USD","bids":[],"asks":[{"price":1773.74,"qty":2.29747210}],"checksum":1712075667,"timestamp":"2026-07-07T23:00:12.845781Z"}]}
{"channel":"book","type":"update","data":[{"symbol":"ETH/USD","bids":[{"price":1773.28,"qty":0.00000000},{"price":1773.08,"qty":21.25080416}],"asks":[],"checksum":478488115,"timestamp":"2026-07-07T23:00:12.845824Z"}]}
{"channel":"book","type":"update","data":[{"symbol":"ETH/USD","bids":[{"price":1773.08,"qty":15.64526276}],"asks":[],"checksum":3852649608,"timestamp":"2026-07-07T23:00:12.846162Z"}]}
{"channel":"book","type":"update","data":[{"symbol":"ETH/USD","bids":[],"asks":[{"price":1773.75,"qty":0.65295893}],"checksum":2648344622,"timestamp":"2026-07-07T23:00:12.846754Z"}]}
{"channel":"book","type":"update","data":[{"symbol":"ETH/USD","bids":[{"price":1773.08,"qty":10.08522828},{"price":1773.25,"qty":5.61642810}],"asks":[],"checksum":383673831,"timestamp":"2026-07-07T23:00:12.847246Z"}]}
{"channel":"book","type":"update","data":[{"symbol":"ETH/USD","bids":[],"asks":[{"price":1773.74,"qty":0.00000000},{"price":1773.86,"qty":28.18726569}],"checksum":1160557308,"timestamp":"2026-07-07T23:00:12.847309Z"}]}
{"channel":"book","type":"update","data":[{"symbol":"ETH/USD","bids":[],"asks":[{"price":1773.73,"qty":1.30275535}],"checksum":2122115058,"timestamp":"2026-07-07T23:00:12.847706Z"}]}
{"channel":"book","type":"update","data":[{"symbol":"ETH/USD","bids":[{"price":1773.11,"qty":8.55395582}],"asks":[],"checksum":3720674830,"timestamp":"2026-07-07T23:00:12.847766Z"}]}
{"channel":"book","type":"update","data":[{"symbol":"ETH/USD","bids":[],"asks":[{"price":1773.73,"qty":0.60314538}],"checksum":3820042286,"timestamp":"2026-07-07T23:00:12.848094Z"}]}
{"channel":"book","type":"update","data":[{"symbol":"ETH/USD","bids":[],"asks":[{"price":1773.73,"qty":0.00000000},{"price":1773.87,"qty":0.28137208}],"checksum":838353331,"timestamp":"2026-07-07T23:00:12.848135Z"}]}
{"channel":"book","type":"update","data":[{"symbol":"ETH/USD","bids":[{"price":1773.38,"qty":0.33730034}],"asks":[],"checksum":3985048574,"timestamp":"2026-07-07T23:00:12.849355Z"}]}
{"channel":"book","type":"update","data":[{"symbol":"ETH/USD","bids":[],"asks":[{"price":1773.73,"qty":2.06566172}],"checksum":3878618755,"timestamp":"2026-07-07T23:00:12.849364Z"}]}
{"channel":"book","type":"update","data":[{"symbol":"ETH/USD","bids":[],"asks":[{"price":1773.73,"qty":0.00000000},{"price":1773.87,"qty":0.28137208}],"checksum":3985048574,"timestamp":"2026-07-07T23:00:12.849575Z"}]}
{"channel":"book","type":"update","data":[{"symbol":"ETH/USD","bids":[],"asks":[{"price":1773.75,"qty":2.95043103}],"checksum":396187214,"timestamp":"2026-07-07T23:00:12.849689Z"}]}
{"channel":"book","type":"update","data":[{"symbol":"ETH/USD","bids":[],"asks":[{"price":1773.74,"qty":2.29747210}],"checksum":1657558605,"timestamp":"2026-07-07T23:00:12.850056Z"}]}
{"channel":"book","type":"update","data":[{"symbol":"ETH/USD","bids":[],"asks":[{"price":1773.74,"qty":0.00000000},{"price":1773.87,"qty":0.28137208}],"checksum":396187214,"timestamp":"2026-07-07T23:00:12.850208Z"}]}
{"channel":"book","type":"update","data":[{"symbol":"ETH/USD","bids":[],"asks":[{"price":1773.74,"qty":0.69407087}],"checksum":1001346654,"timestamp":"2026-07-07T23:00:12.850312Z"}]}
{"channel":"book","type":"update","data":[{"symbol":"ETH/USD","bids":[{"price":1773.39,"qty":0.48930000}],"asks":[],"checksum":263984488,"timestamp":"2026-07-07T23:00:12.850448Z"}]}
{"channel":"book","type":"update","data":[{"symbol":"ETH/USD","bids":[],"asks":[{"price":1773.75,"qty":0.65295893}],"checksum":4198394608,"timestamp":"2026-07-07T23:00:12.851235Z"}]}
{"channel":"book","type":"update","data":[{"symbol":"ETH/USD","bids":[],"asks":[{"price":1773.74,"qty":1.29113070}],"checksum":3499399016,"timestamp":"2026-07-07T23:00:12.851786Z"}]}
{"channel":"book","type":"update","data":[{"symbol":"ETH/USD","bids":[],"asks":[{"price":1773.74,"qty":0.59705983}],"checksum":247802923,"timestamp":"2026-07-07T23:00:12.851799Z"}]}
{"channel":"book","type":"update","data":[{"symbol":"ETH/USD","bids":[],"asks":[{"price":1773.73,"qty":2.06566172}],"checksum":2835607746,"timestamp":"2026-07-07T23:00:12.851871Z"}]}
{"channel":"book","type":"update","data":[{"symbol":"ETH/USD","bids":[],"asks":[{"price":1773.74,"qty":0.00000000},{"price":1773.86,"qty":28.18726569}],"checksum":3543942581,"timestamp":"2026-07-07T23:00:12.851973Z"}]}
{"channel":"book","type":"update","data":[{"symbol":"ETH/USD","bids":[],"asks":[{"price":1773.73,"qty":0.00000000},{"price":1773.87,"qty":0.28137208}],"checksum":3650371784,"timestamp":"2026-07-07T23:00:12.852237Z"}]}
{"channel":"book","type":"update","data":[{"symbol":"ETH/USD","bids":[],"asks":[{"price":1773.75,"qty":2.95043103}],"checksum":596514168,"timestamp":"2026-07-07T23:00:12.852377Z"}]}
{"channel":"book","type":"update","data":[{"symbol":"ETH/USD","bids":[],"asks":[{"price":1773.74,"qty":2.29747210}],"checksum":1457460603,"timestamp":"2026-07-07T23:00:12.852573Z"}]}
{"channel":"book","type":"update","data":[{"symbol":"ETH/USD","bids":[],"asks":[{"price":1773.74,"qty":2.99154297}],"checksum":828454656,"timestamp":"2026-07-07T23:00:12.853031Z"}]}
{"channel":"book","type":"update","data":[{"symbol":"ETH/USD","bids":[],"asks":[{"price":1773.72,"qty":2.29747210}],"checksum":957907497,"timestamp":"2026-07-07T23:00:12.853665Z"}]}
{"channel":"book","type":"update","data":[{"symbol":"ETH/USD","bids":[],"asks":[{"price":1773.75,"qty":0.65295893}],"checksum":1869042566,"timestamp":"2026-07-07T23:00:12.853749Z"}]}
{"channel":"book","type":"update","data":[{"symbol":"ETH/USD","bids":[],"asks":[{"price":1773.53,"qty":0.00000000},{"price":1773.86,"qty":28.18726569}],"checksum":2265735999,"timestamp":"2026-07-07T23:00:12.853834Z"}]}
{"channel":"book","type":"update","data":[{"symbol":"ETH/USD","bids":[],"asks":[{"price":1773.72,"qty":0.00000000},{"price":1773.87,"qty":0.28137208}],"checksum":667561895,"timestamp":"2026-07-07T23:00:12.854014Z"}]}
{"channel":"book","type":"update","data":[{"symbol":"ETH/USD","bids":[],"asks":[{"price":1773.74,"qty":3.58860280}],"checksum":1187572669,"timestamp":"2026-07-07T23:00:12.854452Z"}]}
{"channel":"book","type":"update","data":[{"symbol":"ETH/USD","bids":[],"asks":[{"price":1773.74,"qty":2.89453193}],"checksum":1991069516,"timestamp":"2026-07-07T23:00:12.854754Z"}]}
{"channel":"book","type":"update","data":[{"symbol":"ETH/USD","bids":[],"asks":[{"price":1773.74,"qty":0.59705983}],"checksum":3243193249,"timestamp":"2026-07-07T23:00:12.854931Z"}]}
{"channel":"book","type":"update","data":[{"symbol":"ETH/USD","bids":[],"asks":[{"price":1773.74,"qty":0.00000000},{"price":1773.88,"qty":12.35426731}],"checksum":3081138448,"timestamp":"2026-07-07T23:00:12.855033Z"}]}
{"channel":"book","type":"update","data":[{"symbol":"ETH/USD","bids":[],"asks":[{"price":1773.64,"qty":0.31674471}],"checksum":105876242,"timestamp":"2026-07-07T23:00:12.855362Z"}]}
{"channel":"book","type":"update","data":[{"symbol":"ETH/USD","bids":[],"asks":[{"price":1773.71,"qty":1.53128753}],"checksum":784929747,"timestamp":"2026-07-07T23:00:12.855552Z"}]}
{"channel":"book","type":"update","data":[{"symbol":"ETH/USD","bids":[],"asks":[{"price":1773.75,"qty":2.95043103}],"checksum":2903479139,"timestamp":"2026-07-07T23:00:12.856332Z"}]}
{"channel":"book","type":"update","data":[{"symbol":"ETH/USD","bids":[],"asks":[{"price":1773.73,"qty":1.37986629}],"checksum":755896433,"timestamp":"2026-07-07T23:00:12.856614Z"}]}
{"channel":"book","type":"update","data":[{"symbol":"ETH/USD","bids":[],"asks":[{"price":1773.73,"qty":3.67733839}],"checksum":136087140,"timestamp":"2026-07-07T23:00:12.856692Z"}]}
{"channel":"book","type":"update","data":[{"symbol":"ETH/USD","bids":[],"asks":[{"price":1773.71,"qty":0.00000000},{"price":1773.86,"qty":28.18726569}],"checksum":3139477616,"timestamp":"2026-07-07T23:00:12.856835Z"}]}
{"channel":"book","type":"update","data":[{"symbol":"ETH/USD","bids":[],"asks":[{"price":1773.73,"qty":4.37140926}],"checksum":2826240520,"timestamp":"2026-07-07T23:00:12.856843Z"}]}
{"channel":"book","type":"update","data":[{"symbol":"ETH/USD","bids":[],"asks":[{"price":1773.73,"qty":2.07393716}],"checksum":9604439,"timestamp":"2026-07-07T23:00:12.856855Z"}]}
{"channel":"book","type":"update","data":[{"symbol":"ETH/USD","bids":[],"asks":[{"price":1773.73,"qty":0.69407087}],"checksum":4039938366,"timestamp":"2026-07-07T23:00:12.856892Z"}]}
{"channel":"book","type":"update","data":[{"symbol":"ETH/USD","bids":[],"asks":[{"price":1773.63,"qty":1.53128753}],"checksum":2294553126,"timestamp":"2026-07-07T23:00:12.857223Z"}]}
{"channel":"book","type":"update","data":[{"symbol":"ETH/USD","bids":[],"asks":[{"price":1773.63,"qty":0.00000000},{"price":1773.86,"qty":28.18726569}],"checksum":4039938366,"timestamp":"2026-07-07T23:00:12.857269Z"}]}
{"channel":"book","type":"update","data":[{"symbol":"ETH/USD","bids":[],"asks":[{"price":1773.74,"qty":2.29747210}],"checksum":4216920394,"timestamp":"2026-07-07T23:00:12.858246Z"}]}
{"channel":"book","type":"update","data":[{"symbol":"ETH/USD","bids":[{"price":1773.39,"qty":0.00000000},{"price":1773.09,"qty":0.45737557}],"asks":[],"checksum":3477756540,"timestamp":"2026-07-07T23:00:12.858375Z"}]}
{"channel":"book","type":"update","data":[{"symbol":"ETH/USD","bids":[],"asks":[{"price":1773.73,"qty":1.29113070}],"checksum":1702757739,"timestamp":"2026-07-07T23:00:12.858385Z"}]}
{"channel":"book","type":"update","data":[{"symbol":"ETH/USD","bids":[],"asks":[{"price":1773.73,"qty":0.69407087}],"checksum":3477756540,"timestamp":"2026-07-07T23:00:12.858444Z"}]}
{"channel":"book","type":"update","data":[{"symbol":"ETH/USD","bids":[],"asks":[{"price":1773.73,"qty":0.00000000},{"price":1773.86,"qty":28.18726569}],"checksum":363708219,"timestamp":"2026-07-07T23:00:12.858732Z"}]}
{"channel":"book","type":"update","data":[{"symbol":"ETH/USD","bids":[],"asks":[{"price":1773.73,"qty":2.06566172}],"checksum":4286559201,"timestamp":"2026-07-07T23:00:12.860655Z"}]}
{"channel":"book","type":"update","data":[{"symbol":"BTC/USD","bids":[],"asks":[{"price":63498.1,"qty":4.19307980}],"checksum":401909582,"timestamp":"2026-07-07T23:00:12.860893Z"}]}
{"channel":"book","type":"update","data":[{"symbol":"ETH/USD","bids":[],"asks":[{"price":1773.72,"qty":2.29747210}],"checksum":3940637211,"timestamp":"2026-07-07T23:00:12.860937Z"}]}
{"channel":"book","type":"update","data":[{"symbol":"BTC/USD","bids":[],"asks":[{"price":63498.1,"qty":4.28699945}],"checksum":1525608713,"timestamp":"2026-07-07T23:00:12.860911Z"}]}
{"channel":"book","type":"update","data":[{"symbol":"ETH/USD","bids":[],"asks":[{"price":1773.72,"qty":0.00000000},{"price":1773.85,"qty":0.50000000}],"checksum":4286559201,"timestamp":"2026-07-07T23:00:12.860991Z"}]}
{"channel":"book","type":"update","data":[{"symbol":"ETH/USD","bids":[],"asks":[{"price":1773.75,"qty":0.65295893}],"checksum":1292280035,"timestamp":"2026-07-07T23:00:12.861003Z"}]}
{"channel":"book","type":"update","data":[{"symbol":"ETH/USD","bids":[],"asks":[{"price":1773.74,"qty":0.00000000},{"price":1773.86,"qty":28.18726569}],"checksum":2180441730,"timestamp":"2026-07-07T23:00:12.862292Z"}]}
{"channel":"book","type":"update","data":[{"symbol":"ETH/USD","bids":[],"asks":[{"price":1773.72,"qty":2.29747210}],"checksum":3661084870,"timestamp":"2026-07-07T23:00:12.863625Z"}]}
{"channel":"book","type":"update","data":[{"symbol":"ETH/USD","bids":[],"asks":[{"price":1773.71,"qty":0.68579542}],"checksum":3779370779,"timestamp":"2026-07-07T23:00:12.863636Z"}]}
{"channel":"book","type":"update","data":[{"symbol":"ETH/USD","bids":[],"asks":[{"price":1773.73,"qty":0.00000000},{"price":1773.85,"qty":0.50000000}],"checksum":451127631,"timestamp":"2026-07-07T23:00:12.863751Z"}]}
{"channel":"book","type":"update","data":[{"symbol":"ETH/USD","bids":[],"asks":[{"price":1773.71,"qty":0.00000000},{"price":1773.86,"qty":28.18726569}],"checksum":1484262059,"timestamp":"2026-07-07T23:00:12.863831Z"}]}
{"channel":"book","type":"update","data":[{"symbol":"ETH/USD","bids":[],"asks":[{"price":1773.74,"qty":0.69407087}],"checksum":3212281185,"timestamp":"2026-07-07T23:00:12.865211Z"}]}
{"channel":"book","type":"update","data":[{"symbol":"ETH/USD","bids":[],"asks":[{"price":1773.71,"qty":0.68579542}],"checksum":3101965493,"timestamp":"2026-07-07T23:00:12.865233Z"}]}
{"channel":"book","type":"update","data":[{"symbol":"ETH/USD","bids":[],"asks":[{"price":1773.72,"qty":0.00000000},{"price":1773.85,"qty":0.50000000}],"checksum":1841392700,"timestamp":"2026-07-07T23:00:12.865578Z"}]}
{"channel":"book","type":"update","data":[{"symbol":"ETH/USD","bids":[],"asks":[{"price":1773.71,"qty":0.00000000},{"price":1773.86,"qty":28.18726569}],"checksum":301392412,"timestamp":"2026-07-07T23:00:12.867582Z"}]}
{"channel":"book","type":"update","data":[{"symbol":"ETH/USD","bids":[],"asks":[{"price":1773.75,"qty":2.95043103}],"checksum":1568061023,"timestamp":"2026-07-07T23:00:12.872635Z"}]}
{"channel":"book","type":"update","data":[{"symbol":"ETH/USD","bids":[],"asks":[{"price":1773.74,"qty":1.29113070}],"checksum":2989493923,"timestamp":"2026-07-07T23:00:12.875219Z"}]}
{"channel":"book","type":"update","data":[{"symbol":"ETH/USD","bids":[],"asks":[{"price":1773.74,"qty":3.58860280}],"checksum":2703811552,"timestamp":"2026-07-07T23:00:12.876453Z"}]}
{"channel":"book","type":"update","data":[{"symbol":"ETH/USD","bids":[],"asks":[{"price":1773.75,"qty":0.65295893}],"checksum":4130021703,"timestamp":"2026-07-07T23:00:12.877224Z"}]}
{"channel":"book","type":"update","data":[{"symbol":"ETH/USD","bids":[],"asks":[{"price":1773.74,"qty":2.99154297}],"checksum":463567392,"timestamp":"2026-07-07T23:00:12.877719Z"}]}
{"channel":"book","type":"update","data":[{"symbol":"ETH/USD","bids":[],"asks":[{"price":1773.74,"qty":2.29747210}],"checksum":2026491323,"timestamp":"2026-07-07T23:00:12.877757Z"}]}
{"channel":"book","type":"update","data":[{"symbol":"ETH/USD","bids":[],"asks":[{"price":1773.73,"qty":1.37986629}],"checksum":3518799020,"timestamp":"2026-07-07T23:00:12.879136Z"}]}
{"channel":"book","type":"update","data":[{"symbol":"ETH/USD","bids":[],"asks":[{"price":1773.75,"qty":0.48930000}],"checksum":2612541168,"timestamp":"2026-07-07T23:00:12.879335Z"}]}
{"channel":"book","type":"update","data":[{"symbol":"ETH/USD","bids":[],"asks":[{"price":1773.73,"qty":3.67733839}],"checksum":3670632471,"timestamp":"2026-07-07T23:00:12.880576Z"}]}
{"channel":"book","type":"update","data":[{"symbol":"ETH/USD","bids":[],"asks":[{"price":1773.74,"qty":0.00000000},{"price":1773.86,"qty":28.18726569}],"checksum":158258739,"timestamp":"2026-07-07T23:00:12.881733Z"}]}
{"channel":"book","type":"update","data":[{"symbol":"ETH/USD","bids":[],"asks":[{"price":1773.72,"qty":1.33101410}],"checksum":3372689256,"timestamp":"2026-07-07T23:00:12.883431Z"}]}
{"channel":"book","type":"update","data":[{"symbol":"ETH/USD","bids":[],"asks":[{"price":1773.73,"qty":2.29747210}],"checksum":244094913,"timestamp":"2026-07-07T23:00:12.883658Z"}]}
{"channel":"book","type":"update","data":[{"symbol":"ETH/USD","bids":[],"asks":[{"price":1773.72,"qty":3.62848620}],"checksum":3025601582,"timestamp":"2026-07-07T23:00:12.884898Z"}]}
{"channel":"book","type":"update","data":[{"symbol":"ETH/USD","bids":[],"asks":[{"price":1773.73,"qty":0.00000000},{"price":1773.86,"qty":28.18726569}],"checksum":2710868095,"timestamp":"2026-07-07T23:00:12.886040Z"}]}
{"channel":"book","type":"update","data":[{"symbol":"ETH/USD","bids":[],"asks":[{"price":1773.72,"qty":2.29747210}],"checksum":137419426,"timestamp":"2026-07-07T23:00:12.887487Z"}]}
{"channel":"book","type":"update","data":[{"symbol":"ETH/USD","bids":[],"asks":[{"price":1773.72,"qty":2.94269078}],"checksum":4256260612,"timestamp":"2026-07-07T23:00:12.887604Z"}]}
{"channel":"book","type":"update","data":[{"symbol":"ETH/USD","bids":[{"price":1773.23,"qty":0.45737557}],"asks":[],"checksum":2554215156,"timestamp":"2026-07-07T23:00:12.898944Z"}]}
{"channel":"book","type":"update","data":[{"symbol":"ETH/USD","bids":[{"price":1773.21,"qty":0.00000000},{"price":1773.08,"qty":10.08522828},{"price":1773.23,"qty":2.14704533}],"asks":[],"checksum":1373387025,"timestamp":"2026-07-07T23:00:12.900279Z"}]}
{"channel":"book","type":"update","data":[{"symbol":"ETH/USD","bids":[],"asks":[{"price":1773.69,"qty":2.81898521}],"checksum":1161522920,"timestamp":"2026-07-07T23:00:12.911207Z"}]}
{"channel":"book","type":"update","data":[{"symbol":"ETH/USD","bids":[{"price":1773.35,"qty":2.81952164}],"asks":[],"checksum":3764115088,"timestamp":"2026-07-07T23:00:12.911347Z"}]}
{"channel":"book","type":"update","data":[{"symbol":"BTC/USD","bids":[],"asks":[{"price":63501.0,"qty":0.00000000},{"price":63504.0,"qty":0.00005100}],"checksum":2553009765,"timestamp":"2026-07-07T23:00:12.913457Z"}]}
{"channel":"book","type":"update","data":[{"symbol":"BTC/USD","bids":[],"asks":[{"price":63500.9,"qty":2.24695373}],"checksum":1242977521,"timestamp":"2026-07-07T23:00:12.916192Z"}]}
{"channel":"book","type":"update","data":[{"symbol":"BTC/USD","bids":[],"asks":[{"price":63500.9,"qty":0.77079683}],"checksum":2147882627,"timestamp":"2026-07-07T23:00:12.916269Z"}]}
{"channel":"book","type":"update","data":[{"symbol":"ETH/USD","bids":[{"price":1773.10,"qty":0.00000000},{"price":1773.08,"qty":10.08522828}],"asks":[],"checksum":1101449541,"timestamp":"2026-07-07T23:00:12.927026Z"}]}
{"channel":"book","type":"update","data":[{"symbol":"ETH/USD","bids":[{"price":1773.38,"qty":0.83730034}],"asks":[],"checksum":3300309675,"timestamp":"2026-07-07T23:00:12.927370Z"}]}
{"channel":"book","type":"update","data":[{"symbol":"ETH/USD","bids":[{"price":1773.11,"qty":0.00000000},{"price":1773.07,"qty":28.19540059}],"asks":[],"checksum":2158045184,"timestamp":"2026-07-07T23:00:12.929956Z"}]}
{"channel":"book","type":"update","data":[{"symbol":"ETH/USD","bids":[{"price":1773.35,"qty":0.00000000},{"price":1773.04,"qty":0.48930000}],"asks":[],"checksum":3961014016,"timestamp":"2026-07-07T23:00:12.930528Z"}]}
{"channel":"book","type":"update","data":[{"symbol":"ETH/USD","bids":[],"asks":[{"price":1773.69,"qty":0.00000000},{"price":1773.86,"qty":28.18726569}],"checksum":169079068,"timestamp":"2026-07-07T23:00:12.932412Z"}]}
{"channel":"book","type":"update","data":[{"symbol":"ETH/USD","bids":[],"asks":[{"price":1773.86,"qty":0.00000000},{"price":1773.87,"qty":0.28137208}],"checksum":2413086534,"timestamp":"2026-07-07T23:00:12.933200Z"}]}
{"channel":"book","type":"update","data":[{"symbol":"ETH/USD","bids":[],"asks":[{"price":1773.66,"qty":0.27295200}],"checksum":1514708049,"timestamp":"2026-07-07T23:00:12.933285Z"}]}
{"channel":"book","type":"update","data":[{"symbol":"BTC/USD","bids":[{"price":63478.7,"qty":0.03147178}],"asks":[],"checksum":3066941697,"timestamp":"2026-07-07T23:00:12.953016Z"}]}
{"channel":"book","type":"update","data":[{"symbol":"ETH/USD","bids":[],"asks":[{"price":1773.76,"qty":0.00000000},{"price":1773.87,"qty":0.28137208}],"checksum":1778216129,"timestamp":"2026-07-07T23:00:12.956470Z"}]}
{"channel":"book","type":"update","data":[{"symbol":"ETH/USD","bids":[],"asks":[{"price":1773.72,"qty":2.29747210}],"checksum":207406896,"timestamp":"2026-07-07T23:00:12.957642Z"}]}
{"channel":"book","type":"update","data":[{"symbol":"ETH/USD","bids":[],"asks":[{"price":1773.76,"qty":1.53128753}],"checksum":2425880432,"timestamp":"2026-07-07T23:00:12.958873Z"}]}
{"channel":"book","type":"update","data":[{"symbol":"ETH/USD","bids":[],"asks":[{"price":1773.74,"qty":0.64521868}],"checksum":871423868,"timestamp":"2026-07-07T23:00:12.960245Z"}]}
{"channel":"book","type":"update","data":[{"symbol":"ETH/USD","bids":[],"asks":[{"price":1773.72,"qty":0.00000000},{"price":1773.85,"qty":0.50000000}],"checksum":4078826049,"timestamp":"2026-07-07T23:00:12.961528Z"}]}
{"channel":"book","type":"update","data":[{"symbol":"ETH/USD","bids":[],"asks":[{"price":1773.61,"qty":0.30687730}],"checksum":2483302546,"timestamp":"2026-07-07T23:00:12.999175Z"}]}
{"channel":"book","type":"update","data":[{"symbol":"ETH/USD","bids":[],"asks":[{"price":1773.66,"qty":0.00000000},{"price":1773.85,"qty":0.50000000}],"checksum":3506728806,"timestamp":"2026-07-07T23:00:13.000166Z"}]}
{"channel":"book","type":"update","data":[{"symbol":"ETH/USD","bids":[{"price":1773.39,"qty":0.48930000}],"asks":[],"checksum":2978623936,"timestamp":"2026-07-07T23:00:13.000476Z"}]}
{"channel":"book","type":"update","data":[{"symbol":"ETH/USD","bids":[],"asks":[{"price":1773.51,"qty":1.53128753}],"checksum":323780585,"timestamp":"2026-07-07T23:00:13.000654Z"}]}
{"channel":"book","type":"update","data":[{"symbol":"ETH/USD","bids":[],"asks":[{"price":1773.50,"qty":0.47001888}],"checksum":4248990160,"timestamp":"2026-07-07T23:00:13.002183Z"}]}
{"channel":"book","type":"update","data":[{"symbol":"ETH/USD","bids":[],"asks":[{"price":1773.51,"qty":0.00000000},{"price":1773.84,"qty":15.93800000}],"checksum":1176699232,"timestamp":"2026-07-07T23:00:13.003521Z"}]}
{"channel":"book","type":"update","data":[{"symbol":"ETH/USD","bids":[],"asks":[{"price":1773.50,"qty":0.00000000},{"price":1773.85,"qty":0.50000000}],"checksum":2978623936,"timestamp":"2026-07-07T23:00:13.004933Z"}]}
{"channel":"book","type":"update","data":[{"symbol":"ETH/USD","bids":[],"asks":[{"price":1773.51,"qty":1.53128753}],"checksum":323780585,"timestamp":"2026-07-07T23:00:13.006437Z"}]}
{"channel":"book","type":"update","data":[{"symbol":"ETH/USD","bids":[],"asks":[{"price":1773.50,"qty":0.47001888}],"checksum":4248990160,"timestamp":"2026-07-07T23:00:13.007512Z"}]}
{"channel":"book","type":"update","data":[{"symbol":"ETH/USD","bids":[],"asks":[{"price":1773.51,"qty":0.00000000},{"price":1773.84,"qty":15.93800000}],"checksum":1176699232,"timestamp":"2026-07-07T23:00:13.008738Z"}]}
{"channel":"book","type":"update","data":[{"symbol":"ETH/USD","bids":[],"asks":[{"price":1773.50,"qty":0.00000000},{"price":1773.85,"qty":0.50000000}],"checksum":2978623936,"timestamp":"2026-07-07T23:00:13.010594Z"}]}
{"channel":"book","type":"update","data":[{"symbol":"ETH/USD","bids":[],"asks":[{"price":1773.51,"qty":1.53128753}],"checksum":323780585,"timestamp":"2026-07-07T23:00:13.012176Z"}]}
{"channel":"book","type":"update","data":[{"symbol":"ETH/USD","bids":[],"asks":[{"price":1773.50,"qty":0.47001888}],"checksum":4248990160,"timestamp":"2026-07-07T23:00:13.013488Z"}]}
{"channel":"book","type":"update","data":[{"symbol":"ETH/USD","bids":[],"asks":[{"price":1773.51,"qty":0.00000000},{"price":1773.84,"qty":15.93800000}],"checksum":1176699232,"timestamp":"2026-07-07T23:00:13.014807Z"}]}
{"channel":"book","type":"update","data":[{"symbol":"ETH/USD","bids":[],"asks":[{"price":1773.50,"qty":0.00000000},{"price":1773.85,"qty":0.50000000}],"checksum":2978623936,"timestamp":"2026-07-07T23:00:13.016070Z"}]}
{"channel":"book","type":"update","data":[{"symbol":"ETH/USD","bids":[],"asks":[{"price":1773.51,"qty":1.53128753}],"checksum":323780585,"timestamp":"2026-07-07T23:00:13.017775Z"}]}
{"channel":"book","type":"update","data":[{"symbol":"ETH/USD","bids":[],"asks":[{"price":1773.50,"qty":0.47001888}],"checksum":4248990160,"timestamp":"2026-07-07T23:00:13.019094Z"}]}
{"channel":"book","type":"update","data":[{"symbol":"ETH/USD","bids":[],"asks":[{"price":1773.51,"qty":0.00000000},{"price":1773.84,"qty":15.93800000}],"checksum":1176699232,"timestamp":"2026-07-07T23:00:13.020550Z"}]}
{"channel":"book","type":"update","data":[{"symbol":"ETH/USD","bids":[],"asks":[{"price":1773.50,"qty":0.00000000},{"price":1773.85,"qty":0.50000000}],"checksum":2978623936,"timestamp":"2026-07-07T23:00:13.021840Z"}]}
{"channel":"book","type":"update","data":[{"symbol":"ETH/USD","bids":[],"asks":[{"price":1773.51,"qty":1.53128753}],"checksum":323780585,"timestamp":"2026-07-07T23:00:13.023538Z"}]}
{"channel":"book","type":"update","data":[{"symbol":"ETH/USD","bids":[],"asks":[{"price":1773.50,"qty":0.47001888}],"checksum":4248990160,"timestamp":"2026-07-07T23:00:13.024842Z"}]}
{"channel":"book","type":"update","data":[{"symbol":"ETH/USD","bids":[],"asks":[{"price":1773.51,"qty":0.00000000},{"price":1773.84,"qty":15.93800000}],"checksum":1176699232,"timestamp":"2026-07-07T23:00:13.026326Z"}]}
{"channel":"book","type":"update","data":[{"symbol":"ETH/USD","bids":[],"asks":[{"price":1773.50,"qty":0.00000000},{"price":1773.85,"qty":0.50000000}],"checksum":2978623936,"timestamp":"2026-07-07T23:00:13.027558Z"}]}
{"channel":"book","type":"update","data":[{"symbol":"ETH/USD","bids":[],"asks":[{"price":1773.51,"qty":1.53128753}],"checksum":323780585,"timestamp":"2026-07-07T23:00:13.029006Z"}]}
{"channel":"book","type":"update","data":[{"symbol":"ETH/USD","bids":[],"asks":[{"price":1773.50,"qty":0.47001888}],"checksum":4248990160,"timestamp":"2026-07-07T23:00:13.030246Z"}]}
{"channel":"book","type":"update","data":[{"symbol":"ETH/USD","bids":[],"asks":[{"price":1773.51,"qty":0.00000000},{"price":1773.84,"qty":15.93800000}],"checksum":1176699232,"timestamp":"2026-07-07T23:00:13.032857Z"}]}
{"channel":"book","type":"update","data":[{"symbol":"ETH/USD","bids":[],"asks":[{"price":1773.50,"qty":0.00000000},{"price":1773.85,"qty":0.50000000}],"checksum":2978623936,"timestamp":"2026-07-07T23:00:13.034531Z"}]}
{"channel":"book","type":"update","data":[{"symbol":"ETH/USD","bids":[],"asks":[{"price":1773.51,"qty":1.53128753}],"checksum":323780585,"timestamp":"2026-07-07T23:00:13.036228Z"}]}
{"channel":"book","type":"update","data":[{"symbol":"ETH/USD","bids":[],"asks":[{"price":1773.50,"qty":0.47001888}],"checksum":4248990160,"timestamp":"2026-07-07T23:00:13.037883Z"}]}
{"channel":"book","type":"update","data":[{"symbol":"ETH/USD","bids":[],"asks":[{"price":1773.51,"qty":0.00000000},{"price":1773.84,"qty":15.93800000}],"checksum":1176699232,"timestamp":"2026-07-07T23:00:13.039446Z"}]}
{"channel":"book","type":"update","data":[{"symbol":"ETH/USD","bids":[],"asks":[{"price":1773.50,"qty":0.00000000},{"price":1773.85,"qty":0.50000000}],"checksum":2978623936,"timestamp":"2026-07-07T23:00:13.040751Z"}]}
{"channel":"book","type":"update","data":[{"symbol":"ETH/USD","bids":[],"asks":[{"price":1773.51,"qty":1.53128753}],"checksum":323780585,"timestamp":"2026-07-07T23:00:13.042171Z"}]}
{"channel":"book","type":"update","data":[{"symbol":"ETH/USD","bids":[],"asks":[{"price":1773.50,"qty":0.47001888}],"checksum":4248990160,"timestamp":"2026-07-07T23:00:13.043681Z"}]}
{"channel":"book","type":"update","data":[{"symbol":"ETH/USD","bids":[],"asks":[{"price":1773.51,"qty":0.00000000},{"price":1773.84,"qty":15.93800000}],"checksum":1176699232,"timestamp":"2026-07-07T23:00:13.044998Z"}]}
{"channel":"book","type":"update","data":[{"symbol":"ETH/USD","bids":[],"asks":[{"price":1773.50,"qty":0.00000000},{"price":1773.85,"qty":0.50000000}],"checksum":2978623936,"timestamp":"2026-07-07T23:00:13.047034Z"}]}
{"channel":"book","type":"update","data":[{"symbol":"ETH/USD","bids":[],"asks":[{"price":1773.51,"qty":1.53128753}],"checksum":323780585,"timestamp":"2026-07-07T23:00:13.048408Z"}]}
{"channel":"book","type":"update","data":[{"symbol":"ETH/USD","bids":[],"asks":[{"price":1773.50,"qty":0.47001888}],"checksum":4248990160,"timestamp":"2026-07-07T23:00:13.049730Z"}]}
{"channel":"book","type":"update","data":[{"symbol":"ETH/USD","bids":[],"asks":[{"price":1773.51,"qty":0.00000000},{"price":1773.84,"qty":15.93800000}],"checksum":1176699232,"timestamp":"2026-07-07T23:00:13.051016Z"}]}
{"channel":"book","type":"update","data":[{"symbol":"ETH/USD","bids":[],"asks":[{"price":1773.50,"qty":0.00000000},{"price":1773.85,"qty":0.50000000}],"checksum":2978623936,"timestamp":"2026-07-07T23:00:13.052140Z"}]}
{"channel":"book","type":"update","data":[{"symbol":"ETH/USD","bids":[],"asks":[{"price":1773.51,"qty":1.53128753}],"checksum":323780585,"timestamp":"2026-07-07T23:00:13.053379Z"}]}
{"channel":"book","type":"update","data":[{"symbol":"ETH/USD","bids":[],"asks":[{"price":1773.50,"qty":0.47001888}],"checksum":4248990160,"timestamp":"2026-07-07T23:00:13.055474Z"}]}
{"channel":"book","type":"update","data":[{"symbol":"ETH/USD","bids":[],"asks":[{"price":1773.51,"qty":0.00000000},{"price":1773.84,"qty":15.93800000}],"checksum":1176699232,"timestamp":"2026-07-07T23:00:13.056744Z"}]}
{"channel":"book","type":"update","data":[{"symbol":"ETH/USD","bids":[],"asks":[{"price":1773.50,"qty":0.00000000},{"price":1773.85,"qty":0.50000000}],"checksum":2978623936,"timestamp":"2026-07-07T23:00:13.057843Z"}]}
{"channel":"book","type":"update","data":[{"symbol":"BTC/USD","bids":[{"price":63478.7,"qty":0.81913744}],"asks":[],"checksum":2014669605,"timestamp":"2026-07-07T23:00:13.058729Z"}]}
{"channel":"book","type":"update","data":[{"symbol":"ETH/USD","bids":[],"asks":[{"price":1773.74,"qty":3.46412183}],"checksum":816885491,"timestamp":"2026-07-07T23:00:13.058808Z"}]}
{"channel":"book","type":"update","data":[{"symbol":"ETH/USD","bids":[{"price":1773.42,"qty":2.81940654}],"asks":[],"checksum":630862525,"timestamp":"2026-07-07T23:00:13.058916Z"}]}
{"channel":"book","type":"update","data":[{"symbol":"ETH/USD","bids":[],"asks":[{"price":1773.51,"qty":1.53128753}],"checksum":2605041175,"timestamp":"2026-07-07T23:00:13.059129Z"}]}
{"channel":"book","type":"update","data":[{"symbol":"ETH/USD","bids":[],"asks":[{"price":1773.73,"qty":1.48666127}],"checksum":198922723,"timestamp":"2026-07-07T23:00:13.060243Z"}]}
{"channel":"book","type":"update","data":[{"symbol":"ETH/USD","bids":[],"asks":[{"price":1773.74,"qty":2.81890315}],"checksum":4080979676,"timestamp":"2026-07-07T23:00:13.060292Z"}]}
{"channel":"book","type":"update","data":[{"symbol":"ETH/USD","bids":[],"asks":[{"price":1773.73,"qty":3.78413337}],"checksum":1240858378,"timestamp":"2026-07-07T23:00:13.060410Z"}]}
{"channel":"book","type":"update","data":[{"symbol":"ETH/USD","bids":[],"asks":[{"price":1773.50,"qty":0.47001888}],"checksum":3217146228,"timestamp":"2026-07-07T23:00:13.060540Z"}]}
{"channel":"book","type":"update","data":[{"symbol":"ETH/USD","bids":[],"asks":[{"price":1773.51,"qty":0.00000000},{"price":1773.83,"qty":20.45240713}],"checksum":598563261,"timestamp":"2026-07-07T23:00:13.061958Z"}]}
{"channel":"book","type":"update","data":[{"symbol":"ETH/USD","bids":[],"asks":[{"price":1773.50,"qty":0.00000000},{"price":1773.84,"qty":15.93800000}],"checksum":1514512411,"timestamp":"2026-07-07T23:00:13.063382Z"}]}
{"channel":"book","type":"update","data":[{"symbol":"ETH/USD","bids":[],"asks":[{"price":1773.51,"qty":1.53128753}],"checksum":1240858378,"timestamp":"2026-07-07T23:00:13.065131Z"}]}
{"channel":"book","type":"update","data":[{"symbol":"ETH/USD","bids":[],"asks":[{"price":1773.50,"qty":0.47001888}],"checksum":3217146228,"timestamp":"2026-07-07T23:00:13.066767Z"}]}
{"channel":"book","type":"update","data":[{"symbol":"ETH/USD","bids":[],"asks":[{"price":1773.51,"qty":0.00000000},{"price":1773.83,"qty":20.45240713}],"checksum":598563261,"timestamp":"2026-07-07T23:00:13.068252Z"}]}
{"channel":"book","type":"update","data":[{"symbol":"ETH/USD","bids":[],"asks":[{"price":1773.50,"qty":0.00000000},{"price":1773.84,"qty":15.93800000}],"checksum":1514512411,"timestamp":"2026-07-07T23:00:13.069437Z"}]}
{"channel":"book","type":"update","data":[{"symbol":"ETH/USD","bids":[],"asks":[{"price":1773.51,"qty":1.53128753}],"checksum":1240858378,"timestamp":"2026-07-07T23:00:13.070705Z"}]}
{"channel":"book","type":"update","data":[{"symbol":"ETH/USD","bids":[],"asks":[{"price":1773.50,"qty":0.47001888}],"checksum":3217146228,"timestamp":"2026-07-07T23:00:13.072176Z"}]}
{"channel":"book","type":"update","data":[{"symbol":"ETH/USD","bids":[],"asks":[{"price":1773.51,"qty":0.00000000},{"price":1773.83,"qty":20.45240713}],"checksum":598563261,"timestamp":"2026-07-07T23:00:13.073563Z"}]}
{"channel":"book","type":"update","data":[{"symbol":"ETH/USD","bids":[],"asks":[{"price":1773.50,"qty":0.00000000},{"price":1773.84,"qty":15.93800000}],"checksum":1514512411,"timestamp":"2026-07-07T23:00:13.074809Z"}]}
{"channel":"book","type":"update","data":[{"symbol":"ETH/USD","bids":[],"asks":[{"price":1773.51,"qty":1.53128753}],"checksum":1240858378,"timestamp":"2026-07-07T23:00:13.076704Z"}]}
{"channel":"book","type":"update","data":[{"symbol":"ETH/USD","bids":[],"asks":[{"price":1773.50,"qty":0.47001888}],"checksum":3217146228,"timestamp":"2026-07-07T23:00:13.078873Z"}]}
{"channel":"book","type":"update","data":[{"symbol":"ETH/USD","bids":[],"asks":[{"price":1773.51,"qty":0.00000000},{"price":1773.83,"qty":20.45240713}],"checksum":598563261,"timestamp":"2026-07-07T23:00:13.080670Z"}]}
{"channel":"book","type":"update","data":[{"symbol":"ETH/USD","bids":[],"asks":[{"price":1773.50,"qty":0.00000000},{"price":1773.84,"qty":15.93800000}],"checksum":1514512411,"timestamp":"2026-07-07T23:00:13.082203Z"}]}
{"channel":"book","type":"update","data":[{"symbol":"ETH/USD","bids":[],"asks":[{"price":1773.51,"qty":1.53128753}],"checksum":1240858378,"timestamp":"2026-07-07T23:00:13.083697Z"}]}
{"channel":"book","type":"update","data":[{"symbol":"ETH/USD","bids":[],"asks":[{"price":1773.50,"qty":0.47001888}],"checksum":3217146228,"timestamp":"2026-07-07T23:00:13.088686Z"}]}
{"channel":"book","type":"update","data":[{"symbol":"ETH/USD","bids":[],"asks":[{"price":1773.51,"qty":0.00000000},{"price":1773.83,"qty":20.45240713}],"checksum":598563261,"timestamp":"2026-07-07T23:00:13.090033Z"}]}
{"channel":"book","type":"update","data":[{"symbol":"ETH/USD","bids":[],"asks":[{"price":1773.50,"qty":0.00000000},{"price":1773.84,"qty":15.93800000}],"checksum":1514512411,"timestamp":"2026-07-07T23:00:13.091274Z"}]}
{"channel":"book","type":"update","data":[{"symbol":"ETH/USD","bids":[],"asks":[{"price":1773.51,"qty":1.53128753}],"checksum":1240858378,"timestamp":"2026-07-07T23:00:13.092750Z"}]}
{"channel":"book","type":"update","data":[{"symbol":"BTC/USD","bids":[{"price":63477.3,"qty":0.02060255}],"asks":[],"checksum":2902482245,"timestamp":"2026-07-07T23:00:13.093906Z"}]}
{"channel":"book","type":"update","data":[{"symbol":"ETH/USD","bids":[],"asks":[{"price":1773.50,"qty":0.47001888}],"checksum":3217146228,"timestamp":"2026-07-07T23:00:13.094359Z"}]}
{"channel":"book","type":"update","data":[{"symbol":"ETH/USD","bids":[],"asks":[{"price":1773.51,"qty":0.00000000},{"price":1773.83,"qty":20.45240713}],"checksum":598563261,"timestamp":"2026-07-07T23:00:13.095541Z"}]}
{"channel":"book","type":"update","data":[{"symbol":"ETH/USD","bids":[],"asks":[{"price":1773.50,"qty":0.00000000},{"price":1773.84,"qty":15.93800000}],"checksum":1514512411,"timestamp":"2026-07-07T23:00:13.096679Z"}]}
{"channel":"book","type":"update","data":[{"symbol":"ETH/USD","bids":[],"asks":[{"price":1773.51,"qty":1.53128753}],"checksum":1240858378,"timestamp":"2026-07-07T23:00:13.097893Z"}]}
{"channel":"book","type":"update","data":[{"symbol":"ETH/USD","bids":[],"asks":[{"price":1773.50,"qty":0.47001888}],"checksum":3217146228,"timestamp":"2026-07-07T23:00:13.099226Z"}]}
{"channel":"book","type":"update","data":[{"symbol":"ETH/USD","bids":[],"asks":[{"price":1773.51,"qty":0.00000000},{"price":1773.83,"qty":20.45240713}],"checksum":598563261,"timestamp":"2026-07-07T23:00:13.101640Z"}]}
{"channel":"book","type":"update","data":[{"symbol":"ETH/USD","bids":[],"asks":[{"price":1773.76,"qty":0.00000000},{"price":1773.84,"qty":15.93800000}],"checksum":2673332841,"timestamp":"2026-07-07T23:00:13.101756Z"}]}
{"channel":"book","type":"update","data":[{"symbol":"ETH/USD","bids":[{"price":1773.39,"qty":0.00000000},{"price":1773.07,"qty":28.19540059}],"asks":[],"checksum":761848153,"timestamp":"2026-07-07T23:00:13.102155Z"}]}
{"channel":"book","type":"update","data":[{"symbol":"ETH/USD","bids":[{"price":1773.43,"qty":0.32871282}],"asks":[],"checksum":157306002,"timestamp":"2026-07-07T23:00:13.102437Z"}]}
{"channel":"book","type":"update","data":[{"symbol":"ETH/USD","bids":[],"asks":[{"price":1773.50,"qty":0.00000000},{"price":1773.85,"qty":0.50000000}],"checksum":2282054823,"timestamp":"2026-07-07T23:00:13.103117Z"}]}
{"channel":"book","type":"update","data":[{"symbol":"ETH/USD","bids":[],"asks":[{"price":1773.52,"qty":0.00000000},{"price":1773.87,"qty":0.28137208}],"checksum":1939439351,"timestamp":"2026-07-07T23:00:13.103312Z"}]}
{"channel":"book","type":"update","data":[{"symbol":"ETH/USD","bids":[],"asks":[{"price":1773.69,"qty":1.53128753}],"checksum":3960867595,"timestamp":"2026-07-07T23:00:13.103443Z"}]}
{"channel":"book","type":"update","data":[{"symbol":"ETH/USD","bids":[],"asks":[{"price":1773.73,"qty":2.29747210}],"checksum":1905305357,"timestamp":"2026-07-07T23:00:13.103498Z"}]}
{"channel":"book","type":"update","data":[{"symbol":"ETH/USD","bids":[{"price":1773.38,"qty":0.50000000}],"asks":[],"checksum":3427370814,"timestamp":"2026-07-07T23:00:13.103761Z"}]}
{"channel":"book","type":"update","data":[{"symbol":"ETH/USD","bids":[],"asks":[{"price":1773.72,"qty":1.71536737}],"checksum":2975274974,"timestamp":"2026-07-07T23:00:13.104053Z"}]}
{"channel":"book","type":"update","data":[{"symbol":"ETH/USD","bids":[{"price":1773.24,"qty":9.05942626}],"asks":[],"checksum":3531391554,"timestamp":"2026-07-07T23:00:13.104077Z"}]}
{"channel":"book","type":"update","data":[{"symbol":"ETH/USD","bids":[{"price":1773.42,"qty":0.00000000},{"price":1773.07,"qty":28.19540059}],"asks":[],"checksum":3158749899,"timestamp":"2026-07-07T23:00:13.104854Z"}]}
{"channel":"book","type":"update","data":[{"symbol":"ETH/USD","bids":[],"asks":[{"price":1773.61,"qty":0.00000000},{"price":1773.85,"qty":0.50000000}],"checksum":1449747904,"timestamp":"2026-07-07T23:00:13.105051Z"}]}
{"channel":"book","type":"update","data":[{"symbol":"ETH/USD","bids":[],"asks":[{"price":1773.74,"qty":0.00000000},{"price":1773.87,"qty":0.28137208}],"checksum":2303172299,"timestamp":"2026-07-07T23:00:13.105138Z"}]}
{"channel":"book","type":"update","data":[{"symbol":"ETH/USD","bids":[],"asks":[{"price":1773.63,"qty":0.47001888}],"checksum":2181431763,"timestamp":"2026-07-07T23:00:13.106822Z"}]}
{"channel":"book","type":"update","data":[{"symbol":"ETH/USD","bids":[],"asks":[{"price":1773.51,"qty":1.53128753}],"checksum":2535503922,"timestamp":"2026-07-07T23:00:13.106883Z"}]}
{"channel":"book","type":"update","data":[{"symbol":"ETH/USD","bids":[],"asks":[{"price":1773.64,"qty":0.80604471}],"checksum":1004043619,"timestamp":"2026-07-07T23:00:13.107147Z"}]}
{"channel":"book","type":"update","data":[{"symbol":"ETH/USD","bids":[],"asks":[{"price":1773.75,"qty":0.00000000},{"price":1773.85,"qty":0.50000000}],"checksum":758246889,"timestamp":"2026-07-07T23:00:13.107189Z"}]}
{"channel":"book","type":"update","data":[{"symbol":"ETH/USD","bids":[],"asks":[{"price":1773.72,"qty":0.00000000},{"price":1773.87,"qty":0.28137208}],"checksum":342715387,"timestamp":"2026-07-07T23:00:13.107266Z"}]}
{"channel":"book","type":"update","data":[{"symbol":"ETH/USD","bids":[],"asks":[{"price":1773.72,"qty":0.87392478}],"checksum":3982260789,"timestamp":"2026-07-07T23:00:13.107485Z"}]}
{"channel":"book","type":"update","data":[{"symbol":"ETH/USD","bids":[],"asks":[{"price":1773.51,"qty":0.00000000},{"price":1773.87,"qty":0.28137208}],"checksum":3812272639,"timestamp":"2026-07-07T23:00:13.107552Z"}]}
{"channel":"book","type":"update","data":[{"symbol":"ETH/USD","bids":[],"asks":[{"price":1773.50,"qty":0.47001888}],"checksum":2037198543,"timestamp":"2026-07-07T23:00:13.111455Z"}]}
{"channel":"book","type":"update","data":[{"symbol":"ETH/USD","bids":[],"asks":[{"price":1773.63,"qty":2.00130641}],"checksum":1915116855,"timestamp":"2026-07-07T23:00:13.111485Z"}]}
{"channel":"book","type":"update","data":[{"symbol":"ETH/USD","bids":[],"asks":[{"price":1773.50,"qty":0.00000000},{"price":1773.87,"qty":0.28137208}],"checksum":1954640095,"timestamp":"2026-07-07T23:00:13.111557Z"}]}
{"channel":"book","type":"update","data":[{"symbol":"ETH/USD","bids":[],"asks":[{"price":1773.62,"qty":1.53128753}],"checksum":3216391288,"timestamp":"2026-07-07T23:00:13.111617Z"}]}
{"channel":"book","type":"update","data":[{"symbol":"ETH/USD","bids":[],"asks":[{"price":1773.69,"qty":0.00000000},{"price":1773.87,"qty":0.28137208}],"checksum":3272990508,"timestamp":"2026-07-07T23:00:13.112395Z"}]}
{"channel":"book","type":"update","data":[{"symbol":"ETH/USD","bids":[],"asks":[{"price":1773.63,"qty":0.47001888}],"checksum":3251458296,"timestamp":"2026-07-07T23:00:13.112598Z"}]}
{"channel":"book","type":"update","data":[{"symbol":"ETH/USD","bids":[],"asks":[{"price":1773.62,"qty":0.00000000},{"price":1773.88,"qty":12.35426731}],"checksum":3431937457,"timestamp":"2026-07-07T23:00:13.112802Z"}]}
{"channel":"book","type":"update","data":[{"symbol":"ETH/USD","bids":[],"asks":[{"price":1773.61,"qty":0.47001888}],"checksum":435321211,"timestamp":"2026-07-07T23:00:13.113385Z"}]}
{"channel":"book","type":"update","data":[{"symbol":"ETH/USD","bids":[],"asks":[{"price":1773.62,"qty":1.53128753}],"checksum":3021223986,"timestamp":"2026-07-07T23:00:13.113932Z"}]}
{"channel":"book","type":"update","data":[{"symbol":"ETH/USD","bids":[],"asks":[{"price":1773.61,"qty":2.00130641}],"checksum":3691464360,"timestamp":"2026-07-07T23:00:13.114094Z"}]}
{"channel":"book","type":"update","data":[{"symbol":"ETH/USD","bids":[],"asks":[{"price":1773.61,"qty":0.47001888}],"checksum":3021223986,"timestamp":"2026-07-07T23:00:13.114291Z"}]}
{"channel":"book","type":"update","data":[{"symbol":"ETH/USD","bids":[],"asks":[{"price":1773.61,"qty":0.00000000},{"price":1773.87,"qty":0.28137208}],"checksum":3251458296,"timestamp":"2026-07-07T23:00:13.114367Z"}]}
{"channel":"book","type":"update","data":[{"symbol":"ETH/USD","bids":[],"asks":[{"price":1773.61,"qty":1.53128753}],"checksum":1198654839,"timestamp":"2026-07-07T23:00:13.115380Z"}]}
{"channel":"book","type":"update","data":[{"symbol":"ETH/USD","bids":[],"asks":[{"price":1773.60,"qty":1.53128753}],"checksum":3402014967,"timestamp":"2026-07-07T23:00:13.115540Z"}]}
{"channel":"book","type":"update","data":[{"symbol":"ETH/USD","bids":[],"asks":[{"price":1773.60,"qty":2.00130641}],"checksum":3694205681,"timestamp":"2026-07-07T23:00:13.115679Z"}]}
{"channel":"book","type":"update","data":[{"symbol":"ETH/USD","bids":[],"asks":[{"price":1773.60,"qty":0.47001888}],"checksum":882772463,"timestamp":"2026-07-07T23:00:13.115856Z"}]}
{"channel":"book","type":"update","data":[{"symbol":"ETH/USD","bids":[],"asks":[{"price":1773.62,"qty":0.00000000},{"price":1773.85,"qty":0.50000000}],"checksum":547636073,"timestamp":"2026-07-07T23:00:13.116254Z"}]}
{"channel":"book","type":"update","data":[{"symbol":"ETH/USD","bids":[],"asks":[{"price":1773.61,"qty":0.00000000},{"price":1773.87,"qty":0.28137208}],"checksum":330169991,"timestamp":"2026-07-07T23:00:13.116474Z"}]}
{"channel":"book","type":"update","data":[{"symbol":"ETH/USD","bids":[],"asks":[{"price":1773.60,"qty":2.00130641}],"checksum":1665071641,"timestamp":"2026-07-07T23:00:13.116806Z"}]}
{"channel":"book","type":"update","data":[{"symbol":"ETH/USD","bids":[],"asks":[{"price":1773.59,"qty":1.53128753}],"checksum":1859970705,"timestamp":"2026-07-07T23:00:13.117312Z"}]}
{"channel":"book","type":"update","data":[{"symbol":"ETH/USD","bids":[],"asks":[{"price":1773.60,"qty":1.53128753}],"checksum":1925332782,"timestamp":"2026-07-07T23:00:13.117937Z"}]}
{"channel":"book","type":"update","data":[{"symbol":"ETH/USD","bids":[],"asks":[{"price":1773.58,"qty":0.47001888}],"checksum":4210164244,"timestamp":"2026-07-07T23:00:13.119153Z"}]}
{"channel":"book","type":"update","data":[{"symbol":"ETH/USD","bids":[],"asks":[{"price":1773.57,"qty":1.53128753}],"checksum":1284028532,"timestamp":"2026-07-07T23:00:13.120492Z"}]}
{"channel":"book","type":"update","data":[{"symbol":"ETH/USD","bids":[],"asks":[{"price":1773.59,"qty":0.00000000},{"price":1773.84,"qty":15.93800000}],"checksum":1130517396,"timestamp":"2026-07-07T23:00:13.121473Z"}]}
{"channel":"book","type":"update","data":[{"symbol":"BTC/USD","bids":[{"price":63478.7,"qty":0.78766566},{"price":63478.8,"qty":0.03147178}],"asks":[],"checksum":64071437,"timestamp":"2026-07-07T23:00:13.130700Z"}]}
{"channel":"book","type":"update","data":[{"symbol":"ETH/USD","bids":[{"price":1773.07,"qty":0.00000000},{"price":1773.04,"qty":0.48930000},{"price":1773.21,"qty":28.19436350}],"asks":[],"checksum":1491618141,"timestamp":"2026-07-07T23:00:13.140824Z"}]}
{"channel":"book","type":"update","data":[{"symbol":"ETH/USD","bids":[{"price":1773.24,"qty":15.84081829}],"asks":[],"checksum":4064589610,"timestamp":"2026-07-07T23:00:13.142499Z"}]}
{"channel":"book","type":"update","data":[{"symbol":"ETH/USD","bids":[{"price":1773.08,"qty":0.00000000},{"price":1773.04,"qty":0.48930000}],"asks":[],"checksum":3471095887,"timestamp":"2026-07-07T23:00:13.142901Z"}]}
{"channel":"book","type":"update","data":[{"symbol":"BTC/USD","bids":[],"asks":[{"price":63498.1,"qty":2.72635850},{"price":63500.8,"qty":1.56069195}],"checksum":1519800741,"timestamp":"2026-07-07T23:00:13.145915Z"}]}
{"channel":"book","type":"update","data":[{"symbol":"BTC/USD","bids":[],"asks":[{"price":63498.5,"qty":0.77499427}],"checksum":2465105183,"timestamp":"2026-07-07T23:00:13.147671Z"}]}
{"channel":"book","type":"update","data":[{"symbol":"ETH/USD","bids":[],"asks":[{"price":1773.66,"qty":0.33915954}],"checksum":3533049143,"timestamp":"2026-07-07T23:00:13.205988Z"}]}
{"channel":"book","type":"update","data":[{"symbol":"ETH/USD","bids":[],"asks":[{"price":1773.63,"qty":0.00000000},{"price":1773.84,"qty":15.93800000}],"checksum":1592934409,"timestamp":"2026-07-07T23:00:13.212414Z"}]}
{"channel":"book","type":"update","data":[{"symbol":"ETH/USD","bids":[],"asks":[{"price":1773.56,"qty":0.47001888}],"checksum":2195671651,"timestamp":"2026-07-07T23:00:13.213579Z"}]}
{"channel":"book","type":"update","data":[{"symbol":"ETH/USD","bids":[],"asks":[{"price":1773.55,"qty":1.53128753}],"checksum":1284323804,"timestamp":"2026-07-07T23:00:13.216722Z"}]}
{"channel":"book","type":"update","data":[{"symbol":"ETH/USD","bids":[],"asks":[{"price":1773.57,"qty":0.00000000},{"price":1773.83,"qty":20.45240713}],"checksum":3585415855,"timestamp":"2026-07-07T23:00:13.217962Z"}]}
{"channel":"book","type":"update","data":[{"symbol":"ETH/USD","bids":[],"asks":[{"price":1773.60,"qty":0.00000000},{"price":1773.84,"qty":15.93800000}],"checksum":45403759,"timestamp":"2026-07-07T23:00:13.218338Z"}]}
{"channel":"book","type":"update","data":[{"symbol":"ETH/USD","bids":[{"price":1773.43,"qty":0.00000000},{"price":1772.99,"qty":6.72756010}],"asks":[],"checksum":3819320411,"timestamp":"2026-07-07T23:00:13.251070Z"}]}
{"channel":"book","type":"update","data":[{"symbol":"ETH/USD","bids":[],"asks":[{"price":1773.58,"qty":0.00000000},{"price":1773.85,"qty":0.50000000}],"checksum":2196634281,"timestamp":"2026-07-07T23:00:13.314562Z"}]}
{"channel":"book","type":"update","data":[{"symbol":"ETH/USD","bids":[],"asks":[{"price":1773.54,"qty":0.47001888}],"checksum":2870965995,"timestamp":"2026-07-07T23:00:13.315722Z"}]}
{"channel":"book","type":"update","data":[{"symbol":"ETH/USD","bids":[],"asks":[{"price":1773.53,"qty":1.53128753}],"checksum":1306490985,"timestamp":"2026-07-07T23:00:13.316902Z"}]}
{"channel":"book","type":"update","data":[{"symbol":"ETH/USD","bids":[],"asks":[{"price":1773.56,"qty":0.00000000},{"price":1773.84,"qty":15.93800000}],"checksum":282757701,"timestamp":"2026-07-07T23:00:13.417393Z"}]}
{"channel":"book","type":"update","data":[{"symbol":"ETH/USD","bids":[],"asks":[{"price":1773.55,"qty":0.00000000},{"price":1773.85,"qty":0.50000000}],"checksum":2932792850,"timestamp":"2026-07-07T23:00:13.417939Z"}]}
{"channel":"book","type":"update","data":[{"symbol":"ETH/USD","bids":[],"asks":[{"price":1773.52,"qty":0.47001888}],"checksum":3012467268,"timestamp":"2026-07-07T23:00:13.418758Z"}]}
{"channel":"book","type":"update","data":[{"symbol":"ETH/USD","bids":[],"asks":[{"price":1773.51,"qty":1.53128753}],"checksum":1266034138,"timestamp":"2026-07-07T23:00:13.420048Z"}]}
{"channel":"book","type":"update","data":[{"symbol":"ETH/USD","bids":[{"price":1773.12,"qty":0.00000000},{"price":1772.98,"qty":2.87402415}],"asks":[],"checksum":2944951356,"timestamp":"2026-07-07T23:00:13.489869Z"}]}
{"channel":"book","type":"update","data":[{"symbol":"ETH/USD","bids":[],"asks":[{"price":1773.55,"qty":0.27423396}],"checksum":4041367438,"timestamp":"2026-07-07T23:00:13.496395Z"}]}
{"channel":"book","type":"update","data":[{"symbol":"ETH/USD","bids":[{"price":1773.35,"qty":0.30521550}],"asks":[],"checksum":1975430465,"timestamp":"2026-07-07T23:00:13.496711Z"}]}
{"channel":"book","type":"update","data":[{"symbol":"ETH/USD","bids":[],"asks":[{"price":1773.66,"qty":0.00000000},{"price":1773.83,"qty":20.45240713}],"checksum":2002759413,"timestamp":"2026-07-07T23:00:13.497513Z"}]}
{"channel":"book","type":"update","data":[{"symbol":"BTC/USD","bids":[{"price":63478.7,"qty":0.00000000},{"price":63477.2,"qty":0.05744528}],"asks":[],"checksum":3053613710,"timestamp":"2026-07-07T23:00:13.505691Z"}]}
{"channel":"book","type":"update","data":[{"symbol":"ETH/USD","bids":[{"price":1773.21,"qty":0.00000000},{"price":1772.98,"qty":2.87402415},{"price":1773.13,"qty":28.19472477}],"asks":[],"checksum":3030651204,"timestamp":"2026-07-07T23:00:13.506054Z"}]}
{"channel":"book","type":"update","data":[{"symbol":"BTC/USD","bids":[{"price":63478.8,"qty":0.00000000},{"price":63477.1,"qty":0.00157500},{"price":63478.7,"qty":0.03147178}],"asks":[],"checksum":3984806991,"timestamp":"2026-07-07T23:00:13.506984Z"}]}
{"channel":"book","type":"update","data":[{"symbol":"BTC/USD","bids":[{"price":63478.0,"qty":0.78767397}],"asks":[],"checksum":2837783419,"timestamp":"2026-07-07T23:00:13.507198Z"}]}
{"channel":"book","type":"update","data":[{"symbol":"ETH/USD","bids":[{"price":1773.24,"qty":9.05942626}],"asks":[],"checksum":370914676,"timestamp":"2026-07-07T23:00:13.507430Z"}]}
{"channel":"book","type":"update","data":[{"symbol":"ETH/USD","bids":[{"price":1773.14,"qty":8.41612534}],"asks":[],"checksum":3304746419,"timestamp":"2026-07-07T23:00:13.507518Z"}]}
{"channel":"book","type":"update","data":[{"symbol":"ETH/USD","bids":[],"asks":[{"price":1773.54,"qty":0.00000000},{"price":1773.84,"qty":15.93800000}],"checksum":2755650274,"timestamp":"2026-07-07T23:00:13.519675Z"}]}
{"channel":"book","type":"update","data":[{"symbol":"ETH/USD","bids":[],"asks":[{"price":1773.50,"qty":0.47001888}],"checksum":2179044929,"timestamp":"2026-07-07T23:00:13.521063Z"}]}
{"channel":"book","type":"update","data":[{"symbol":"ETH/USD","bids":[],"asks":[{"price":1773.53,"qty":0.00000000},{"price":1773.84,"qty":15.93800000}],"checksum":2790886627,"timestamp":"2026-07-07T23:00:13.521083Z"}]}
{"channel":"book","type":"update","data":[{"symbol":"BTC/USD","bids":[{"price":63478.0,"qty":0.00000000},{"price":63477.2,"qty":0.05744528}],"asks":[],"checksum":3984806991,"timestamp":"2026-07-07T23:00:13.521624Z"}]}
{"channel":"book","type":"update","data":[{"symbol":"ETH/USD","bids":[],"asks":[{"price":1773.67,"qty":2.81901673}],"checksum":1478393214,"timestamp":"2026-07-07T23:00:13.529682Z"}]}
{"channel":"book","type":"update","data":[{"symbol":"ETH/USD","bids":[{"price":1773.38,"qty":3.31946269}],"asks":[],"checksum":2771014312,"timestamp":"2026-07-07T23:00:13.530378Z"}]}
{"channel":"book","type":"update","data":[{"symbol":"ETH/USD","bids":[{"price":1773.17,"qty":28.19802992}],"asks":[],"checksum":2889131193,"timestamp":"2026-07-07T23:00:13.530612Z"}]}
{"channel":"heartbeat"}
{"channel":"book","type":"update","data":[{"symbol":"ETH/USD","bids":[{"price":1773.38,"qty":2.81946269}],"asks":[],"checksum":1902783562,"timestamp":"2026-07-07T23:00:13.593074Z"}]}
{"channel":"book","type":"update","data":[{"symbol":"BTC/USD","bids":[],"asks":[{"price":63501.6,"qty":2.36295376}],"checksum":3030153773,"timestamp":"2026-07-07T23:00:13.595552Z"}]}
{"channel":"book","type":"update","data":[{"symbol":"ETH/USD","bids":[],"asks":[{"price":1773.64,"qty":0.31674471}],"checksum":2813939476,"timestamp":"2026-07-07T23:00:13.597735Z"}]}
{"channel":"book","type":"update","data":[{"symbol":"ETH/USD","bids":[{"price":1773.39,"qty":0.48930000}],"asks":[],"checksum":1295153854,"timestamp":"2026-07-07T23:00:13.597934Z"}]}
{"channel":"book","type":"update","data":[{"symbol":"BTC/USD","bids":[],"asks":[{"price":63500.9,"qty":1.37759367}],"checksum":820563550,"timestamp":"2026-07-07T23:00:13.598217Z"}]}
{"channel":"book","type":"update","data":[{"symbol":"ETH/USD","bids":[],"asks":[{"price":1773.68,"qty":0.48930000}],"checksum":3281931955,"timestamp":"2026-07-07T23:00:13.601015Z"}]}
{"channel":"book","type":"update","data":[{"symbol":"ETH/USD","bids":[{"price":1773.38,"qty":0.00000000},{"price":1773.13,"qty":28.19472477}],"asks":[],"checksum":1324065655,"timestamp":"2026-07-07T23:00:13.614026Z"}]}
{"channel":"book","type":"update","data":[{"symbol":"ETH/USD","bids":[{"price":1773.33,"qty":2.81954911}],"asks":[],"checksum":2928578557,"timestamp":"2026-07-07T23:00:13.615254Z"}]}
{"channel":"book","type":"update","data":[{"symbol":"BTC/USD","bids":[],"asks":[{"price":63501.6,"qty":0.00000000},{"price":63504.0,"qty":0.00005100}],"checksum":3712298490,"timestamp":"2026-07-07T23:00:13.619757Z"}]}
{"channel":"book","type":"update","data":[{"symbol":"ETH/USD","bids":[],"asks":[{"price":1773.49,"qty":0.30734019}],"checksum":180567062,"timestamp":"2026-07-07T23:00:13.620433Z"}]}
{"channel":"book","type":"update","data":[{"symbol":"BTC/USD","bids":[],"asks":[{"price":63500.9,"qty":0.77079683}],"checksum":3984806991,"timestamp":"2026-07-07T23:00:13.621280Z"}]}
{"channel":"book","type":"update","data":[{"symbol":"ETH/USD","bids":[],"asks":[{"price":1773.55,"qty":0.00000000},{"price":1773.80,"qty":0.14094909}],"checksum":461239869,"timestamp":"2026-07-07T23:00:13.621695Z"}]}
{"channel":"book","type":"update","data":[{"symbol":"ETH/USD","bids":[{"price":1773.39,"qty":0.00000000},{"price":1773.13,"qty":28.19472477}],"asks":[],"checksum":3449173590,"timestamp":"2026-07-07T23:00:13.621899Z"}]}
{"channel":"book","type":"update","data":[{"symbol":"ETH/USD","bids":[],"asks":[{"price":1773.52,"qty":0.00000000},{"price":1773.83,"qty":20.45240713}],"checksum":2196013209,"timestamp":"2026-07-07T23:00:13.622343Z"}]}
{"channel":"book","type":"update","data":[{"symbol":"ETH/USD","bids":[{"price":1773.37,"qty":0.67143883}],"asks":[],"checksum":2941065291,"timestamp":"2026-07-07T23:00:13.623411Z"}]}
{"channel":"book","type":"update","data":[{"symbol":"ETH/USD","bids":[],"asks":[{"price":1773.67,"qty":0.00000000},{"price":1773.84,"qty":15.93800000}],"checksum":1901185897,"timestamp":"2026-07-07T23:00:13.625385Z"}]}
{"channel":"book","type":"update","data":[{"symbol":"ETH/USD","bids":[],"asks":[{"price":1773.63,"qty":2.81908965}],"checksum":4012158619,"timestamp":"2026-07-07T23:00:13.627459Z"}]}
{"channel":"book","type":"update","data":[{"symbol":"ETH/USD","bids":[{"price":1773.13,"qty":0.00000000},{"price":1773.04,"qty":0.48930000},{"price":1773.05,"qty":28.19578493}],"asks":[],"checksum":2705060577,"timestamp":"2026-07-07T23:00:13.634146Z"}]}
{"channel":"book","type":"update","data":[{"symbol":"ETH/USD","bids":[{"price":1773.14,"qty":0.00000000},{"price":1773.04,"qty":0.48930000}],"asks":[],"checksum":3604969239,"timestamp":"2026-07-07T23:00:13.635738Z"}]}
{"channel":"book","type":"update","data":[{"symbol":"ETH/USD","bids":[{"price":1773.18,"qty":8.41711193}],"asks":[],"checksum":1262051487,"timestamp":"2026-07-07T23:00:13.637059Z"}]}
{"channel":"book","type":"update","data":[{"symbol":"ETH/USD","bids":[{"price":1773.24,"qty":8.57012626}],"asks":[],"checksum":2487041946,"timestamp":"2026-07-07T23:00:13.774486Z"}]}
{"channel":"book","type":"update","data":[{"symbol":"ETH/USD","bids":[{"price":1773.37,"qty":0.18213883}],"asks":[],"checksum":3113527112,"timestamp":"2026-07-07T23:00:13.938553Z"}]}
{"channel":"book","type":"update","data":[{"symbol":"ETH/USD","bids":[{"price":1773.17,"qty":0.00000000},{"price":1773.04,"qty":0.48930000}],"asks":[],"checksum":3433363186,"timestamp":"2026-07-07T23:00:13.941566Z"}]}
{"channel":"book","type":"update","data":[{"symbol":"ETH/USD","bids":[],"asks":[{"price":1773.63,"qty":0.00000000},{"price":1773.84,"qty":15.93800000}],"checksum":1040100649,"timestamp":"2026-07-07T23:00:13.942236Z"}]}
{"channel":"book","type":"update","data":[{"symbol":"ETH/USD","bids":[{"price":1773.25,"qty":0.05639362},{"price":1773.06,"qty":5.56003448}],"asks":[],"checksum":3726446465,"timestamp":"2026-07-07T23:00:13.942883Z"}]}
{"channel":"book","type":"update","data":[{"symbol":"ETH/USD","bids":[{"price":1773.18,"qty":0.00000000},{"price":1773.04,"qty":0.48930000}],"asks":[],"checksum":4251654416,"timestamp":"2026-07-07T23:00:13.943035Z"}]}
{"channel":"book","type":"update","data":[{"symbol":"ETH/USD","bids":[],"asks":[{"price":1773.60,"qty":2.81912871}],"checksum":627293708,"timestamp":"2026-07-07T23:00:13.943879Z"}]}
{"channel":"book","type":"update","data":[{"symbol":"ETH/USD","bids":[],"asks":[{"price":1773.81,"qty":28.18806908}],"checksum":904763980,"timestamp":"2026-07-07T23:00:13.944457Z"}]}
{"channel":"book","type":"update","data":[{"symbol":"ETH/USD","bids":[{"price":1773.06,"qty":14.12253233}],"asks":[],"checksum":470262316,"timestamp":"2026-07-07T23:00:13.944475Z"}]}
{"channel":"book","type":"update","data":[{"symbol":"ETH/USD","bids":[{"price":1773.09,"qty":28.19923200}],"asks":[],"checksum":3703430324,"timestamp":"2026-07-07T23:00:13.944624Z"}]}
{"channel":"book","type":"update","data":[{"symbol":"ETH/USD","bids":[{"price":1773.23,"qty":0.45737557},{"price":1773.20,"qty":21.53583080}],"asks":[],"checksum":230784092,"timestamp":"2026-07-07T23:00:13.945010Z"}]}
{"channel":"book","type":"update","data":[{"symbol":"ETH/USD","bids":[{"price":1773.07,"qty":0.02253546}],"asks":[],"checksum":291455467,"timestamp":"2026-07-07T23:00:13.947262Z"}]}
{"channel":"book","type":"update","data":[{"symbol":"ETH/USD","bids":[{"price":1773.33,"qty":0.00000000},{"price":1773.05,"qty":28.19578493}],"asks":[],"checksum":3791543431,"timestamp":"2026-07-07T23:00:13.948239Z"}]}
{"channel":"book","type":"update","data":[{"symbol":"ETH/USD","bids":[{"price":1773.07,"qty":0.00000000},{"price":1773.04,"qty":0.48930000},{"price":1773.10,"qty":0.02253546}],"asks":[],"checksum":2387153210,"timestamp":"2026-07-07T23:00:13.949777Z"}]}
{"channel":"book","type":"update","data":[{"symbol":"ETH/USD","bids":[{"price":1773.29,"qty":2.81960513}],"asks":[],"checksum":817859974,"timestamp":"2026-07-07T23:00:13.949827Z"}]}
{"channel":"book","type":"update","data":[{"symbol":"ETH/USD","bids":[],"asks":[{"price":1773.71,"qty":0.14094909}],"checksum":3969599689,"timestamp":"2026-07-07T23:00:14.002668Z"}]}
{"channel":"book","type":"update","data":[{"symbol":"ETH/USD","bids":[{"price":1773.06,"qty":8.56249785},{"price":1773.21,"qty":5.56003448}],"asks":[],"checksum":1198531282,"timestamp":"2026-07-07T23:00:14.003792Z"}]}
{"channel":"book","type":"update","data":[{"symbol":"BTC/USD","bids":[],"asks":[{"price":63501.6,"qty":2.36299556}],"checksum":155184387,"timestamp":"2026-07-07T23:00:14.022726Z"}]}
{"channel":"book","type":"update","data":[{"symbol":"BTC/USD","bids":[],"asks":[{"price":63500.9,"qty":1.37760615}],"checksum":2545987780,"timestamp":"2026-07-07T23:00:14.025606Z"}]}
{"channel":"book","type":"update","data":[{"symbol":"ETH/USD","bids":[],"asks":[{"price":1773.59,"qty":0.47000000}],"checksum":2585828614,"timestamp":"2026-07-07T23:00:14.193806Z"}]}
{"channel":"heartbeat"}
{"channel":"book","type":"update","data":[{"symbol":"ETH/USD","bids":[{"price":1773.20,"qty":19.84616104},{"price":1773.22,"qty":1.68966976}],"asks":[],"checksum":686710534,"timestamp":"2026-07-07T23:00:14.596632Z"}]}
{"channel":"book","type":"update","data":[{"symbol":"ETH/USD","bids":[{"price":1773.30,"qty":0.05639203}],"asks":[],"checksum":861326820,"timestamp":"2026-07-07T23:00:14.609354Z"}]}
{"channel":"book","type":"update","data":[{"symbol":"ETH/USD","bids":[],"asks":[{"price":1773.49,"qty":0.00000000},{"price":1773.80,"qty":0.14094909}],"checksum":474903699,"timestamp":"2026-07-07T23:00:14.620900Z"}]}
{"channel":"book","type":"update","data":[{"symbol":"ETH/USD","bids":[{"price":1773.29,"qty":0.00000000},{"price":1773.10,"qty":0.02253546}],"asks":[],"checksum":2245284626,"timestamp":"2026-07-07T23:00:14.622375Z"}]}
{"channel":"book","type":"update","data":[{"symbol":"ETH/USD","bids":[],"asks":[{"price":1773.60,"qty":0.00000000},{"price":1773.81,"qty":28.18806908}],"checksum":1890643654,"timestamp":"2026-07-07T23:00:14.622503Z"}]}
{"channel":"book","type":"update","data":[{"symbol":"ETH/USD","bids":[{"price":1773.41,"qty":0.48930000}],"asks":[],"checksum":3775817642,"timestamp":"2026-07-07T23:00:14.624216Z"}]}
{"channel":"book","type":"update","data":[{"symbol":"ETH/USD","bids":[],"asks":[{"price":1773.68,"qty":0.00000000},{"price":1773.83,"qty":20.45240713}],"checksum":2108374977,"timestamp":"2026-07-07T23:00:14.624892Z"}]}
{"channel":"book","type":"update","data":[{"symbol":"ETH/USD","bids":[],"asks":[{"price":1773.81,"qty":0.00000000},{"price":1773.84,"qty":15.93800000}],"checksum":2752133898,"timestamp":"2026-07-07T23:00:14.624986Z"}]}
{"channel":"book","type":"update","data":[{"symbol":"ETH/USD","bids":[{"price":1773.30,"qty":0.00000000},{"price":1773.10,"qty":0.02253546}],"asks":[],"checksum":3723304042,"timestamp":"2026-07-07T23:00:14.627634Z"}]}
{"channel":"book","type":"update","data":[{"symbol":"ETH/USD","bids":[{"price":1773.25,"qty":0.00000000},{"price":1773.09,"qty":28.19923200}],"asks":[],"checksum":2612236063,"timestamp":"2026-07-07T23:00:14.628189Z"}]}
{"channel":"book","type":"update","data":[{"symbol":"ETH/USD","bids":[],"asks":[{"price":1773.74,"qty":2.81890805}],"checksum":2155714459,"timestamp":"2026-07-07T23:00:14.628316Z"}]}
{"channel":"book","type":"update","data":[{"symbol":"ETH/USD","bids":[{"price":1773.23,"qty":0.94667557}],"asks":[],"checksum":1679453466,"timestamp":"2026-07-07T23:00:14.628789Z"}]}
{"channel":"book","type":"update","data":[{"symbol":"ETH/USD","bids":[{"price":1773.25,"qty":0.05639362}],"asks":[],"checksum":2842170664,"timestamp":"2026-07-07T23:00:14.632036Z"}]}
{"channel":"book","type":"update","data":[{"symbol":"ETH/USD","bids":[{"price":1773.32,"qty":2.81956519}],"asks":[],"checksum":4241032337,"timestamp":"2026-07-07T23:00:14.634357Z"}]}
{"channel":"book","type":"update","data":[{"symbol":"BTC/USD","bids":[],"asks":[{"price":63501.6,"qty":0.00000000},{"price":63504.0,"qty":0.00005100}],"checksum":3723412678,"timestamp":"2026-07-07T23:00:14.634646Z"}]}
{"channel":"book","type":"update","data":[{"symbol":"ETH/USD","bids":[{"price":1773.22,"qty":29.88417382}],"asks":[],"checksum":154548198,"timestamp":"2026-07-07T23:00:14.634832Z"}]}
{"channel":"book","type":"update","data":[{"symbol":"ETH/USD","bids":[{"price":1773.32,"qty":0.00000000},{"price":1773.10,"qty":0.02253546}],"asks":[],"checksum":2707146655,"timestamp":"2026-07-07T23:00:14.635139Z"}]}
{"channel":"book","type":"update","data":[{"symbol":"BTC/USD","bids":[{"price":63478.8,"qty":0.05990000}],"asks":[],"checksum":2010725302,"timestamp":"2026-07-07T23:00:14.635474Z"}]}
{"channel":"book","type":"update","data":[{"symbol":"ETH/USD","bids":[{"price":1773.21,"qty":0.00000000},{"price":1773.09,"qty":28.19923200},{"price":1773.25,"qty":5.61642810}],"asks":[],"checksum":1463137926,"timestamp":"2026-07-07T23:00:14.637354Z"}]}
{"channel":"book","type":"update","data":[{"symbol":"BTC/USD","bids":[],"asks":[{"price":63500.9,"qty":0.77079683}],"checksum":1203022655,"timestamp":"2026-07-07T23:00:14.638575Z"}]}
{"channel":"book","type":"update","data":[{"symbol":"ETH/USD","bids":[{"price":1773.09,"qty":0.00000000},{"price":1773.06,"qty":8.56249785}],"asks":[],"checksum":2687774340,"timestamp":"2026-07-07T23:00:14.638584Z"}]}
{"channel":"book","type":"update","data":[{"symbol":"BTC/USD","bids":[{"price":63478.7,"qty":0.00000000},{"price":63477.2,"qty":0.05744528},{"price":63478.9,"qty":0.03147178}],"asks":[],"checksum":1937245664,"timestamp":"2026-07-07T23:00:14.638637Z"}]}
{"channel":"book","type":"update","data":[{"symbol":"ETH/USD","bids":[{"price":1773.06,"qty":0.00000000},{"price":1773.04,"qty":0.48930000}],"asks":[],"checksum":607648178,"timestamp":"2026-07-07T23:00:14.638773Z"}]}
{"channel":"book","type":"update","data":[{"symbol":"ETH/USD","bids":[{"price":1773.33,"qty":0.84164021}],"asks":[],"checksum":2567590684,"timestamp":"2026-07-07T23:00:14.638860Z"}]}
{"channel":"book","type":"update","data":[{"symbol":"ETH/USD","bids":[{"price":1773.33,"qty":0.00000000},{"price":1773.04,"qty":0.48930000}],"asks":[],"checksum":607648178,"timestamp":"2026-07-07T23:00:14.639058Z"}]}
{"channel":"book","type":"update","data":[{"symbol":"ETH/USD","bids":[],"asks":[{"price":1773.74,"qty":0.00000000},{"price":1773.84,"qty":15.93800000}],"checksum":3951691495,"timestamp":"2026-07-07T23:00:14.639392Z"}]}
{"channel":"book","type":"update","data":[{"symbol":"ETH/USD","bids":[{"price":1773.24,"qty":15.49761630}],"asks":[],"checksum":2563804077,"timestamp":"2026-07-07T23:00:14.642011Z"}]}
{"channel":"book","type":"update","data":[{"symbol":"ETH/USD","bids":[{"price":1773.16,"qty":28.19817986}],"asks":[],"checksum":865873441,"timestamp":"2026-07-07T23:00:14.642872Z"}]}
{"channel":"book","type":"update","data":[{"symbol":"ETH/USD","bids":[],"asks":[{"price":1773.72,"qty":1.45758322}],"checksum":3418680360,"timestamp":"2026-07-07T23:00:14.643339Z"}]}
{"channel":"book","type":"update","data":[{"symbol":"ETH/USD","bids":[],"asks":[{"price":1773.72,"qty":0.87392478}],"checksum":865873441,"timestamp":"2026-07-07T23:00:14.643623Z"}]}
{"channel":"book","type":"update","data":[{"symbol":"ETH/USD","bids":[{"price":1773.22,"qty":1.68966976},{"price":1773.11,"qty":28.19332078}],"asks":[],"checksum":681907274,"timestamp":"2026-07-07T23:00:14.645251Z"}]}
{"channel":"book","type":"update","data":[{"symbol":"ETH/USD","bids":[{"price":1773.17,"qty":8.42388352}],"asks":[],"checksum":2470211187,"timestamp":"2026-07-07T23:00:14.645562Z"}]}
{"channel":"book","type":"update","data":[{"symbol":"ETH/USD","bids":[{"price":1773.24,"qty":8.57012626}],"asks":[],"checksum":3953277178,"timestamp":"2026-07-07T23:00:14.652106Z"}]}
{"channel":"book","type":"update","data":[{"symbol":"ETH/USD","bids":[{"price":1773.20,"qty":0.00000000},{"price":1773.11,"qty":28.19332078}],"asks":[],"checksum":1036192572,"timestamp":"2026-07-07T23:00:14.654275Z"}]}
{"channel":"book","type":"update","data":[{"symbol":"ETH/USD","bids":[{"price":1773.26,"qty":2.85150287}],"asks":[],"checksum":2543333125,"timestamp":"2026-07-07T23:00:14.655938Z"}]}
{"channel":"book","type":"update","data":[{"symbol":"ETH/USD","bids":[{"price":1773.24,"qty":1.30000000}],"asks":[],"checksum":3496694077,"timestamp":"2026-07-07T23:00:14.656026Z"}]}
{"channel":"book","type":"update","data":[{"symbol":"ETH/USD","bids":[{"price":1773.25,"qty":0.05639362},{"price":1773.18,"qty":5.56003448}],"asks":[],"checksum":354915067,"timestamp":"2026-07-07T23:00:14.657831Z"}]}
{"channel":"book","type":"update","data":[{"symbol":"ETH/USD","bids":[],"asks":[{"price":1773.83,"qty":4.77600128}],"checksum":1420169137,"timestamp":"2026-07-07T23:00:14.658488Z"}]}
{"channel":"book","type":"update","data":[{"symbol":"ETH/USD","bids":[],"asks":[{"price":1773.83,"qty":13.84253264}],"checksum":2695272380,"timestamp":"2026-07-07T23:00:14.658621Z"}]}
{"channel":"book","type":"update","data":[{"symbol":"ETH/USD","bids":[{"price":1773.17,"qty":15.76261287}],"asks":[],"checksum":310158971,"timestamp":"2026-07-07T23:00:14.660179Z"}]}
{"channel":"book","type":"update","data":[{"symbol":"ETH/USD","bids":[{"price":1773.18,"qty":5.58256994}],"asks":[],"checksum":644759064,"timestamp":"2026-07-07T23:00:14.660368Z"}]}
{"channel":"book","type":"update","data":[{"symbol":"ETH/USD","bids":[],"asks":[{"price":1773.64,"qty":0.00000000},{"price":1773.85,"qty":0.50000000}],"checksum":701187983,"timestamp":"2026-07-07T23:00:14.665531Z"}]}
{"channel":"book","type":"update","data":[{"symbol":"ETH/USD","bids":[],"asks":[{"price":1773.75,"qty":0.31674471}],"checksum":2658507899,"timestamp":"2026-07-07T23:00:14.666774Z"}]}
{"channel":"book","type":"update","data":[{"symbol":"ETH/USD","bids":[],"asks":[{"price":1773.51,"qty":0.00000000},{"price":1773.85,"qty":0.50000000}],"checksum":344334282,"timestamp":"2026-07-07T23:00:14.677473Z"}]}
{"channel":"book","type":"update","data":[{"symbol":"ETH/USD","bids":[],"asks":[{"price":1773.73,"qty":0.00000000},{"price":1773.87,"qty":0.28137208}],"checksum":633489856,"timestamp":"2026-07-07T23:00:14.678042Z"}]}
{"channel":"book","type":"update","data":[{"symbol":"ETH/USD","bids":[],"asks":[{"price":1773.50,"qty":0.00000000},{"price":1773.88,"qty":12.35426731}],"checksum":2473784385,"timestamp":"2026-07-07T23:00:14.680097Z"}]}
{"channel":"book","type":"update","data":[{"symbol":"ETH/USD","bids":[],"asks":[{"price":1773.72,"qty":0.00000000},{"price":1773.89,"qty":1.30000000}],"checksum":241677905,"timestamp":"2026-07-07T23:00:14.680930Z"}]}
{"channel":"book","type":"update","data":[{"symbol":"ETH/USD","bids":[{"price":1773.38,"qty":19.84616104}],"asks":[],"checksum":1840191918,"timestamp":"2026-07-07T23:00:14.681994Z"}]}
{"channel":"book","type":"update","data":[{"symbol":"ETH/USD","bids":[],"asks":[{"price":1773.78,"qty":2.81884640}],"checksum":1991597828,"timestamp":"2026-07-07T23:00:14.682258Z"}]}
{"channel":"book","type":"update","data":[{"symbol":"ETH/USD","bids":[{"price":1773.42,"qty":2.81941108}],"asks":[],"checksum":1801442163,"timestamp":"2026-07-07T23:00:14.682594Z"}]}
{"channel":"book","type":"update","data":[{"symbol":"ETH/USD","bids":[],"asks":[{"price":1773.78,"qty":0.00000000},{"price":1773.89,"qty":1.30000000}],"checksum":1883608537,"timestamp":"2026-07-07T23:00:14.683550Z"}]}
{"channel":"book","type":"update","data":[{"symbol":"ETH/USD","bids":[],"asks":[{"price":1773.77,"qty":0.88349895}],"checksum":2931136034,"timestamp":"2026-07-07T23:00:14.683906Z"}]}
{"channel":"book","type":"update","data":[{"symbol":"ETH/USD","bids":[{"price":1773.39,"qty":5.97844751}],"asks":[],"checksum":2604506009,"timestamp":"2026-07-07T23:00:14.684595Z"}]}
{"channel":"book","type":"update","data":[{"symbol":"ETH/USD","bids":[{"price":1773.42,"qty":3.31941108}],"asks":[],"checksum":200248248,"timestamp":"2026-07-07T23:00:14.685002Z"}]}
{"channel":"book","type":"update","data":[{"symbol":"ETH/USD","bids":[{"price":1773.53,"qty":0.48930000}],"asks":[],"checksum":79277184,"timestamp":"2026-07-07T23:00:14.685139Z"}]}
{"channel":"book","type":"update","data":[{"symbol":"ETH/USD","bids":[{"price":1773.42,"qty":0.50000000}],"asks":[],"checksum":4092598690,"timestamp":"2026-07-07T23:00:14.685941Z"}]}
{"channel":"book","type":"update","data":[{"symbol":"ETH/USD","bids":[],"asks":[{"price":1773.77,"qty":0.00000000},{"price":1773.89,"qty":1.30000000}],"checksum":3094161231,"timestamp":"2026-07-07T23:00:14.686148Z"}]}
{"channel":"book","type":"update","data":[{"symbol":"ETH/USD","bids":[{"price":1773.25,"qty":28.24847161}],"asks":[],"checksum":666265081,"timestamp":"2026-07-07T23:00:14.687850Z"}]}
{"channel":"book","type":"update","data":[{"symbol":"ETH/USD","bids":[{"price":1773.26,"qty":10.90900596}],"asks":[],"checksum":3615595965,"timestamp":"2026-07-07T23:00:14.689912Z"}]}
{"channel":"book","type":"update","data":[{"symbol":"ETH/USD","bids":[{"price":1773.25,"qty":28.19207799}],"asks":[],"checksum":1738049037,"timestamp":"2026-07-07T23:00:14.692679Z"}]}
{"channel":"book","type":"update","data":[{"symbol":"ETH/USD","bids":[],"asks":[{"price":1773.88,"qty":0.00000000},{"price":1773.93,"qty":9.34517172}],"checksum":2504159505,"timestamp":"2026-07-07T23:00:14.693689Z"}]}
{"channel":"book","type":"update","data":[{"symbol":"ETH/USD","bids":[],"asks":[{"price":1773.83,"qty":4.77600128}],"checksum":2141677274,"timestamp":"2026-07-07T23:00:14.695475Z"}]}
{"channel":"book","type":"update","data":[{"symbol":"ETH/USD","bids":[{"price":1773.37,"qty":0.06935921}],"asks":[],"checksum":2551176877,"timestamp":"2026-07-07T23:00:14.696254Z"}]}
{"channel":"book","type":"update","data":[{"symbol":"ETH/USD","bids":[],"asks":[{"price":1773.59,"qty":0.00000000},{"price":1773.94,"qty":28.18586277}],"checksum":1263238340,"timestamp":"2026-07-07T23:00:14.697508Z"}]}
{"channel":"book","type":"update","data":[{"symbol":"ETH/USD","bids":[],"asks":[{"price":1773.82,"qty":6.80441895}],"checksum":2569124545,"timestamp":"2026-07-07T23:00:14.697775Z"}]}
{"channel":"book","type":"update","data":[{"symbol":"ETH/USD","bids":[],"asks":[{"price":1773.93,"qty":0.48930000}],"checksum":3427966155,"timestamp":"2026-07-07T23:00:14.702186Z"}]}
{"channel":"book","type":"update","data":[{"symbol":"ETH/USD","bids":[{"price":1773.38,"qty":20.30353661}],"asks":[],"checksum":597539941,"timestamp":"2026-07-07T23:00:14.702673Z"}]}
{"channel":"book","type":"update","data":[{"symbol":"ETH/USD","bids":[{"price":1773.50,"qty":0.30171526}],"asks":[],"checksum":1053308029,"timestamp":"2026-07-07T23:00:14.726981Z"}]}
{"channel":"book","type":"update","data":[{"symbol":"ETH/USD","bids":[{"price":1773.35,"qty":0.00000000},{"price":1773.24,"qty":1.30000000}],"asks":[],"checksum":573797161,"timestamp":"2026-07-07T23:00:14.728515Z"}]}
{"channel":"book","type":"update","data":[{"symbol":"ETH/USD","bids":[],"asks":[{"price":1773.79,"qty":2.81882665}],"checksum":1786654124,"timestamp":"2026-07-07T23:00:14.735078Z"}]}
{"channel":"book","type":"update","data":[{"symbol":"ETH/USD","bids":[{"price":1773.45,"qty":2.81936046}],"asks":[],"checksum":970101215,"timestamp":"2026-07-07T23:00:14.735370Z"}]}
{"channel":"book","type":"update","data":[{"symbol":"ETH/USD","bids":[],"asks":[{"price":1773.74,"qty":0.47001888}],"checksum":866427144,"timestamp":"2026-07-07T23:00:14.758607Z"}]}
{"channel":"book","type":"update","data":[{"symbol":"ETH/USD","bids":[{"price":1773.53,"qty":0.00000000},{"price":1773.24,"qty":1.30000000}],"asks":[],"checksum":3509395764,"timestamp":"2026-07-07T23:00:14.769400Z"}]}
{"channel":"book","type":"update","data":[{"symbol":"ETH/USD","bids":[],"asks":[{"price":1773.79,"qty":0.00000000},{"price":1773.89,"qty":1.30000000}],"checksum":3901040537,"timestamp":"2026-07-07T23:00:14.771251Z"}]}
{"channel":"book","type":"update","data":[{"symbol":"ETH/USD","bids":[{"price":1773.53,"qty":0.48930000}],"asks":[],"checksum":2551303915,"timestamp":"2026-07-07T23:00:14.771451Z"}]}
{"channel":"book","type":"update","data":[{"symbol":"ETH/USD","bids":[{"price":1773.41,"qty":0.00000000},{"price":1773.24,"qty":1.30000000}],"asks":[],"checksum":3947693756,"timestamp":"2026-07-07T23:00:14.772680Z"}]}
{"channel":"book","type":"update","data":[{"symbol":"ETH/USD","bids":[],"asks":[{"price":1773.81,"qty":2.29747210}],"checksum":253653928,"timestamp":"2026-07-07T23:00:14.778187Z"}]}
{"channel":"book","type":"update","data":[{"symbol":"ETH/USD","bids":[],"asks":[{"price":1773.70,"qty":1.53128753}],"checksum":1175148516,"timestamp":"2026-07-07T23:00:14.778893Z"}]}
{"channel":"book","type":"update","data":[{"symbol":"ETH/USD","bids":[],"asks":[{"price":1773.69,"qty":0.47001888}],"checksum":1455793874,"timestamp":"2026-07-07T23:00:14.785596Z"}]}
{"channel":"book","type":"update","data":[{"symbol":"ETH/USD","bids":[],"asks":[{"price":1773.79,"qty":2.29747210}],"checksum":2009745375,"timestamp":"2026-07-07T23:00:14.787281Z"}]}
{"channel":"book","type":"update","data":[{"symbol":"ETH/USD","bids":[],"asks":[{"price":1773.79,"qty":0.00000000},{"price":1773.84,"qty":15.93800000}],"checksum":1455793874,"timestamp":"2026-07-07T23:00:14.787558Z"}]}
{"channel":"book","type":"update","data":[{"symbol":"ETH/USD","bids":[],"asks":[{"price":1773.73,"qty":0.41000000}],"checksum":3042657868,"timestamp":"2026-07-07T23:00:14.823854Z"}]}
{"channel":"book","type":"update","data":[{"symbol":"ETH/USD","bids":[{"price":1773.53,"qty":0.00000000},{"price":1773.23,"qty":2.17896976}],"asks":[],"checksum":1562037293,"timestamp":"2026-07-07T23:00:14.877474Z"}]}
{"channel":"book","type":"update","data":[{"symbol":"ETH/USD","bids":[],"asks":[{"price":1773.76,"qty":2.81887351}],"checksum":3725951547,"timestamp":"2026-07-07T23:00:14.879023Z"}]}
{"channel":"book","type":"update","data":[{"symbol":"ETH/USD","bids":[],"asks":[{"price":1773.74,"qty":0.00000000},{"price":1773.83,"qty":4.77600128}],"checksum":2067991694,"timestamp":"2026-07-07T23:00:14.886626Z"}]}
{"channel":"book","type":"update","data":[{"symbol":"ETH/USD","bids":[],"asks":[{"price":1773.81,"qty":0.00000000},{"price":1773.84,"qty":15.57800000}],"checksum":270005735,"timestamp":"2026-07-07T23:00:14.888339Z"}]}
{"channel":"book","type":"update","data":[{"symbol":"ETH/USD","bids":[],"asks":[{"price":1773.68,"qty":0.29000197}],"checksum":1465742870,"timestamp":"2026-07-07T23:00:14.929835Z"}]}
{"channel":"book","type":"update","data":[{"symbol":"ETH/USD","bids":[{"price":1773.23,"qty":30.37595320}],"asks":[],"checksum":1455600546,"timestamp":"2026-07-07T23:00:15.058202Z"}]}
{"channel":"book","type":"update","data":[{"symbol":"ETH/USD","bids":[{"price":1773.40,"qty":5.56003448}],"asks":[],"checksum":4205201164,"timestamp":"2026-07-07T23:00:15.059428Z"}]}
{"channel":"book","type":"update","data":[{"symbol":"ETH/USD","bids":[{"price":1773.26,"qty":8.05750309}],"asks":[],"checksum":3417811251,"timestamp":"2026-07-07T23:00:15.060725Z"}]}
{"channel":"book","type":"update","data":[{"symbol":"ETH/USD","bids":[{"price":1773.26,"qty":0.00000000},{"price":1773.23,"qty":30.37595320}],"asks":[],"checksum":219128839,"timestamp":"2026-07-07T23:00:15.060772Z"}]}
{"channel":"book","type":"update","data":[{"symbol":"ETH/USD","bids":[{"price":1773.26,"qty":16.65649494}],"asks":[],"checksum":2611622904,"timestamp":"2026-07-07T23:00:15.061803Z"}]}
{"channel":"book","type":"update","data":[{"symbol":"ETH/USD","bids":[],"asks":[{"price":1773.75,"qty":1.20025176}],"checksum":3041581700,"timestamp":"2026-07-07T23:00:15.062757Z"}]}
{"channel":"book","type":"update","data":[{"symbol":"ETH/USD","bids":[{"price":1773.50,"qty":0.79101526}],"asks":[],"checksum":2315968935,"timestamp":"2026-07-07T23:00:15.114361Z"}]}
{"channel":"book","type":"update","data":[{"symbol":"ETH/USD","bids":[{"price":1773.51,"qty":0.48930000}],"asks":[],"checksum":3069478534,"timestamp":"2026-07-07T23:00:15.119248Z"}]}
{"channel":"book","type":"update","data":[{"symbol":"ETH/USD","bids":[],"asks":[{"price":1773.68,"qty":0.00000000},{"price":1773.84,"qty":15.57800000}],"checksum":163273233,"timestamp":"2026-07-07T23:00:15.259776Z"}]}
{"channel":"book","type":"update","data":[{"symbol":"ETH/USD","bids":[],"asks":[{"price":1773.68,"qty":1.53128753}],"checksum":2427458436,"timestamp":"2026-07-07T23:00:15.262654Z"}]}
{"channel":"book","type":"update","data":[{"symbol":"ETH/USD","bids":[],"asks":[{"price":1773.67,"qty":0.47001888}],"checksum":2055574383,"timestamp":"2026-07-07T23:00:15.264151Z"}]}
{"channel":"book","type":"update","data":[{"symbol":"ETH/USD","bids":[],"asks":[{"price":1773.68,"qty":0.00000000},{"price":1773.83,"qty":4.77600128}],"checksum":2313301393,"timestamp":"2026-07-07T23:00:15.265311Z"}]}
{"channel":"book","type":"update","data":[{"symbol":"ETH/USD","bids":[],"asks":[{"price":1773.67,"qty":0.00000000},{"price":1773.84,"qty":15.57800000}],"checksum":163273233,"timestamp":"2026-07-07T23:00:15.266423Z"}]}
{"channel":"book","type":"update","data":[{"symbol":"ETH/USD","bids":[],"asks":[{"price":1773.70,"qty":0.00000000},{"price":1773.85,"qty":0.50000000}],"checksum":3232080926,"timestamp":"2026-07-07T23:00:15.266555Z"}]}
{"channel":"book","type":"update","data":[{"symbol":"ETH/USD","bids":[{"price":1773.45,"qty":0.00000000},{"price":1773.24,"qty":1.30000000}],"asks":[],"checksum":870664063,"timestamp":"2026-07-07T23:00:15.267189Z"}]}
{"channel":"book","type":"update","data":[{"symbol":"ETH/USD","bids":[],"asks":[{"price":1773.76,"qty":0.00000000},{"price":1773.87,"qty":0.28137208}],"checksum":275955415,"timestamp":"2026-07-07T23:00:15.267213Z"}]}
{"channel":"book","type":"update","data":[{"symbol":"ETH/USD","bids":[],"asks":[{"price":1773.75,"qty":0.31674471}],"checksum":4088107713,"timestamp":"2026-07-07T23:00:15.268743Z"}]}
{"channel":"book","type":"update","data":[{"symbol":"ETH/USD","bids":[],"asks":[{"price":1773.80,"qty":2.95976272}],"checksum":3931682383,"timestamp":"2026-07-07T23:00:15.268822Z"}]}
{"channel":"book","type":"update","data":[{"symbol":"ETH/USD","bids":[{"price":1773.48,"qty":2.81930134}],"asks":[],"checksum":613099047,"timestamp":"2026-07-07T23:00:15.269230Z"}]}
{"channel":"book","type":"update","data":[{"symbol":"ETH/USD","bids":[],"asks":[{"price":1773.79,"qty":0.88348917}],"checksum":1869451604,"timestamp":"2026-07-07T23:00:15.270380Z"}]}
{"channel":"book","type":"update","data":[{"symbol":"ETH/USD","bids":[{"price":1773.50,"qty":0.30171526}],"asks":[],"checksum":3765179020,"timestamp":"2026-07-07T23:00:15.272410Z"}]}
{"channel":"book","type":"update","data":[{"symbol":"ETH/USD","bids":[{"price":1773.51,"qty":0.60207072}],"asks":[],"checksum":4206611685,"timestamp":"2026-07-07T23:00:15.275316Z"}]}
{"channel":"book","type":"update","data":[{"symbol":"ETH/USD","bids":[{"price":1773.59,"qty":0.48930000}],"asks":[],"checksum":3496243700,"timestamp":"2026-07-07T23:00:15.276807Z"}]}
{"channel":"book","type":"update","data":[{"symbol":"ETH/USD","bids":[{"price":1773.51,"qty":0.11277072}],"asks":[],"checksum":2393129486,"timestamp":"2026-07-07T23:00:15.277499Z"}]}
{"channel":"book","type":"update","data":[{"symbol":"ETH/USD","bids":[{"price":1773.41,"qty":0.48930000}],"asks":[],"checksum":2493829710,"timestamp":"2026-07-07T23:00:15.279635Z"}]}
{"channel":"book","type":"update","data":[{"symbol":"ETH/USD","bids":[{"price":1773.59,"qty":0.00000000},{"price":1773.26,"qty":16.65649494}],"asks":[],"checksum":2824868525,"timestamp":"2026-07-07T23:00:15.287043Z"}]}
{"channel":"book","type":"update","data":[{"symbol":"ETH/USD","bids":[],"asks":[{"price":1773.68,"qty":1.53128753}],"checksum":612260806,"timestamp":"2026-07-07T23:00:15.348460Z"}]}
{"channel":"book","type":"update","data":[{"symbol":"ETH/USD","bids":[],"asks":[{"price":1773.67,"qty":0.47001888}],"checksum":1731150181,"timestamp":"2026-07-07T23:00:15.349705Z"}]}
{"channel":"book","type":"update","data":[{"symbol":"ETH/USD","bids":[],"asks":[{"price":1773.66,"qty":1.53128753}],"checksum":2659077984,"timestamp":"2026-07-07T23:00:15.351425Z"}]}
{"channel":"book","type":"update","data":[{"symbol":"BTC/USD","bids":[{"price":63478.6,"qty":0.78782716}],"asks":[],"checksum":433197909,"timestamp":"2026-07-07T23:00:15.351666Z"}]}
{"channel":"book","type":"update","data":[{"symbol":"ETH/USD","bids":[],"asks":[{"price":1773.69,"qty":0.00000000},{"price":1773.83,"qty":4.77600128}],"checksum":873937201,"timestamp":"2026-07-07T23:00:15.365247Z"}]}
{"channel":"book","type":"update","data":[{"symbol":"ETH/USD","bids":[{"price":1773.27,"qty":1.68966976}],"asks":[],"checksum":2939087802,"timestamp":"2026-07-07T23:00:15.366611Z"}]}
{"channel":"book","type":"update","data":[{"symbol":"ETH/USD","bids":[],"asks":[{"price":1773.65,"qty":0.47001888}],"checksum":2703631698,"timestamp":"2026-07-07T23:00:15.366727Z"}]}
{"channel":"book","type":"update","data":[{"symbol":"ETH/USD","bids":[],"asks":[{"price":1773.73,"qty":0.70996590}],"checksum":931605980,"timestamp":"2026-07-07T23:00:15.368504Z"}]}
{"channel":"book","type":"update","data":[{"symbol":"BTC/USD","bids":[{"price":63478.6,"qty":0.00016057}],"asks":[],"checksum":1937245664,"timestamp":"2026-07-07T23:00:15.369559Z"}]}
{"channel":"book","type":"update","data":[{"symbol":"ETH/USD","bids":[],"asks":[{"price":1773.80,"qty":0.14094909}],"checksum":1924847677,"timestamp":"2026-07-07T23:00:15.370871Z"}]}
{"channel":"book","type":"update","data":[{"symbol":"ETH/USD","bids":[{"price":1773.48,"qty":0.00000000},{"price":1773.26,"qty":16.65649494}],"asks":[],"checksum":3422048762,"timestamp":"2026-07-07T23:00:15.372005Z"}]}
{"channel":"book","type":"update","data":[{"symbol":"ETH/USD","bids":[{"price":1773.40,"qty":0.00000000},{"price":1773.25,"qty":28.19207799}],"asks":[],"checksum":1927142998,"timestamp":"2026-07-07T23:00:15.372471Z"}]}
{"channel":"book","type":"update","data":[{"symbol":"ETH/USD","bids":[],"asks":[{"price":1773.79,"qty":0.00000000},{"price":1773.83,"qty":4.77600128}],"checksum":1977448052,"timestamp":"2026-07-07T23:00:15.373052Z"}]}
{"channel":"book","type":"update","data":[{"symbol":"ETH/USD","bids":[{"price":1773.26,"qty":0.00000000},{"price":1773.24,"qty":1.30000000}],"asks":[],"checksum":3867450414,"timestamp":"2026-07-07T23:00:15.373166Z"}]}
{"channel":"book","type":"update","data":[{"symbol":"ETH/USD","bids":[{"price":1773.51,"qty":2.93202465}],"asks":[],"checksum":2543541916,"timestamp":"2026-07-07T23:00:15.374375Z"}]}
{"channel":"book","type":"update","data":[{"symbol":"ETH/USD","bids":[{"price":1773.31,"qty":28.19575795}],"asks":[],"checksum":702805094,"timestamp":"2026-07-07T23:00:15.374452Z"}]}
{"channel":"book","type":"update","data":[{"symbol":"ETH/USD","bids":[{"price":1773.26,"qty":8.94944133}],"asks":[],"checksum":1439343261,"timestamp":"2026-07-07T23:00:15.374764Z"}]}
{"channel":"book","type":"update","data":[{"symbol":"ETH/USD","bids":[{"price":1773.27,"qty":0.00000000},{"price":1773.25,"qty":28.19207799},{"price":1773.26,"qty":10.63911109}],"asks":[],"checksum":2881258434,"timestamp":"2026-07-07T23:00:15.375235Z"}]}
{"channel":"book","type":"update","data":[{"symbol":"ETH/USD","bids":[{"price":1773.32,"qty":8.92080017}],"asks":[],"checksum":3483125267,"timestamp":"2026-07-07T23:00:15.378071Z"}]}
{"channel":"book","type":"update","data":[{"symbol":"ETH/USD","bids":[{"price":1773.55,"qty":0.48930000}],"asks":[],"checksum":3404437025,"timestamp":"2026-07-07T23:00:15.430693Z"}]}
{"channel":"book","type":"update","data":[{"symbol":"ETH/USD","bids":[{"price":1773.41,"qty":0.00000000},{"price":1773.26,"qty":10.63911109}],"asks":[],"checksum":1024407039,"timestamp":"2026-07-07T23:00:15.431252Z"}]}
{"channel":"book","type":"update","data":[{"symbol":"ETH/USD","bids":[{"price":1773.40,"qty":5.56003448}],"asks":[],"checksum":250929935,"timestamp":"2026-07-07T23:00:15.431859Z"}]}
{"channel":"book","type":"update","data":[{"symbol":"ETH/USD","bids":[],"asks":[{"price":1773.68,"qty":0.00000000},{"price":1773.84,"qty":18.39674461}],"checksum":3218379993,"timestamp":"2026-07-07T23:00:15.453125Z"}]}
{"channel":"book","type":"update","data":[{"symbol":"ETH/USD","bids":[],"asks":[{"price":1773.64,"qty":1.53128753}],"checksum":1694942884,"timestamp":"2026-07-07T23:00:15.454581Z"}]}
{"channel":"book","type":"update","data":[{"symbol":"ETH/USD","bids":[],"asks":[{"price":1773.67,"qty":0.00000000},{"price":1773.84,"qty":18.39674461}],"checksum":2419603830,"timestamp":"2026-07-07T23:00:15.467840Z"}]}
{"channel":"book","type":"update","data":[{"symbol":"ETH/USD","bids":[],"asks":[{"price":1773.63,"qty":0.47001888}],"checksum":4036713927,"timestamp":"2026-07-07T23:00:15.469699Z"}]}
{"channel":"book","type":"update","data":[{"symbol":"ETH/USD","bids":[],"asks":[{"price":1773.62,"qty":1.53128753}],"checksum":1214707741,"timestamp":"2026-07-07T23:00:15.471245Z"}]}
{"channel":"book","type":"update","data":[{"symbol":"ETH/USD","bids":[],"asks":[{"price":1773.64,"qty":0.00000000},{"price":1773.83,"qty":4.77600128}],"checksum":780327875,"timestamp":"2026-07-07T23:00:15.472221Z"}]}
{"channel":"book","type":"update","data":[{"symbol":"ETH/USD","bids":[{"price":1773.55,"qty":0.82737915}],"asks":[],"checksum":690578734,"timestamp":"2026-07-07T23:00:15.530543Z"}]}
{"channel":"book","type":"update","data":[{"symbol":"ETH/USD","bids":[{"price":1773.33,"qty":1.68966976}],"asks":[],"checksum":1360986409,"timestamp":"2026-07-07T23:00:15.531794Z"}]}
{"channel":"book","type":"update","data":[{"symbol":"ETH/USD","bids":[{"price":1773.50,"qty":0.00000000},{"price":1773.31,"qty":28.19575795}],"asks":[],"checksum":539260978,"timestamp":"2026-07-07T23:00:15.531849Z"}]}
{"channel":"book","type":"update","data":[{"symbol":"ETH/USD","bids":[],"asks":[{"price":1773.80,"qty":0.00000000},{"price":1773.84,"qty":18.39674461}],"checksum":2818468790,"timestamp":"2026-07-07T23:00:15.538663Z"}]}
{"channel":"book","type":"update","data":[{"symbol":"ETH/USD","bids":[],"asks":[{"price":1773.66,"qty":0.00000000},{"price":1773.85,"qty":0.50000000}],"checksum":3712053708,"timestamp":"2026-07-07T23:00:15.555771Z"}]}
{"channel":"heartbeat"}
{"channel":"book","type":"update","data":[{"symbol":"ETH/USD","bids":[],"asks":[{"price":1773.65,"qty":0.00000000},{"price":1773.87,"qty":0.28137208}],"checksum":19267854,"timestamp":"2026-07-07T23:00:15.570919Z"}]}
{"channel":"book","type":"update","data":[{"symbol":"ETH/USD","bids":[],"asks":[{"price":1773.61,"qty":0.47001888}],"checksum":3013452510,"timestamp":"2026-07-07T23:00:15.572336Z"}]}
{"channel":"book","type":"update","data":[{"symbol":"ETH/USD","bids":[],"asks":[{"price":1773.60,"qty":1.53128753}],"checksum":1327023458,"timestamp":"2026-07-07T23:00:15.573686Z"}]}
{"channel":"book","type":"update","data":[{"symbol":"ETH/USD","bids":[{"price":1773.55,"qty":0.33807915}],"asks":[],"checksum":2509561327,"timestamp":"2026-07-07T23:00:15.591527Z"}]}
{"channel":"book","type":"update","data":[{"symbol":"ETH/USD","bids":[],"asks":[{"price":1773.62,"qty":1.67223662}],"checksum":4264564166,"timestamp":"2026-07-07T23:00:15.594059Z"}]}
{"channel":"book","type":"update","data":[{"symbol":"ETH/USD","bids":[],"asks":[{"price":1773.63,"qty":0.00000000},{"price":1773.85,"qty":0.50000000}],"checksum":704680662,"timestamp":"2026-07-07T23:00:15.673313Z"}]}
{"channel":"book","type":"update","data":[{"symbol":"ETH/USD","bids":[],"asks":[{"price":1773.59,"qty":0.47001888}],"checksum":1424522550,"timestamp":"2026-07-07T23:00:15.674481Z"}]}
{"channel":"book","type":"update","data":[{"symbol":"ETH/USD","bids":[],"asks":[{"price":1773.62,"qty":0.14094909}],"checksum":2616071268,"timestamp":"2026-07-07T23:00:15.674633Z"}]}
{"channel":"book","type":"update","data":[{"symbol":"ETH/USD","bids":[],"asks":[{"price":1773.61,"qty":0.00000000},{"price":1773.85,"qty":0.50000000}],"checksum":1023057211,"timestamp":"2026-07-07T23:00:15.775441Z"}]}
{"channel":"book","type":"update","data":[{"symbol":"ETH/USD","bids":[],"asks":[{"price":1773.68,"qty":0.28103042}],"checksum":242086041,"timestamp":"2026-07-07T23:00:15.867217Z"}]}
{"channel":"book","type":"update","data":[{"symbol":"ETH/USD","bids":[],"asks":[{"price":1773.73,"qty":0.41000000}],"checksum":984534094,"timestamp":"2026-07-07T23:00:15.868262Z"}]}
{"channel":"book","type":"update","data":[{"symbol":"ETH/USD","bids":[],"asks":[{"price":1773.84,"qty":15.57800000}],"checksum":923258249,"timestamp":"2026-07-07T23:00:15.887301Z"}]}
{"channel":"book","type":"update","data":[{"symbol":"ETH/USD","bids":[],"asks":[{"price":1773.78,"qty":2.81885246}],"checksum":2822127387,"timestamp":"2026-07-07T23:00:15.889265Z"}]}
{"channel":"book","type":"update","data":[{"symbol":"ETH/USD","bids":[{"price":1773.55,"qty":0.00000000},{"price":1773.26,"qty":8.94944133}],"asks":[],"checksum":2106054454,"timestamp":"2026-07-07T23:00:15.908501Z"}]}
{"channel":"book","type":"update","data":[{"symbol":"BTC/USD","bids":[{"price":63478.8,"qty":0.84756443}],"asks":[],"checksum":3420265942,"timestamp":"2026-07-07T23:00:15.966557Z"}]}
{"channel":"book","type":"update","data":[{"symbol":"BTC/USD","bids":[{"price":63478.8,"qty":0.05990000}],"asks":[],"checksum":1937245664,"timestamp":"2026-07-07T23:00:15.969392Z"}]}
{"channel":"book","type":"update","data":[{"symbol":"BTC/USD","bids":[{"price":63479.0,"qty":0.02732241}],"asks":[],"checksum":4217326086,"timestamp":"2026-07-07T23:00:15.981125Z"}]}
{"channel":"book","type":"update","data":[{"symbol":"BTC/USD","bids":[{"price":63478.9,"qty":0.00000000},{"price":63478.6,"qty":0.00016057},{"price":63479.0,"qty":0.05879419}],"asks":[],"checksum":1300339571,"timestamp":"2026-07-07T23:00:15.982290Z"}]}
{"channel":"book","type":"update","data":[{"symbol":"BTC/USD","bids":[{"price":63479.0,"qty":0.03147178}],"asks":[],"checksum":1464116461,"timestamp":"2026-07-07T23:00:15.983554Z"}]}
{"channel":"book","type":"update","data":[{"symbol":"BTC/USD","bids":[{"price":63479.0,"qty":0.00000000},{"price":63477.5,"qty":0.78767991},{"price":63478.9,"qty":0.03147178}],"asks":[],"checksum":1937245664,"timestamp":"2026-07-07T23:00:15.985035Z"}]}
{"channel":"book","type":"update","data":[{"symbol":"BTC/USD","bids":[{"price":63479.1,"qty":0.02732241}],"asks":[],"checksum":3755809584,"timestamp":"2026-07-07T23:00:15.985300Z"}]}
{"channel":"book","type":"update","data":[{"symbol":"ETH/USD","bids":[{"price":1773.51,"qty":0.11277072}],"asks":[],"checksum":2161547148,"timestamp":"2026-07-07T23:00:15.996055Z"}]}
{"channel":"book","type":"update","data":[{"symbol":"ETH/USD","bids":[{"price":1773.47,"qty":2.81932142}],"asks":[],"checksum":3983667715,"timestamp":"2026-07-07T23:00:15.997320Z"}]}
{"channel":"book","type":"update","data":[{"symbol":"BTC/USD","bids":[{"price":63479.1,"qty":0.00000000},{"price":63478.6,"qty":0.00016057}],"asks":[],"checksum":1937245664,"timestamp":"2026-07-07T23:00:16.023084Z"}]}
{"channel":"book","type":"update","data":[{"symbol":"ETH/USD","bids":[{"price":1773.43,"qty":0.30260817}],"asks":[],"checksum":3421639545,"timestamp":"2026-07-07T23:00:16.033157Z"}]}
{"channel":"book","type":"update","data":[{"symbol":"ETH/USD","bids":[{"price":1773.47,"qty":0.00000000},{"price":1773.26,"qty":8.94944133}],"asks":[],"checksum":2737239222,"timestamp":"2026-07-07T23:00:16.139644Z"}]}
{"channel":"book","type":"update","data":[{"symbol":"ETH/USD","bids":[{"price":1773.32,"qty":0.00000000},{"price":1773.25,"qty":28.19207799}],"asks":[],"checksum":1523087061,"timestamp":"2026-07-07T23:00:16.140752Z"}]}
{"channel":"book","type":"update","data":[{"symbol":"ETH/USD","bids":[{"price":1773.40,"qty":0.00000000},{"price":1773.24,"qty":1.30000000}],"asks":[],"checksum":4086740740,"timestamp":"2026-07-07T23:00:16.140826Z"}]}
{"channel":"book","type":"update","data":[{"symbol":"ETH/USD","bids":[{"price":1773.33,"qty":0.00000000},{"price":1773.23,"qty":0.48930000},{"price":1773.27,"qty":1.68966976}],"asks":[],"checksum":2640849468,"timestamp":"2026-07-07T23:00:16.142213Z"}]}
{"channel":"book","type":"update","data":[{"symbol":"ETH/USD","bids":[{"price":1773.43,"qty":3.12199562}],"asks":[],"checksum":1377761733,"timestamp":"2026-07-07T23:00:16.142264Z"}]}
{"channel":"book","type":"update","data":[{"symbol":"ETH/USD","bids":[{"price":1773.26,"qty":16.22210522}],"asks":[],"checksum":2199115144,"timestamp":"2026-07-07T23:00:16.143848Z"}]}
{"channel":"book","type":"update","data":[{"symbol":"ETH/USD","bids":[],"asks":[{"price":1773.78,"qty":0.00000000},{"price":1773.84,"qty":15.57800000}],"checksum":2643269138,"timestamp":"2026-07-07T23:00:16.162117Z"}]}
{"channel":"book","type":"update","data":[{"symbol":"ETH/USD","bids":[],"asks":[{"price":1773.75,"qty":3.13563813}],"checksum":1315929832,"timestamp":"2026-07-07T23:00:16.163527Z"}]}
{"channel":"book","type":"update","data":[{"symbol":"BTC/USD","bids":[{"price":63479.1,"qty":0.78766035}],"asks":[],"checksum":170857205,"timestamp":"2026-07-07T23:00:16.300761Z"}]}
{"channel":"book","type":"update","data":[{"symbol":"ETH/USD","bids":[],"asks":[{"price":1773.62,"qty":0.42351680}],"checksum":3118968375,"timestamp":"2026-07-07T23:00:16.514210Z"}]}
{"channel":"book","type":"update","data":[{"symbol":"ETH/USD","bids":[],"asks":[{"price":1773.68,"qty":0.00000000},{"price":1773.85,"qty":0.50000000}],"checksum":3651652643,"timestamp":"2026-07-07T23:00:16.516030Z"}]}
{"channel":"heartbeat"}
{"channel":"book","type":"update","data":[{"symbol":"ETH/USD","bids":[],"asks":[{"price":1773.73,"qty":0.00000000},{"price":1773.87,"qty":0.28137208}],"checksum":405387147,"timestamp":"2026-07-07T23:00:16.619034Z"}]}
{"channel":"book","type":"update","data":[{"symbol":"ETH/USD","bids":[],"asks":[{"price":1773.75,"qty":0.31674471}],"checksum":322292275,"timestamp":"2026-07-07T23:00:16.700052Z"}]}
{"channel":"book","type":"update","data":[{"symbol":"ETH/USD","bids":[],"asks":[{"price":1773.72,"qty":2.81894252}],"checksum":1574235176,"timestamp":"2026-07-07T23:00:16.701917Z"}]}
{"channel":"book","type":"update","data":[{"symbol":"ETH/USD","bids":[{"price":1773.40,"qty":0.05638885}],"asks":[],"checksum":1967012464,"timestamp":"2026-07-07T23:00:17.013875Z"}]}
{"channel":"book","type":"update","data":[{"symbol":"ETH/USD","bids":[],"asks":[{"price":1773.75,"qty":0.00000000},{"price":1773.87,"qty":0.28137208}],"checksum":732214310,"timestamp":"2026-07-07T23:00:17.166944Z"}]}
{"channel":"book","type":"update","data":[{"symbol":"ETH/USD","bids":[],"asks":[{"price":1773.82,"qty":0.00000000},{"price":1773.89,"qty":1.30000000}],"checksum":3459841479,"timestamp":"2026-07-07T23:00:17.166958Z"}]}
{"channel":"book","type":"update","data":[{"symbol":"ETH/USD","bids":[],"asks":[{"price":1773.84,"qty":0.50000000}],"checksum":1672201680,"timestamp":"2026-07-07T23:00:17.168360Z"}]}
{"channel":"book","type":"update","data":[{"symbol":"ETH/USD","bids":[{"price":1773.55,"qty":0.48930000}],"asks":[],"checksum":2835113854,"timestamp":"2026-07-07T23:00:17.171565Z"}]}
{"channel":"book","type":"update","data":[{"symbol":"ETH/USD","bids":[],"asks":[{"price":1773.62,"qty":0.14094909}],"checksum":1036688348,"timestamp":"2026-07-07T23:00:17.174941Z"}]}
{"channel":"book","type":"update","data":[{"symbol":"ETH/USD","bids":[],"asks":[{"price":1773.72,"qty":0.00000000},{"price":1773.93,"qty":0.48930000}],"checksum":969402764,"timestamp":"2026-07-07T23:00:17.176856Z"}]}
{"channel":"book","type":"update","data":[{"symbol":"ETH/USD","bids":[],"asks":[{"price":1773.60,"qty":0.00000000},{"price":1773.97,"qty":13.83631649}],"checksum":2642056164,"timestamp":"2026-07-07T23:00:17.177157Z"}]}
{"channel":"book","type":"update","data":[{"symbol":"ETH/USD","bids":[{"price":1773.38,"qty":0.45737557}],"asks":[],"checksum":450956377,"timestamp":"2026-07-07T23:00:17.178017Z"}]}
{"channel":"book","type":"update","data":[{"symbol":"ETH/USD","bids":[],"asks":[{"price":1773.59,"qty":0.00000000},{"price":1773.98,"qty":48.43877900}],"checksum":3979904246,"timestamp":"2026-07-07T23:00:17.180517Z"}]}
{"channel":"book","type":"update","data":[{"symbol":"ETH/USD","bids":[{"price":1773.27,"qty":0.00000000},{"price":1773.25,"qty":28.19207799},{"price":1773.42,"qty":2.18966976}],"asks":[],"checksum":752258839,"timestamp":"2026-07-07T23:00:17.180851Z"}]}
{"channel":"book","type":"update","data":[{"symbol":"ETH/USD","bids":[],"asks":[{"price":1773.98,"qty":46.14130690}],"checksum":139554857,"timestamp":"2026-07-07T23:00:17.180935Z"}]}
{"channel":"book","type":"update","data":[{"symbol":"ETH/USD","bids":[],"asks":[{"price":1773.84,"qty":0.00000000},{"price":1773.99,"qty":0.32561079}],"checksum":3315589026,"timestamp":"2026-07-07T23:00:17.182028Z"}]}
{"channel":"book","type":"update","data":[{"symbol":"ETH/USD","bids":[],"asks":[{"price":1773.93,"qty":0.00000000},{"price":1774.04,"qty":0.95885108}],"checksum":3173952878,"timestamp":"2026-07-07T23:00:17.182095Z"}]}
{"channel":"book","type":"update","data":[{"symbol":"ETH/USD","bids":[{"price":1773.40,"qty":5.61642333}],"asks":[],"checksum":2408938449,"timestamp":"2026-07-07T23:00:17.182317Z"}]}
{"channel":"book","type":"update","data":[{"symbol":"ETH/USD","bids":[],"asks":[{"price":1773.98,"qty":17.95600000}],"checksum":1836328504,"timestamp":"2026-07-07T23:00:17.182503Z"}]}
{"channel":"book","type":"update","data":[{"symbol":"ETH/USD","bids":[],"asks":[{"price":1773.89,"qty":0.00000000},{"price":1774.06,"qty":0.33820726}],"checksum":1506308896,"timestamp":"2026-07-07T23:00:17.183285Z"}]}
{"channel":"book","type":"update","data":[{"symbol":"ETH/USD","bids":[],"asks":[{"price":1774.06,"qty":0.16910363}],"checksum":897511245,"timestamp":"2026-07-07T23:00:17.183682Z"}]}
{"channel":"book","type":"update","data":[{"symbol":"ETH/USD","bids":[],"asks":[{"price":1773.85,"qty":0.00000000},{"price":1774.08,"qty":6.67540478}],"checksum":549273368,"timestamp":"2026-07-07T23:00:17.184004Z"}]}
{"channel":"book","type":"update","data":[{"symbol":"ETH/USD","bids":[],"asks":[{"price":1773.83,"qty":0.00000000},{"price":1774.11,"qty":0.98930000}],"checksum":2328702192,"timestamp":"2026-07-07T23:00:17.184370Z"}]}
{"channel":"book","type":"update","data":[{"symbol":"BTC/USD","bids":[{"price":63479.1,"qty":0.00000000},{"price":63478.6,"qty":0.02952384}],"asks":[],"checksum":3412498935,"timestamp":"2026-07-07T23:00:17.184518Z"}]}
{"channel":"book","type":"update","data":[{"symbol":"ETH/USD","bids":[{"price":1773.43,"qty":0.30260817}],"asks":[],"checksum":3343130440,"timestamp":"2026-07-07T23:00:17.184786Z"}]}
{"channel":"book","type":"update","data":[{"symbol":"ETH/USD","bids":[{"price":1773.25,"qty":0.00000000},{"price":1773.24,"qty":1.30000000}],"asks":[],"checksum":3750950451,"timestamp":"2026-07-07T23:00:17.185085Z"}]}
{"channel":"book","type":"update","data":[{"symbol":"BTC/USD","bids":[{"price":63485.2,"qty":0.05990000}],"asks":[],"checksum":1364107091,"timestamp":"2026-07-07T23:00:17.185115Z"}]}
{"channel":"book","type":"update","data":[{"symbol":"BTC/USD","bids":[{"price":63482.4,"qty":0.60470924}],"asks":[],"checksum":3586112808,"timestamp":"2026-07-07T23:00:17.185430Z"}]}
{"channel":"book","type":"update","data":[{"symbol":"ETH/USD","bids":[{"price":1773.61,"qty":19.84616104}],"asks":[],"checksum":52583700,"timestamp":"2026-07-07T23:00:17.186981Z"}]}
{"channel":"book","type":"update","data":[{"symbol":"ETH/USD","bids":[],"asks":[{"price":1773.87,"qty":0.00000000},{"price":1774.12,"qty":0.50000000}],"checksum":828904331,"timestamp":"2026-07-07T23:00:17.188409Z"}]}
{"channel":"book","type":"update","data":[{"symbol":"ETH/USD","bids":[],"asks":[{"price":1774.06,"qty":0.00000000},{"price":1774.13,"qty":0.50000000}],"checksum":1887157979,"timestamp":"2026-07-07T23:00:17.190026Z"}]}
{"channel":"book","type":"update","data":[{"symbol":"BTC/USD","bids":[{"price":63480.0,"qty":0.78764917}],"asks":[],"checksum":905390570,"timestamp":"2026-07-07T23:00:17.191398Z"}]}
{"channel":"book","type":"update","data":[{"symbol":"BTC/USD","bids":[{"price":63482.5,"qty":0.18050571}],"asks":[],"checksum":4147097909,"timestamp":"2026-07-07T23:00:17.191700Z"}]}
{"channel":"book","type":"update","data":[{"symbol":"ETH/USD","bids":[{"price":1773.52,"qty":28.19332116}],"asks":[],"checksum":3050116855,"timestamp":"2026-07-07T23:00:17.193989Z"}]}
{"channel":"book","type":"update","data":[{"symbol":"ETH/USD","bids":[],"asks":[{"price":1773.97,"qty":1.48204918}],"checksum":2309856497,"timestamp":"2026-07-07T23:00:17.195182Z"}]}
{"channel":"book","type":"update","data":[{"symbol":"ETH/USD","bids":[{"price":1773.40,"qty":5.56003448}],"asks":[],"checksum":3741151624,"timestamp":"2026-07-07T23:00:17.197565Z"}]}
{"channel":"book","type":"update","data":[{"symbol":"ETH/USD","bids":[{"price":1773.52,"qty":0.00000000},{"price":1773.26,"qty":16.22210522},{"price":1773.44,"qty":28.18875429}],"asks":[],"checksum":2157471881,"timestamp":"2026-07-07T23:00:17.198786Z"}]}
{"channel":"book","type":"update","data":[{"symbol":"ETH/USD","bids":[],"asks":[{"price":1774.08,"qty":0.00000000},{"price":1774.14,"qty":0.52770405}],"checksum":1789590959,"timestamp":"2026-07-07T23:00:17.198935Z"}]}
{"channel":"book","type":"update","data":[{"symbol":"ETH/USD","bids":[{"price":1773.39,"qty":0.00000000},{"price":1773.26,"qty":16.22210522}],"asks":[],"checksum":909175052,"timestamp":"2026-07-07T23:00:17.199067Z"}]}
{"channel":"book","type":"update","data":[{"symbol":"ETH/USD","bids":[],"asks":[{"price":1774.04,"qty":0.00000000},{"price":1774.16,"qty":0.28137208}],"checksum":1396509655,"timestamp":"2026-07-07T23:00:17.199173Z"}]}
{"channel":"book","type":"update","data":[{"symbol":"ETH/USD","bids":[{"price":1773.44,"qty":29.44398239}],"asks":[],"checksum":86530449,"timestamp":"2026-07-07T23:00:17.199208Z"}]}
{"channel":"book","type":"update","data":[{"symbol":"ETH/USD","bids":[{"price":1773.26,"qty":7.27266389}],"asks":[],"checksum":3395366369,"timestamp":"2026-07-07T23:00:17.199411Z"}]}
{"channel":"book","type":"update","data":[{"symbol":"ETH/USD","bids":[],"asks":[{"price":1774.08,"qty":0.75132571}],"checksum":732564003,"timestamp":"2026-07-07T23:00:17.202904Z"}]}
{"channel":"book","type":"update","data":[{"symbol":"ETH/USD","bids":[{"price":1773.26,"qty":0.00000000},{"price":1773.24,"qty":1.30000000}],"asks":[],"checksum":31988230,"timestamp":"2026-07-07T23:00:17.202997Z"}]}
{"channel":"book","type":"update","data":[{"symbol":"ETH/USD","bids":[],"asks":[{"price":1773.95,"qty":2.81857345}],"checksum":4040689894,"timestamp":"2026-07-07T23:00:17.203951Z"}]}
{"channel":"book","type":"update","data":[{"symbol":"ETH/USD","bids":[{"price":1773.59,"qty":2.81913219}],"asks":[],"checksum":477996654,"timestamp":"2026-07-07T23:00:17.204556Z"}]}
{"channel":"book","type":"update","data":[{"symbol":"ETH/USD","bids":[{"price":1773.40,"qty":0.00000000},{"price":1773.24,"qty":1.30000000}],"asks":[],"checksum":3211662009,"timestamp":"2026-07-07T23:00:17.204630Z"}]}
{"channel":"book","type":"update","data":[{"symbol":"ETH/USD","bids":[{"price":1773.39,"qty":28.19454041}],"asks":[],"checksum":1509077058,"timestamp":"2026-07-07T23:00:17.204660Z"}]}
{"channel":"book","type":"update","data":[{"symbol":"ETH/USD","bids":[{"price":1773.61,"qty":20.34616104}],"asks":[],"checksum":402622619,"timestamp":"2026-07-07T23:00:17.204877Z"}]}
{"channel":"book","type":"update","data":[{"symbol":"ETH/USD","bids":[],"asks":[{"price":1773.98,"qty":0.00000000},{"price":1774.14,"qty":28.71039465}],"checksum":2712939562,"timestamp":"2026-07-07T23:00:17.205238Z"}]}
{"channel":"book","type":"update","data":[{"symbol":"ETH/USD","bids":[],"asks":[{"price":1774.10,"qty":17.95600000}],"checksum":2251418495,"timestamp":"2026-07-07T23:00:17.207854Z"}]}
{"channel":"book","type":"update","data":[{"symbol":"BTC/USD","bids":[],"asks":[{"price":63498.1,"qty":2.70422768}],"checksum":569027114,"timestamp":"2026-07-07T23:00:17.208325Z"}]}
{"channel":"book","type":"update","data":[{"symbol":"ETH/USD","bids":[{"price":1773.45,"qty":10.97518874}],"asks":[],"checksum":444710132,"timestamp":"2026-07-07T23:00:17.211558Z"}]}
{"channel":"book","type":"update","data":[{"symbol":"ETH/USD","bids":[{"price":1773.44,"qty":30.60595351}],"asks":[],"checksum":484881250,"timestamp":"2026-07-07T23:00:17.211585Z"}]}
{"channel":"book","type":"update","data":[{"symbol":"ETH/USD","bids":[],"asks":[{"price":1774.08,"qty":1.76697894}],"checksum":3797528783,"timestamp":"2026-07-07T23:00:17.211628Z"}]}
{"channel":"book","type":"update","data":[{"symbol":"ETH/USD","bids":[],"asks":[{"price":1774.08,"qty":0.75132571}],"checksum":484881250,"timestamp":"2026-07-07T23:00:17.211949Z"}]}
{"channel":"book","type":"update","data":[{"symbol":"ETH/USD","bids":[{"price":1773.44,"qty":29.44398239}],"asks":[],"checksum":444710132,"timestamp":"2026-07-07T23:00:17.212086Z"}]}
{"channel":"book","type":"update","data":[{"symbol":"ETH/USD","bids":[],"asks":[{"price":1774.13,"qty":6.79794835}],"checksum":3659669834,"timestamp":"2026-07-07T23:00:17.212216Z"}]}
{"channel":"book","type":"update","data":[{"symbol":"ETH/USD","bids":[{"price":1773.53,"qty":8.44936843}],"asks":[],"checksum":2536933301,"timestamp":"2026-07-07T23:00:17.212301Z"}]}
{"channel":"book","type":"update","data":[{"symbol":"ETH/USD","bids":[{"price":1773.53,"qty":0.00000000},{"price":1773.38,"qty":0.45737557}],"asks":[],"checksum":3659669834,"timestamp":"2026-07-07T23:00:17.212465Z"}]}
{"channel":"book","type":"update","data":[{"symbol":"ETH/USD","bids":[],"asks":[{"price":1773.62,"qty":0.00000000},{"price":1774.14,"qty":28.71039465}],"checksum":1828932955,"timestamp":"2026-07-07T23:00:17.212802Z"}]}
{"channel":"book","type":"update","data":[{"symbol":"ETH/USD","bids":[],"asks":[{"price":1774.08,"qty":0.00000000},{"price":1774.16,"qty":0.28137208}],"checksum":64011155,"timestamp":"2026-07-07T23:00:17.212910Z"}]}
{"channel":"book","type":"update","data":[{"symbol":"ETH/USD","bids":[],"asks":[{"price":1773.71,"qty":0.00000000},{"price":1774.17,"qty":3.44294531}],"checksum":1113598621,"timestamp":"2026-07-07T23:00:17.213301Z"}]}
{"channel":"book","type":"update","data":[{"symbol":"ETH/USD","bids":[{"price":1773.59,"qty":0.00000000},{"price":1773.37,"qty":0.06935921}],"asks":[],"checksum":1562984439,"timestamp":"2026-07-07T23:00:17.214534Z"}]}
{"channel":"book","type":"update","data":[{"symbol":"ETH/USD","bids":[],"asks":[{"price":1773.95,"qty":3.30787345}],"checksum":2333578673,"timestamp":"2026-07-07T23:00:17.217048Z"}]}
{"channel":"book","type":"update","data":[{"symbol":"ETH/USD","bids":[{"price":1773.44,"qty":28.18875429}],"asks":[],"checksum":2972116832,"timestamp":"2026-07-07T23:00:17.217184Z"}]}
{"channel":"book","type":"update","data":[{"symbol":"ETH/USD","bids":[],"asks":[{"price":1774.11,"qty":0.50000000}],"checksum":924209624,"timestamp":"2026-07-07T23:00:17.217506Z"}]}
{"channel":"book","type":"update","data":[{"symbol":"BTC/USD","bids":[{"price":63483.2,"qty":0.02936327}],"asks":[],"checksum":3354545664,"timestamp":"2026-07-07T23:00:17.217574Z"}]}
{"channel":"book","type":"update","data":[{"symbol":"ETH/USD","bids":[{"price":1773.62,"qty":0.48930000}],"asks":[],"checksum":4210661503,"timestamp":"2026-07-07T23:00:17.217813Z"}]}
{"channel":"book","type":"update","data":[{"symbol":"ETH/USD","bids":[{"price":1773.55,"qty":0.00000000},{"price":1773.37,"qty":0.06935921}],"asks":[],"checksum":2489490981,"timestamp":"2026-07-07T23:00:17.218810Z"}]}
{"channel":"book","type":"update","data":[{"symbol":"ETH/USD","bids":[{"price":1773.62,"qty":7.55019608}],"asks":[],"checksum":1345003682,"timestamp":"2026-07-07T23:00:17.219129Z"}]}
{"channel":"book","type":"update","data":[{"symbol":"ETH/USD","bids":[{"price":1773.45,"qty":16.32843251}],"asks":[],"checksum":2702474168,"timestamp":"2026-07-07T23:00:17.219470Z"}]}
{"channel":"book","type":"update","data":[{"symbol":"ETH/USD","bids":[{"price":1773.60,"qty":0.98756701}],"asks":[],"checksum":2895984902,"timestamp":"2026-07-07T23:00:17.219639Z"}]}
{"channel":"book","type":"update","data":[{"symbol":"ETH/USD","bids":[{"price":1773.60,"qty":0.00000000},{"price":1773.37,"qty":0.06935921}],"asks":[],"checksum":2702474168,"timestamp":"2026-07-07T23:00:17.219812Z"}]}
{"channel":"book","type":"update","data":[{"symbol":"ETH/USD","bids":[],"asks":[{"price":1774.13,"qty":7.28724835}],"checksum":2115452868,"timestamp":"2026-07-07T23:00:17.221862Z"}]}
{"channel":"book","type":"update","data":[{"symbol":"ETH/USD","bids":[{"price":1773.62,"qty":7.06089608}],"asks":[],"checksum":1553580590,"timestamp":"2026-07-07T23:00:17.222230Z"}]}
{"channel":"book","type":"update","data":[{"symbol":"ETH/USD","bids":[{"price":1773.62,"qty":7.56089608}],"asks":[],"checksum":2384481700,"timestamp":"2026-07-07T23:00:17.222238Z"}]}
{"channel":"book","type":"update","data":[{"symbol":"ETH/USD","bids":[{"price":1773.63,"qty":0.48930000}],"asks":[],"checksum":3990023237,"timestamp":"2026-07-07T23:00:17.224801Z"}]}
{"channel":"book","type":"update","data":[{"symbol":"BTC/USD","bids":[],"asks":[{"price":63500.8,"qty":0.00005100}],"checksum":248791119,"timestamp":"2026-07-07T23:00:17.226316Z"}]}
{"channel":"book","type":"update","data":[{"symbol":"ETH/USD","bids":[{"price":1773.63,"qty":0.98930000}],"asks":[],"checksum":3211835173,"timestamp":"2026-07-07T23:00:17.227688Z"}]}
{"channel":"book","type":"update","data":[{"symbol":"ETH/USD","bids":[{"price":1773.38,"qty":0.00000000},{"price":1773.37,"qty":0.06935921}],"asks":[],"checksum":77071892,"timestamp":"2026-07-07T23:00:17.228647Z"}]}
{"channel":"book","type":"update","data":[{"symbol":"ETH/USD","bids":[{"price":1773.54,"qty":0.57284095}],"asks":[],"checksum":2775829556,"timestamp":"2026-07-07T23:00:17.228821Z"}]}
{"channel":"book","type":"update","data":[{"symbol":"BTC/USD","bids":[],"asks":[{"price":63498.5,"qty":0.35444250}],"checksum":3333199093,"timestamp":"2026-07-07T23:00:17.229003Z"}]}
{"channel":"book","type":"update","data":[{"symbol":"ETH/USD","bids":[{"price":1773.64,"qty":0.48930000}],"asks":[],"checksum":3219573526,"timestamp":"2026-07-07T23:00:17.229864Z"}]}
{"channel":"book","type":"update","data":[{"symbol":"ETH/USD","bids":[{"price":1773.63,"qty":0.50000000}],"asks":[],"checksum":1399467581,"timestamp":"2026-07-07T23:00:17.230550Z"}]}
{"channel":"book","type":"update","data":[{"symbol":"BTC/USD","bids":[],"asks":[{"price":63498.1,"qty":2.72635850}],"checksum":308965014,"timestamp":"2026-07-07T23:00:17.231532Z"}]}
{"channel":"book","type":"update","data":[{"symbol":"ETH/USD","bids":[{"price":1773.42,"qty":1.68966976}],"asks":[],"checksum":1612848097,"timestamp":"2026-07-07T23:00:17.232548Z"}]}
{"channel":"book","type":"update","data":[{"symbol":"ETH/USD","bids":[{"price":1773.46,"qty":0.48930000}],"asks":[],"checksum":1457826475,"timestamp":"2026-07-07T23:00:17.232691Z"}]}
{"channel":"book","type":"update","data":[{"symbol":"ETH/USD","bids":[{"price":1773.64,"qty":0.98930000}],"asks":[],"checksum":1950308137,"timestamp":"2026-07-07T23:00:17.232708Z"}]}
{"channel":"book","type":"update","data":[{"symbol":"ETH/USD","bids":[],"asks":[{"price":1774.17,"qty":0.00000000},{"price":1774.20,"qty":2.14310284}],"checksum":3808389794,"timestamp":"2026-07-07T23:00:17.233804Z"}]}
{"channel":"book","type":"update","data":[{"symbol":"ETH/USD","bids":[{"price":1773.64,"qty":0.50000000}],"asks":[],"checksum":911974571,"timestamp":"2026-07-07T23:00:17.234850Z"}]}
{"channel":"book","type":"update","data":[{"symbol":"ETH/USD","bids":[{"price":1773.65,"qty":0.48930000}],"asks":[],"checksum":897372168,"timestamp":"2026-07-07T23:00:17.235013Z"}]}
{"channel":"book","type":"update","data":[{"symbol":"ETH/USD","bids":[],"asks":[{"price":1773.95,"qty":0.48930000}],"checksum":4172109011,"timestamp":"2026-07-07T23:00:17.237161Z"}]}
{"channel":"book","type":"update","data":[{"symbol":"ETH/USD","bids":[],"asks":[{"price":1774.14,"qty":0.52770405}],"checksum":2957855525,"timestamp":"2026-07-07T23:00:17.237615Z"}]}
{"channel":"book","type":"update","data":[{"symbol":"ETH/USD","bids":[{"price":1773.61,"qty":19.84616104}],"asks":[],"checksum":379709849,"timestamp":"2026-07-07T23:00:17.239849Z"}]}
{"channel":"book","type":"update","data":[{"symbol":"ETH/USD","bids":[{"price":1773.65,"qty":0.98930000}],"asks":[],"checksum":880415771,"timestamp":"2026-07-07T23:00:17.240037Z"}]}
{"channel":"book","type":"update","data":[{"symbol":"ETH/USD","bids":[{"price":1773.46,"qty":6.04933448}],"asks":[],"checksum":239825917,"timestamp":"2026-07-07T23:00:17.240324Z"}]}
{"channel":"book","type":"update","data":[{"symbol":"ETH/USD","bids":[],"asks":[{"price":1774.20,"qty":14.49737015}],"checksum":3286268480,"timestamp":"2026-07-07T23:00:17.240795Z"}]}
{"channel":"book","type":"update","data":[{"symbol":"ETH/USD","bids":[],"asks":[{"price":1774.13,"qty":0.98930000}],"checksum":549197082,"timestamp":"2026-07-07T23:00:17.241281Z"}]}
{"channel":"book","type":"update","data":[{"symbol":"ETH/USD","bids":[{"price":1773.70,"qty":0.48930000}],"asks":[],"checksum":2471181461,"timestamp":"2026-07-07T23:00:17.242339Z"}]}
{"channel":"book","type":"update","data":[{"symbol":"ETH/USD","bids":[],"asks":[{"price":1773.95,"qty":0.00000000},{"price":1774.21,"qty":7.17957400}],"checksum":2639932064,"timestamp":"2026-07-07T23:00:17.242565Z"}]}
{"channel":"book","type":"update","data":[{"symbol":"ETH/USD","bids":[],"asks":[{"price":1774.21,"qty":0.00000000},{"price":1774.27,"qty":0.33816724}],"checksum":3716099476,"timestamp":"2026-07-07T23:00:17.242696Z"}]}
{"channel":"book","type":"update","data":[{"symbol":"ETH/USD","bids":[],"asks":[{"price":1774.20,"qty":12.35426731}],"checksum":553415096,"timestamp":"2026-07-07T23:00:17.243460Z"}]}
{"channel":"book","type":"update","data":[{"symbol":"ETH/USD","bids":[{"price":1773.66,"qty":0.59380605}],"asks":[],"checksum":2808916209,"timestamp":"2026-07-07T23:00:17.244050Z"}]}
{"channel":"book","type":"update","data":[{"symbol":"ETH/USD","bids":[],"asks":[{"price":1774.09,"qty":5.05763308}],"checksum":1496686542,"timestamp":"2026-07-07T23:00:17.244243Z"}]}
{"channel":"book","type":"update","data":[{"symbol":"ETH/USD","bids":[],"asks":[{"price":1774.19,"qty":5.83085163}],"checksum":2859603469,"timestamp":"2026-07-07T23:00:17.245231Z"}]}
{"channel":"book","type":"update","data":[{"symbol":"ETH/USD","bids":[],"asks":[{"price":1774.09,"qty":20.70183308}],"checksum":3050400428,"timestamp":"2026-07-07T23:00:17.245733Z"}]}
{"channel":"book","type":"update","data":[{"symbol":"ETH/USD","bids":[{"price":1773.47,"qty":1.80572634}],"asks":[],"checksum":1716870305,"timestamp":"2026-07-07T23:00:17.246262Z"}]}
{"channel":"book","type":"update","data":[{"symbol":"ETH/USD","bids":[],"asks":[{"price":1774.19,"qty":0.00000000},{"price":1774.20,"qty":12.35426731}],"checksum":729782721,"timestamp":"2026-07-07T23:00:17.246344Z"}]}
{"channel":"book","type":"update","data":[{"symbol":"ETH/USD","bids":[],"asks":[{"price":1773.97,"qty":1.97134918}],"checksum":1488049648,"timestamp":"2026-07-07T23:00:17.246405Z"}]}
{"channel":"book","type":"update","data":[{"symbol":"ETH/USD","bids":[],"asks":[{"price":1774.13,"qty":0.50000000}],"checksum":1372650282,"timestamp":"2026-07-07T23:00:17.246614Z"}]}
{"channel":"book","type":"update","data":[{"symbol":"BTC/USD","bids":[{"price":63482.5,"qty":0.00000000},{"price":63481.5,"qty":0.00030000}],"asks":[],"checksum":2591644044,"timestamp":"2026-07-07T23:00:17.247101Z"}]}
{"channel":"book","type":"update","data":[{"symbol":"ETH/USD","bids":[],"asks":[{"price":1774.00,"qty":2.81850303}],"checksum":429437300,"timestamp":"2026-07-07T23:00:17.248664Z"}]}
{"channel":"book","type":"update","data":[{"symbol":"ETH/USD","bids":[{"price":1773.62,"qty":10.37998923}],"asks":[],"checksum":1602879345,"timestamp":"2026-07-07T23:00:17.248940Z"}]}
{"channel":"book","type":"update","data":[{"symbol":"ETH/USD","bids":[{"price":1773.70,"qty":0.00000000},{"price":1773.46,"qty":6.04933448}],"asks":[],"checksum":2584700091,"timestamp":"2026-07-07T23:00:17.254615Z"}]}
{"channel":"book","type":"update","data":[{"symbol":"ETH/USD","bids":[{"price":1773.66,"qty":1.08310605}],"asks":[],"checksum":3944160118,"timestamp":"2026-07-07T23:00:17.256309Z"}]}
{"channel":"book","type":"update","data":[{"symbol":"ETH/USD","bids":[{"price":1773.65,"qty":0.50000000}],"asks":[],"checksum":688582709,"timestamp":"2026-07-07T23:00:17.256350Z"}]}
{"channel":"book","type":"update","data":[{"symbol":"ETH/USD","bids":[],"asks":[{"price":1774.00,"qty":0.00000000},{"price":1774.19,"qty":3.68774879}],"checksum":1066968751,"timestamp":"2026-07-07T23:00:17.256514Z"}]}
{"channel":"book","type":"update","data":[{"symbol":"ETH/USD","bids":[],"asks":[{"price":1773.99,"qty":0.00000000},{"price":1774.20,"qty":12.35426731}],"checksum":2542613107,"timestamp":"2026-07-07T23:00:17.257412Z"}]}
{"channel":"book","type":"update","data":[{"symbol":"ETH/USD","bids":[],"asks":[{"price":1774.09,"qty":21.00183308}],"checksum":2723658664,"timestamp":"2026-07-07T23:00:17.257477Z"}]}
{"channel":"book","type":"update","data":[{"symbol":"ETH/USD","bids":[{"price":1773.66,"qty":0.48930000}],"asks":[],"checksum":342959652,"timestamp":"2026-07-07T23:00:17.257756Z"}]}
{"channel":"book","type":"update","data":[{"symbol":"ETH/USD","bids":[],"asks":[{"price":1773.99,"qty":2.29747210}],"checksum":1957252833,"timestamp":"2026-07-07T23:00:17.258141Z"}]}
{"channel":"book","type":"update","data":[{"symbol":"ETH/USD","bids":[],"asks":[{"price":1773.96,"qty":0.68564255}],"checksum":2002663620,"timestamp":"2026-07-07T23:00:17.258337Z"}]}
{"channel":"book","type":"update","data":[{"symbol":"ETH/USD","bids":[{"price":1773.67,"qty":0.48930000}],"asks":[],"checksum":776051806,"timestamp":"2026-07-07T23:00:17.258353Z"}]}
{"channel":"book","type":"update","data":[{"symbol":"ETH/USD","bids":[{"price":1773.66,"qty":0.00000000},{"price":1773.46,"qty":6.04933448}],"asks":[],"checksum":2285669040,"timestamp":"2026-07-07T23:00:17.258433Z"}]}
{"channel":"book","type":"update","data":[{"symbol":"ETH/USD","bids":[],"asks":[{"price":1773.96,"qty":1.17494255}],"checksum":2491184466,"timestamp":"2026-07-07T23:00:17.260621Z"}]}
{"channel":"book","type":"update","data":[{"symbol":"ETH/USD","bids":[],"asks":[{"price":1773.96,"qty":3.47241465}],"checksum":2232778225,"timestamp":"2026-07-07T23:00:17.260846Z"}]}
{"channel":"book","type":"update","data":[{"symbol":"ETH/USD","bids":[],"asks":[{"price":1773.97,"qty":1.48204918}],"checksum":3807552117,"timestamp":"2026-07-07T23:00:17.262764Z"}]}
{"channel":"book","type":"update","data":[{"symbol":"ETH/USD","bids":[{"price":1773.62,"qty":7.56089608}],"asks":[],"checksum":2458388696,"timestamp":"2026-07-07T23:00:17.263418Z"}]}
{"channel":"book","type":"update","data":[{"symbol":"BTC/USD","bids":[{"price":63482.5,"qty":0.18050571}],"asks":[],"checksum":308965014,"timestamp":"2026-07-07T23:00:17.263736Z"}]}
{"channel":"book","type":"update","data":[{"symbol":"ETH/USD","bids":[],"asks":[{"price":1774.14,"qty":1.01700405}],"checksum":1117048017,"timestamp":"2026-07-07T23:00:17.264148Z"}]}
{"channel":"book","type":"update","data":[{"symbol":"BTC/USD","bids":[{"price":63482.5,"qty":0.00000000},{"price":63481.5,"qty":0.00030000}],"asks":[],"checksum":2591644044,"timestamp":"2026-07-07T23:00:17.265781Z"}]}
{"channel":"book","type":"update","data":[{"symbol":"ETH/USD","bids":[{"price":1773.51,"qty":0.00000000},{"price":1773.45,"qty":16.32843251}],"asks":[],"checksum":1206450695,"timestamp":"2026-07-07T23:00:17.273507Z"}]}
{"channel":"book","type":"update","data":[{"symbol":"ETH/USD","bids":[],"asks":[{"price":1773.95,"qty":1.53128753}],"checksum":1811957153,"timestamp":"2026-07-07T23:00:17.276758Z"}]}
{"channel":"book","type":"update","data":[{"symbol":"ETH/USD","bids":[],"asks":[{"price":1773.95,"qty":2.00130641}],"checksum":2105616993,"timestamp":"2026-07-07T23:00:17.277408Z"}]}
{"channel":"book","type":"update","data":[{"symbol":"ETH/USD","bids":[],"asks":[{"price":1773.95,"qty":2.49060641}],"checksum":2518048032,"timestamp":"2026-07-07T23:00:17.278271Z"}]}
{"channel":"book","type":"update","data":[{"symbol":"ETH/USD","bids":[{"price":1773.64,"qty":0.78850135}],"asks":[],"checksum":2044123185,"timestamp":"2026-07-07T23:00:17.278500Z"}]}
{"channel":"book","type":"update","data":[{"symbol":"ETH/USD","bids":[],"asks":[{"price":1774.13,"qty":0.88794601}],"checksum":4009864855,"timestamp":"2026-07-07T23:00:17.279599Z"}]}
{"channel":"book","type":"update","data":[{"symbol":"ETH/USD","bids":[],"asks":[{"price":1773.95,"qty":4.78807851}],"checksum":2441326075,"timestamp":"2026-07-07T23:00:17.279734Z"}]}
{"channel":"book","type":"update","data":[{"symbol":"ETH/USD","bids":[],"asks":[{"price":1773.96,"qty":1.17494255}],"checksum":1314310509,"timestamp":"2026-07-07T23:00:17.281599Z"}]}
{"channel":"book","type":"update","data":[{"symbol":"BTC/USD","bids":[{"price":63485.2,"qty":0.00000000},{"price":63479.1,"qty":0.03608734}],"asks":[],"checksum":1053157454,"timestamp":"2026-07-07T23:00:17.293226Z"}]}
{"channel":"book","type":"update","data":[{"symbol":"ETH/USD","bids":[],"asks":[{"price":1773.95,"qty":4.29877851}],"checksum":871056547,"timestamp":"2026-07-07T23:00:17.298355Z"}]}
{"channel":"book","type":"update","data":[{"symbol":"ETH/USD","bids":[{"price":1773.46,"qty":0.48930000}],"asks":[],"checksum":3228818323,"timestamp":"2026-07-07T23:00:17.304477Z"}]}
{"channel":"book","type":"update","data":[{"symbol":"ETH/USD","bids":[],"asks":[{"price":1773.96,"qty":3.99349539}],"checksum":2862540799,"timestamp":"2026-07-07T23:00:17.304904Z"}]}
{"channel":"book","type":"update","data":[{"symbol":"ETH/USD","bids":[{"price":1773.45,"qty":10.97518874}],"asks":[],"checksum":4140344686,"timestamp":"2026-07-07T23:00:17.305241Z"}]}
{"channel":"book","type":"update","data":[{"symbol":"ETH/USD","bids":[{"price":1773.65,"qty":3.31903054}],"asks":[],"checksum":673141807,"timestamp":"2026-07-07T23:00:17.305255Z"}]}
{"channel":"book","type":"update","data":[{"symbol":"ETH/USD","bids":[{"price":1773.47,"qty":0.00000000},{"price":1773.44,"qty":28.18875429}],"asks":[],"checksum":1968307574,"timestamp":"2026-07-07T23:00:17.306081Z"}]}
{"channel":"book","type":"update","data":[{"symbol":"ETH/USD","bids":[{"price":1773.66,"qty":1.37534827}],"asks":[],"checksum":1036054528,"timestamp":"2026-07-07T23:00:17.325399Z"}]}
{"channel":"book","type":"update","data":[{"symbol":"BTC/USD","bids":[],"asks":[{"price":63498.1,"qty":2.71335850}],"checksum":1293731608,"timestamp":"2026-07-07T23:00:17.339301Z"}]}
{"channel":"book","type":"update","data":[{"symbol":"ETH/USD","bids":[],"asks":[{"price":1773.96,"qty":3.50419539}],"checksum":332510875,"timestamp":"2026-07-07T23:00:17.339703Z"}]}
{"channel":"book","type":"update","data":[{"symbol":"ETH/USD","bids":[{"price":1773.47,"qty":1.68966976}],"asks":[],"checksum":300208955,"timestamp":"2026-07-07T23:00:17.340664Z"}]}
{"channel":"book","type":"update","data":[{"symbol":"ETH/USD","bids":[{"price":1773.48,"qty":0.65042247}],"asks":[],"checksum":504952839,"timestamp":"2026-07-07T23:00:17.342691Z"}]}
{"channel":"book","type":"update","data":[{"symbol":"ETH/USD","bids":[],"asks":[{"price":1773.95,"qty":2.00130641}],"checksum":238364736,"timestamp":"2026-07-07T23:00:17.349440Z"}]}
{"channel":"book","type":"update","data":[{"symbol":"ETH/USD","bids":[],"asks":[{"price":1773.99,"qty":0.00000000},{"price":1774.16,"qty":0.28137208}],"checksum":2625031610,"timestamp":"2026-07-07T23:00:17.351042Z"}]}
{"channel":"book","type":"update","data":[{"symbol":"ETH/USD","bids":[],"asks":[{"price":1773.97,"qty":0.00000000},{"price":1774.19,"qty":3.68774879}],"checksum":1849721068,"timestamp":"2026-07-07T23:00:17.351778Z"}]}
{"channel":"book","type":"update","data":[{"symbol":"ETH/USD","bids":[],"asks":[{"price":1773.96,"qty":2.81855284}],"checksum":2651224627,"timestamp":"2026-07-07T23:00:17.352821Z"}]}
{"channel":"book","type":"update","data":[{"symbol":"BTC/USD","bids":[{"price":63482.4,"qty":0.00000000},{"price":63478.9,"qty":0.03147178}],"asks":[],"checksum":2560135814,"timestamp":"2026-07-07T23:00:17.354565Z"}]}
{"channel":"book","type":"update","data":[{"symbol":"ETH/USD","bids":[{"price":1773.65,"qty":0.50000000}],"asks":[],"checksum":2323500014,"timestamp":"2026-07-07T23:00:17.354636Z"}]}
{"channel":"book","type":"update","data":[{"symbol":"ETH/USD","bids":[],"asks":[{"price":1774.14,"qty":0.98930000}],"checksum":2672915643,"timestamp":"2026-07-07T23:00:17.354993Z"}]}
{"channel":"book","type":"update","data":[{"symbol":"BTC/USD","bids":[{"price":63482.5,"qty":0.18050571}],"asks":[],"checksum":3014945517,"timestamp":"2026-07-07T23:00:17.357118Z"}]}
{"channel":"book","type":"update","data":[{"symbol":"BTC/USD","bids":[{"price":63482.5,"qty":0.00000000},{"price":63478.9,"qty":0.03147178}],"asks":[],"checksum":2560135814,"timestamp":"2026-07-07T23:00:17.357247Z"}]}
{"channel":"book","type":"update","data":[{"symbol":"ETH/USD","bids":[],"asks":[{"price":1773.96,"qty":0.00000000},{"price":1774.20,"qty":12.35426731}],"checksum":1457670644,"timestamp":"2026-07-07T23:00:17.357284Z"}]}
{"channel":"book","type":"update","data":[{"symbol":"ETH/USD","bids":[{"price":1773.68,"qty":0.67992370}],"asks":[],"checksum":3574758879,"timestamp":"2026-07-07T23:00:17.357347Z"}]}
{"channel":"book","type":"update","data":[{"symbol":"ETH/USD","bids":[{"price":1773.66,"qty":0.00000000},{"price":1773.47,"qty":1.68966976}],"asks":[],"checksum":3179801136,"timestamp":"2026-07-07T23:00:17.357376Z"}]}
{"channel":"book","type":"update","data":[{"symbol":"BTC/USD","bids":[{"price":63485.2,"qty":0.05990000}],"asks":[],"checksum":3087919882,"timestamp":"2026-07-07T23:00:17.358469Z"}]}
{"channel":"book","type":"update","data":[{"symbol":"ETH/USD","bids":[],"asks":[{"price":1774.06,"qty":2.81840342}],"checksum":483523747,"timestamp":"2026-07-07T23:00:17.358974Z"}]}
{"channel":"book","type":"update","data":[{"symbol":"ETH/USD","bids":[{"price":1773.76,"qty":0.48930000}],"asks":[],"checksum":1033625990,"timestamp":"2026-07-07T23:00:17.359033Z"}]}
{"channel":"book","type":"update","data":[{"symbol":"ETH/USD","bids":[{"price":1773.73,"qty":2.81891643}],"asks":[],"checksum":2713729079,"timestamp":"2026-07-07T23:00:17.359337Z"}]}
{"channel":"book","type":"update","data":[{"symbol":"ETH/USD","bids":[{"price":1773.71,"qty":0.30991866}],"asks":[],"checksum":2311751780,"timestamp":"2026-07-07T23:00:17.366777Z"}]}
{"channel":"book","type":"update","data":[{"symbol":"ETH/USD","bids":[{"price":1773.64,"qty":0.50000000}],"asks":[],"checksum":1333719498,"timestamp":"2026-07-07T23:00:17.368050Z"}]}
{"channel":"book","type":"update","data":[{"symbol":"ETH/USD","bids":[],"asks":[{"price":1774.04,"qty":0.33819100}],"checksum":3582121381,"timestamp":"2026-07-07T23:00:17.383561Z"}]}
{"channel":"book","type":"update","data":[{"symbol":"BTC/USD","bids":[{"price":63485.2,"qty":0.00000000},{"price":63478.9,"qty":0.03147178}],"asks":[],"checksum":2560135814,"timestamp":"2026-07-07T23:00:17.390819Z"}]}
{"channel":"book","type":"update","data":[{"symbol":"ETH/USD","bids":[{"price":1773.76,"qty":0.00000000},{"price":1773.54,"qty":0.57284095}],"asks":[],"checksum":3190213976,"timestamp":"2026-07-07T23:00:17.394668Z"}]}
{"channel":"book","type":"update","data":[{"symbol":"ETH/USD","bids":[{"price":1773.73,"qty":3.30821643}],"asks":[],"checksum":2222975970,"timestamp":"2026-07-07T23:00:17.396122Z"}]}
{"channel":"book","type":"update","data":[{"symbol":"ETH/USD","bids":[{"price":1773.67,"qty":0.00000000},{"price":1773.48,"qty":2.22693753}],"asks":[],"checksum":3458546222,"timestamp":"2026-07-07T23:00:17.396777Z"}]}
{"channel":"book","type":"update","data":[{"symbol":"ETH/USD","bids":[{"price":1773.68,"qty":0.00000000},{"price":1773.47,"qty":1.68966976}],"asks":[],"checksum":1281352677,"timestamp":"2026-07-07T23:00:17.398155Z"}]}
{"channel":"book","type":"update","data":[{"symbol":"ETH/USD","bids":[],"asks":[{"price":1774.05,"qty":0.84129342}],"checksum":2440703905,"timestamp":"2026-07-07T23:00:17.400695Z"}]}
{"channel":"book","type":"update","data":[{"symbol":"ETH/USD","bids":[],"asks":[{"price":1773.94,"qty":0.14097691}],"checksum":482577539,"timestamp":"2026-07-07T23:00:17.402693Z"}]}
{"channel":"book","type":"update","data":[{"symbol":"ETH/USD","bids":[],"asks":[{"price":1773.95,"qty":0.47001888}],"checksum":3477673991,"timestamp":"2026-07-07T23:00:17.404348Z"}]}
{"channel":"book","type":"update","data":[{"symbol":"ETH/USD","bids":[{"price":1773.63,"qty":6.06003448}],"asks":[],"checksum":547214364,"timestamp":"2026-07-07T23:00:17.406848Z"}]}
{"channel":"book","type":"update","data":[{"symbol":"ETH/USD","bids":[{"price":1773.48,"qty":0.65042247}],"asks":[],"checksum":877731370,"timestamp":"2026-07-07T23:00:17.408559Z"}]}
{"channel":"book","type":"update","data":[{"symbol":"ETH/USD","bids":[{"price":1773.64,"qty":2.30892029}],"asks":[],"checksum":954583617,"timestamp":"2026-07-07T23:00:17.410055Z"}]}
{"channel":"book","type":"update","data":[{"symbol":"ETH/USD","bids":[],"asks":[{"price":1774.06,"qty":0.00000000},{"price":1774.14,"qty":0.98930000}],"checksum":3258476359,"timestamp":"2026-07-07T23:00:17.411571Z"}]}
{"channel":"book","type":"update","data":[{"symbol":"ETH/USD","bids":[],"asks":[{"price":1774.05,"qty":0.00000000},{"price":1774.16,"qty":0.28137208}],"checksum":2085770294,"timestamp":"2026-07-07T23:00:17.412931Z"}]}
{"channel":"book","type":"update","data":[{"symbol":"ETH/USD","bids":[],"asks":[{"price":1774.03,"qty":2.81844932}],"checksum":809459355,"timestamp":"2026-07-07T23:00:17.413314Z"}]}
{"channel":"book","type":"update","data":[{"symbol":"ETH/USD","bids":[],"asks":[{"price":1774.02,"qty":0.94225714}],"checksum":1732448406,"timestamp":"2026-07-07T23:00:17.415154Z"}]}
{"channel":"book","type":"update","data":[{"symbol":"ETH/USD","bids":[],"asks":[{"price":1773.94,"qty":0.00000000},{"price":1774.14,"qty":0.98930000}],"checksum":1920366478,"timestamp":"2026-07-07T23:00:17.417547Z"}]}
{"channel":"book","type":"update","data":[{"symbol":"BTC/USD","bids":[{"price":63483.7,"qty":0.78760344}],"asks":[],"checksum":3275512098,"timestamp":"2026-07-07T23:00:17.430542Z"}]}
{"channel":"book","type":"update","data":[{"symbol":"ETH/USD","bids":[],"asks":[{"price":1774.01,"qty":1.53128753}],"checksum":2318162786,"timestamp":"2026-07-07T23:00:17.430691Z"}]}
{"channel":"book","type":"update","data":[{"symbol":"ETH/USD","bids":[],"asks":[{"price":1774.13,"qty":0.50000000}],"checksum":3316048104,"timestamp":"2026-07-07T23:00:17.446532Z"}]}
{"channel":"book","type":"update","data":[{"symbol":"ETH/USD","bids":[],"asks":[{"price":1774.04,"qty":0.72613701}],"checksum":42048606,"timestamp":"2026-07-07T23:00:17.446805Z"}]}
{"channel":"book","type":"update","data":[{"symbol":"ETH/USD","bids":[{"price":1773.73,"qty":0.48930000}],"asks":[],"checksum":3556961879,"timestamp":"2026-07-07T23:00:17.463279Z"}]}
{"channel":"book","type":"update","data":[{"symbol":"ETH/USD","bids":[{"price":1773.67,"qty":2.81900485}],"asks":[],"checksum":1636554333,"timestamp":"2026-07-07T23:00:17.464669Z"}]}
{"channel":"book","type":"update","data":[{"symbol":"ETH/USD","bids":[],"asks":[{"price":1774.02,"qty":0.00000000},{"price":1774.14,"qty":0.98930000}],"checksum":2787770112,"timestamp":"2026-07-07T23:00:17.481076Z"}]}
{"channel":"book","type":"update","data":[{"symbol":"ETH/USD","bids":[],"asks":[{"price":1774.00,"qty":1.51514835}],"checksum":3760418556,"timestamp":"2026-07-07T23:00:17.482860Z"}]}
{"channel":"book","type":"update","data":[{"symbol":"ETH/USD","bids":[],"asks":[{"price":1773.99,"qty":1.53128753}],"checksum":3302119964,"timestamp":"2026-07-07T23:00:17.484820Z"}]}
{"channel":"book","type":"update","data":[{"symbol":"ETH/USD","bids":[],"asks":[{"price":1773.97,"qty":0.30765112}],"checksum":333915226,"timestamp":"2026-07-07T23:00:17.500900Z"}]}
{"channel":"book","type":"update","data":[{"symbol":"ETH/USD","bids":[],"asks":[{"price":1774.04,"qty":0.38794601}],"checksum":770814569,"timestamp":"2026-07-07T23:00:17.502168Z"}]}
{"channel":"book","type":"update","data":[{"symbol":"ETH/USD","bids":[],"asks":[{"price":1773.96,"qty":1.53128753}],"checksum":426589251,"timestamp":"2026-07-07T23:00:17.502323Z"}]}
{"channel":"book","type":"update","data":[{"symbol":"ETH/USD","bids":[{"price":1773.49,"qty":1.68966976}],"asks":[],"checksum":169081195,"timestamp":"2026-07-07T23:00:17.502489Z"}]}
{"channel":"book","type":"update","data":[{"symbol":"ETH/USD","bids":[],"asks":[{"price":1773.99,"qty":0.00000000},{"price":1774.11,"qty":0.50000000}],"checksum":2693891346,"timestamp":"2026-07-07T23:00:17.503208Z"}]}
{"channel":"book","type":"update","data":[{"symbol":"ETH/USD","bids":[],"asks":[{"price":1773.94,"qty":1.53128753}],"checksum":3924859632,"timestamp":"2026-07-07T23:00:17.504638Z"}]}
{"channel":"book","type":"update","data":[{"symbol":"ETH/USD","bids":[{"price":1773.50,"qty":0.65042247}],"asks":[],"checksum":3441392877,"timestamp":"2026-07-07T23:00:17.505316Z"}]}
{"channel":"book","type":"update","data":[{"symbol":"ETH/USD","bids":[],"asks":[{"price":1773.96,"qty":0.00000000},{"price":1774.11,"qty":0.50000000}],"checksum":1755414727,"timestamp":"2026-07-07T23:00:17.505409Z"}]}
{"channel":"book","type":"update","data":[{"symbol":"ETH/USD","bids":[],"asks":[{"price":1773.93,"qty":0.47001888}],"checksum":1038151764,"timestamp":"2026-07-07T23:00:17.505831Z"}]}
{"channel":"book","type":"update","data":[{"symbol":"ETH/USD","bids":[],"asks":[{"price":1773.92,"qty":1.53128753}],"checksum":1690372354,"timestamp":"2026-07-07T23:00:17.507336Z"}]}
{"channel":"book","type":"update","data":[{"symbol":"ETH/USD","bids":[],"asks":[{"price":1773.94,"qty":0.00000000},{"price":1774.10,"qty":17.95600000}],"checksum":2039776226,"timestamp":"2026-07-07T23:00:17.508331Z"}]}
{"channel":"book","type":"update","data":[{"symbol":"BTC/USD","bids":[{"price":63484.6,"qty":0.60470924}],"asks":[],"checksum":1176280635,"timestamp":"2026-07-07T23:00:17.534097Z"}]}
{"channel":"book","type":"update","data":[{"symbol":"ETH/USD","bids":[],"asks":[{"price":1774.03,"qty":0.00000000},{"price":1774.11,"qty":0.50000000}],"checksum":2479220919,"timestamp":"2026-07-07T23:00:17.536981Z"}]}
{"channel":"book","type":"update","data":[{"symbol":"ETH/USD","bids":[],"asks":[{"price":1773.98,"qty":2.81852273}],"checksum":2602518417,"timestamp":"2026-07-07T23:00:17.538986Z"}]}
{"channel":"book","type":"update","data":[{"symbol":"ETH/USD","bids":[],"asks":[{"price":1774.00,"qty":0.00000000},{"price":1774.11,"qty":0.50000000}],"checksum":1968366515,"timestamp":"2026-07-07T23:00:17.539233Z"}]}
{"channel":"book","type":"update","data":[{"symbol":"ETH/USD","bids":[{"price":1773.54,"qty":28.76501262}],"asks":[],"checksum":2584947649,"timestamp":"2026-07-07T23:00:17.539326Z"}]}
{"channel":"book","type":"update","data":[{"symbol":"ETH/USD","bids":[],"asks":[{"price":1774.00,"qty":0.57289121}],"checksum":178361575,"timestamp":"2026-07-07T23:00:17.541073Z"}]}
{"channel":"heartbeat"}
{"channel":"book","type":"update","data":[{"symbol":"ETH/USD","bids":[],"asks":[{"price":1774.01,"qty":0.00000000},{"price":1774.11,"qty":0.50000000}],"checksum":2857694679,"timestamp":"2026-07-07T23:00:17.585856Z"}]}
{"channel":"book","type":"update","data":[{"symbol":"ETH/USD","bids":[],"asks":[{"price":1774.00,"qty":0.00000000},{"price":1774.12,"qty":0.50000000}],"checksum":834258173,"timestamp":"2026-07-07T23:00:17.587062Z"}]}
{"channel":"book","type":"update","data":[{"symbol":"ETH/USD","bids":[],"asks":[{"price":1773.95,"qty":0.00000000},{"price":1774.13,"qty":0.50000000}],"checksum":1087474473,"timestamp":"2026-07-07T23:00:17.607886Z"}]}
{"channel":"book","type":"update","data":[{"symbol":"ETH/USD","bids":[],"asks":[{"price":1773.91,"qty":0.47001888}],"checksum":2292262367,"timestamp":"2026-07-07T23:00:17.609532Z"}]}
{"channel":"book","type":"update","data":[{"symbol":"ETH/USD","bids":[],"asks":[{"price":1773.90,"qty":1.53128753}],"checksum":1599253384,"timestamp":"2026-07-07T23:00:17.611590Z"}]}
{"channel":"book","type":"update","data":[{"symbol":"ETH/USD","bids":[],"asks":[{"price":1774.09,"qty":20.70183308}],"checksum":1391996693,"timestamp":"2026-07-07T23:00:17.631365Z"}]}
{"channel":"book","type":"update","data":[{"symbol":"ETH/USD","bids":[{"price":1773.73,"qty":0.00000000},{"price":1773.47,"qty":1.68966976}],"asks":[],"checksum":2102446973,"timestamp":"2026-07-07T23:00:17.645846Z"}]}
{"channel":"book","type":"update","data":[{"symbol":"ETH/USD","bids":[{"price":1773.64,"qty":0.50000000}],"asks":[],"checksum":4185267506,"timestamp":"2026-07-07T23:00:17.657612Z"}]}
{"channel":"book","type":"update","data":[{"symbol":"ETH/USD","bids":[{"price":1773.68,"qty":2.94889324}],"asks":[],"checksum":1110343521,"timestamp":"2026-07-07T23:00:17.658948Z"}]}
{"channel":"book","type":"update","data":[{"symbol":"ETH/USD","bids":[{"price":1773.50,"qty":2.34009223}],"asks":[],"checksum":2000917298,"timestamp":"2026-07-07T23:00:17.688446Z"}]}
{"channel":"book","type":"update","data":[{"symbol":"ETH/USD","bids":[{"price":1773.50,"qty":1.68966976}],"asks":[],"checksum":820678898,"timestamp":"2026-07-07T23:00:17.689532Z"}]}
{"channel":"book","type":"update","data":[{"symbol":"ETH/USD","bids":[{"price":1773.50,"qty":0.00000000},{"price":1773.46,"qty":0.48930000},{"price":1773.47,"qty":1.68966976}],"asks":[],"checksum":330847307,"timestamp":"2026-07-07T23:00:17.690733Z"}]}
{"channel":"book","type":"update","data":[{"symbol":"ETH/USD","bids":[{"price":1773.62,"qty":11.24629637}],"asks":[],"checksum":2093536001,"timestamp":"2026-07-07T23:00:17.690921Z"}]}
{"channel":"book","type":"update","data":[{"symbol":"ETH/USD","bids":[],"asks":[{"price":1773.93,"qty":0.00000000},{"price":1774.12,"qty":0.50000000}],"checksum":2831203677,"timestamp":"2026-07-07T23:00:17.710575Z"}]}
{"channel":"book","type":"update","data":[{"symbol":"ETH/USD","bids":[],"asks":[{"price":1773.89,"qty":0.47001888}],"checksum":2010572984,"timestamp":"2026-07-07T23:00:17.712297Z"}]}
{"channel":"book","type":"update","data":[{"symbol":"ETH/USD","bids":[],"asks":[{"price":1773.92,"qty":0.00000000},{"price":1774.12,"qty":0.50000000}],"checksum":3020366922,"timestamp":"2026-07-07T23:00:17.712851Z"}]}
{"channel":"book","type":"update","data":[{"symbol":"ETH/USD","bids":[],"asks":[{"price":1773.88,"qty":1.53128753}],"checksum":3155369434,"timestamp":"2026-07-07T23:00:17.714211Z"}]}
{"channel":"book","type":"update","data":[{"symbol":"BTC/USD","bids":[],"asks":[{"price":63498.1,"qty":2.13405050}],"checksum":2178517301,"timestamp":"2026-07-07T23:00:17.714694Z"}]}
{"channel":"book","type":"update","data":[{"symbol":"ETH/USD","bids":[{"price":1773.67,"qty":0.00000000},{"price":1773.46,"qty":0.48930000}],"asks":[],"checksum":2784280333,"timestamp":"2026-07-07T23:00:17.715551Z"}]}
{"channel":"book","type":"update","data":[{"symbol":"ETH/USD","bids":[{"price":1773.71,"qty":3.12886587}],"asks":[],"checksum":4184269477,"timestamp":"2026-07-07T23:00:17.717369Z"}]}
{"channel":"book","type":"update","data":[{"symbol":"ETH/USD","bids":[{"price":1773.68,"qty":0.00000000},{"price":1773.45,"qty":10.97518874}],"asks":[],"checksum":3724858600,"timestamp":"2026-07-07T23:00:17.717606Z"}]}
{"channel":"book","type":"update","data":[{"symbol":"ETH/USD","bids":[],"asks":[{"price":1773.92,"qty":0.30392551}],"checksum":965091164,"timestamp":"2026-07-07T23:00:17.730926Z"}]}
{"channel":"book","type":"update","data":[{"symbol":"ETH/USD","bids":[],"asks":[{"price":1773.97,"qty":0.00000000},{"price":1774.11,"qty":0.50000000}],"checksum":3096078229,"timestamp":"2026-07-07T23:00:17.731959Z"}]}
{"channel":"book","type":"update","data":[{"symbol":"ETH/USD","bids":[],"asks":[{"price":1773.98,"qty":0.00000000},{"price":1774.12,"qty":0.50000000}],"checksum":2463712493,"timestamp":"2026-07-07T23:00:17.732762Z"}]}
{"channel":"book","type":"update","data":[{"symbol":"ETH/USD","bids":[],"asks":[{"price":1774.04,"qty":3.20638289}],"checksum":281533722,"timestamp":"2026-07-07T23:00:17.734248Z"}]}
{"channel":"book","type":"update","data":[{"symbol":"ETH/USD","bids":[],"asks":[{"price":1774.03,"qty":0.95710529}],"checksum":1725613108,"timestamp":"2026-07-07T23:00:17.735596Z"}]}
{"channel":"book","type":"update","data":[{"symbol":"ETH/USD","bids":[],"asks":[{"price":1774.04,"qty":0.38794601}],"checksum":335435384,"timestamp":"2026-07-07T23:00:17.735804Z"}]}
{"channel":"book","type":"update","data":[{"symbol":"ETH/USD","bids":[],"asks":[{"price":1774.03,"qty":0.00000000},{"price":1774.12,"qty":0.50000000}],"checksum":2463712493,"timestamp":"2026-07-07T23:00:17.736972Z"}]}
{"channel":"book","type":"update","data":[{"symbol":"BTC/USD","bids":[{"price":63484.6,"qty":0.00000000},{"price":63479.1,"qty":0.03608734}],"asks":[],"checksum":3515081561,"timestamp":"2026-07-07T23:00:17.745763Z"}]}
{"channel":"book","type":"update","data":[{"symbol":"ETH/USD","bids":[{"price":1773.72,"qty":0.48930000}],"asks":[],"checksum":2152980816,"timestamp":"2026-07-07T23:00:17.808066Z"}]}
{"channel":"book","type":"update","data":[{"symbol":"ETH/USD","bids":[],"asks":[{"price":1773.91,"qty":0.00000000},{"price":1774.13,"qty":0.50000000}],"checksum":140739738,"timestamp":"2026-07-07T23:00:17.814825Z"}]}
{"channel":"book","type":"update","data":[{"symbol":"BTC/USD","bids":[],"asks":[{"price":63498.1,"qty":2.71341350}],"checksum":3379992944,"timestamp":"2026-07-07T23:00:17.814864Z"}]}
{"channel":"book","type":"update","data":[{"symbol":"ETH/USD","bids":[],"asks":[{"price":1773.90,"qty":0.00000000},{"price":1774.14,"qty":0.98930000}],"checksum":3229582117,"timestamp":"2026-07-07T23:00:17.815276Z"}]}
{"channel":"book","type":"update","data":[{"symbol":"ETH/USD","bids":[],"asks":[{"price":1774.04,"qty":3.20637293}],"checksum":537944970,"timestamp":"2026-07-07T23:00:17.816019Z"}]}
{"channel":"book","type":"update","data":[{"symbol":"ETH/USD","bids":[],"asks":[{"price":1773.87,"qty":0.47001888}],"checksum":2679555892,"timestamp":"2026-07-07T23:00:17.816626Z"}]}
{"channel":"book","type":"update","data":[{"symbol":"ETH/USD","bids":[],"asks":[{"price":1774.03,"qty":0.95710232}],"checksum":3611332379,"timestamp":"2026-07-07T23:00:17.817587Z"}]}
{"channel":"book","type":"update","data":[{"symbol":"BTC/USD","bids":[],"asks":[{"price":63499.1,"qty":0.01200000}],"checksum":1500825984,"timestamp":"2026-07-07T23:00:17.842615Z"}]}
{"channel":"book","type":"update","data":[{"symbol":"ETH/USD","bids":[{"price":1773.62,"qty":10.74629637}],"asks":[],"checksum":3117692542,"timestamp":"2026-07-07T23:00:17.916414Z"}]}
{"channel":"book","type":"update","data":[{"symbol":"ETH/USD","bids":[{"price":1773.63,"qty":5.56003448}],"asks":[],"checksum":3909076996,"timestamp":"2026-07-07T23:00:17.916516Z"}]}
{"channel":"book","type":"update","data":[{"symbol":"ETH/USD","bids":[],"asks":[{"price":1773.89,"qty":0.00000000},{"price":1774.13,"qty":0.50000000}],"checksum":3924176572,"timestamp":"2026-07-07T23:00:17.917475Z"}]}
{"channel":"book","type":"update","data":[{"symbol":"ETH/USD","bids":[],"asks":[{"price":1773.86,"qty":1.53128753}],"checksum":1187366049,"timestamp":"2026-07-07T23:00:17.918001Z"}]}
{"channel":"book","type":"update","data":[{"symbol":"ETH/USD","bids":[],"asks":[{"price":1773.85,"qty":0.47001888}],"checksum":1827513574,"timestamp":"2026-07-07T23:00:17.919337Z"}]}
{"channel":"book","type":"update","data":[{"symbol":"ETH/USD","bids":[{"price":1773.71,"qty":0.30991866}],"asks":[],"checksum":4094337554,"timestamp":"2026-07-07T23:00:17.919374Z"}]}
{"channel":"book","type":"update","data":[{"symbol":"ETH/USD","bids":[],"asks":[{"price":1773.84,"qty":1.53128753}],"checksum":757813116,"timestamp":"2026-07-07T23:00:17.920806Z"}]}
{"channel":"book","type":"update","data":[{"symbol":"ETH/USD","bids":[{"price":1773.73,"qty":2.81891832}],"asks":[],"checksum":3441656435,"timestamp":"2026-07-07T23:00:17.921023Z"}]}
{"channel":"book","type":"update","data":[{"symbol":"ETH/USD","bids":[],"asks":[{"price":1773.86,"qty":0.00000000},{"price":1774.11,"qty":0.50000000}],"checksum":4293208660,"timestamp":"2026-07-07T23:00:17.921709Z"}]}
{"channel":"book","type":"update","data":[{"symbol":"ETH/USD","bids":[],"asks":[{"price":1773.91,"qty":0.14097691}],"checksum":3293076634,"timestamp":"2026-07-07T23:00:17.931035Z"}]}
{"channel":"book","type":"update","data":[{"symbol":"ETH/USD","bids":[{"price":1773.72,"qty":0.60205737}],"asks":[],"checksum":627707015,"timestamp":"2026-07-07T23:00:17.931836Z"}]}
{"channel":"book","type":"update","data":[{"symbol":"ETH/USD","bids":[{"price":1773.55,"qty":28.18790011}],"asks":[],"checksum":2843791424,"timestamp":"2026-07-07T23:00:18.006169Z"}]}
{"channel":"book","type":"update","data":[{"symbol":"ETH/USD","bids":[{"price":1773.62,"qty":3.68540029}],"asks":[],"checksum":3980335509,"timestamp":"2026-07-07T23:00:18.007363Z"}]}
{"channel":"book","type":"update","data":[{"symbol":"ETH/USD","bids":[{"price":1773.62,"qty":0.00000000},{"price":1773.47,"qty":1.68966976}],"asks":[],"checksum":923941938,"timestamp":"2026-07-07T23:00:18.007420Z"}]}
{"channel":"book","type":"update","data":[{"symbol":"ETH/USD","bids":[{"price":1773.73,"qty":0.00000000},{"price":1773.46,"qty":0.48930000}],"asks":[],"checksum":1164537122,"timestamp":"2026-07-07T23:00:18.008318Z"}]}
{"channel":"book","type":"update","data":[{"symbol":"ETH/USD","bids":[],"asks":[{"price":1774.04,"qty":0.38794601}],"checksum":1586621104,"timestamp":"2026-07-07T23:00:18.010109Z"}]}
{"channel":"book","type":"update","data":[{"symbol":"ETH/USD","bids":[{"price":1773.64,"qty":2.15967029}],"asks":[],"checksum":1447216029,"timestamp":"2026-07-07T23:00:18.010491Z"}]}
{"channel":"book","type":"update","data":[{"symbol":"ETH/USD","bids":[{"price":1773.62,"qty":12.05919865}],"asks":[],"checksum":1643775182,"timestamp":"2026-07-07T23:00:18.010521Z"}]}
{"channel":"book","type":"update","data":[{"symbol":"ETH/USD","bids":[{"price":1773.63,"qty":5.61641602}],"asks":[],"checksum":1162939844,"timestamp":"2026-07-07T23:00:18.010749Z"}]}
{"channel":"book","type":"update","data":[{"symbol":"ETH/USD","bids":[{"price":1773.48,"qty":0.65042247}],"asks":[],"checksum":1286150770,"timestamp":"2026-07-07T23:00:18.010783Z"}]}
{"channel":"book","type":"update","data":[{"symbol":"ETH/USD","bids":[{"price":1773.72,"qty":0.11275737}],"asks":[],"checksum":1110358654,"timestamp":"2026-07-07T23:00:18.010812Z"}]}
{"channel":"book","type":"update","data":[{"symbol":"ETH/USD","bids":[],"asks":[{"price":1774.03,"qty":0.00000000},{"price":1774.11,"qty":0.50000000}],"checksum":4288412238,"timestamp":"2026-07-07T23:00:18.011445Z"}]}
{"channel":"book","type":"update","data":[{"symbol":"ETH/USD","bids":[],"asks":[{"price":1773.98,"qty":2.81852191}],"checksum":1893831818,"timestamp":"2026-07-07T23:00:18.011643Z"}]}
{"channel":"book","type":"update","data":[{"symbol":"ETH/USD","bids":[{"price":1773.68,"qty":2.81899093}],"asks":[],"checksum":2089885318,"timestamp":"2026-07-07T23:00:18.011910Z"}]}
{"channel":"book","type":"update","data":[{"symbol":"ETH/USD","bids":[{"price":1773.63,"qty":5.56003448}],"asks":[],"checksum":564066778,"timestamp":"2026-07-07T23:00:18.016128Z"}]}
{"channel":"book","type":"update","data":[{"symbol":"ETH/USD","bids":[],"asks":[{"price":1773.88,"qty":0.00000000},{"price":1774.11,"qty":0.50000000}],"checksum":2079100746,"timestamp":"2026-07-07T23:00:18.018936Z"}]}
{"channel":"book","type":"update","data":[{"symbol":"ETH/USD","bids":[],"asks":[{"price":1773.87,"qty":0.00000000},{"price":1774.12,"qty":0.50000000}],"checksum":3356210411,"timestamp":"2026-07-07T23:00:18.020196Z"}]}
{"channel":"book","type":"update","data":[{"symbol":"ETH/USD","bids":[],"asks":[{"price":1773.83,"qty":0.47001888}],"checksum":1091684470,"timestamp":"2026-07-07T23:00:18.021510Z"}]}
{"channel":"book","type":"update","data":[{"symbol":"BTC/USD","bids":[{"price":63482.4,"qty":0.78761951}],"asks":[],"checksum":2235968295,"timestamp":"2026-07-07T23:00:18.058399Z"}]}
{"channel":"book","type":"update","data":[{"symbol":"ETH/USD","bids":[{"price":1773.69,"qty":2.79963908}],"asks":[],"checksum":2816359484,"timestamp":"2026-07-07T23:00:18.074829Z"}]}
{"channel":"book","type":"update","data":[{"symbol":"ETH/USD","bids":[{"price":1773.64,"qty":0.50000000}],"asks":[],"checksum":563508855,"timestamp":"2026-07-07T23:00:18.075048Z"}]}
{"channel":"book","type":"update","data":[{"symbol":"ETH/USD","bids":[],"asks":[{"price":1773.85,"qty":0.00000000},{"price":1774.12,"qty":0.50000000}],"checksum":2720677335,"timestamp":"2026-07-07T23:00:18.122499Z"}]}
{"channel":"book","type":"update","data":[{"symbol":"ETH/USD","bids":[],"asks":[{"price":1773.98,"qty":0.00000000},{"price":1774.13,"qty":0.50000000}],"checksum":4248836890,"timestamp":"2026-07-07T23:00:18.186894Z"}]}
{"channel":"book","type":"update","data":[{"symbol":"ETH/USD","bids":[{"price":1773.68,"qty":0.00000000},{"price":1773.54,"qty":28.76501262}],"asks":[],"checksum":4071083585,"timestamp":"2026-07-07T23:00:18.187095Z"}]}
{"channel":"book","type":"update","data":[{"symbol":"ETH/USD","bids":[],"asks":[{"price":1774.04,"qty":3.20638193}],"checksum":2677564178,"timestamp":"2026-07-07T23:00:18.188662Z"}]}
{"channel":"book","type":"update","data":[{"symbol":"ETH/USD","bids":[{"price":1773.73,"qty":2.81891832}],"asks":[],"checksum":3917225994,"timestamp":"2026-07-07T23:00:18.188968Z"}]}
{"channel":"book","type":"update","data":[{"symbol":"ETH/USD","bids":[{"price":1773.69,"qty":0.00000000},{"price":1773.54,"qty":28.76501262}],"asks":[],"checksum":3734402210,"timestamp":"2026-07-07T23:00:18.190125Z"}]}
{"channel":"book","type":"update","data":[{"symbol":"ETH/USD","bids":[{"price":1773.69,"qty":1.95817029}],"asks":[],"checksum":1947714103,"timestamp":"2026-07-07T23:00:18.190355Z"}]}
{"channel":"book","type":"update","data":[{"symbol":"ETH/USD","bids":[{"price":1773.72,"qty":0.00000000},{"price":1773.54,"qty":28.76501262}],"asks":[],"checksum":2069853887,"timestamp":"2026-07-07T23:00:18.205647Z"}]}
{"channel":"book","type":"update","data":[{"symbol":"ETH/USD","bids":[],"asks":[{"price":1774.03,"qty":0.95710501}],"checksum":1509808702,"timestamp":"2026-07-07T23:00:18.208557Z"}]}
{"channel":"book","type":"update","data":[{"symbol":"ETH/USD","bids":[{"price":1773.73,"qty":0.00000000},{"price":1773.51,"qty":0.65042247}],"asks":[],"checksum":3543859018,"timestamp":"2026-07-07T23:00:18.218090Z"}]}
{"channel":"book","type":"update","data":[{"symbol":"ETH/USD","bids":[],"asks":[{"price":1774.04,"qty":0.38794601}],"checksum":2864369139,"timestamp":"2026-07-07T23:00:18.219280Z"}]}
{"channel":"book","type":"update","data":[{"symbol":"ETH/USD","bids":[{"price":1773.71,"qty":0.79921866}],"asks":[],"checksum":3579556684,"timestamp":"2026-07-07T23:00:18.219352Z"}]}
{"channel":"book","type":"update","data":[{"symbol":"ETH/USD","bids":[],"asks":[{"price":1774.03,"qty":0.00000000},{"price":1774.13,"qty":0.50000000}],"checksum":1633555472,"timestamp":"2026-07-07T23:00:18.220331Z"}]}
{"channel":"book","type":"update","data":[{"symbol":"ETH/USD","bids":[{"price":1773.72,"qty":0.48930000}],"asks":[],"checksum":4237022675,"timestamp":"2026-07-07T23:00:18.221459Z"}]}
{"channel":"book","type":"update","data":[{"symbol":"ETH/USD","bids":[{"price":1773.71,"qty":0.30991866}],"asks":[],"checksum":236468229,"timestamp":"2026-07-07T23:00:18.221475Z"}]}
{"channel":"trade","type":"update","data":[{"symbol":"ETH/USD","side":"buy","price":1773.83,"qty":0.00563748,"ord_type":"market","trade_id":64175818,"timestamp":"2026-07-07T23:00:18.273341Z"}]}
{"channel":"book","type":"update","data":[{"symbol":"ETH/USD","bids":[],"asks":[{"price":1773.83,"qty":0.46438140}],"checksum":3925773864,"timestamp":"2026-07-07T23:00:18.273341Z"}]}
{"channel":"book","type":"update","data":[{"symbol":"BTC/USD","bids":[],"asks":[{"price":63498.1,"qty":2.13405050}],"checksum":2076027835,"timestamp":"2026-07-07T23:00:18.403559Z"}]}
{"channel":"book","type":"update","data":[{"symbol":"BTC/USD","bids":[],"asks":[{"price":63498.1,"qty":2.71341550}],"checksum":2222328585,"timestamp":"2026-07-07T23:00:18.501657Z"}]}
{"channel":"book","type":"update","data":[{"symbol":"ETH/USD","bids":[{"price":1773.69,"qty":0.00000000},{"price":1773.51,"qty":0.65042247}],"asks":[],"checksum":1437622710,"timestamp":"2026-07-07T23:00:18.532219Z"}]}
{"channel":"book","type":"update","data":[{"symbol":"ETH/USD","bids":[],"asks":[{"price":1773.96,"qty":2.81856104}],"checksum":2118161276,"timestamp":"2026-07-07T23:00:18.532390Z"}]}
{"channel":"book","type":"update","data":[{"symbol":"ETH/USD","bids":[{"price":1773.68,"qty":2.81899082}],"asks":[],"checksum":2096143597,"timestamp":"2026-07-07T23:00:18.532671Z"}]}
{"channel":"book","type":"update","data":[{"symbol":"ETH/USD","bids":[{"price":1773.64,"qty":2.15967029}],"asks":[],"checksum":2167883630,"timestamp":"2026-07-07T23:00:18.533456Z"}]}
{"channel":"book","type":"update","data":[{"symbol":"ETH/USD","bids":[],"asks":[{"price":1774.09,"qty":22.86774469}],"checksum":1450821321,"timestamp":"2026-07-07T23:00:18.534013Z"}]}
{"channel":"book","type":"update","data":[{"symbol":"ETH/USD","bids":[{"price":1773.54,"qty":0.57284095}],"asks":[],"checksum":549110084,"timestamp":"2026-07-07T23:00:18.546623Z"}]}
{"channel":"book","type":"update","data":[{"symbol":"ETH/USD","bids":[{"price":1773.63,"qty":0.00000000},{"price":1773.51,"qty":0.65042247}],"asks":[],"checksum":3434370818,"timestamp":"2026-07-07T23:00:18.547897Z"}]}
{"channel":"book","type":"update","data":[{"symbol":"ETH/USD","bids":[{"price":1773.64,"qty":0.50000000}],"asks":[],"checksum":2536267782,"timestamp":"2026-07-07T23:00:18.549140Z"}]}
{"channel":"heartbeat"}
{"channel":"book","type":"update","data":[{"symbol":"ETH/USD","bids":[],"asks":[{"price":1773.96,"qty":0.00000000},{"price":1774.13,"qty":0.50000000}],"checksum":1393256839,"timestamp":"2026-07-07T23:00:18.660795Z"}]}
{"channel":"book","type":"update","data":[{"symbol":"ETH/USD","bids":[],"asks":[{"price":1773.93,"qty":2.81861155}],"checksum":450045374,"timestamp":"2026-07-07T23:00:18.662623Z"}]}
{"channel":"book","type":"update","data":[{"symbol":"ETH/USD","bids":[{"price":1773.51,"qty":8.98300002}],"asks":[],"checksum":521201233,"timestamp":"2026-07-07T23:00:18.741813Z"}]}
{"channel":"book","type":"update","data":[{"symbol":"ETH/USD","bids":[{"price":1773.72,"qty":0.00000000},{"price":1773.47,"qty":1.68966976}],"asks":[],"checksum":171645491,"timestamp":"2026-07-07T23:00:18.872325Z"}]}
{"channel":"book","type":"update","data":[{"symbol":"BTC/USD","bids":[],"asks":[{"price":63498.1,"qty":2.13405050}],"checksum":2076027835,"timestamp":"2026-07-07T23:00:18.903273Z"}]}
{"channel":"book","type":"update","data":[{"symbol":"ETH/USD","bids":[{"price":1773.64,"qty":0.00000000},{"price":1773.46,"qty":28.68270963}],"asks":[],"checksum":1785382517,"timestamp":"2026-07-07T23:00:18.906781Z"}]}
{"channel":"book","type":"update","data":[{"symbol":"ETH/USD","bids":[{"price":1773.63,"qty":5.56003448}],"asks":[],"checksum":335965081,"timestamp":"2026-07-07T23:00:18.908207Z"}]}
{"channel":"book","type":"update","data":[{"symbol":"BTC/USD","bids":[],"asks":[{"price":63498.1,"qty":2.71341150}],"checksum":2242497341,"timestamp":"2026-07-07T23:00:19.003290Z"}]}
{"channel":"book","type":"update","data":[{"symbol":"ETH/USD","bids":[{"price":1773.63,"qty":5.61641602}],"asks":[],"checksum":656058760,"timestamp":"2026-07-07T23:00:19.078387Z"}]}
{"channel":"book","type":"update","data":[{"symbol":"ETH/USD","bids":[],"asks":[{"price":1773.93,"qty":0.00000000},{"price":1774.13,"qty":0.50000000}],"checksum":3630443825,"timestamp":"2026-07-07T23:00:19.121374Z"}]}
{"channel":"book","type":"update","data":[{"symbol":"ETH/USD","bids":[],"asks":[{"price":1773.99,"qty":2.81850701}],"checksum":1795310848,"timestamp":"2026-07-07T23:00:19.122887Z"}]}
{"channel":"book","type":"update","data":[{"symbol":"BTC/USD","bids":[{"price":63482.4,"qty":0.00000000},{"price":63479.1,"qty":0.03608734}],"asks":[],"checksum":3063206784,"timestamp":"2026-07-07T23:00:19.145413Z"}]}
{"channel":"book","type":"update","data":[{"symbol":"BTC/USD","bids":[{"price":63483.7,"qty":0.00000000},{"price":63478.9,"qty":0.03147178}],"asks":[],"checksum":1521593412,"timestamp":"2026-07-07T23:00:19.145437Z"}]}
{"channel":"book","type":"update","data":[{"symbol":"BTC/USD","bids":[{"price":63483.1,"qty":0.78761112}],"asks":[],"checksum":183949924,"timestamp":"2026-07-07T23:00:19.147453Z"}]}
{"channel":"book","type":"update","data":[{"symbol":"BTC/USD","bids":[{"price":63480.9,"qty":0.78763726}],"asks":[],"checksum":724121576,"timestamp":"2026-07-07T23:00:19.147663Z"}]}
{"channel":"book","type":"update","data":[{"symbol":"BTC/USD","bids":[{"price":63481.0,"qty":0.26243213}],"asks":[],"checksum":118896832,"timestamp":"2026-07-07T23:00:19.150975Z"}]}
{"channel":"book","type":"update","data":[{"symbol":"ETH/USD","bids":[{"price":1773.71,"qty":0.79921866}],"asks":[],"checksum":350436287,"timestamp":"2026-07-07T23:00:19.156350Z"}]}
{"channel":"book","type":"update","data":[{"symbol":"ETH/USD","bids":[{"price":1773.72,"qty":0.48930000}],"asks":[],"checksum":771915378,"timestamp":"2026-07-07T23:00:19.157528Z"}]}
{"channel":"book","type":"update","data":[{"symbol":"BTC/USD","bids":[{"price":63485.2,"qty":0.05990000}],"asks":[],"checksum":3444328264,"timestamp":"2026-07-07T23:00:19.160175Z"}]}
{"channel":"book","type":"update","data":[{"symbol":"BTC/USD","bids":[],"asks":[{"price":63498.1,"qty":2.13405050}],"checksum":221755344,"timestamp":"2026-07-07T23:00:19.162323Z"}]}
{"channel":"book","type":"update","data":[{"symbol":"BTC/USD","bids":[{"price":63483.1,"qty":0.00000000},{"price":63481.0,"qty":0.26243213}],"asks":[],"checksum":410908052,"timestamp":"2026-07-07T23:00:19.163657Z"}]}
{"channel":"book","type":"update","data":[{"symbol":"BTC/USD","bids":[{"price":63485.2,"qty":0.66460924}],"asks":[],"checksum":3574592497,"timestamp":"2026-07-07T23:00:19.165408Z"}]}
{"channel":"book","type":"update","data":[{"symbol":"ETH/USD","bids":[{"price":1773.68,"qty":0.00000000},{"price":1773.47,"qty":1.68966976}],"asks":[],"checksum":2834298161,"timestamp":"2026-07-07T23:00:19.167205Z"}]}
{"channel":"book","type":"update","data":[{"symbol":"ETH/USD","bids":[],"asks":[{"price":1773.99,"qty":0.00000000},{"price":1774.13,"qty":0.50000000}],"checksum":2835213001,"timestamp":"2026-07-07T23:00:19.167360Z"}]}
{"channel":"book","type":"update","data":[{"symbol":"BTC/USD","bids":[],"asks":[{"price":63498.1,"qty":2.03907204}],"checksum":351776143,"timestamp":"2026-07-07T23:00:19.167484Z"}]}
{"channel":"book","type":"update","data":[{"symbol":"BTC/USD","bids":[{"price":63481.0,"qty":0.00000000},{"price":63478.9,"qty":0.03147178}],"asks":[],"checksum":2597633849,"timestamp":"2026-07-07T23:00:19.171189Z"}]}
{"channel":"book","type":"update","data":[{"symbol":"BTC/USD","bids":[{"price":63478.9,"qty":0.00000000},{"price":63478.8,"qty":0.05990000},{"price":63481.1,"qty":0.03147178}],"asks":[],"checksum":345590106,"timestamp":"2026-07-07T23:00:19.172147Z"}]}
{"channel":"book","type":"update","data":[{"symbol":"BTC/USD","bids":[{"price":63481.1,"qty":0.00000000},{"price":63479.0,"qty":0.02732241}],"asks":[],"checksum":931602916,"timestamp":"2026-07-07T23:00:19.174875Z"}]}
{"channel":"book","type":"update","data":[{"symbol":"ETH/USD","bids":[],"asks":[{"price":1774.13,"qty":12.85426731}],"checksum":1400857033,"timestamp":"2026-07-07T23:00:19.175382Z"}]}
{"channel":"book","type":"update","data":[{"symbol":"ETH/USD","bids":[{"price":1773.55,"qty":0.00000000},{"price":1773.46,"qty":0.48930000}],"asks":[],"checksum":2400471142,"timestamp":"2026-07-07T23:00:19.175397Z"}]}
{"channel":"book","type":"update","data":[{"symbol":"BTC/USD","bids":[{"price":63481.2,"qty":0.02732241}],"asks":[],"checksum":1064427276,"timestamp":"2026-07-07T23:00:19.175503Z"}]}
{"channel":"book","type":"update","data":[{"symbol":"ETH/USD","bids":[{"price":1773.64,"qty":1.67650018}],"asks":[],"checksum":2761777287,"timestamp":"2026-07-07T23:00:19.176217Z"}]}
{"channel":"book","type":"update","data":[{"symbol":"ETH/USD","bids":[{"price":1773.51,"qty":0.65042247}],"asks":[],"checksum":3673793192,"timestamp":"2026-07-07T23:00:19.176448Z"}]}
{"channel":"book","type":"update","data":[{"symbol":"ETH/USD","bids":[],"asks":[{"price":1774.04,"qty":3.20638134}],"checksum":3105167557,"timestamp":"2026-07-07T23:00:19.176498Z"}]}
{"channel":"book","type":"update","data":[{"symbol":"ETH/USD","bids":[{"price":1773.73,"qty":2.81891832}],"asks":[],"checksum":3349692999,"timestamp":"2026-07-07T23:00:19.176671Z"}]}
{"channel":"book","type":"update","data":[{"symbol":"ETH/USD","bids":[{"price":1773.55,"qty":28.19193113}],"asks":[],"checksum":580538013,"timestamp":"2026-07-07T23:00:19.176721Z"}]}
{"channel":"book","type":"update","data":[{"symbol":"ETH/USD","bids":[{"price":1773.63,"qty":0.05638154}],"asks":[],"checksum":3870221930,"timestamp":"2026-07-07T23:00:19.178151Z"}]}
{"channel":"book","type":"update","data":[{"symbol":"ETH/USD","bids":[{"price":1773.80,"qty":0.48930000}],"asks":[],"checksum":2497798323,"timestamp":"2026-07-07T23:00:19.178981Z"}]}
{"channel":"book","type":"update","data":[{"symbol":"ETH/USD","bids":[{"price":1773.62,"qty":0.00000000},{"price":1773.54,"qty":0.57284095}],"asks":[],"checksum":352053298,"timestamp":"2026-07-07T23:00:19.179508Z"}]}
{"channel":"book","type":"update","data":[{"symbol":"BTC/USD","bids":[],"asks":[{"price":63498.1,"qty":2.01694122}],"checksum":3007483303,"timestamp":"2026-07-07T23:00:19.179572Z"}]}
{"channel":"book","type":"update","data":[{"symbol":"ETH/USD","bids":[{"price":1773.64,"qty":0.00000000},{"price":1773.51,"qty":0.65042247}],"asks":[],"checksum":3055984180,"timestamp":"2026-07-07T23:00:19.181535Z"}]}
{"channel":"book","type":"update","data":[{"symbol":"ETH/USD","bids":[{"price":1773.74,"qty":0.98750317}],"asks":[],"checksum":3371445719,"timestamp":"2026-07-07T23:00:19.181572Z"}]}
{"channel":"book","type":"update","data":[{"symbol":"ETH/USD","bids":[{"price":1773.63,"qty":0.00000000},{"price":1773.51,"qty":0.65042247}],"asks":[],"checksum":2719079663,"timestamp":"2026-07-07T23:00:19.181864Z"}]}
{"channel":"book","type":"update","data":[{"symbol":"ETH/USD","bids":[{"price":1773.72,"qty":0.00000000},{"price":1773.47,"qty":1.68966976}],"asks":[],"checksum":1893100897,"timestamp":"2026-07-07T23:00:19.182055Z"}]}
{"channel":"book","type":"update","data":[{"symbol":"BTC/USD","bids":[{"price":63481.2,"qty":0.25894363}],"asks":[],"checksum":3225351480,"timestamp":"2026-07-07T23:00:19.182192Z"}]}
{"channel":"book","type":"update","data":[{"symbol":"ETH/USD","bids":[{"price":1773.62,"qty":14.51036354}],"asks":[],"checksum":1940731476,"timestamp":"2026-07-07T23:00:19.183215Z"}]}
{"channel":"book","type":"update","data":[{"symbol":"ETH/USD","bids":[],"asks":[{"price":1773.92,"qty":0.00000000},{"price":1774.14,"qty":0.98930000}],"checksum":1082469853,"timestamp":"2026-07-07T23:00:19.193323Z"}]}
{"channel":"book","type":"update","data":[{"symbol":"ETH/USD","bids":[{"price":1773.74,"qty":0.00000000},{"price":1773.47,"qty":1.68966976}],"asks":[],"checksum":1445591980,"timestamp":"2026-07-07T23:00:19.202206Z"}]}
{"channel":"book","type":"update","data":[{"symbol":"ETH/USD","bids":[{"price":1773.63,"qty":5.56003448}],"asks":[],"checksum":116093338,"timestamp":"2026-07-07T23:00:19.203515Z"}]}
{"channel":"book","type":"update","data":[{"symbol":"ETH/USD","bids":[{"price":1773.64,"qty":1.65967029}],"asks":[],"checksum":1494800828,"timestamp":"2026-07-07T23:00:19.205109Z"}]}
{"channel":"book","type":"update","data":[{"symbol":"ETH/USD","bids":[{"price":1773.80,"qty":0.00000000},{"price":1773.51,"qty":0.65042247}],"asks":[],"checksum":3965610200,"timestamp":"2026-07-07T23:00:19.214128Z"}]}
{"channel":"book","type":"update","data":[{"symbol":"ETH/USD","bids":[{"price":1773.76,"qty":0.48930000}],"asks":[],"checksum":1943520267,"timestamp":"2026-07-07T23:00:19.216523Z"}]}
{"channel":"book","type":"update","data":[{"symbol":"ETH/USD","bids":[{"price":1773.73,"qty":0.00000000},{"price":1773.51,"qty":0.65042247}],"asks":[],"checksum":2310654023,"timestamp":"2026-07-07T23:00:19.216632Z"}]}
{"channel":"book","type":"update","data":[{"symbol":"ETH/USD","bids":[{"price":1773.71,"qty":0.30991866}],"asks":[],"checksum":2965625238,"timestamp":"2026-07-07T23:00:19.216813Z"}]}
{"channel":"book","type":"update","data":[{"symbol":"ETH/USD","bids":[],"asks":[{"price":1773.99,"qty":4.71459584}],"checksum":519686329,"timestamp":"2026-07-07T23:00:19.221788Z"}]}
{"channel":"book","type":"update","data":[{"symbol":"ETH/USD","bids":[{"price":1773.54,"qty":0.00000000},{"price":1773.47,"qty":1.68966976}],"asks":[],"checksum":4267467670,"timestamp":"2026-07-07T23:00:19.226817Z"}]}
{"channel":"book","type":"update","data":[{"symbol":"ETH/USD","bids":[{"price":1773.68,"qty":0.57284095}],"asks":[],"checksum":3349017238,"timestamp":"2026-07-07T23:00:19.227122Z"}]}
{"channel":"book","type":"update","data":[{"symbol":"BTC/USD","bids":[],"asks":[{"price":63498.1,"qty":2.59630622}],"checksum":3354283900,"timestamp":"2026-07-07T23:00:19.265002Z"}]}
{"channel":"book","type":"update","data":[{"symbol":"BTC/USD","bids":[],"asks":[{"price":63498.1,"qty":2.61843704}],"checksum":4294140765,"timestamp":"2026-07-07T23:00:19.267935Z"}]}
