{"channel":"book","type":"update","data":[{"symbol":"ETH/USD","bids":[],"asks":[{"price":1774.01,"qty":0.28355973}],"checksum":2951959360,"timestamp":"2026-07-07T23:00:19.318935Z"}]}
{"channel":"book","type":"update","data":[{"symbol":"ETH/USD","bids":[{"price":1773.77,"qty":0.27406994}],"asks":[],"checksum":655631257,"timestamp":"2026-07-07T23:00:19.318950Z"}]}
{"channel":"book","type":"update","data":[{"symbol":"ETH/USD","bids":[{"price":1773.71,"qty":0.00000000},{"price":1773.51,"qty":0.65042247}],"asks":[],"checksum":3278652304,"timestamp":"2026-07-07T23:00:19.320223Z"}]}
{"channel":"book","type":"update","data":[{"symbol":"ETH/USD","bids":[{"price":1773.72,"qty":2.81893287}],"asks":[],"checksum":1680273610,"timestamp":"2026-07-07T23:00:19.320623Z"}]}
{"channel":"book","type":"update","data":[{"symbol":"ETH/USD","bids":[{"price":1773.63,"qty":0.00000000},{"price":1773.51,"qty":0.65042247}],"asks":[],"checksum":3057522633,"timestamp":"2026-07-07T23:00:19.321875Z"}]}
{"channel":"book","type":"update","data":[{"symbol":"ETH/USD","bids":[{"price":1773.64,"qty":0.00000000},{"price":1773.47,"qty":1.68966976}],"asks":[],"checksum":571391643,"timestamp":"2026-07-07T23:00:19.323544Z"}]}
{"channel":"book","type":"update","data":[{"symbol":"ETH/USD","bids":[{"price":1773.76,"qty":0.00000000},{"price":1773.46,"qty":0.48930000}],"asks":[],"checksum":330041805,"timestamp":"2026-07-07T23:00:19.344957Z"}]}
{"channel":"book","type":"update","data":[{"symbol":"ETH/USD","bids":[{"price":1773.63,"qty":5.56003448}],"asks":[],"checksum":1688705631,"timestamp":"2026-07-07T23:00:19.346218Z"}]}
{"channel":"book","type":"update","data":[{"symbol":"BTC/USD","bids":[{"price":63485.2,"qty":0.60470924}],"asks":[],"checksum":3346425996,"timestamp":"2026-07-07T23:00:19.347458Z"}]}
{"channel":"book","type":"update","data":[{"symbol":"BTC/USD","bids":[],"asks":[{"price":63500.0,"qty":0.06026266}],"checksum":2121351127,"timestamp":"2026-07-07T23:00:19.421390Z"}]}
{"channel":"book","type":"update","data":[{"symbol":"BTC/USD","bids":[],"asks":[{"price":63498.1,"qty":2.55750347}],"checksum":2841788669,"timestamp":"2026-07-07T23:00:19.421854Z"}]}
{"channel":"book","type":"update","data":[{"symbol":"ETH/USD","bids":[],"asks":[{"price":1774.10,"qty":0.00000000},{"price":1774.13,"qty":12.85426731}],"checksum":4214065136,"timestamp":"2026-07-07T23:00:19.473497Z"}]}
{"channel":"book","type":"update","data":[{"symbol":"ETH/USD","bids":[{"price":1773.77,"qty":0.76336994}],"asks":[],"checksum":2262014770,"timestamp":"2026-07-07T23:00:19.474777Z"}]}
{"channel":"book","type":"update","data":[{"symbol":"ETH/USD","bids":[],"asks":[{"price":1774.09,"qty":20.70183308}],"checksum":3161657434,"timestamp":"2026-07-07T23:00:19.474990Z"}]}
{"channel":"book","type":"update","data":[{"symbol":"BTC/USD","bids":[{"price":63485.2,"qty":0.66460924}],"asks":[],"checksum":2447854380,"timestamp":"2026-07-07T23:00:19.475773Z"}]}
{"channel":"book","type":"update","data":[{"symbol":"ETH/USD","bids":[{"price":1773.78,"qty":0.48930000}],"asks":[],"checksum":243320338,"timestamp":"2026-07-07T23:00:19.477010Z"}]}
{"channel":"book","type":"update","data":[{"symbol":"ETH/USD","bids":[],"asks":[{"price":1773.99,"qty":0.00000000},{"price":1774.14,"qty":0.98930000}],"checksum":1651727738,"timestamp":"2026-07-07T23:00:19.477325Z"}]}
{"channel":"book","type":"update","data":[{"symbol":"ETH/USD","bids":[{"price":1773.73,"qty":0.84145146}],"asks":[],"checksum":123376752,"timestamp":"2026-07-07T23:00:19.478356Z"}]}
{"channel":"book","type":"update","data":[{"symbol":"ETH/USD","bids":[{"price":1773.73,"qty":0.00000000},{"price":1773.51,"qty":0.65042247}],"asks":[],"checksum":1651727738,"timestamp":"2026-07-07T23:00:19.478530Z"}]}
{"channel":"book","type":"update","data":[{"symbol":"ETH/USD","bids":[],"asks":[{"price":1774.04,"qty":0.38794601}],"checksum":2392826173,"timestamp":"2026-07-07T23:00:19.479688Z"}]}
{"channel":"book","type":"update","data":[{"symbol":"ETH/USD","bids":[],"asks":[{"price":1774.13,"qty":0.50000000}],"checksum":2259926332,"timestamp":"2026-07-07T23:00:19.480123Z"}]}
{"channel":"book","type":"update","data":[{"symbol":"ETH/USD","bids":[],"asks":[{"price":1774.03,"qty":0.95710483}],"checksum":3967445797,"timestamp":"2026-07-07T23:00:19.480364Z"}]}
{"channel":"book","type":"update","data":[{"symbol":"ETH/USD","bids":[],"asks":[{"price":1774.03,"qty":0.00000000},{"price":1774.14,"qty":0.98930000}],"checksum":2259926332,"timestamp":"2026-07-07T23:00:19.481368Z"}]}
{"channel":"book","type":"update","data":[{"symbol":"ETH/USD","bids":[],"asks":[{"price":1774.01,"qty":3.10204474}],"checksum":123923597,"timestamp":"2026-07-07T23:00:19.481639Z"}]}
{"channel":"book","type":"update","data":[{"symbol":"ETH/USD","bids":[],"asks":[{"price":1774.09,"qty":15.64420000}],"checksum":667643172,"timestamp":"2026-07-07T23:00:19.482449Z"}]}
{"channel":"book","type":"update","data":[{"symbol":"ETH/USD","bids":[],"asks":[{"price":1774.08,"qty":5.49683932}],"checksum":1184361840,"timestamp":"2026-07-07T23:00:19.483896Z"}]}
{"channel":"book","type":"update","data":[{"symbol":"ETH/USD","bids":[{"price":1773.64,"qty":1.65967029}],"asks":[],"checksum":641504559,"timestamp":"2026-07-07T23:00:19.523290Z"}]}
{"channel":"heartbeat"}
{"channel":"book","type":"update","data":[{"symbol":"ETH/USD","bids":[{"price":1773.77,"qty":0.27406994}],"asks":[],"checksum":1356240285,"timestamp":"2026-07-07T23:00:19.632757Z"}]}
{"channel":"book","type":"update","data":[{"symbol":"ETH/USD","bids":[],"asks":[{"price":1773.95,"qty":0.30869817}],"checksum":736022353,"timestamp":"2026-07-07T23:00:19.718325Z"}]}
{"channel":"book","type":"update","data":[{"symbol":"ETH/USD","bids":[],"asks":[{"price":1774.01,"qty":2.81848501}],"checksum":4155431672,"timestamp":"2026-07-07T23:00:19.719506Z"}]}
{"channel":"book","type":"update","data":[{"symbol":"ETH/USD","bids":[{"price":1773.78,"qty":0.00000000},{"price":1773.51,"qty":0.65042247}],"asks":[],"checksum":1724515871,"timestamp":"2026-07-07T23:00:19.796631Z"}]}
{"channel":"book","type":"update","data":[{"symbol":"ETH/USD","bids":[{"price":1773.78,"qty":0.48930000}],"asks":[],"checksum":4155431672,"timestamp":"2026-07-07T23:00:19.912466Z"}]}
{"channel":"book","type":"update","data":[{"symbol":"ETH/USD","bids":[{"price":1773.77,"qty":0.76336994}],"asks":[],"checksum":2168773194,"timestamp":"2026-07-07T23:00:19.912525Z"}]}
{"channel":"book","type":"update","data":[{"symbol":"BTC/USD","bids":[{"price":63485.3,"qty":0.19838586}],"asks":[],"checksum":656538577,"timestamp":"2026-07-07T23:00:19.929541Z"}]}
{"channel":"book","type":"update","data":[{"symbol":"BTC/USD","bids":[],"asks":[{"price":63499.0,"qty":2.00000000}],"checksum":2718478966,"timestamp":"2026-07-07T23:00:20.001024Z"}]}
{"channel":"book","type":"update","data":[{"symbol":"ETH/USD","bids":[{"price":1773.73,"qty":0.05637836}],"asks":[],"checksum":1660778007,"timestamp":"2026-07-07T23:00:20.013285Z"}]}
{"channel":"book","type":"update","data":[{"symbol":"BTC/USD","bids":[],"asks":[{"price":63498.1,"qty":1.97813847}],"checksum":584154584,"timestamp":"2026-07-07T23:00:20.037651Z"}]}
{"channel":"book","type":"update","data":[{"symbol":"BTC/USD","bids":[{"price":63486.4,"qty":0.78756968}],"asks":[],"checksum":820168624,"timestamp":"2026-07-07T23:00:20.057807Z"}]}
{"channel":"book","type":"update","data":[{"symbol":"ETH/USD","bids":[{"price":1773.77,"qty":0.27406994}],"asks":[],"checksum":3100880958,"timestamp":"2026-07-07T23:00:20.063813Z"}]}
{"channel":"book","type":"update","data":[{"symbol":"ETH/USD","bids":[{"price":1773.62,"qty":18.72761918}],"asks":[],"checksum":715138965,"timestamp":"2026-07-07T23:00:20.105176Z"}]}
{"channel":"book","type":"update","data":[{"symbol":"ETH/USD","bids":[{"price":1773.82,"qty":0.62790976}],"asks":[],"checksum":2079933021,"timestamp":"2026-07-07T23:00:20.120670Z"}]}
{"channel":"book","type":"update","data":[{"symbol":"BTC/USD","bids":[],"asks":[{"price":63498.1,"qty":2.55749747}],"checksum":1140231347,"timestamp":"2026-07-07T23:00:20.137890Z"}]}
{"channel":"book","type":"update","data":[{"symbol":"ETH/USD","bids":[{"price":1773.82,"qty":0.00000000},{"price":1773.61,"qty":19.84616104}],"asks":[],"checksum":715138965,"timestamp":"2026-07-07T23:00:20.190605Z"}]}
{"channel":"book","type":"update","data":[{"symbol":"ETH/USD","bids":[],"asks":[{"price":1773.95,"qty":0.00000000},{"price":1774.13,"qty":0.50000000}],"checksum":569816202,"timestamp":"2026-07-07T23:00:20.285358Z"}]}
{"channel":"book","type":"update","data":[{"symbol":"ETH/USD","bids":[],"asks":[{"price":1773.84,"qty":0.00000000},{"price":1774.14,"qty":0.98930000}],"checksum":450666349,"timestamp":"2026-07-07T23:00:20.285530Z"}]}
{"channel":"book","type":"update","data":[{"symbol":"ETH/USD","bids":[],"asks":[{"price":1773.83,"qty":0.00000000},{"price":1774.16,"qty":0.28137208}],"checksum":52727824,"timestamp":"2026-07-07T23:00:20.287094Z"}]}
{"channel":"trade","type":"update","data":[{"symbol":"BTC/USD","side":"buy","price":63498.1,"qty":0.00001982,"ord_type":"limit","trade_id":103436778,"timestamp":"2026-07-07T23:00:20.287196Z"}]}
{"channel":"book","type":"update","data":[{"symbol":"BTC/USD","bids":[],"asks":[{"price":63498.1,"qty":2.55747765}],"checksum":2611035468,"timestamp":"2026-07-07T23:00:20.287196Z"}]}
{"channel":"book","type":"update","data":[{"symbol":"ETH/USD","bids":[],"asks":[{"price":1774.00,"qty":0.47001888}],"checksum":180185539,"timestamp":"2026-07-07T23:00:20.366279Z"}]}
{"channel":"book","type":"update","data":[{"symbol":"ETH/USD","bids":[],"asks":[{"price":1773.90,"qty":1.53128753}],"checksum":52519544,"timestamp":"2026-07-07T23:00:20.385356Z"}]}
{"channel":"book","type":"update","data":[{"symbol":"ETH/USD","bids":[{"price":1773.72,"qty":0.00000000},{"price":1773.55,"qty":28.19193113}],"asks":[],"checksum":804824813,"timestamp":"2026-07-07T23:00:20.386762Z"}]}
{"channel":"book","type":"update","data":[{"symbol":"ETH/USD","bids":[],"asks":[{"price":1773.89,"qty":0.47001888}],"checksum":495121490,"timestamp":"2026-07-07T23:00:20.386799Z"}]}
{"channel":"book","type":"update","data":[{"symbol":"ETH/USD","bids":[{"price":1773.75,"qty":2.81888328}],"asks":[],"checksum":1699977481,"timestamp":"2026-07-07T23:00:20.388225Z"}]}
{"channel":"book","type":"update","data":[{"symbol":"ETH/USD","bids":[],"asks":[{"price":1773.88,"qty":1.53128753}],"checksum":1790383851,"timestamp":"2026-07-07T23:00:20.388279Z"}]}
{"channel":"book","type":"update","data":[{"symbol":"ETH/USD","bids":[{"price":1773.73,"qty":0.00000000},{"price":1773.55,"qty":28.19193113},{"price":1773.69,"qty":0.05637963}],"asks":[],"checksum":3707103009,"timestamp":"2026-07-07T23:00:20.390722Z"}]}
{"channel":"book","type":"update","data":[{"symbol":"ETH/USD","bids":[],"asks":[{"price":1773.97,"qty":0.34096408}],"checksum":300009244,"timestamp":"2026-07-07T23:00:20.434489Z"}]}
{"channel":"book","type":"update","data":[{"symbol":"ETH/USD","bids":[{"price":1773.78,"qty":1.41254654}],"asks":[],"checksum":2212421305,"timestamp":"2026-07-07T23:00:20.435794Z"}]}
{"channel":"book","type":"update","data":[{"symbol":"ETH/USD","bids":[{"price":1773.84,"qty":0.48930000}],"asks":[],"checksum":3133447520,"timestamp":"2026-07-07T23:00:20.436890Z"}]}
{"channel":"book","type":"update","data":[{"symbol":"ETH/USD","bids":[],"asks":[{"price":1774.01,"qty":0.00000000},{"price":1774.11,"qty":0.50000000}],"checksum":36089016,"timestamp":"2026-07-07T23:00:20.473488Z"}]}
{"channel":"book","type":"update","data":[{"symbol":"ETH/USD","bids":[{"price":1773.78,"qty":0.48930000}],"asks":[],"checksum":587885292,"timestamp":"2026-07-07T23:00:20.485978Z"}]}
{"channel":"book","type":"update","data":[{"symbol":"ETH/USD","bids":[],"asks":[{"price":1774.00,"qty":0.00000000},{"price":1774.12,"qty":0.50000000}],"checksum":2012096671,"timestamp":"2026-07-07T23:00:20.487798Z"}]}
{"channel":"book","type":"update","data":[{"symbol":"ETH/USD","bids":[],"asks":[{"price":1773.90,"qty":0.00000000},{"price":1774.13,"qty":0.50000000}],"checksum":1877748180,"timestamp":"2026-07-07T23:00:20.489110Z"}]}
{"channel":"book","type":"update","data":[{"symbol":"ETH/USD","bids":[],"asks":[{"price":1773.87,"qty":0.47001888}],"checksum":3355371750,"timestamp":"2026-07-07T23:00:20.490513Z"}]}
{"channel":"book","type":"update","data":[{"symbol":"ETH/USD","bids":[],"asks":[{"price":1773.86,"qty":1.53128753}],"checksum":3091091801,"timestamp":"2026-07-07T23:00:20.492573Z"}]}
{"channel":"book","type":"update","data":[{"symbol":"ETH/USD","bids":[{"price":1773.84,"qty":0.00000000},{"price":1773.61,"qty":19.84616104}],"asks":[],"checksum":2984793894,"timestamp":"2026-07-07T23:00:20.493752Z"}]}
{"channel":"book","type":"update","data":[{"symbol":"ETH/USD","bids":[],"asks":[{"price":1774.11,"qty":3.31832646}],"checksum":3436273109,"timestamp":"2026-07-07T23:00:20.531528Z"}]}
{"channel":"book","type":"update","data":[{"symbol":"ETH/USD","bids":[{"price":1773.78,"qty":1.41254654}],"asks":[],"checksum":1639683127,"timestamp":"2026-07-07T23:00:20.531605Z"}]}
{"channel":"book","type":"update","data":[{"symbol":"ETH/USD","bids":[{"price":1773.80,"qty":0.48930000}],"asks":[],"checksum":3946022954,"timestamp":"2026-07-07T23:00:20.532851Z"}]}
{"channel":"heartbeat"}
{"channel":"book","type":"update","data":[{"symbol":"BTC/USD","bids":[],"asks":[{"price":63498.1,"qty":1.97811865}],"checksum":2449948958,"timestamp":"2026-07-07T23:00:20.569631Z"}]}
{"channel":"book","type":"update","data":[{"symbol":"ETH/USD","bids":[],"asks":[{"price":1773.89,"qty":0.00000000},{"price":1774.12,"qty":0.50000000}],"checksum":1971185056,"timestamp":"2026-07-07T23:00:20.591582Z"}]}
{"channel":"book","type":"update","data":[{"symbol":"ETH/USD","bids":[],"asks":[{"price":1773.85,"qty":0.47001888}],"checksum":1579482408,"timestamp":"2026-07-07T23:00:20.593041Z"}]}
{"channel":"book","type":"update","data":[{"symbol":"ETH/USD","bids":[],"asks":[{"price":1773.88,"qty":0.00000000},{"price":1774.12,"qty":0.50000000}],"checksum":49547984,"timestamp":"2026-07-07T23:00:20.593788Z"}]}
{"channel":"book","type":"update","data":[{"symbol":"ETH/USD","bids":[],"asks":[{"price":1773.86,"qty":0.00000000},{"price":1774.13,"qty":0.50000000}],"checksum":1788307583,"timestamp":"2026-07-07T23:00:20.594321Z"}]}
{"channel":"book","type":"update","data":[{"symbol":"ETH/USD","bids":[],"asks":[{"price":1774.11,"qty":0.50000000}],"checksum":3988219957,"timestamp":"2026-07-07T23:00:20.595128Z"}]}
{"channel":"book","type":"update","data":[{"symbol":"ETH/USD","bids":[],"asks":[{"price":1773.85,"qty":0.00000000},{"price":1774.14,"qty":0.98930000}],"checksum":973416017,"timestamp":"2026-07-07T23:00:20.595543Z"}]}
{"channel":"book","type":"update","data":[{"symbol":"ETH/USD","bids":[],"asks":[{"price":1774.04,"qty":1.91923354}],"checksum":1048331330,"timestamp":"2026-07-07T23:00:20.595649Z"}]}
{"channel":"book","type":"update","data":[{"symbol":"ETH/USD","bids":[],"asks":[{"price":1774.07,"qty":2.81838129}],"checksum":1102323856,"timestamp":"2026-07-07T23:00:20.596900Z"}]}
{"channel":"book","type":"update","data":[{"symbol":"ETH/USD","bids":[],"asks":[{"price":1774.07,"qty":5.11585339}],"checksum":2572032554,"timestamp":"2026-07-07T23:00:20.596933Z"}]}
{"channel":"book","type":"update","data":[{"symbol":"ETH/USD","bids":[],"asks":[{"price":1773.86,"qty":1.53128753}],"checksum":1457101815,"timestamp":"2026-07-07T23:00:20.597148Z"}]}
{"channel":"book","type":"update","data":[{"symbol":"ETH/USD","bids":[],"asks":[{"price":1773.85,"qty":0.47001888}],"checksum":3735068153,"timestamp":"2026-07-07T23:00:20.598586Z"}]}
{"channel":"book","type":"update","data":[{"symbol":"ETH/USD","bids":[],"asks":[{"price":1773.86,"qty":0.00000000},{"price":1774.12,"qty":0.50000000}],"checksum":3143942211,"timestamp":"2026-07-07T23:00:20.599713Z"}]}
{"channel":"book","type":"update","data":[{"symbol":"ETH/USD","bids":[],"asks":[{"price":1773.85,"qty":0.00000000},{"price":1774.13,"qty":0.50000000}],"checksum":2572032554,"timestamp":"2026-07-07T23:00:20.601144Z"}]}
{"channel":"book","type":"update","data":[{"symbol":"ETH/USD","bids":[],"asks":[{"price":1773.86,"qty":1.53128753}],"checksum":1457101815,"timestamp":"2026-07-07T23:00:20.602462Z"}]}
{"channel":"book","type":"update","data":[{"symbol":"ETH/USD","bids":[],"asks":[{"price":1773.85,"qty":0.47001888}],"checksum":3735068153,"timestamp":"2026-07-07T23:00:20.603743Z"}]}
{"channel":"book","type":"update","data":[{"symbol":"ETH/USD","bids":[],"asks":[{"price":1773.86,"qty":0.00000000},{"price":1774.12,"qty":0.50000000}],"checksum":3143942211,"timestamp":"2026-07-07T23:00:20.604990Z"}]}
{"channel":"book","type":"update","data":[{"symbol":"ETH/USD","bids":[],"asks":[{"price":1773.85,"qty":0.00000000},{"price":1774.13,"qty":0.50000000}],"checksum":2572032554,"timestamp":"2026-07-07T23:00:20.606161Z"}]}
{"channel":"book","type":"update","data":[{"symbol":"ETH/USD","bids":[{"price":1773.80,"qty":0.60205228}],"asks":[],"checksum":3954603157,"timestamp":"2026-07-07T23:00:20.607737Z"}]}
{"channel":"book","type":"update","data":[{"symbol":"ETH/USD","bids":[],"asks":[{"price":1773.86,"qty":1.53128753}],"checksum":606205256,"timestamp":"2026-07-07T23:00:20.607772Z"}]}
{"channel":"book","type":"update","data":[{"symbol":"ETH/USD","bids":[],"asks":[{"price":1773.85,"qty":0.47001888}],"checksum":2891510598,"timestamp":"2026-07-07T23:00:20.609753Z"}]}
{"channel":"book","type":"update","data":[{"symbol":"ETH/USD","bids":[],"asks":[{"price":1773.86,"qty":0.00000000},{"price":1774.12,"qty":0.50000000}],"checksum":3382488828,"timestamp":"2026-07-07T23:00:20.611374Z"}]}
{"channel":"book","type":"update","data":[{"symbol":"ETH/USD","bids":[],"asks":[{"price":1773.85,"qty":0.00000000},{"price":1774.13,"qty":0.50000000}],"checksum":3954603157,"timestamp":"2026-07-07T23:00:20.612566Z"}]}
{"channel":"book","type":"update","data":[{"symbol":"ETH/USD","bids":[],"asks":[{"price":1773.86,"qty":1.53128753}],"checksum":606205256,"timestamp":"2026-07-07T23:00:20.613862Z"}]}
{"channel":"book","type":"update","data":[{"symbol":"ETH/USD","bids":[],"asks":[{"price":1773.85,"qty":0.47001888}],"checksum":2891510598,"timestamp":"2026-07-07T23:00:20.614928Z"}]}
{"channel":"book","type":"update","data":[{"symbol":"ETH/USD","bids":[],"asks":[{"price":1773.86,"qty":0.00000000},{"price":1774.12,"qty":0.50000000}],"checksum":3382488828,"timestamp":"2026-07-07T23:00:20.616063Z"}]}
{"channel":"book","type":"update","data":[{"symbol":"ETH/USD","bids":[],"asks":[{"price":1773.85,"qty":0.00000000},{"price":1774.13,"qty":0.50000000}],"checksum":3954603157,"timestamp":"2026-07-07T23:00:20.617984Z"}]}
{"channel":"book","type":"update","data":[{"symbol":"ETH/USD","bids":[],"asks":[{"price":1773.86,"qty":1.53128753}],"checksum":606205256,"timestamp":"2026-07-07T23:00:20.619556Z"}]}
{"channel":"book","type":"update","data":[{"symbol":"ETH/USD","bids":[],"asks":[{"price":1773.85,"qty":0.47001888}],"checksum":2891510598,"timestamp":"2026-07-07T23:00:20.621673Z"}]}
{"channel":"book","type":"update","data":[{"symbol":"ETH/USD","bids":[{"price":1773.80,"qty":0.48930000}],"asks":[],"checksum":3735068153,"timestamp":"2026-07-07T23:00:20.623049Z"}]}
{"channel":"book","type":"update","data":[{"symbol":"ETH/USD","bids":[],"asks":[{"price":1773.86,"qty":0.00000000},{"price":1774.12,"qty":0.50000000}],"checksum":3143942211,"timestamp":"2026-07-07T23:00:20.624125Z"}]}
{"channel":"book","type":"update","data":[{"symbol":"ETH/USD","bids":[],"asks":[{"price":1773.85,"qty":0.00000000},{"price":1774.13,"qty":0.50000000}],"checksum":2572032554,"timestamp":"2026-07-07T23:00:20.627505Z"}]}
{"channel":"book","type":"update","data":[{"symbol":"ETH/USD","bids":[],"asks":[{"price":1773.86,"qty":1.53128753}],"checksum":1457101815,"timestamp":"2026-07-07T23:00:20.629651Z"}]}
{"channel":"book","type":"update","data":[{"symbol":"ETH/USD","bids":[],"asks":[{"price":1773.85,"qty":0.47001888}],"checksum":3735068153,"timestamp":"2026-07-07T23:00:20.631896Z"}]}
{"channel":"book","type":"update","data":[{"symbol":"ETH/USD","bids":[],"asks":[{"price":1773.86,"qty":0.00000000},{"price":1774.12,"qty":0.50000000}],"checksum":3143942211,"timestamp":"2026-07-07T23:00:20.633888Z"}]}
{"channel":"book","type":"update","data":[{"symbol":"ETH/USD","bids":[],"asks":[{"price":1773.85,"qty":0.00000000},{"price":1774.13,"qty":0.50000000}],"checksum":2572032554,"timestamp":"2026-07-07T23:00:20.635072Z"}]}
{"channel":"book","type":"update","data":[{"symbol":"ETH/USD","bids":[],"asks":[{"price":1773.86,"qty":1.53128753}],"checksum":1457101815,"timestamp":"2026-07-07T23:00:20.636776Z"}]}
{"channel":"book","type":"update","data":[{"symbol":"ETH/USD","bids":[],"asks":[{"price":1773.85,"qty":0.47001888}],"checksum":3735068153,"timestamp":"2026-07-07T23:00:20.638221Z"}]}
{"channel":"book","type":"update","data":[{"symbol":"ETH/USD","bids":[],"asks":[{"price":1773.86,"qty":0.00000000},{"price":1774.12,"qty":0.50000000}],"checksum":3143942211,"timestamp":"2026-07-07T23:00:20.639382Z"}]}
{"channel":"book","type":"update","data":[{"symbol":"ETH/USD","bids":[],"asks":[{"price":1773.85,"qty":0.00000000},{"price":1774.13,"qty":0.50000000}],"checksum":2572032554,"timestamp":"2026-07-07T23:00:20.640759Z"}]}
{"channel":"book","type":"update","data":[{"symbol":"ETH/USD","bids":[],"asks":[{"price":1773.86,"qty":1.53128753}],"checksum":1457101815,"timestamp":"2026-07-07T23:00:20.642553Z"}]}
{"channel":"book","type":"update","data":[{"symbol":"ETH/USD","bids":[],"asks":[{"price":1773.85,"qty":0.47001888}],"checksum":3735068153,"timestamp":"2026-07-07T23:00:20.644802Z"}]}
{"channel":"book","type":"update","data":[{"symbol":"ETH/USD","bids":[],"asks":[{"price":1773.86,"qty":0.00000000},{"price":1774.12,"qty":0.50000000}],"checksum":3143942211,"timestamp":"2026-07-07T23:00:20.645960Z"}]}
{"channel":"book","type":"update","data":[{"symbol":"ETH/USD","bids":[],"asks":[{"price":1773.85,"qty":0.00000000},{"price":1774.13,"qty":0.50000000}],"checksum":2572032554,"timestamp":"2026-07-07T23:00:20.647260Z"}]}
{"channel":"book","type":"update","data":[{"symbol":"ETH/USD","bids":[],"asks":[{"price":1774.07,"qty":2.81838129}],"checksum":1102323856,"timestamp":"2026-07-07T23:00:20.647312Z"}]}
{"channel":"book","type":"update","data":[{"symbol":"ETH/USD","bids":[],"asks":[{"price":1773.87,"qty":0.00000000},{"price":1774.14,"qty":0.98930000}],"checksum":1705560654,"timestamp":"2026-07-07T23:00:20.647512Z"}]}
{"channel":"book","type":"update","data":[{"symbol":"ETH/USD","bids":[],"asks":[{"price":1774.04,"qty":0.38794601}],"checksum":4125711922,"timestamp":"2026-07-07T23:00:20.648378Z"}]}
{"channel":"book","type":"update","data":[{"symbol":"ETH/USD","bids":[{"price":1773.70,"qty":1.68966976}],"asks":[],"checksum":2118435444,"timestamp":"2026-07-07T23:00:20.648605Z"}]}
{"channel":"book","type":"update","data":[{"symbol":"ETH/USD","bids":[{"price":1773.64,"qty":0.00000000},{"price":1773.62,"qty":18.72761918}],"asks":[],"checksum":2409906173,"timestamp":"2026-07-07T23:00:20.649743Z"}]}
{"channel":"book","type":"update","data":[{"symbol":"ETH/USD","bids":[{"price":1773.71,"qty":2.50110906}],"asks":[],"checksum":1147301984,"timestamp":"2026-07-07T23:00:20.649984Z"}]}
{"channel":"book","type":"update","data":[{"symbol":"BTC/USD","bids":[],"asks":[{"price":63498.1,"qty":2.55747865}],"checksum":4004739093,"timestamp":"2026-07-07T23:00:20.670017Z"}]}
{"channel":"book","type":"update","data":[{"symbol":"ETH/USD","bids":[{"price":1773.78,"qty":0.92324654}],"asks":[],"checksum":3073176134,"timestamp":"2026-07-07T23:00:20.684503Z"}]}
{"channel":"book","type":"update","data":[{"symbol":"ETH/USD","bids":[],"asks":[{"price":1773.96,"qty":0.47001888}],"checksum":1083543505,"timestamp":"2026-07-07T23:00:20.747679Z"}]}
{"channel":"book","type":"update","data":[{"symbol":"ETH/USD","bids":[{"price":1773.78,"qty":0.00000000},{"price":1773.62,"qty":18.72761918}],"asks":[],"checksum":1627508960,"timestamp":"2026-07-07T23:00:20.822041Z"}]}
{"channel":"book","type":"update","data":[{"symbol":"ETH/USD","bids":[],"asks":[{"price":1774.07,"qty":0.00000000},{"price":1774.14,"qty":0.98930000}],"checksum":2189166099,"timestamp":"2026-07-07T23:00:20.839517Z"}]}
{"channel":"book","type":"update","data":[{"symbol":"ETH/USD","bids":[],"asks":[{"price":1774.02,"qty":2.81846076}],"checksum":1750024996,"timestamp":"2026-07-07T23:00:20.841348Z"}]}
{"channel":"book","type":"update","data":[{"symbol":"ETH/USD","bids":[{"price":1773.72,"qty":0.05637868}],"asks":[],"checksum":2352819033,"timestamp":"2026-07-07T23:00:21.013861Z"}]}
{"channel":"book","type":"update","data":[{"symbol":"BTC/USD","bids":[{"price":63484.5,"qty":0.78759339}],"asks":[],"checksum":1581004007,"timestamp":"2026-07-07T23:00:21.057864Z"}]}
{"channel":"book","type":"update","data":[{"symbol":"ETH/USD","bids":[{"price":1773.80,"qty":0.00000000},{"price":1773.62,"qty":18.72761918}],"asks":[],"checksum":3978530906,"timestamp":"2026-07-07T23:00:21.156528Z"}]}
{"channel":"book","type":"update","data":[{"symbol":"ETH/USD","bids":[{"price":1773.76,"qty":0.85826570}],"asks":[],"checksum":358613903,"timestamp":"2026-07-07T23:00:21.157745Z"}]}
{"channel":"book","type":"update","data":[{"symbol":"ETH/USD","bids":[{"price":1773.77,"qty":0.76336994}],"asks":[],"checksum":2394586424,"timestamp":"2026-07-07T23:00:21.205744Z"}]}
{"channel":"book","type":"update","data":[{"symbol":"BTC/USD","bids":[],"asks":[{"price":63498.1,"qty":1.97811865}],"checksum":3381811542,"timestamp":"2026-07-07T23:00:21.206105Z"}]}
{"channel":"book","type":"update","data":[{"symbol":"BTC/USD","bids":[{"price":63498.0,"qty":1.05577987}],"asks":[],"checksum":3380737595,"timestamp":"2026-07-07T23:00:21.221527Z"}]}
{"channel":"book","type":"update","data":[{"symbol":"BTC/USD","bids":[],"asks":[{"price":63498.1,"qty":2.55747765}],"checksum":1290625183,"timestamp":"2026-07-07T23:00:21.306166Z"}]}
{"channel":"trade","type":"update","data":[{"symbol":"ETH/USD","side":"sell","price":1773.77,"qty":0.00563748,"ord_type":"market","trade_id":64175819,"timestamp":"2026-07-07T23:00:21.337848Z"}]}
{"channel":"book","type":"update","data":[{"symbol":"ETH/USD","bids":[{"price":1773.77,"qty":0.75773246}],"asks":[],"checksum":1480281921,"timestamp":"2026-07-07T23:00:21.337848Z"}]}
{"channel":"book","type":"update","data":[{"symbol":"BTC/USD","bids":[],"asks":[{"price":63498.1,"qty":2.44747765}],"checksum":2186964822,"timestamp":"2026-07-07T23:00:21.348427Z"}]}
{"channel":"book","type":"update","data":[{"symbol":"ETH/USD","bids":[{"price":1773.78,"qty":0.48930000}],"asks":[],"checksum":1015868324,"timestamp":"2026-07-07T23:00:21.352674Z"}]}
{"channel":"book","type":"update","data":[{"symbol":"ETH/USD","bids":[{"price":1773.78,"qty":0.98930000}],"asks":[],"checksum":1649146412,"timestamp":"2026-07-07T23:00:21.355445Z"}]}
{"channel":"book","type":"update","data":[{"symbol":"BTC/USD","bids":[],"asks":[{"price":63498.1,"qty":1.86811865}],"checksum":121043442,"timestamp":"2026-07-07T23:00:21.355596Z"}]}
{"channel":"book","type":"update","data":[{"symbol":"ETH/USD","bids":[],"asks":[{"price":1774.02,"qty":0.00000000},{"price":1774.14,"qty":0.98930000}],"checksum":459597519,"timestamp":"2026-07-07T23:00:21.356666Z"}]}
{"channel":"book","type":"update","data":[{"symbol":"ETH/USD","bids":[{"price":1773.82,"qty":0.48930000}],"asks":[],"checksum":807012039,"timestamp":"2026-07-07T23:00:21.357666Z"}]}
{"channel":"book","type":"update","data":[{"symbol":"ETH/USD","bids":[{"price":1773.78,"qty":0.50000000}],"asks":[],"checksum":3000518944,"timestamp":"2026-07-07T23:00:21.358341Z"}]}
{"channel":"book","type":"update","data":[{"symbol":"ETH/USD","bids":[],"asks":[{"price":1774.08,"qty":8.31521720}],"checksum":3814281710,"timestamp":"2026-07-07T23:00:21.358602Z"}]}
{"channel":"book","type":"update","data":[{"symbol":"ETH/USD","bids":[{"price":1773.71,"qty":10.59487425}],"asks":[],"checksum":631107827,"timestamp":"2026-07-07T23:00:21.365386Z"}]}
{"channel":"book","type":"update","data":[{"symbol":"BTC/USD","bids":[],"asks":[{"price":63498.5,"qty":0.92771336}],"checksum":2799215060,"timestamp":"2026-07-07T23:00:21.365987Z"}]}
{"channel":"book","type":"update","data":[{"symbol":"ETH/USD","bids":[],"asks":[{"price":1774.12,"qty":0.00000000},{"price":1774.16,"qty":1.81265961}],"checksum":3646995079,"timestamp":"2026-07-07T23:00:21.366862Z"}]}
{"channel":"book","type":"update","data":[{"symbol":"ETH/USD","bids":[],"asks":[{"price":1774.11,"qty":0.00000000},{"price":1774.19,"qty":8.73008660}],"checksum":1511564538,"timestamp":"2026-07-07T23:00:21.366882Z"}]}
{"channel":"book","type":"update","data":[{"symbol":"BTC/USD","bids":[{"price":63485.2,"qty":0.05990000}],"asks":[],"checksum":928784359,"timestamp":"2026-07-07T23:00:21.398208Z"}]}
{"channel":"book","type":"update","data":[{"symbol":"BTC/USD","bids":[{"price":63485.3,"qty":0.00000000},{"price":63483.2,"qty":0.02936327}],"asks":[],"checksum":3390792676,"timestamp":"2026-07-07T23:00:21.400955Z"}]}
{"channel":"book","type":"update","data":[{"symbol":"BTC/USD","bids":[{"price":63486.5,"qty":0.25296970}],"asks":[],"checksum":1075117261,"timestamp":"2026-07-07T23:00:21.402759Z"}]}
{"channel":"book","type":"update","data":[{"symbol":"ETH/USD","bids":[{"price":1773.82,"qty":0.82063228}],"asks":[],"checksum":2584630071,"timestamp":"2026-07-07T23:00:21.426463Z"}]}
{"channel":"book","type":"update","data":[{"symbol":"BTC/USD","bids":[],"asks":[{"price":63499.1,"qty":0.00000000},{"price":63501.7,"qty":2.55057649}],"checksum":335990261,"timestamp":"2026-07-07T23:00:21.427469Z"}]}
{"channel":"book","type":"update","data":[{"symbol":"ETH/USD","bids":[{"price":1773.77,"qty":0.48930000}],"asks":[],"checksum":4133235879,"timestamp":"2026-07-07T23:00:21.427635Z"}]}
{"channel":"book","type":"update","data":[{"symbol":"ETH/USD","bids":[{"price":1773.83,"qty":0.48930000}],"asks":[],"checksum":1113975222,"timestamp":"2026-07-07T23:00:21.427846Z"}]}
{"channel":"book","type":"update","data":[{"symbol":"ETH/USD","bids":[],"asks":[{"price":1774.08,"qty":5.49683932}],"checksum":3253762370,"timestamp":"2026-07-07T23:00:21.428522Z"}]}
{"channel":"book","type":"update","data":[{"symbol":"ETH/USD","bids":[{"price":1773.82,"qty":0.33133228}],"asks":[],"checksum":2999483081,"timestamp":"2026-07-07T23:00:21.428660Z"}]}
{"channel":"book","type":"update","data":[{"symbol":"ETH/USD","bids":[],"asks":[{"price":1774.05,"qty":2.81841693}],"checksum":348137380,"timestamp":"2026-07-07T23:00:21.430116Z"}]}
{"channel":"book","type":"update","data":[{"symbol":"ETH/USD","bids":[{"price":1773.69,"qty":0.00000000},{"price":1773.68,"qty":0.57284095}],"asks":[],"checksum":2702613278,"timestamp":"2026-07-07T23:00:21.431939Z"}]}
{"channel":"book","type":"update","data":[{"symbol":"ETH/USD","bids":[{"price":1773.70,"qty":0.00000000},{"price":1773.65,"qty":6.06003448},{"price":1773.69,"qty":1.68966976}],"asks":[],"checksum":1471500937,"timestamp":"2026-07-07T23:00:21.433444Z"}]}
{"channel":"book","type":"update","data":[{"symbol":"ETH/USD","bids":[],"asks":[{"price":1773.97,"qty":0.00000000},{"price":1774.19,"qty":8.73008660}],"checksum":2688726369,"timestamp":"2026-07-07T23:00:21.436560Z"}]}
{"channel":"book","type":"update","data":[{"symbol":"ETH/USD","bids":[],"asks":[{"price":1773.96,"qty":0.00000000},{"price":1774.20,"qty":46.70976164}],"checksum":2617528372,"timestamp":"2026-07-07T23:00:21.437985Z"}]}
{"channel":"book","type":"update","data":[{"symbol":"ETH/USD","bids":[],"asks":[{"price":1774.03,"qty":0.47001888}],"checksum":2885519426,"timestamp":"2026-07-07T23:00:21.438190Z"}]}
{"channel":"book","type":"update","data":[{"symbol":"BTC/USD","bids":[{"price":63498.0,"qty":1.05266166}],"asks":[],"checksum":128557301,"timestamp":"2026-07-07T23:00:21.442897Z"}]}
{"channel":"book","type":"update","data":[{"symbol":"BTC/USD","bids":[],"asks":[{"price":63498.1,"qty":2.44747665}],"checksum":4192143185,"timestamp":"2026-07-07T23:00:21.453854Z"}]}
{"channel":"trade","type":"update","data":[{"symbol":"BTC/USD","side":"buy","price":63498.1,"qty":0.00001954,"ord_type":"limit","trade_id":103436779,"timestamp":"2026-07-07T23:00:21.478279Z"}]}
{"channel":"book","type":"update","data":[{"symbol":"BTC/USD","bids":[],"asks":[{"price":63498.1,"qty":2.44745711}],"checksum":3688338732,"timestamp":"2026-07-07T23:00:21.478279Z"}]}
{"channel":"book","type":"update","data":[{"symbol":"BTC/USD","bids":[{"price":63486.4,"qty":0.00000000},{"price":63483.2,"qty":0.02936327}],"asks":[],"checksum":3953796265,"timestamp":"2026-07-07T23:00:21.487487Z"}]}
{"channel":"book","type":"update","data":[{"symbol":"BTC/USD","bids":[{"price":63486.5,"qty":0.00000000},{"price":63481.5,"qty":0.00030000}],"asks":[],"checksum":990667966,"timestamp":"2026-07-07T23:00:21.488877Z"}]}
{"channel":"book","type":"update","data":[{"symbol":"BTC/USD","bids":[{"price":63487.0,"qty":0.78756171}],"asks":[],"checksum":2284365826,"timestamp":"2026-07-07T23:00:21.489042Z"}]}
{"channel":"book","type":"update","data":[{"symbol":"BTC/USD","bids":[{"price":63485.3,"qty":0.01788015}],"asks":[],"checksum":410870853,"timestamp":"2026-07-07T23:00:21.490246Z"}]}
{"channel":"book","type":"update","data":[{"symbol":"BTC/USD","bids":[{"price":63485.3,"qty":0.00000000},{"price":63483.2,"qty":0.02936327}],"asks":[],"checksum":2284365826,"timestamp":"2026-07-07T23:00:21.490537Z"}]}
{"channel":"book","type":"update","data":[{"symbol":"BTC/USD","bids":[{"price":63487.1,"qty":0.25296732}],"asks":[],"checksum":2877886669,"timestamp":"2026-07-07T23:00:21.492938Z"}]}
{"channel":"book","type":"update","data":[{"symbol":"ETH/USD","bids":[{"price":1773.83,"qty":0.00000000},{"price":1773.65,"qty":6.06003448}],"asks":[],"checksum":1251227603,"timestamp":"2026-07-07T23:00:21.507718Z"}]}
{"channel":"heartbeat"}
{"channel":"book","type":"update","data":[{"symbol":"ETH/USD","bids":[],"asks":[{"price":1773.96,"qty":0.31534426}],"checksum":3873760979,"timestamp":"2026-07-07T23:00:21.586503Z"}]}
{"channel":"book","type":"update","data":[{"symbol":"BTC/USD","bids":[],"asks":[{"price":63500.0,"qty":0.00000000},{"price":63504.0,"qty":0.00005100}],"checksum":1893551104,"timestamp":"2026-07-07T23:00:21.672247Z"}]}
{"channel":"book","type":"update","data":[{"symbol":"BTC/USD","bids":[],"asks":[{"price":63502.4,"qty":0.06003821}],"checksum":2909030686,"timestamp":"2026-07-07T23:00:21.672455Z"}]}
{"channel":"book","type":"update","data":[{"symbol":"ETH/USD","bids":[],"asks":[{"price":1774.05,"qty":0.00000000},{"price":1774.19,"qty":8.73008660}],"checksum":594376824,"timestamp":"2026-07-07T23:00:21.696803Z"}]}
{"channel":"book","type":"update","data":[{"symbol":"ETH/USD","bids":[],"asks":[{"price":1774.02,"qty":2.81847149}],"checksum":1995588161,"timestamp":"2026-07-07T23:00:21.698114Z"}]}
{"channel":"book","type":"update","data":[{"symbol":"ETH/USD","bids":[{"price":1773.76,"qty":0.00000000},{"price":1773.64,"qty":28.18602030}],"asks":[],"checksum":1824923285,"timestamp":"2026-07-07T23:00:21.700141Z"}]}
{"channel":"book","type":"update","data":[{"symbol":"ETH/USD","bids":[],"asks":[{"price":1774.01,"qty":0.47001888}],"checksum":1151310127,"timestamp":"2026-07-07T23:00:21.700167Z"}]}
{"channel":"book","type":"update","data":[{"symbol":"ETH/USD","bids":[{"price":1773.64,"qty":0.00000000},{"price":1773.62,"qty":18.72761918}],"asks":[],"checksum":1083696754,"timestamp":"2026-07-07T23:00:21.702447Z"}]}
{"channel":"book","type":"update","data":[{"symbol":"ETH/USD","bids":[{"price":1773.71,"qty":2.50110906}],"asks":[],"checksum":3277730451,"timestamp":"2026-07-07T23:00:21.704566Z"}]}
{"channel":"book","type":"update","data":[{"symbol":"ETH/USD","bids":[{"price":1773.65,"qty":0.50000000},{"price":1773.63,"qty":5.56003448}],"asks":[],"checksum":937158592,"timestamp":"2026-07-07T23:00:21.705089Z"}]}
{"channel":"book","type":"update","data":[{"symbol":"ETH/USD","bids":[{"price":1773.82,"qty":0.82063228}],"asks":[],"checksum":3580360984,"timestamp":"2026-07-07T23:00:21.706616Z"}]}
{"channel":"book","type":"update","data":[{"symbol":"ETH/USD","bids":[{"price":1773.83,"qty":0.48930000}],"asks":[],"checksum":469377618,"timestamp":"2026-07-07T23:00:21.707215Z"}]}
{"channel":"book","type":"update","data":[{"symbol":"ETH/USD","bids":[{"price":1773.82,"qty":0.33133228}],"asks":[],"checksum":1757553113,"timestamp":"2026-07-07T23:00:21.708138Z"}]}
{"channel":"book","type":"update","data":[{"symbol":"ETH/USD","bids":[{"price":1773.66,"qty":28.18646172}],"asks":[],"checksum":1028195374,"timestamp":"2026-07-07T23:00:21.732878Z"}]}
{"channel":"book","type":"update","data":[{"symbol":"ETH/USD","bids":[{"price":1773.71,"qty":10.57817670}],"asks":[],"checksum":4135913254,"timestamp":"2026-07-07T23:00:21.734250Z"}]}
{"channel":"book","type":"update","data":[{"symbol":"ETH/USD","bids":[{"price":1773.67,"qty":5.56003448}],"asks":[],"checksum":4139930279,"timestamp":"2026-07-07T23:00:21.734442Z"}]}
{"channel":"book","type":"update","data":[{"symbol":"BTC/USD","bids":[],"asks":[{"price":63498.1,"qty":2.47906355}],"checksum":3702196471,"timestamp":"2026-07-07T23:00:21.760537Z"}]}
{"channel":"book","type":"update","data":[{"symbol":"ETH/USD","bids":[],"asks":[{"price":1774.03,"qty":0.00000000},{"price":1774.16,"qty":1.81265961}],"checksum":4190854048,"timestamp":"2026-07-07T23:00:21.801282Z"}]}
{"channel":"book","type":"update","data":[{"symbol":"ETH/USD","bids":[{"price":1773.83,"qty":0.00000000},{"price":1773.66,"qty":28.18646172}],"asks":[],"checksum":1249401667,"timestamp":"2026-07-07T23:00:21.802888Z"}]}
{"channel":"book","type":"update","data":[{"symbol":"ETH/USD","bids":[{"price":1773.78,"qty":0.00000000},{"price":1773.65,"qty":0.50000000}],"asks":[],"checksum":1311638777,"timestamp":"2026-07-07T23:00:21.871775Z"}]}
{"channel":"book","type":"update","data":[{"symbol":"ETH/USD","bids":[{"price":1773.65,"qty":0.00000000},{"price":1773.62,"qty":18.72761918}],"asks":[],"checksum":1324346163,"timestamp":"2026-07-07T23:00:21.871954Z"}]}
{"channel":"book","type":"update","data":[{"symbol":"BTC/USD","bids":[],"asks":[{"price":63502.3,"qty":0.01200000}],"checksum":2170118623,"timestamp":"2026-07-07T23:00:21.930763Z"}]}
{"channel":"book","type":"update","data":[{"symbol":"ETH/USD","bids":[{"price":1773.82,"qty":0.82063228}],"asks":[],"checksum":3886049565,"timestamp":"2026-07-07T23:00:21.965522Z"}]}
{"channel":"book","type":"update","data":[{"symbol":"ETH/USD","bids":[],"asks":[{"price":1774.04,"qty":0.00000000},{"price":1774.19,"qty":8.73008660}],"checksum":3838181926,"timestamp":"2026-07-07T23:00:21.966558Z"}]}
{"channel":"book","type":"update","data":[{"symbol":"ETH/USD","bids":[{"price":1773.83,"qty":0.48930000}],"asks":[],"checksum":2278299515,"timestamp":"2026-07-07T23:00:21.967855Z"}]}
{"channel":"book","type":"update","data":[{"symbol":"ETH/USD","bids":[],"asks":[{"price":1774.18,"qty":0.37613300}],"checksum":1132221197,"timestamp":"2026-07-07T23:00:21.968291Z"}]}
{"channel":"book","type":"update","data":[{"symbol":"ETH/USD","bids":[{"price":1773.76,"qty":0.85826570}],"asks":[],"checksum":1118280519,"timestamp":"2026-07-07T23:00:21.971080Z"}]}
{"channel":"book","type":"update","data":[{"symbol":"ETH/USD","bids":[],"asks":[{"price":1774.02,"qty":0.00000000},{"price":1774.19,"qty":8.73008660}],"checksum":3982244096,"timestamp":"2026-07-07T23:00:21.978617Z"}]}
{"channel":"book","type":"update","data":[{"symbol":"ETH/USD","bids":[],"asks":[{"price":1774.06,"qty":2.81840587}],"checksum":308728825,"timestamp":"2026-07-07T23:00:21.980091Z"}]}
{"channel":"book","type":"update","data":[{"symbol":"BTC/USD","bids":[{"price":63487.1,"qty":0.28286190}],"asks":[],"checksum":3183545213,"timestamp":"2026-07-07T23:00:21.982002Z"}]}
{"channel":"book","type":"update","data":[{"symbol":"ETH/USD","bids":[],"asks":[{"price":1774.13,"qty":0.00000000},{"price":1774.19,"qty":8.73008660}],"checksum":3280271253,"timestamp":"2026-07-07T23:00:21.983221Z"}]}
{"channel":"book","type":"update","data":[{"symbol":"ETH/USD","bids":[],"asks":[{"price":1774.06,"qty":0.00000000},{"price":1774.22,"qty":1.30000000}],"checksum":2930802253,"timestamp":"2026-07-07T23:00:21.983851Z"}]}
{"channel":"book","type":"update","data":[{"symbol":"ETH/USD","bids":[{"price":1773.75,"qty":0.00000000},{"price":1773.66,"qty":28.18646172}],"asks":[],"checksum":2349258192,"timestamp":"2026-07-07T23:00:21.983955Z"}]}
{"channel":"book","type":"update","data":[{"symbol":"BTC/USD","bids":[{"price":63487.0,"qty":0.00000000},{"price":63481.5,"qty":0.00030000}],"asks":[],"checksum":2039263975,"timestamp":"2026-07-07T23:00:21.984584Z"}]}
{"channel":"book","type":"update","data":[{"symbol":"BTC/USD","bids":[{"price":63484.5,"qty":0.00000000},{"price":63481.2,"qty":0.29041541}],"asks":[],"checksum":4100227644,"timestamp":"2026-07-07T23:00:21.984752Z"}]}
{"channel":"book","type":"update","data":[{"symbol":"ETH/USD","bids":[],"asks":[{"price":1774.19,"qty":11.24376978}],"checksum":2509425387,"timestamp":"2026-07-07T23:00:21.985412Z"}]}
{"channel":"book","type":"update","data":[{"symbol":"ETH/USD","bids":[{"price":1773.79,"qty":2.81882076}],"asks":[],"checksum":2600449437,"timestamp":"2026-07-07T23:00:21.986101Z"}]}
{"channel":"book","type":"update","data":[{"symbol":"ETH/USD","bids":[],"asks":[{"price":1774.19,"qty":2.51368318}],"checksum":2502813372,"timestamp":"2026-07-07T23:00:21.986118Z"}]}
{"channel":"book","type":"update","data":[{"symbol":"ETH/USD","bids":[{"price":1773.76,"qty":0.00000000},{"price":1773.66,"qty":28.18646172}],"asks":[],"checksum":1062045199,"timestamp":"2026-07-07T23:00:21.986572Z"}]}
{"channel":"book","type":"update","data":[{"symbol":"BTC/USD","bids":[{"price":63487.7,"qty":0.78755352}],"asks":[],"checksum":1422424376,"timestamp":"2026-07-07T23:00:21.986688Z"}]}
{"channel":"book","type":"update","data":[{"symbol":"BTC/USD","bids":[{"price":63485.6,"qty":0.78757925}],"asks":[],"checksum":3425812760,"timestamp":"2026-07-07T23:00:21.987181Z"}]}
{"channel":"book","type":"update","data":[{"symbol":"BTC/USD","bids":[{"price":63487.1,"qty":0.02989458}],"asks":[],"checksum":2439489209,"timestamp":"2026-07-07T23:00:21.987757Z"}]}
{"channel":"book","type":"update","data":[{"symbol":"ETH/USD","bids":[],"asks":[{"price":1773.96,"qty":0.00000000},{"price":1774.25,"qty":7.12104918}],"checksum":1826398863,"timestamp":"2026-07-07T23:00:21.988799Z"}]}
{"channel":"book","type":"update","data":[{"symbol":"BTC/USD","bids":[{"price":63487.8,"qty":0.31949480}],"asks":[],"checksum":3833517349,"timestamp":"2026-07-07T23:00:22.044199Z"}]}
{"channel":"book","type":"update","data":[{"symbol":"ETH/USD","bids":[],"asks":[{"price":1774.07,"qty":2.81838645}],"checksum":3590918914,"timestamp":"2026-07-07T23:00:22.058541Z"}]}
{"channel":"book","type":"update","data":[{"symbol":"ETH/USD","bids":[{"price":1773.79,"qty":0.00000000},{"price":1773.62,"qty":18.72761918}],"asks":[],"checksum":585786026,"timestamp":"2026-07-07T23:00:22.074232Z"}]}
{"channel":"book","type":"update","data":[{"symbol":"ETH/USD","bids":[],"asks":[{"price":1774.07,"qty":0.00000000},{"price":1774.25,"qty":7.12104918}],"checksum":2975418502,"timestamp":"2026-07-07T23:00:22.074242Z"}]}
{"channel":"book","type":"update","data":[{"symbol":"ETH/USD","bids":[{"price":1773.75,"qty":2.81888291}],"asks":[],"checksum":1552502123,"timestamp":"2026-07-07T23:00:22.075904Z"}]}
{"channel":"book","type":"update","data":[{"symbol":"ETH/USD","bids":[{"price":1773.76,"qty":0.85826558}],"asks":[],"checksum":142937218,"timestamp":"2026-07-07T23:00:22.078639Z"}]}
{"channel":"book","type":"update","data":[{"symbol":"ETH/USD","bids":[{"price":1773.76,"qty":0.91464299}],"asks":[],"checksum":4069263490,"timestamp":"2026-07-07T23:00:22.080197Z"}]}
{"channel":"book","type":"update","data":[{"symbol":"ETH/USD","bids":[{"price":1773.77,"qty":0.00000000},{"price":1773.66,"qty":28.18646172}],"asks":[],"checksum":2539575901,"timestamp":"2026-07-07T23:00:22.118281Z"}]}
{"channel":"book","type":"update","data":[{"symbol":"ETH/USD","bids":[{"price":1773.82,"qty":0.33133228}],"asks":[],"checksum":1909705027,"timestamp":"2026-07-07T23:00:22.120580Z"}]}
{"channel":"book","type":"update","data":[{"symbol":"ETH/USD","bids":[{"price":1773.83,"qty":0.00000000},{"price":1773.62,"qty":18.72761918}],"asks":[],"checksum":1938638668,"timestamp":"2026-07-07T23:00:22.121659Z"}]}
{"channel":"book","type":"update","data":[{"symbol":"ETH/USD","bids":[{"price":1773.65,"qty":0.48930000}],"asks":[],"checksum":945422828,"timestamp":"2026-07-07T23:00:22.122927Z"}]}
{"channel":"book","type":"update","data":[{"symbol":"ETH/USD","bids":[],"asks":[{"price":1773.98,"qty":0.30836790}],"checksum":597240285,"timestamp":"2026-07-07T23:00:22.143045Z"}]}
{"channel":"book","type":"update","data":[{"symbol":"ETH/USD","bids":[],"asks":[{"price":1773.97,"qty":0.47001888}],"checksum":490725061,"timestamp":"2026-07-07T23:00:22.144471Z"}]}
{"channel":"book","type":"update","data":[{"symbol":"ETH/USD","bids":[],"asks":[{"price":1774.04,"qty":2.81842966}],"checksum":2062497176,"timestamp":"2026-07-07T23:00:22.149510Z"}]}
{"channel":"book","type":"update","data":[{"symbol":"ETH/USD","bids":[{"price":1773.76,"qty":0.85826558}],"asks":[],"checksum":3758728245,"timestamp":"2026-07-07T23:00:22.211470Z"}]}
{"channel":"book","type":"update","data":[{"symbol":"ETH/USD","bids":[],"asks":[{"price":1774.01,"qty":0.00000000},{"price":1774.19,"qty":2.51368318}],"checksum":284582708,"timestamp":"2026-07-07T23:00:22.245358Z"}]}
{"channel":"book","type":"update","data":[{"symbol":"ETH/USD","bids":[],"asks":[{"price":1774.18,"qty":0.00000000},{"price":1774.22,"qty":1.30000000}],"checksum":2589015844,"timestamp":"2026-07-07T23:00:22.252664Z"}]}
{"channel":"book","type":"update","data":[{"symbol":"ETH/USD","bids":[],"asks":[{"price":1774.08,"qty":5.87297232}],"checksum":635426044,"timestamp":"2026-07-07T23:00:22.252873Z"}]}
{"channel":"book","type":"update","data":[{"symbol":"BTC/USD","bids":[{"price":63487.7,"qty":0.00000000},{"price":63485.2,"qty":0.05990000}],"asks":[],"checksum":512831174,"timestamp":"2026-07-07T23:00:22.278997Z"}]}
{"channel":"book","type":"update","data":[{"symbol":"ETH/USD","bids":[{"price":1773.76,"qty":0.00000000},{"price":1773.62,"qty":18.72761918}],"asks":[],"checksum":1590962817,"timestamp":"2026-07-07T23:00:22.280043Z"}]}
{"channel":"book","type":"update","data":[{"symbol":"BTC/USD","bids":[{"price":63486.8,"qty":0.78756434}],"asks":[],"checksum":1121896586,"timestamp":"2026-07-07T23:00:22.280863Z"}]}
{"channel":"book","type":"update","data":[{"symbol":"BTC/USD","bids":[{"price":63487.8,"qty":0.00000000},{"price":63485.2,"qty":0.05990000}],"asks":[],"checksum":1653551522,"timestamp":"2026-07-07T23:00:22.281115Z"}]}
{"channel":"book","type":"update","data":[{"symbol":"ETH/USD","bids":[{"price":1773.75,"qty":0.00000000},{"price":1773.61,"qty":19.84616104}],"asks":[],"checksum":854128292,"timestamp":"2026-07-07T23:00:22.281405Z"}]}
{"channel":"book","type":"update","data":[{"symbol":"ETH/USD","bids":[],"asks":[{"price":1774.04,"qty":0.00000000},{"price":1774.25,"qty":7.12104918}],"checksum":75565724,"timestamp":"2026-07-07T23:00:22.281486Z"}]}
{"channel":"book","type":"update","data":[{"symbol":"ETH/USD","bids":[],"asks":[{"price":1773.97,"qty":3.28855957}],"checksum":4265047892,"timestamp":"2026-07-07T23:00:22.283171Z"}]}
{"channel":"book","type":"update","data":[{"symbol":"ETH/USD","bids":[{"price":1773.70,"qty":2.81895748}],"asks":[],"checksum":3265777602,"timestamp":"2026-07-07T23:00:22.283472Z"}]}
{"channel":"book","type":"update","data":[{"symbol":"BTC/USD","bids":[{"price":63485.7,"qty":0.25297256}],"asks":[],"checksum":3171508483,"timestamp":"2026-07-07T23:00:22.285693Z"}]}
{"channel":"book","type":"update","data":[{"symbol":"ETH/USD","bids":[],"asks":[{"price":1773.93,"qty":0.30673502}],"checksum":2322341660,"timestamp":"2026-07-07T23:00:22.286074Z"}]}
{"channel":"book","type":"update","data":[{"symbol":"ETH/USD","bids":[{"price":1773.69,"qty":0.00000000},{"price":1773.61,"qty":19.84616104},{"price":1773.70,"qty":4.50862724}],"asks":[],"checksum":2565457087,"timestamp":"2026-07-07T23:00:22.286198Z"}]}
{"channel":"book","type":"update","data":[{"symbol":"ETH/USD","bids":[],"asks":[{"price":1773.98,"qty":0.00000000},{"price":1774.25,"qty":7.12104918}],"checksum":1893174257,"timestamp":"2026-07-07T23:00:22.287522Z"}]}
{"channel":"book","type":"update","data":[{"symbol":"ETH/USD","bids":[],"asks":[{"price":1773.92,"qty":0.47001888}],"checksum":2470408863,"timestamp":"2026-07-07T23:00:22.287879Z"}]}
{"channel":"book","type":"update","data":[{"symbol":"BTC/USD","bids":[{"price":63485.6,"qty":0.00000000},{"price":63485.2,"qty":0.05990000}],"asks":[],"checksum":3508347174,"timestamp":"2026-07-07T23:00:22.311546Z"}]}
{"channel":"book","type":"update","data":[{"symbol":"BTC/USD","bids":[{"price":63485.7,"qty":0.00000000},{"price":63482.1,"qty":0.03147178}],"asks":[],"checksum":3071200962,"timestamp":"2026-07-07T23:00:22.312878Z"}]}
{"channel":"book","type":"update","data":[{"symbol":"BTC/USD","bids":[{"price":63484.5,"qty":0.78759347}],"asks":[],"checksum":3424543555,"timestamp":"2026-07-07T23:00:22.313114Z"}]}
{"channel":"book","type":"update","data":[{"symbol":"BTC/USD","bids":[{"price":63486.9,"qty":0.25296811}],"asks":[],"checksum":2573343034,"timestamp":"2026-07-07T23:00:22.314287Z"}]}
{"channel":"book","type":"update","data":[{"symbol":"ETH/USD","bids":[],"asks":[{"price":1773.97,"qty":2.81854069}],"checksum":675548915,"timestamp":"2026-07-07T23:00:22.388973Z"}]}
{"channel":"heartbeat"}
{"channel":"book","type":"update","data":[{"symbol":"ETH/USD","bids":[{"price":1773.71,"qty":2.50110906}],"asks":[],"checksum":2176586222,"timestamp":"2026-07-07T23:00:22.601656Z"}]}
{"channel":"book","type":"update","data":[{"symbol":"ETH/USD","bids":[{"price":1773.71,"qty":0.00000000},{"price":1773.55,"qty":28.19193113}],"asks":[],"checksum":913273154,"timestamp":"2026-07-07T23:00:22.601860Z"}]}
{"channel":"book","type":"update","data":[{"symbol":"ETH/USD","bids":[{"price":1773.68,"qty":10.79222612}],"asks":[],"checksum":3809084121,"timestamp":"2026-07-07T23:00:22.603090Z"}]}
{"channel":"book","type":"update","data":[{"symbol":"ETH/USD","bids":[{"price":1773.67,"qty":0.00000000},{"price":1773.46,"qty":0.48930000},{"price":1773.69,"qty":5.56003448}],"asks":[],"checksum":1088834678,"timestamp":"2026-07-07T23:00:22.604248Z"}]}
{"channel":"book","type":"update","data":[{"symbol":"BTC/USD","bids":[{"price":63486.8,"qty":0.00000000},{"price":63484.5,"qty":0.78759347}],"asks":[],"checksum":549240290,"timestamp":"2026-07-07T23:00:22.635505Z"}]}
{"channel":"book","type":"update","data":[{"symbol":"BTC/USD","bids":[{"price":63486.2,"qty":0.78757272}],"asks":[],"checksum":2834856648,"timestamp":"2026-07-07T23:00:22.638103Z"}]}
{"channel":"book","type":"update","data":[{"symbol":"BTC/USD","bids":[{"price":63486.9,"qty":0.00000000},{"price":63484.5,"qty":0.78759347}],"asks":[],"checksum":2556015480,"timestamp":"2026-07-07T23:00:22.638150Z"}]}
{"channel":"book","type":"update","data":[{"symbol":"ETH/USD","bids":[],"asks":[{"price":1774.11,"qty":4.79549924}],"checksum":2641289811,"timestamp":"2026-07-07T23:00:22.726607Z"}]}
{"channel":"book","type":"update","data":[{"symbol":"ETH/USD","bids":[{"price":1773.70,"qty":1.68966976}],"asks":[],"checksum":1361953022,"timestamp":"2026-07-07T23:00:22.891357Z"}]}
{"channel":"book","type":"update","data":[{"symbol":"ETH/USD","bids":[{"price":1773.73,"qty":2.81890939}],"asks":[],"checksum":869601460,"timestamp":"2026-07-07T23:00:22.893282Z"}]}
{"channel":"book","type":"update","data":[{"symbol":"ETH/USD","bids":[],"asks":[{"price":1774.19,"qty":10.06066969}],"checksum":910360392,"timestamp":"2026-07-07T23:00:22.894396Z"}]}
{"channel":"book","type":"update","data":[{"symbol":"ETH/USD","bids":[{"price":1773.74,"qty":0.05637804}],"asks":[],"checksum":1324578032,"timestamp":"2026-07-07T23:00:23.015763Z"}]}
{"channel":"book","type":"update","data":[{"symbol":"BTC/USD","bids":[{"price":63486.2,"qty":0.00000000},{"price":63482.1,"qty":0.03147178}],"asks":[],"checksum":282584032,"timestamp":"2026-07-07T23:00:23.058682Z"}]}
{"channel":"book","type":"update","data":[{"symbol":"BTC/USD","bids":[{"price":63486.9,"qty":0.78756364}],"asks":[],"checksum":3626345755,"timestamp":"2026-07-07T23:00:23.060151Z"}]}
{"channel":"book","type":"update","data":[{"symbol":"BTC/USD","bids":[{"price":63487.0,"qty":0.25296790}],"asks":[],"checksum":120178214,"timestamp":"2026-07-07T23:00:23.064779Z"}]}
{"channel":"book","type":"update","data":[{"symbol":"BTC/USD","bids":[{"price":63486.9,"qty":0.00000000},{"price":63482.0,"qty":0.03147178}],"asks":[],"checksum":364516467,"timestamp":"2026-07-07T23:00:23.340630Z"}]}
{"channel":"book","type":"update","data":[{"symbol":"BTC/USD","bids":[{"price":63487.5,"qty":0.78755547}],"asks":[],"checksum":960011750,"timestamp":"2026-07-07T23:00:23.341991Z"}]}
{"channel":"book","type":"update","data":[{"symbol":"BTC/USD","bids":[{"price":63485.5,"qty":0.78758105}],"asks":[],"checksum":2068748710,"timestamp":"2026-07-07T23:00:23.342240Z"}]}
{"channel":"book","type":"update","data":[{"symbol":"BTC/USD","bids":[{"price":63487.0,"qty":0.00000000},{"price":63485.2,"qty":0.05990000}],"asks":[],"checksum":1715610759,"timestamp":"2026-07-07T23:00:23.342256Z"}]}
{"channel":"book","type":"update","data":[{"symbol":"BTC/USD","bids":[{"price":63487.6,"qty":0.26188899}],"asks":[],"checksum":834761149,"timestamp":"2026-07-07T23:00:23.343601Z"}]}
{"channel":"book","type":"update","data":[{"symbol":"ETH/USD","bids":[],"asks":[{"price":1773.93,"qty":0.00000000},{"price":1774.21,"qty":28.18158663}],"checksum":1308132984,"timestamp":"2026-07-07T23:00:23.359447Z"}]}
{"channel":"book","type":"update","data":[{"symbol":"ETH/USD","bids":[],"asks":[{"price":1773.92,"qty":0.00000000},{"price":1774.22,"qty":1.30000000}],"checksum":3801910458,"timestamp":"2026-07-07T23:00:23.360719Z"}]}
{"channel":"book","type":"update","data":[{"symbol":"ETH/USD","bids":[],"asks":[{"price":1773.96,"qty":0.47001888}],"checksum":2978585823,"timestamp":"2026-07-07T23:00:23.360978Z"}]}
{"channel":"book","type":"update","data":[{"symbol":"ETH/USD","bids":[],"asks":[{"price":1773.97,"qty":0.00000000},{"price":1774.22,"qty":1.30000000}],"checksum":2117430520,"timestamp":"2026-07-07T23:00:23.365792Z"}]}
{"channel":"book","type":"update","data":[{"symbol":"ETH/USD","bids":[],"asks":[{"price":1774.21,"qty":0.00000000},{"price":1774.25,"qty":7.12104918}],"checksum":855462646,"timestamp":"2026-07-07T23:00:23.365842Z"}]}
{"channel":"book","type":"update","data":[{"symbol":"ETH/USD","bids":[],"asks":[{"price":1774.25,"qty":1.48204918}],"checksum":3655904388,"timestamp":"2026-07-07T23:00:23.367527Z"}]}
{"channel":"book","type":"update","data":[{"symbol":"ETH/USD","bids":[],"asks":[{"price":1774.19,"qty":2.51368318}],"checksum":3417265897,"timestamp":"2026-07-07T23:00:23.367660Z"}]}
{"channel":"book","type":"update","data":[{"symbol":"ETH/USD","bids":[],"asks":[{"price":1774.14,"qty":3.80756803}],"checksum":3909567565,"timestamp":"2026-07-07T23:00:23.367713Z"}]}
{"channel":"book","type":"update","data":[{"symbol":"ETH/USD","bids":[],"asks":[{"price":1774.19,"qty":0.00000000},{"price":1774.29,"qty":9.15349385}],"checksum":2107331719,"timestamp":"2026-07-07T23:00:23.370226Z"}]}
{"channel":"book","type":"update","data":[{"symbol":"ETH/USD","bids":[],"asks":[{"price":1774.19,"qty":0.83044168}],"checksum":825163441,"timestamp":"2026-07-07T23:00:23.370238Z"}]}
{"channel":"book","type":"update","data":[{"symbol":"BTC/USD","bids":[{"price":63491.6,"qty":0.05990000}],"asks":[],"checksum":32733556,"timestamp":"2026-07-07T23:00:23.372180Z"}]}
{"channel":"book","type":"update","data":[{"symbol":"ETH/USD","bids":[{"price":1773.73,"qty":0.00000000},{"price":1773.61,"qty":19.84616104}],"asks":[],"checksum":4038595474,"timestamp":"2026-07-07T23:00:23.372575Z"}]}
{"channel":"book","type":"update","data":[{"symbol":"BTC/USD","bids":[{"price":63487.5,"qty":0.00000000},{"price":63485.5,"qty":0.78758105}],"asks":[],"checksum":280858385,"timestamp":"2026-07-07T23:00:23.375166Z"}]}
{"channel":"book","type":"update","data":[{"symbol":"ETH/USD","bids":[{"price":1773.82,"qty":0.44408329}],"asks":[],"checksum":3263839714,"timestamp":"2026-07-07T23:00:23.375267Z"}]}
{"channel":"book","type":"update","data":[{"symbol":"BTC/USD","bids":[{"price":63485.5,"qty":0.00000000},{"price":63485.2,"qty":0.05990000}],"asks":[],"checksum":2709511862,"timestamp":"2026-07-07T23:00:23.376240Z"}]}
{"channel":"book","type":"update","data":[{"symbol":"ETH/USD","bids":[{"price":1773.83,"qty":0.48930000}],"asks":[],"checksum":1615647434,"timestamp":"2026-07-07T23:00:23.378458Z"}]}
{"channel":"book","type":"update","data":[{"symbol":"ETH/USD","bids":[{"price":1773.74,"qty":0.00000000},{"price":1773.61,"qty":19.84616104},{"price":1773.71,"qty":0.05637900}],"asks":[],"checksum":2656355105,"timestamp":"2026-07-07T23:00:23.382092Z"}]}
{"channel":"book","type":"update","data":[{"symbol":"ETH/USD","bids":[],"asks":[{"price":1774.22,"qty":0.00000000},{"price":1774.29,"qty":9.15349385}],"checksum":1302464705,"timestamp":"2026-07-07T23:00:23.383146Z"}]}
{"channel":"book","type":"update","data":[{"symbol":"ETH/USD","bids":[{"price":1773.62,"qty":20.02761918}],"asks":[],"checksum":394795203,"timestamp":"2026-07-07T23:00:23.386443Z"}]}
{"channel":"book","type":"update","data":[{"symbol":"ETH/USD","bids":[{"price":1773.72,"qty":0.00000000},{"price":1773.61,"qty":19.84616104}],"asks":[],"checksum":3059774527,"timestamp":"2026-07-07T23:00:23.386525Z"}]}
{"channel":"book","type":"update","data":[{"symbol":"ETH/USD","bids":[{"price":1773.80,"qty":2.81879953}],"asks":[],"checksum":1627614473,"timestamp":"2026-07-07T23:00:23.387247Z"}]}
{"channel":"book","type":"update","data":[{"symbol":"BTC/USD","bids":[],"asks":[{"price":63498.1,"qty":2.24137036}],"checksum":2703724737,"timestamp":"2026-07-07T23:00:23.387497Z"}]}
{"channel":"book","type":"update","data":[{"symbol":"ETH/USD","bids":[{"price":1773.62,"qty":48.21854508}],"asks":[],"checksum":891376292,"timestamp":"2026-07-07T23:00:23.387560Z"}]}
{"channel":"book","type":"update","data":[{"symbol":"BTC/USD","bids":[{"price":63487.6,"qty":0.00000000},{"price":63482.0,"qty":0.03147178}],"asks":[],"checksum":540540880,"timestamp":"2026-07-07T23:00:23.393812Z"}]}
{"channel":"book","type":"update","data":[{"symbol":"ETH/USD","bids":[],"asks":[{"price":1774.19,"qty":0.00000000},{"price":1774.30,"qty":19.01700000}],"checksum":3566546864,"timestamp":"2026-07-07T23:00:23.397068Z"}]}
{"channel":"book","type":"update","data":[{"symbol":"ETH/USD","bids":[{"price":1773.62,"qty":33.70818154}],"asks":[],"checksum":2518001166,"timestamp":"2026-07-07T23:00:23.397844Z"}]}
{"channel":"book","type":"update","data":[{"symbol":"ETH/USD","bids":[{"price":1773.81,"qty":0.84141166}],"asks":[],"checksum":2450445681,"timestamp":"2026-07-07T23:00:23.398925Z"}]}
{"channel":"book","type":"update","data":[{"symbol":"ETH/USD","bids":[{"price":1773.81,"qty":0.00000000},{"price":1773.62,"qty":33.70818154}],"asks":[],"checksum":2518001166,"timestamp":"2026-07-07T23:00:23.401077Z"}]}
{"channel":"book","type":"update","data":[{"symbol":"BTC/USD","bids":[{"price":63484.1,"qty":0.78759839}],"asks":[],"checksum":3507173972,"timestamp":"2026-07-07T23:00:23.401442Z"}]}
{"channel":"book","type":"update","data":[{"symbol":"ETH/USD","bids":[{"price":1773.81,"qty":0.84141166}],"asks":[],"checksum":2450445681,"timestamp":"2026-07-07T23:00:23.406885Z"}]}
{"channel":"book","type":"update","data":[{"symbol":"ETH/USD","bids":[],"asks":[{"price":1774.11,"qty":0.00000000},{"price":1774.32,"qty":0.48930000}],"checksum":2856220166,"timestamp":"2026-07-07T23:00:23.409401Z"}]}
{"channel":"book","type":"update","data":[{"symbol":"BTC/USD","bids":[{"price":63490.1,"qty":0.60470924}],"asks":[],"checksum":1368536978,"timestamp":"2026-07-07T23:00:23.414455Z"}]}
{"channel":"book","type":"update","data":[{"symbol":"BTC/USD","bids":[{"price":63487.2,"qty":0.02680368}],"asks":[],"checksum":3039991316,"timestamp":"2026-07-07T23:00:23.414752Z"}]}
{"channel":"book","type":"update","data":[{"symbol":"BTC/USD","bids":[],"asks":[{"price":63498.1,"qty":1.63666112}],"checksum":695784769,"timestamp":"2026-07-07T23:00:23.415094Z"}]}
{"channel":"book","type":"update","data":[{"symbol":"BTC/USD","bids":[{"price":63491.6,"qty":0.00000000},{"price":63485.2,"qty":0.05990000}],"asks":[],"checksum":3507347699,"timestamp":"2026-07-07T23:00:23.419364Z"}]}
{"channel":"book","type":"update","data":[{"symbol":"ETH/USD","bids":[{"price":1773.82,"qty":0.33133228}],"asks":[],"checksum":527081380,"timestamp":"2026-07-07T23:00:23.419821Z"}]}
{"channel":"book","type":"update","data":[{"symbol":"BTC/USD","bids":[],"asks":[{"price":63498.1,"qty":1.63656278}],"checksum":2211103168,"timestamp":"2026-07-07T23:00:23.424904Z"}]}
{"channel":"book","type":"update","data":[{"symbol":"ETH/USD","bids":[{"price":1773.81,"qty":0.00000000},{"price":1773.63,"qty":13.19378487}],"asks":[],"checksum":2771655016,"timestamp":"2026-07-07T23:00:23.430689Z"}]}
{"channel":"book","type":"update","data":[{"symbol":"BTC/USD","bids":[{"price":63490.1,"qty":0.00000000},{"price":63484.2,"qty":0.24449245}],"asks":[],"checksum":2720220946,"timestamp":"2026-07-07T23:00:23.439002Z"}]}
{"channel":"book","type":"update","data":[{"symbol":"ETH/USD","bids":[],"asks":[{"price":1774.14,"qty":3.30756803}],"checksum":108874369,"timestamp":"2026-07-07T23:00:23.440168Z"}]}
{"channel":"book","type":"update","data":[{"symbol":"BTC/USD","bids":[],"asks":[{"price":63502.3,"qty":0.00000000},{"price":63502.4,"qty":0.06003821}],"checksum":1874463635,"timestamp":"2026-07-07T23:00:23.440837Z"}]}
{"channel":"book","type":"update","data":[{"symbol":"ETH/USD","bids":[],"asks":[{"price":1774.08,"qty":5.49683932}],"checksum":4158373863,"timestamp":"2026-07-07T23:00:23.442346Z"}]}
{"channel":"book","type":"update","data":[{"symbol":"BTC/USD","bids":[],"asks":[{"price":63501.7,"qty":1.76319600}],"checksum":985685657,"timestamp":"2026-07-07T23:00:23.443119Z"}]}
{"channel":"book","type":"update","data":[{"symbol":"ETH/USD","bids":[],"asks":[{"price":1774.08,"qty":0.00000000},{"price":1774.33,"qty":48.02581689}],"checksum":4007121435,"timestamp":"2026-07-07T23:00:23.443687Z"}]}
{"channel":"book","type":"update","data":[{"symbol":"BTC/USD","bids":[],"asks":[{"price":63498.1,"qty":1.05720478}],"checksum":1056889834,"timestamp":"2026-07-07T23:00:23.443744Z"}]}
{"channel":"book","type":"update","data":[{"symbol":"ETH/USD","bids":[],"asks":[{"price":1774.22,"qty":0.37031102}],"checksum":2021284799,"timestamp":"2026-07-07T23:00:23.446798Z"}]}
{"channel":"book","type":"update","data":[{"symbol":"BTC/USD","bids":[{"price":63490.6,"qty":0.78751758}],"asks":[],"checksum":338332407,"timestamp":"2026-07-07T23:00:23.446933Z"}]}
{"channel":"book","type":"update","data":[{"symbol":"BTC/USD","bids":[],"asks":[{"price":63498.1,"qty":1.01560478}],"checksum":1397792431,"timestamp":"2026-07-07T23:00:23.459400Z"}]}
{"channel":"book","type":"update","data":[{"symbol":"ETH/USD","bids":[],"asks":[{"price":1774.08,"qty":0.29836281}],"checksum":3125771102,"timestamp":"2026-07-07T23:00:23.459919Z"}]}
{"channel":"book","type":"update","data":[{"symbol":"BTC/USD","bids":[{"price":63491.6,"qty":0.05990000}],"asks":[],"checksum":1579973675,"timestamp":"2026-07-07T23:00:23.465953Z"}]}
{"channel":"book","type":"update","data":[{"symbol":"BTC/USD","bids":[],"asks":[{"price":63499.2,"qty":0.00000000},{"price":63502.6,"qty":0.01021802}],"checksum":1849719911,"timestamp":"2026-07-07T23:00:23.467564Z"}]}
{"channel":"book","type":"update","data":[{"symbol":"BTC/USD","bids":[{"price":63490.6,"qty":0.00000000},{"price":63485.2,"qty":0.05990000}],"asks":[],"checksum":2843710901,"timestamp":"2026-07-07T23:00:23.467817Z"}]}
{"channel":"book","type":"update","data":[{"symbol":"BTC/USD","bids":[],"asks":[{"price":63498.1,"qty":0.97640478}],"checksum":573396373,"timestamp":"2026-07-07T23:00:23.469554Z"}]}
{"channel":"book","type":"update","data":[{"symbol":"BTC/USD","bids":[{"price":63498.0,"qty":1.09186166}],"asks":[],"checksum":3253979644,"timestamp":"2026-07-07T23:00:23.469942Z"}]}
{"channel":"book","type":"update","data":[{"symbol":"BTC/USD","bids":[],"asks":[{"price":63500.3,"qty":0.78739836}],"checksum":2825228479,"timestamp":"2026-07-07T23:00:23.471455Z"}]}
{"channel":"book","type":"update","data":[{"symbol":"ETH/USD","bids":[{"price":1773.66,"qty":0.00000000},{"price":1773.62,"qty":29.49092590},{"price":1773.75,"qty":28.18501386}],"asks":[],"checksum":2513697572,"timestamp":"2026-07-07T23:00:23.480661Z"}]}
{"channel":"book","type":"update","data":[{"symbol":"BTC/USD","bids":[],"asks":[{"price":63500.3,"qty":0.00000000},{"price":63502.6,"qty":0.01021802}],"checksum":3253979644,"timestamp":"2026-07-07T23:00:23.481732Z"}]}
{"channel":"book","type":"update","data":[{"symbol":"ETH/USD","bids":[{"price":1773.68,"qty":0.57284095}],"asks":[],"checksum":1471781957,"timestamp":"2026-07-07T23:00:23.482754Z"}]}
{"channel":"book","type":"update","data":[{"symbol":"ETH/USD","bids":[{"price":1773.76,"qty":8.41322664}],"asks":[],"checksum":2241974031,"timestamp":"2026-07-07T23:00:23.482764Z"}]}
{"channel":"book","type":"update","data":[{"symbol":"ETH/USD","bids":[{"price":1773.69,"qty":0.00000000},{"price":1773.63,"qty":13.19378487}],"asks":[],"checksum":1083242894,"timestamp":"2026-07-07T23:00:23.483604Z"}]}
{"channel":"book","type":"update","data":[{"symbol":"ETH/USD","bids":[{"price":1773.71,"qty":2.53746479}],"asks":[],"checksum":2649270698,"timestamp":"2026-07-07T23:00:23.485112Z"}]}
{"channel":"book","type":"update","data":[{"symbol":"ETH/USD","bids":[{"price":1773.71,"qty":3.35888029}],"asks":[],"checksum":567913421,"timestamp":"2026-07-07T23:00:23.485862Z"}]}
{"channel":"book","type":"update","data":[{"symbol":"ETH/USD","bids":[{"price":1773.71,"qty":0.87779450}],"asks":[],"checksum":3049842245,"timestamp":"2026-07-07T23:00:23.485983Z"}]}
{"channel":"book","type":"update","data":[{"symbol":"ETH/USD","bids":[{"price":1773.70,"qty":0.00000000},{"price":1773.62,"qty":29.49092590},{"price":1773.69,"qty":1.68966976}],"asks":[],"checksum":2604904787,"timestamp":"2026-07-07T23:00:23.486202Z"}]}
{"channel":"book","type":"update","data":[{"symbol":"ETH/USD","bids":[{"price":1773.80,"qty":0.00000000},{"price":1773.62,"qty":29.49092590}],"asks":[],"checksum":1842272639,"timestamp":"2026-07-07T23:00:23.529955Z"}]}
{"channel":"book","type":"update","data":[{"symbol":"ETH/USD","bids":[],"asks":[{"price":1774.14,"qty":2.81826803}],"checksum":1788112788,"timestamp":"2026-07-07T23:00:23.531752Z"}]}
{"channel":"book","type":"update","data":[{"symbol":"ETH/USD","bids":[{"price":1773.83,"qty":3.30805230}],"asks":[],"checksum":1653406144,"timestamp":"2026-07-07T23:00:23.532506Z"}]}
{"channel":"book","type":"update","data":[{"symbol":"ETH/USD","bids":[{"price":1773.84,"qty":1.30000000}],"asks":[],"checksum":748578322,"timestamp":"2026-07-07T23:00:23.532563Z"}]}
{"channel":"book","type":"update","data":[{"symbol":"BTC/USD","bids":[],"asks":[{"price":63498.1,"qty":0.18897965}],"checksum":3742407649,"timestamp":"2026-07-07T23:00:23.533684Z"}]}
{"channel":"book","type":"update","data":[{"symbol":"ETH/USD","bids":[{"price":1773.84,"qty":2.38635630}],"asks":[],"checksum":2984066497,"timestamp":"2026-07-07T23:00:23.535704Z"}]}
{"channel":"book","type":"update","data":[{"symbol":"ETH/USD","bids":[],"asks":[{"price":1774.14,"qty":0.00000000},{"price":1774.32,"qty":0.48930000}],"checksum":268654345,"timestamp":"2026-07-07T23:00:23.535874Z"}]}
{"channel":"book","type":"update","data":[{"symbol":"ETH/USD","bids":[{"price":1773.90,"qty":0.48930000}],"asks":[],"checksum":2112699624,"timestamp":"2026-07-07T23:00:23.536206Z"}]}
{"channel":"book","type":"update","data":[{"symbol":"BTC/USD","bids":[],"asks":[{"price":63499.7,"qty":0.78740643}],"checksum":40131092,"timestamp":"2026-07-07T23:00:23.539370Z"}]}
{"channel":"book","type":"update","data":[{"symbol":"ETH/USD","bids":[{"price":1773.84,"qty":1.08635630}],"asks":[],"checksum":3578636823,"timestamp":"2026-07-07T23:00:23.539411Z"}]}
{"channel":"book","type":"update","data":[{"symbol":"ETH/USD","bids":[],"asks":[{"price":1774.22,"qty":3.18846313}],"checksum":683364722,"timestamp":"2026-07-07T23:00:23.539683Z"}]}
{"channel":"book","type":"update","data":[{"symbol":"ETH/USD","bids":[{"price":1773.83,"qty":2.81875230}],"asks":[],"checksum":3408443213,"timestamp":"2026-07-07T23:00:23.539951Z"}]}
{"channel":"book","type":"update","data":[{"symbol":"BTC/USD","bids":[],"asks":[{"price":63498.1,"qty":0.76833065}],"checksum":2154287469,"timestamp":"2026-07-07T23:00:23.541709Z"}]}
{"channel":"book","type":"update","data":[{"symbol":"ETH/USD","bids":[{"price":1773.90,"qty":0.82518122}],"asks":[],"checksum":2037911601,"timestamp":"2026-07-07T23:00:23.542346Z"}]}
{"channel":"book","type":"update","data":[{"symbol":"ETH/USD","bids":[{"price":1773.71,"qty":0.82141550}],"asks":[],"checksum":3508368242,"timestamp":"2026-07-07T23:00:23.542440Z"}]}
{"channel":"book","type":"update","data":[{"symbol":"ETH/USD","bids":[],"asks":[{"price":1774.21,"qty":1.39414792}],"checksum":2503663717,"timestamp":"2026-07-07T23:00:23.543103Z"}]}
{"channel":"book","type":"update","data":[{"symbol":"BTC/USD","bids":[{"price":63491.7,"qty":0.01789537}],"asks":[],"checksum":3974968310,"timestamp":"2026-07-07T23:00:23.543289Z"}]}
{"channel":"book","type":"update","data":[{"symbol":"ETH/USD","bids":[{"price":1773.82,"qty":0.00000000},{"price":1773.64,"qty":5.56003448}],"asks":[],"checksum":46424455,"timestamp":"2026-07-07T23:00:23.543992Z"}]}
{"channel":"book","type":"update","data":[{"symbol":"BTC/USD","bids":[{"price":63498.0,"qty":1.13346166}],"asks":[],"checksum":250037312,"timestamp":"2026-07-07T23:00:23.545104Z"}]}
{"channel":"book","type":"update","data":[{"symbol":"ETH/USD","bids":[{"price":1773.90,"qty":0.33588122}],"asks":[],"checksum":2912032476,"timestamp":"2026-07-07T23:00:23.546266Z"}]}
{"channel":"book","type":"update","data":[{"symbol":"BTC/USD","bids":[{"price":63491.1,"qty":0.02989458}],"asks":[],"checksum":2653583555,"timestamp":"2026-07-07T23:00:23.551594Z"}]}
{"channel":"book","type":"update","data":[{"symbol":"BTC/USD","bids":[{"price":63487.2,"qty":0.00000000},{"price":63485.2,"qty":0.05990000}],"asks":[],"checksum":3817497667,"timestamp":"2026-07-07T23:00:23.553445Z"}]}
{"channel":"book","type":"update","data":[{"symbol":"BTC/USD","bids":[{"price":63487.2,"qty":0.01788015}],"asks":[],"checksum":2459749687,"timestamp":"2026-07-07T23:00:23.553529Z"}]}
{"channel":"book","type":"update","data":[{"symbol":"BTC/USD","bids":[{"price":63494.5,"qty":0.60470924}],"asks":[],"checksum":1409126315,"timestamp":"2026-07-07T23:00:23.555850Z"}]}
{"channel":"book","type":"update","data":[{"symbol":"BTC/USD","bids":[{"price":63498.0,"qty":1.09186166}],"asks":[],"checksum":1897763685,"timestamp":"2026-07-07T23:00:23.555929Z"}]}
{"channel":"book","type":"update","data":[{"symbol":"BTC/USD","bids":[],"asks":[{"price":63498.7,"qty":0.00000000},{"price":63502.6,"qty":0.01021802}],"checksum":2375328470,"timestamp":"2026-07-07T23:00:23.556135Z"}]}
{"channel":"heartbeat"}
{"channel":"book","type":"update","data":[{"symbol":"ETH/USD","bids":[{"price":1773.90,"qty":0.82518122}],"asks":[],"checksum":46424455,"timestamp":"2026-07-07T23:00:23.561671Z"}]}
{"channel":"book","type":"update","data":[{"symbol":"ETH/USD","bids":[{"price":1773.83,"qty":0.00000000},{"price":1773.62,"qty":1.30000000}],"asks":[],"checksum":2954559253,"timestamp":"2026-07-07T23:00:23.562868Z"}]}
{"channel":"book","type":"update","data":[{"symbol":"ETH/USD","bids":[],"asks":[{"price":1774.22,"qty":0.37031102}],"checksum":464680428,"timestamp":"2026-07-07T23:00:23.562901Z"}]}
{"channel":"book","type":"update","data":[{"symbol":"BTC/USD","bids":[{"price":63492.7,"qty":0.78749106}],"asks":[],"checksum":1152480842,"timestamp":"2026-07-07T23:00:23.562960Z"}]}
{"channel":"book","type":"update","data":[{"symbol":"ETH/USD","bids":[{"price":1773.64,"qty":0.00000000},{"price":1773.52,"qty":6.11605605}],"asks":[],"checksum":2717965011,"timestamp":"2026-07-07T23:00:23.564393Z"}]}
{"channel":"book","type":"update","data":[{"symbol":"BTC/USD","bids":[{"price":63492.8,"qty":0.25296145}],"asks":[],"checksum":16414768,"timestamp":"2026-07-07T23:00:23.565261Z"}]}
{"channel":"book","type":"update","data":[{"symbol":"ETH/USD","bids":[{"price":1773.71,"qty":2.37606944}],"asks":[],"checksum":1428200033,"timestamp":"2026-07-07T23:00:23.565492Z"}]}
{"channel":"book","type":"update","data":[{"symbol":"ETH/USD","bids":[{"price":1773.71,"qty":0.82141550}],"asks":[],"checksum":2717965011,"timestamp":"2026-07-07T23:00:23.566160Z"}]}
{"channel":"book","type":"update","data":[{"symbol":"BTC/USD","bids":[{"price":63491.7,"qty":0.00000000},{"price":63491.1,"qty":0.02989458}],"asks":[],"checksum":1090212496,"timestamp":"2026-07-07T23:00:23.566515Z"}]}
{"channel":"book","type":"update","data":[{"symbol":"ETH/USD","bids":[{"price":1773.84,"qty":0.00000000},{"price":1773.51,"qty":20.00000000}],"asks":[],"checksum":2833735208,"timestamp":"2026-07-07T23:00:23.566720Z"}]}
{"channel":"book","type":"update","data":[{"symbol":"ETH/USD","bids":[],"asks":[{"price":1774.21,"qty":0.00000000},{"price":1774.32,"qty":0.48930000}],"checksum":843970517,"timestamp":"2026-07-07T23:00:23.566915Z"}]}
{"channel":"book","type":"update","data":[{"symbol":"BTC/USD","bids":[{"price":63492.7,"qty":0.00000000},{"price":63488.2,"qty":0.00005100}],"asks":[],"checksum":3254143799,"timestamp":"2026-07-07T23:00:23.580837Z"}]}
{"channel":"book","type":"update","data":[{"symbol":"BTC/USD","bids":[{"price":63492.8,"qty":0.27085682}],"asks":[],"checksum":1838098494,"timestamp":"2026-07-07T23:00:23.584665Z"}]}
{"channel":"book","type":"update","data":[{"symbol":"BTC/USD","bids":[{"price":63492.8,"qty":0.01789537}],"asks":[],"checksum":3804587604,"timestamp":"2026-07-07T23:00:23.584690Z"}]}
{"channel":"book","type":"update","data":[{"symbol":"ETH/USD","bids":[{"price":1773.90,"qty":0.33588122}],"asks":[],"checksum":3462080990,"timestamp":"2026-07-07T23:00:23.590210Z"}]}
{"channel":"book","type":"update","data":[{"symbol":"BTC/USD","bids":[{"price":63492.8,"qty":0.00000000},{"price":63485.4,"qty":0.02727448}],"asks":[],"checksum":692848711,"timestamp":"2026-07-07T23:00:23.592279Z"}]}
{"channel":"book","type":"update","data":[{"symbol":"BTC/USD","bids":[{"price":63491.7,"qty":0.01789537}],"asks":[],"checksum":2375328470,"timestamp":"2026-07-07T23:00:23.593855Z"}]}
{"channel":"book","type":"update","data":[{"symbol":"ETH/USD","bids":[],"asks":[{"price":1774.16,"qty":1.53128753}],"checksum":2641826394,"timestamp":"2026-07-07T23:00:23.595869Z"}]}
{"channel":"book","type":"update","data":[{"symbol":"BTC/USD","bids":[],"asks":[{"price":63502.4,"qty":0.00000000},{"price":63504.0,"qty":0.78740416}],"checksum":2030618794,"timestamp":"2026-07-07T23:00:23.628056Z"}]}
{"channel":"book","type":"update","data":[{"symbol":"ETH/USD","bids":[{"price":1773.62,"qty":0.00000000},{"price":1773.46,"qty":0.48930000}],"asks":[],"checksum":1835268160,"timestamp":"2026-07-07T23:00:23.634392Z"}]}
{"channel":"book","type":"update","data":[{"symbol":"BTC/USD","bids":[],"asks":[{"price":63498.1,"qty":0.18897965}],"checksum":1347617465,"timestamp":"2026-07-07T23:00:23.646187Z"}]}
{"channel":"book","type":"update","data":[{"symbol":"BTC/USD","bids":[{"price":63498.0,"qty":1.13346166}],"asks":[],"checksum":1924341367,"timestamp":"2026-07-07T23:00:23.654295Z"}]}
{"channel":"book","type":"update","data":[{"symbol":"ETH/USD","bids":[{"price":1773.90,"qty":0.82518122}],"asks":[],"checksum":3258289947,"timestamp":"2026-07-07T23:00:23.673572Z"}]}
{"channel":"book","type":"update","data":[{"symbol":"ETH/USD","bids":[{"price":1773.66,"qty":1.30000000}],"asks":[],"checksum":594177562,"timestamp":"2026-07-07T23:00:23.676591Z"}]}
{"channel":"book","type":"update","data":[{"symbol":"ETH/USD","bids":[],"asks":[{"price":1774.13,"qty":2.81828800}],"checksum":2816347029,"timestamp":"2026-07-07T23:00:23.678651Z"}]}
{"channel":"book","type":"update","data":[{"symbol":"ETH/USD","bids":[{"price":1773.87,"qty":2.81868392}],"asks":[],"checksum":152146622,"timestamp":"2026-07-07T23:00:23.679199Z"}]}
{"channel":"book","type":"update","data":[{"symbol":"ETH/USD","bids":[{"price":1773.75,"qty":0.00000000},{"price":1773.51,"qty":20.00000000},{"price":1773.85,"qty":28.18575974}],"asks":[],"checksum":746830676,"timestamp":"2026-07-07T23:00:23.682740Z"}]}
{"channel":"book","type":"update","data":[{"symbol":"ETH/USD","bids":[{"price":1773.76,"qty":0.00000000},{"price":1773.51,"qty":20.00000000}],"asks":[],"checksum":860582733,"timestamp":"2026-07-07T23:00:23.684823Z"}]}
{"channel":"book","type":"update","data":[{"symbol":"ETH/USD","bids":[{"price":1773.86,"qty":8.41344928}],"asks":[],"checksum":1759746745,"timestamp":"2026-07-07T23:00:23.684844Z"}]}
{"channel":"book","type":"update","data":[{"symbol":"ETH/USD","bids":[{"price":1773.85,"qty":0.00000000},{"price":1773.51,"qty":20.00000000},{"price":1773.77,"qty":28.18578007}],"asks":[],"checksum":2533189946,"timestamp":"2026-07-07T23:00:23.711995Z"}]}
{"channel":"book","type":"update","data":[{"symbol":"ETH/USD","bids":[{"price":1773.86,"qty":0.00000000},{"price":1773.51,"qty":20.00000000}],"asks":[],"checksum":1384732394,"timestamp":"2026-07-07T23:00:23.713668Z"}]}
{"channel":"book","type":"update","data":[{"symbol":"ETH/USD","bids":[{"price":1773.78,"qty":8.41345535}],"asks":[],"checksum":692344491,"timestamp":"2026-07-07T23:00:23.713773Z"}]}
{"channel":"book","type":"update","data":[{"symbol":"ETH/USD","bids":[],"asks":[{"price":1773.91,"qty":0.00000000},{"price":1774.32,"qty":0.48930000}],"checksum":57585014,"timestamp":"2026-07-07T23:00:23.726496Z"}]}
{"channel":"book","type":"update","data":[{"symbol":"ETH/USD","bids":[{"price":1773.71,"qty":20.66757654}],"asks":[],"checksum":646532197,"timestamp":"2026-07-07T23:00:23.727885Z"}]}
{"channel":"book","type":"update","data":[{"symbol":"ETH/USD","bids":[{"price":1773.71,"qty":19.84616104}],"asks":[],"checksum":588569882,"timestamp":"2026-07-07T23:00:23.729105Z"}]}
{"channel":"book","type":"update","data":[{"symbol":"ETH/USD","bids":[{"price":1773.53,"qty":5.56003448}],"asks":[],"checksum":1591569283,"timestamp":"2026-07-07T23:00:23.729168Z"}]}
{"channel":"book","type":"update","data":[{"symbol":"ETH/USD","bids":[{"price":1773.91,"qty":0.48930000}],"asks":[],"checksum":3996954593,"timestamp":"2026-07-07T23:00:23.729792Z"}]}
{"channel":"book","type":"update","data":[{"symbol":"ETH/USD","bids":[{"price":1773.72,"qty":7.13354457}],"asks":[],"checksum":1177153135,"timestamp":"2026-07-07T23:00:23.729857Z"}]}
{"channel":"book","type":"update","data":[{"symbol":"ETH/USD","bids":[{"price":1773.90,"qty":0.33588122}],"asks":[],"checksum":670419879,"timestamp":"2026-07-07T23:00:23.730383Z"}]}
{"channel":"book","type":"update","data":[{"symbol":"ETH/USD","bids":[],"asks":[{"price":1773.99,"qty":0.14097214}],"checksum":1529430379,"timestamp":"2026-07-07T23:00:23.739108Z"}]}
{"channel":"book","type":"update","data":[{"symbol":"BTC/USD","bids":[],"asks":[{"price":63498.1,"qty":0.76832965}],"checksum":2292493028,"timestamp":"2026-07-07T23:00:23.745770Z"}]}
{"channel":"book","type":"update","data":[{"symbol":"BTC/USD","bids":[{"price":63494.5,"qty":0.00000000},{"price":63485.4,"qty":0.02727448}],"asks":[],"checksum":3206367058,"timestamp":"2026-07-07T23:00:23.745794Z"}]}
{"channel":"book","type":"update","data":[{"symbol":"BTC/USD","bids":[{"price":63485.5,"qty":0.03147178}],"asks":[],"checksum":2705312749,"timestamp":"2026-07-07T23:00:23.747348Z"}]}
{"channel":"book","type":"update","data":[{"symbol":"BTC/USD","bids":[{"price":63498.0,"qty":1.09186166}],"asks":[],"checksum":1127595099,"timestamp":"2026-07-07T23:00:23.747580Z"}]}
{"channel":"book","type":"update","data":[{"symbol":"BTC/USD","bids":[{"price":63485.6,"qty":0.02727448}],"asks":[],"checksum":523384729,"timestamp":"2026-07-07T23:00:23.748822Z"}]}
{"channel":"book","type":"update","data":[{"symbol":"BTC/USD","bids":[],"asks":[{"price":63498.6,"qty":0.78741971}],"checksum":1857705591,"timestamp":"2026-07-07T23:00:23.815079Z"}]}
{"channel":"book","type":"update","data":[{"symbol":"BTC/USD","bids":[{"price":63491.9,"qty":0.78750158}],"asks":[],"checksum":1562990906,"timestamp":"2026-07-07T23:00:23.815117Z"}]}
{"channel":"book","type":"update","data":[{"symbol":"BTC/USD","bids":[{"price":63489.8,"qty":0.78752713}],"asks":[],"checksum":4129085721,"timestamp":"2026-07-07T23:00:23.815134Z"}]}
{"channel":"book","type":"update","data":[{"symbol":"BTC/USD","bids":[{"price":63491.7,"qty":0.00000000},{"price":63488.2,"qty":0.00005100}],"asks":[],"checksum":3313231053,"timestamp":"2026-07-07T23:00:23.817116Z"}]}
{"channel":"book","type":"update","data":[{"symbol":"BTC/USD","bids":[{"price":63492.0,"qty":0.25296460}],"asks":[],"checksum":2297114039,"timestamp":"2026-07-07T23:00:23.819039Z"}]}
{"channel":"book","type":"update","data":[{"symbol":"BTC/USD","bids":[{"price":63489.9,"qty":0.23509207}],"asks":[],"checksum":2682518947,"timestamp":"2026-07-07T23:00:23.819384Z"}]}
{"channel":"book","type":"update","data":[{"symbol":"ETH/USD","bids":[{"price":1773.77,"qty":0.00000000},{"price":1773.65,"qty":0.48930000},{"price":1773.72,"qty":35.31904786}],"asks":[],"checksum":4061799345,"timestamp":"2026-07-07T23:00:23.834153Z"}]}
{"channel":"book","type":"update","data":[{"symbol":"ETH/USD","bids":[{"price":1773.91,"qty":1.43093769}],"asks":[],"checksum":3130502400,"timestamp":"2026-07-07T23:00:23.837457Z"}]}
{"channel":"book","type":"update","data":[{"symbol":"ETH/USD","bids":[{"price":1773.92,"qty":0.48930000}],"asks":[],"checksum":821230326,"timestamp":"2026-07-07T23:00:23.838752Z"}]}
{"channel":"book","type":"update","data":[{"symbol":"ETH/USD","bids":[{"price":1773.91,"qty":0.94163769}],"asks":[],"checksum":1968431773,"timestamp":"2026-07-07T23:00:23.839783Z"}]}
{"channel":"book","type":"update","data":[{"symbol":"ETH/USD","bids":[],"asks":[{"price":1774.08,"qty":0.00000000},{"price":1774.32,"qty":0.48930000}],"checksum":3469712296,"timestamp":"2026-07-07T23:00:23.842384Z"}]}
{"channel":"book","type":"update","data":[{"symbol":"BTC/USD","bids":[],"asks":[{"price":63498.6,"qty":0.00000000},{"price":63504.0,"qty":0.78740416}],"checksum":1780565279,"timestamp":"2026-07-07T23:00:23.844641Z"}]}
{"channel":"book","type":"update","data":[{"symbol":"BTC/USD","bids":[{"price":63491.9,"qty":0.00000000},{"price":63489.8,"qty":0.78752713}],"asks":[],"checksum":2000114769,"timestamp":"2026-07-07T23:00:23.844899Z"}]}
{"channel":"book","type":"update","data":[{"symbol":"BTC/USD","bids":[],"asks":[{"price":63499.7,"qty":0.00000000},{"price":63505.4,"qty":0.40000000}],"checksum":1794291730,"timestamp":"2026-07-07T23:00:23.845062Z"}]}
{"channel":"book","type":"update","data":[{"symbol":"ETH/USD","bids":[],"asks":[{"price":1774.13,"qty":0.00000000},{"price":1774.33,"qty":19.84616104}],"checksum":723627947,"timestamp":"2026-07-07T23:00:23.846695Z"}]}
{"channel":"book","type":"update","data":[{"symbol":"BTC/USD","bids":[{"price":63492.0,"qty":0.00000000},{"price":63488.2,"qty":0.00005100}],"asks":[],"checksum":1314962621,"timestamp":"2026-07-07T23:00:23.847131Z"}]}
{"channel":"book","type":"update","data":[{"symbol":"BTC/USD","bids":[],"asks":[{"price":63504.0,"qty":0.00005100}],"checksum":4054416455,"timestamp":"2026-07-07T23:00:23.847342Z"}]}
{"channel":"book","type":"update","data":[{"symbol":"BTC/USD","bids":[],"asks":[{"price":63498.5,"qty":0.35444250}],"checksum":614619908,"timestamp":"2026-07-07T23:00:23.848782Z"}]}
{"channel":"book","type":"update","data":[{"symbol":"ETH/USD","bids":[],"asks":[{"price":1774.17,"qty":2.81822055}],"checksum":2076013812,"timestamp":"2026-07-07T23:00:23.849541Z"}]}
{"channel":"book","type":"update","data":[{"symbol":"BTC/USD","bids":[{"price":63491.7,"qty":0.01789537}],"asks":[],"checksum":70567838,"timestamp":"2026-07-07T23:00:23.849997Z"}]}
{"channel":"book","type":"update","data":[{"symbol":"ETH/USD","bids":[{"price":1773.68,"qty":28.76270544}],"asks":[],"checksum":3741278410,"timestamp":"2026-07-07T23:00:23.850030Z"}]}
{"channel":"book","type":"update","data":[{"symbol":"BTC/USD","bids":[],"asks":[{"price":63500.9,"qty":0.00000000},{"price":63507.1,"qty":0.01200000}],"checksum":1561223377,"timestamp":"2026-07-07T23:00:23.851139Z"}]}
{"channel":"book","type":"update","data":[{"symbol":"BTC/USD","bids":[],"asks":[{"price":63505.3,"qty":0.19394864}],"checksum":1868397781,"timestamp":"2026-07-07T23:00:23.853343Z"}]}
{"channel":"book","type":"update","data":[{"symbol":"ETH/USD","bids":[{"price":1773.73,"qty":5.56003448}],"asks":[],"checksum":659736480,"timestamp":"2026-07-07T23:00:23.853390Z"}]}
{"channel":"book","type":"update","data":[{"symbol":"ETH/USD","bids":[{"price":1773.72,"qty":42.82171279}],"asks":[],"checksum":2239512961,"timestamp":"2026-07-07T23:00:23.853782Z"}]}
{"channel":"book","type":"update","data":[{"symbol":"BTC/USD","bids":[],"asks":[{"price":63501.6,"qty":0.31951707}],"checksum":3181789009,"timestamp":"2026-07-07T23:00:23.853938Z"}]}
{"channel":"book","type":"update","data":[{"symbol":"ETH/USD","bids":[],"asks":[{"price":1774.17,"qty":0.00000000},{"price":1774.33,"qty":19.84616104}],"checksum":2841533402,"timestamp":"2026-07-07T23:00:23.856541Z"}]}
{"channel":"book","type":"update","data":[{"symbol":"ETH/USD","bids":[{"price":1773.87,"qty":0.00000000},{"price":1773.66,"qty":1.30000000}],"asks":[],"checksum":371880361,"timestamp":"2026-07-07T23:00:23.856730Z"}]}
{"channel":"book","type":"update","data":[{"symbol":"ETH/USD","bids":[{"price":1773.91,"qty":3.76026520}],"asks":[],"checksum":1047315692,"timestamp":"2026-07-07T23:00:23.858849Z"}]}
{"channel":"book","type":"update","data":[{"symbol":"ETH/USD","bids":[{"price":1773.91,"qty":2.81862751}],"asks":[],"checksum":196744629,"timestamp":"2026-07-07T23:00:23.859033Z"}]}
{"channel":"book","type":"update","data":[{"symbol":"ETH/USD","bids":[],"asks":[{"price":1773.96,"qty":0.00000000},{"price":1774.35,"qty":31.09405510}],"checksum":2941520288,"timestamp":"2026-07-07T23:00:23.861315Z"}]}
{"channel":"book","type":"update","data":[{"symbol":"ETH/USD","bids":[],"asks":[{"price":1774.08,"qty":0.47001888}],"checksum":722948358,"timestamp":"2026-07-07T23:00:23.861415Z"}]}
{"channel":"book","type":"update","data":[{"symbol":"ETH/USD","bids":[{"price":1773.92,"qty":1.43092086}],"asks":[],"checksum":4178379158,"timestamp":"2026-07-07T23:00:23.861526Z"}]}
{"channel":"book","type":"update","data":[{"symbol":"ETH/USD","bids":[{"price":1773.96,"qty":0.48930000}],"asks":[],"checksum":4092683608,"timestamp":"2026-07-07T23:00:23.863784Z"}]}
{"channel":"book","type":"update","data":[{"symbol":"ETH/USD","bids":[{"price":1773.92,"qty":0.94162086}],"asks":[],"checksum":309464150,"timestamp":"2026-07-07T23:00:23.864568Z"}]}
{"channel":"book","type":"update","data":[{"symbol":"BTC/USD","bids":[],"asks":[{"price":63498.1,"qty":0.76737389}],"checksum":1394869962,"timestamp":"2026-07-07T23:00:23.870518Z"}]}
{"channel":"book","type":"update","data":[{"symbol":"ETH/USD","bids":[],"asks":[{"price":1773.99,"qty":0.00000000},{"price":1774.35,"qty":31.09405510}],"checksum":1289139903,"timestamp":"2026-07-07T23:00:23.893628Z"}]}
{"channel":"book","type":"update","data":[{"symbol":"ETH/USD","bids":[],"asks":[{"price":1774.08,"qty":0.61099102}],"checksum":1910999007,"timestamp":"2026-07-07T23:00:23.893930Z"}]}
{"channel":"book","type":"update","data":[{"symbol":"ETH/USD","bids":[],"asks":[{"price":1774.07,"qty":1.53128753}],"checksum":2365374715,"timestamp":"2026-07-07T23:00:23.895781Z"}]}
{"channel":"book","type":"update","data":[{"symbol":"ETH/USD","bids":[],"asks":[{"price":1774.08,"qty":0.14097214}],"checksum":2382258480,"timestamp":"2026-07-07T23:00:23.897294Z"}]}
{"channel":"book","type":"update","data":[{"symbol":"BTC/USD","bids":[],"asks":[{"price":63498.1,"qty":0.67345424}],"checksum":281089582,"timestamp":"2026-07-07T23:00:23.915231Z"}]}
{"channel":"book","type":"update","data":[{"symbol":"BTC/USD","bids":[],"asks":[{"price":63498.5,"qty":0.00000000},{"price":63505.4,"qty":0.40000000}],"checksum":1634779963,"timestamp":"2026-07-07T23:00:23.915688Z"}]}
{"channel":"book","type":"update","data":[{"symbol":"BTC/USD","bids":[{"price":63493.7,"qty":0.78747893}],"asks":[],"checksum":3287628380,"timestamp":"2026-07-07T23:00:23.917156Z"}]}
{"channel":"book","type":"update","data":[{"symbol":"ETH/USD","bids":[],"asks":[{"price":1774.07,"qty":0.00000000},{"price":1774.35,"qty":31.09405510}],"checksum":452902793,"timestamp":"2026-07-07T23:00:23.918085Z"}]}
{"channel":"book","type":"update","data":[{"symbol":"ETH/USD","bids":[],"asks":[{"price":1774.33,"qty":0.00000000},{"price":1774.36,"qty":7.93647210}],"checksum":3064361621,"timestamp":"2026-07-07T23:00:23.918874Z"}]}
{"channel":"book","type":"update","data":[{"symbol":"ETH/USD","bids":[{"price":1773.68,"qty":28.18986449}],"asks":[],"checksum":2457415179,"timestamp":"2026-07-07T23:00:23.919019Z"}]}
{"channel":"book","type":"update","data":[{"symbol":"BTC/USD","bids":[],"asks":[{"price":63501.6,"qty":0.00000000},{"price":63506.0,"qty":0.78732765}],"checksum":3652183602,"timestamp":"2026-07-07T23:00:23.919158Z"}]}
{"channel":"book","type":"update","data":[{"symbol":"ETH/USD","bids":[{"price":1773.84,"qty":0.54387671}],"asks":[],"checksum":2323717418,"timestamp":"2026-07-07T23:00:23.919250Z"}]}
{"channel":"book","type":"update","data":[{"symbol":"BTC/USD","bids":[],"asks":[{"price":63498.1,"qty":0.09410424}],"checksum":3112816676,"timestamp":"2026-07-07T23:00:23.919565Z"}]}
{"channel":"book","type":"update","data":[{"symbol":"ETH/USD","bids":[],"asks":[{"price":1774.32,"qty":0.00000000},{"price":1774.37,"qty":0.50000000}],"checksum":63643632,"timestamp":"2026-07-07T23:00:23.919868Z"}]}
{"channel":"book","type":"update","data":[{"symbol":"ETH/USD","bids":[],"asks":[{"price":1774.36,"qty":2.29747210}],"checksum":956318216,"timestamp":"2026-07-07T23:00:23.920155Z"}]}
{"channel":"book","type":"update","data":[{"symbol":"BTC/USD","bids":[{"price":63493.7,"qty":0.00000000},{"price":63489.8,"qty":0.78752713}],"asks":[],"checksum":453781827,"timestamp":"2026-07-07T23:00:23.920498Z"}]}
{"channel":"book","type":"update","data":[{"symbol":"ETH/USD","bids":[{"price":1773.69,"qty":0.00000000},{"price":1773.68,"qty":28.18986449},{"price":1773.74,"qty":1.68966976}],"asks":[],"checksum":4194692096,"timestamp":"2026-07-07T23:00:23.921529Z"}]}
{"channel":"book","type":"update","data":[{"symbol":"ETH/USD","bids":[],"asks":[{"price":1774.09,"qty":0.00000000},{"price":1774.40,"qty":0.02770405}],"checksum":2786309185,"timestamp":"2026-07-07T23:00:23.922969Z"}]}
{"channel":"book","type":"update","data":[{"symbol":"ETH/USD","bids":[],"asks":[{"price":1774.40,"qty":0.00000000},{"price":1774.41,"qty":1.30000000}],"checksum":1932173205,"timestamp":"2026-07-07T23:00:23.923090Z"}]}
{"channel":"book","type":"update","data":[{"symbol":"ETH/USD","bids":[],"asks":[{"price":1774.37,"qty":0.00000000},{"price":1774.44,"qty":0.28137208}],"checksum":2099990926,"timestamp":"2026-07-07T23:00:23.925466Z"}]}
{"channel":"book","type":"update","data":[{"symbol":"ETH/USD","bids":[],"asks":[{"price":1774.35,"qty":2.91460658}],"checksum":4197148007,"timestamp":"2026-07-07T23:00:23.926573Z"}]}
{"channel":"book","type":"update","data":[{"symbol":"BTC/USD","bids":[],"asks":[{"price":63506.0,"qty":0.00000000},{"price":63507.1,"qty":0.01200000}],"checksum":4238053932,"timestamp":"2026-07-07T23:00:23.927152Z"}]}
{"channel":"book","type":"update","data":[{"symbol":"BTC/USD","bids":[{"price":63494.8,"qty":0.60470924}],"asks":[],"checksum":3082790713,"timestamp":"2026-07-07T23:00:23.931528Z"}]}
{"channel":"book","type":"update","data":[{"symbol":"BTC/USD","bids":[{"price":63491.7,"qty":0.00000000},{"price":63489.8,"qty":0.78752713}],"asks":[],"checksum":548398936,"timestamp":"2026-07-07T23:00:23.934731Z"}]}
{"channel":"book","type":"update","data":[{"symbol":"BTC/USD","bids":[{"price":63491.5,"qty":0.11000000}],"asks":[],"checksum":3602181743,"timestamp":"2026-07-07T23:00:23.935304Z"}]}
{"channel":"book","type":"update","data":[{"symbol":"BTC/USD","bids":[{"price":63494.8,"qty":0.00000000},{"price":63489.8,"qty":0.78752713}],"asks":[],"checksum":1680308041,"timestamp":"2026-07-07T23:00:23.935336Z"}]}
{"channel":"book","type":"update","data":[{"symbol":"BTC/USD","bids":[],"asks":[{"price":63498.1,"qty":0.08623426}],"checksum":3151932312,"timestamp":"2026-07-07T23:00:23.935853Z"}]}
{"channel":"book","type":"update","data":[{"symbol":"ETH/USD","bids":[],"asks":[{"price":1774.22,"qty":0.00000000},{"price":1774.50,"qty":0.48930000}],"checksum":4004025437,"timestamp":"2026-07-07T23:00:23.937813Z"}]}
{"channel":"book","type":"update","data":[{"symbol":"ETH/USD","bids":[],"asks":[{"price":1774.29,"qty":0.00000000},{"price":1774.54,"qty":12.35426731}],"checksum":1567509103,"timestamp":"2026-07-07T23:00:23.937828Z"}]}
{"channel":"book","type":"update","data":[{"symbol":"ETH/USD","bids":[{"price":1773.97,"qty":1.30000000}],"asks":[],"checksum":2503394003,"timestamp":"2026-07-07T23:00:23.939256Z"}]}
{"channel":"book","type":"update","data":[{"symbol":"BTC/USD","bids":[],"asks":[{"price":63505.3,"qty":0.33321858}],"checksum":2817386340,"timestamp":"2026-07-07T23:00:23.940162Z"}]}
{"channel":"book","type":"update","data":[{"symbol":"ETH/USD","bids":[{"price":1773.91,"qty":0.00000000},{"price":1773.71,"qty":19.84616104}],"asks":[],"checksum":3102373627,"timestamp":"2026-07-07T23:00:23.941166Z"}]}
{"channel":"book","type":"update","data":[{"symbol":"ETH/USD","bids":[],"asks":[{"price":1774.29,"qty":4.74570421}],"checksum":4288684670,"timestamp":"2026-07-07T23:00:23.941784Z"}]}
{"channel":"book","type":"update","data":[{"symbol":"ETH/USD","bids":[],"asks":[{"price":1774.16,"qty":0.00000000},{"price":1774.54,"qty":12.35426731}],"checksum":740621020,"timestamp":"2026-07-07T23:00:23.942269Z"}]}
{"channel":"book","type":"update","data":[{"symbol":"BTC/USD","bids":[],"asks":[{"price":63498.1,"qty":0.06410344}],"checksum":2201550998,"timestamp":"2026-07-07T23:00:23.942297Z"}]}
{"channel":"book","type":"update","data":[{"symbol":"ETH/USD","bids":[],"asks":[{"price":1774.54,"qty":0.00000000},{"price":1774.55,"qty":0.33811388}],"checksum":2613792859,"timestamp":"2026-07-07T23:00:23.942850Z"}]}
{"channel":"book","type":"update","data":[{"symbol":"ETH/USD","bids":[{"price":1773.72,"qty":14.63620950},{"price":1773.92,"qty":29.12688544}],"asks":[],"checksum":3787710773,"timestamp":"2026-07-07T23:00:23.945605Z"}]}
{"channel":"book","type":"update","data":[{"symbol":"BTC/USD","bids":[{"price":63491.1,"qty":0.00000000},{"price":63488.2,"qty":0.00005100}],"asks":[],"checksum":1828441002,"timestamp":"2026-07-07T23:00:23.947178Z"}]}
{"channel":"book","type":"update","data":[{"symbol":"ETH/USD","bids":[],"asks":[{"price":1774.55,"qty":20.18427492}],"checksum":184958796,"timestamp":"2026-07-07T23:00:23.948406Z"}]}
{"channel":"book","type":"update","data":[{"symbol":"BTC/USD","bids":[],"asks":[{"price":63505.3,"qty":0.19394864}],"checksum":2014997650,"timestamp":"2026-07-07T23:00:23.948873Z"}]}
{"channel":"book","type":"update","data":[{"symbol":"ETH/USD","bids":[],"asks":[{"price":1774.47,"qty":2.66933048}],"checksum":684879610,"timestamp":"2026-07-07T23:00:23.949210Z"}]}
{"channel":"book","type":"update","data":[{"symbol":"ETH/USD","bids":[],"asks":[{"price":1774.36,"qty":0.00000000},{"price":1774.55,"qty":20.18427492}],"checksum":1586997599,"timestamp":"2026-07-07T23:00:23.949389Z"}]}
{"channel":"book","type":"update","data":[{"symbol":"ETH/USD","bids":[{"price":1773.96,"qty":0.00000000},{"price":1773.66,"qty":1.30000000}],"asks":[],"checksum":3503262201,"timestamp":"2026-07-07T23:00:23.949886Z"}]}
{"channel":"book","type":"update","data":[{"symbol":"BTC/USD","bids":[],"asks":[{"price":63502.6,"qty":0.00000000},{"price":63507.2,"qty":0.00005100}],"checksum":1015194895,"timestamp":"2026-07-07T23:00:23.953150Z"}]}
{"channel":"book","type":"update","data":[{"symbol":"BTC/USD","bids":[{"price":63495.2,"qty":0.02989458}],"asks":[],"checksum":1608467658,"timestamp":"2026-07-07T23:00:23.954146Z"}]}
{"channel":"book","type":"update","data":[{"symbol":"BTC/USD","bids":[{"price":63489.8,"qty":0.00000000},{"price":63488.2,"qty":0.00005100}],"asks":[],"checksum":1493565149,"timestamp":"2026-07-07T23:00:23.954175Z"}]}
{"channel":"book","type":"update","data":[{"symbol":"ETH/USD","bids":[{"price":1773.73,"qty":0.00000000},{"price":1773.65,"qty":0.48930000},{"price":1773.79,"qty":5.56003448}],"asks":[],"checksum":3325752754,"timestamp":"2026-07-07T23:00:23.954753Z"}]}
{"channel":"book","type":"update","data":[{"symbol":"BTC/USD","bids":[{"price":63498.0,"qty":1.13346166}],"asks":[],"checksum":637268342,"timestamp":"2026-07-07T23:00:23.955134Z"}]}
{"channel":"book","type":"update","data":[{"symbol":"ETH/USD","bids":[],"asks":[{"price":1774.35,"qty":0.00000000},{"price":1774.59,"qty":2.87402415}],"checksum":3115226856,"timestamp":"2026-07-07T23:00:23.955875Z"}]}
{"channel":"book","type":"update","data":[{"symbol":"BTC/USD","bids":[],"asks":[{"price":63505.3,"qty":0.00000000},{"price":63507.8,"qty":0.27925236}],"checksum":222587135,"timestamp":"2026-07-07T23:00:23.960314Z"}]}
{"channel":"book","type":"update","data":[{"symbol":"ETH/USD","bids":[],"asks":[{"price":1774.31,"qty":15.64420000}],"checksum":89516756,"timestamp":"2026-07-07T23:00:23.960930Z"}]}
{"channel":"book","type":"update","data":[{"symbol":"ETH/USD","bids":[],"asks":[{"price":1774.55,"qty":20.01521798}],"checksum":794674094,"timestamp":"2026-07-07T23:00:23.963152Z"}]}
{"channel":"book","type":"update","data":[{"symbol":"ETH/USD","bids":[],"asks":[{"price":1774.47,"qty":0.00000000},{"price":1774.59,"qty":2.87402415}],"checksum":1235411257,"timestamp":"2026-07-07T23:00:23.964831Z"}]}
{"channel":"book","type":"update","data":[{"symbol":"BTC/USD","bids":[{"price":63498.0,"qty":1.13661137}],"asks":[],"checksum":3679292794,"timestamp":"2026-07-07T23:00:23.965875Z"}]}
{"channel":"book","type":"update","data":[{"symbol":"ETH/USD","bids":[],"asks":[{"price":1774.55,"qty":19.84616104}],"checksum":3692779757,"timestamp":"2026-07-07T23:00:23.966382Z"}]}
{"channel":"book","type":"update","data":[{"symbol":"ETH/USD","bids":[{"price":1773.84,"qty":0.00000000},{"price":1773.65,"qty":0.48930000}],"asks":[],"checksum":1804988361,"timestamp":"2026-07-07T23:00:23.967912Z"}]}
{"channel":"book","type":"update","data":[{"symbol":"ETH/USD","bids":[],"asks":[{"price":1774.43,"qty":2.81780677}],"checksum":3639839612,"timestamp":"2026-07-07T23:00:23.969395Z"}]}
{"channel":"book","type":"update","data":[{"symbol":"BTC/USD","bids":[{"price":63494.9,"qty":0.18052093}],"asks":[],"checksum":1326952870,"timestamp":"2026-07-07T23:00:23.969812Z"}]}
{"channel":"book","type":"update","data":[{"symbol":"ETH/USD","bids":[{"price":1774.05,"qty":2.81839433}],"asks":[],"checksum":3212210805,"timestamp":"2026-07-07T23:00:23.970082Z"}]}
{"channel":"book","type":"update","data":[{"symbol":"ETH/USD","bids":[{"price":1773.69,"qty":140.94885588}],"asks":[],"checksum":75068426,"timestamp":"2026-07-07T23:00:23.970240Z"}]}
{"channel":"book","type":"update","data":[{"symbol":"BTC/USD","bids":[{"price":63494.9,"qty":0.00000000},{"price":63488.2,"qty":0.00005100}],"asks":[],"checksum":3679292794,"timestamp":"2026-07-07T23:00:23.970695Z"}]}
{"channel":"book","type":"update","data":[{"symbol":"ETH/USD","bids":[],"asks":[{"price":1774.41,"qty":0.00000000},{"price":1774.59,"qty":2.87402415}],"checksum":2022319410,"timestamp":"2026-07-07T23:00:23.973219Z"}]}
{"channel":"book","type":"update","data":[{"symbol":"ETH/USD","bids":[],"asks":[{"price":1774.59,"qty":0.00000000},{"price":1774.62,"qty":12.35426731}],"checksum":3350977816,"timestamp":"2026-07-07T23:00:23.973571Z"}]}
{"channel":"book","type":"update","data":[{"symbol":"ETH/USD","bids":[{"price":1773.71,"qty":0.00000000},{"price":1773.66,"qty":1.30000000}],"asks":[],"checksum":310982394,"timestamp":"2026-07-07T23:00:23.984795Z"}]}
{"channel":"book","type":"update","data":[{"symbol":"ETH/USD","bids":[{"price":1774.07,"qty":0.48930000}],"asks":[],"checksum":3837006784,"timestamp":"2026-07-07T23:00:23.989494Z"}]}
{"channel":"book","type":"update","data":[{"symbol":"ETH/USD","bids":[{"price":1773.78,"qty":0.00000000},{"price":1773.66,"qty":1.30000000}],"asks":[],"checksum":16786529,"timestamp":"2026-07-07T23:00:23.991193Z"}]}
{"channel":"book","type":"update","data":[{"symbol":"ETH/USD","bids":[],"asks":[{"price":1774.37,"qty":0.37031102}],"checksum":93959648,"timestamp":"2026-07-07T23:00:23.992185Z"}]}
{"channel":"book","type":"update","data":[{"symbol":"ETH/USD","bids":[{"price":1773.79,"qty":0.00000000},{"price":1773.65,"qty":0.48930000}],"asks":[],"checksum":4247041495,"timestamp":"2026-07-07T23:00:23.992844Z"}]}
{"channel":"book","type":"update","data":[{"symbol":"ETH/USD","bids":[],"asks":[{"price":1774.43,"qty":0.00000000},{"price":1774.62,"qty":12.35426731}],"checksum":2534849276,"timestamp":"2026-07-07T23:00:23.994303Z"}]}
{"channel":"book","type":"update","data":[{"symbol":"ETH/USD","bids":[{"price":1773.98,"qty":0.33164537}],"asks":[],"checksum":1971282301,"timestamp":"2026-07-07T23:00:23.994413Z"}]}
{"channel":"book","type":"update","data":[{"symbol":"ETH/USD","bids":[],"asks":[{"price":1774.29,"qty":0.00000000},{"price":1774.69,"qty":36.29700000}],"checksum":870178593,"timestamp":"2026-07-07T23:00:23.995346Z"}]}
{"channel":"book","type":"update","data":[{"symbol":"BTC/USD","bids":[{"price":63498.0,"qty":1.74132061}],"asks":[],"checksum":840795465,"timestamp":"2026-07-07T23:00:23.995462Z"}]}
{"channel":"book","type":"update","data":[{"symbol":"ETH/USD","bids":[{"price":1773.72,"qty":7.13354457}],"asks":[],"checksum":1660700330,"timestamp":"2026-07-07T23:00:23.996140Z"}]}
{"channel":"book","type":"update","data":[{"symbol":"ETH/USD","bids":[{"price":1773.90,"qty":0.00000000},{"price":1773.65,"qty":0.48930000}],"asks":[],"checksum":1964552347,"timestamp":"2026-07-07T23:00:23.996211Z"}]}
{"channel":"book","type":"update","data":[{"symbol":"ETH/USD","bids":[],"asks":[{"price":1774.08,"qty":0.00000000},{"price":1774.76,"qty":0.48930000}],"checksum":1415437359,"timestamp":"2026-07-07T23:00:23.999214Z"}]}
{"channel":"book","type":"update","data":[{"symbol":"ETH/USD","bids":[],"asks":[{"price":1774.62,"qty":0.00000000},{"price":1774.81,"qty":0.33806434},{"price":1774.67,"qty":12.35426731}],"checksum":1137516321,"timestamp":"2026-07-07T23:00:24.002048Z"}]}
{"channel":"book","type":"update","data":[{"symbol":"ETH/USD","bids":[{"price":1773.72,"qty":41.69532992}],"asks":[],"checksum":2517345913,"timestamp":"2026-07-07T23:00:24.002181Z"}]}
{"channel":"book","type":"update","data":[{"symbol":"BTC/USD","bids":[{"price":63489.9,"qty":0.00000000},{"price":63485.6,"qty":0.02727448}],"asks":[],"checksum":1710175335,"timestamp":"2026-07-07T23:00:24.003616Z"}]}
{"channel":"book","type":"update","data":[{"symbol":"ETH/USD","bids":[{"price":1774.06,"qty":0.54387671}],"asks":[],"checksum":3877920120,"timestamp":"2026-07-07T23:00:24.005147Z"}]}
{"channel":"book","type":"update","data":[{"symbol":"ETH/USD","bids":[{"price":1774.15,"qty":19.84616104}],"asks":[],"checksum":475962306,"timestamp":"2026-07-07T23:00:24.005480Z"}]}
{"channel":"book","type":"update","data":[{"symbol":"BTC/USD","bids":[],"asks":[{"price":63507.8,"qty":0.05073037}],"checksum":3077508757,"timestamp":"2026-07-07T23:00:24.010720Z"}]}
{"channel":"book","type":"update","data":[{"symbol":"ETH/USD","bids":[],"asks":[{"price":1774.53,"qty":4.64657199}],"checksum":180936038,"timestamp":"2026-07-07T23:00:24.011851Z"}]}
{"channel":"book","type":"update","data":[{"symbol":"ETH/USD","bids":[{"price":1773.92,"qty":28.18526458}],"asks":[],"checksum":3392417863,"timestamp":"2026-07-07T23:00:24.012286Z"}]}
{"channel":"book","type":"update","data":[{"symbol":"BTC/USD","bids":[{"price":63491.7,"qty":0.05073037}],"asks":[],"checksum":1148886828,"timestamp":"2026-07-07T23:00:24.014373Z"}]}
{"channel":"book","type":"update","data":[{"symbol":"ETH/USD","bids":[{"price":1773.98,"qty":0.87552208}],"asks":[],"checksum":1250085257,"timestamp":"2026-07-07T23:00:24.015594Z"}]}
{"channel":"book","type":"update","data":[{"symbol":"ETH/USD","bids":[],"asks":[{"price":1774.31,"qty":0.00000000},{"price":1774.76,"qty":0.48930000}],"checksum":3712708140,"timestamp":"2026-07-07T23:00:24.022485Z"}]}
{"channel":"book","type":"update","data":[{"symbol":"ETH/USD","bids":[],"asks":[{"price":1774.53,"qty":0.00000000},{"price":1774.81,"qty":0.33806434}],"checksum":2095572821,"timestamp":"2026-07-07T23:00:24.022583Z"}]}
{"channel":"book","type":"update","data":[{"symbol":"ETH/USD","bids":[{"price":1773.93,"qty":5.56003448}],"asks":[],"checksum":1322860824,"timestamp":"2026-07-07T23:00:24.023659Z"}]}
{"channel":"book","type":"update","data":[{"symbol":"ETH/USD","bids":[],"asks":[{"price":1774.30,"qty":0.00000000},{"price":1774.88,"qty":10.60120175}],"checksum":3123105897,"timestamp":"2026-07-07T23:00:24.023710Z"}]}
{"channel":"book","type":"update","data":[{"symbol":"ETH/USD","bids":[],"asks":[{"price":1774.50,"qty":0.00000000},{"price":1774.89,"qty":50.72542230}],"checksum":2231014318,"timestamp":"2026-07-07T23:00:24.025180Z"}]}
{"channel":"book","type":"update","data":[{"symbol":"ETH/USD","bids":[],"asks":[{"price":1774.46,"qty":0.30935016}],"checksum":3163493259,"timestamp":"2026-07-07T23:00:24.025289Z"}]}
{"channel":"book","type":"update","data":[{"symbol":"ETH/USD","bids":[],"asks":[{"price":1774.55,"qty":0.00000000},{"price":1774.89,"qty":50.72542230}],"checksum":2857424564,"timestamp":"2026-07-07T23:00:24.025432Z"}]}
{"channel":"book","type":"update","data":[{"symbol":"ETH/USD","bids":[{"price":1773.98,"qty":0.33164537}],"asks":[],"checksum":3802249427,"timestamp":"2026-07-07T23:00:24.025990Z"}]}
{"channel":"book","type":"update","data":[{"symbol":"BTC/USD","bids":[],"asks":[{"price":63501.7,"qty":0.00000000},{"price":63510.1,"qty":0.01021802}],"checksum":2165355952,"timestamp":"2026-07-07T23:00:24.026954Z"}]}
{"channel":"book","type":"update","data":[{"symbol":"ETH/USD","bids":[{"price":1774.05,"qty":0.00000000},{"price":1773.69,"qty":140.94885588}],"asks":[],"checksum":3682981309,"timestamp":"2026-07-07T23:00:24.032796Z"}]}
{"channel":"book","type":"update","data":[{"symbol":"ETH/USD","bids":[{"price":1773.69,"qty":0.00000000},{"price":1773.66,"qty":1.30000000}],"asks":[],"checksum":4161042353,"timestamp":"2026-07-07T23:00:24.033126Z"}]}
{"channel":"book","type":"update","data":[{"symbol":"BTC/USD","bids":[{"price":63498.0,"qty":1.77121519}],"asks":[],"checksum":4211868422,"timestamp":"2026-07-07T23:00:24.033591Z"}]}
{"channel":"book","type":"update","data":[{"symbol":"ETH/USD","bids":[],"asks":[{"price":1774.37,"qty":0.00000000},{"price":1774.90,"qty":140.85351961}],"checksum":3316557498,"timestamp":"2026-07-07T23:00:24.033765Z"}]}
{"channel":"book","type":"update","data":[{"symbol":"ETH/USD","bids":[{"price":1774.24,"qty":0.48930000}],"asks":[],"checksum":3335403239,"timestamp":"2026-07-07T23:00:24.035182Z"}]}
{"channel":"book","type":"update","data":[{"symbol":"ETH/USD","bids":[{"price":1773.72,"qty":7.13354457}],"asks":[],"checksum":3590075178,"timestamp":"2026-07-07T23:00:24.037939Z"}]}
{"channel":"book","type":"update","data":[{"symbol":"ETH/USD","bids":[],"asks":[{"price":1774.54,"qty":10.52018757}],"checksum":1038110937,"timestamp":"2026-07-07T23:00:24.038123Z"}]}
{"channel":"book","type":"update","data":[{"symbol":"ETH/USD","bids":[{"price":1773.80,"qty":2.16403672}],"asks":[],"checksum":3918099257,"timestamp":"2026-07-07T23:00:24.038660Z"}]}
{"channel":"book","type":"update","data":[{"symbol":"ETH/USD","bids":[{"price":1773.94,"qty":2.87402415}],"asks":[],"checksum":2592537583,"timestamp":"2026-07-07T23:00:24.039146Z"}]}
{"channel":"book","type":"update","data":[{"symbol":"ETH/USD","bids":[],"asks":[{"price":1774.55,"qty":1.68966976}],"checksum":2343586155,"timestamp":"2026-07-07T23:00:24.041212Z"}]}
{"channel":"book","type":"update","data":[{"symbol":"ETH/USD","bids":[{"price":1773.93,"qty":14.07359650}],"asks":[],"checksum":3520083148,"timestamp":"2026-07-07T23:00:24.044200Z"}]}
{"channel":"book","type":"update","data":[{"symbol":"BTC/USD","bids":[{"price":63498.0,"qty":1.89217519}],"asks":[],"checksum":4223734173,"timestamp":"2026-07-07T23:00:24.044326Z"}]}
{"channel":"book","type":"update","data":[{"symbol":"BTC/USD","bids":[],"asks":[{"price":63507.8,"qty":0.00000000},{"price":63510.3,"qty":0.00005100}],"checksum":2132487658,"timestamp":"2026-07-07T23:00:24.045011Z"}]}
{"channel":"book","type":"update","data":[{"symbol":"ETH/USD","bids":[{"price":1773.93,"qty":8.51356202}],"asks":[],"checksum":4077752081,"timestamp":"2026-07-07T23:00:24.046585Z"}]}
{"channel":"book","type":"update","data":[{"symbol":"BTC/USD","bids":[{"price":63498.0,"qty":2.02326921}],"asks":[],"checksum":2367287127,"timestamp":"2026-07-07T23:00:24.047864Z"}]}
{"channel":"book","type":"update","data":[{"symbol":"BTC/USD","bids":[{"price":63498.0,"qty":2.13326921}],"asks":[],"checksum":710873030,"timestamp":"2026-07-07T23:00:24.047995Z"}]}
{"channel":"book","type":"update","data":[{"symbol":"ETH/USD","bids":[],"asks":[{"price":1774.67,"qty":19.00209179}],"checksum":469419081,"timestamp":"2026-07-07T23:00:24.049606Z"}]}
{"channel":"book","type":"update","data":[{"symbol":"BTC/USD","bids":[],"asks":[{"price":63510.1,"qty":0.00000000},{"price":63513.5,"qty":0.00005100}],"checksum":1876243749,"timestamp":"2026-07-07T23:00:24.050595Z"}]}
{"channel":"book","type":"update","data":[{"symbol":"BTC/USD","bids":[],"asks":[{"price":63505.4,"qty":0.00000000},{"price":63514.0,"qty":0.48142856}],"checksum":3952727496,"timestamp":"2026-07-07T23:00:24.051438Z"}]}
{"channel":"book","type":"update","data":[{"symbol":"ETH/USD","bids":[],"asks":[{"price":1774.44,"qty":0.00000000},{"price":1774.89,"qty":50.72542230}],"checksum":2592468835,"timestamp":"2026-07-07T23:00:24.053050Z"}]}
{"channel":"book","type":"update","data":[{"symbol":"BTC/USD","bids":[],"asks":[{"price":63498.1,"qty":0.04835494}],"checksum":3769965071,"timestamp":"2026-07-07T23:00:24.053869Z"}]}
{"channel":"book","type":"update","data":[{"symbol":"BTC/USD","bids":[],"asks":[{"price":63498.1,"qty":0.03260644}],"checksum":2122200880,"timestamp":"2026-07-07T23:00:24.054279Z"}]}
{"channel":"book","type":"update","data":[{"symbol":"ETH/USD","bids":[],"asks":[{"price":1774.89,"qty":0.00000000},{"price":1774.90,"qty":140.85351961}],"checksum":3496518739,"timestamp":"2026-07-07T23:00:24.055969Z"}]}
{"channel":"book","type":"update","data":[{"symbol":"ETH/USD","bids":[],"asks":[{"price":1774.67,"qty":6.64782448},{"price":1774.75,"qty":12.35426731}],"checksum":3815521450,"timestamp":"2026-07-07T23:00:24.056196Z"}]}
{"channel":"book","type":"update","data":[{"symbol":"ETH/USD","bids":[{"price":1774.24,"qty":1.78930000}],"asks":[],"checksum":607595130,"timestamp":"2026-07-07T23:00:24.058228Z"}]}
{"channel":"book","type":"update","data":[{"symbol":"BTC/USD","bids":[],"asks":[{"price":63514.0,"qty":0.46341570}],"checksum":1922503857,"timestamp":"2026-07-07T23:00:24.058709Z"}]}
{"channel":"book","type":"update","data":[{"symbol":"ETH/USD","bids":[],"asks":[{"price":1774.88,"qty":0.00000000},{"price":1774.90,"qty":140.85351961}],"checksum":2780549538,"timestamp":"2026-07-07T23:00:24.059113Z"}]}
{"channel":"book","type":"update","data":[{"symbol":"BTC/USD","bids":[{"price":63488.4,"qty":0.60470924}],"asks":[],"checksum":2057870371,"timestamp":"2026-07-07T23:00:24.059736Z"}]}
{"channel":"book","type":"update","data":[{"symbol":"ETH/USD","bids":[],"asks":[{"price":1774.90,"qty":141.22383063}],"checksum":2344891186,"timestamp":"2026-07-07T23:00:24.062245Z"}]}
{"channel":"book","type":"update","data":[{"symbol":"BTC/USD","bids":[],"asks":[{"price":63507.1,"qty":0.00000000},{"price":63516.0,"qty":0.01574406}],"checksum":841717440,"timestamp":"2026-07-07T23:00:24.063517Z"}]}
{"channel":"book","type":"update","data":[{"symbol":"ETH/USD","bids":[],"asks":[{"price":1774.81,"qty":0.16903217}],"checksum":1315238027,"timestamp":"2026-07-07T23:00:24.063552Z"}]}
{"channel":"book","type":"update","data":[{"symbol":"ETH/USD","bids":[{"price":1773.80,"qty":0.00000000},{"price":1773.74,"qty":1.68966976}],"asks":[],"checksum":3207692254,"timestamp":"2026-07-07T23:00:24.066708Z"}]}
{"channel":"book","type":"update","data":[{"symbol":"ETH/USD","bids":[],"asks":[{"price":1774.55,"qty":0.00000000},{"price":1774.91,"qty":0.02770405},{"price":1774.66,"qty":1.68966976}],"checksum":1779812349,"timestamp":"2026-07-07T23:00:24.067946Z"}]}
{"channel":"book","type":"update","data":[{"symbol":"BTC/USD","bids":[],"asks":[{"price":63514.0,"qty":0.00000000},{"price":63520.2,"qty":0.00388539}],"checksum":2008134915,"timestamp":"2026-07-07T23:00:24.069079Z"}]}
{"channel":"book","type":"update","data":[{"symbol":"ETH/USD","bids":[],"asks":[{"price":1774.46,"qty":0.00000000},{"price":1774.91,"qty":0.02770405}],"checksum":715300014,"timestamp":"2026-07-07T23:00:24.070324Z"}]}
{"channel":"book","type":"update","data":[{"symbol":"ETH/USD","bids":[],"asks":[{"price":1774.54,"qty":0.00000000},{"price":1774.96,"qty":0.48930000}],"checksum":144173097,"timestamp":"2026-07-07T23:00:24.071333Z"}]}
{"channel":"book","type":"update","data":[{"symbol":"BTC/USD","bids":[{"price":63495.2,"qty":0.00000000},{"price":63488.2,"qty":0.00005100}],"asks":[],"checksum":483815278,"timestamp":"2026-07-07T23:00:24.071371Z"}]}
{"channel":"book","type":"update","data":[{"symbol":"ETH/USD","bids":[],"asks":[{"price":1774.75,"qty":0.00000000},{"price":1775.03,"qty":0.16901122},{"price":1774.89,"qty":12.35426731}],"checksum":1268303189,"timestamp":"2026-07-07T23:00:24.071618Z"}]}
{"channel":"book","type":"update","data":[{"symbol":"ETH/USD","bids":[],"asks":[{"price":1774.89,"qty":0.00000000},{"price":1775.03,"qty":0.16901122},{"price":1774.93,"qty":12.35426731}],"checksum":1088298950,"timestamp":"2026-07-07T23:00:24.074366Z"}]}
{"channel":"book","type":"update","data":[{"symbol":"ETH/USD","bids":[{"price":1773.89,"qty":0.48930000}],"asks":[],"checksum":4182368153,"timestamp":"2026-07-07T23:00:24.075638Z"}]}
{"channel":"book","type":"update","data":[{"symbol":"ETH/USD","bids":[{"price":1774.06,"qty":0.00000000},{"price":1773.74,"qty":1.68966976}],"asks":[],"checksum":1174771181,"timestamp":"2026-07-07T23:00:24.081572Z"}]}
{"channel":"book","type":"update","data":[{"symbol":"BTC/USD","bids":[],"asks":[{"price":63514.0,"qty":0.18276969}],"checksum":312824481,"timestamp":"2026-07-07T23:00:24.082715Z"}]}
{"channel":"book","type":"update","data":[{"symbol":"ETH/USD","bids":[{"price":1774.20,"qty":0.33447626}],"asks":[],"checksum":3988195408,"timestamp":"2026-07-07T23:00:24.083344Z"}]}
{"channel":"book","type":"update","data":[{"symbol":"ETH/USD","bids":[],"asks":[{"price":1774.84,"qty":0.33814853}],"checksum":1697780416,"timestamp":"2026-07-07T23:00:24.083499Z"}]}
{"channel":"book","type":"update","data":[{"symbol":"ETH/USD","bids":[],"asks":[{"price":1774.93,"qty":0.00000000},{"price":1774.96,"qty":0.48930000}],"checksum":692510124,"timestamp":"2026-07-07T23:00:24.087482Z"}]}
{"channel":"book","type":"update","data":[{"symbol":"BTC/USD","bids":[],"asks":[{"price":63514.0,"qty":0.00000000},{"price":63520.2,"qty":0.00388539}],"checksum":483815278,"timestamp":"2026-07-07T23:00:24.088297Z"}]}
{"channel":"book","type":"update","data":[{"symbol":"ETH/USD","bids":[],"asks":[{"price":1774.89,"qty":50.71944318}],"checksum":1437155478,"timestamp":"2026-07-07T23:00:24.088430Z"}]}
{"channel":"book","type":"update","data":[{"symbol":"ETH/USD","bids":[],"asks":[{"price":1774.69,"qty":0.00000000},{"price":1774.96,"qty":0.48930000}],"checksum":4268100979,"timestamp":"2026-07-07T23:00:24.088491Z"}]}
{"channel":"book","type":"update","data":[{"symbol":"BTC/USD","bids":[],"asks":[{"price":63510.0,"qty":0.00043126}],"checksum":322349587,"timestamp":"2026-07-07T23:00:24.088931Z"}]}
{"channel":"book","type":"update","data":[{"symbol":"BTC/USD","bids":[],"asks":[{"price":63510.0,"qty":0.00000000},{"price":63520.2,"qty":0.00388539}],"checksum":483815278,"timestamp":"2026-07-07T23:00:24.089350Z"}]}
{"channel":"book","type":"update","data":[{"symbol":"ETH/USD","bids":[{"price":1774.24,"qty":3.47896976}],"asks":[],"checksum":594519345,"timestamp":"2026-07-07T23:00:24.089650Z"}]}
{"channel":"book","type":"update","data":[{"symbol":"ETH/USD","bids":[],"asks":[{"price":1774.90,"qty":0.37031102}],"checksum":1792899806,"timestamp":"2026-07-07T23:00:24.092334Z"}]}
{"channel":"book","type":"update","data":[{"symbol":"ETH/USD","bids":[{"price":1774.16,"qty":0.54387671}],"asks":[],"checksum":1362168502,"timestamp":"2026-07-07T23:00:24.093352Z"}]}
{"channel":"book","type":"update","data":[{"symbol":"ETH/USD","bids":[{"price":1774.06,"qty":0.84129071}],"asks":[],"checksum":804387733,"timestamp":"2026-07-07T23:00:24.096010Z"}]}
{"channel":"book","type":"update","data":[{"symbol":"ETH/USD","bids":[],"asks":[{"price":1774.81,"qty":0.00000000},{"price":1775.03,"qty":0.16901122}],"checksum":3818521220,"timestamp":"2026-07-07T23:00:24.096025Z"}]}
{"channel":"book","type":"update","data":[{"symbol":"BTC/USD","bids":[{"price":63498.0,"qty":2.14350169}],"asks":[],"checksum":3180862134,"timestamp":"2026-07-07T23:00:24.099628Z"}]}
{"channel":"book","type":"update","data":[{"symbol":"ETH/USD","bids":[],"asks":[{"price":1774.90,"qty":0.00000000},{"price":1775.04,"qty":12.35426731}],"checksum":2944541572,"timestamp":"2026-07-07T23:00:24.101109Z"}]}
{"channel":"book","type":"update","data":[{"symbol":"BTC/USD","bids":[],"asks":[{"price":63516.0,"qty":0.03148812}],"checksum":1891726692,"timestamp":"2026-07-07T23:00:24.101159Z"}]}
{"channel":"book","type":"update","data":[{"symbol":"ETH/USD","bids":[],"asks":[{"price":1774.84,"qty":1.63814853}],"checksum":3827175348,"timestamp":"2026-07-07T23:00:24.101193Z"}]}
{"channel":"book","type":"update","data":[{"symbol":"ETH/USD","bids":[],"asks":[{"price":1775.02,"qty":2.87402415}],"checksum":3069359497,"timestamp":"2026-07-07T23:00:24.101400Z"}]}
{"channel":"book","type":"update","data":[{"symbol":"BTC/USD","bids":[{"price":63488.5,"qty":0.18052093}],"asks":[],"checksum":1684083922,"timestamp":"2026-07-07T23:00:24.101920Z"}]}
{"channel":"book","type":"update","data":[{"symbol":"ETH/USD","bids":[],"asks":[{"price":1774.89,"qty":66.22294756}],"checksum":1246748938,"timestamp":"2026-07-07T23:00:24.102377Z"}]}
{"channel":"book","type":"update","data":[{"symbol":"ETH/USD","bids":[],"asks":[{"price":1774.96,"qty":0.85961102}],"checksum":3534348331,"timestamp":"2026-07-07T23:00:24.104979Z"}]}
{"channel":"book","type":"update","data":[{"symbol":"ETH/USD","bids":[{"price":1773.95,"qty":5.56003448}],"asks":[],"checksum":2754166790,"timestamp":"2026-07-07T23:00:24.106339Z"}]}
{"channel":"book","type":"update","data":[{"symbol":"BTC/USD","bids":[{"price":63498.0,"qty":2.17497347}],"asks":[],"checksum":2411000356,"timestamp":"2026-07-07T23:00:24.106695Z"}]}
{"channel":"book","type":"update","data":[{"symbol":"ETH/USD","bids":[],"asks":[{"price":1774.65,"qty":1.53128753}],"checksum":3654678743,"timestamp":"2026-07-07T23:00:24.110018Z"}]}
{"channel":"book","type":"update","data":[{"symbol":"ETH/USD","bids":[],"asks":[{"price":1774.68,"qty":0.37031102}],"checksum":2266531126,"timestamp":"2026-07-07T23:00:24.110654Z"}]}
{"channel":"book","type":"update","data":[{"symbol":"ETH/USD","bids":[{"price":1773.98,"qty":0.00000000},{"price":1773.93,"qty":8.51356202}],"asks":[],"checksum":3328118658,"timestamp":"2026-07-07T23:00:24.110998Z"}]}
{"channel":"book","type":"update","data":[{"symbol":"ETH/USD","bids":[],"asks":[{"price":1774.67,"qty":0.00000000},{"price":1775.02,"qty":2.87402415}],"checksum":2533065265,"timestamp":"2026-07-07T23:00:24.113570Z"}]}
{"channel":"book","type":"update","data":[{"symbol":"ETH/USD","bids":[],"asks":[{"price":1774.88,"qty":15.13975379}],"checksum":1337881447,"timestamp":"2026-07-07T23:00:24.114492Z"}]}
{"channel":"book","type":"update","data":[{"symbol":"ETH/USD","bids":[],"asks":[{"price":1774.89,"qty":50.71944318}],"checksum":2292708721,"timestamp":"2026-07-07T23:00:24.114645Z"}]}
{"channel":"book","type":"update","data":[{"symbol":"ETH/USD","bids":[{"price":1774.16,"qty":6.46795578}],"asks":[],"checksum":2869665452,"timestamp":"2026-07-07T23:00:24.129629Z"}]}
{"channel":"book","type":"update","data":[{"symbol":"BTC/USD","bids":[],"asks":[{"price":63517.3,"qty":0.09391965}],"checksum":1826211048,"timestamp":"2026-07-07T23:00:24.130799Z"}]}
{"channel":"book","type":"update","data":[{"symbol":"ETH/USD","bids":[],"asks":[{"price":1774.96,"qty":1.14098310}],"checksum":339201333,"timestamp":"2026-07-07T23:00:24.132006Z"}]}
{"channel":"book","type":"update","data":[{"symbol":"BTC/USD","bids":[],"asks":[{"price":63516.2,"qty":1.76365700}],"checksum":1710948264,"timestamp":"2026-07-07T23:00:24.135067Z"}]}
{"channel":"book","type":"update","data":[{"symbol":"BTC/USD","bids":[],"asks":[{"price":63511.8,"qty":0.57934800}],"checksum":520265631,"timestamp":"2026-07-07T23:00:24.136149Z"}]}
{"channel":"book","type":"update","data":[{"symbol":"ETH/USD","bids":[{"price":1774.06,"qty":0.00000000},{"price":1773.92,"qty":28.18526458}],"asks":[],"checksum":3527474359,"timestamp":"2026-07-07T23:00:24.137411Z"}]}
{"channel":"book","type":"update","data":[{"symbol":"BTC/USD","bids":[],"asks":[{"price":63511.8,"qty":0.00000000},{"price":63516.2,"qty":1.76365700}],"checksum":1710948264,"timestamp":"2026-07-07T23:00:24.139112Z"}]}
{"channel":"book","type":"update","data":[{"symbol":"BTC/USD","bids":[],"asks":[{"price":63516.1,"qty":0.52645161}],"checksum":2752004054,"timestamp":"2026-07-07T23:00:24.139449Z"}]}
{"channel":"book","type":"update","data":[{"symbol":"ETH/USD","bids":[{"price":1773.95,"qty":0.00000000},{"price":1773.89,"qty":0.48930000}],"asks":[],"checksum":2322920277,"timestamp":"2026-07-07T23:00:24.141821Z"}]}
{"channel":"book","type":"update","data":[{"symbol":"ETH/USD","bids":[],"asks":[{"price":1774.25,"qty":0.00000000},{"price":1775.02,"qty":2.87402415},{"price":1774.92,"qty":1.48204918}],"checksum":2774922251,"timestamp":"2026-07-07T23:00:24.144122Z"}]}
{"channel":"book","type":"update","data":[{"symbol":"ETH/USD","bids":[],"asks":[{"price":1774.80,"qty":19.34300000}],"checksum":2087423258,"timestamp":"2026-07-07T23:00:24.146729Z"}]}
{"channel":"book","type":"update","data":[{"symbol":"ETH/USD","bids":[],"asks":[{"price":1774.65,"qty":2.02058753}],"checksum":1648230018,"timestamp":"2026-07-07T23:00:24.150089Z"}]}
{"channel":"book","type":"update","data":[{"symbol":"BTC/USD","bids":[],"asks":[{"price":63516.1,"qty":0.00000000},{"price":63517.3,"qty":0.09391965}],"checksum":1826211048,"timestamp":"2026-07-07T23:00:24.150107Z"}]}
{"channel":"book","type":"update","data":[{"symbol":"ETH/USD","bids":[{"price":1774.33,"qty":0.48930000}],"asks":[],"checksum":1946959016,"timestamp":"2026-07-07T23:00:24.150186Z"}]}
{"channel":"book","type":"update","data":[{"symbol":"BTC/USD","bids":[{"price":63491.5,"qty":0.00000000},{"price":63488.2,"qty":0.00005100}],"asks":[],"checksum":971005656,"timestamp":"2026-07-07T23:00:24.150348Z"}]}
{"channel":"book","type":"update","data":[{"symbol":"ETH/USD","bids":[],"asks":[{"price":1774.64,"qty":0.47001888}],"checksum":2049359259,"timestamp":"2026-07-07T23:00:24.150571Z"}]}
{"channel":"book","type":"update","data":[{"symbol":"ETH/USD","bids":[],"asks":[{"price":1774.91,"qty":0.81067919}],"checksum":3409999637,"timestamp":"2026-07-07T23:00:24.151115Z"}]}
{"channel":"book","type":"update","data":[{"symbol":"ETH/USD","bids":[],"asks":[{"price":1774.63,"qty":1.53128753}],"checksum":2182450788,"timestamp":"2026-07-07T23:00:24.154768Z"}]}
{"channel":"book","type":"update","data":[{"symbol":"ETH/USD","bids":[],"asks":[{"price":1774.64,"qty":0.95931888}],"checksum":2742550077,"timestamp":"2026-07-07T23:00:24.154941Z"}]}
{"channel":"book","type":"update","data":[{"symbol":"ETH/USD","bids":[],"asks":[{"price":1774.65,"qty":1.53128753}],"checksum":3135224729,"timestamp":"2026-07-07T23:00:24.155383Z"}]}
{"channel":"book","type":"update","data":[{"symbol":"ETH/USD","bids":[{"price":1773.96,"qty":20.07600000}],"asks":[],"checksum":232941984,"timestamp":"2026-07-07T23:00:24.156146Z"}]}
{"channel":"book","type":"update","data":[{"symbol":"ETH/USD","bids":[{"price":1774.16,"qty":34.64754564}],"asks":[],"checksum":2808488056,"timestamp":"2026-07-07T23:00:24.156895Z"}]}
{"channel":"book","type":"update","data":[{"symbol":"ETH/USD","bids":[],"asks":[{"price":1774.79,"qty":5.77388550}],"checksum":107226123,"timestamp":"2026-07-07T23:00:24.157228Z"}]}
{"channel":"book","type":"update","data":[{"symbol":"ETH/USD","bids":[],"asks":[{"price":1774.63,"qty":2.02058753}],"checksum":4172179726,"timestamp":"2026-07-07T23:00:24.159017Z"}]}
{"channel":"book","type":"update","data":[{"symbol":"ETH/USD","bids":[{"price":1773.97,"qty":0.00000000},{"price":1773.89,"qty":0.48930000}],"asks":[],"checksum":29608568,"timestamp":"2026-07-07T23:00:24.159333Z"}]}
{"channel":"book","type":"update","data":[{"symbol":"BTC/USD","bids":[],"asks":[{"price":63517.2,"qty":0.02803502}],"checksum":3548740799,"timestamp":"2026-07-07T23:00:24.159400Z"}]}
{"channel":"book","type":"update","data":[{"symbol":"BTC/USD","bids":[],"asks":[{"price":63517.1,"qty":0.78719011}],"checksum":347773351,"timestamp":"2026-07-07T23:00:24.159461Z"}]}
{"channel":"book","type":"update","data":[{"symbol":"ETH/USD","bids":[],"asks":[{"price":1774.64,"qty":0.47001888}],"checksum":3611764300,"timestamp":"2026-07-07T23:00:24.159641Z"}]}
{"channel":"book","type":"update","data":[{"symbol":"BTC/USD","bids":[{"price":63498.0,"qty":2.96239984}],"asks":[],"checksum":3951116190,"timestamp":"2026-07-07T23:00:24.159664Z"}]}
{"channel":"book","type":"update","data":[{"symbol":"BTC/USD","bids":[{"price":63494.7,"qty":0.78746666}],"asks":[],"checksum":2465868763,"timestamp":"2026-07-07T23:00:24.159690Z"}]}
{"channel":"book","type":"update","data":[{"symbol":"ETH/USD","bids":[],"asks":[{"price":1774.62,"qty":0.47001888}],"checksum":3570601198,"timestamp":"2026-07-07T23:00:24.159810Z"}]}
{"channel":"book","type":"update","data":[{"symbol":"BTC/USD","bids":[],"asks":[{"price":63515.5,"qty":0.57934800}],"checksum":1554040236,"timestamp":"2026-07-07T23:00:24.161956Z"}]}
{"channel":"book","type":"update","data":[{"symbol":"BTC/USD","bids":[{"price":63496.4,"qty":1.76365700}],"asks":[],"checksum":778119798,"timestamp":"2026-07-07T23:00:24.162252Z"}]}
{"channel":"book","type":"update","data":[{"symbol":"BTC/USD","bids":[],"asks":[{"price":63515.5,"qty":0.00000000},{"price":63517.2,"qty":0.02803502}],"checksum":4201847402,"timestamp":"2026-07-07T23:00:24.162978Z"}]}
{"channel":"book","type":"update","data":[{"symbol":"ETH/USD","bids":[],"asks":[{"price":1774.60,"qty":0.30948353}],"checksum":2872493217,"timestamp":"2026-07-07T23:00:24.163128Z"}]}
{"channel":"book","type":"update","data":[{"symbol":"ETH/USD","bids":[],"asks":[{"price":1774.60,"qty":0.00000000},{"price":1774.84,"qty":1.63814853}],"checksum":3570601198,"timestamp":"2026-07-07T23:00:24.163878Z"}]}
{"channel":"book","type":"update","data":[{"symbol":"BTC/USD","bids":[{"price":63491.7,"qty":0.06862574}],"asks":[],"checksum":1263600258,"timestamp":"2026-07-07T23:00:24.164857Z"}]}
{"channel":"book","type":"update","data":[{"symbol":"BTC/USD","bids":[],"asks":[{"price":63517.0,"qty":0.26301126}],"checksum":1588777287,"timestamp":"2026-07-07T23:00:24.164993Z"}]}
{"channel":"book","type":"update","data":[{"symbol":"ETH/USD","bids":[],"asks":[{"price":1774.62,"qty":0.95931888}],"checksum":3418061869,"timestamp":"2026-07-07T23:00:24.165095Z"}]}
{"channel":"book","type":"update","data":[{"symbol":"ETH/USD","bids":[],"asks":[{"price":1774.63,"qty":1.53128753}],"checksum":2914580712,"timestamp":"2026-07-07T23:00:24.165310Z"}]}
{"channel":"book","type":"update","data":[{"symbol":"ETH/USD","bids":[],"asks":[{"price":1774.61,"qty":1.53128753}],"checksum":848057326,"timestamp":"2026-07-07T23:00:24.165636Z"}]}
{"channel":"book","type":"update","data":[{"symbol":"ETH/USD","bids":[],"asks":[{"price":1774.62,"qty":2.77475848}],"checksum":6711831,"timestamp":"2026-07-07T23:00:24.166625Z"}]}
{"channel":"book","type":"update","data":[{"symbol":"ETH/USD","bids":[{"price":1773.93,"qty":0.00000000},{"price":1773.75,"qty":1.65967029}],"asks":[],"checksum":3030768283,"timestamp":"2026-07-07T23:00:24.166692Z"}]}
{"channel":"book","type":"update","data":[{"symbol":"BTC/USD","bids":[],"asks":[{"price":63517.0,"qty":0.00000000},{"price":63517.2,"qty":0.02803502}],"checksum":1263600258,"timestamp":"2026-07-07T23:00:24.166742Z"}]}
{"channel":"book","type":"update","data":[{"symbol":"BTC/USD","bids":[],"asks":[{"price":63517.2,"qty":0.00000000},{"price":63517.3,"qty":0.09391965}],"checksum":2163596487,"timestamp":"2026-07-07T23:00:24.167191Z"}]}
{"channel":"book","type":"update","data":[{"symbol":"ETH/USD","bids":[],"asks":[{"price":1774.63,"qty":0.00000000},{"price":1774.84,"qty":1.63814853}],"checksum":2871377545,"timestamp":"2026-07-07T23:00:24.167460Z"}]}
{"channel":"book","type":"update","data":[{"symbol":"BTC/USD","bids":[{"price":63496.5,"qty":0.76152564}],"asks":[],"checksum":1777252096,"timestamp":"2026-07-07T23:00:24.169346Z"}]}
{"channel":"book","type":"update","data":[{"symbol":"ETH/USD","bids":[],"asks":[{"price":1774.62,"qty":2.28545848}],"checksum":316131657,"timestamp":"2026-07-07T23:00:24.170625Z"}]}
{"channel":"book","type":"update","data":[{"symbol":"ETH/USD","bids":[],"asks":[{"price":1774.61,"qty":2.02058753}],"checksum":1163278811,"timestamp":"2026-07-07T23:00:24.170699Z"}]}
{"channel":"book","type":"update","data":[{"symbol":"ETH/USD","bids":[],"asks":[{"price":1774.64,"qty":1.54201247}],"checksum":1742746850,"timestamp":"2026-07-07T23:00:24.170862Z"}]}
{"channel":"book","type":"update","data":[{"symbol":"ETH/USD","bids":[{"price":1773.75,"qty":0.00000000},{"price":1773.71,"qty":15.28691228}],"asks":[],"checksum":1979545942,"timestamp":"2026-07-07T23:00:24.172947Z"}]}
{"channel":"book","type":"update","data":[{"symbol":"ETH/USD","bids":[],"asks":[{"price":1774.60,"qty":0.74344601}],"checksum":605367131,"timestamp":"2026-07-07T23:00:24.174302Z"}]}
{"channel":"book","type":"update","data":[{"symbol":"ETH/USD","bids":[],"asks":[{"price":1774.62,"qty":0.47001888}],"checksum":3170026657,"timestamp":"2026-07-07T23:00:24.175079Z"}]}
{"channel":"book","type":"update","data":[{"symbol":"ETH/USD","bids":[],"asks":[{"price":1774.66,"qty":0.00000000},{"price":1774.84,"qty":1.63814853},{"price":1774.63,"qty":1.68966976}],"checksum":1364869905,"timestamp":"2026-07-07T23:00:24.175717Z"}]}
{"channel":"book","type":"update","data":[{"symbol":"ETH/USD","bids":[{"price":1773.97,"qty":6.85058221}],"asks":[],"checksum":4279698518,"timestamp":"2026-07-07T23:00:24.177031Z"}]}
{"channel":"book","type":"update","data":[{"symbol":"ETH/USD","bids":[],"asks":[{"price":1774.64,"qty":2.61400606}],"checksum":3421314029,"timestamp":"2026-07-07T23:00:24.177343Z"}]}
{"channel":"book","type":"update","data":[{"symbol":"ETH/USD","bids":[],"asks":[{"price":1774.76,"qty":0.00000000},{"price":1774.84,"qty":1.63814853}],"checksum":1864890398,"timestamp":"2026-07-07T23:00:24.178431Z"}]}
{"channel":"book","type":"update","data":[{"symbol":"ETH/USD","bids":[{"price":1774.24,"qty":2.98966976}],"asks":[],"checksum":3316010295,"timestamp":"2026-07-07T23:00:24.178575Z"}]}
{"channel":"book","type":"update","data":[{"symbol":"BTC/USD","bids":[{"price":63491.7,"qty":0.01789537}],"asks":[],"checksum":1523592219,"timestamp":"2026-07-07T23:00:24.178804Z"}]}
{"channel":"book","type":"update","data":[{"symbol":"ETH/USD","bids":[],"asks":[{"price":1774.64,"qty":1.54201247}],"checksum":2569133356,"timestamp":"2026-07-07T23:00:24.179430Z"}]}
{"channel":"book","type":"update","data":[{"symbol":"ETH/USD","bids":[],"asks":[{"price":1774.59,"qty":1.53128753}],"checksum":2140892975,"timestamp":"2026-07-07T23:00:24.179539Z"}]}
{"channel":"book","type":"update","data":[{"symbol":"ETH/USD","bids":[],"asks":[{"price":1774.61,"qty":0.48930000}],"checksum":1264984064,"timestamp":"2026-07-07T23:00:24.180868Z"}]}
{"channel":"book","type":"update","data":[{"symbol":"ETH/USD","bids":[],"asks":[{"price":1774.64,"qty":0.47001888}],"checksum":3364377607,"timestamp":"2026-07-07T23:00:24.183791Z"}]}
{"channel":"book","type":"update","data":[{"symbol":"ETH/USD","bids":[],"asks":[{"price":1774.62,"qty":1.54201247}],"checksum":3318721812,"timestamp":"2026-07-07T23:00:24.183811Z"}]}
{"channel":"book","type":"update","data":[{"symbol":"ETH/USD","bids":[],"asks":[{"price":1774.60,"qty":0.00000000},{"price":1774.84,"qty":1.63814853}],"checksum":2367375453,"timestamp":"2026-07-07T23:00:24.188299Z"}]}
{"channel":"book","type":"update","data":[{"symbol":"ETH/USD","bids":[],"asks":[{"price":1774.61,"qty":3.30682046}],"checksum":3657512613,"timestamp":"2026-07-07T23:00:24.189226Z"}]}
{"channel":"book","type":"update","data":[{"symbol":"ETH/USD","bids":[],"asks":[{"price":1774.84,"qty":29.80980343}],"checksum":2170552430,"timestamp":"2026-07-07T23:00:24.189504Z"}]}
{"channel":"book","type":"update","data":[{"symbol":"ETH/USD","bids":[{"price":1774.27,"qty":2.81805445}],"asks":[],"checksum":523715092,"timestamp":"2026-07-07T23:00:24.190131Z"}]}
{"channel":"book","type":"update","data":[{"symbol":"ETH/USD","bids":[{"price":1774.08,"qty":28.18362193}],"asks":[],"checksum":2284598876,"timestamp":"2026-07-07T23:00:24.190450Z"}]}
{"channel":"book","type":"update","data":[{"symbol":"ETH/USD","bids":[],"asks":[{"price":1774.58,"qty":0.74344601}],"checksum":970152046,"timestamp":"2026-07-07T23:00:24.194256Z"}]}
{"channel":"book","type":"update","data":[{"symbol":"ETH/USD","bids":[{"price":1774.16,"qty":40.03589567}],"asks":[],"checksum":40942185,"timestamp":"2026-07-07T23:00:24.197283Z"}]}
{"channel":"book","type":"update","data":[{"symbol":"ETH/USD","bids":[],"asks":[{"price":1774.58,"qty":1.48942776}],"checksum":2934820093,"timestamp":"2026-07-07T23:00:24.197672Z"}]}
{"channel":"book","type":"update","data":[{"symbol":"ETH/USD","bids":[],"asks":[{"price":1774.57,"qty":1.53128753}],"checksum":2408639064,"timestamp":"2026-07-07T23:00:24.200357Z"}]}
{"channel":"book","type":"update","data":[{"symbol":"ETH/USD","bids":[],"asks":[{"price":1774.59,"qty":0.00000000},{"price":1774.80,"qty":19.34300000}],"checksum":1114179956,"timestamp":"2026-07-07T23:00:24.201516Z"}]}
{"channel":"book","type":"update","data":[{"symbol":"ETH/USD","bids":[],"asks":[{"price":1774.58,"qty":2.68996310}],"checksum":2313820580,"timestamp":"2026-07-07T23:00:24.208138Z"}]}
{"channel":"book","type":"update","data":[{"symbol":"ETH/USD","bids":[],"asks":[{"price":1774.58,"qty":1.48942776}],"checksum":1114179956,"timestamp":"2026-07-07T23:00:24.208199Z"}]}
{"channel":"book","type":"update","data":[{"symbol":"ETH/USD","bids":[{"price":1773.98,"qty":5.56003448}],"asks":[],"checksum":3544821652,"timestamp":"2026-07-07T23:00:24.220855Z"}]}
{"channel":"book","type":"update","data":[{"symbol":"ETH/USD","bids":[{"price":1773.98,"qty":0.00000000},{"price":1773.96,"qty":20.07600000},{"price":1774.17,"qty":5.56003448}],"asks":[],"checksum":680680430,"timestamp":"2026-07-07T23:00:24.242482Z"}]}
{"channel":"book","type":"update","data":[{"symbol":"BTC/USD","bids":[],"asks":[{"price":63515.4,"qty":0.57934800}],"checksum":2422594948,"timestamp":"2026-07-07T23:00:24.244736Z"}]}
{"channel":"book","type":"update","data":[{"symbol":"BTC/USD","bids":[],"asks":[{"price":63515.3,"qty":0.18233458}],"checksum":1446501101,"timestamp":"2026-07-07T23:00:24.246430Z"}]}
{"channel":"book","type":"update","data":[{"symbol":"ETH/USD","bids":[],"asks":[{"price":1774.56,"qty":0.37031102}],"checksum":1712613561,"timestamp":"2026-07-07T23:00:24.251994Z"}]}
{"channel":"book","type":"update","data":[{"symbol":"ETH/USD","bids":[],"asks":[{"price":1774.68,"qty":0.00000000},{"price":1774.80,"qty":19.34300000}],"checksum":399038756,"timestamp":"2026-07-07T23:00:24.252279Z"}]}
{"channel":"book","type":"update","data":[{"symbol":"ETH/USD","bids":[{"price":1774.16,"qty":11.85630581},{"price":1774.08,"qty":56.36332135}],"asks":[],"checksum":3286666329,"timestamp":"2026-07-07T23:00:24.253817Z"}]}
{"channel":"book","type":"update","data":[{"symbol":"ETH/USD","bids":[],"asks":[{"price":1774.55,"qty":1.53128753}],"checksum":2132952933,"timestamp":"2026-07-07T23:00:24.253888Z"}]}
{"channel":"book","type":"update","data":[{"symbol":"ETH/USD","bids":[],"asks":[{"price":1774.57,"qty":0.00000000},{"price":1774.80,"qty":19.34300000}],"checksum":3402186479,"timestamp":"2026-07-07T23:00:24.254906Z"}]}
{"channel":"book","type":"update","data":[{"symbol":"ETH/USD","bids":[{"price":1774.26,"qty":0.29425762}],"asks":[],"checksum":61936678,"timestamp":"2026-07-07T23:00:24.257237Z"}]}
{"channel":"book","type":"update","data":[{"symbol":"ETH/USD","bids":[],"asks":[{"price":1774.65,"qty":0.00000000},{"price":1774.83,"qty":18.74262182}],"checksum":2302932447,"timestamp":"2026-07-07T23:00:24.257467Z"}]}
{"channel":"book","type":"update","data":[{"symbol":"ETH/USD","bids":[{"price":1774.20,"qty":0.00000000},{"price":1773.97,"qty":6.85058221}],"asks":[],"checksum":1995664628,"timestamp":"2026-07-07T23:00:24.258404Z"}]}
{"channel":"book","type":"update","data":[{"symbol":"ETH/USD","bids":[],"asks":[{"price":1774.62,"qty":0.47001888}],"checksum":3587338531,"timestamp":"2026-07-07T23:00:24.259173Z"}]}
{"channel":"book","type":"update","data":[{"symbol":"ETH/USD","bids":[],"asks":[{"price":1774.62,"qty":1.11468594}],"checksum":1342182671,"timestamp":"2026-07-07T23:00:24.259741Z"}]}
{"channel":"book","type":"update","data":[{"symbol":"ETH/USD","bids":[],"asks":[{"price":1774.64,"qty":0.00000000},{"price":1774.84,"qty":29.47165490}],"checksum":1404004866,"timestamp":"2026-07-07T23:00:24.261427Z"}]}
{"channel":"book","type":"update","data":[{"symbol":"ETH/USD","bids":[],"asks":[{"price":1774.63,"qty":0.00000000},{"price":1774.88,"qty":32.20042835},{"price":1774.78,"qty":1.68966976}],"checksum":249224584,"timestamp":"2026-07-07T23:00:24.264875Z"}]}
{"channel":"book","type":"update","data":[{"symbol":"ETH/USD","bids":[],"asks":[{"price":1774.62,"qty":0.47001888}],"checksum":2100598453,"timestamp":"2026-07-07T23:00:24.266411Z"}]}
{"channel":"book","type":"update","data":[{"symbol":"ETH/USD","bids":[],"asks":[{"price":1774.54,"qty":0.47001888}],"checksum":792480994,"timestamp":"2026-07-07T23:00:24.268101Z"}]}
{"channel":"book","type":"update","data":[{"symbol":"ETH/USD","bids":[],"asks":[{"price":1774.53,"qty":1.53128753}],"checksum":1372751867,"timestamp":"2026-07-07T23:00:24.269791Z"}]}
{"channel":"book","type":"update","data":[{"symbol":"ETH/USD","bids":[],"asks":[{"price":1774.61,"qty":0.48930000}],"checksum":1943506317,"timestamp":"2026-07-07T23:00:24.276056Z"}]}
{"channel":"book","type":"update","data":[{"symbol":"ETH/USD","bids":[],"asks":[{"price":1774.58,"qty":4.30700405}],"checksum":1935726812,"timestamp":"2026-07-07T23:00:24.277698Z"}]}
{"channel":"book","type":"update","data":[{"symbol":"ETH/USD","bids":[],"asks":[{"price":1774.58,"qty":3.56355804}],"checksum":2150607085,"timestamp":"2026-07-07T23:00:24.278315Z"}]}
{"channel":"book","type":"update","data":[{"symbol":"ETH/USD","bids":[],"asks":[{"price":1774.58,"qty":2.81757629}],"checksum":3126848408,"timestamp":"2026-07-07T23:00:24.278326Z"}]}
{"channel":"book","type":"update","data":[{"symbol":"ETH/USD","bids":[],"asks":[{"price":1774.54,"qty":1.32400273}],"checksum":3574619261,"timestamp":"2026-07-07T23:00:24.278445Z"}]}
{"channel":"book","type":"update","data":[{"symbol":"BTC/USD","bids":[{"price":63493.6,"qty":0.57934800}],"asks":[],"checksum":2564029844,"timestamp":"2026-07-07T23:00:24.278458Z"}]}
{"channel":"book","type":"update","data":[{"symbol":"ETH/USD","bids":[],"asks":[{"price":1774.54,"qty":2.05586910}],"checksum":2713579190,"timestamp":"2026-07-07T23:00:24.279766Z"}]}
{"channel":"book","type":"update","data":[{"symbol":"BTC/USD","bids":[{"price":63491.7,"qty":0.00000000},{"price":63491.4,"qty":0.00005100}],"asks":[],"checksum":4278073815,"timestamp":"2026-07-07T23:00:24.280240Z"}]}
{"channel":"book","type":"update","data":[{"symbol":"BTC/USD","bids":[{"price":63493.7,"qty":0.19083075}],"asks":[],"checksum":2907208583,"timestamp":"2026-07-07T23:00:24.280561Z"}]}
{"channel":"book","type":"update","data":[{"symbol":"ETH/USD","bids":[{"price":1774.33,"qty":0.00000000},{"price":1773.96,"qty":20.07600000}],"asks":[],"checksum":3364261000,"timestamp":"2026-07-07T23:00:24.299995Z"}]}
{"channel":"book","type":"update","data":[{"symbol":"ETH/USD","bids":[{"price":1774.30,"qty":0.48930000}],"asks":[],"checksum":1232003985,"timestamp":"2026-07-07T23:00:24.301237Z"}]}
{"channel":"book","type":"update","data":[{"symbol":"ETH/USD","bids":[{"price":1774.28,"qty":1.30000000}],"asks":[],"checksum":370204566,"timestamp":"2026-07-07T23:00:24.301604Z"}]}
{"channel":"book","type":"update","data":[{"symbol":"ETH/USD","bids":[{"price":1774.28,"qty":0.00000000},{"price":1773.97,"qty":6.85058221}],"asks":[],"checksum":1232003985,"timestamp":"2026-07-07T23:00:24.303064Z"}]}
{"channel":"book","type":"update","data":[{"symbol":"ETH/USD","bids":[],"asks":[{"price":1774.52,"qty":0.29393134}],"checksum":4055690093,"timestamp":"2026-07-07T23:00:24.332185Z"}]}
{"channel":"book","type":"update","data":[{"symbol":"BTC/USD","bids":[],"asks":[{"price":63515.3,"qty":0.00000000},{"price":63516.0,"qty":0.03148812}],"checksum":1445321748,"timestamp":"2026-07-07T23:00:24.333978Z"}]}
{"channel":"book","type":"update","data":[{"symbol":"ETH/USD","bids":[],"asks":[{"price":1774.54,"qty":1.32400273}],"checksum":924111017,"timestamp":"2026-07-07T23:00:24.334324Z"}]}
{"channel":"book","type":"update","data":[{"symbol":"ETH/USD","bids":[],"asks":[{"price":1774.54,"qty":0.47001888}],"checksum":1570164901,"timestamp":"2026-07-07T23:00:24.334771Z"}]}
{"channel":"book","type":"update","data":[{"symbol":"ETH/USD","bids":[{"price":1774.25,"qty":2.55208672}],"asks":[],"checksum":2473928545,"timestamp":"2026-07-07T23:00:24.337002Z"}]}
{"channel":"book","type":"update","data":[{"symbol":"ETH/USD","bids":[{"price":1774.28,"qty":0.92902515}],"asks":[],"checksum":2718425328,"timestamp":"2026-07-07T23:00:24.337662Z"}]}
{"channel":"book","type":"update","data":[{"symbol":"ETH/USD","bids":[],"asks":[{"price":1774.61,"qty":0.00000000},{"price":1774.80,"qty":19.34300000}],"checksum":749004743,"timestamp":"2026-07-07T23:00:24.338080Z"}]}
{"channel":"book","type":"update","data":[{"symbol":"ETH/USD","bids":[],"asks":[{"price":1774.78,"qty":0.00000000},{"price":1774.83,"qty":12.59886962},{"price":1774.62,"qty":2.15968864}],"checksum":1458722242,"timestamp":"2026-07-07T23:00:24.338364Z"}]}
{"channel":"book","type":"update","data":[{"symbol":"ETH/USD","bids":[],"asks":[{"price":1774.58,"qty":0.00000000},{"price":1774.84,"qty":29.47165490}],"checksum":1719359664,"timestamp":"2026-07-07T23:00:24.339955Z"}]}
{"channel":"book","type":"update","data":[{"symbol":"ETH/USD","bids":[{"price":1774.27,"qty":0.00000000},{"price":1774.07,"qty":0.48930000}],"asks":[],"checksum":2491319687,"timestamp":"2026-07-07T23:00:24.340887Z"}]}
{"channel":"book","type":"update","data":[{"symbol":"ETH/USD","bids":[],"asks":[{"price":1774.70,"qty":0.48930000}],"checksum":2897083863,"timestamp":"2026-07-07T23:00:24.341239Z"}]}
{"channel":"book","type":"update","data":[{"symbol":"BTC/USD","bids":[{"price":63497.4,"qty":0.78743294}],"asks":[],"checksum":2589782581,"timestamp":"2026-07-07T23:00:24.341403Z"}]}
{"channel":"book","type":"update","data":[{"symbol":"ETH/USD","bids":[],"asks":[{"price":1774.63,"qty":2.81749985}],"checksum":3933376256,"timestamp":"2026-07-07T23:00:24.342676Z"}]}
{"channel":"book","type":"update","data":[{"symbol":"ETH/USD","bids":[{"price":1774.27,"qty":2.81805706}],"asks":[],"checksum":631089749,"timestamp":"2026-07-07T23:00:24.343323Z"}]}
{"channel":"book","type":"update","data":[{"symbol":"ETH/USD","bids":[{"price":1774.28,"qty":0.00000000},{"price":1774.07,"qty":0.48930000}],"asks":[],"checksum":1830187035,"timestamp":"2026-07-07T23:00:24.345962Z"}]}
{"channel":"book","type":"update","data":[{"symbol":"ETH/USD","bids":[{"price":1774.27,"qty":0.00000000},{"price":1773.97,"qty":6.85058221}],"asks":[],"checksum":3830859909,"timestamp":"2026-07-07T23:00:24.347014Z"}]}
{"channel":"book","type":"update","data":[{"symbol":"ETH/USD","bids":[{"price":1774.16,"qty":30.45962726}],"asks":[],"checksum":3692726633,"timestamp":"2026-07-07T23:00:24.347189Z"}]}
{"channel":"book","type":"update","data":[{"symbol":"ETH/USD","bids":[{"price":1774.16,"qty":24.53554819}],"asks":[],"checksum":590451769,"timestamp":"2026-07-07T23:00:24.347215Z"}]}
{"channel":"book","type":"update","data":[{"symbol":"ETH/USD","bids":[{"price":1774.16,"qty":19.14719816}],"asks":[],"checksum":3736700114,"timestamp":"2026-07-07T23:00:24.347250Z"}]}
{"channel":"book","type":"update","data":[{"symbol":"ETH/USD","bids":[{"price":1774.28,"qty":0.92902593}],"asks":[],"checksum":3406833615,"timestamp":"2026-07-07T23:00:24.347343Z"}]}
{"channel":"book","type":"update","data":[{"symbol":"ETH/USD","bids":[],"asks":[{"price":1774.51,"qty":1.53128753}],"checksum":3639566042,"timestamp":"2026-07-07T23:00:24.349456Z"}]}
{"channel":"book","type":"update","data":[{"symbol":"BTC/USD","bids":[],"asks":[{"price":63515.4,"qty":0.00000000},{"price":63517.2,"qty":0.78718857}],"checksum":2601011410,"timestamp":"2026-07-07T23:00:24.349476Z"}]}
{"channel":"book","type":"update","data":[{"symbol":"ETH/USD","bids":[{"price":1774.15,"qty":0.00000000},{"price":1773.97,"qty":6.85058221}],"asks":[],"checksum":1090244073,"timestamp":"2026-07-07T23:00:24.350083Z"}]}
{"channel":"book","type":"update","data":[{"symbol":"ETH/USD","bids":[],"asks":[{"price":1774.53,"qty":0.00000000},{"price":1774.80,"qty":19.34300000}],"checksum":901675114,"timestamp":"2026-07-07T23:00:24.350462Z"}]}
{"channel":"book","type":"update","data":[{"symbol":"ETH/USD","bids":[{"price":1774.04,"qty":19.84616104}],"asks":[],"checksum":2726969766,"timestamp":"2026-07-07T23:00:24.352440Z"}]}
{"channel":"book","type":"update","data":[{"symbol":"ETH/USD","bids":[{"price":1774.28,"qty":0.00000000},{"price":1773.97,"qty":6.85058221}],"asks":[],"checksum":279936360,"timestamp":"2026-07-07T23:00:24.353984Z"}]}
{"channel":"book","type":"update","data":[{"symbol":"ETH/USD","bids":[{"price":1774.05,"qty":5.92407907}],"asks":[],"checksum":2983105017,"timestamp":"2026-07-07T23:00:24.358587Z"}]}
{"channel":"book","type":"update","data":[{"symbol":"ETH/USD","bids":[{"price":1774.08,"qty":28.17969942}],"asks":[],"checksum":787624519,"timestamp":"2026-07-07T23:00:24.366524Z"}]}
{"channel":"book","type":"update","data":[{"symbol":"ETH/USD","bids":[{"price":1774.16,"qty":27.55883844}],"asks":[],"checksum":2426321,"timestamp":"2026-07-07T23:00:24.368601Z"}]}
{"channel":"book","type":"update","data":[{"symbol":"ETH/USD","bids":[],"asks":[{"price":1774.62,"qty":1.68966976}],"checksum":563241588,"timestamp":"2026-07-07T23:00:24.369153Z"}]}
{"channel":"book","type":"update","data":[{"symbol":"ETH/USD","bids":[{"price":1774.16,"qty":8.95551699}],"asks":[],"checksum":853296096,"timestamp":"2026-07-07T23:00:24.369557Z"}]}
{"channel":"book","type":"update","data":[{"symbol":"ETH/USD","bids":[{"price":1774.17,"qty":0.00000000},{"price":1773.97,"qty":6.85058221},{"price":1774.09,"qty":5.56003448}],"asks":[],"checksum":2237986692,"timestamp":"2026-07-07T23:00:24.370910Z"}]}
{"channel":"book","type":"update","data":[{"symbol":"ETH/USD","bids":[],"asks":[{"price":1774.55,"qty":0.00000000},{"price":1774.83,"qty":12.59886962}],"checksum":1009461933,"timestamp":"2026-07-07T23:00:24.370969Z"}]}
{"channel":"book","type":"update","data":[{"symbol":"ETH/USD","bids":[{"price":1774.25,"qty":0.00000000},{"price":1773.97,"qty":6.85058221}],"asks":[],"checksum":1685811864,"timestamp":"2026-07-07T23:00:24.372813Z"}]}
{"channel":"book","type":"update","data":[{"symbol":"ETH/USD","bids":[{"price":1774.25,"qty":0.89241642}],"asks":[],"checksum":2770991082,"timestamp":"2026-07-07T23:00:24.373013Z"}]}
{"channel":"book","type":"update","data":[{"symbol":"ETH/USD","bids":[],"asks":[{"price":1774.50,"qty":0.47001888}],"checksum":3498177678,"timestamp":"2026-07-07T23:00:24.374376Z"}]}
{"channel":"book","type":"update","data":[{"symbol":"ETH/USD","bids":[],"asks":[{"price":1774.80,"qty":24.98200000}],"checksum":2564577336,"timestamp":"2026-07-07T23:00:24.376552Z"}]}
{"channel":"book","type":"update","data":[{"symbol":"ETH/USD","bids":[],"asks":[{"price":1774.49,"qty":1.53128753}],"checksum":2425922497,"timestamp":"2026-07-07T23:00:24.377227Z"}]}
{"channel":"book","type":"update","data":[{"symbol":"ETH/USD","bids":[{"price":1774.24,"qty":1.68966976}],"asks":[],"checksum":1870459135,"timestamp":"2026-07-07T23:00:24.403019Z"}]}
{"channel":"book","type":"update","data":[{"symbol":"ETH/USD","bids":[{"price":1774.24,"qty":0.00000000},{"price":1773.97,"qty":6.85058221},{"price":1774.17,"qty":1.68966976}],"asks":[],"checksum":655903337,"timestamp":"2026-07-07T23:00:24.404778Z"}]}
{"channel":"book","type":"update","data":[{"symbol":"ETH/USD","bids":[{"price":1774.11,"qty":1.30000000}],"asks":[],"checksum":1045189183,"timestamp":"2026-07-07T23:00:24.404992Z"}]}
{"channel":"book","type":"update","data":[{"symbol":"ETH/USD","bids":[{"price":1774.25,"qty":0.00000000},{"price":1774.04,"qty":19.84616104}],"asks":[],"checksum":2590175061,"timestamp":"2026-07-07T23:00:24.405025Z"}]}
{"channel":"book","type":"update","data":[{"symbol":"ETH/USD","bids":[],"asks":[{"price":1774.63,"qty":0.00000000},{"price":1774.80,"qty":24.98200000}],"checksum":2499116534,"timestamp":"2026-07-07T23:00:24.408658Z"}]}
{"channel":"book","type":"update","data":[{"symbol":"ETH/USD","bids":[],"asks":[{"price":1774.62,"qty":0.00000000},{"price":1774.83,"qty":24.95313693},{"price":1774.69,"qty":1.68966976}],"checksum":2664163417,"timestamp":"2026-07-07T23:00:24.410252Z"}]}
{"channel":"book","type":"update","data":[{"symbol":"ETH/USD","bids":[],"asks":[{"price":1774.59,"qty":2.81755359}],"checksum":3086770377,"timestamp":"2026-07-07T23:00:24.410424Z"}]}
{"channel":"book","type":"update","data":[{"symbol":"ETH/USD","bids":[{"price":1774.25,"qty":2.81809203}],"asks":[],"checksum":1688006870,"timestamp":"2026-07-07T23:00:24.410798Z"}]}
{"channel":"book","type":"update","data":[{"symbol":"ETH/USD","bids":[],"asks":[{"price":1774.68,"qty":0.65042247}],"checksum":1920520372,"timestamp":"2026-07-07T23:00:24.411876Z"}]}
{"channel":"book","type":"update","data":[{"symbol":"BTC/USD","bids":[],"asks":[{"price":63517.2,"qty":0.00000000},{"price":63517.3,"qty":0.09391965}],"checksum":3047981680,"timestamp":"2026-07-07T23:00:24.426980Z"}]}
{"channel":"book","type":"update","data":[{"symbol":"BTC/USD","bids":[],"asks":[{"price":63498.2,"qty":0.00000000},{"price":63517.9,"qty":0.01021802}],"checksum":3562404204,"timestamp":"2026-07-07T23:00:24.442807Z"}]}
{"channel":"book","type":"update","data":[{"symbol":"ETH/USD","bids":[{"price":1774.31,"qty":0.30792118}],"asks":[],"checksum":1542392833,"timestamp":"2026-07-07T23:00:24.464672Z"}]}
{"channel":"book","type":"update","data":[{"symbol":"ETH/USD","bids":[{"price":1774.26,"qty":0.00000000},{"price":1774.05,"qty":5.92407907}],"asks":[],"checksum":284614787,"timestamp":"2026-07-07T23:00:24.465766Z"}]}
{"channel":"book","type":"update","data":[{"symbol":"ETH/USD","bids":[{"price":1774.33,"qty":0.48930000}],"asks":[],"checksum":1422635689,"timestamp":"2026-07-07T23:00:24.465948Z"}]}
{"channel":"book","type":"update","data":[{"symbol":"ETH/USD","bids":[{"price":1774.26,"qty":1.34556689}],"asks":[],"checksum":1453359428,"timestamp":"2026-07-07T23:00:24.467581Z"}]}
{"channel":"book","type":"update","data":[{"symbol":"ETH/USD","bids":[],"asks":[{"price":1774.54,"qty":0.00000000},{"price":1774.79,"qty":5.77388550}],"checksum":1181357583,"timestamp":"2026-07-07T23:00:24.475193Z"}]}
{"channel":"book","type":"update","data":[{"symbol":"BTC/USD","bids":[],"asks":[{"price":63515.6,"qty":0.78720868}],"checksum":4180930489,"timestamp":"2026-07-07T23:00:24.475981Z"}]}
{"channel":"book","type":"update","data":[{"symbol":"BTC/USD","bids":[],"asks":[{"price":63515.5,"qty":0.24438099}],"checksum":2460274026,"timestamp":"2026-07-07T23:00:24.477476Z"}]}
{"channel":"book","type":"update","data":[{"symbol":"ETH/USD","bids":[],"asks":[{"price":1774.48,"qty":0.47001888}],"checksum":1736213145,"timestamp":"2026-07-07T23:00:24.478212Z"}]}
{"channel":"book","type":"update","data":[{"symbol":"ETH/USD","bids":[],"asks":[{"price":1774.51,"qty":0.00000000},{"price":1774.79,"qty":5.77388550}],"checksum":761325051,"timestamp":"2026-07-07T23:00:24.478311Z"}]}
{"channel":"book","type":"update","data":[{"symbol":"ETH/USD","bids":[],"asks":[{"price":1774.47,"qty":1.53128753}],"checksum":3908788980,"timestamp":"2026-07-07T23:00:24.480776Z"}]}
{"channel":"book","type":"update","data":[{"symbol":"ETH/USD","bids":[{"price":1774.16,"qty":28.80167803}],"asks":[],"checksum":963515649,"timestamp":"2026-07-07T23:00:24.482127Z"}]}
{"channel":"book","type":"update","data":[{"symbol":"ETH/USD","bids":[{"price":1774.09,"qty":0.00000000},{"price":1774.07,"qty":0.48930000},{"price":1774.18,"qty":5.56003448}],"asks":[],"checksum":1088730381,"timestamp":"2026-07-07T23:00:24.483561Z"}]}
{"channel":"book","type":"update","data":[{"symbol":"ETH/USD","bids":[{"price":1774.26,"qty":2.83320911}],"asks":[],"checksum":3481860323,"timestamp":"2026-07-07T23:00:24.485148Z"}]}
{"channel":"book","type":"update","data":[{"symbol":"ETH/USD","bids":[{"price":1774.17,"qty":0.00000000},{"price":1774.07,"qty":0.48930000},{"price":1774.19,"qty":1.68966976}],"asks":[],"checksum":111668593,"timestamp":"2026-07-07T23:00:24.485481Z"}]}
{"channel":"book","type":"update","data":[{"symbol":"ETH/USD","bids":[],"asks":[{"price":1774.69,"qty":0.00000000},{"price":1774.79,"qty":5.77388550},{"price":1774.67,"qty":1.68966976}],"checksum":3438295164,"timestamp":"2026-07-07T23:00:24.510053Z"}]}
{"channel":"book","type":"update","data":[{"symbol":"ETH/USD","bids":[],"asks":[{"price":1774.68,"qty":0.00000000},{"price":1774.79,"qty":5.77388550}],"checksum":3694364713,"timestamp":"2026-07-07T23:00:24.511932Z"}]}
{"channel":"book","type":"update","data":[{"symbol":"ETH/USD","bids":[],"asks":[{"price":1774.66,"qty":0.65042247}],"checksum":2011089643,"timestamp":"2026-07-07T23:00:24.512082Z"}]}
{"channel":"book","type":"update","data":[{"symbol":"BTC/USD","bids":[],"asks":[{"price":63515.6,"qty":1.36655568}],"checksum":1234486702,"timestamp":"2026-07-07T23:00:24.527205Z"}]}
{"channel":"heartbeat"}
{"channel":"book","type":"update","data":[{"symbol":"ETH/USD","bids":[],"asks":[{"price":1774.50,"qty":0.00000000},{"price":1774.79,"qty":5.77388550}],"checksum":877267646,"timestamp":"2026-07-07T23:00:24.579238Z"}]}
{"channel":"book","type":"update","data":[{"symbol":"ETH/USD","bids":[],"asks":[{"price":1774.46,"qty":0.47001888}],"checksum":2596318330,"timestamp":"2026-07-07T23:00:24.580524Z"}]}
{"channel":"book","type":"update","data":[{"symbol":"ETH/USD","bids":[],"asks":[{"price":1774.47,"qty":0.00000000},{"price":1774.79,"qty":5.77388550}],"checksum":4105168712,"timestamp":"2026-07-07T23:00:24.581637Z"}]}
{"channel":"book","type":"update","data":[{"symbol":"ETH/USD","bids":[],"asks":[{"price":1774.49,"qty":0.00000000},{"price":1774.80,"qty":24.98200000}],"checksum":1721935752,"timestamp":"2026-07-07T23:00:24.581902Z"}]}
{"channel":"book","type":"update","data":[{"symbol":"ETH/USD","bids":[],"asks":[{"price":1774.46,"qty":0.00000000},{"price":1774.83,"qty":12.59886962}],"checksum":1545477885,"timestamp":"2026-07-07T23:00:24.582859Z"}]}
{"channel":"book","type":"update","data":[{"symbol":"ETH/USD","bids":[],"asks":[{"price":1774.65,"qty":1.53128753}],"checksum":1026894885,"timestamp":"2026-07-07T23:00:24.583073Z"}]}
{"channel":"book","type":"update","data":[{"symbol":"ETH/USD","bids":[],"asks":[{"price":1774.47,"qty":1.53128753}],"checksum":946608831,"timestamp":"2026-07-07T23:00:24.584022Z"}]}
{"channel":"book","type":"update","data":[{"symbol":"ETH/USD","bids":[],"asks":[{"price":1774.66,"qty":0.00000000},{"price":1774.80,"qty":24.98200000}],"checksum":1966641986,"timestamp":"2026-07-07T23:00:24.584468Z"}]}
{"channel":"book","type":"update","data":[{"symbol":"ETH/USD","bids":[],"asks":[{"price":1774.64,"qty":1.10751180}],"checksum":4133131034,"timestamp":"2026-07-07T23:00:24.584616Z"}]}
{"channel":"book","type":"update","data":[{"symbol":"ETH/USD","bids":[],"asks":[{"price":1774.46,"qty":0.47001888}],"checksum":96866158,"timestamp":"2026-07-07T23:00:24.586943Z"}]}
{"channel":"book","type":"update","data":[{"symbol":"ETH/USD","bids":[],"asks":[{"price":1774.47,"qty":0.00000000},{"price":1774.79,"qty":5.77388550}],"checksum":2722374110,"timestamp":"2026-07-07T23:00:24.588628Z"}]}
{"channel":"book","type":"update","data":[{"symbol":"ETH/USD","bids":[],"asks":[{"price":1774.46,"qty":0.00000000},{"price":1774.80,"qty":24.98200000}],"checksum":563626557,"timestamp":"2026-07-07T23:00:24.590442Z"}]}
{"channel":"book","type":"update","data":[{"symbol":"ETH/USD","bids":[],"asks":[{"price":1774.47,"qty":1.53128753}],"checksum":4133131034,"timestamp":"2026-07-07T23:00:24.591788Z"}]}
{"channel":"book","type":"update","data":[{"symbol":"ETH/USD","bids":[],"asks":[{"price":1774.46,"qty":0.47001888}],"checksum":96866158,"timestamp":"2026-07-07T23:00:24.593397Z"}]}
{"channel":"book","type":"update","data":[{"symbol":"ETH/USD","bids":[],"asks":[{"price":1774.47,"qty":0.00000000},{"price":1774.79,"qty":5.77388550}],"checksum":2722374110,"timestamp":"2026-07-07T23:00:24.594759Z"}]}
{"channel":"book","type":"update","data":[{"symbol":"ETH/USD","bids":[],"asks":[{"price":1774.46,"qty":0.00000000},{"price":1774.80,"qty":24.98200000}],"checksum":563626557,"timestamp":"2026-07-07T23:00:24.596096Z"}]}
{"channel":"book","type":"update","data":[{"symbol":"ETH/USD","bids":[],"asks":[{"price":1774.47,"qty":1.53128753}],"checksum":4133131034,"timestamp":"2026-07-07T23:00:24.597872Z"}]}
{"channel":"book","type":"update","data":[{"symbol":"ETH/USD","bids":[],"asks":[{"price":1774.46,"qty":0.47001888}],"checksum":96866158,"timestamp":"2026-07-07T23:00:24.599641Z"}]}
{"channel":"book","type":"update","data":[{"symbol":"ETH/USD","bids":[],"asks":[{"price":1774.47,"qty":0.00000000},{"price":1774.79,"qty":5.77388550}],"checksum":2722374110,"timestamp":"2026-07-07T23:00:24.601387Z"}]}
{"channel":"book","type":"update","data":[{"symbol":"ETH/USD","bids":[],"asks":[{"price":1774.46,"qty":0.00000000},{"price":1774.80,"qty":24.98200000}],"checksum":563626557,"timestamp":"2026-07-07T23:00:24.603209Z"}]}
{"channel":"book","type":"update","data":[{"symbol":"ETH/USD","bids":[],"asks":[{"price":1774.47,"qty":1.53128753}],"checksum":4133131034,"timestamp":"2026-07-07T23:00:24.604934Z"}]}
{"channel":"book","type":"update","data":[{"symbol":"ETH/USD","bids":[],"asks":[{"price":1774.46,"qty":0.47001888}],"checksum":96866158,"timestamp":"2026-07-07T23:00:24.607302Z"}]}
{"channel":"book","type":"update","data":[{"symbol":"ETH/USD","bids":[],"asks":[{"price":1774.47,"qty":0.00000000},{"price":1774.79,"qty":5.77388550}],"checksum":2722374110,"timestamp":"2026-07-07T23:00:24.610146Z"}]}
{"channel":"book","type":"update","data":[{"symbol":"ETH/USD","bids":[],"asks":[{"price":1774.46,"qty":0.00000000},{"price":1774.80,"qty":24.98200000}],"checksum":563626557,"timestamp":"2026-07-07T23:00:24.613878Z"}]}
{"channel":"book","type":"update","data":[{"symbol":"ETH/USD","bids":[],"asks":[{"price":1774.47,"qty":1.53128753}],"checksum":4133131034,"timestamp":"2026-07-07T23:00:24.615224Z"}]}
{"channel":"book","type":"update","data":[{"symbol":"ETH/USD","bids":[],"asks":[{"price":1774.46,"qty":0.47001888}],"checksum":96866158,"timestamp":"2026-07-07T23:00:24.616456Z"}]}
{"channel":"book","type":"update","data":[{"symbol":"ETH/USD","bids":[],"asks":[{"price":1774.47,"qty":0.00000000},{"price":1774.79,"qty":5.77388550}],"checksum":2722374110,"timestamp":"2026-07-07T23:00:24.617672Z"}]}
{"channel":"book","type":"update","data":[{"symbol":"ETH/USD","bids":[{"price":1774.30,"qty":0.00000000},{"price":1774.07,"qty":0.48930000}],"asks":[],"checksum":484902224,"timestamp":"2026-07-07T23:00:24.617681Z"}]}
{"channel":"book","type":"update","data":[{"symbol":"ETH/USD","bids":[],"asks":[{"price":1774.46,"qty":0.00000000},{"price":1774.80,"qty":24.98200000}],"checksum":2671470259,"timestamp":"2026-07-07T23:00:24.618755Z"}]}
{"channel":"book","type":"update","data":[{"symbol":"ETH/USD","bids":[],"asks":[{"price":1774.47,"qty":1.53128753}],"checksum":1224325012,"timestamp":"2026-07-07T23:00:24.620334Z"}]}
{"channel":"book","type":"update","data":[{"symbol":"ETH/USD","bids":[],"asks":[{"price":1774.46,"qty":0.47001888}],"checksum":3143969760,"timestamp":"2026-07-07T23:00:24.621713Z"}]}
{"channel":"book","type":"update","data":[{"symbol":"ETH/USD","bids":[],"asks":[{"price":1774.47,"qty":0.00000000},{"price":1774.79,"qty":5.77388550}],"checksum":484902224,"timestamp":"2026-07-07T23:00:24.622763Z"}]}
{"channel":"book","type":"update","data":[{"symbol":"ETH/USD","bids":[],"asks":[{"price":1774.46,"qty":0.00000000},{"price":1774.80,"qty":24.98200000}],"checksum":2671470259,"timestamp":"2026-07-07T23:00:24.623919Z"}]}
{"channel":"book","type":"update","data":[{"symbol":"ETH/USD","bids":[],"asks":[{"price":1774.47,"qty":1.53128753}],"checksum":1224325012,"timestamp":"2026-07-07T23:00:24.625045Z"}]}
{"channel":"book","type":"update","data":[{"symbol":"ETH/USD","bids":[],"asks":[{"price":1774.46,"qty":0.47001888}],"checksum":3143969760,"timestamp":"2026-07-07T23:00:24.626155Z"}]}
{"channel":"book","type":"update","data":[{"symbol":"ETH/USD","bids":[],"asks":[{"price":1774.47,"qty":0.00000000},{"price":1774.79,"qty":5.77388550}],"checksum":484902224,"timestamp":"2026-07-07T23:00:24.627269Z"}]}
{"channel":"book","type":"update","data":[{"symbol":"ETH/USD","bids":[],"asks":[{"price":1774.46,"qty":0.00000000},{"price":1774.80,"qty":24.98200000}],"checksum":2671470259,"timestamp":"2026-07-07T23:00:24.628457Z"}]}
{"channel":"book","type":"update","data":[{"symbol":"ETH/USD","bids":[],"asks":[{"price":1774.47,"qty":1.53128753}],"checksum":1224325012,"timestamp":"2026-07-07T23:00:24.629755Z"}]}
{"channel":"book","type":"update","data":[{"symbol":"ETH/USD","bids":[],"asks":[{"price":1774.46,"qty":0.47001888}],"checksum":3143969760,"timestamp":"2026-07-07T23:00:24.632918Z"}]}
{"channel":"book","type":"update","data":[{"symbol":"ETH/USD","bids":[],"asks":[{"price":1774.47,"qty":0.00000000},{"price":1774.79,"qty":5.77388550}],"checksum":484902224,"timestamp":"2026-07-07T23:00:24.634325Z"}]}
{"channel":"book","type":"update","data":[{"symbol":"ETH/USD","bids":[],"asks":[{"price":1774.46,"qty":0.00000000},{"price":1774.80,"qty":24.98200000}],"checksum":2671470259,"timestamp":"2026-07-07T23:00:24.635388Z"}]}
{"channel":"book","type":"update","data":[{"symbol":"ETH/USD","bids":[],"asks":[{"price":1774.47,"qty":1.53128753}],"checksum":1224325012,"timestamp":"2026-07-07T23:00:24.636675Z"}]}
{"channel":"book","type":"update","data":[{"symbol":"ETH/USD","bids":[],"asks":[{"price":1774.46,"qty":0.47001888}],"checksum":3143969760,"timestamp":"2026-07-07T23:00:24.638164Z"}]}
{"channel":"book","type":"update","data":[{"symbol":"ETH/USD","bids":[],"asks":[{"price":1774.47,"qty":0.00000000},{"price":1774.79,"qty":5.77388550}],"checksum":484902224,"timestamp":"2026-07-07T23:00:24.639323Z"}]}
{"channel":"book","type":"update","data":[{"symbol":"ETH/USD","bids":[],"asks":[{"price":1774.46,"qty":0.00000000},{"price":1774.80,"qty":24.98200000}],"checksum":2671470259,"timestamp":"2026-07-07T23:00:24.640372Z"}]}
{"channel":"book","type":"update","data":[{"symbol":"ETH/USD","bids":[],"asks":[{"price":1774.47,"qty":1.53128753}],"checksum":1224325012,"timestamp":"2026-07-07T23:00:24.641834Z"}]}
{"channel":"book","type":"update","data":[{"symbol":"ETH/USD","bids":[],"asks":[{"price":1774.46,"qty":0.47001888}],"checksum":3143969760,"timestamp":"2026-07-07T23:00:24.643128Z"}]}
{"channel":"book","type":"update","data":[{"symbol":"ETH/USD","bids":[],"asks":[{"price":1774.47,"qty":0.00000000},{"price":1774.79,"qty":5.77388550}],"checksum":484902224,"timestamp":"2026-07-07T23:00:24.644486Z"}]}
{"channel":"book","type":"update","data":[{"symbol":"ETH/USD","bids":[],"asks":[{"price":1774.46,"qty":0.00000000},{"price":1774.80,"qty":24.98200000}],"checksum":2671470259,"timestamp":"2026-07-07T23:00:24.645616Z"}]}
{"channel":"book","type":"update","data":[{"symbol":"ETH/USD","bids":[],"asks":[{"price":1774.47,"qty":1.53128753}],"checksum":1224325012,"timestamp":"2026-07-07T23:00:24.646843Z"}]}
{"channel":"book","type":"update","data":[{"symbol":"ETH/USD","bids":[],"asks":[{"price":1774.46,"qty":0.47001888}],"checksum":3143969760,"timestamp":"2026-07-07T23:00:24.648008Z"}]}
{"channel":"book","type":"update","data":[{"symbol":"ETH/USD","bids":[],"asks":[{"price":1774.47,"qty":0.00000000},{"price":1774.79,"qty":5.77388550}],"checksum":484902224,"timestamp":"2026-07-07T23:00:24.649174Z"}]}
{"channel":"book","type":"update","data":[{"symbol":"ETH/USD","bids":[],"asks":[{"price":1774.46,"qty":0.00000000},{"price":1774.80,"qty":24.98200000}],"checksum":2671470259,"timestamp":"2026-07-07T23:00:24.650402Z"}]}
{"channel":"book","type":"update","data":[{"symbol":"ETH/USD","bids":[],"asks":[{"price":1774.47,"qty":1.53128753}],"checksum":1224325012,"timestamp":"2026-07-07T23:00:24.651952Z"}]}
{"channel":"book","type":"update","data":[{"symbol":"ETH/USD","bids":[],"asks":[{"price":1774.46,"qty":0.47001888}],"checksum":3143969760,"timestamp":"2026-07-07T23:00:24.653388Z"}]}
{"channel":"book","type":"update","data":[{"symbol":"ETH/USD","bids":[],"asks":[{"price":1774.47,"qty":0.00000000},{"price":1774.79,"qty":5.77388550}],"checksum":484902224,"timestamp":"2026-07-07T23:00:24.655850Z"}]}
{"channel":"book","type":"update","data":[{"symbol":"ETH/USD","bids":[],"asks":[{"price":1774.46,"qty":0.00000000},{"price":1774.80,"qty":24.98200000}],"checksum":2671470259,"timestamp":"2026-07-07T23:00:24.657273Z"}]}
{"channel":"book","type":"update","data":[{"symbol":"ETH/USD","bids":[],"asks":[{"price":1774.47,"qty":1.53128753}],"checksum":1224325012,"timestamp":"2026-07-07T23:00:24.658675Z"}]}
{"channel":"book","type":"update","data":[{"symbol":"ETH/USD","bids":[],"asks":[{"price":1774.46,"qty":0.47001888}],"checksum":3143969760,"timestamp":"2026-07-07T23:00:24.659739Z"}]}
{"channel":"book","type":"update","data":[{"symbol":"ETH/USD","bids":[],"asks":[{"price":1774.47,"qty":0.00000000},{"price":1774.79,"qty":5.77388550}],"checksum":484902224,"timestamp":"2026-07-07T23:00:24.660871Z"}]}
{"channel":"book","type":"update","data":[{"symbol":"ETH/USD","bids":[],"asks":[{"price":1774.46,"qty":0.00000000},{"price":1774.80,"qty":24.98200000}],"checksum":2671470259,"timestamp":"2026-07-07T23:00:24.662190Z"}]}
{"channel":"book","type":"update","data":[{"symbol":"ETH/USD","bids":[],"asks":[{"price":1774.47,"qty":1.53128753}],"checksum":1224325012,"timestamp":"2026-07-07T23:00:24.663651Z"}]}
{"channel":"book","type":"update","data":[{"symbol":"ETH/USD","bids":[],"asks":[{"price":1774.46,"qty":0.47001888}],"checksum":3143969760,"timestamp":"2026-07-07T23:00:24.664914Z"}]}
{"channel":"book","type":"update","data":[{"symbol":"ETH/USD","bids":[],"asks":[{"price":1774.47,"qty":0.00000000},{"price":1774.79,"qty":5.77388550}],"checksum":484902224,"timestamp":"2026-07-07T23:00:24.666035Z"}]}
{"channel":"book","type":"update","data":[{"symbol":"ETH/USD","bids":[],"asks":[{"price":1774.46,"qty":0.00000000},{"price":1774.80,"qty":24.98200000}],"checksum":2671470259,"timestamp":"2026-07-07T23:00:24.667201Z"}]}
{"channel":"book","type":"update","data":[{"symbol":"ETH/USD","bids":[],"asks":[{"price":1774.47,"qty":1.53128753}],"checksum":1224325012,"timestamp":"2026-07-07T23:00:24.668513Z"}]}
{"channel":"book","type":"update","data":[{"symbol":"ETH/USD","bids":[],"asks":[{"price":1774.46,"qty":0.47001888}],"checksum":3143969760,"timestamp":"2026-07-07T23:00:24.669848Z"}]}
{"channel":"book","type":"update","data":[{"symbol":"ETH/USD","bids":[],"asks":[{"price":1774.47,"qty":0.00000000},{"price":1774.79,"qty":5.77388550}],"checksum":484902224,"timestamp":"2026-07-07T23:00:24.671080Z"}]}
{"channel":"book","type":"update","data":[{"symbol":"ETH/USD","bids":[],"asks":[{"price":1774.67,"qty":0.00000000},{"price":1774.80,"qty":24.98200000},{"price":1774.63,"qty":1.68966976}],"checksum":4130706522,"timestamp":"2026-07-07T23:00:24.671230Z"}]}
{"channel":"book","type":"update","data":[{"symbol":"ETH/USD","bids":[],"asks":[{"price":1774.46,"qty":0.00000000},{"price":1774.80,"qty":24.98200000}],"checksum":155586878,"timestamp":"2026-07-07T23:00:24.672314Z"}]}
{"channel":"book","type":"update","data":[{"symbol":"ETH/USD","bids":[],"asks":[{"price":1774.64,"qty":0.00000000},{"price":1774.83,"qty":12.59886962}],"checksum":782626348,"timestamp":"2026-07-07T23:00:24.672680Z"}]}
{"channel":"book","type":"update","data":[{"symbol":"ETH/USD","bids":[],"asks":[{"price":1774.62,"qty":1.10751180}],"checksum":3174157121,"timestamp":"2026-07-07T23:00:24.672988Z"}]}
{"channel":"book","type":"update","data":[{"symbol":"ETH/USD","bids":[],"asks":[{"price":1774.63,"qty":0.00000000},{"price":1774.83,"qty":12.59886962},{"price":1774.64,"qty":1.68966976}],"checksum":1449666786,"timestamp":"2026-07-07T23:00:24.674164Z"}]}
{"channel":"book","type":"update","data":[{"symbol":"ETH/USD","bids":[],"asks":[{"price":1774.48,"qty":0.00000000},{"price":1774.83,"qty":12.59886962}],"checksum":932087741,"timestamp":"2026-07-07T23:00:24.681434Z"}]}
{"channel":"book","type":"update","data":[{"symbol":"ETH/USD","bids":[],"asks":[{"price":1774.55,"qty":0.47001888}],"checksum":210066109,"timestamp":"2026-07-07T23:00:24.682953Z"}]}
{"channel":"book","type":"update","data":[{"symbol":"ETH/USD","bids":[],"asks":[{"price":1774.65,"qty":0.00000000},{"price":1774.83,"qty":12.59886962}],"checksum":2590518172,"timestamp":"2026-07-07T23:00:24.684841Z"}]}
{"channel":"book","type":"update","data":[{"symbol":"ETH/USD","bids":[],"asks":[{"price":1774.62,"qty":0.00000000},{"price":1774.84,"qty":29.47165490}],"checksum":1031239242,"timestamp":"2026-07-07T23:00:24.685975Z"}]}
{"channel":"book","type":"update","data":[{"symbol":"ETH/USD","bids":[],"asks":[{"price":1774.62,"qty":0.65042247}],"checksum":5543795,"timestamp":"2026-07-07T23:00:24.686234Z"}]}
{"channel":"book","type":"update","data":[{"symbol":"ETH/USD","bids":[],"asks":[{"price":1774.51,"qty":1.53128753}],"checksum":1091426596,"timestamp":"2026-07-07T23:00:24.687141Z"}]}
{"channel":"book","type":"update","data":[{"symbol":"ETH/USD","bids":[],"asks":[{"price":1774.50,"qty":0.47001888}],"checksum":3728156998,"timestamp":"2026-07-07T23:00:24.688460Z"}]}
{"channel":"book","type":"update","data":[{"symbol":"ETH/USD","bids":[],"asks":[{"price":1774.59,"qty":0.00000000},{"price":1774.80,"qty":24.98200000}],"checksum":1302364246,"timestamp":"2026-07-07T23:00:24.726726Z"}]}
{"channel":"book","type":"update","data":[{"symbol":"ETH/USD","bids":[],"asks":[{"price":1774.55,"qty":3.28764654}],"checksum":2179233294,"timestamp":"2026-07-07T23:00:24.728739Z"}]}
{"channel":"book","type":"update","data":[{"symbol":"ETH/USD","bids":[],"asks":[{"price":1774.76,"qty":28.17284982}],"checksum":3980409185,"timestamp":"2026-07-07T23:00:24.729172Z"}]}
{"channel":"book","type":"update","data":[{"symbol":"ETH/USD","bids":[],"asks":[{"price":1774.79,"qty":0.00000000},{"price":1774.80,"qty":24.98200000}],"checksum":2522879143,"timestamp":"2026-07-07T23:00:24.730943Z"}]}
{"channel":"book","type":"update","data":[{"symbol":"ETH/USD","bids":[],"asks":[{"price":1774.75,"qty":9.89391854}],"checksum":1782845780,"timestamp":"2026-07-07T23:00:24.731166Z"}]}
{"channel":"book","type":"update","data":[{"symbol":"BTC/USD","bids":[],"asks":[{"price":63515.6,"qty":0.57934700}],"checksum":924650201,"timestamp":"2026-07-07T23:00:24.733217Z"}]}
{"channel":"book","type":"update","data":[{"symbol":"BTC/USD","bids":[],"asks":[{"price":63515.5,"qty":0.00000000},{"price":63517.3,"qty":0.09391965}],"checksum":2892102467,"timestamp":"2026-07-07T23:00:24.734548Z"}]}
{"channel":"book","type":"update","data":[{"symbol":"BTC/USD","bids":[],"asks":[{"price":63515.0,"qty":0.78721655}],"checksum":3952615021,"timestamp":"2026-07-07T23:00:24.735060Z"}]}
{"channel":"book","type":"update","data":[{"symbol":"BTC/USD","bids":[],"asks":[{"price":63515.5,"qty":0.18233428}],"checksum":3075851701,"timestamp":"2026-07-07T23:00:24.735889Z"}]}
{"channel":"book","type":"update","data":[{"symbol":"BTC/USD","bids":[],"asks":[{"price":63515.6,"qty":0.00000000},{"price":63516.0,"qty":0.03148812}],"checksum":3653154001,"timestamp":"2026-07-07T23:00:24.736041Z"}]}
{"channel":"book","type":"update","data":[{"symbol":"BTC/USD","bids":[],"asks":[{"price":63515.5,"qty":0.00000000},{"price":63517.3,"qty":0.09391965}],"checksum":1677789994,"timestamp":"2026-07-07T23:00:24.737321Z"}]}
{"channel":"book","type":"update","data":[{"symbol":"BTC/USD","bids":[],"asks":[{"price":63514.9,"qty":0.24438334}],"checksum":1864265835,"timestamp":"2026-07-07T23:00:24.738498Z"}]}
{"channel":"book","type":"update","data":[{"symbol":"ETH/USD","bids":[],"asks":[{"price":1774.55,"qty":2.81762766}],"checksum":607805457,"timestamp":"2026-07-07T23:00:24.789301Z"}]}
{"channel":"book","type":"update","data":[{"symbol":"ETH/USD","bids":[],"asks":[{"price":1774.49,"qty":1.53128753}],"checksum":1839646179,"timestamp":"2026-07-07T23:00:24.790658Z"}]}
{"channel":"book","type":"update","data":[{"symbol":"ETH/USD","bids":[],"asks":[{"price":1774.48,"qty":0.47001888}],"checksum":3107865974,"timestamp":"2026-07-07T23:00:24.795379Z"}]}
{"channel":"book","type":"update","data":[{"symbol":"ETH/USD","bids":[],"asks":[{"price":1774.47,"qty":1.53128753}],"checksum":1704849149,"timestamp":"2026-07-07T23:00:24.797409Z"}]}
{"channel":"book","type":"update","data":[{"symbol":"ETH/USD","bids":[],"asks":[{"price":1774.49,"qty":0.00000000},{"price":1774.70,"qty":0.48930000}],"checksum":2119583644,"timestamp":"2026-07-07T23:00:24.798340Z"}]}
{"channel":"book","type":"update","data":[{"symbol":"BTC/USD","bids":[],"asks":[{"price":63512.5,"qty":0.57934500}],"checksum":114768483,"timestamp":"2026-07-07T23:00:24.836012Z"}]}
{"channel":"book","type":"update","data":[{"symbol":"ETH/USD","bids":[],"asks":[{"price":1774.64,"qty":0.00000000},{"price":1774.75,"qty":9.89391854},{"price":1774.62,"qty":2.34009223}],"checksum":853904880,"timestamp":"2026-07-07T23:00:24.846368Z"}]}
{"channel":"book","type":"update","data":[{"symbol":"ETH/USD","bids":[],"asks":[{"price":1774.62,"qty":1.68966976}],"checksum":1165215121,"timestamp":"2026-07-07T23:00:24.847583Z"}]}
{"channel":"book","type":"update","data":[{"symbol":"ETH/USD","bids":[],"asks":[{"price":1774.62,"qty":0.00000000},{"price":1774.76,"qty":28.17284982},{"price":1774.69,"qty":1.68966976}],"checksum":1282262431,"timestamp":"2026-07-07T23:00:24.848950Z"}]}
{"channel":"book","type":"update","data":[{"symbol":"ETH/USD","bids":[],"asks":[{"price":1774.68,"qty":0.65042247}],"checksum":1555060380,"timestamp":"2026-07-07T23:00:24.850151Z"}]}
{"channel":"book","type":"update","data":[{"symbol":"ETH/USD","bids":[],"asks":[{"price":1774.47,"qty":1.82007650}],"checksum":2097312311,"timestamp":"2026-07-07T23:00:24.864733Z"}]}
{"channel":"book","type":"update","data":[{"symbol":"ETH/USD","bids":[],"asks":[{"price":1774.52,"qty":0.00000000},{"price":1774.75,"qty":9.89391854}],"checksum":300897618,"timestamp":"2026-07-07T23:00:24.865701Z"}]}
{"channel":"book","type":"update","data":[{"symbol":"ETH/USD","bids":[],"asks":[{"price":1774.51,"qty":0.00000000},{"price":1774.76,"qty":28.17284982}],"checksum":872312353,"timestamp":"2026-07-07T23:00:24.891711Z"}]}
{"channel":"book","type":"update","data":[{"symbol":"ETH/USD","bids":[],"asks":[{"price":1774.50,"qty":0.00000000},{"price":1774.80,"qty":24.98200000}],"checksum":2079224440,"timestamp":"2026-07-07T23:00:24.896567Z"}]}
{"channel":"book","type":"update","data":[{"symbol":"ETH/USD","bids":[],"asks":[{"price":1774.46,"qty":0.47001888}],"checksum":1046219655,"timestamp":"2026-07-07T23:00:24.897848Z"}]}
{"channel":"book","type":"update","data":[{"symbol":"ETH/USD","bids":[{"price":1774.33,"qty":0.00000000},{"price":1773.99,"qty":11.94633425}],"asks":[],"checksum":2104140193,"timestamp":"2026-07-07T23:00:24.916563Z"}]}
{"channel":"book","type":"update","data":[{"symbol":"BTC/USD","bids":[],"asks":[{"price":63515.0,"qty":0.00000000},{"price":63516.0,"qty":0.03148812}],"checksum":4197502306,"timestamp":"2026-07-07T23:00:24.990629Z"}]}
{"channel":"book","type":"update","data":[{"symbol":"BTC/USD","bids":[],"asks":[{"price":63514.9,"qty":0.00000000},{"price":63517.3,"qty":0.09391965}],"checksum":2170436749,"timestamp":"2026-07-07T23:00:24.992206Z"}]}
{"channel":"book","type":"update","data":[{"symbol":"BTC/USD","bids":[],"asks":[{"price":63514.4,"qty":0.78722414}],"checksum":1345281939,"timestamp":"2026-07-07T23:00:24.992744Z"}]}
{"channel":"book","type":"update","data":[{"symbol":"BTC/USD","bids":[],"asks":[{"price":63514.3,"qty":0.15827511}],"checksum":755166310,"timestamp":"2026-07-07T23:00:24.994367Z"}]}
{"channel":"book","type":"update","data":[{"symbol":"ETH/USD","bids":[{"price":1774.31,"qty":0.79722118}],"asks":[],"checksum":650899138,"timestamp":"2026-07-07T23:00:24.995541Z"}]}
{"channel":"book","type":"update","data":[{"symbol":"ETH/USD","bids":[],"asks":[{"price":1774.48,"qty":0.00000000},{"price":1774.80,"qty":24.98200000}],"checksum":2240257362,"timestamp":"2026-07-07T23:00:24.998862Z"}]}
{"channel":"book","type":"update","data":[{"symbol":"ETH/USD","bids":[{"price":1773.99,"qty":62.66934624}],"asks":[],"checksum":141285375,"timestamp":"2026-07-07T23:00:25.010130Z"}]}
{"channel":"book","type":"update","data":[{"symbol":"ETH/USD","bids":[{"price":1774.00,"qty":15.14081908}],"asks":[],"checksum":3754312268,"timestamp":"2026-07-07T23:00:25.011768Z"}]}
{"channel":"book","type":"update","data":[{"symbol":"ETH/USD","bids":[],"asks":[{"price":1774.69,"qty":0.00000000},{"price":1774.83,"qty":6.99792449},{"price":1774.67,"qty":1.68966976}],"checksum":473460681,"timestamp":"2026-07-07T23:00:25.012077Z"}]}
{"channel":"book","type":"update","data":[{"symbol":"ETH/USD","bids":[],"asks":[{"price":1774.68,"qty":0.00000000},{"price":1774.83,"qty":6.99792449}],"checksum":3053434326,"timestamp":"2026-07-07T23:00:25.013820Z"}]}
{"channel":"book","type":"update","data":[{"symbol":"ETH/USD","bids":[],"asks":[{"price":1774.66,"qty":0.65042247}],"checksum":444312975,"timestamp":"2026-07-07T23:00:25.014010Z"}]}
{"channel":"book","type":"update","data":[{"symbol":"ETH/USD","bids":[{"price":1774.32,"qty":0.48930000}],"asks":[],"checksum":751310973,"timestamp":"2026-07-07T23:00:25.015178Z"}]}
{"channel":"book","type":"update","data":[{"symbol":"ETH/USD","bids":[],"asks":[{"price":1774.67,"qty":0.00000000},{"price":1774.83,"qty":6.99792449},{"price":1774.69,"qty":1.68966976}],"checksum":2996915999,"timestamp":"2026-07-07T23:00:25.015323Z"}]}
{"channel":"book","type":"update","data":[{"symbol":"ETH/USD","bids":[],"asks":[{"price":1774.55,"qty":0.00000000},{"price":1774.83,"qty":6.99792449}],"checksum":3964949505,"timestamp":"2026-07-07T23:00:25.016445Z"}]}
{"channel":"book","type":"update","data":[{"symbol":"ETH/USD","bids":[],"asks":[{"price":1774.52,"qty":2.81767403}],"checksum":799738851,"timestamp":"2026-07-07T23:00:25.017962Z"}]}
{"channel":"book","type":"update","data":[{"symbol":"ETH/USD","bids":[{"price":1774.31,"qty":0.30792118}],"asks":[],"checksum":3729167280,"timestamp":"2026-07-07T23:00:25.168344Z"}]}
{"channel":"book","type":"update","data":[{"symbol":"ETH/USD","bids":[],"asks":[{"price":1774.69,"qty":0.00000000},{"price":1774.83,"qty":6.99792449},{"price":1774.65,"qty":1.68966976}],"checksum":971867896,"timestamp":"2026-07-07T23:00:25.201810Z"}]}
{"channel":"book","type":"update","data":[{"symbol":"ETH/USD","bids":[],"asks":[{"price":1774.64,"qty":0.65042247}],"checksum":29460680,"timestamp":"2026-07-07T23:00:25.203261Z"}]}
{"channel":"book","type":"update","data":[{"symbol":"ETH/USD","bids":[],"asks":[{"price":1774.66,"qty":0.00000000},{"price":1774.80,"qty":24.98200000}],"checksum":1001914021,"timestamp":"2026-07-07T23:00:25.203275Z"}]}
{"channel":"book","type":"update","data":[{"symbol":"ETH/USD","bids":[],"asks":[{"price":1774.65,"qty":0.00000000},{"price":1774.83,"qty":6.99792449},{"price":1774.63,"qty":1.68966976}],"checksum":785428087,"timestamp":"2026-07-07T23:00:25.474359Z"}]}
{"channel":"book","type":"update","data":[{"symbol":"ETH/USD","bids":[],"asks":[{"price":1774.64,"qty":0.00000000},{"price":1774.83,"qty":6.99792449}],"checksum":1853909479,"timestamp":"2026-07-07T23:00:25.475629Z"}]}
{"channel":"book","type":"update","data":[{"symbol":"ETH/USD","bids":[],"asks":[{"price":1774.62,"qty":0.65042247}],"checksum":3072307260,"timestamp":"2026-07-07T23:00:25.475791Z"}]}
{"channel":"book","type":"update","data":[{"symbol":"ETH/USD","bids":[],"asks":[{"price":1774.63,"qty":0.00000000},{"price":1774.83,"qty":6.99792449},{"price":1774.69,"qty":1.68966976}],"checksum":3346903364,"timestamp":"2026-07-07T23:00:25.476906Z"}]}
{"channel":"book","type":"update","data":[{"symbol":"ETH/USD","bids":[{"price":1774.26,"qty":1.48764222}],"asks":[],"checksum":3327059584,"timestamp":"2026-07-07T23:00:25.554673Z"}]}
{"channel":"book","type":"update","data":[{"symbol":"ETH/USD","bids":[{"price":1774.26,"qty":0.00000000},{"price":1774.00,"qty":15.14081908}],"asks":[],"checksum":2231077248,"timestamp":"2026-07-07T23:00:25.554865Z"}]}
{"channel":"heartbeat"}
{"channel":"book","type":"update","data":[{"symbol":"ETH/USD","bids":[{"price":1774.25,"qty":0.00000000},{"price":1773.99,"qty":11.94633425}],"asks":[],"checksum":2109013274,"timestamp":"2026-07-07T23:00:25.572979Z"}]}
{"channel":"book","type":"update","data":[{"symbol":"ETH/USD","bids":[{"price":1774.32,"qty":0.00000000},{"price":1773.98,"qty":35.02158740}],"asks":[],"checksum":1829331568,"timestamp":"2026-07-07T23:00:25.573294Z"}]}
{"channel":"book","type":"update","data":[{"symbol":"ETH/USD","bids":[{"price":1774.00,"qty":0.00000000},{"price":1773.96,"qty":20.07600000}],"asks":[],"checksum":3560755068,"timestamp":"2026-07-07T23:00:25.573472Z"}]}
{"channel":"book","type":"update","data":[{"symbol":"ETH/USD","bids":[{"price":1774.20,"qty":2.16403672}],"asks":[],"checksum":664313636,"timestamp":"2026-07-07T23:00:25.574455Z"}]}
{"channel":"book","type":"update","data":[{"symbol":"ETH/USD","bids":[{"price":1774.17,"qty":2.81821513}],"asks":[],"checksum":3007783202,"timestamp":"2026-07-07T23:00:25.574486Z"}]}
{"channel":"book","type":"update","data":[{"symbol":"ETH/USD","bids":[{"price":1774.19,"qty":0.00000000},{"price":1773.98,"qty":35.02158740},{"price":1774.21,"qty":1.68966976}],"asks":[],"checksum":1410614399,"timestamp":"2026-07-07T23:00:25.576220Z"}]}
{"channel":"book","type":"update","data":[{"symbol":"ETH/USD","bids":[{"price":1774.31,"qty":0.00000000},{"price":1773.98,"qty":35.02158740}],"asks":[],"checksum":1469112681,"timestamp":"2026-07-07T23:00:25.607720Z"}]}
{"channel":"book","type":"update","data":[{"symbol":"ETH/USD","bids":[{"price":1774.22,"qty":1.30000000}],"asks":[],"checksum":3201299925,"timestamp":"2026-07-07T23:00:25.609183Z"}]}
{"channel":"book","type":"update","data":[{"symbol":"ETH/USD","bids":[{"price":1774.26,"qty":0.48930000}],"asks":[],"checksum":3431809240,"timestamp":"2026-07-07T23:00:25.609345Z"}]}
{"channel":"book","type":"update","data":[{"symbol":"ETH/USD","bids":[{"price":1774.26,"qty":0.00000000},{"price":1773.99,"qty":11.94633425}],"asks":[],"checksum":3201299925,"timestamp":"2026-07-07T23:00:25.610582Z"}]}
{"channel":"book","type":"update","data":[{"symbol":"ETH/USD","bids":[],"asks":[{"price":1774.46,"qty":0.95931888}],"checksum":2934583351,"timestamp":"2026-07-07T23:00:25.611146Z"}]}
{"channel":"book","type":"update","data":[{"symbol":"ETH/USD","bids":[{"price":1774.20,"qty":0.00000000},{"price":1773.98,"qty":35.02158740}],"asks":[],"checksum":1241625303,"timestamp":"2026-07-07T23:00:25.611262Z"}]}
{"channel":"book","type":"update","data":[{"symbol":"ETH/USD","bids":[],"asks":[{"price":1774.52,"qty":0.00000000},{"price":1774.83,"qty":6.99792449}],"checksum":1321943293,"timestamp":"2026-07-07T23:00:25.613395Z"}]}
{"channel":"book","type":"update","data":[{"symbol":"ETH/USD","bids":[],"asks":[{"price":1774.76,"qty":0.00000000},{"price":1774.84,"qty":1.30000000}],"checksum":3080617870,"timestamp":"2026-07-07T23:00:25.613965Z"}]}
{"channel":"book","type":"update","data":[{"symbol":"ETH/USD","bids":[{"price":1774.21,"qty":0.00000000},{"price":1773.96,"qty":20.07600000},{"price":1774.19,"qty":1.68966976}],"asks":[],"checksum":2357970949,"timestamp":"2026-07-07T23:00:25.615273Z"}]}
{"channel":"book","type":"update","data":[{"symbol":"BTC/USD","bids":[],"asks":[{"price":63514.4,"qty":0.00000000},{"price":63516.0,"qty":0.03148812}],"checksum":1127623836,"timestamp":"2026-07-07T23:00:25.615839Z"}]}
{"channel":"book","type":"update","data":[{"symbol":"ETH/USD","bids":[{"price":1774.16,"qty":20.39003775}],"asks":[],"checksum":1759495466,"timestamp":"2026-07-07T23:00:25.616067Z"}]}
{"channel":"book","type":"update","data":[{"symbol":"ETH/USD","bids":[],"asks":[{"price":1774.75,"qty":14.60180469}],"checksum":1227098852,"timestamp":"2026-07-07T23:00:25.616259Z"}]}
{"channel":"book","type":"update","data":[{"symbol":"ETH/USD","bids":[],"asks":[{"price":1774.75,"qty":9.89391854}],"checksum":1759495466,"timestamp":"2026-07-07T23:00:25.616610Z"}]}
{"channel":"book","type":"update","data":[{"symbol":"ETH/USD","bids":[],"asks":[{"price":1774.46,"qty":3.77708770}],"checksum":4191841008,"timestamp":"2026-07-07T23:00:25.617459Z"}]}
{"channel":"book","type":"update","data":[{"symbol":"ETH/USD","bids":[],"asks":[{"price":1774.69,"qty":29.86369799}],"checksum":250538397,"timestamp":"2026-07-07T23:00:25.617557Z"}]}
{"channel":"book","type":"update","data":[{"symbol":"BTC/USD","bids":[],"asks":[{"price":63513.7,"qty":0.78723226}],"checksum":3105221402,"timestamp":"2026-07-07T23:00:25.618283Z"}]}
{"channel":"book","type":"update","data":[{"symbol":"ETH/USD","bids":[{"price":1774.17,"qty":0.00000000},{"price":1773.96,"qty":20.07600000}],"asks":[],"checksum":3380714278,"timestamp":"2026-07-07T23:00:25.619130Z"}]}
{"channel":"book","type":"update","data":[{"symbol":"ETH/USD","bids":[],"asks":[{"price":1774.62,"qty":8.97721467}],"checksum":2294394234,"timestamp":"2026-07-07T23:00:25.622119Z"}]}
{"channel":"book","type":"update","data":[{"symbol":"ETH/USD","bids":[{"price":1774.18,"qty":0.00000000},{"price":1773.94,"qty":2.87402415},{"price":1774.17,"qty":5.56003448}],"asks":[],"checksum":2765076003,"timestamp":"2026-07-07T23:00:25.622240Z"}]}
{"channel":"book","type":"update","data":[{"symbol":"BTC/USD","bids":[],"asks":[{"price":63514.3,"qty":0.00000000},{"price":63516.0,"qty":0.03148812}],"checksum":2319766926,"timestamp":"2026-07-07T23:00:25.622732Z"}]}
{"channel":"book","type":"update","data":[{"symbol":"BTC/USD","bids":[],"asks":[{"price":63513.7,"qty":0.00000000},{"price":63517.3,"qty":0.09391965}],"checksum":2170436749,"timestamp":"2026-07-07T23:00:25.623229Z"}]}
{"channel":"book","type":"update","data":[{"symbol":"BTC/USD","bids":[],"asks":[{"price":63513.6,"qty":0.22973860}],"checksum":1083894650,"timestamp":"2026-07-07T23:00:25.625201Z"}]}
{"channel":"book","type":"update","data":[{"symbol":"BTC/USD","bids":[],"asks":[{"price":63512.4,"qty":0.11693040}],"checksum":3840323026,"timestamp":"2026-07-07T23:00:25.625351Z"}]}
{"channel":"book","type":"update","data":[{"symbol":"BTC/USD","bids":[],"asks":[{"price":63513.6,"qty":0.00000000},{"price":63515.5,"qty":0.78721049}],"checksum":2681009628,"timestamp":"2026-07-07T23:00:25.626031Z"}]}
{"channel":"book","type":"update","data":[{"symbol":"BTC/USD","bids":[],"asks":[{"price":63515.4,"qty":0.24438154}],"checksum":1575042890,"timestamp":"2026-07-07T23:00:25.628316Z"}]}
{"channel":"book","type":"update","data":[{"symbol":"ETH/USD","bids":[{"price":1773.98,"qty":28.18512742}],"asks":[],"checksum":2425621340,"timestamp":"2026-07-07T23:00:25.631503Z"}]}
{"channel":"book","type":"update","data":[{"symbol":"ETH/USD","bids":[],"asks":[{"price":1774.46,"qty":3.28778770}],"checksum":1227062501,"timestamp":"2026-07-07T23:00:25.633099Z"}]}
{"channel":"book","type":"update","data":[{"symbol":"ETH/USD","bids":[],"asks":[{"price":1774.45,"qty":1.67075351}],"checksum":3210568784,"timestamp":"2026-07-07T23:00:25.633285Z"}]}
{"channel":"book","type":"update","data":[{"symbol":"ETH/USD","bids":[],"asks":[{"price":1774.69,"qty":28.17402823},{"price":1774.55,"qty":1.68966976}],"checksum":3751813565,"timestamp":"2026-07-07T23:00:25.634338Z"}]}
{"channel":"book","type":"update","data":[{"symbol":"ETH/USD","bids":[],"asks":[{"price":1774.46,"qty":0.47001888}],"checksum":1364408782,"timestamp":"2026-07-07T23:00:25.634508Z"}]}
{"channel":"book","type":"update","data":[{"symbol":"ETH/USD","bids":[],"asks":[{"price":1774.44,"qty":0.47001888}],"checksum":2279960017,"timestamp":"2026-07-07T23:00:25.634519Z"}]}
{"channel":"book","type":"update","data":[{"symbol":"ETH/USD","bids":[{"price":1774.16,"qty":0.54387671}],"asks":[],"checksum":3754964953,"timestamp":"2026-07-07T23:00:25.634835Z"}]}
{"channel":"book","type":"update","data":[{"symbol":"ETH/USD","bids":[],"asks":[{"price":1774.54,"qty":0.61490426}],"checksum":1648950105,"timestamp":"2026-07-07T23:00:25.635653Z"}]}
{"channel":"book","type":"update","data":[{"symbol":"ETH/USD","bids":[],"asks":[{"price":1774.45,"qty":0.00000000},{"price":1774.75,"qty":9.89391854}],"checksum":1327463217,"timestamp":"2026-07-07T23:00:25.635982Z"}]}
{"channel":"book","type":"update","data":[{"symbol":"ETH/USD","bids":[],"asks":[{"price":1774.45,"qty":0.68359347}],"checksum":3623298600,"timestamp":"2026-07-07T23:00:25.636024Z"}]}
{"channel":"book","type":"update","data":[{"symbol":"ETH/USD","bids":[{"price":1774.05,"qty":19.84616104}],"asks":[],"checksum":1273925710,"timestamp":"2026-07-07T23:00:25.636145Z"}]}
{"channel":"book","type":"update","data":[{"symbol":"ETH/USD","bids":[{"price":1774.09,"qty":8.41164028}],"asks":[],"checksum":3660727052,"timestamp":"2026-07-07T23:00:25.636492Z"}]}
{"channel":"book","type":"update","data":[{"symbol":"ETH/USD","bids":[{"price":1774.12,"qty":2.81829692}],"asks":[],"checksum":778086953,"timestamp":"2026-07-07T23:00:25.636507Z"}]}
{"channel":"book","type":"update","data":[{"symbol":"ETH/USD","bids":[],"asks":[{"price":1774.44,"qty":0.00000000},{"price":1774.75,"qty":9.89391854}],"checksum":797748989,"timestamp":"2026-07-07T23:00:25.637558Z"}]}
{"channel":"book","type":"update","data":[{"symbol":"ETH/USD","bids":[{"price":1774.06,"qty":5.92407907}],"asks":[],"checksum":3625711308,"timestamp":"2026-07-07T23:00:25.638215Z"}]}
