{"channel":"status","type":"update","data":[{"version":"2.0.10","system":"online","api_version":"v2","connection_id":4421894013101914413}]}
{"method":"subscribe","result":{"channel":"book","depth":10,"snapshot":true,"symbol":"BTC/USD"},"success":true,"time_in":"2026-07-07T23:00:03.501510Z","time_out":"2026-07-07T23:00:03.501553Z"}
{"method":"subscribe","result":{"channel":"book","depth":10,"snapshot":true,"symbol":"ETH/USD"},"success":true,"time_in":"2026-07-07T23:00:03.501510Z","time_out":"2026-07-07T23:00:03.501553Z"}
{"method":"subscribe","result":{"channel":"trade","snapshot":false,"symbol":"BTC/USD"},"success":true,"time_in":"2026-07-07T23:00:03.515033Z","time_out":"2026-07-07T23:00:03.515064Z"}
{"method":"subscribe","result":{"channel":"trade","snapshot":false,"symbol":"ETH/USD"},"success":true,"time_in":"2026-07-07T23:00:03.515033Z","time_out":"2026-07-07T23:00:03.515064Z"}
{"channel":"heartbeat"}
{"channel":"book","type":"snapshot","data":[{"symbol":"BTC/USD","bids":[{"price":63501.6,"qty":0.63889204},{"price":63500.9,"qty":0.00005100},{"price":63499.0,"qty":0.78741286},{"price":63498.0,"qty":1.30271205},{"price":63497.7,"qty":0.00005100},{"price":63497.0,"qty":0.00015000},{"price":63496.4,"qty":0.27044082},{"price":63496.3,"qty":0.81891828},{"price":63495.8,"qty":0.02713013},{"price":63495.2,"qty":0.05990000}],"asks":[{"price":63501.9,"qty":0.00100000},{"price":63502.0,"qty":0.00073311},{"price":63502.1,"qty":0.01946065},{"price":63502.2,"qty":0.06514381},{"price":63504.0,"qty":0.00005100},{"price":63504.7,"qty":0.47474367},{"price":63504.8,"qty":0.78734230},{"price":63505.1,"qty":0.00786998},{"price":63505.9,"qty":0.78732894},{"price":63506.4,"qty":0.00783883}],"checksum":423379305,"timestamp":"2026-07-07T23:00:03.947173Z"}]}
{"channel":"book","type":"snapshot","data":[{"symbol":"ETH/USD","bids":[{"price":1774.13,"qty":1.13309580},{"price":1774.00,"qty":0.31278143},{"price":1773.95,"qty":0.48930000},{"price":1773.90,"qty":0.84136855},{"price":1773.89,"qty":2.81865510},{"price":1773.79,"qty":1.68966976},{"price":1773.78,"qty":0.45737557},{"price":1773.76,"qty":5.56003448},{"price":1773.75,"qty":28.18364181},{"price":1773.72,"qty":16.23079170}],"asks":[{"price":1774.14,"qty":2.31805112},{"price":1774.20,"qty":0.84122283},{"price":1774.21,"qty":2.81816695},{"price":1774.37,"qty":0.50000000},{"price":1774.38,"qty":5.10831691},{"price":1774.39,"qty":6.21593794},{"price":1774.40,"qty":9.52100000},{"price":1774.41,"qty":1.30000000},{"price":1774.44,"qty":1.93301040},{"price":1774.45,"qty":2.87402415}],"checksum":4114450078,"timestamp":"2026-07-07T23:00:03.973810Z"}]}
{"channel":"book","type":"update","data":[{"symbol":"ETH/USD","bids":[],"asks":[{"price":1774.14,"qty":2.00130641}],"checksum":3356266482,"timestamp":"2026-07-07T23:00:03.977459Z"}]}
{"channel":"book","type":"update","data":[{"symbol":"ETH/USD","bids":[],"asks":[{"price":1774.25,"qty":0.31674471}],"checksum":2094025605,"timestamp":"2026-07-07T23:00:03.978991Z"}]}
{"channel":"book","type":"update","data":[{"symbol":"ETH/USD","bids":[],"asks":[{"price":1774.32,"qty":0.48930000}],"checksum":61430240,"timestamp":"2026-07-07T23:00:03.995164Z"}]}
{"channel":"book","type":"update","data":[{"symbol":"ETH/USD","bids":[{"price":1773.90,"qty":0.00000000},{"price":1773.70,"qty":28.18950592}],"asks":[],"checksum":188427729,"timestamp":"2026-07-07T23:00:04.000677Z"}]}
{"channel":"book","type":"update","data":[{"symbol":"ETH/USD","bids":[{"price":1773.77,"qty":10.07248737}],"asks":[],"checksum":1224311855,"timestamp":"2026-07-07T23:00:04.004598Z"}]}
{"channel":"book","type":"update","data":[{"symbol":"ETH/USD","bids":[{"price":1773.76,"qty":0.00000000},{"price":1773.70,"qty":28.18950592},{"price":1773.78,"qty":6.01741005}],"asks":[],"checksum":1653630510,"timestamp":"2026-07-07T23:00:04.005636Z"}]}
{"channel":"book","type":"update","data":[{"symbol":"ETH/USD","bids":[],"asks":[{"price":1774.18,"qty":0.27995236}],"checksum":3680296913,"timestamp":"2026-07-07T23:00:04.017787Z"}]}
{"channel":"book","type":"update","data":[{"symbol":"BTC/USD","bids":[],"asks":[{"price":63502.0,"qty":0.01573311}],"checksum":1007031556,"timestamp":"2026-07-07T23:00:04.031158Z"}]}
{"channel":"book","type":"update","data":[{"symbol":"BTC/USD","bids":[],"asks":[{"price":63502.0,"qty":0.01500000},{"price":63501.9,"qty":0.00205659}],"checksum":1741843838,"timestamp":"2026-07-07T23:00:04.032943Z"}]}
{"channel":"book","type":"update","data":[{"symbol":"BTC/USD","bids":[{"price":63501.8,"qty":0.03920000}],"asks":[],"checksum":360752936,"timestamp":"2026-07-07T23:00:04.034771Z"}]}
{"channel":"book","type":"update","data":[{"symbol":"BTC/USD","bids":[{"price":63501.8,"qty":0.00000000},{"price":63495.2,"qty":0.05990000}],"asks":[],"checksum":1741843838,"timestamp":"2026-07-07T23:00:04.036583Z"}]}
{"channel":"book","type":"update","data":[{"symbol":"ETH/USD","bids":[],"asks":[{"price":1774.40,"qty":37.69954910}],"checksum":2478850393,"timestamp":"2026-07-07T23:00:04.057960Z"}]}
{"channel":"book","type":"update","data":[{"symbol":"ETH/USD","bids":[],"asks":[{"price":1774.38,"qty":12.84373463}],"checksum":2268163764,"timestamp":"2026-07-07T23:00:04.075363Z"}]}
{"channel":"book","type":"update","data":[{"symbol":"BTC/USD","bids":[{"price":63496.4,"qty":0.00000000},{"price":63494.6,"qty":0.00005100}],"asks":[],"checksum":3994479706,"timestamp":"2026-07-07T23:00:04.089746Z"}]}
{"channel":"book","type":"update","data":[{"symbol":"ETH/USD","bids":[],"asks":[{"price":1774.39,"qty":6.54793657}],"checksum":2322173678,"timestamp":"2026-07-07T23:00:04.180764Z"}]}
{"channel":"book","type":"update","data":[{"symbol":"ETH/USD","bids":[],"asks":[{"price":1774.21,"qty":0.00000000},{"price":1774.41,"qty":1.30000000}],"checksum":2119992109,"timestamp":"2026-07-07T23:00:04.223793Z"}]}
{"channel":"book","type":"update","data":[{"symbol":"ETH/USD","bids":[],"asks":[{"price":1774.20,"qty":0.00000000},{"price":1774.45,"qty":2.87402415}],"checksum":2257459046,"timestamp":"2026-07-07T23:00:04.225122Z"}]}
{"channel":"book","type":"update","data":[{"symbol":"ETH/USD","bids":[],"asks":[{"price":1774.16,"qty":2.81823949}],"checksum":232962895,"timestamp":"2026-07-07T23:00:04.225497Z"}]}
{"channel":"book","type":"update","data":[{"symbol":"BTC/USD","bids":[{"price":63501.6,"qty":0.03422434}],"asks":[],"checksum":3418844395,"timestamp":"2026-07-07T23:00:04.285801Z"}]}
{"channel":"book","type":"update","data":[{"symbol":"BTC/USD","bids":[],"asks":[{"price":63501.8,"qty":0.02213082}],"checksum":1292825678,"timestamp":"2026-07-07T23:00:04.288938Z"}]}
{"channel":"book","type":"update","data":[{"symbol":"BTC/USD","bids":[],"asks":[{"price":63501.9,"qty":0.00100000},{"price":63501.7,"qty":0.00105659}],"checksum":4260582610,"timestamp":"2026-07-07T23:00:04.290253Z"}]}
{"channel":"book","type":"update","data":[{"symbol":"BTC/USD","bids":[{"price":63499.7,"qty":0.60470924}],"asks":[],"checksum":1565893961,"timestamp":"2026-07-07T23:00:04.290406Z"}]}
{"channel":"book","type":"update","data":[{"symbol":"BTC/USD","bids":[{"price":63496.4,"qty":0.27044082}],"asks":[],"checksum":294308926,"timestamp":"2026-07-07T23:00:04.292620Z"}]}
{"channel":"book","type":"update","data":[{"symbol":"BTC/USD","bids":[],"asks":[{"price":63501.8,"qty":0.00000000},{"price":63505.9,"qty":0.78732894}],"checksum":1886110973,"timestamp":"2026-07-07T23:00:04.293463Z"}]}
{"channel":"book","type":"update","data":[{"symbol":"BTC/USD","bids":[],"asks":[{"price":63501.7,"qty":0.00000000},{"price":63506.4,"qty":0.00783883},{"price":63501.9,"qty":0.00205659}],"checksum":576330430,"timestamp":"2026-07-07T23:00:04.294819Z"}]}
{"channel":"book","type":"update","data":[{"symbol":"ETH/USD","bids":[],"asks":[{"price":1774.16,"qty":0.00000000},{"price":1774.44,"qty":1.83004268}],"checksum":860332376,"timestamp":"2026-07-07T23:00:04.405055Z"}]}
{"channel":"book","type":"update","data":[{"symbol":"ETH/USD","bids":[],"asks":[{"price":1774.20,"qty":2.81817962}],"checksum":4023358864,"timestamp":"2026-07-07T23:00:04.406496Z"}]}
{"channel":"heartbeat"}
{"channel":"trade","type":"update","data":[{"symbol":"ETH/USD","side":"buy","price":1774.14,"qty":0.00147959,"ord_type":"limit","trade_id":64175815,"timestamp":"2026-07-07T23:00:04.585581Z"}]}
{"channel":"book","type":"update","data":[{"symbol":"ETH/USD","bids":[],"asks":[{"price":1774.14,"qty":1.99982682}],"checksum":1698733121,"timestamp":"2026-07-07T23:00:04.585581Z"}]}
{"channel":"trade","type":"update","data":[{"symbol":"BTC/USD","side":"buy","price":63501.9,"qty":0.00004134,"ord_type":"limit","trade_id":103436768,"timestamp":"2026-07-07T23:00:04.590753Z"}]}
{"channel":"book","type":"update","data":[{"symbol":"BTC/USD","bids":[],"asks":[{"price":63501.9,"qty":0.00201525}],"checksum":1812535124,"timestamp":"2026-07-07T23:00:04.590753Z"}]}
{"channel":"book","type":"update","data":[{"symbol":"ETH/USD","bids":[{"price":1774.13,"qty":1.24582711}],"asks":[],"checksum":1332909310,"timestamp":"2026-07-07T23:00:04.602155Z"}]}
{"channel":"book","type":"update","data":[{"symbol":"ETH/USD","bids":[{"price":1773.80,"qty":0.05637614}],"asks":[],"checksum":317247385,"timestamp":"2026-07-07T23:00:04.634099Z"}]}
{"channel":"book","type":"update","data":[{"symbol":"ETH/USD","bids":[{"price":1773.79,"qty":0.00000000},{"price":1773.70,"qty":28.18950592},{"price":1773.81,"qty":1.68966976}],"asks":[],"checksum":1475412217,"timestamp":"2026-07-07T23:00:04.635653Z"}]}
{"channel":"book","type":"update","data":[{"symbol":"ETH/USD","bids":[{"price":1773.80,"qty":0.00000000},{"price":1773.70,"qty":28.18950592},{"price":1773.82,"qty":0.05637550}],"asks":[],"checksum":2480411938,"timestamp":"2026-07-07T23:00:04.640084Z"}]}
{"channel":"book","type":"update","data":[{"symbol":"ETH/USD","bids":[],"asks":[{"price":1774.39,"qty":6.21593794}],"checksum":959259907,"timestamp":"2026-07-07T23:00:04.689417Z"}]}
{"channel":"book","type":"update","data":[{"symbol":"ETH/USD","bids":[],"asks":[{"price":1774.37,"qty":0.83017114}],"checksum":206899834,"timestamp":"2026-07-07T23:00:04.689674Z"}]}
{"channel":"book","type":"update","data":[{"symbol":"ETH/USD","bids":[{"price":1773.81,"qty":0.00000000},{"price":1773.70,"qty":28.18950592},{"price":1773.83,"qty":1.68966976}],"asks":[],"checksum":2887830600,"timestamp":"2026-07-07T23:00:04.838760Z"}]}
{"channel":"book","type":"update","data":[{"symbol":"BTC/USD","bids":[],"asks":[{"price":63502.0,"qty":0.00000000},{"price":63507.2,"qty":0.00005100}],"checksum":2713140502,"timestamp":"2026-07-07T23:00:04.852585Z"}]}
{"channel":"book","type":"update","data":[{"symbol":"BTC/USD","bids":[{"price":63501.8,"qty":0.04160000}],"asks":[],"checksum":2313858885,"timestamp":"2026-07-07T23:00:04.854623Z"}]}
{"channel":"book","type":"update","data":[{"symbol":"BTC/USD","bids":[{"price":63501.8,"qty":0.00000000},{"price":63495.8,"qty":0.02713013}],"asks":[],"checksum":2713140502,"timestamp":"2026-07-07T23:00:04.856496Z"}]}
{"channel":"book","type":"update","data":[{"symbol":"ETH/USD","bids":[{"price":1773.82,"qty":0.00000000},{"price":1773.70,"qty":28.18950592}],"asks":[],"checksum":2643234298,"timestamp":"2026-07-07T23:00:04.981552Z"}]}
{"channel":"book","type":"update","data":[{"symbol":"ETH/USD","bids":[{"price":1773.83,"qty":0.00000000},{"price":1773.68,"qty":0.00950074},{"price":1773.79,"qty":1.68966976}],"asks":[],"checksum":1938692714,"timestamp":"2026-07-07T23:00:04.983842Z"}]}
{"channel":"book","type":"update","data":[{"symbol":"ETH/USD","bids":[{"price":1773.79,"qty":1.71220522}],"asks":[],"checksum":3007666177,"timestamp":"2026-07-07T23:00:04.984296Z"}]}
{"channel":"book","type":"update","data":[{"symbol":"ETH/USD","bids":[{"price":1773.79,"qty":0.02253546},{"price":1773.80,"qty":1.68966976}],"asks":[],"checksum":4168615124,"timestamp":"2026-07-07T23:00:05.003730Z"}]}
{"channel":"book","type":"update","data":[{"symbol":"ETH/USD","bids":[{"price":1774.06,"qty":0.33119950}],"asks":[],"checksum":3442797297,"timestamp":"2026-07-07T23:00:05.168085Z"}]}
{"channel":"book","type":"update","data":[{"symbol":"ETH/USD","bids":[{"price":1774.00,"qty":0.00000000},{"price":1773.72,"qty":16.23079170}],"asks":[],"checksum":523285347,"timestamp":"2026-07-07T23:00:05.170443Z"}]}
{"channel":"book","type":"update","data":[{"symbol":"ETH/USD","bids":[{"price":1773.79,"qty":0.03755910}],"asks":[],"checksum":1279753491,"timestamp":"2026-07-07T23:00:05.220952Z"}]}
{"channel":"book","type":"update","data":[{"symbol":"BTC/USD","bids":[],"asks":[{"price":63505.9,"qty":0.00000000},{"price":63508.2,"qty":0.05073037}],"checksum":687679087,"timestamp":"2026-07-07T23:00:05.233871Z"}]}
{"channel":"book","type":"update","data":[{"symbol":"BTC/USD","bids":[],"asks":[{"price":63504.7,"qty":0.00000000},{"price":63508.3,"qty":0.05990000}],"checksum":535012228,"timestamp":"2026-07-07T23:00:05.235267Z"}]}
{"channel":"book","type":"update","data":[{"symbol":"BTC/USD","bids":[],"asks":[{"price":63507.3,"qty":0.78731188}],"checksum":2823975086,"timestamp":"2026-07-07T23:00:05.235359Z"}]}
{"channel":"book","type":"update","data":[{"symbol":"BTC/USD","bids":[],"asks":[{"price":63504.7,"qty":0.23972598}],"checksum":2735993407,"timestamp":"2026-07-07T23:00:05.235473Z"}]}
{"channel":"book","type":"update","data":[{"symbol":"BTC/USD","bids":[],"asks":[{"price":63507.2,"qty":0.28579397}],"checksum":1196232242,"timestamp":"2026-07-07T23:00:05.237003Z"}]}
{"channel":"book","type":"update","data":[{"symbol":"BTC/USD","bids":[{"price":63496.4,"qty":0.00000000},{"price":63495.2,"qty":0.05990000}],"asks":[],"checksum":693340796,"timestamp":"2026-07-07T23:00:05.249636Z"}]}
{"channel":"book","type":"update","data":[{"symbol":"BTC/USD","bids":[{"price":63496.3,"qty":0.03147178}],"asks":[],"checksum":844659555,"timestamp":"2026-07-07T23:00:05.252336Z"}]}
{"channel":"book","type":"update","data":[{"symbol":"BTC/USD","bids":[{"price":63499.0,"qty":0.00000000},{"price":63494.6,"qty":0.00005100}],"asks":[],"checksum":699544223,"timestamp":"2026-07-07T23:00:05.252371Z"}]}
{"channel":"book","type":"update","data":[{"symbol":"BTC/USD","bids":[{"price":63496.3,"qty":0.00000000},{"price":63493.0,"qty":0.23508064},{"price":63495.9,"qty":0.03147178}],"asks":[],"checksum":3357145503,"timestamp":"2026-07-07T23:00:05.254343Z"}]}
{"channel":"book","type":"update","data":[{"symbol":"BTC/USD","bids":[{"price":63495.2,"qty":0.00000000},{"price":63491.4,"qty":0.00005100}],"asks":[],"checksum":698792178,"timestamp":"2026-07-07T23:00:05.255429Z"}]}
{"channel":"book","type":"update","data":[{"symbol":"BTC/USD","bids":[{"price":63495.9,"qty":0.00000000},{"price":63488.5,"qty":0.18049331}],"asks":[],"checksum":99715903,"timestamp":"2026-07-07T23:00:05.256149Z"}]}
{"channel":"book","type":"update","data":[{"symbol":"BTC/USD","bids":[],"asks":[{"price":63501.8,"qty":0.02213082}],"checksum":1057383285,"timestamp":"2026-07-07T23:00:05.256165Z"}]}
{"channel":"book","type":"update","data":[{"symbol":"BTC/USD","bids":[{"price":63488.6,"qty":0.18748506}],"asks":[],"checksum":318157503,"timestamp":"2026-07-07T23:00:05.256520Z"}]}
{"channel":"book","type":"update","data":[{"symbol":"BTC/USD","bids":[{"price":63496.0,"qty":0.03538804}],"asks":[],"checksum":35744012,"timestamp":"2026-07-07T23:00:05.256539Z"}]}
{"channel":"book","type":"update","data":[{"symbol":"BTC/USD","bids":[{"price":63496.0,"qty":0.00000000},{"price":63488.6,"qty":0.18748506}],"asks":[],"checksum":318157503,"timestamp":"2026-07-07T23:00:05.257641Z"}]}
{"channel":"book","type":"update","data":[{"symbol":"BTC/USD","bids":[{"price":63488.6,"qty":0.21895684}],"asks":[],"checksum":3604745035,"timestamp":"2026-07-07T23:00:05.257668Z"}]}
{"channel":"book","type":"update","data":[{"symbol":"BTC/USD","bids":[],"asks":[{"price":63501.9,"qty":0.00095866},{"price":63501.7,"qty":0.00105659}],"checksum":503184712,"timestamp":"2026-07-07T23:00:05.258276Z"}]}
{"channel":"book","type":"update","data":[{"symbol":"BTC/USD","bids":[],"asks":[{"price":63504.8,"qty":0.00000000},{"price":63507.2,"qty":0.28579397}],"checksum":3135157722,"timestamp":"2026-07-07T23:00:05.259804Z"}]}
{"channel":"book","type":"update","data":[{"symbol":"BTC/USD","bids":[],"asks":[{"price":63504.0,"qty":0.78740365}],"checksum":800085851,"timestamp":"2026-07-07T23:00:05.262653Z"}]}
{"channel":"book","type":"update","data":[{"symbol":"BTC/USD","bids":[],"asks":[{"price":63507.2,"qty":0.00005100}],"checksum":1095950571,"timestamp":"2026-07-07T23:00:05.263499Z"}]}
{"channel":"book","type":"update","data":[{"symbol":"BTC/USD","bids":[],"asks":[{"price":63507.2,"qty":0.05078137}],"checksum":2855217087,"timestamp":"2026-07-07T23:00:05.263756Z"}]}
{"channel":"book","type":"update","data":[{"symbol":"BTC/USD","bids":[],"asks":[{"price":63501.8,"qty":0.00000000},{"price":63508.3,"qty":0.05990000}],"checksum":1620866312,"timestamp":"2026-07-07T23:00:05.263813Z"}]}
{"channel":"book","type":"update","data":[{"symbol":"BTC/USD","bids":[],"asks":[{"price":63504.7,"qty":0.00000000},{"price":63508.7,"qty":0.11000000}],"checksum":2704866945,"timestamp":"2026-07-07T23:00:05.263864Z"}]}
{"channel":"book","type":"update","data":[{"symbol":"BTC/USD","bids":[],"asks":[{"price":63502.1,"qty":0.25199741}],"checksum":3023695375,"timestamp":"2026-07-07T23:00:05.265705Z"}]}
{"channel":"book","type":"update","data":[{"symbol":"BTC/USD","bids":[],"asks":[{"price":63501.7,"qty":0.00000000},{"price":63510.3,"qty":0.00005100},{"price":63502.0,"qty":0.00105659}],"checksum":1079929543,"timestamp":"2026-07-07T23:00:05.265861Z"}]}
{"channel":"book","type":"update","data":[{"symbol":"ETH/USD","bids":[{"price":1773.79,"qty":0.01502364}],"asks":[],"checksum":1699907647,"timestamp":"2026-07-07T23:00:05.268122Z"}]}
{"channel":"book","type":"update","data":[{"symbol":"ETH/USD","bids":[],"asks":[{"price":1774.18,"qty":0.00000000},{"price":1774.44,"qty":1.83004268}],"checksum":4195039887,"timestamp":"2026-07-07T23:00:05.268285Z"}]}
{"channel":"book","type":"update","data":[{"symbol":"ETH/USD","bids":[{"price":1773.79,"qty":0.00000000},{"price":1773.70,"qty":28.18950592}],"asks":[],"checksum":591460648,"timestamp":"2026-07-07T23:00:05.268366Z"}]}
{"channel":"book","type":"update","data":[{"symbol":"ETH/USD","bids":[{"price":1773.80,"qty":0.00000000},{"price":1773.68,"qty":0.00950074},{"price":1773.79,"qty":1.68966976}],"asks":[],"checksum":1627838496,"timestamp":"2026-07-07T23:00:05.270684Z"}]}
{"channel":"book","type":"update","data":[{"symbol":"BTC/USD","bids":[{"price":63495.2,"qty":0.05990000}],"asks":[],"checksum":103743286,"timestamp":"2026-07-07T23:00:05.298424Z"}]}
{"channel":"book","type":"update","data":[{"symbol":"ETH/USD","bids":[],"asks":[{"price":1774.32,"qty":0.00000000},{"price":1774.45,"qty":2.87402415}],"checksum":1315985925,"timestamp":"2026-07-07T23:00:05.313844Z"}]}
{"channel":"book","type":"update","data":[{"symbol":"ETH/USD","bids":[{"price":1773.77,"qty":0.00000000},{"price":1773.68,"qty":0.00950074}],"asks":[],"checksum":1194042170,"timestamp":"2026-07-07T23:00:05.318506Z"}]}
{"channel":"book","type":"update","data":[{"symbol":"ETH/USD","bids":[{"price":1773.72,"qty":7.66925781}],"asks":[],"checksum":3606903730,"timestamp":"2026-07-07T23:00:05.318533Z"}]}
{"channel":"book","type":"update","data":[{"symbol":"ETH/USD","bids":[{"price":1774.06,"qty":0.00000000},{"price":1773.67,"qty":18.24200000}],"asks":[],"checksum":3764906541,"timestamp":"2026-07-07T23:00:05.318578Z"}]}
{"channel":"book","type":"update","data":[{"symbol":"ETH/USD","bids":[{"price":1773.72,"qty":0.00000000},{"price":1773.66,"qty":0.48930000}],"asks":[],"checksum":1307332096,"timestamp":"2026-07-07T23:00:05.318607Z"}]}
{"channel":"book","type":"update","data":[{"symbol":"BTC/USD","bids":[{"price":63499.7,"qty":0.00000000},{"price":63488.6,"qty":0.21895684}],"asks":[],"checksum":2593293414,"timestamp":"2026-07-07T23:00:05.318624Z"}]}
{"channel":"book","type":"update","data":[{"symbol":"ETH/USD","bids":[],"asks":[{"price":1774.25,"qty":0.00000000},{"price":1774.48,"qty":12.35426731}],"checksum":3278282104,"timestamp":"2026-07-07T23:00:05.319385Z"}]}
{"channel":"book","type":"update","data":[{"symbol":"ETH/USD","bids":[],"asks":[{"price":1774.14,"qty":2.31657153}],"checksum":2730182251,"timestamp":"2026-07-07T23:00:05.319484Z"}]}
{"channel":"book","type":"update","data":[{"symbol":"BTC/USD","bids":[],"asks":[{"price":63504.0,"qty":0.00005100}],"checksum":1562475839,"timestamp":"2026-07-07T23:00:05.319512Z"}]}
{"channel":"book","type":"update","data":[{"symbol":"ETH/USD","bids":[],"asks":[{"price":1774.19,"qty":0.93577491}],"checksum":4245680557,"timestamp":"2026-07-07T23:00:05.320445Z"}]}
{"channel":"book","type":"update","data":[{"symbol":"ETH/USD","bids":[{"price":1773.75,"qty":0.00000000},{"price":1773.61,"qty":1.30000000}],"asks":[],"checksum":102425487,"timestamp":"2026-07-07T23:00:05.320545Z"}]}
{"channel":"book","type":"update","data":[{"symbol":"ETH/USD","bids":[{"price":1773.78,"qty":5.56003448}],"asks":[],"checksum":1811926949,"timestamp":"2026-07-07T23:00:05.320893Z"}]}
{"channel":"book","type":"update","data":[{"symbol":"BTC/USD","bids":[{"price":63495.8,"qty":0.00000000},{"price":63488.4,"qty":0.60466770}],"asks":[],"checksum":1002608538,"timestamp":"2026-07-07T23:00:05.320930Z"}]}
{"channel":"book","type":"update","data":[{"symbol":"ETH/USD","bids":[{"price":1773.67,"qty":0.00000000},{"price":1773.48,"qty":0.48930000}],"asks":[],"checksum":3096767640,"timestamp":"2026-07-07T23:00:05.321038Z"}]}
{"channel":"book","type":"update","data":[{"symbol":"BTC/USD","bids":[{"price":63498.1,"qty":0.00157485}],"asks":[],"checksum":3714930587,"timestamp":"2026-07-07T23:00:05.321185Z"}]}
{"channel":"book","type":"update","data":[{"symbol":"BTC/USD","bids":[{"price":63495.2,"qty":0.00000000},{"price":63488.4,"qty":0.60466770}],"asks":[],"checksum":4015734843,"timestamp":"2026-07-07T23:00:05.322131Z"}]}
{"channel":"book","type":"update","data":[{"symbol":"BTC/USD","bids":[],"asks":[{"price":63502.1,"qty":0.01946065}],"checksum":1343364730,"timestamp":"2026-07-07T23:00:05.322459Z"}]}
{"channel":"book","type":"update","data":[{"symbol":"ETH/USD","bids":[],"asks":[{"price":1774.32,"qty":0.48930000}],"checksum":3771771677,"timestamp":"2026-07-07T23:00:05.322942Z"}]}
{"channel":"book","type":"update","data":[{"symbol":"BTC/USD","bids":[{"price":63490.8,"qty":0.02713013}],"asks":[],"checksum":2621661005,"timestamp":"2026-07-07T23:00:05.323029Z"}]}
{"channel":"book","type":"update","data":[{"symbol":"ETH/USD","bids":[{"price":1773.55,"qty":0.45737557}],"asks":[],"checksum":3717184624,"timestamp":"2026-07-07T23:00:05.323280Z"}]}
{"channel":"book","type":"update","data":[{"symbol":"ETH/USD","bids":[{"price":1773.78,"qty":0.00000000},{"price":1773.48,"qty":0.48930000}],"asks":[],"checksum":3329121973,"timestamp":"2026-07-07T23:00:05.323719Z"}]}
{"channel":"book","type":"update","data":[{"symbol":"BTC/USD","bids":[],"asks":[{"price":63501.7,"qty":0.05990000}],"checksum":823702784,"timestamp":"2026-07-07T23:00:05.323887Z"}]}
{"channel":"book","type":"update","data":[{"symbol":"ETH/USD","bids":[],"asks":[{"price":1774.14,"qty":2.80587153}],"checksum":4264667768,"timestamp":"2026-07-07T23:00:05.324225Z"}]}
{"channel":"book","type":"update","data":[{"symbol":"ETH/USD","bids":[{"price":1773.89,"qty":0.00000000},{"price":1773.46,"qty":5.59759358}],"asks":[],"checksum":3173039601,"timestamp":"2026-07-07T23:00:05.324288Z"}]}
{"channel":"book","type":"update","data":[{"symbol":"ETH/USD","bids":[{"price":1773.70,"qty":0.00000000},{"price":1773.45,"qty":23.18944540}],"asks":[],"checksum":1174070503,"timestamp":"2026-07-07T23:00:05.325198Z"}]}
{"channel":"book","type":"update","data":[{"symbol":"BTC/USD","bids":[],"asks":[{"price":63506.4,"qty":0.00000000},{"price":63508.7,"qty":0.11000000}],"checksum":1695915844,"timestamp":"2026-07-07T23:00:05.326480Z"}]}
{"channel":"book","type":"update","data":[{"symbol":"ETH/USD","bids":[],"asks":[{"price":1774.40,"qty":43.33854910}],"checksum":3622638607,"timestamp":"2026-07-07T23:00:05.326492Z"}]}
{"channel":"book","type":"update","data":[{"symbol":"ETH/USD","bids":[{"price":1773.95,"qty":0.00000000},{"price":1773.43,"qty":2.87402415}],"asks":[],"checksum":734219592,"timestamp":"2026-07-07T23:00:05.327804Z"}]}
{"channel":"book","type":"update","data":[{"symbol":"ETH/USD","bids":[],"asks":[{"price":1774.40,"qty":15.16000000}],"checksum":3174351983,"timestamp":"2026-07-07T23:00:05.328330Z"}]}
{"channel":"book","type":"update","data":[{"symbol":"ETH/USD","bids":[],"asks":[{"price":1774.14,"qty":4.10587153}],"checksum":1428611633,"timestamp":"2026-07-07T23:00:05.328784Z"}]}
{"channel":"book","type":"update","data":[{"symbol":"ETH/USD","bids":[{"price":1773.47,"qty":1.67088168}],"asks":[],"checksum":552204936,"timestamp":"2026-07-07T23:00:05.329251Z"}]}
{"channel":"book","type":"update","data":[{"symbol":"BTC/USD","bids":[{"price":63488.6,"qty":0.03147178}],"asks":[],"checksum":929495633,"timestamp":"2026-07-07T23:00:05.329649Z"}]}
{"channel":"book","type":"update","data":[{"symbol":"ETH/USD","bids":[],"asks":[{"price":1774.20,"qty":0.00000000},{"price":1774.45,"qty":2.87402415}],"checksum":251655788,"timestamp":"2026-07-07T23:00:05.329680Z"}]}
{"channel":"book","type":"update","data":[{"symbol":"BTC/USD","bids":[],"asks":[{"price":63501.7,"qty":0.07006651}],"checksum":3073262673,"timestamp":"2026-07-07T23:00:05.330205Z"}]}
{"channel":"book","type":"update","data":[{"symbol":"ETH/USD","bids":[{"price":1773.45,"qty":24.66504533}],"asks":[],"checksum":1684949031,"timestamp":"2026-07-07T23:00:05.335366Z"}]}
{"channel":"book","type":"update","data":[{"symbol":"ETH/USD","bids":[{"price":1773.79,"qty":0.00000000},{"price":1773.43,"qty":2.87402415}],"asks":[],"checksum":3188529824,"timestamp":"2026-07-07T23:00:05.336290Z"}]}
{"channel":"book","type":"update","data":[{"symbol":"BTC/USD","bids":[{"price":63488.6,"qty":0.00000000},{"price":63487.1,"qty":0.01000000}],"asks":[],"checksum":379497134,"timestamp":"2026-07-07T23:00:05.336453Z"}]}
{"channel":"book","type":"update","data":[{"symbol":"ETH/USD","bids":[],"asks":[{"price":1774.38,"qty":5.10831691}],"checksum":3382543239,"timestamp":"2026-07-07T23:00:05.337405Z"}]}
{"channel":"book","type":"update","data":[{"symbol":"BTC/USD","bids":[{"price":63490.8,"qty":0.00000000},{"price":63486.5,"qty":0.18748506}],"asks":[],"checksum":3341246355,"timestamp":"2026-07-07T23:00:05.337420Z"}]}
{"channel":"book","type":"update","data":[{"symbol":"ETH/USD","bids":[],"asks":[{"price":1774.44,"qty":5.28382412}],"checksum":3788923889,"timestamp":"2026-07-07T23:00:05.340275Z"}]}
{"channel":"book","type":"update","data":[{"symbol":"ETH/USD","bids":[{"price":1773.45,"qty":1.47559993}],"asks":[],"checksum":345312255,"timestamp":"2026-07-07T23:00:05.340620Z"}]}
{"channel":"book","type":"update","data":[{"symbol":"ETH/USD","bids":[],"asks":[{"price":1774.19,"qty":13.29004222}],"checksum":2577837266,"timestamp":"2026-07-07T23:00:05.341221Z"}]}
{"channel":"book","type":"update","data":[{"symbol":"ETH/USD","bids":[{"price":1773.62,"qty":1.68966976}],"asks":[],"checksum":3454788208,"timestamp":"2026-07-07T23:00:05.341576Z"}]}
{"channel":"book","type":"update","data":[{"symbol":"ETH/USD","bids":[],"asks":[{"price":1774.19,"qty":12.35426731}],"checksum":1356993690,"timestamp":"2026-07-07T23:00:05.341698Z"}]}
{"channel":"book","type":"update","data":[{"symbol":"BTC/USD","bids":[],"asks":[{"price":63507.1,"qty":0.60470924}],"checksum":3050308444,"timestamp":"2026-07-07T23:00:05.342067Z"}]}
{"channel":"book","type":"update","data":[{"symbol":"BTC/USD","bids":[],"asks":[{"price":63507.1,"qty":0.00000000},{"price":63508.7,"qty":0.11000000}],"checksum":3341246355,"timestamp":"2026-07-07T23:00:05.344632Z"}]}
{"channel":"book","type":"update","data":[{"symbol":"ETH/USD","bids":[],"asks":[{"price":1774.44,"qty":1.83004268}],"checksum":431684770,"timestamp":"2026-07-07T23:00:05.344899Z"}]}
{"channel":"book","type":"update","data":[{"symbol":"ETH/USD","bids":[],"asks":[{"price":1774.18,"qty":3.68774879}],"checksum":4196494964,"timestamp":"2026-07-07T23:00:05.346134Z"}]}
{"channel":"book","type":"update","data":[{"symbol":"BTC/USD","bids":[],"asks":[{"price":63507.0,"qty":0.18052093}],"checksum":3175396459,"timestamp":"2026-07-07T23:00:05.346336Z"}]}
{"channel":"book","type":"update","data":[{"symbol":"ETH/USD","bids":[],"asks":[{"price":1774.34,"qty":19.84616104}],"checksum":1651192221,"timestamp":"2026-07-07T23:00:05.347051Z"}]}
{"channel":"book","type":"update","data":[{"symbol":"BTC/USD","bids":[],"asks":[{"price":63502.1,"qty":0.62416989}],"checksum":2606040247,"timestamp":"2026-07-07T23:00:05.347884Z"}]}
{"channel":"book","type":"update","data":[{"symbol":"ETH/USD","bids":[{"price":1773.46,"qty":0.03755910}],"asks":[],"checksum":3515199093,"timestamp":"2026-07-07T23:00:05.348581Z"}]}
{"channel":"book","type":"update","data":[{"symbol":"BTC/USD","bids":[],"asks":[{"price":63507.0,"qty":0.00000000},{"price":63508.7,"qty":0.11000000}],"checksum":3778473807,"timestamp":"2026-07-07T23:00:05.348853Z"}]}
{"channel":"book","type":"update","data":[{"symbol":"ETH/USD","bids":[{"price":1774.13,"qty":1.13309580}],"asks":[],"checksum":2329518309,"timestamp":"2026-07-07T23:00:05.350499Z"}]}
{"channel":"book","type":"update","data":[{"symbol":"ETH/USD","bids":[{"price":1773.47,"qty":0.00000000},{"price":1773.43,"qty":2.87402415}],"asks":[],"checksum":2288401132,"timestamp":"2026-07-07T23:00:05.352346Z"}]}
{"channel":"book","type":"update","data":[{"symbol":"ETH/USD","bids":[],"asks":[{"price":1774.33,"qty":5.92407907}],"checksum":2111618349,"timestamp":"2026-07-07T23:00:05.356088Z"}]}
{"channel":"book","type":"update","data":[{"symbol":"BTC/USD","bids":[{"price":63486.5,"qty":0.00000000},{"price":63485.7,"qty":0.00126168}],"asks":[],"checksum":3348308267,"timestamp":"2026-07-07T23:00:05.357966Z"}]}
{"channel":"book","type":"update","data":[{"symbol":"ETH/USD","bids":[{"price":1773.62,"qty":0.00000000},{"price":1773.37,"qty":2.06935921}],"asks":[],"checksum":2245213614,"timestamp":"2026-07-07T23:00:05.361163Z"}]}
{"channel":"book","type":"update","data":[{"symbol":"ETH/USD","bids":[{"price":1773.46,"qty":0.01502364}],"asks":[],"checksum":1453225648,"timestamp":"2026-07-07T23:00:05.364110Z"}]}
{"channel":"book","type":"update","data":[{"symbol":"ETH/USD","bids":[{"price":1773.46,"qty":0.00000000},{"price":1773.28,"qty":0.68579542}],"asks":[],"checksum":3258500557,"timestamp":"2026-07-07T23:00:05.364664Z"}]}
{"channel":"book","type":"update","data":[{"symbol":"ETH/USD","bids":[],"asks":[{"price":1774.37,"qty":0.50000000}],"checksum":552805957,"timestamp":"2026-07-07T23:00:05.368282Z"}]}
{"channel":"book","type":"update","data":[{"symbol":"BTC/USD","bids":[{"price":63485.7,"qty":0.00000000},{"price":63485.4,"qty":0.02713013}],"asks":[],"checksum":3815095127,"timestamp":"2026-07-07T23:00:05.369864Z"}]}
{"channel":"book","type":"update","data":[{"symbol":"ETH/USD","bids":[],"asks":[{"price":1774.17,"qty":2.81822987}],"checksum":1655190948,"timestamp":"2026-07-07T23:00:05.370749Z"}]}
{"channel":"book","type":"update","data":[{"symbol":"ETH/USD","bids":[],"asks":[{"price":1774.25,"qty":28.18099544}],"checksum":2088336898,"timestamp":"2026-07-07T23:00:05.371011Z"}]}
{"channel":"book","type":"update","data":[{"symbol":"ETH/USD","bids":[{"price":1773.63,"qty":2.81906683}],"asks":[],"checksum":1424508270,"timestamp":"2026-07-07T23:00:05.371783Z"}]}
{"channel":"book","type":"update","data":[{"symbol":"ETH/USD","bids":[{"price":1773.45,"qty":29.66911883}],"asks":[],"checksum":2504627097,"timestamp":"2026-07-07T23:00:05.372310Z"}]}
{"channel":"book","type":"update","data":[{"symbol":"BTC/USD","bids":[],"asks":[{"price":63502.1,"qty":0.60470924}],"checksum":564349252,"timestamp":"2026-07-07T23:00:05.374442Z"}]}
{"channel":"book","type":"update","data":[{"symbol":"BTC/USD","bids":[],"asks":[{"price":63501.7,"qty":0.18006651}],"checksum":614894664,"timestamp":"2026-07-07T23:00:05.374519Z"}]}
{"channel":"book","type":"update","data":[{"symbol":"ETH/USD","bids":[{"price":1773.66,"qty":0.00000000},{"price":1773.28,"qty":0.68579542}],"asks":[],"checksum":441907381,"timestamp":"2026-07-07T23:00:05.375822Z"}]}
{"channel":"book","type":"update","data":[{"symbol":"BTC/USD","bids":[],"asks":[{"price":63502.0,"qty":0.20102295}],"checksum":3370355820,"timestamp":"2026-07-07T23:00:05.380556Z"}]}
{"channel":"book","type":"update","data":[{"symbol":"BTC/USD","bids":[],"asks":[{"price":63501.7,"qty":0.27398616}],"checksum":918031026,"timestamp":"2026-07-07T23:00:05.384579Z"}]}
{"channel":"book","type":"update","data":[{"symbol":"ETH/USD","bids":[],"asks":[{"price":1774.34,"qty":0.00000000},{"price":1774.39,"qty":6.21593794}],"checksum":1703307078,"timestamp":"2026-07-07T23:00:05.384620Z"}]}
{"channel":"book","type":"update","data":[{"symbol":"ETH/USD","bids":[],"asks":[{"price":1774.18,"qty":11.62830452}],"checksum":2964346122,"timestamp":"2026-07-07T23:00:05.386511Z"}]}
{"channel":"book","type":"update","data":[{"symbol":"ETH/USD","bids":[{"price":1773.42,"qty":50.73988004}],"asks":[],"checksum":1817062389,"timestamp":"2026-07-07T23:00:05.389217Z"}]}
{"channel":"book","type":"update","data":[{"symbol":"ETH/USD","bids":[{"price":1773.45,"qty":28.19351890}],"asks":[],"checksum":2589424294,"timestamp":"2026-07-07T23:00:05.389532Z"}]}
{"channel":"book","type":"update","data":[{"symbol":"ETH/USD","bids":[],"asks":[{"price":1774.33,"qty":0.00000000},{"price":1774.40,"qty":15.16000000}],"checksum":4052730857,"timestamp":"2026-07-07T23:00:05.392641Z"}]}
{"channel":"book","type":"update","data":[{"symbol":"ETH/USD","bids":[{"price":1773.46,"qty":0.02253546}],"asks":[],"checksum":3075329212,"timestamp":"2026-07-07T23:00:05.392917Z"}]}
{"channel":"book","type":"update","data":[{"symbol":"ETH/USD","bids":[],"asks":[{"price":1774.19,"qty":0.00000000},{"price":1774.41,"qty":1.30000000},{"price":1774.31,"qty":12.35426731}],"checksum":2207223438,"timestamp":"2026-07-07T23:00:05.393985Z"}]}
{"channel":"book","type":"update","data":[{"symbol":"ETH/USD","bids":[{"price":1773.46,"qty":0.00000000},{"price":1773.37,"qty":2.06935921}],"asks":[],"checksum":2217575398,"timestamp":"2026-07-07T23:00:05.394417Z"}]}
{"channel":"book","type":"update","data":[{"symbol":"ETH/USD","bids":[{"price":1773.42,"qty":0.00000000},{"price":1773.28,"qty":0.68579542}],"asks":[],"checksum":2002371616,"timestamp":"2026-07-07T23:00:05.401749Z"}]}
{"channel":"book","type":"update","data":[{"symbol":"BTC/USD","bids":[],"asks":[{"price":63501.7,"qty":1.06136665}],"checksum":135369959,"timestamp":"2026-07-07T23:00:05.403062Z"}]}
{"channel":"book","type":"update","data":[{"symbol":"BTC/USD","bids":[{"price":63485.4,"qty":0.00000000},{"price":63484.3,"qty":0.54650000}],"asks":[],"checksum":3264827633,"timestamp":"2026-07-07T23:00:05.406757Z"}]}
{"channel":"book","type":"update","data":[{"symbol":"ETH/USD","bids":[{"price":1773.43,"qty":5.26200267}],"asks":[],"checksum":1246590997,"timestamp":"2026-07-07T23:00:05.407221Z"}]}
{"channel":"book","type":"update","data":[{"symbol":"ETH/USD","bids":[{"price":1773.43,"qty":2.87402415}],"asks":[],"checksum":2002371616,"timestamp":"2026-07-07T23:00:05.407723Z"}]}
{"channel":"book","type":"update","data":[{"symbol":"ETH/USD","bids":[{"price":1773.44,"qty":1.47559993}],"asks":[],"checksum":2199207456,"timestamp":"2026-07-07T23:00:05.410425Z"}]}
{"channel":"book","type":"update","data":[{"symbol":"ETH/USD","bids":[],"asks":[{"price":1774.39,"qty":56.95738474}],"checksum":4248352252,"timestamp":"2026-07-07T23:00:05.411484Z"}]}
{"channel":"book","type":"update","data":[{"symbol":"ETH/USD","bids":[],"asks":[{"price":1774.18,"qty":3.68774879}],"checksum":2792489061,"timestamp":"2026-07-07T23:00:05.411557Z"}]}
{"channel":"book","type":"update","data":[{"symbol":"ETH/USD","bids":[],"asks":[{"price":1774.18,"qty":0.00000000},{"price":1774.41,"qty":1.30000000}],"checksum":2663425065,"timestamp":"2026-07-07T23:00:05.411652Z"}]}
{"channel":"book","type":"update","data":[{"symbol":"BTC/USD","bids":[{"price":63484.3,"qty":0.00000000},{"price":63481.8,"qty":0.40000000}],"asks":[],"checksum":2159627656,"timestamp":"2026-07-07T23:00:05.414586Z"}]}
{"channel":"book","type":"update","data":[{"symbol":"ETH/USD","bids":[{"price":1773.63,"qty":0.00000000},{"price":1773.28,"qty":0.68579542}],"asks":[],"checksum":3069202478,"timestamp":"2026-07-07T23:00:05.414770Z"}]}
{"channel":"book","type":"update","data":[{"symbol":"ETH/USD","bids":[{"price":1773.45,"qty":0.00000000},{"price":1773.27,"qty":2.29747210}],"asks":[],"checksum":3588248819,"timestamp":"2026-07-07T23:00:05.415204Z"}]}
{"channel":"book","type":"update","data":[{"symbol":"BTC/USD","bids":[],"asks":[{"price":63507.5,"qty":0.60470924}],"checksum":1864344047,"timestamp":"2026-07-07T23:00:05.415795Z"}]}
{"channel":"book","type":"update","data":[{"symbol":"ETH/USD","bids":[],"asks":[{"price":1774.38,"qty":21.26200110}],"checksum":1373101268,"timestamp":"2026-07-07T23:00:05.416169Z"}]}
{"channel":"book","type":"update","data":[{"symbol":"ETH/USD","bids":[{"price":1773.44,"qty":0.00000000},{"price":1773.22,"qty":0.48930000}],"asks":[],"checksum":965845422,"timestamp":"2026-07-07T23:00:05.416375Z"}]}
{"channel":"book","type":"update","data":[{"symbol":"BTC/USD","bids":[],"asks":[{"price":63501.7,"qty":2.82456265}],"checksum":3620998280,"timestamp":"2026-07-07T23:00:05.418150Z"}]}
{"channel":"book","type":"update","data":[{"symbol":"ETH/USD","bids":[],"asks":[{"price":1774.30,"qty":3.83380484}],"checksum":4148085419,"timestamp":"2026-07-07T23:00:05.418510Z"}]}
{"channel":"book","type":"update","data":[{"symbol":"BTC/USD","bids":[],"asks":[{"price":63502.0,"qty":0.19996636},{"price":63501.7,"qty":2.82558694}],"checksum":813145527,"timestamp":"2026-07-07T23:00:05.419120Z"}]}
{"channel":"book","type":"update","data":[{"symbol":"ETH/USD","bids":[{"price":1773.75,"qty":0.32908293}],"asks":[],"checksum":3832446162,"timestamp":"2026-07-07T23:00:05.419619Z"}]}
{"channel":"book","type":"update","data":[{"symbol":"ETH/USD","bids":[],"asks":[{"price":1774.14,"qty":4.44528648}],"checksum":1136492276,"timestamp":"2026-07-07T23:00:05.419773Z"}]}
{"channel":"book","type":"update","data":[{"symbol":"BTC/USD","bids":[{"price":63481.9,"qty":0.15223500}],"asks":[],"checksum":513947481,"timestamp":"2026-07-07T23:00:05.424013Z"}]}
{"channel":"book","type":"update","data":[{"symbol":"ETH/USD","bids":[{"price":1773.49,"qty":28.19034629}],"asks":[],"checksum":397346138,"timestamp":"2026-07-07T23:00:05.426296Z"}]}
{"channel":"book","type":"update","data":[{"symbol":"BTC/USD","bids":[{"price":63498.1,"qty":0.00000000},{"price":63481.8,"qty":0.40000000}],"asks":[],"checksum":2006833030,"timestamp":"2026-07-07T23:00:05.428639Z"}]}
{"channel":"book","type":"update","data":[{"symbol":"ETH/USD","bids":[{"price":1773.44,"qty":1.47559993}],"asks":[],"checksum":866472131,"timestamp":"2026-07-07T23:00:05.429596Z"}]}
{"channel":"book","type":"update","data":[{"symbol":"BTC/USD","bids":[],"asks":[{"price":63507.2,"qty":0.22480130}],"checksum":466850981,"timestamp":"2026-07-07T23:00:05.429982Z"}]}
{"channel":"book","type":"update","data":[{"symbol":"ETH/USD","bids":[],"asks":[{"price":1774.18,"qty":7.94055572}],"checksum":1645051380,"timestamp":"2026-07-07T23:00:05.436738Z"}]}
{"channel":"book","type":"update","data":[{"symbol":"ETH/USD","bids":[{"price":1773.46,"qty":7.00404691}],"asks":[],"checksum":1196309141,"timestamp":"2026-07-07T23:00:05.437686Z"}]}
{"channel":"book","type":"update","data":[{"symbol":"ETH/USD","bids":[],"asks":[{"price":1774.31,"qty":0.00000000},{"price":1774.40,"qty":15.16000000},{"price":1774.14,"qty":16.79955379}],"checksum":2330008353,"timestamp":"2026-07-07T23:00:05.438132Z"}]}
{"channel":"book","type":"update","data":[{"symbol":"ETH/USD","bids":[{"price":1773.46,"qty":0.00000000},{"price":1773.37,"qty":2.06935921}],"asks":[],"checksum":2946653248,"timestamp":"2026-07-07T23:00:05.438835Z"}]}
{"channel":"book","type":"update","data":[{"symbol":"BTC/USD","bids":[],"asks":[{"price":63503.9,"qty":2.36267944}],"checksum":1145337102,"timestamp":"2026-07-07T23:00:05.442520Z"}]}
{"channel":"book","type":"update","data":[{"symbol":"ETH/USD","bids":[],"asks":[{"price":1774.30,"qty":0.00000000},{"price":1774.44,"qty":28.30001358}],"checksum":3141095668,"timestamp":"2026-07-07T23:00:05.442686Z"}]}
{"channel":"book","type":"update","data":[{"symbol":"ETH/USD","bids":[{"price":1773.49,"qty":0.00000000},{"price":1773.28,"qty":0.68579542},{"price":1773.39,"qty":28.18988385}],"asks":[],"checksum":4112580018,"timestamp":"2026-07-07T23:00:05.446581Z"}]}
{"channel":"book","type":"update","data":[{"symbol":"ETH/USD","bids":[{"price":1773.50,"qty":5.56003448}],"asks":[],"checksum":3950110329,"timestamp":"2026-07-07T23:00:05.447125Z"}]}
{"channel":"book","type":"update","data":[{"symbol":"BTC/USD","bids":[],"asks":[{"price":63502.0,"qty":0.87966087}],"checksum":3575894134,"timestamp":"2026-07-07T23:00:05.447528Z"}]}
{"channel":"book","type":"update","data":[{"symbol":"ETH/USD","bids":[{"price":1773.44,"qty":7.25371212}],"asks":[],"checksum":2195901741,"timestamp":"2026-07-07T23:00:05.451130Z"}]}
{"channel":"book","type":"update","data":[{"symbol":"ETH/USD","bids":[{"price":1773.47,"qty":2.81932626}],"asks":[],"checksum":71344623,"timestamp":"2026-07-07T23:00:05.451195Z"}]}
{"channel":"book","type":"update","data":[{"symbol":"ETH/USD","bids":[{"price":1773.44,"qty":1.47559993}],"asks":[],"checksum":4145712107,"timestamp":"2026-07-07T23:00:05.451429Z"}]}
{"channel":"book","type":"update","data":[{"symbol":"ETH/USD","bids":[{"price":1773.44,"qty":0.00000000},{"price":1773.39,"qty":28.18988385}],"asks":[],"checksum":3426163437,"timestamp":"2026-07-07T23:00:05.451560Z"}]}
{"channel":"book","type":"update","data":[{"symbol":"BTC/USD","bids":[{"price":63481.8,"qty":0.00000000},{"price":63481.5,"qty":0.00030000}],"asks":[],"checksum":1270425437,"timestamp":"2026-07-07T23:00:05.453045Z"}]}
{"channel":"book","type":"update","data":[{"symbol":"BTC/USD","bids":[],"asks":[{"price":63503.9,"qty":0.00000000},{"price":63508.3,"qty":0.05990000}],"checksum":2870858088,"timestamp":"2026-07-07T23:00:05.454023Z"}]}
{"channel":"book","type":"update","data":[{"symbol":"ETH/USD","bids":[{"price":1773.40,"qty":9.03238405}],"asks":[],"checksum":2427146098,"timestamp":"2026-07-07T23:00:05.455477Z"}]}
{"channel":"book","type":"update","data":[{"symbol":"ETH/USD","bids":[{"price":1773.47,"qty":0.00000000},{"price":1773.39,"qty":28.18988385}],"asks":[],"checksum":1157251918,"timestamp":"2026-07-07T23:00:05.457951Z"}]}
{"channel":"book","type":"update","data":[{"symbol":"BTC/USD","bids":[{"price":63481.9,"qty":0.00000000},{"price":63481.4,"qty":0.00821373}],"asks":[],"checksum":2967545692,"timestamp":"2026-07-07T23:00:05.458553Z"}]}
{"channel":"book","type":"update","data":[{"symbol":"BTC/USD","bids":[],"asks":[{"price":63506.6,"qty":0.40000000}],"checksum":2160344088,"timestamp":"2026-07-07T23:00:05.458590Z"}]}
{"channel":"book","type":"update","data":[{"symbol":"BTC/USD","bids":[],"asks":[{"price":63502.0,"qty":0.19996636}],"checksum":1599573689,"timestamp":"2026-07-07T23:00:05.460167Z"}]}
{"channel":"book","type":"update","data":[{"symbol":"BTC/USD","bids":[],"asks":[{"price":63506.5,"qty":0.11941522}],"checksum":2190083178,"timestamp":"2026-07-07T23:00:05.464128Z"}]}
{"channel":"book","type":"update","data":[{"symbol":"ETH/USD","bids":[{"price":1773.75,"qty":0.00000000},{"price":1773.37,"qty":2.06935921}],"asks":[],"checksum":2059272365,"timestamp":"2026-07-07T23:00:05.465332Z"}]}
{"channel":"book","type":"update","data":[{"symbol":"ETH/USD","bids":[{"price":1773.61,"qty":0.00000000},{"price":1773.28,"qty":0.68579542}],"asks":[],"checksum":2416376897,"timestamp":"2026-07-07T23:00:05.465435Z"}]}
{"channel":"book","type":"update","data":[{"symbol":"ETH/USD","bids":[{"price":1773.43,"qty":0.00000000},{"price":1773.27,"qty":2.29747210}],"asks":[],"checksum":1890969180,"timestamp":"2026-07-07T23:00:05.465748Z"}]}
{"channel":"book","type":"update","data":[{"symbol":"ETH/USD","bids":[{"price":1773.34,"qty":19.84616104}],"asks":[],"checksum":3267339606,"timestamp":"2026-07-07T23:00:05.465935Z"}]}
{"channel":"book","type":"update","data":[{"symbol":"ETH/USD","bids":[],"asks":[{"price":1774.24,"qty":0.28137208}],"checksum":1834744654,"timestamp":"2026-07-07T23:00:05.467579Z"}]}
{"channel":"book","type":"update","data":[{"symbol":"ETH/USD","bids":[{"price":1773.50,"qty":0.00000000},{"price":1773.27,"qty":2.29747210},{"price":1773.40,"qty":14.59241853}],"asks":[],"checksum":502490600,"timestamp":"2026-07-07T23:00:05.471565Z"}]}
{"channel":"book","type":"update","data":[{"symbol":"ETH/USD","bids":[{"price":1773.39,"qty":0.00000000},{"price":1773.25,"qty":5.28085305},{"price":1773.28,"qty":28.87562629}],"asks":[],"checksum":3399012911,"timestamp":"2026-07-07T23:00:05.471915Z"}]}
{"channel":"book","type":"update","data":[{"symbol":"ETH/USD","bids":[],"asks":[{"price":1774.14,"qty":19.67357794}],"checksum":2817646179,"timestamp":"2026-07-07T23:00:05.473662Z"}]}
{"channel":"book","type":"update","data":[{"symbol":"ETH/USD","bids":[{"price":1773.68,"qty":0.00000000},{"price":1773.24,"qty":17.20200000}],"asks":[],"checksum":997984997,"timestamp":"2026-07-07T23:00:05.475670Z"}]}
{"channel":"book","type":"update","data":[{"symbol":"ETH/USD","bids":[{"price":1773.55,"qty":0.00000000},{"price":1773.22,"qty":0.48930000}],"asks":[],"checksum":342308642,"timestamp":"2026-07-07T23:00:05.478094Z"}]}
{"channel":"book","type":"update","data":[{"symbol":"ETH/USD","bids":[{"price":1773.28,"qty":28.18983087}],"asks":[],"checksum":3268352763,"timestamp":"2026-07-07T23:00:05.481212Z"}]}
{"channel":"book","type":"update","data":[{"symbol":"ETH/USD","bids":[{"price":1773.35,"qty":3.16892940}],"asks":[],"checksum":534454164,"timestamp":"2026-07-07T23:00:05.482659Z"}]}
{"channel":"book","type":"update","data":[{"symbol":"BTC/USD","bids":[{"price":63501.6,"qty":0.03107481}],"asks":[],"checksum":1437487406,"timestamp":"2026-07-07T23:00:05.484908Z"}]}
{"channel":"book","type":"update","data":[{"symbol":"ETH/USD","bids":[],"asks":[{"price":1774.14,"qty":39.51973898}],"checksum":1387254978,"timestamp":"2026-07-07T23:00:05.488009Z"}]}
{"channel":"book","type":"update","data":[{"symbol":"ETH/USD","bids":[],"asks":[{"price":1774.39,"qty":6.21593794}],"checksum":1423967338,"timestamp":"2026-07-07T23:00:05.488254Z"}]}
{"channel":"book","type":"update","data":[{"symbol":"ETH/USD","bids":[{"price":1773.40,"qty":5.56003448}],"asks":[],"checksum":3722235741,"timestamp":"2026-07-07T23:00:05.488918Z"}]}
{"channel":"book","type":"update","data":[{"symbol":"ETH/USD","bids":[{"price":1773.28,"qty":0.00000000},{"price":1773.22,"qty":0.48930000}],"asks":[],"checksum":2320351932,"timestamp":"2026-07-07T23:00:05.489819Z"}]}
{"channel":"book","type":"update","data":[{"symbol":"ETH/USD","bids":[{"price":1773.41,"qty":2.27737402}],"asks":[],"checksum":3961853888,"timestamp":"2026-07-07T23:00:05.492933Z"}]}
{"channel":"book","type":"update","data":[{"symbol":"ETH/USD","bids":[{"price":1773.41,"qty":0.00000000},{"price":1773.22,"qty":0.48930000}],"asks":[],"checksum":2320351932,"timestamp":"2026-07-07T23:00:05.493864Z"}]}
{"channel":"book","type":"update","data":[{"symbol":"ETH/USD","bids":[{"price":1773.40,"qty":0.00000000},{"price":1773.17,"qty":15.50341803},{"price":1773.41,"qty":5.56003448}],"asks":[],"checksum":2346034260,"timestamp":"2026-07-07T23:00:05.494319Z"}]}
{"channel":"book","type":"update","data":[{"symbol":"ETH/USD","bids":[{"price":1773.48,"qty":0.00000000},{"price":1773.17,"qty":15.50341803}],"asks":[],"checksum":1105034916,"timestamp":"2026-07-07T23:00:05.504751Z"}]}
{"channel":"book","type":"update","data":[{"symbol":"ETH/USD","bids":[{"price":1773.35,"qty":10.72325265}],"asks":[],"checksum":1954990023,"timestamp":"2026-07-07T23:00:05.506322Z"}]}
{"channel":"book","type":"update","data":[{"symbol":"ETH/USD","bids":[{"price":1773.38,"qty":0.45737557}],"asks":[],"checksum":1308031864,"timestamp":"2026-07-07T23:00:05.506637Z"}]}
{"channel":"book","type":"update","data":[{"symbol":"ETH/USD","bids":[{"price":1773.38,"qty":3.27684925}],"asks":[],"checksum":2120159455,"timestamp":"2026-07-07T23:00:05.507326Z"}]}
{"channel":"book","type":"update","data":[{"symbol":"ETH/USD","bids":[{"price":1773.28,"qty":1.68966976}],"asks":[],"checksum":1178071521,"timestamp":"2026-07-07T23:00:05.510100Z"}]}
{"channel":"book","type":"update","data":[{"symbol":"ETH/USD","bids":[{"price":1773.28,"qty":0.00000000},{"price":1773.22,"qty":0.48930000}],"asks":[],"checksum":2120159455,"timestamp":"2026-07-07T23:00:05.510525Z"}]}
{"channel":"book","type":"update","data":[{"symbol":"ETH/USD","bids":[{"price":1773.38,"qty":0.45737557}],"asks":[],"checksum":1308031864,"timestamp":"2026-07-07T23:00:05.510693Z"}]}
{"channel":"book","type":"update","data":[{"symbol":"ETH/USD","bids":[],"asks":[{"price":1774.39,"qty":1.48204918}],"checksum":2434686053,"timestamp":"2026-07-07T23:00:05.511852Z"}]}
{"channel":"book","type":"update","data":[{"symbol":"ETH/USD","bids":[{"price":1773.41,"qty":6.04933448}],"asks":[],"checksum":341042855,"timestamp":"2026-07-07T23:00:05.513517Z"}]}
{"channel":"book","type":"update","data":[{"symbol":"ETH/USD","bids":[],"asks":[{"price":1774.38,"qty":5.10831691}],"checksum":3384347967,"timestamp":"2026-07-07T23:00:05.518272Z"}]}
{"channel":"book","type":"update","data":[{"symbol":"ETH/USD","bids":[{"price":1773.41,"qty":0.48930000},{"price":1773.36,"qty":5.56003448}],"asks":[],"checksum":908367520,"timestamp":"2026-07-07T23:00:05.520908Z"}]}
{"channel":"book","type":"update","data":[{"symbol":"ETH/USD","bids":[{"price":1773.35,"qty":7.55432325}],"asks":[],"checksum":984661176,"timestamp":"2026-07-07T23:00:05.522602Z"}]}
{"channel":"book","type":"update","data":[{"symbol":"ETH/USD","bids":[{"price":1773.35,"qty":14.16419774}],"asks":[],"checksum":1172237119,"timestamp":"2026-07-07T23:00:05.523299Z"}]}
{"channel":"book","type":"update","data":[{"symbol":"BTC/USD","bids":[],"asks":[{"price":63501.7,"qty":2.95668096}],"checksum":3616282984,"timestamp":"2026-07-07T23:00:05.526811Z"}]}
{"channel":"book","type":"update","data":[{"symbol":"ETH/USD","bids":[{"price":1773.35,"qty":6.60987449}],"asks":[],"checksum":274479753,"timestamp":"2026-07-07T23:00:05.526875Z"}]}
{"channel":"book","type":"update","data":[{"symbol":"ETH/USD","bids":[{"price":1773.35,"qty":0.00000000},{"price":1773.22,"qty":0.48930000}],"asks":[],"checksum":1635912784,"timestamp":"2026-07-07T23:00:05.527100Z"}]}
{"channel":"book","type":"update","data":[{"symbol":"BTC/USD","bids":[],"asks":[{"price":63502.0,"qty":2.56289125}],"checksum":2604661423,"timestamp":"2026-07-07T23:00:05.528004Z"}]}
{"channel":"book","type":"update","data":[{"symbol":"BTC/USD","bids":[],"asks":[{"price":63507.2,"qty":0.17407093}],"checksum":1774784156,"timestamp":"2026-07-07T23:00:05.529909Z"}]}
{"channel":"book","type":"update","data":[{"symbol":"ETH/USD","bids":[],"asks":[{"price":1774.38,"qty":10.23864250}],"checksum":4116118955,"timestamp":"2026-07-07T23:00:05.535277Z"}]}
{"channel":"book","type":"update","data":[{"symbol":"ETH/USD","bids":[],"asks":[{"price":1774.14,"qty":40.94914898}],"checksum":2173187449,"timestamp":"2026-07-07T23:00:05.536643Z"}]}
{"channel":"book","type":"update","data":[{"symbol":"ETH/USD","bids":[],"asks":[{"price":1774.40,"qty":9.52100000},{"price":1774.14,"qty":46.58814898}],"checksum":742909025,"timestamp":"2026-07-07T23:00:05.539442Z"}]}
{"channel":"book","type":"update","data":[{"symbol":"BTC/USD","bids":[],"asks":[{"price":63501.7,"qty":3.19437415}],"checksum":793663772,"timestamp":"2026-07-07T23:00:05.541978Z"}]}
{"channel":"book","type":"update","data":[{"symbol":"BTC/USD","bids":[],"asks":[{"price":63501.9,"qty":0.90625810}],"checksum":359028094,"timestamp":"2026-07-07T23:00:05.542288Z"}]}
{"channel":"book","type":"update","data":[{"symbol":"ETH/USD","bids":[{"price":1773.36,"qty":0.00000000},{"price":1773.17,"qty":8.77228952}],"asks":[],"checksum":1743010630,"timestamp":"2026-07-07T23:00:05.543987Z"}]}
{"channel":"book","type":"update","data":[{"symbol":"BTC/USD","bids":[],"asks":[{"price":63507.2,"qty":0.00005100}],"checksum":516912213,"timestamp":"2026-07-07T23:00:05.544344Z"}]}
{"channel":"book","type":"update","data":[{"symbol":"BTC/USD","bids":[],"asks":[{"price":63507.2,"qty":0.47234854}],"checksum":791230228,"timestamp":"2026-07-07T23:00:05.546280Z"}]}
{"channel":"book","type":"update","data":[{"symbol":"ETH/USD","bids":[{"price":1773.34,"qty":0.00000000},{"price":1773.16,"qty":28.19160254}],"asks":[],"checksum":3452936732,"timestamp":"2026-07-07T23:00:05.549617Z"}]}
{"channel":"heartbeat"}
{"channel":"book","type":"update","data":[{"symbol":"ETH/USD","bids":[{"price":1773.28,"qty":0.68579542}],"asks":[],"checksum":2443959123,"timestamp":"2026-07-07T23:00:05.553777Z"}]}
{"channel":"book","type":"update","data":[{"symbol":"ETH/USD","bids":[{"price":1773.24,"qty":0.00000000},{"price":1773.16,"qty":28.19160254}],"asks":[],"checksum":1266990980,"timestamp":"2026-07-07T23:00:05.553804Z"}]}
{"channel":"book","type":"update","data":[{"symbol":"ETH/USD","bids":[{"price":1773.16,"qty":0.00000000},{"price":1773.15,"qty":1.19630206}],"asks":[],"checksum":2002598018,"timestamp":"2026-07-07T23:00:05.554315Z"}]}
{"channel":"book","type":"update","data":[{"symbol":"ETH/USD","bids":[{"price":1773.27,"qty":0.00000000},{"price":1773.07,"qty":28.19309061}],"asks":[],"checksum":3083972916,"timestamp":"2026-07-07T23:00:05.556464Z"}]}
{"channel":"book","type":"update","data":[{"symbol":"ETH/USD","bids":[{"price":1773.17,"qty":0.00000000},{"price":1773.04,"qty":0.48930000}],"asks":[],"checksum":2906816031,"timestamp":"2026-07-07T23:00:05.557756Z"}]}
{"channel":"book","type":"update","data":[{"symbol":"ETH/USD","bids":[{"price":1773.08,"qty":8.56169360}],"asks":[],"checksum":137972079,"timestamp":"2026-07-07T23:00:05.558132Z"}]}
{"channel":"book","type":"update","data":[{"symbol":"ETH/USD","bids":[],"asks":[{"price":1774.14,"qty":48.88562108}],"checksum":469461793,"timestamp":"2026-07-07T23:00:05.558517Z"}]}
{"channel":"book","type":"update","data":[{"symbol":"ETH/USD","bids":[{"price":1773.37,"qty":0.06935921}],"asks":[],"checksum":148174030,"timestamp":"2026-07-07T23:00:05.559313Z"}]}
{"channel":"book","type":"update","data":[{"symbol":"ETH/USD","bids":[{"price":1773.25,"qty":0.00000000},{"price":1773.04,"qty":0.48930000}],"asks":[],"checksum":358421387,"timestamp":"2026-07-07T23:00:05.559793Z"}]}
{"channel":"book","type":"update","data":[{"symbol":"ETH/USD","bids":[{"price":1773.14,"qty":16.94200000}],"asks":[],"checksum":1081008185,"timestamp":"2026-07-07T23:00:05.562511Z"}]}
{"channel":"trade","type":"update","data":[{"symbol":"BTC/USD","side":"sell","price":63501.6,"qty":0.00185211,"ord_type":"limit","trade_id":103436769,"timestamp":"2026-07-07T23:00:05.562702Z"},{"symbol":"BTC/USD","side":"sell","price":63501.6,"qty":0.02922270,"ord_type":"limit","trade_id":103436770,"timestamp":"2026-07-07T23:00:05.562702Z"},{"symbol":"BTC/USD","side":"sell","price":63500.9,"qty":0.00005100,"ord_type":"limit","trade_id":103436771,"timestamp":"2026-07-07T23:00:05.562702Z"}]}
{"channel":"book","type":"update","data":[{"symbol":"BTC/USD","bids":[{"price":63501.6,"qty":0.02922270},{"price":63501.6,"qty":0.00000000},{"price":63478.6,"qty":0.00016057},{"price":63500.9,"qty":0.00000000},{"price":63477.2,"qty":0.05744528}],"asks":[{"price":63498.1,"qty":0.03355821}],"checksum":3987746476,"timestamp":"2026-07-07T23:00:05.562702Z"}]}
{"channel":"book","type":"update","data":[{"symbol":"ETH/USD","bids":[{"price":1773.28,"qty":0.00000000},{"price":1773.04,"qty":0.48930000}],"asks":[],"checksum":86357645,"timestamp":"2026-07-07T23:00:05.563162Z"}]}
{"channel":"book","type":"update","data":[{"symbol":"ETH/USD","bids":[{"price":1773.45,"qty":0.32719118}],"asks":[],"checksum":3083122950,"timestamp":"2026-07-07T23:00:05.564383Z"}]}
{"channel":"book","type":"update","data":[{"symbol":"ETH/USD","bids":[],"asks":[{"price":1774.37,"qty":0.59803460}],"checksum":3893391800,"timestamp":"2026-07-07T23:00:05.565101Z"}]}
{"channel":"book","type":"update","data":[{"symbol":"BTC/USD","bids":[],"asks":[{"price":63498.1,"qty":0.04360529}],"checksum":2341363479,"timestamp":"2026-07-07T23:00:05.565216Z"}]}
{"channel":"book","type":"update","data":[{"symbol":"BTC/USD","bids":[],"asks":[{"price":63498.1,"qty":0.10350529}],"checksum":2973252036,"timestamp":"2026-07-07T23:00:05.565538Z"}]}
{"channel":"book","type":"update","data":[{"symbol":"ETH/USD","bids":[{"price":1773.15,"qty":6.25348906}],"asks":[],"checksum":123126818,"timestamp":"2026-07-07T23:00:05.565991Z"}]}
{"channel":"book","type":"update","data":[{"symbol":"BTC/USD","bids":[],"asks":[{"price":63502.1,"qty":0.00000000},{"price":63507.2,"qty":0.47234854}],"checksum":2592810603,"timestamp":"2026-07-07T23:00:05.566395Z"}]}
{"channel":"book","type":"update","data":[{"symbol":"BTC/USD","bids":[],"asks":[{"price":63498.1,"qty":0.21350529}],"checksum":3431110418,"timestamp":"2026-07-07T23:00:05.566533Z"}]}
{"channel":"book","type":"update","data":[{"symbol":"BTC/USD","bids":[],"asks":[{"price":63498.1,"qty":0.30742494}],"checksum":396056595,"timestamp":"2026-07-07T23:00:05.566583Z"}]}
{"channel":"book","type":"update","data":[{"symbol":"BTC/USD","bids":[],"asks":[{"price":63501.9,"qty":0.00095866}],"checksum":4279409553,"timestamp":"2026-07-07T23:00:05.567759Z"}]}
{"channel":"book","type":"update","data":[{"symbol":"BTC/USD","bids":[],"asks":[{"price":63501.7,"qty":3.13447415}],"checksum":3447152349,"timestamp":"2026-07-07T23:00:05.567935Z"}]}
{"channel":"book","type":"update","data":[{"symbol":"ETH/USD","bids":[{"price":1773.35,"qty":5.56003448}],"asks":[],"checksum":3397110883,"timestamp":"2026-07-07T23:00:05.568185Z"}]}
{"channel":"book","type":"update","data":[{"symbol":"BTC/USD","bids":[],"asks":[{"price":63501.6,"qty":1.85910628}],"checksum":1719198284,"timestamp":"2026-07-07T23:00:05.569957Z"}]}
{"channel":"book","type":"update","data":[{"symbol":"BTC/USD","bids":[],"asks":[{"price":63501.6,"qty":2.09679947}],"checksum":3980094949,"timestamp":"2026-07-07T23:00:05.570097Z"}]}
{"channel":"book","type":"update","data":[{"symbol":"ETH/USD","bids":[{"price":1773.38,"qty":0.00000000},{"price":1773.07,"qty":28.19309061}],"asks":[],"checksum":3377852658,"timestamp":"2026-07-07T23:00:05.570406Z"}]}
{"channel":"book","type":"update","data":[{"symbol":"BTC/USD","bids":[],"asks":[{"price":63498.1,"qty":0.75466771}],"checksum":2535666902,"timestamp":"2026-07-07T23:00:05.570547Z"}]}
{"channel":"book","type":"update","data":[{"symbol":"BTC/USD","bids":[],"asks":[{"price":63501.6,"qty":1.85910628}],"checksum":476101503,"timestamp":"2026-07-07T23:00:05.570681Z"}]}
{"channel":"book","type":"update","data":[{"symbol":"ETH/USD","bids":[{"price":1773.41,"qty":0.00000000},{"price":1773.04,"qty":0.48930000}],"asks":[],"checksum":2079308727,"timestamp":"2026-07-07T23:00:05.570849Z"}]}
{"channel":"book","type":"update","data":[{"symbol":"BTC/USD","bids":[],"asks":[{"price":63502.0,"qty":0.19996636},{"price":63501.7,"qty":5.49743007}],"checksum":3619913403,"timestamp":"2026-07-07T23:00:05.571525Z"}]}
{"channel":"book","type":"update","data":[{"symbol":"BTC/USD","bids":[],"asks":[{"price":63501.7,"qty":5.25973688}],"checksum":2754531162,"timestamp":"2026-07-07T23:00:05.571836Z"}]}
{"channel":"book","type":"update","data":[{"symbol":"BTC/USD","bids":[],"asks":[{"price":63502.0,"qty":0.00000000},{"price":63507.2,"qty":0.47234854}],"checksum":1037163445,"timestamp":"2026-07-07T23:00:05.572424Z"}]}
{"channel":"book","type":"update","data":[{"symbol":"ETH/USD","bids":[{"price":1773.14,"qty":0.00000000},{"price":1772.97,"qty":2.00950467}],"asks":[],"checksum":3636481593,"timestamp":"2026-07-07T23:00:05.574543Z"}]}
{"channel":"book","type":"update","data":[{"symbol":"ETH/USD","bids":[],"asks":[{"price":1774.16,"qty":3.44294531}],"checksum":3988371222,"timestamp":"2026-07-07T23:00:05.575863Z"}]}
{"channel":"book","type":"update","data":[{"symbol":"BTC/USD","bids":[],"asks":[{"price":63503.6,"qty":0.78735736}],"checksum":3685658631,"timestamp":"2026-07-07T23:00:05.576558Z"}]}
{"channel":"book","type":"update","data":[{"symbol":"BTC/USD","bids":[],"asks":[{"price":63501.7,"qty":5.25871259},{"price":63498.1,"qty":0.75566283}],"checksum":2865133838,"timestamp":"2026-07-07T23:00:05.579592Z"}]}
{"channel":"book","type":"update","data":[{"symbol":"ETH/USD","bids":[{"price":1773.15,"qty":1.19630206}],"asks":[],"checksum":3620927833,"timestamp":"2026-07-07T23:00:05.580284Z"}]}
{"channel":"book","type":"update","data":[{"symbol":"BTC/USD","bids":[],"asks":[{"price":63501.7,"qty":5.24854608}],"checksum":2173631594,"timestamp":"2026-07-07T23:00:05.581257Z"}]}
{"channel":"book","type":"update","data":[{"symbol":"BTC/USD","bids":[],"asks":[{"price":63503.6,"qty":0.00000000},{"price":63507.2,"qty":0.47234854}],"checksum":1743886296,"timestamp":"2026-07-07T23:00:05.581316Z"}]}
{"channel":"book","type":"update","data":[{"symbol":"ETH/USD","bids":[{"price":1773.19,"qty":0.45737557}],"asks":[],"checksum":2908680924,"timestamp":"2026-07-07T23:00:05.582660Z"}]}
{"channel":"book","type":"update","data":[{"symbol":"ETH/USD","bids":[{"price":1773.26,"qty":2.81965496}],"asks":[],"checksum":1964984841,"timestamp":"2026-07-07T23:00:05.582707Z"}]}
{"channel":"book","type":"update","data":[{"symbol":"ETH/USD","bids":[{"price":1773.27,"qty":1.12424966}],"asks":[],"checksum":3112134047,"timestamp":"2026-07-07T23:00:05.590289Z"}]}
{"channel":"book","type":"update","data":[{"symbol":"ETH/USD","bids":[{"price":1773.35,"qty":0.00000000},{"price":1773.07,"qty":28.19309061},{"price":1773.16,"qty":5.56003448}],"asks":[],"checksum":12094018,"timestamp":"2026-07-07T23:00:05.591329Z"}]}
{"channel":"book","type":"update","data":[{"symbol":"BTC/USD","bids":[],"asks":[{"price":63503.8,"qty":1.56064095}],"checksum":4014775845,"timestamp":"2026-07-07T23:00:05.592079Z"}]}
{"channel":"book","type":"update","data":[{"symbol":"BTC/USD","bids":[],"asks":[{"price":63498.1,"qty":1.54308796}],"checksum":2053980702,"timestamp":"2026-07-07T23:00:05.593860Z"}]}
{"channel":"book","type":"update","data":[{"symbol":"ETH/USD","bids":[{"price":1773.17,"qty":2.01676646}],"asks":[],"checksum":3832473897,"timestamp":"2026-07-07T23:00:05.594393Z"}]}
{"channel":"book","type":"update","data":[{"symbol":"ETH/USD","bids":[{"price":1773.27,"qty":0.00000000},{"price":1773.08,"qty":8.56169360}],"asks":[],"checksum":2566147552,"timestamp":"2026-07-07T23:00:05.594655Z"}]}
{"channel":"book","type":"update","data":[{"symbol":"ETH/USD","bids":[{"price":1773.27,"qty":1.12424966}],"asks":[],"checksum":3832473897,"timestamp":"2026-07-07T23:00:05.609278Z"}]}
{"channel":"book","type":"update","data":[{"symbol":"BTC/USD","bids":[{"price":63488.7,"qty":0.06000000}],"asks":[],"checksum":3702990554,"timestamp":"2026-07-07T23:00:05.611148Z"}]}
{"channel":"book","type":"update","data":[{"symbol":"BTC/USD","bids":[],"asks":[{"price":63506.5,"qty":0.18034879}],"checksum":561147197,"timestamp":"2026-07-07T23:00:05.611668Z"}]}
{"channel":"book","type":"update","data":[{"symbol":"ETH/USD","bids":[{"price":1773.27,"qty":0.00000000},{"price":1773.08,"qty":8.56169360}],"asks":[],"checksum":2566147552,"timestamp":"2026-07-07T23:00:05.612170Z"}]}
{"channel":"book","type":"update","data":[{"symbol":"BTC/USD","bids":[],"asks":[{"price":63503.8,"qty":0.00000000},{"price":63507.2,"qty":0.47234854},{"price":63506.5,"qty":1.74098974}],"checksum":1753083648,"timestamp":"2026-07-07T23:00:05.612392Z"}]}
{"channel":"book","type":"update","data":[{"symbol":"ETH/USD","bids":[{"price":1773.16,"qty":0.00000000},{"price":1773.07,"qty":28.19309061},{"price":1773.09,"qty":5.56003448}],"asks":[],"checksum":2067358117,"timestamp":"2026-07-07T23:00:05.614200Z"}]}
{"channel":"book","type":"update","data":[{"symbol":"BTC/USD","bids":[],"asks":[{"price":63506.5,"qty":1.62157452}],"checksum":1586194093,"timestamp":"2026-07-07T23:00:05.614531Z"}]}
{"channel":"book","type":"update","data":[{"symbol":"BTC/USD","bids":[],"asks":[{"price":63506.4,"qty":0.60345522}],"checksum":3612133290,"timestamp":"2026-07-07T23:00:05.615427Z"}]}
{"channel":"book","type":"update","data":[{"symbol":"ETH/USD","bids":[{"price":1773.26,"qty":0.00000000},{"price":1773.07,"qty":28.19309061}],"asks":[],"checksum":3298247450,"timestamp":"2026-07-07T23:00:05.627042Z"}]}
{"channel":"book","type":"update","data":[{"symbol":"ETH/USD","bids":[{"price":1773.19,"qty":3.27714328}],"asks":[],"checksum":3390764891,"timestamp":"2026-07-07T23:00:05.630321Z"}]}
{"channel":"trade","type":"update","data":[{"symbol":"ETH/USD","side":"sell","price":1774.13,"qty":0.13466847,"ord_type":"limit","trade_id":64175816,"timestamp":"2026-07-07T23:00:05.637989Z"},{"symbol":"ETH/USD","side":"sell","price":1774.13,"qty":0.99842733,"ord_type":"limit","trade_id":64175817,"timestamp":"2026-07-07T23:00:05.637989Z"}]}
{"channel":"book","type":"update","data":[{"symbol":"ETH/USD","bids":[{"price":1774.13,"qty":0.99842733},{"price":1774.13,"qty":0.00000000},{"price":1773.04,"qty":0.48930000}],"asks":[],"checksum":962786083,"timestamp":"2026-07-07T23:00:05.637989Z"}]}
{"channel":"book","type":"update","data":[{"symbol":"ETH/USD","bids":[],"asks":[{"price":1774.13,"qty":16.46131868}],"checksum":3753542396,"timestamp":"2026-07-07T23:00:05.639598Z"}]}
{"channel":"book","type":"update","data":[{"symbol":"ETH/USD","bids":[],"asks":[{"price":1774.17,"qty":0.00000000},{"price":1774.39,"qty":1.48204918}],"checksum":3329879083,"timestamp":"2026-07-07T23:00:05.639644Z"}]}
{"channel":"book","type":"update","data":[{"symbol":"ETH/USD","bids":[{"price":1773.19,"qty":0.45737557}],"asks":[],"checksum":540056056,"timestamp":"2026-07-07T23:00:05.639698Z"}]}
{"channel":"book","type":"update","data":[{"symbol":"ETH/USD","bids":[],"asks":[{"price":1774.25,"qty":0.00000000},{"price":1774.40,"qty":9.52100000}],"checksum":2972346405,"timestamp":"2026-07-07T23:00:05.639812Z"}]}
{"channel":"book","type":"update","data":[{"symbol":"ETH/USD","bids":[],"asks":[{"price":1774.14,"qty":49.38562108}],"checksum":3358996476,"timestamp":"2026-07-07T23:00:05.640111Z"}]}
{"channel":"book","type":"update","data":[{"symbol":"ETH/USD","bids":[],"asks":[{"price":1774.13,"qty":17.76131868}],"checksum":2705154118,"timestamp":"2026-07-07T23:00:05.640267Z"}]}
{"channel":"book","type":"update","data":[{"symbol":"ETH/USD","bids":[],"asks":[{"price":1774.13,"qty":19.29260621}],"checksum":1741433699,"timestamp":"2026-07-07T23:00:05.640328Z"}]}
{"channel":"book","type":"update","data":[{"symbol":"ETH/USD","bids":[],"asks":[{"price":1774.13,"qty":19.76262509}],"checksum":2027762492,"timestamp":"2026-07-07T23:00:05.640470Z"}]}
{"channel":"book","type":"update","data":[{"symbol":"ETH/USD","bids":[],"asks":[{"price":1774.13,"qty":22.63664924}],"checksum":3846031083,"timestamp":"2026-07-07T23:00:05.640489Z"}]}
{"channel":"book","type":"update","data":[{"symbol":"ETH/USD","bids":[],"asks":[{"price":1774.18,"qty":0.00000000},{"price":1774.44,"qty":61.24031477}],"checksum":4221125161,"timestamp":"2026-07-07T23:00:05.641107Z"}]}
{"channel":"book","type":"update","data":[{"symbol":"ETH/USD","bids":[],"asks":[{"price":1774.14,"qty":29.53946004}],"checksum":469660590,"timestamp":"2026-07-07T23:00:05.641191Z"}]}
{"channel":"book","type":"update","data":[{"symbol":"ETH/USD","bids":[],"asks":[{"price":1774.14,"qty":29.22271533}],"checksum":2144606042,"timestamp":"2026-07-07T23:00:05.641222Z"}]}
{"channel":"book","type":"update","data":[{"symbol":"ETH/USD","bids":[],"asks":[{"price":1774.13,"qty":23.13664924}],"checksum":3846659707,"timestamp":"2026-07-07T23:00:05.641248Z"}]}
{"channel":"book","type":"update","data":[{"symbol":"ETH/USD","bids":[{"price":1773.16,"qty":19.84616104}],"asks":[],"checksum":4024408155,"timestamp":"2026-07-07T23:00:05.641349Z"}]}
{"channel":"book","type":"update","data":[{"symbol":"ETH/USD","bids":[],"asks":[{"price":1774.12,"qty":0.31674471}],"checksum":2294730142,"timestamp":"2026-07-07T23:00:05.641409Z"}]}
{"channel":"book","type":"update","data":[{"symbol":"ETH/USD","bids":[],"asks":[{"price":1774.12,"qty":2.61421681}],"checksum":2992899027,"timestamp":"2026-07-07T23:00:05.642085Z"}]}
{"channel":"book","type":"update","data":[{"symbol":"ETH/USD","bids":[{"price":1773.45,"qty":0.00000000},{"price":1773.04,"qty":0.48930000}],"asks":[],"checksum":2210899777,"timestamp":"2026-07-07T23:00:05.642618Z"}]}
{"channel":"book","type":"update","data":[{"symbol":"ETH/USD","bids":[],"asks":[{"price":1774.13,"qty":6.67533056}],"checksum":1291725930,"timestamp":"2026-07-07T23:00:05.642718Z"}]}
{"channel":"book","type":"update","data":[{"symbol":"ETH/USD","bids":[],"asks":[{"price":1774.14,"qty":26.92524323}],"checksum":85573869,"timestamp":"2026-07-07T23:00:05.643381Z"}]}
{"channel":"book","type":"update","data":[{"symbol":"ETH/USD","bids":[],"asks":[{"price":1774.12,"qty":3.11421681}],"checksum":1240089594,"timestamp":"2026-07-07T23:00:05.643448Z"}]}
{"channel":"book","type":"update","data":[{"symbol":"ETH/USD","bids":[],"asks":[{"price":1774.12,"qty":14.85750268}],"checksum":2852639244,"timestamp":"2026-07-07T23:00:05.644092Z"}]}
{"channel":"book","type":"update","data":[{"symbol":"ETH/USD","bids":[],"asks":[{"price":1774.12,"qty":14.54075797}],"checksum":1198284492,"timestamp":"2026-07-07T23:00:05.644268Z"}]}
{"channel":"book","type":"update","data":[{"symbol":"ETH/USD","bids":[],"asks":[{"price":1774.11,"qty":0.31674471}],"checksum":1351210076,"timestamp":"2026-07-07T23:00:05.644279Z"}]}
{"channel":"book","type":"update","data":[{"symbol":"ETH/USD","bids":[],"asks":[{"price":1774.37,"qty":11.87803460}],"checksum":3106718761,"timestamp":"2026-07-07T23:00:05.644564Z"}]}
{"channel":"book","type":"update","data":[{"symbol":"ETH/USD","bids":[{"price":1773.45,"qty":0.48930000}],"asks":[],"checksum":1940081952,"timestamp":"2026-07-07T23:00:05.644578Z"}]}
{"channel":"book","type":"update","data":[{"symbol":"ETH/USD","bids":[],"asks":[{"price":1773.85,"qty":19.84616104}],"checksum":529484592,"timestamp":"2026-07-07T23:00:05.644602Z"}]}
{"channel":"book","type":"update","data":[{"symbol":"ETH/USD","bids":[],"asks":[{"price":1774.12,"qty":15.03005797}],"checksum":2680809295,"timestamp":"2026-07-07T23:00:05.644755Z"}]}
{"channel":"book","type":"update","data":[{"symbol":"ETH/USD","bids":[],"asks":[{"price":1773.61,"qty":2.81912291}],"checksum":1989807397,"timestamp":"2026-07-07T23:00:05.645232Z"}]}
{"channel":"book","type":"update","data":[{"symbol":"ETH/USD","bids":[],"asks":[{"price":1774.11,"qty":1.84803224}],"checksum":1946561904,"timestamp":"2026-07-07T23:00:05.645284Z"}]}
{"channel":"book","type":"update","data":[{"symbol":"ETH/USD","bids":[],"asks":[{"price":1773.61,"qty":0.00000000},{"price":1774.38,"qty":10.23864250}],"checksum":715486011,"timestamp":"2026-07-07T23:00:05.646194Z"}]}
{"channel":"book","type":"update","data":[{"symbol":"ETH/USD","bids":[],"asks":[{"price":1774.13,"qty":5.14404303}],"checksum":1468401333,"timestamp":"2026-07-07T23:00:05.646378Z"}]}
{"channel":"book","type":"update","data":[{"symbol":"ETH/USD","bids":[],"asks":[{"price":1774.11,"qty":2.33733224}],"checksum":3694517368,"timestamp":"2026-07-07T23:00:05.646523Z"}]}
{"channel":"book","type":"update","data":[{"symbol":"ETH/USD","bids":[],"asks":[{"price":1774.11,"qty":2.83733224}],"checksum":3067147876,"timestamp":"2026-07-07T23:00:05.646725Z"}]}
{"channel":"book","type":"update","data":[{"symbol":"ETH/USD","bids":[],"asks":[{"price":1774.14,"qty":26.43594323}],"checksum":3355800074,"timestamp":"2026-07-07T23:00:05.646767Z"}]}
{"channel":"book","type":"update","data":[{"symbol":"ETH/USD","bids":[],"asks":[{"price":1773.84,"qty":0.31674471}],"checksum":1947622791,"timestamp":"2026-07-07T23:00:05.646881Z"}]}
{"channel":"book","type":"update","data":[{"symbol":"ETH/USD","bids":[],"asks":[{"price":1774.11,"qty":2.52058753}],"checksum":1732006185,"timestamp":"2026-07-07T23:00:05.647140Z"}]}
{"channel":"book","type":"update","data":[{"symbol":"BTC/USD","bids":[{"price":63478.8,"qty":0.05990000}],"asks":[],"checksum":3334258862,"timestamp":"2026-07-07T23:00:05.647380Z"}]}
{"channel":"book","type":"update","data":[{"symbol":"ETH/USD","bids":[],"asks":[{"price":1773.62,"qty":0.31674471}],"checksum":2468603173,"timestamp":"2026-07-07T23:00:05.647479Z"}]}
{"channel":"book","type":"update","data":[{"symbol":"ETH/USD","bids":[],"asks":[{"price":1773.85,"qty":20.34616104}],"checksum":3255820107,"timestamp":"2026-07-07T23:00:05.647524Z"}]}
{"channel":"book","type":"update","data":[{"symbol":"ETH/USD","bids":[],"asks":[{"price":1774.14,"qty":25.00653323}],"checksum":10153830,"timestamp":"2026-07-07T23:00:05.647641Z"}]}
{"channel":"book","type":"update","data":[{"symbol":"ETH/USD","bids":[],"asks":[{"price":1773.84,"qty":0.00000000},{"price":1774.37,"qty":11.87803460}],"checksum":391919789,"timestamp":"2026-07-07T23:00:05.647722Z"}]}
{"channel":"book","type":"update","data":[{"symbol":"ETH/USD","bids":[],"asks":[{"price":1773.84,"qty":1.53128753}],"checksum":3790417603,"timestamp":"2026-07-07T23:00:05.647842Z"}]}
{"channel":"book","type":"update","data":[{"symbol":"ETH/USD","bids":[],"asks":[{"price":1773.84,"qty":16.60928753}],"checksum":2170490738,"timestamp":"2026-07-07T23:00:05.647901Z"}]}
{"channel":"book","type":"update","data":[{"symbol":"ETH/USD","bids":[],"asks":[{"price":1773.84,"qty":17.09858753}],"checksum":2530673259,"timestamp":"2026-07-07T23:00:05.648842Z"}]}
{"channel":"book","type":"update","data":[{"symbol":"ETH/USD","bids":[],"asks":[{"price":1774.13,"qty":4.67402415}],"checksum":1451665249,"timestamp":"2026-07-07T23:00:05.648994Z"}]}
{"channel":"book","type":"update","data":[{"symbol":"ETH/USD","bids":[],"asks":[{"price":1773.84,"qty":17.59858753}],"checksum":4023798207,"timestamp":"2026-07-07T23:00:05.649079Z"}]}
{"channel":"book","type":"update","data":[{"symbol":"ETH/USD","bids":[],"asks":[{"price":1774.11,"qty":0.98930000}],"checksum":4115357320,"timestamp":"2026-07-07T23:00:05.649206Z"}]}
{"channel":"book","type":"update","data":[{"symbol":"ETH/USD","bids":[],"asks":[{"price":1773.84,"qty":18.06860641}],"checksum":4026154128,"timestamp":"2026-07-07T23:00:05.650790Z"}]}
{"channel":"book","type":"update","data":[{"symbol":"ETH/USD","bids":[],"asks":[{"price":1773.83,"qty":11.17725745}],"checksum":1805435891,"timestamp":"2026-07-07T23:00:05.651403Z"}]}
{"channel":"book","type":"update","data":[{"symbol":"ETH/USD","bids":[{"price":1773.09,"qty":0.00000000},{"price":1773.04,"qty":0.48930000},{"price":1773.18,"qty":5.56003448}],"asks":[],"checksum":3596350918,"timestamp":"2026-07-07T23:00:05.653487Z"}]}
{"channel":"book","type":"update","data":[{"symbol":"ETH/USD","bids":[],"asks":[{"price":1774.13,"qty":5.03402415}],"checksum":3235025616,"timestamp":"2026-07-07T23:00:05.654507Z"}]}
{"channel":"book","type":"update","data":[{"symbol":"ETH/USD","bids":[{"price":1773.45,"qty":0.00000000},{"price":1773.05,"qty":0.30000000}],"asks":[],"checksum":3249426425,"timestamp":"2026-07-07T23:00:05.656693Z"}]}
{"channel":"book","type":"update","data":[{"symbol":"ETH/USD","bids":[],"asks":[{"price":1773.83,"qty":39.36485152}],"checksum":2104754314,"timestamp":"2026-07-07T23:00:05.659093Z"}]}
{"channel":"book","type":"update","data":[{"symbol":"ETH/USD","bids":[],"asks":[{"price":1774.11,"qty":141.90502675}],"checksum":2482395856,"timestamp":"2026-07-07T23:00:05.659430Z"}]}
{"channel":"book","type":"update","data":[{"symbol":"ETH/USD","bids":[{"price":1773.06,"qty":28.19980462}],"asks":[],"checksum":2385011894,"timestamp":"2026-07-07T23:00:05.659739Z"}]}
{"channel":"book","type":"update","data":[{"symbol":"BTC/USD","bids":[],"asks":[{"price":63506.6,"qty":0.00000000},{"price":63507.2,"qty":0.47234854},{"price":63498.7,"qty":0.40000000}],"checksum":3679142099,"timestamp":"2026-07-07T23:00:05.660275Z"}]}
{"channel":"book","type":"update","data":[{"symbol":"ETH/USD","bids":[],"asks":[{"price":1774.12,"qty":3.28677210}],"checksum":3426816050,"timestamp":"2026-07-07T23:00:05.661169Z"}]}
{"channel":"book","type":"update","data":[{"symbol":"BTC/USD","bids":[],"asks":[{"price":63498.1,"qty":1.67418198}],"checksum":326953863,"timestamp":"2026-07-07T23:00:05.662138Z"}]}
{"channel":"book","type":"update","data":[{"symbol":"BTC/USD","bids":[],"asks":[{"price":63498.6,"qty":0.11940000}],"checksum":1850508377,"timestamp":"2026-07-07T23:00:05.662885Z"}]}
{"channel":"book","type":"update","data":[{"symbol":"ETH/USD","bids":[],"asks":[{"price":1774.10,"qty":36.31293466}],"checksum":4241720052,"timestamp":"2026-07-07T23:00:05.662979Z"}]}
{"channel":"book","type":"update","data":[{"symbol":"ETH/USD","bids":[{"price":1773.40,"qty":0.48930000}],"asks":[],"checksum":2021437992,"timestamp":"2026-07-07T23:00:05.665323Z"}]}
{"channel":"book","type":"update","data":[{"symbol":"ETH/USD","bids":[{"price":1773.17,"qty":3.70643622}],"asks":[],"checksum":3597584042,"timestamp":"2026-07-07T23:00:05.665619Z"}]}
{"channel":"book","type":"update","data":[{"symbol":"BTC/USD","bids":[],"asks":[{"price":63501.7,"qty":5.13854608}],"checksum":925338704,"timestamp":"2026-07-07T23:00:05.669045Z"}]}
{"channel":"book","type":"update","data":[{"symbol":"BTC/USD","bids":[],"asks":[{"price":63501.7,"qty":5.04462643}],"checksum":2106963110,"timestamp":"2026-07-07T23:00:05.670457Z"}]}
{"channel":"book","type":"update","data":[{"symbol":"ETH/USD","bids":[{"price":1773.11,"qty":16.81400000}],"asks":[],"checksum":1192150928,"timestamp":"2026-07-07T23:00:05.674165Z"}]}
{"channel":"book","type":"update","data":[{"symbol":"BTC/USD","bids":[],"asks":[{"price":63504.9,"qty":2.36202522}],"checksum":4165987955,"timestamp":"2026-07-07T23:00:05.694783Z"}]}
{"channel":"book","type":"update","data":[{"symbol":"BTC/USD","bids":[],"asks":[{"price":63504.8,"qty":1.19146893}],"checksum":896710039,"timestamp":"2026-07-07T23:00:05.701297Z"}]}
{"channel":"book","type":"update","data":[{"symbol":"BTC/USD","bids":[],"asks":[{"price":63498.1,"qty":2.25348998}],"checksum":2324492133,"timestamp":"2026-07-07T23:00:05.702043Z"}]}
{"channel":"book","type":"update","data":[{"symbol":"BTC/USD","bids":[],"asks":[{"price":63498.1,"qty":2.85819922}],"checksum":3819575369,"timestamp":"2026-07-07T23:00:05.708066Z"}]}
{"channel":"book","type":"update","data":[{"symbol":"ETH/USD","bids":[{"price":1773.17,"qty":9.10463626}],"asks":[],"checksum":3513209019,"timestamp":"2026-07-07T23:00:05.719607Z"}]}
{"channel":"book","type":"update","data":[{"symbol":"BTC/USD","bids":[],"asks":[{"price":63501.7,"qty":2.68167051}],"checksum":2513260449,"timestamp":"2026-07-07T23:00:05.722587Z"}]}
{"channel":"book","type":"update","data":[{"symbol":"ETH/USD","bids":[{"price":1773.19,"qty":2.11704586}],"asks":[],"checksum":1756791825,"timestamp":"2026-07-07T23:00:05.724603Z"}]}
{"channel":"book","type":"update","data":[{"symbol":"BTC/USD","bids":[],"asks":[{"price":63501.6,"qty":0.00000000},{"price":63505.1,"qty":0.00786998}],"checksum":3284044474,"timestamp":"2026-07-07T23:00:05.725222Z"}]}
{"channel":"book","type":"update","data":[{"symbol":"ETH/USD","bids":[{"price":1773.17,"qty":3.70643622}],"asks":[],"checksum":4276032314,"timestamp":"2026-07-07T23:00:05.725475Z"}]}
{"channel":"book","type":"update","data":[{"symbol":"ETH/USD","bids":[{"price":1773.17,"qty":1.68966976}],"asks":[],"checksum":1927917630,"timestamp":"2026-07-07T23:00:05.725507Z"}]}
{"channel":"book","type":"update","data":[{"symbol":"BTC/USD","bids":[],"asks":[{"price":63501.6,"qty":0.82022546}],"checksum":4054066517,"timestamp":"2026-07-07T23:00:05.725910Z"}]}
{"channel":"book","type":"update","data":[{"symbol":"BTC/USD","bids":[],"asks":[{"price":63504.8,"qty":1.74446625}],"checksum":2353202684,"timestamp":"2026-07-07T23:00:05.726329Z"}]}
{"channel":"book","type":"update","data":[{"symbol":"BTC/USD","bids":[],"asks":[{"price":63501.6,"qty":3.18311870}],"checksum":2362411402,"timestamp":"2026-07-07T23:00:05.726802Z"}]}
{"channel":"book","type":"update","data":[{"symbol":"ETH/USD","bids":[{"price":1773.17,"qty":12.98982400}],"asks":[],"checksum":1781587724,"timestamp":"2026-07-07T23:00:05.728439Z"}]}
{"channel":"book","type":"update","data":[{"symbol":"BTC/USD","bids":[],"asks":[{"price":63501.5,"qty":1.52554909}],"checksum":2557650813,"timestamp":"2026-07-07T23:00:05.728841Z"}]}
{"channel":"book","type":"update","data":[{"symbol":"BTC/USD","bids":[],"asks":[{"price":63501.6,"qty":2.36289324}],"checksum":1797309821,"timestamp":"2026-07-07T23:00:05.729063Z"}]}
{"channel":"book","type":"update","data":[{"symbol":"BTC/USD","bids":[],"asks":[{"price":63504.8,"qty":1.19146893}],"checksum":2352093952,"timestamp":"2026-07-07T23:00:05.729287Z"}]}
{"channel":"book","type":"update","data":[{"symbol":"ETH/USD","bids":[{"price":1773.16,"qty":21.14616104}],"asks":[],"checksum":2339082674,"timestamp":"2026-07-07T23:00:05.733310Z"}]}
{"channel":"book","type":"update","data":[{"symbol":"BTC/USD","bids":[],"asks":[{"price":63501.6,"qty":0.00000000},{"price":63504.9,"qty":2.36202522}],"checksum":365052276,"timestamp":"2026-07-07T23:00:05.733365Z"}]}
{"channel":"book","type":"update","data":[{"symbol":"BTC/USD","bids":[],"asks":[{"price":63501.5,"qty":0.00000000},{"price":63505.1,"qty":0.00786998}],"checksum":3284044474,"timestamp":"2026-07-07T23:00:05.735373Z"}]}
{"channel":"book","type":"update","data":[{"symbol":"BTC/USD","bids":[],"asks":[{"price":63501.5,"qty":0.82022546}],"checksum":1382529387,"timestamp":"2026-07-07T23:00:05.735701Z"}]}
{"channel":"book","type":"update","data":[{"symbol":"BTC/USD","bids":[],"asks":[{"price":63504.8,"qty":1.74446541}],"checksum":1704913537,"timestamp":"2026-07-07T23:00:05.738493Z"}]}
{"channel":"book","type":"update","data":[{"symbol":"ETH/USD","bids":[],"asks":[{"price":1774.14,"qty":23.70653323}],"checksum":2580349828,"timestamp":"2026-07-07T23:00:05.741242Z"}]}
{"channel":"book","type":"update","data":[{"symbol":"ETH/USD","bids":[],"asks":[{"price":1774.14,"qty":20.83250908}],"checksum":969022555,"timestamp":"2026-07-07T23:00:05.741402Z"}]}
{"channel":"book","type":"update","data":[{"symbol":"ETH/USD","bids":[],"asks":[{"price":1774.14,"qty":19.30122155}],"checksum":3162451833,"timestamp":"2026-07-07T23:00:05.741504Z"}]}
{"channel":"book","type":"update","data":[{"symbol":"ETH/USD","bids":[],"asks":[{"price":1774.14,"qty":18.83268226}],"checksum":1159402976,"timestamp":"2026-07-07T23:00:05.742564Z"}]}
{"channel":"book","type":"update","data":[{"symbol":"ETH/USD","bids":[],"asks":[{"price":1773.97,"qty":1.48204918}],"checksum":3045475891,"timestamp":"2026-07-07T23:00:05.745628Z"}]}
{"channel":"book","type":"update","data":[{"symbol":"ETH/USD","bids":[],"asks":[{"price":1773.89,"qty":1.30000000}],"checksum":638538938,"timestamp":"2026-07-07T23:00:05.747485Z"}]}
{"channel":"book","type":"update","data":[{"symbol":"ETH/USD","bids":[],"asks":[{"price":1773.82,"qty":0.47001888}],"checksum":271035564,"timestamp":"2026-07-07T23:00:05.747892Z"}]}
{"channel":"book","type":"update","data":[{"symbol":"ETH/USD","bids":[],"asks":[{"price":1773.71,"qty":0.31388300}],"checksum":2958845086,"timestamp":"2026-07-07T23:00:05.757068Z"}]}
{"channel":"book","type":"update","data":[{"symbol":"BTC/USD","bids":[],"asks":[{"price":63501.7,"qty":2.55057649}],"checksum":547048707,"timestamp":"2026-07-07T23:00:05.763148Z"}]}
{"channel":"book","type":"update","data":[{"symbol":"BTC/USD","bids":[{"price":63478.8,"qty":0.00000000},{"price":63478.6,"qty":0.00016057}],"asks":[],"checksum":47053766,"timestamp":"2026-07-07T23:00:05.777993Z"}]}
{"channel":"book","type":"update","data":[{"symbol":"ETH/USD","bids":[{"price":1773.40,"qty":0.00000000},{"price":1773.07,"qty":28.19309061}],"asks":[],"checksum":3738483117,"timestamp":"2026-07-07T23:00:05.778694Z"}]}
{"channel":"book","type":"update","data":[{"symbol":"BTC/USD","bids":[{"price":63488.7,"qty":0.00000000},{"price":63477.2,"qty":0.05744528}],"asks":[],"checksum":2753011458,"timestamp":"2026-07-07T23:00:05.779397Z"}]}
{"channel":"book","type":"update","data":[{"symbol":"ETH/USD","bids":[{"price":1773.23,"qty":1.30000000}],"asks":[],"checksum":3654983578,"timestamp":"2026-07-07T23:00:05.779992Z"}]}
{"channel":"book","type":"update","data":[{"symbol":"ETH/USD","bids":[{"price":1773.23,"qty":1.77001888}],"asks":[],"checksum":2471669857,"timestamp":"2026-07-07T23:00:05.780148Z"}]}
{"channel":"book","type":"update","data":[{"symbol":"BTC/USD","bids":[],"asks":[{"price":63498.1,"qty":2.88033004}],"checksum":3270839358,"timestamp":"2026-07-07T23:00:05.783796Z"}]}
{"channel":"book","type":"update","data":[{"symbol":"ETH/USD","bids":[{"price":1773.22,"qty":0.00000000},{"price":1773.07,"qty":28.19309061}],"asks":[],"checksum":124451512,"timestamp":"2026-07-07T23:00:05.783937Z"}]}
{"channel":"book","type":"update","data":[{"symbol":"ETH/USD","bids":[{"price":1773.37,"qty":0.55865921}],"asks":[],"checksum":786054248,"timestamp":"2026-07-07T23:00:05.784120Z"}]}
{"channel":"book","type":"update","data":[{"symbol":"ETH/USD","bids":[{"price":1773.23,"qty":0.47001888}],"asks":[],"checksum":1305564175,"timestamp":"2026-07-07T23:00:05.786173Z"}]}
{"channel":"book","type":"update","data":[{"symbol":"ETH/USD","bids":[],"asks":[{"price":1773.84,"qty":30.42287372}],"checksum":3298736484,"timestamp":"2026-07-07T23:00:05.792902Z"}]}
{"channel":"book","type":"update","data":[{"symbol":"BTC/USD","bids":[],"asks":[{"price":63498.1,"qty":2.92193004}],"checksum":3310411817,"timestamp":"2026-07-07T23:00:05.795685Z"}]}
{"channel":"book","type":"update","data":[{"symbol":"ETH/USD","bids":[{"price":1773.19,"qty":2.14884586}],"asks":[],"checksum":3800491683,"timestamp":"2026-07-07T23:00:05.798206Z"}]}
{"channel":"book","type":"update","data":[{"symbol":"ETH/USD","bids":[],"asks":[{"price":1773.62,"qty":0.64532012}],"checksum":3550429218,"timestamp":"2026-07-07T23:00:05.810853Z"}]}
{"channel":"book","type":"update","data":[{"symbol":"ETH/USD","bids":[{"price":1773.38,"qty":0.33531602}],"asks":[],"checksum":2003746741,"timestamp":"2026-07-07T23:00:05.811027Z"}]}
{"channel":"book","type":"update","data":[{"symbol":"ETH/USD","bids":[],"asks":[{"price":1773.71,"qty":0.00000000},{"price":1774.12,"qty":2.79747210}],"checksum":178146992,"timestamp":"2026-07-07T23:00:05.812057Z"}]}
{"channel":"book","type":"update","data":[{"symbol":"ETH/USD","bids":[],"asks":[{"price":1773.82,"qty":0.00000000},{"price":1774.13,"qty":5.03402415}],"checksum":2064979817,"timestamp":"2026-07-07T23:00:05.812448Z"}]}
{"channel":"book","type":"update","data":[{"symbol":"ETH/USD","bids":[],"asks":[{"price":1774.13,"qty":4.67402415}],"checksum":1321441797,"timestamp":"2026-07-07T23:00:05.819439Z"}]}
{"channel":"book","type":"update","data":[{"symbol":"ETH/USD","bids":[{"price":1773.38,"qty":0.82461602}],"asks":[],"checksum":1181931626,"timestamp":"2026-07-07T23:00:05.819774Z"}]}
{"channel":"book","type":"update","data":[{"symbol":"ETH/USD","bids":[{"price":1773.39,"qty":0.48930000}],"asks":[],"checksum":2970862005,"timestamp":"2026-07-07T23:00:05.837288Z"}]}
{"channel":"book","type":"update","data":[{"symbol":"ETH/USD","bids":[],"asks":[{"price":1774.13,"qty":3.37402415}],"checksum":714088189,"timestamp":"2026-07-07T23:00:05.848697Z"}]}
{"channel":"book","type":"update","data":[{"symbol":"ETH/USD","bids":[],"asks":[{"price":1773.84,"qty":29.95285484}],"checksum":2803123455,"timestamp":"2026-07-07T23:00:05.849066Z"}]}
{"channel":"book","type":"update","data":[{"symbol":"ETH/USD","bids":[{"price":1773.24,"qty":0.53000000}],"asks":[],"checksum":1527990577,"timestamp":"2026-07-07T23:00:05.854109Z"}]}
{"channel":"book","type":"update","data":[{"symbol":"ETH/USD","bids":[],"asks":[{"price":1773.59,"qty":2.81914596}],"checksum":2988743601,"timestamp":"2026-07-07T23:00:05.855532Z"}]}
{"channel":"book","type":"update","data":[{"symbol":"ETH/USD","bids":[{"price":1773.33,"qty":2.81955365}],"asks":[],"checksum":1163259256,"timestamp":"2026-07-07T23:00:05.855875Z"}]}
{"channel":"book","type":"update","data":[{"symbol":"ETH/USD","bids":[],"asks":[{"price":1773.58,"qty":1.03414312}],"checksum":1220306725,"timestamp":"2026-07-07T23:00:05.856989Z"}]}
{"channel":"book","type":"update","data":[{"symbol":"ETH/USD","bids":[{"price":1773.39,"qty":0.00000000},{"price":1773.15,"qty":1.19630206}],"asks":[],"checksum":2021140871,"timestamp":"2026-07-07T23:00:05.862212Z"}]}
{"channel":"book","type":"update","data":[{"symbol":"ETH/USD","bids":[{"price":1773.38,"qty":0.33531602}],"asks":[],"checksum":3510086569,"timestamp":"2026-07-07T23:00:05.866934Z"}]}
{"channel":"book","type":"update","data":[{"symbol":"ETH/USD","bids":[{"price":1773.37,"qty":0.06935921}],"asks":[],"checksum":2145766342,"timestamp":"2026-07-07T23:00:05.868113Z"}]}
{"channel":"book","type":"update","data":[{"symbol":"ETH/USD","bids":[{"price":1773.16,"qty":19.84616104}],"asks":[],"checksum":63957209,"timestamp":"2026-07-07T23:00:05.881042Z"}]}
{"channel":"book","type":"update","data":[{"symbol":"BTC/USD","bids":[],"asks":[{"price":63499.2,"qty":0.78741207}],"checksum":3188155593,"timestamp":"2026-07-07T23:00:05.924271Z"}]}
{"channel":"book","type":"update","data":[{"symbol":"BTC/USD","bids":[],"asks":[{"price":63498.6,"qty":0.33917745}],"checksum":531818295,"timestamp":"2026-07-07T23:00:05.929304Z"}]}
{"channel":"book","type":"update","data":[{"symbol":"BTC/USD","bids":[],"asks":[{"price":63498.6,"qty":2.70212323}],"checksum":4096634283,"timestamp":"2026-07-07T23:00:05.958281Z"}]}
{"channel":"book","type":"update","data":[{"symbol":"BTC/USD","bids":[],"asks":[{"price":63498.6,"qty":2.58272323}],"checksum":2695716142,"timestamp":"2026-07-07T23:00:05.959900Z"}]}
{"channel":"book","type":"update","data":[{"symbol":"BTC/USD","bids":[],"asks":[{"price":63504.8,"qty":1.19146893}],"checksum":2650455175,"timestamp":"2026-07-07T23:00:05.960017Z"}]}
{"channel":"book","type":"update","data":[{"symbol":"BTC/USD","bids":[],"asks":[{"price":63498.6,"qty":2.36294578}],"checksum":2665309987,"timestamp":"2026-07-07T23:00:05.960245Z"}]}
{"channel":"book","type":"update","data":[{"symbol":"BTC/USD","bids":[],"asks":[{"price":63498.5,"qty":1.05978182}],"checksum":4253617568,"timestamp":"2026-07-07T23:00:05.961768Z"}]}
{"channel":"book","type":"update","data":[{"symbol":"ETH/USD","bids":[],"asks":[{"price":1773.59,"qty":0.00000000},{"price":1774.12,"qty":2.79747210}],"checksum":2235248296,"timestamp":"2026-07-07T23:00:05.966350Z"}]}
{"channel":"book","type":"update","data":[{"symbol":"ETH/USD","bids":[{"price":1773.16,"qty":21.14616104}],"asks":[],"checksum":4178644407,"timestamp":"2026-07-07T23:00:05.967623Z"}]}
{"channel":"book","type":"update","data":[{"symbol":"ETH/USD","bids":[],"asks":[{"price":1773.63,"qty":2.81908517}],"checksum":1548812945,"timestamp":"2026-07-07T23:00:05.967852Z"}]}
{"channel":"book","type":"update","data":[{"symbol":"ETH/USD","bids":[],"asks":[{"price":1773.58,"qty":0.00000000},{"price":1774.12,"qty":2.79747210}],"checksum":51242566,"timestamp":"2026-07-07T23:00:05.967975Z"}]}
{"channel":"book","type":"update","data":[{"symbol":"ETH/USD","bids":[],"asks":[{"price":1773.62,"qty":1.48681704}],"checksum":4273759002,"timestamp":"2026-07-07T23:00:05.969227Z"}]}
{"channel":"book","type":"update","data":[{"symbol":"ETH/USD","bids":[],"asks":[{"price":1773.62,"qty":1.97611704}],"checksum":3836318956,"timestamp":"2026-07-07T23:00:05.972235Z"}]}
{"channel":"book","type":"update","data":[{"symbol":"BTC/USD","bids":[{"price":63488.2,"qty":0.00005100}],"asks":[],"checksum":2259045807,"timestamp":"2026-07-07T23:00:05.981837Z"}]}
{"channel":"book","type":"update","data":[{"symbol":"BTC/USD","bids":[{"price":63481.4,"qty":0.00000000},{"price":63477.2,"qty":0.05744528}],"asks":[],"checksum":3260018420,"timestamp":"2026-07-07T23:00:05.996201Z"}]}
{"channel":"book","type":"update","data":[{"symbol":"ETH/USD","bids":[],"asks":[{"price":1773.62,"qty":1.48681704}],"checksum":4273759002,"timestamp":"2026-07-07T23:00:06.067174Z"}]}
{"channel":"book","type":"update","data":[{"symbol":"ETH/USD","bids":[{"price":1773.39,"qty":0.48930000}],"asks":[],"checksum":1915747936,"timestamp":"2026-07-07T23:00:06.067199Z"}]}
{"channel":"book","type":"update","data":[{"symbol":"BTC/USD","bids":[],"asks":[{"price":63498.1,"qty":2.93767854}],"checksum":1063238846,"timestamp":"2026-07-07T23:00:06.078664Z"}]}
{"channel":"book","type":"update","data":[{"symbol":"BTC/USD","bids":[],"asks":[{"price":63498.1,"qty":2.95342704}],"checksum":3667069193,"timestamp":"2026-07-07T23:00:06.079202Z"}]}
{"channel":"book","type":"update","data":[{"symbol":"BTC/USD","bids":[],"asks":[{"price":63498.1,"qty":2.99262704}],"checksum":3290412022,"timestamp":"2026-07-07T23:00:06.090452Z"}]}
{"channel":"book","type":"update","data":[{"symbol":"ETH/USD","bids":[{"price":1773.39,"qty":0.00000000},{"price":1773.15,"qty":1.19630206}],"asks":[],"checksum":4273759002,"timestamp":"2026-07-07T23:00:06.216881Z"}]}
{"channel":"book","type":"update","data":[{"symbol":"ETH/USD","bids":[{"price":1773.38,"qty":0.82461602}],"asks":[],"checksum":227548918,"timestamp":"2026-07-07T23:00:06.228859Z"}]}
{"channel":"book","type":"update","data":[{"symbol":"ETH/USD","bids":[{"price":1773.39,"qty":0.48930000}],"asks":[],"checksum":2493705598,"timestamp":"2026-07-07T23:00:06.229955Z"}]}
{"channel":"book","type":"update","data":[{"symbol":"ETH/USD","bids":[{"price":1773.38,"qty":0.33531602}],"asks":[],"checksum":1915747936,"timestamp":"2026-07-07T23:00:06.230036Z"}]}
{"channel":"book","type":"update","data":[{"symbol":"ETH/USD","bids":[],"asks":[{"price":1773.63,"qty":0.00000000},{"price":1774.13,"qty":3.37402415}],"checksum":2524585762,"timestamp":"2026-07-07T23:00:06.230662Z"}]}
{"channel":"book","type":"update","data":[{"symbol":"ETH/USD","bids":[],"asks":[{"price":1773.62,"qty":0.64532012}],"checksum":1158035768,"timestamp":"2026-07-07T23:00:06.232127Z"}]}
{"channel":"book","type":"update","data":[{"symbol":"ETH/USD","bids":[],"asks":[{"price":1773.69,"qty":2.81898447}],"checksum":466293754,"timestamp":"2026-07-07T23:00:06.232246Z"}]}
{"channel":"book","type":"update","data":[{"symbol":"ETH/USD","bids":[],"asks":[{"price":1773.68,"qty":0.84146686}],"checksum":2799245337,"timestamp":"2026-07-07T23:00:06.233813Z"}]}
{"channel":"book","type":"update","data":[{"symbol":"ETH/USD","bids":[{"price":1773.33,"qty":0.00000000},{"price":1773.15,"qty":1.19630206}],"asks":[],"checksum":1369992912,"timestamp":"2026-07-07T23:00:06.247915Z"}]}
{"channel":"book","type":"update","data":[{"symbol":"ETH/USD","bids":[{"price":1773.40,"qty":2.81944287}],"asks":[],"checksum":73345905,"timestamp":"2026-07-07T23:00:06.249907Z"}]}
{"channel":"book","type":"update","data":[{"symbol":"ETH/USD","bids":[{"price":1773.16,"qty":49.34436344}],"asks":[],"checksum":2690391378,"timestamp":"2026-07-07T23:00:06.250111Z"}]}
{"channel":"book","type":"update","data":[{"symbol":"ETH/USD","bids":[{"price":1773.40,"qty":3.30874287}],"asks":[],"checksum":4260132959,"timestamp":"2026-07-07T23:00:06.251125Z"}]}
{"channel":"book","type":"update","data":[{"symbol":"ETH/USD","bids":[{"price":1773.41,"qty":0.48930000}],"asks":[],"checksum":3857605301,"timestamp":"2026-07-07T23:00:06.251150Z"}]}
{"channel":"book","type":"update","data":[{"symbol":"ETH/USD","bids":[],"asks":[{"price":1773.83,"qty":11.17725745}],"checksum":1680157125,"timestamp":"2026-07-07T23:00:06.251450Z"}]}
{"channel":"book","type":"update","data":[{"symbol":"ETH/USD","bids":[{"price":1773.17,"qty":20.35033496}],"asks":[],"checksum":2167529096,"timestamp":"2026-07-07T23:00:06.251610Z"}]}
{"channel":"book","type":"update","data":[{"symbol":"ETH/USD","bids":[{"price":1773.40,"qty":2.81944287}],"asks":[],"checksum":1609182386,"timestamp":"2026-07-07T23:00:06.252151Z"}]}
{"channel":"book","type":"update","data":[{"symbol":"ETH/USD","bids":[{"price":1773.40,"qty":0.00000000},{"price":1773.16,"qty":49.34436344}],"asks":[],"checksum":1228868224,"timestamp":"2026-07-07T23:00:06.252775Z"}]}
{"channel":"book","type":"update","data":[{"symbol":"ETH/USD","bids":[],"asks":[{"price":1773.92,"qty":28.18618532}],"checksum":3810632240,"timestamp":"2026-07-07T23:00:06.254156Z"}]}
{"channel":"book","type":"update","data":[{"symbol":"ETH/USD","bids":[],"asks":[{"price":1773.62,"qty":0.31674471}],"checksum":4240742786,"timestamp":"2026-07-07T23:00:06.254537Z"}]}
{"channel":"book","type":"update","data":[{"symbol":"ETH/USD","bids":[{"price":1773.24,"qty":0.00000000},{"price":1773.15,"qty":1.19630206}],"asks":[],"checksum":3222139805,"timestamp":"2026-07-07T23:00:06.258349Z"}]}
{"channel":"book","type":"update","data":[{"symbol":"ETH/USD","bids":[],"asks":[{"price":1773.62,"qty":0.00000000},{"price":1774.11,"qty":141.90502675}],"checksum":2978549523,"timestamp":"2026-07-07T23:00:06.275929Z"}]}
{"channel":"book","type":"update","data":[{"symbol":"BTC/USD","bids":[{"price":63478.8,"qty":0.05990000}],"asks":[],"checksum":4039098674,"timestamp":"2026-07-07T23:00:06.277124Z"}]}
{"channel":"book","type":"update","data":[{"symbol":"ETH/USD","bids":[],"asks":[{"price":1773.75,"qty":0.31674471}],"checksum":1236677240,"timestamp":"2026-07-07T23:00:06.277298Z"}]}
{"channel":"book","type":"update","data":[{"symbol":"ETH/USD","bids":[{"price":1773.16,"qty":29.49820240}],"asks":[],"checksum":1389219918,"timestamp":"2026-07-07T23:00:06.277393Z"}]}
{"channel":"book","type":"update","data":[{"symbol":"ETH/USD","bids":[{"price":1773.39,"qty":0.94667557}],"asks":[],"checksum":2297842905,"timestamp":"2026-07-07T23:00:06.280446Z"}]}
{"channel":"book","type":"update","data":[{"symbol":"ETH/USD","bids":[{"price":1773.19,"qty":1.69147029}],"asks":[],"checksum":2171833505,"timestamp":"2026-07-07T23:00:06.280692Z"}]}
{"channel":"book","type":"update","data":[{"symbol":"ETH/USD","bids":[],"asks":[{"price":1773.69,"qty":0.00000000},{"price":1774.11,"qty":141.90502675}],"checksum":4171464844,"timestamp":"2026-07-07T23:00:06.289774Z"}]}
{"channel":"book","type":"update","data":[{"symbol":"ETH/USD","bids":[],"asks":[{"price":1773.92,"qty":0.00000000},{"price":1774.12,"qty":2.79747210}],"checksum":651474483,"timestamp":"2026-07-07T23:00:06.290280Z"}]}
{"channel":"book","type":"update","data":[{"symbol":"ETH/USD","bids":[],"asks":[{"price":1774.11,"qty":0.98930000}],"checksum":1113203145,"timestamp":"2026-07-07T23:00:06.291255Z"}]}
{"channel":"book","type":"update","data":[{"symbol":"ETH/USD","bids":[],"asks":[{"price":1773.75,"qty":0.00000000},{"price":1774.13,"qty":3.37402415}],"checksum":1713834525,"timestamp":"2026-07-07T23:00:06.292035Z"}]}
{"channel":"book","type":"update","data":[{"symbol":"BTC/USD","bids":[{"price":63479.3,"qty":0.78765761}],"asks":[],"checksum":1526522354,"timestamp":"2026-07-07T23:00:06.292097Z"}]}
{"channel":"book","type":"update","data":[{"symbol":"ETH/USD","bids":[],"asks":[{"price":1773.68,"qty":0.00000000},{"price":1774.14,"qty":11.00244117}],"checksum":3646379585,"timestamp":"2026-07-07T23:00:06.292519Z"}]}
{"channel":"book","type":"update","data":[{"symbol":"ETH/USD","bids":[],"asks":[{"price":1773.84,"qty":29.46355484}],"checksum":3120019524,"timestamp":"2026-07-07T23:00:06.292543Z"}]}
{"channel":"book","type":"update","data":[{"symbol":"BTC/USD","bids":[],"asks":[{"price":63498.2,"qty":0.00314970}],"checksum":3890814681,"timestamp":"2026-07-07T23:00:06.292646Z"}]}
{"channel":"book","type":"update","data":[{"symbol":"ETH/USD","bids":[{"price":1773.17,"qty":18.66066520},{"price":1773.18,"qty":7.24970424}],"asks":[],"checksum":2354617673,"timestamp":"2026-07-07T23:00:06.292803Z"}]}
{"channel":"book","type":"update","data":[{"symbol":"BTC/USD","bids":[],"asks":[{"price":63498.6,"qty":0.00000000},{"price":63504.0,"qty":0.00005100},{"price":63501.4,"qty":2.36281698}],"checksum":2747572995,"timestamp":"2026-07-07T23:00:06.293286Z"}]}
{"channel":"book","type":"update","data":[{"symbol":"ETH/USD","bids":[],"asks":[{"price":1773.78,"qty":2.81884739}],"checksum":209672478,"timestamp":"2026-07-07T23:00:06.293383Z"}]}
{"channel":"book","type":"update","data":[{"symbol":"ETH/USD","bids":[],"asks":[{"price":1773.78,"qty":0.00000000},{"price":1774.14,"qty":11.00244117}],"checksum":2354617673,"timestamp":"2026-07-07T23:00:06.294236Z"}]}
{"channel":"book","type":"update","data":[{"symbol":"ETH/USD","bids":[{"price":1773.16,"qty":1.30000000}],"asks":[],"checksum":2956511777,"timestamp":"2026-07-07T23:00:06.294309Z"}]}
{"channel":"book","type":"update","data":[{"symbol":"ETH/USD","bids":[{"price":1773.32,"qty":19.84616104}],"asks":[],"checksum":159414713,"timestamp":"2026-07-07T23:00:06.294830Z"}]}
{"channel":"book","type":"update","data":[{"symbol":"BTC/USD","bids":[{"price":63480.0,"qty":0.60470924}],"asks":[],"checksum":2371719815,"timestamp":"2026-07-07T23:00:06.295051Z"}]}
{"channel":"book","type":"update","data":[{"symbol":"ETH/USD","bids":[],"asks":[{"price":1773.82,"qty":1.30000000}],"checksum":1638096556,"timestamp":"2026-07-07T23:00:06.295033Z"}]}
{"channel":"book","type":"update","data":[{"symbol":"BTC/USD","bids":[{"price":63479.4,"qty":0.21244161}],"asks":[],"checksum":2725801469,"timestamp":"2026-07-07T23:00:06.295086Z"}]}
{"channel":"book","type":"update","data":[{"symbol":"ETH/USD","bids":[],"asks":[{"price":1773.82,"qty":2.83128753}],"checksum":2254736233,"timestamp":"2026-07-07T23:00:06.295158Z"}]}
{"channel":"book","type":"update","data":[{"symbol":"ETH/USD","bids":[],"asks":[{"price":1773.85,"qty":0.50000000}],"checksum":4037517178,"timestamp":"2026-07-07T23:00:06.295306Z"}]}
{"channel":"book","type":"update","data":[{"symbol":"ETH/USD","bids":[],"asks":[{"price":1774.10,"qty":0.00000000},{"price":1774.14,"qty":11.00244117}],"checksum":3180099110,"timestamp":"2026-07-07T23:00:06.295315Z"}]}
{"channel":"book","type":"update","data":[{"symbol":"ETH/USD","bids":[],"asks":[{"price":1773.82,"qty":3.30130641}],"checksum":4206288688,"timestamp":"2026-07-07T23:00:06.295644Z"}]}
{"channel":"book","type":"update","data":[{"symbol":"ETH/USD","bids":[],"asks":[{"price":1773.77,"qty":1.53128753}],"checksum":424506046,"timestamp":"2026-07-07T23:00:06.296049Z"}]}
{"channel":"book","type":"update","data":[{"symbol":"ETH/USD","bids":[],"asks":[{"price":1773.84,"qty":27.93226731}],"checksum":1044316363,"timestamp":"2026-07-07T23:00:06.296352Z"}]}
{"channel":"book","type":"update","data":[{"symbol":"ETH/USD","bids":[],"asks":[{"price":1773.77,"qty":2.00130641}],"checksum":801009419,"timestamp":"2026-07-07T23:00:06.296365Z"}]}
{"channel":"book","type":"update","data":[{"symbol":"ETH/USD","bids":[],"asks":[{"price":1773.77,"qty":0.47001888}],"checksum":2910848814,"timestamp":"2026-07-07T23:00:06.296786Z"}]}
{"channel":"book","type":"update","data":[{"symbol":"ETH/USD","bids":[{"price":1773.17,"qty":7.36051096}],"asks":[],"checksum":427528006,"timestamp":"2026-07-07T23:00:06.296844Z"}]}
{"channel":"book","type":"update","data":[{"symbol":"ETH/USD","bids":[],"asks":[{"price":1773.84,"qty":15.57800000},{"price":1773.96,"qty":12.35426731}],"checksum":2948176739,"timestamp":"2026-07-07T23:00:06.296876Z"}]}
{"channel":"book","type":"update","data":[{"symbol":"ETH/USD","bids":[{"price":1773.33,"qty":5.92407907}],"asks":[],"checksum":92788101,"timestamp":"2026-07-07T23:00:06.297345Z"}]}
{"channel":"book","type":"update","data":[{"symbol":"ETH/USD","bids":[],"asks":[{"price":1773.82,"qty":1.77001888}],"checksum":1113013949,"timestamp":"2026-07-07T23:00:06.297463Z"}]}
{"channel":"book","type":"update","data":[{"symbol":"ETH/USD","bids":[],"asks":[{"price":1773.77,"qty":0.00000000},{"price":1774.13,"qty":3.37402415}],"checksum":2311551329,"timestamp":"2026-07-07T23:00:06.297969Z"}]}
{"channel":"book","type":"update","data":[{"symbol":"BTC/USD","bids":[],"asks":[{"price":63498.5,"qty":0.00000000},{"price":63504.0,"qty":0.00005100}],"checksum":1442900691,"timestamp":"2026-07-07T23:00:06.297980Z"}]}
{"channel":"book","type":"update","data":[{"symbol":"ETH/USD","bids":[],"asks":[{"price":1774.10,"qty":6.44944554}],"checksum":2267415207,"timestamp":"2026-07-07T23:00:06.298134Z"}]}
{"channel":"book","type":"update","data":[{"symbol":"BTC/USD","bids":[],"asks":[{"price":63498.5,"qty":0.35444250}],"checksum":1791896900,"timestamp":"2026-07-07T23:00:06.298169Z"}]}
{"channel":"book","type":"update","data":[{"symbol":"ETH/USD","bids":[],"asks":[{"price":1774.11,"qty":6.62830000}],"checksum":984736493,"timestamp":"2026-07-07T23:00:06.298986Z"}]}
{"channel":"book","type":"update","data":[{"symbol":"ETH/USD","bids":[],"asks":[{"price":1773.81,"qty":1.53128753}],"checksum":1108269113,"timestamp":"2026-07-07T23:00:06.299060Z"}]}
{"channel":"book","type":"update","data":[{"symbol":"BTC/USD","bids":[],"asks":[{"price":63501.4,"qty":0.00000000},{"price":63504.0,"qty":0.00005100}],"checksum":3436370399,"timestamp":"2026-07-07T23:00:06.299163Z"}]}
{"channel":"book","type":"update","data":[{"symbol":"ETH/USD","bids":[],"asks":[{"price":1773.83,"qty":0.00000000},{"price":1774.12,"qty":2.79747210}],"checksum":2820964515,"timestamp":"2026-07-07T23:00:06.299639Z"}]}
{"channel":"book","type":"update","data":[{"symbol":"BTC/USD","bids":[{"price":63479.4,"qty":0.00000000},{"price":63478.8,"qty":0.05990000}],"asks":[],"checksum":3072794018,"timestamp":"2026-07-07T23:00:06.300420Z"}]}
{"channel":"book","type":"update","data":[{"symbol":"BTC/USD","bids":[{"price":63480.1,"qty":0.19843379}],"asks":[],"checksum":2994697255,"timestamp":"2026-07-07T23:00:06.300692Z"}]}
{"channel":"book","type":"update","data":[{"symbol":"ETH/USD","bids":[],"asks":[{"price":1773.76,"qty":1.53128753}],"checksum":3185834748,"timestamp":"2026-07-07T23:00:06.300825Z"}]}
{"channel":"book","type":"update","data":[{"symbol":"ETH/USD","bids":[],"asks":[{"price":1773.76,"qty":2.12867749}],"checksum":3269911592,"timestamp":"2026-07-07T23:00:06.300884Z"}]}
{"channel":"book","type":"update","data":[{"symbol":"BTC/USD","bids":[],"asks":[{"price":63498.1,"qty":2.54538427}],"checksum":2888208219,"timestamp":"2026-07-07T23:00:06.300995Z"}]}
{"channel":"book","type":"update","data":[{"symbol":"ETH/USD","bids":[],"asks":[{"price":1773.76,"qty":0.59738996}],"checksum":1605480467,"timestamp":"2026-07-07T23:00:06.301042Z"}]}
{"channel":"book","type":"update","data":[{"symbol":"ETH/USD","bids":[],"asks":[{"price":1773.83,"qty":5.18733300}],"checksum":3926462259,"timestamp":"2026-07-07T23:00:06.301093Z"}]}
{"channel":"book","type":"update","data":[{"symbol":"ETH/USD","bids":[],"asks":[{"price":1773.76,"qty":0.00000000},{"price":1774.11,"qty":6.62830000}],"checksum":221792221,"timestamp":"2026-07-07T23:00:06.301124Z"}]}
{"channel":"book","type":"update","data":[{"symbol":"ETH/USD","bids":[],"asks":[{"price":1773.95,"qty":4.13014047}],"checksum":2796294692,"timestamp":"2026-07-07T23:00:06.302281Z"}]}
{"channel":"book","type":"update","data":[{"symbol":"ETH/USD","bids":[{"price":1773.48,"qty":2.81931091}],"asks":[],"checksum":1624068082,"timestamp":"2026-07-07T23:00:06.302928Z"}]}
{"channel":"book","type":"update","data":[{"symbol":"ETH/USD","bids":[],"asks":[{"price":1773.96,"qty":0.00000000},{"price":1774.11,"qty":6.62830000},{"price":1774.09,"qty":12.35426731}],"checksum":459698527,"timestamp":"2026-07-07T23:00:06.302964Z"}]}
{"channel":"book","type":"update","data":[{"symbol":"ETH/USD","bids":[],"asks":[{"price":1773.80,"qty":0.47001888}],"checksum":3839384740,"timestamp":"2026-07-07T23:00:06.304838Z"}]}
{"channel":"book","type":"update","data":[{"symbol":"ETH/USD","bids":[],"asks":[{"price":1773.75,"qty":1.53128753}],"checksum":213701669,"timestamp":"2026-07-07T23:00:06.305841Z"}]}
{"channel":"book","type":"update","data":[{"symbol":"ETH/USD","bids":[],"asks":[{"price":1773.75,"qty":0.00000000},{"price":1774.09,"qty":12.35426731}],"checksum":3839384740,"timestamp":"2026-07-07T23:00:06.305977Z"}]}
{"channel":"book","type":"update","data":[{"symbol":"ETH/USD","bids":[{"price":1773.55,"qty":0.48930000}],"asks":[],"checksum":2761185910,"timestamp":"2026-07-07T23:00:06.306252Z"}]}
{"channel":"book","type":"update","data":[{"symbol":"ETH/USD","bids":[],"asks":[{"price":1774.03,"qty":19.84616104}],"checksum":2083690931,"timestamp":"2026-07-07T23:00:06.306343Z"}]}
{"channel":"book","type":"update","data":[{"symbol":"ETH/USD","bids":[{"price":1773.48,"qty":0.00000000},{"price":1773.18,"qty":7.24970424}],"asks":[],"checksum":2274738420,"timestamp":"2026-07-07T23:00:06.306676Z"}]}
{"channel":"book","type":"update","data":[{"symbol":"ETH/USD","bids":[],"asks":[{"price":1773.90,"qty":0.31674471}],"checksum":819951834,"timestamp":"2026-07-07T23:00:06.308823Z"}]}
{"channel":"book","type":"update","data":[{"symbol":"ETH/USD","bids":[],"asks":[{"price":1773.95,"qty":0.00000000},{"price":1774.03,"qty":19.84616104}],"checksum":2236307389,"timestamp":"2026-07-07T23:00:06.308978Z"}]}
{"channel":"book","type":"update","data":[{"symbol":"ETH/USD","bids":[{"price":1773.34,"qty":28.19003267}],"asks":[],"checksum":3838364065,"timestamp":"2026-07-07T23:00:06.309358Z"}]}
{"channel":"book","type":"update","data":[{"symbol":"ETH/USD","bids":[],"asks":[{"price":1773.79,"qty":1.53128753}],"checksum":359181312,"timestamp":"2026-07-07T23:00:06.309809Z"}]}
{"channel":"book","type":"update","data":[{"symbol":"ETH/USD","bids":[{"price":1773.34,"qty":33.75006715}],"asks":[],"checksum":3270078752,"timestamp":"2026-07-07T23:00:06.310951Z"}]}
{"channel":"book","type":"update","data":[{"symbol":"ETH/USD","bids":[],"asks":[{"price":1773.79,"qty":2.12867749}],"checksum":1715786562,"timestamp":"2026-07-07T23:00:06.311190Z"}]}
{"channel":"book","type":"update","data":[{"symbol":"ETH/USD","bids":[{"price":1773.33,"qty":0.00000000},{"price":1773.18,"qty":1.68966976}],"asks":[],"checksum":2677180363,"timestamp":"2026-07-07T23:00:06.312997Z"}]}
{"channel":"book","type":"update","data":[{"symbol":"ETH/USD","bids":[],"asks":[{"price":1773.79,"qty":1.53128753}],"checksum":993994153,"timestamp":"2026-07-07T23:00:06.313273Z"}]}
{"channel":"book","type":"update","data":[{"symbol":"ETH/USD","bids":[{"price":1773.19,"qty":0.03180000}],"asks":[],"checksum":490068963,"timestamp":"2026-07-07T23:00:06.313880Z"}]}
{"channel":"book","type":"update","data":[{"symbol":"ETH/USD","bids":[],"asks":[{"price":1773.78,"qty":1.05447929}],"checksum":3755914212,"timestamp":"2026-07-07T23:00:06.315090Z"}]}
{"channel":"book","type":"update","data":[{"symbol":"ETH/USD","bids":[{"price":1773.35,"qty":15.99847411}],"asks":[],"checksum":657136769,"timestamp":"2026-07-07T23:00:06.315242Z"}]}
{"channel":"book","type":"update","data":[{"symbol":"ETH/USD","bids":[{"price":1773.24,"qty":0.65415936}],"asks":[],"checksum":4214614112,"timestamp":"2026-07-07T23:00:06.315805Z"}]}
{"channel":"book","type":"update","data":[{"symbol":"ETH/USD","bids":[],"asks":[{"price":1773.77,"qty":1.53128753}],"checksum":1643353346,"timestamp":"2026-07-07T23:00:06.317157Z"}]}
{"channel":"book","type":"update","data":[{"symbol":"ETH/USD","bids":[],"asks":[{"price":1773.79,"qty":0.00000000},{"price":1773.90,"qty":0.31674471}],"checksum":35610116,"timestamp":"2026-07-07T23:00:06.318198Z"}]}
{"channel":"book","type":"update","data":[{"symbol":"ETH/USD","bids":[],"asks":[{"price":1773.78,"qty":1.65186925}],"checksum":4119353678,"timestamp":"2026-07-07T23:00:06.320102Z"}]}
{"channel":"book","type":"update","data":[{"symbol":"ETH/USD","bids":[],"asks":[{"price":1773.78,"qty":0.59738996}],"checksum":1853947065,"timestamp":"2026-07-07T23:00:06.320303Z"}]}
{"channel":"book","type":"update","data":[{"symbol":"ETH/USD","bids":[{"price":1773.34,"qty":28.19003267},{"price":1773.36,"qty":5.56003448}],"asks":[],"checksum":1954034078,"timestamp":"2026-07-07T23:00:06.334289Z"}]}
{"channel":"book","type":"update","data":[{"symbol":"BTC/USD","bids":[{"price":63480.0,"qty":0.00000000},{"price":63478.8,"qty":0.05990000}],"asks":[],"checksum":1078387745,"timestamp":"2026-07-07T23:00:06.343848Z"}]}
{"channel":"book","type":"update","data":[{"symbol":"ETH/USD","bids":[{"price":1773.55,"qty":0.00000000},{"price":1773.23,"qty":0.47001888}],"asks":[],"checksum":985205546,"timestamp":"2026-07-07T23:00:06.346687Z"}]}
{"channel":"book","type":"update","data":[{"symbol":"BTC/USD","bids":[{"price":63480.1,"qty":0.00000000},{"price":63478.6,"qty":0.00016057}],"asks":[],"checksum":3442984096,"timestamp":"2026-07-07T23:00:06.347838Z"}]}
{"channel":"book","type":"update","data":[{"symbol":"BTC/USD","bids":[{"price":63480.1,"qty":0.01792808}],"asks":[],"checksum":2664954100,"timestamp":"2026-07-07T23:00:06.348283Z"}]}
{"channel":"book","type":"update","data":[{"symbol":"ETH/USD","bids":[],"asks":[{"price":1773.86,"qty":2.81872118}],"checksum":2452327542,"timestamp":"2026-07-07T23:00:06.359305Z"}]}
{"channel":"book","type":"update","data":[{"symbol":"ETH/USD","bids":[{"price":1773.42,"qty":2.81941108}],"asks":[],"checksum":4202612498,"timestamp":"2026-07-07T23:00:06.359651Z"}]}
{"channel":"book","type":"update","data":[{"symbol":"ETH/USD","bids":[],"asks":[{"price":1773.78,"qty":0.00000000},{"price":1773.90,"qty":0.31674471}],"checksum":3656986570,"timestamp":"2026-07-07T23:00:06.360033Z"}]}
{"channel":"book","type":"update","data":[{"symbol":"ETH/USD","bids":[{"price":1773.42,"qty":0.00000000},{"price":1773.23,"qty":0.47001888}],"asks":[],"checksum":3433360257,"timestamp":"2026-07-07T23:00:06.361518Z"}]}
{"channel":"book","type":"update","data":[{"symbol":"ETH/USD","bids":[{"price":1773.43,"qty":3.05069876}],"asks":[],"checksum":3127880335,"timestamp":"2026-07-07T23:00:06.361986Z"}]}
{"channel":"book","type":"update","data":[{"symbol":"ETH/USD","bids":[{"price":1773.43,"qty":3.38749307}],"asks":[],"checksum":3673560046,"timestamp":"2026-07-07T23:00:06.362343Z"}]}
{"channel":"book","type":"update","data":[{"symbol":"ETH/USD","bids":[{"price":1773.52,"qty":0.48930000}],"asks":[],"checksum":3264439066,"timestamp":"2026-07-07T23:00:06.362460Z"}]}
{"channel":"book","type":"update","data":[{"symbol":"ETH/USD","bids":[{"price":1773.41,"qty":0.00000000},{"price":1773.24,"qty":0.65415936}],"asks":[],"checksum":4165870751,"timestamp":"2026-07-07T23:00:06.362698Z"}]}
{"channel":"book","type":"update","data":[{"symbol":"ETH/USD","bids":[{"price":1773.43,"qty":0.33679431}],"asks":[],"checksum":265902676,"timestamp":"2026-07-07T23:00:06.363986Z"}]}
{"channel":"book","type":"update","data":[{"symbol":"BTC/USD","bids":[{"price":63480.1,"qty":0.00000000},{"price":63478.6,"qty":0.00016057}],"asks":[],"checksum":3442984096,"timestamp":"2026-07-07T23:00:06.364214Z"}]}
{"channel":"book","type":"update","data":[{"symbol":"ETH/USD","bids":[{"price":1773.38,"qty":0.00000000},{"price":1773.23,"qty":0.47001888}],"asks":[],"checksum":1835084802,"timestamp":"2026-07-07T23:00:06.364253Z"}]}
{"channel":"book","type":"update","data":[{"symbol":"ETH/USD","bids":[],"asks":[{"price":1773.86,"qty":0.00000000},{"price":1773.93,"qty":0.32659670}],"checksum":383078052,"timestamp":"2026-07-07T23:00:06.365152Z"}]}
{"channel":"book","type":"update","data":[{"symbol":"ETH/USD","bids":[{"price":1773.39,"qty":2.72714142}],"asks":[],"checksum":3177486407,"timestamp":"2026-07-07T23:00:06.365951Z"}]}
{"channel":"book","type":"update","data":[{"symbol":"BTC/USD","bids":[{"price":63478.9,"qty":0.01792808}],"asks":[],"checksum":1952844810,"timestamp":"2026-07-07T23:00:06.366206Z"}]}
{"channel":"book","type":"update","data":[{"symbol":"BTC/USD","bids":[{"price":63478.9,"qty":0.00000000},{"price":63478.6,"qty":0.00016057}],"asks":[],"checksum":3442984096,"timestamp":"2026-07-07T23:00:06.367842Z"}]}
{"channel":"book","type":"update","data":[{"symbol":"ETH/USD","bids":[],"asks":[{"price":1773.77,"qty":2.02058753}],"checksum":1981100663,"timestamp":"2026-07-07T23:00:06.369033Z"}]}
{"channel":"book","type":"update","data":[{"symbol":"ETH/USD","bids":[{"price":1773.52,"qty":0.00000000},{"price":1773.19,"qty":0.03180000}],"asks":[],"checksum":76792814,"timestamp":"2026-07-07T23:00:06.369076Z"}]}
{"channel":"book","type":"update","data":[{"symbol":"ETH/USD","bids":[{"price":1773.34,"qty":0.00000000},{"price":1773.18,"qty":1.68966976},{"price":1773.25,"qty":28.19106278}],"asks":[],"checksum":3426445525,"timestamp":"2026-07-07T23:00:06.369901Z"}]}
{"channel":"book","type":"update","data":[{"symbol":"ETH/USD","bids":[{"price":1773.48,"qty":0.48930000}],"asks":[],"checksum":4010855736,"timestamp":"2026-07-07T23:00:06.371202Z"}]}
{"channel":"book","type":"update","data":[{"symbol":"ETH/USD","bids":[{"price":1773.39,"qty":2.23784142}],"asks":[],"checksum":3617327262,"timestamp":"2026-07-07T23:00:06.371650Z"}]}
{"channel":"book","type":"update","data":[{"symbol":"ETH/USD","bids":[{"price":1773.24,"qty":0.00000000},{"price":1773.19,"qty":0.03180000}],"asks":[],"checksum":1465215295,"timestamp":"2026-07-07T23:00:06.372190Z"}]}
{"channel":"book","type":"update","data":[{"symbol":"ETH/USD","bids":[{"price":1773.35,"qty":0.00000000},{"price":1773.18,"qty":1.68966976}],"asks":[],"checksum":1440784799,"timestamp":"2026-07-07T23:00:06.372418Z"}]}
{"channel":"book","type":"update","data":[{"symbol":"ETH/USD","bids":[],"asks":[{"price":1773.76,"qty":1.20053534}],"checksum":4288583551,"timestamp":"2026-07-07T23:00:06.374402Z"}]}
{"channel":"book","type":"update","data":[{"symbol":"ETH/USD","bids":[{"price":1773.36,"qty":0.00000000},{"price":1773.17,"qty":7.36051096},{"price":1773.33,"qty":5.56003448}],"asks":[],"checksum":383955661,"timestamp":"2026-07-07T23:00:06.374436Z"}]}
{"channel":"book","type":"update","data":[{"symbol":"ETH/USD","bids":[{"price":1773.30,"qty":0.48930000}],"asks":[],"checksum":1429301747,"timestamp":"2026-07-07T23:00:06.374645Z"}]}
{"channel":"book","type":"update","data":[{"symbol":"ETH/USD","bids":[{"price":1773.33,"qty":11.48411355}],"asks":[],"checksum":4262027904,"timestamp":"2026-07-07T23:00:06.375133Z"}]}
{"channel":"book","type":"update","data":[{"symbol":"ETH/USD","bids":[{"price":1773.39,"qty":0.45737557}],"asks":[],"checksum":618661300,"timestamp":"2026-07-07T23:00:06.378413Z"}]}
{"channel":"book","type":"update","data":[{"symbol":"ETH/USD","bids":[],"asks":[{"price":1773.76,"qty":1.68983534}],"checksum":149776285,"timestamp":"2026-07-07T23:00:06.378976Z"}]}
{"channel":"book","type":"update","data":[{"symbol":"ETH/USD","bids":[],"asks":[{"price":1773.75,"qty":1.53128753}],"checksum":27785022,"timestamp":"2026-07-07T23:00:06.378992Z"}]}
{"channel":"book","type":"update","data":[{"symbol":"ETH/USD","bids":[],"asks":[{"price":1773.77,"qty":1.53128753}],"checksum":3098105281,"timestamp":"2026-07-07T23:00:06.379113Z"}]}
{"channel":"book","type":"update","data":[{"symbol":"ETH/USD","bids":[],"asks":[{"price":1773.77,"qty":0.00000000},{"price":1773.90,"qty":0.31674471}],"checksum":3148888421,"timestamp":"2026-07-07T23:00:06.380279Z"}]}
{"channel":"book","type":"update","data":[{"symbol":"ETH/USD","bids":[{"price":1773.26,"qty":9.06919160}],"asks":[],"checksum":4266936662,"timestamp":"2026-07-07T23:00:06.380511Z"}]}
{"channel":"book","type":"update","data":[{"symbol":"ETH/USD","bids":[],"asks":[{"price":1773.76,"qty":0.48930000}],"checksum":500466261,"timestamp":"2026-07-07T23:00:06.381046Z"}]}
{"channel":"book","type":"update","data":[{"symbol":"ETH/USD","bids":[],"asks":[{"price":1773.75,"qty":2.02058753}],"checksum":231554789,"timestamp":"2026-07-07T23:00:06.381915Z"}]}
{"channel":"book","type":"update","data":[{"symbol":"ETH/USD","bids":[],"asks":[{"price":1773.76,"qty":0.00000000},{"price":1773.93,"qty":0.32659670}],"checksum":2971651811,"timestamp":"2026-07-07T23:00:06.382285Z"}]}
{"channel":"book","type":"update","data":[{"symbol":"ETH/USD","bids":[],"asks":[{"price":1773.74,"qty":1.20053534}],"checksum":1539566520,"timestamp":"2026-07-07T23:00:06.383880Z"}]}
{"channel":"book","type":"update","data":[{"symbol":"ETH/USD","bids":[],"asks":[{"price":1773.73,"qty":1.53128753}],"checksum":595838735,"timestamp":"2026-07-07T23:00:06.385657Z"}]}
{"channel":"book","type":"update","data":[{"symbol":"ETH/USD","bids":[],"asks":[{"price":1773.75,"qty":0.48930000}],"checksum":24332362,"timestamp":"2026-07-07T23:00:06.386830Z"}]}
{"channel":"book","type":"update","data":[{"symbol":"ETH/USD","bids":[],"asks":[{"price":1773.74,"qty":0.00000000},{"price":1773.90,"qty":0.31674471}],"checksum":922989405,"timestamp":"2026-07-07T23:00:06.388337Z"}]}
{"channel":"book","type":"update","data":[{"symbol":"ETH/USD","bids":[],"asks":[{"price":1773.72,"qty":1.20053534}],"checksum":365775487,"timestamp":"2026-07-07T23:00:06.390252Z"}]}
{"channel":"book","type":"update","data":[{"symbol":"ETH/USD","bids":[],"asks":[{"price":1773.73,"qty":0.00000000},{"price":1773.90,"qty":0.31674471}],"checksum":684128766,"timestamp":"2026-07-07T23:00:06.392626Z"}]}
{"channel":"book","type":"update","data":[{"symbol":"ETH/USD","bids":[],"asks":[{"price":1773.72,"qty":0.00000000},{"price":1773.93,"qty":0.81589670}],"checksum":1692850434,"timestamp":"2026-07-07T23:00:06.394009Z"}]}
{"channel":"book","type":"update","data":[{"symbol":"ETH/USD","bids":[],"asks":[{"price":1773.74,"qty":1.53128753}],"checksum":4072219122,"timestamp":"2026-07-07T23:00:06.396035Z"}]}
{"channel":"book","type":"update","data":[{"symbol":"ETH/USD","bids":[],"asks":[{"price":1773.89,"qty":0.00000000},{"price":1773.93,"qty":0.81589670}],"checksum":2393021940,"timestamp":"2026-07-07T23:00:06.396334Z"}]}
{"channel":"book","type":"update","data":[{"symbol":"ETH/USD","bids":[],"asks":[{"price":1773.79,"qty":0.59738996}],"checksum":3855309793,"timestamp":"2026-07-07T23:00:06.396386Z"}]}
{"channel":"book","type":"update","data":[{"symbol":"ETH/USD","bids":[],"asks":[{"price":1773.73,"qty":1.30000000}],"checksum":2789393907,"timestamp":"2026-07-07T23:00:06.397714Z"}]}
{"channel":"book","type":"update","data":[{"symbol":"ETH/USD","bids":[],"asks":[{"price":1773.79,"qty":0.00000000},{"price":1773.90,"qty":0.31674471}],"checksum":4062119946,"timestamp":"2026-07-07T23:00:06.398693Z"}]}
{"channel":"book","type":"update","data":[{"symbol":"ETH/USD","bids":[],"asks":[{"price":1773.82,"qty":1.30000000}],"checksum":2264538158,"timestamp":"2026-07-07T23:00:06.398732Z"}]}
{"channel":"book","type":"update","data":[{"symbol":"ETH/USD","bids":[],"asks":[{"price":1773.74,"qty":2.02058753}],"checksum":644991478,"timestamp":"2026-07-07T23:00:06.400872Z"}]}
{"channel":"book","type":"update","data":[{"symbol":"ETH/USD","bids":[],"asks":[{"price":1773.75,"qty":0.00000000},{"price":1773.93,"qty":0.81589670}],"checksum":3920423533,"timestamp":"2026-07-07T23:00:06.401239Z"}]}
{"channel":"book","type":"update","data":[{"symbol":"ETH/USD","bids":[],"asks":[{"price":1773.72,"qty":0.47001888}],"checksum":1049222244,"timestamp":"2026-07-07T23:00:06.401915Z"}]}
{"channel":"book","type":"update","data":[{"symbol":"ETH/USD","bids":[],"asks":[{"price":1773.72,"qty":2.05860422}],"checksum":927091243,"timestamp":"2026-07-07T23:00:06.401983Z"}]}
{"channel":"book","type":"update","data":[{"symbol":"ETH/USD","bids":[],"asks":[{"price":1773.81,"qty":0.00000000},{"price":1773.93,"qty":0.81589670}],"checksum":574552509,"timestamp":"2026-07-07T23:00:06.402301Z"}]}
{"channel":"book","type":"update","data":[{"symbol":"BTC/USD","bids":[{"price":63483.1,"qty":0.78761113}],"asks":[],"checksum":430659040,"timestamp":"2026-07-07T23:00:06.403782Z"}]}
{"channel":"book","type":"update","data":[{"symbol":"ETH/USD","bids":[],"asks":[{"price":1773.72,"qty":0.47001888}],"checksum":1608818097,"timestamp":"2026-07-07T23:00:06.404657Z"}]}
{"channel":"book","type":"update","data":[{"symbol":"ETH/USD","bids":[],"asks":[{"price":1773.72,"qty":1.60151489}],"checksum":336038486,"timestamp":"2026-07-07T23:00:06.406289Z"}]}
{"channel":"book","type":"update","data":[{"symbol":"ETH/USD","bids":[{"price":1773.33,"qty":5.56003448}],"asks":[],"checksum":3833941399,"timestamp":"2026-07-07T23:00:06.406879Z"}]}
{"channel":"book","type":"update","data":[{"symbol":"ETH/USD","bids":[{"price":1773.48,"qty":0.00000000},{"price":1773.19,"qty":0.03180000}],"asks":[],"checksum":1065689730,"timestamp":"2026-07-07T23:00:06.407674Z"}]}
{"channel":"book","type":"update","data":[{"symbol":"ETH/USD","bids":[{"price":1773.45,"qty":0.48930000}],"asks":[],"checksum":1030649377,"timestamp":"2026-07-07T23:00:06.408851Z"}]}
{"channel":"book","type":"update","data":[{"symbol":"ETH/USD","bids":[],"asks":[{"price":1773.72,"qty":2.09081489}],"checksum":1577074339,"timestamp":"2026-07-07T23:00:06.437830Z"}]}
{"channel":"book","type":"update","data":[{"symbol":"ETH/USD","bids":[],"asks":[{"price":1773.71,"qty":0.32402984}],"checksum":243812906,"timestamp":"2026-07-07T23:00:06.438393Z"}]}
{"channel":"book","type":"update","data":[{"symbol":"ETH/USD","bids":[],"asks":[{"price":1773.74,"qty":1.53128753}],"checksum":2518477745,"timestamp":"2026-07-07T23:00:06.438539Z"}]}
{"channel":"book","type":"update","data":[{"symbol":"ETH/USD","bids":[],"asks":[{"price":1773.73,"qty":0.00000000},{"price":1773.93,"qty":0.48930000}],"checksum":144515083,"timestamp":"2026-07-07T23:00:06.439647Z"}]}
{"channel":"book","type":"update","data":[{"symbol":"ETH/USD","bids":[],"asks":[{"price":1773.72,"qty":0.95931888}],"checksum":1783593766,"timestamp":"2026-07-07T23:00:06.440798Z"}]}
{"channel":"book","type":"update","data":[{"symbol":"ETH/USD","bids":[],"asks":[{"price":1773.92,"qty":0.58844773}],"checksum":1229290528,"timestamp":"2026-07-07T23:00:06.440825Z"}]}
{"channel":"book","type":"update","data":[{"symbol":"ETH/USD","bids":[],"asks":[{"price":1773.72,"qty":1.55670884}],"checksum":455699943,"timestamp":"2026-07-07T23:00:06.440929Z"}]}
{"channel":"book","type":"update","data":[{"symbol":"BTC/USD","bids":[{"price":63480.0,"qty":0.60470924}],"asks":[],"checksum":1075613900,"timestamp":"2026-07-07T23:00:06.446883Z"}]}
{"channel":"book","type":"update","data":[{"symbol":"ETH/USD","bids":[],"asks":[{"price":1773.71,"qty":3.14298385}],"checksum":938976269,"timestamp":"2026-07-07T23:00:06.458829Z"}]}
{"channel":"book","type":"update","data":[{"symbol":"ETH/USD","bids":[{"price":1773.40,"qty":2.81943302}],"asks":[],"checksum":3628438681,"timestamp":"2026-07-07T23:00:06.459106Z"}]}
{"channel":"book","type":"update","data":[{"symbol":"ETH/USD","bids":[{"price":1773.25,"qty":29.88073254}],"asks":[],"checksum":52707691,"timestamp":"2026-07-07T23:00:06.459224Z"}]}
{"channel":"book","type":"update","data":[{"symbol":"ETH/USD","bids":[],"asks":[{"price":1773.70,"qty":1.22453736}],"checksum":1489034153,"timestamp":"2026-07-07T23:00:06.460700Z"}]}
{"channel":"book","type":"update","data":[{"symbol":"ETH/USD","bids":[{"price":1773.34,"qty":7.42266310}],"asks":[],"checksum":4246681098,"timestamp":"2026-07-07T23:00:06.460918Z"}]}
{"channel":"book","type":"update","data":[{"symbol":"ETH/USD","bids":[{"price":1773.33,"qty":0.00000000},{"price":1773.25,"qty":29.88073254},{"price":1773.35,"qty":5.56003448}],"asks":[],"checksum":486317094,"timestamp":"2026-07-07T23:00:06.461976Z"}]}
{"channel":"book","type":"update","data":[{"symbol":"BTC/USD","bids":[],"asks":[{"price":63500.8,"qty":0.00005100}],"checksum":3246412651,"timestamp":"2026-07-07T23:00:06.496215Z"}]}
{"channel":"book","type":"update","data":[{"symbol":"ETH/USD","bids":[],"asks":[{"price":1773.82,"qty":0.00000000},{"price":1773.92,"qty":0.58844773}],"checksum":1076285749,"timestamp":"2026-07-07T23:00:06.498881Z"}]}
{"channel":"book","type":"update","data":[{"symbol":"ETH/USD","bids":[],"asks":[{"price":1773.80,"qty":0.00000000},{"price":1773.93,"qty":0.48930000}],"checksum":1591649319,"timestamp":"2026-07-07T23:00:06.503079Z"}]}
{"channel":"book","type":"update","data":[{"symbol":"ETH/USD","bids":[],"asks":[{"price":1773.89,"qty":1.30000000}],"checksum":798932284,"timestamp":"2026-07-07T23:00:06.504299Z"}]}
{"channel":"book","type":"update","data":[{"symbol":"ETH/USD","bids":[],"asks":[{"price":1773.69,"qty":0.47001888}],"checksum":1922299139,"timestamp":"2026-07-07T23:00:06.504388Z"}]}
{"channel":"book","type":"update","data":[{"symbol":"ETH/USD","bids":[],"asks":[{"price":1773.76,"qty":0.31674471}],"checksum":1133647457,"timestamp":"2026-07-07T23:00:06.538533Z"}]}
{"channel":"book","type":"update","data":[{"symbol":"ETH/USD","bids":[{"price":1773.40,"qty":0.00000000},{"price":1773.25,"qty":29.88073254}],"asks":[],"checksum":973834643,"timestamp":"2026-07-07T23:00:06.544960Z"}]}
{"channel":"book","type":"update","data":[{"symbol":"ETH/USD","bids":[{"price":1773.44,"qty":2.81936491}],"asks":[],"checksum":2832365099,"timestamp":"2026-07-07T23:00:06.546560Z"}]}
{"channel":"heartbeat"}
{"channel":"book","type":"update","data":[{"symbol":"ETH/USD","bids":[{"price":1773.30,"qty":0.00000000},{"price":1773.25,"qty":29.88073254}],"asks":[],"checksum":2763651049,"timestamp":"2026-07-07T23:00:06.562797Z"}]}
{"channel":"book","type":"update","data":[{"symbol":"ETH/USD","bids":[{"price":1773.27,"qty":0.48930000}],"asks":[],"checksum":1010946386,"timestamp":"2026-07-07T23:00:06.566920Z"}]}
{"channel":"book","type":"update","data":[{"symbol":"BTC/USD","bids":[{"price":63483.1,"qty":0.00000000},{"price":63478.8,"qty":0.05990000}],"asks":[],"checksum":3455804388,"timestamp":"2026-07-07T23:00:06.580764Z"}]}
{"channel":"book","type":"update","data":[{"symbol":"BTC/USD","bids":[{"price":63481.4,"qty":0.78763219}],"asks":[],"checksum":109539317,"timestamp":"2026-07-07T23:00:06.584627Z"}]}
{"channel":"book","type":"update","data":[{"symbol":"ETH/USD","bids":[],"asks":[{"price":1773.72,"qty":1.08668996}],"checksum":2154002988,"timestamp":"2026-07-07T23:00:06.605527Z"}]}
{"channel":"book","type":"update","data":[{"symbol":"ETH/USD","bids":[{"price":1773.34,"qty":0.00000000},{"price":1773.25,"qty":29.88073254}],"asks":[],"checksum":854153259,"timestamp":"2026-07-07T23:00:06.630545Z"}]}
{"channel":"book","type":"update","data":[{"symbol":"ETH/USD","bids":[{"price":1773.35,"qty":0.00000000},{"price":1773.23,"qty":0.47001888},{"price":1773.33,"qty":5.56003448}],"asks":[],"checksum":2213450904,"timestamp":"2026-07-07T23:00:06.631821Z"}]}
{"channel":"book","type":"update","data":[{"symbol":"BTC/USD","bids":[],"asks":[{"price":63498.1,"qty":2.60631784}],"checksum":249028329,"timestamp":"2026-07-07T23:00:06.732205Z"}]}
{"channel":"book","type":"update","data":[{"symbol":"ETH/USD","bids":[{"price":1773.34,"qty":7.68127221}],"asks":[],"checksum":3426124590,"timestamp":"2026-07-07T23:00:06.742420Z"}]}
{"channel":"book","type":"update","data":[{"symbol":"ETH/USD","bids":[{"price":1773.33,"qty":0.00000000},{"price":1773.25,"qty":29.88073254},{"price":1773.35,"qty":5.56003448}],"asks":[],"checksum":3623892062,"timestamp":"2026-07-07T23:00:06.743446Z"}]}
{"channel":"book","type":"update","data":[{"symbol":"ETH/USD","bids":[{"price":1773.39,"qty":0.00000000},{"price":1773.25,"qty":29.88073254}],"asks":[],"checksum":341364472,"timestamp":"2026-07-07T23:00:06.831004Z"}]}
{"channel":"book","type":"update","data":[{"symbol":"BTC/USD","bids":[],"asks":[{"price":63501.9,"qty":0.00000000},{"price":63504.0,"qty":0.00005100}],"checksum":4293576974,"timestamp":"2026-07-07T23:00:07.017446Z"}]}
{"channel":"book","type":"update","data":[{"symbol":"BTC/USD","bids":[{"price":63481.4,"qty":0.00000000},{"price":63478.9,"qty":0.03147178}],"asks":[],"checksum":2142554235,"timestamp":"2026-07-07T23:00:07.044708Z"}]}
{"channel":"book","type":"update","data":[{"symbol":"BTC/USD","bids":[{"price":63480.6,"qty":0.78764197}],"asks":[],"checksum":3213732122,"timestamp":"2026-07-07T23:00:07.046316Z"}]}
{"channel":"book","type":"update","data":[{"symbol":"BTC/USD","bids":[{"price":63487.1,"qty":0.00000000},{"price":63478.9,"qty":0.03147178}],"asks":[],"checksum":1772867346,"timestamp":"2026-07-07T23:00:07.052679Z"}]}
{"channel":"book","type":"update","data":[{"symbol":"ETH/USD","bids":[],"asks":[{"price":1773.72,"qty":0.59738996}],"checksum":3642683148,"timestamp":"2026-07-07T23:00:07.106937Z"}]}
{"channel":"book","type":"update","data":[{"symbol":"ETH/USD","bids":[{"price":1773.45,"qty":0.00000000},{"price":1773.24,"qty":0.45737557}],"asks":[],"checksum":611436954,"timestamp":"2026-07-07T23:00:07.157974Z"}]}
{"channel":"book","type":"update","data":[{"symbol":"ETH/USD","bids":[],"asks":[{"price":1773.69,"qty":0.95931888}],"checksum":1792487971,"timestamp":"2026-07-07T23:00:07.158208Z"}]}
{"channel":"book","type":"update","data":[{"symbol":"ETH/USD","bids":[{"price":1773.34,"qty":0.00000000},{"price":1773.23,"qty":28.66706636}],"asks":[],"checksum":2438417483,"timestamp":"2026-07-07T23:00:07.158417Z"}]}
{"channel":"book","type":"update","data":[{"symbol":"ETH/USD","bids":[{"price":1773.35,"qty":0.00000000},{"price":1773.17,"qty":7.36051096},{"price":1773.33,"qty":5.56003448}],"asks":[],"checksum":17719371,"timestamp":"2026-07-07T23:00:07.159584Z"}]}
{"channel":"book","type":"update","data":[{"symbol":"ETH/USD","bids":[{"price":1773.34,"qty":7.28734355}],"asks":[],"checksum":950491115,"timestamp":"2026-07-07T23:00:07.161016Z"}]}
{"channel":"book","type":"update","data":[{"symbol":"ETH/USD","bids":[{"price":1773.34,"qty":0.00000000},{"price":1773.23,"qty":28.66706636}],"asks":[],"checksum":17719371,"timestamp":"2026-07-07T23:00:07.167067Z"}]}
{"channel":"book","type":"update","data":[{"symbol":"ETH/USD","bids":[],"asks":[{"price":1773.71,"qty":0.32402984}],"checksum":2371315679,"timestamp":"2026-07-07T23:00:07.383105Z"}]}
{"channel":"book","type":"update","data":[{"symbol":"ETH/USD","bids":[],"asks":[{"price":1773.68,"qty":2.81899778}],"checksum":1169466945,"timestamp":"2026-07-07T23:00:07.384499Z"}]}
{"channel":"book","type":"update","data":[{"symbol":"ETH/USD","bids":[],"asks":[{"price":1773.70,"qty":0.00000000},{"price":1773.89,"qty":1.30000000}],"checksum":652766463,"timestamp":"2026-07-07T23:00:07.384642Z"}]}
{"channel":"book","type":"update","data":[{"symbol":"ETH/USD","bids":[],"asks":[{"price":1773.88,"qty":28.18683393}],"checksum":789329737,"timestamp":"2026-07-07T23:00:07.384768Z"}]}
{"channel":"book","type":"update","data":[{"symbol":"ETH/USD","bids":[],"asks":[{"price":1773.67,"qty":1.22455043}],"checksum":1384737324,"timestamp":"2026-07-07T23:00:07.386080Z"}]}
{"channel":"book","type":"update","data":[{"symbol":"ETH/USD","bids":[],"asks":[{"price":1773.83,"qty":12.93791263}],"checksum":3305869810,"timestamp":"2026-07-07T23:00:07.388830Z"}]}
{"channel":"book","type":"update","data":[{"symbol":"ETH/USD","bids":[],"asks":[{"price":1773.67,"qty":1.71385043}],"checksum":2958506148,"timestamp":"2026-07-07T23:00:07.400306Z"}]}
{"channel":"book","type":"update","data":[{"symbol":"ETH/USD","bids":[{"price":1773.44,"qty":2.93214008}],"asks":[],"checksum":2523631287,"timestamp":"2026-07-07T23:00:07.400329Z"}]}
{"channel":"book","type":"update","data":[{"symbol":"ETH/USD","bids":[],"asks":[{"price":1773.69,"qty":0.47001888}],"checksum":2326456084,"timestamp":"2026-07-07T23:00:07.400892Z"}]}
{"channel":"book","type":"update","data":[{"symbol":"ETH/USD","bids":[],"asks":[{"price":1773.66,"qty":0.30087264}],"checksum":3151797051,"timestamp":"2026-07-07T23:00:07.411874Z"}]}
{"channel":"book","type":"update","data":[{"symbol":"ETH/USD","bids":[],"asks":[{"price":1773.71,"qty":0.00000000},{"price":1773.85,"qty":0.50000000}],"checksum":3559467750,"timestamp":"2026-07-07T23:00:07.412902Z"}]}
{"channel":"book","type":"update","data":[{"symbol":"ETH/USD","bids":[{"price":1773.25,"qty":1.68966976}],"asks":[],"checksum":765506933,"timestamp":"2026-07-07T23:00:07.429248Z"}]}
{"channel":"book","type":"update","data":[{"symbol":"ETH/USD","bids":[],"asks":[{"price":1773.83,"qty":17.71391391}],"checksum":1730222137,"timestamp":"2026-07-07T23:00:07.446419Z"}]}
{"channel":"book","type":"update","data":[{"symbol":"ETH/USD","bids":[{"price":1773.26,"qty":13.42473454}],"asks":[],"checksum":2197365565,"timestamp":"2026-07-07T23:00:07.486122Z"}]}
{"channel":"heartbeat"}
{"channel":"book","type":"update","data":[{"symbol":"BTC/USD","bids":[{"price":63480.6,"qty":0.00000000},{"price":63478.8,"qty":0.78766386}],"asks":[],"checksum":3576439229,"timestamp":"2026-07-07T23:00:07.613082Z"}]}
{"channel":"book","type":"update","data":[{"symbol":"BTC/USD","bids":[{"price":63481.3,"qty":0.78763294}],"asks":[],"checksum":716434439,"timestamp":"2026-07-07T23:00:07.614443Z"}]}
{"channel":"book","type":"update","data":[{"symbol":"ETH/USD","bids":[],"asks":[{"price":1773.67,"qty":1.22455043}],"checksum":2193005170,"timestamp":"2026-07-07T23:00:07.632355Z"}]}
{"channel":"book","type":"update","data":[{"symbol":"BTC/USD","bids":[{"price":63481.3,"qty":0.00000000},{"price":63478.8,"qty":0.78766386}],"asks":[],"checksum":3576439229,"timestamp":"2026-07-07T23:00:07.736741Z"}]}
{"channel":"book","type":"update","data":[{"symbol":"BTC/USD","bids":[{"price":63480.6,"qty":0.78764108}],"asks":[],"checksum":2916534319,"timestamp":"2026-07-07T23:00:07.738254Z"}]}
{"channel":"book","type":"update","data":[{"symbol":"ETH/USD","bids":[{"price":1773.25,"qty":0.00000000},{"price":1773.18,"qty":28.19284229},{"price":1773.28,"qty":1.68966976}],"asks":[],"checksum":74738162,"timestamp":"2026-07-07T23:00:07.769980Z"}]}
{"channel":"book","type":"update","data":[{"symbol":"ETH/USD","bids":[{"price":1773.34,"qty":7.85057270}],"asks":[],"checksum":3108612038,"timestamp":"2026-07-07T23:00:07.890989Z"}]}
{"channel":"book","type":"update","data":[{"symbol":"ETH/USD","bids":[{"price":1773.34,"qty":0.00000000},{"price":1773.23,"qty":28.66706636}],"asks":[],"checksum":74738162,"timestamp":"2026-07-07T23:00:07.980102Z"}]}
{"channel":"book","type":"update","data":[{"symbol":"BTC/USD","bids":[],"asks":[{"price":63498.1,"qty":2.60731784}],"checksum":2913024034,"timestamp":"2026-07-07T23:00:08.019848Z"}]}
{"channel":"book","type":"update","data":[{"symbol":"BTC/USD","bids":[],"asks":[{"price":63498.1,"qty":2.70229630}],"checksum":3839307013,"timestamp":"2026-07-07T23:00:08.034204Z"}]}
{"channel":"book","type":"update","data":[{"symbol":"ETH/USD","bids":[{"price":1773.44,"qty":0.11277517}],"asks":[],"checksum":3731968359,"timestamp":"2026-07-07T23:00:08.034475Z"}]}
{"channel":"book","type":"update","data":[{"symbol":"ETH/USD","bids":[{"price":1773.39,"qty":2.81944819}],"asks":[],"checksum":3716728693,"timestamp":"2026-07-07T23:00:08.036235Z"}]}
{"channel":"book","type":"update","data":[{"symbol":"ETH/USD","bids":[{"price":1773.39,"qty":0.00000000},{"price":1773.23,"qty":0.47001888}],"asks":[],"checksum":738087571,"timestamp":"2026-07-07T23:00:08.109396Z"}]}
{"channel":"book","type":"update","data":[{"symbol":"ETH/USD","bids":[],"asks":[{"price":1773.68,"qty":0.00000000},{"price":1773.88,"qty":28.18683393}],"checksum":828836481,"timestamp":"2026-07-07T23:00:08.109537Z"}]}
{"channel":"book","type":"update","data":[{"symbol":"ETH/USD","bids":[{"price":1773.26,"qty":9.06919160}],"asks":[],"checksum":402727347,"timestamp":"2026-07-07T23:00:08.109680Z"}]}
{"channel":"book","type":"update","data":[{"symbol":"BTC/USD","bids":[{"price":63480.6,"qty":0.00000000},{"price":63478.8,"qty":0.78766386}],"asks":[],"checksum":2620245143,"timestamp":"2026-07-07T23:00:08.110031Z"}]}
{"channel":"book","type":"update","data":[{"symbol":"BTC/USD","bids":[{"price":63478.9,"qty":0.00000000},{"price":63478.6,"qty":0.00016057}],"asks":[],"checksum":1027012210,"timestamp":"2026-07-07T23:00:08.110379Z"}]}
{"channel":"book","type":"update","data":[{"symbol":"BTC/USD","bids":[{"price":63478.8,"qty":0.00000000},{"price":63477.2,"qty":0.05744528}],"asks":[],"checksum":1847707946,"timestamp":"2026-07-07T23:00:08.110697Z"}]}
{"channel":"book","type":"update","data":[{"symbol":"ETH/USD","bids":[],"asks":[{"price":1773.67,"qty":0.00000000},{"price":1773.89,"qty":1.30000000}],"checksum":3775246668,"timestamp":"2026-07-07T23:00:08.111409Z"}]}
{"channel":"book","type":"update","data":[{"symbol":"ETH/USD","bids":[],"asks":[{"price":1773.61,"qty":2.81911959}],"checksum":2783889487,"timestamp":"2026-07-07T23:00:08.112490Z"}]}
{"channel":"book","type":"update","data":[{"symbol":"ETH/USD","bids":[{"price":1773.25,"qty":2.81966723}],"asks":[],"checksum":52185271,"timestamp":"2026-07-07T23:00:08.112848Z"}]}
{"channel":"book","type":"update","data":[{"symbol":"BTC/USD","bids":[{"price":63478.0,"qty":0.78767355}],"asks":[],"checksum":3603249681,"timestamp":"2026-07-07T23:00:08.113052Z"}]}
{"channel":"book","type":"update","data":[{"symbol":"ETH/USD","bids":[],"asks":[{"price":1773.69,"qty":0.00000000},{"price":1773.89,"qty":1.30000000}],"checksum":3215747342,"timestamp":"2026-07-07T23:00:08.114008Z"}]}
{"channel":"book","type":"update","data":[{"symbol":"BTC/USD","bids":[],"asks":[{"price":63501.4,"qty":2.36289415}],"checksum":2862906431,"timestamp":"2026-07-07T23:00:08.114160Z"}]}
{"channel":"book","type":"update","data":[{"symbol":"ETH/USD","bids":[],"asks":[{"price":1773.71,"qty":0.47001888}],"checksum":3752210208,"timestamp":"2026-07-07T23:00:08.114208Z"}]}
{"channel":"book","type":"update","data":[{"symbol":"ETH/USD","bids":[],"asks":[{"price":1773.60,"qty":0.84150720}],"checksum":1249972448,"timestamp":"2026-07-07T23:00:08.114597Z"}]}
{"channel":"book","type":"update","data":[{"symbol":"BTC/USD","bids":[],"asks":[{"price":63501.5,"qty":0.00000000},{"price":63504.0,"qty":0.00005100}],"checksum":4191173617,"timestamp":"2026-07-07T23:00:08.115831Z"}]}
{"channel":"book","type":"update","data":[{"symbol":"ETH/USD","bids":[{"price":1773.25,"qty":0.00000000},{"price":1773.23,"qty":0.47001888}],"asks":[],"checksum":1374802601,"timestamp":"2026-07-07T23:00:08.117826Z"}]}
{"channel":"book","type":"update","data":[{"symbol":"BTC/USD","bids":[],"asks":[{"price":63501.3,"qty":1.48613164}],"checksum":2824366643,"timestamp":"2026-07-07T23:00:08.118812Z"}]}
{"channel":"book","type":"update","data":[{"symbol":"ETH/USD","bids":[],"asks":[{"price":1773.76,"qty":0.00000000},{"price":1773.88,"qty":28.18683393}],"checksum":552484199,"timestamp":"2026-07-07T23:00:08.130494Z"}]}
{"channel":"book","type":"update","data":[{"symbol":"ETH/USD","bids":[],"asks":[{"price":1773.65,"qty":0.31674471}],"checksum":23992941,"timestamp":"2026-07-07T23:00:08.130844Z"}]}
{"channel":"book","type":"update","data":[{"symbol":"BTC/USD","bids":[],"asks":[{"price":63501.4,"qty":0.00000000},{"price":63504.0,"qty":0.00005100}],"checksum":1826504797,"timestamp":"2026-07-07T23:00:08.132045Z"}]}
{"channel":"book","type":"update","data":[{"symbol":"BTC/USD","bids":[],"asks":[{"price":63501.3,"qty":0.00000000},{"price":63504.7,"qty":2.36288608}],"checksum":1586317622,"timestamp":"2026-07-07T23:00:08.133303Z"}]}
{"channel":"book","type":"update","data":[{"symbol":"BTC/USD","bids":[],"asks":[{"price":63501.3,"qty":0.78080773}],"checksum":4079483227,"timestamp":"2026-07-07T23:00:08.133800Z"}]}
{"channel":"book","type":"update","data":[{"symbol":"BTC/USD","bids":[{"price":63480.0,"qty":0.00000000},{"price":63477.3,"qty":0.03147178}],"asks":[],"checksum":4203086332,"timestamp":"2026-07-07T23:00:08.143516Z"}]}
{"channel":"book","type":"update","data":[{"symbol":"ETH/USD","bids":[],"asks":[{"price":1773.61,"qty":0.00000000},{"price":1773.88,"qty":28.18683393}],"checksum":1246057896,"timestamp":"2026-07-07T23:00:08.152358Z"}]}
{"channel":"book","type":"update","data":[{"symbol":"ETH/USD","bids":[],"asks":[{"price":1773.60,"qty":0.00000000},{"price":1773.89,"qty":1.30000000}],"checksum":4087782145,"timestamp":"2026-07-07T23:00:08.153807Z"}]}
{"channel":"book","type":"update","data":[{"symbol":"ETH/USD","bids":[{"price":1773.32,"qty":0.00000000},{"price":1773.18,"qty":28.19284229}],"asks":[],"checksum":2934308725,"timestamp":"2026-07-07T23:00:08.155317Z"}]}
{"channel":"book","type":"update","data":[{"symbol":"ETH/USD","bids":[],"asks":[{"price":1773.65,"qty":0.80604471}],"checksum":1655954633,"timestamp":"2026-07-07T23:00:08.156653Z"}]}
{"channel":"book","type":"update","data":[{"symbol":"ETH/USD","bids":[{"price":1773.33,"qty":0.00000000},{"price":1773.16,"qty":1.30000000},{"price":1773.19,"qty":5.56003448}],"asks":[],"checksum":716104550,"timestamp":"2026-07-07T23:00:08.156785Z"}]}
{"channel":"book","type":"update","data":[{"symbol":"ETH/USD","bids":[],"asks":[{"price":1773.87,"qty":12.35426731}],"checksum":1988881485,"timestamp":"2026-07-07T23:00:08.159745Z"}]}
{"channel":"book","type":"update","data":[{"symbol":"ETH/USD","bids":[],"asks":[{"price":1773.65,"qty":0.48930000}],"checksum":1992500528,"timestamp":"2026-07-07T23:00:08.201613Z"}]}
{"channel":"book","type":"update","data":[{"symbol":"ETH/USD","bids":[],"asks":[{"price":1773.64,"qty":0.31674471}],"checksum":2084196253,"timestamp":"2026-07-07T23:00:08.201710Z"}]}
{"channel":"book","type":"update","data":[{"symbol":"ETH/USD","bids":[{"price":1773.21,"qty":19.84616104}],"asks":[],"checksum":2419115628,"timestamp":"2026-07-07T23:00:08.202909Z"}]}
{"channel":"book","type":"update","data":[{"symbol":"ETH/USD","bids":[{"price":1773.19,"qty":0.00000000},{"price":1773.18,"qty":28.19284229},{"price":1773.29,"qty":5.56003448}],"asks":[],"checksum":139037744,"timestamp":"2026-07-07T23:00:08.204152Z"}]}
{"channel":"book","type":"update","data":[{"symbol":"ETH/USD","bids":[{"price":1773.28,"qty":0.00000000},{"price":1773.18,"qty":28.19284229},{"price":1773.30,"qty":1.68966976}],"asks":[],"checksum":1488397478,"timestamp":"2026-07-07T23:00:08.205627Z"}]}
{"channel":"book","type":"update","data":[{"symbol":"BTC/USD","bids":[{"price":63478.0,"qty":0.00000000},{"price":63477.2,"qty":0.05744528}],"asks":[],"checksum":2507780224,"timestamp":"2026-07-07T23:00:08.213239Z"}]}
{"channel":"book","type":"update","data":[{"symbol":"BTC/USD","bids":[{"price":63478.7,"qty":0.78766516}],"asks":[],"checksum":560427258,"timestamp":"2026-07-07T23:00:08.214662Z"}]}
{"channel":"book","type":"update","data":[{"symbol":"BTC/USD","bids":[],"asks":[{"price":63501.6,"qty":1.56064095}],"checksum":3316991538,"timestamp":"2026-07-07T23:00:08.235184Z"}]}
{"channel":"book","type":"update","data":[{"symbol":"ETH/USD","bids":[],"asks":[{"price":1773.65,"qty":3.30835077}],"checksum":1266536498,"timestamp":"2026-07-07T23:00:08.268079Z"}]}
{"channel":"book","type":"update","data":[{"symbol":"ETH/USD","bids":[{"price":1773.35,"qty":2.81952101}],"asks":[],"checksum":1597745039,"timestamp":"2026-07-07T23:00:08.268452Z"}]}
{"channel":"book","type":"update","data":[{"symbol":"ETH/USD","bids":[],"asks":[{"price":1773.64,"qty":1.53439853}],"checksum":2402586450,"timestamp":"2026-07-07T23:00:08.269344Z"}]}
{"channel":"book","type":"update","data":[{"symbol":"ETH/USD","bids":[],"asks":[{"price":1773.64,"qty":2.02369853}],"checksum":2551081691,"timestamp":"2026-07-07T23:00:08.269549Z"}]}
{"channel":"book","type":"update","data":[{"symbol":"ETH/USD","bids":[{"price":1773.29,"qty":0.00000000},{"price":1773.21,"qty":19.84616104},{"price":1773.27,"qty":6.04933448}],"asks":[],"checksum":3384017383,"timestamp":"2026-07-07T23:00:08.270519Z"}]}
{"channel":"book","type":"update","data":[{"symbol":"ETH/USD","bids":[{"price":1773.30,"qty":0.00000000},{"price":1773.18,"qty":28.19284229},{"price":1773.28,"qty":1.68966976}],"asks":[],"checksum":2143015389,"timestamp":"2026-07-07T23:00:08.272369Z"}]}
{"channel":"book","type":"update","data":[{"symbol":"ETH/USD","bids":[{"price":1773.38,"qty":0.05638949}],"asks":[],"checksum":3022884038,"timestamp":"2026-07-07T23:00:08.409691Z"}]}
{"channel":"book","type":"update","data":[{"symbol":"ETH/USD","bids":[],"asks":[{"price":1773.65,"qty":2.81905077}],"checksum":766338348,"timestamp":"2026-07-07T23:00:08.423585Z"}]}
{"channel":"book","type":"update","data":[{"symbol":"ETH/USD","bids":[],"asks":[{"price":1773.64,"qty":1.53439853}],"checksum":2700521394,"timestamp":"2026-07-07T23:00:08.482214Z"}]}
{"channel":"book","type":"update","data":[{"symbol":"BTC/USD","bids":[{"price":63478.0,"qty":0.60470924}],"asks":[],"checksum":1433943939,"timestamp":"2026-07-07T23:00:08.488115Z"}]}
{"channel":"book","type":"update","data":[{"symbol":"BTC/USD","bids":[{"price":63478.1,"qty":0.03147178}],"asks":[],"checksum":1479118494,"timestamp":"2026-07-07T23:00:08.489436Z"}]}
{"channel":"book","type":"update","data":[{"symbol":"BTC/USD","bids":[{"price":63478.7,"qty":0.00000000},{"price":63478.0,"qty":0.60470924}],"asks":[],"checksum":2953314951,"timestamp":"2026-07-07T23:00:08.554220Z"}]}
{"channel":"book","type":"update","data":[{"symbol":"BTC/USD","bids":[{"price":63478.1,"qty":0.81914491}],"asks":[],"checksum":4119712789,"timestamp":"2026-07-07T23:00:08.555833Z"}]}
{"channel":"heartbeat"}
{"channel":"book","type":"update","data":[{"symbol":"BTC/USD","bids":[{"price":63478.1,"qty":0.03147178}],"asks":[],"checksum":2953314951,"timestamp":"2026-07-07T23:00:08.700533Z"}]}
{"channel":"book","type":"update","data":[{"symbol":"BTC/USD","bids":[],"asks":[{"price":63501.3,"qty":1.14683433}],"checksum":3918313084,"timestamp":"2026-07-07T23:00:08.737927Z"}]}
{"channel":"book","type":"update","data":[{"symbol":"ETH/USD","bids":[],"asks":[{"price":1773.65,"qty":0.00000000},{"price":1773.88,"qty":28.18683393}],"checksum":2011425361,"timestamp":"2026-07-07T23:00:08.738138Z"}]}
{"channel":"book","type":"update","data":[{"symbol":"ETH/USD","bids":[],"asks":[{"price":1773.63,"qty":2.81907725}],"checksum":285306835,"timestamp":"2026-07-07T23:00:08.739674Z"}]}
{"channel":"book","type":"update","data":[{"symbol":"ETH/USD","bids":[{"price":1773.35,"qty":0.00000000},{"price":1773.21,"qty":19.84616104}],"asks":[],"checksum":2262214552,"timestamp":"2026-07-07T23:00:08.739885Z"}]}
{"channel":"book","type":"update","data":[{"symbol":"ETH/USD","bids":[],"asks":[{"price":1773.64,"qty":0.31674471}],"checksum":3584492007,"timestamp":"2026-07-07T23:00:08.739899Z"}]}
{"channel":"book","type":"update","data":[{"symbol":"ETH/USD","bids":[],"asks":[{"price":1773.62,"qty":0.84149456}],"checksum":1488755343,"timestamp":"2026-07-07T23:00:08.741303Z"}]}
{"channel":"book","type":"update","data":[{"symbol":"ETH/USD","bids":[{"price":1773.30,"qty":2.81959355}],"asks":[],"checksum":2822963834,"timestamp":"2026-07-07T23:00:08.741637Z"}]}
{"channel":"book","type":"update","data":[{"symbol":"ETH/USD","bids":[{"price":1773.28,"qty":0.00000000},{"price":1773.21,"qty":19.84616104},{"price":1773.31,"qty":1.68966976}],"asks":[],"checksum":4212326642,"timestamp":"2026-07-07T23:00:08.743236Z"}]}
{"channel":"book","type":"update","data":[{"symbol":"ETH/USD","bids":[],"asks":[{"price":1773.61,"qty":0.31852463}],"checksum":2631680165,"timestamp":"2026-07-07T23:00:08.751778Z"}]}
{"channel":"book","type":"update","data":[{"symbol":"ETH/USD","bids":[],"asks":[{"price":1773.66,"qty":0.00000000},{"price":1773.85,"qty":0.50000000}],"checksum":2767982742,"timestamp":"2026-07-07T23:00:08.752692Z"}]}
{"channel":"book","type":"update","data":[{"symbol":"ETH/USD","bids":[{"price":1773.44,"qty":0.00000000},{"price":1773.21,"qty":19.84616104}],"asks":[],"checksum":1171069519,"timestamp":"2026-07-07T23:00:08.753703Z"}]}
{"channel":"book","type":"update","data":[{"symbol":"ETH/USD","bids":[],"asks":[{"price":1773.61,"qty":0.80782463}],"checksum":3187701872,"timestamp":"2026-07-07T23:00:08.756397Z"}]}
{"channel":"book","type":"update","data":[{"symbol":"ETH/USD","bids":[{"price":1773.26,"qty":0.00000000},{"price":1773.18,"qty":28.19284229}],"asks":[],"checksum":715451357,"timestamp":"2026-07-07T23:00:08.782301Z"}]}
{"channel":"book","type":"update","data":[{"symbol":"ETH/USD","bids":[{"price":1773.27,"qty":0.48930000},{"price":1773.22,"qty":5.56003448}],"asks":[],"checksum":4021042847,"timestamp":"2026-07-07T23:00:08.783566Z"}]}
{"channel":"book","type":"update","data":[{"symbol":"ETH/USD","bids":[{"price":1773.22,"qty":15.73091546}],"asks":[],"checksum":1014851683,"timestamp":"2026-07-07T23:00:08.783589Z"}]}
{"channel":"book","type":"update","data":[{"symbol":"ETH/USD","bids":[{"price":1773.43,"qty":0.00000000},{"price":1773.18,"qty":28.19284229}],"asks":[],"checksum":1159417987,"timestamp":"2026-07-07T23:00:08.793219Z"}]}
{"channel":"book","type":"update","data":[{"symbol":"BTC/USD","bids":[{"price":63478.0,"qty":0.00000000},{"price":63477.2,"qty":0.05744528}],"asks":[],"checksum":1180141133,"timestamp":"2026-07-07T23:00:08.806591Z"}]}
{"channel":"book","type":"update","data":[{"symbol":"BTC/USD","bids":[{"price":63478.1,"qty":0.00000000},{"price":63477.1,"qty":0.00157500},{"price":63477.3,"qty":0.03147178}],"asks":[],"checksum":2114559856,"timestamp":"2026-07-07T23:00:08.808120Z"}]}
{"channel":"book","type":"update","data":[{"symbol":"ETH/USD","bids":[{"price":1773.38,"qty":0.00000000},{"price":1773.16,"qty":1.30000000},{"price":1773.32,"qty":0.05639140}],"asks":[],"checksum":2598456745,"timestamp":"2026-07-07T23:00:08.814838Z"}]}
{"channel":"book","type":"update","data":[{"symbol":"ETH/USD","bids":[],"asks":[{"price":1773.64,"qty":0.00000000},{"price":1773.87,"qty":12.35426731}],"checksum":487315761,"timestamp":"2026-07-07T23:00:08.816730Z"}]}
{"channel":"book","type":"update","data":[{"symbol":"ETH/USD","bids":[],"asks":[{"price":1773.63,"qty":0.00000000},{"price":1773.89,"qty":1.30000000}],"checksum":3973557133,"timestamp":"2026-07-07T23:00:08.816802Z"}]}
{"channel":"book","type":"update","data":[{"symbol":"ETH/USD","bids":[],"asks":[{"price":1773.60,"qty":0.31674471}],"checksum":1339158786,"timestamp":"2026-07-07T23:00:08.817023Z"}]}
{"channel":"book","type":"update","data":[{"symbol":"ETH/USD","bids":[],"asks":[{"price":1773.83,"qty":9.96333428}],"checksum":1839056059,"timestamp":"2026-07-07T23:00:08.818250Z"}]}
{"channel":"book","type":"update","data":[{"symbol":"ETH/USD","bids":[],"asks":[{"price":1773.83,"qty":4.77600128}],"checksum":145095072,"timestamp":"2026-07-07T23:00:08.818316Z"}]}
{"channel":"book","type":"update","data":[{"symbol":"ETH/USD","bids":[],"asks":[{"price":1773.60,"qty":3.13586965}],"checksum":3059470164,"timestamp":"2026-07-07T23:00:08.818487Z"}]}
{"channel":"book","type":"update","data":[{"symbol":"ETH/USD","bids":[],"asks":[{"price":1773.62,"qty":0.00000000},{"price":1773.89,"qty":1.30000000}],"checksum":1315873583,"timestamp":"2026-07-07T23:00:08.818593Z"}]}
{"channel":"book","type":"update","data":[{"symbol":"ETH/USD","bids":[],"asks":[{"price":1773.81,"qty":28.18798320}],"checksum":2378767931,"timestamp":"2026-07-07T23:00:08.818846Z"}]}
{"channel":"book","type":"update","data":[{"symbol":"ETH/USD","bids":[],"asks":[{"price":1773.59,"qty":1.17719274}],"checksum":3117881776,"timestamp":"2026-07-07T23:00:08.820252Z"}]}
{"channel":"book","type":"update","data":[{"symbol":"ETH/USD","bids":[],"asks":[{"price":1773.83,"qty":13.65108307}],"checksum":3169891521,"timestamp":"2026-07-07T23:00:08.820451Z"}]}
{"channel":"book","type":"update","data":[{"symbol":"ETH/USD","bids":[],"asks":[{"price":1773.72,"qty":8.79482718}],"checksum":4230847194,"timestamp":"2026-07-07T23:00:08.821141Z"}]}
{"channel":"book","type":"update","data":[{"symbol":"ETH/USD","bids":[{"price":1773.24,"qty":0.00000000},{"price":1773.16,"qty":1.30000000}],"asks":[],"checksum":670327549,"timestamp":"2026-07-07T23:00:08.833358Z"}]}
{"channel":"book","type":"update","data":[{"symbol":"ETH/USD","bids":[],"asks":[{"price":1773.60,"qty":0.31674471}],"checksum":2354786234,"timestamp":"2026-07-07T23:00:08.844869Z"}]}
{"channel":"book","type":"update","data":[{"symbol":"ETH/USD","bids":[],"asks":[{"price":1773.59,"qty":0.00000000},{"price":1773.87,"qty":12.35426731}],"checksum":841722958,"timestamp":"2026-07-07T23:00:08.846246Z"}]}
{"channel":"book","type":"update","data":[{"symbol":"ETH/USD","bids":[{"price":1773.18,"qty":0.00000000},{"price":1773.12,"qty":6.11610747}],"asks":[],"checksum":2811508145,"timestamp":"2026-07-07T23:00:08.847671Z"}]}
{"channel":"book","type":"update","data":[{"symbol":"ETH/USD","bids":[],"asks":[{"price":1773.61,"qty":0.31852463}],"checksum":2522500682,"timestamp":"2026-07-07T23:00:08.848761Z"}]}
{"channel":"book","type":"update","data":[{"symbol":"ETH/USD","bids":[],"asks":[{"price":1773.60,"qty":0.80604471}],"checksum":2244359064,"timestamp":"2026-07-07T23:00:08.848896Z"}]}
{"channel":"book","type":"update","data":[{"symbol":"ETH/USD","bids":[{"price":1773.22,"qty":21.65499453}],"asks":[],"checksum":3566799572,"timestamp":"2026-07-07T23:00:08.848958Z"}]}
{"channel":"book","type":"update","data":[{"symbol":"ETH/USD","bids":[{"price":1773.22,"qty":11.48411355}],"asks":[],"checksum":1147154808,"timestamp":"2026-07-07T23:00:08.849019Z"}]}
{"channel":"book","type":"update","data":[{"symbol":"ETH/USD","bids":[{"price":1773.32,"qty":0.00000000},{"price":1773.11,"qty":16.81400000}],"asks":[],"checksum":236795636,"timestamp":"2026-07-07T23:00:08.870919Z"}]}
{"channel":"book","type":"update","data":[{"symbol":"ETH/USD","bids":[{"price":1773.22,"qty":5.56003448}],"asks":[],"checksum":1906913710,"timestamp":"2026-07-07T23:00:08.877868Z"}]}
{"channel":"book","type":"update","data":[{"symbol":"ETH/USD","bids":[{"price":1773.30,"qty":0.00000000},{"price":1773.09,"qty":0.45737557}],"asks":[],"checksum":1241290702,"timestamp":"2026-07-07T23:00:08.889183Z"}]}
{"channel":"book","type":"update","data":[{"symbol":"ETH/USD","bids":[],"asks":[{"price":1773.58,"qty":2.81915673}],"checksum":2123522555,"timestamp":"2026-07-07T23:00:08.890950Z"}]}
{"channel":"book","type":"update","data":[{"symbol":"ETH/USD","bids":[{"price":1773.31,"qty":0.00000000},{"price":1773.07,"qty":8.65140978},{"price":1773.28,"qty":1.68966976}],"asks":[],"checksum":126241691,"timestamp":"2026-07-07T23:00:08.890979Z"}]}
{"channel":"book","type":"update","data":[{"symbol":"ETH/USD","bids":[{"price":1773.24,"qty":2.81968154}],"asks":[],"checksum":3110266598,"timestamp":"2026-07-07T23:00:08.891233Z"}]}
{"channel":"book","type":"update","data":[{"symbol":"ETH/USD","bids":[],"asks":[{"price":1773.60,"qty":0.31674471}],"checksum":622709604,"timestamp":"2026-07-07T23:00:08.892303Z"}]}
{"channel":"book","type":"update","data":[{"symbol":"ETH/USD","bids":[],"asks":[{"price":1773.58,"qty":3.30845673}],"checksum":1637069314,"timestamp":"2026-07-07T23:00:08.892318Z"}]}
{"channel":"book","type":"update","data":[{"symbol":"ETH/USD","bids":[{"price":1773.29,"qty":1.30000000}],"asks":[],"checksum":1060309694,"timestamp":"2026-07-07T23:00:08.892429Z"}]}
{"channel":"book","type":"update","data":[{"symbol":"ETH/USD","bids":[],"asks":[{"price":1773.57,"qty":1.17720223}],"checksum":847599756,"timestamp":"2026-07-07T23:00:08.892470Z"}]}
{"channel":"book","type":"update","data":[{"symbol":"ETH/USD","bids":[{"price":1773.29,"qty":1.77001888}],"asks":[],"checksum":2243835973,"timestamp":"2026-07-07T23:00:08.892490Z"}]}
{"channel":"book","type":"update","data":[{"symbol":"ETH/USD","bids":[],"asks":[{"price":1773.58,"qty":0.48930000}],"checksum":3602461917,"timestamp":"2026-07-07T23:00:08.893657Z"}]}
{"channel":"book","type":"update","data":[{"symbol":"ETH/USD","bids":[],"asks":[{"price":1773.57,"qty":1.66650223}],"checksum":2672802993,"timestamp":"2026-07-07T23:00:08.894164Z"}]}
{"channel":"book","type":"update","data":[{"symbol":"ETH/USD","bids":[],"asks":[{"price":1773.58,"qty":0.00000000},{"price":1773.85,"qty":0.50000000}],"checksum":1903635627,"timestamp":"2026-07-07T23:00:08.894470Z"}]}
{"channel":"book","type":"update","data":[{"symbol":"ETH/USD","bids":[],"asks":[{"price":1773.57,"qty":0.48930000}],"checksum":16115733,"timestamp":"2026-07-07T23:00:08.894984Z"}]}
{"channel":"book","type":"update","data":[{"symbol":"ETH/USD","bids":[],"asks":[{"price":1773.75,"qty":0.48930000}],"checksum":3553881068,"timestamp":"2026-07-07T23:00:08.896621Z"}]}
{"channel":"book","type":"update","data":[{"symbol":"ETH/USD","bids":[{"price":1773.27,"qty":0.78154096}],"asks":[],"checksum":2604069606,"timestamp":"2026-07-07T23:00:08.896738Z"}]}
{"channel":"book","type":"update","data":[{"symbol":"ETH/USD","bids":[{"price":1773.28,"qty":0.00000000},{"price":1773.09,"qty":0.45737557},{"price":1773.30,"qty":1.68966976}],"asks":[],"checksum":3398953428,"timestamp":"2026-07-07T23:00:08.915384Z"}]}
{"channel":"book","type":"update","data":[{"symbol":"ETH/USD","bids":[{"price":1773.22,"qty":0.00000000},{"price":1773.09,"qty":0.45737557}],"asks":[],"checksum":2740795595,"timestamp":"2026-07-07T23:00:08.916499Z"}]}
{"channel":"book","type":"update","data":[{"symbol":"ETH/USD","bids":[{"price":1773.29,"qty":1.30000000}],"asks":[],"checksum":1964809729,"timestamp":"2026-07-07T23:00:08.916653Z"}]}
{"channel":"book","type":"update","data":[{"symbol":"ETH/USD","bids":[{"price":1773.12,"qty":1.09712847}],"asks":[],"checksum":2538473481,"timestamp":"2026-07-07T23:00:08.916733Z"}]}
{"channel":"book","type":"update","data":[{"symbol":"ETH/USD","bids":[],"asks":[{"price":1773.56,"qty":0.29730332}],"checksum":3774655288,"timestamp":"2026-07-07T23:00:08.916787Z"}]}
{"channel":"book","type":"update","data":[{"symbol":"ETH/USD","bids":[{"price":1773.17,"qty":0.85206946}],"asks":[],"checksum":1072673382,"timestamp":"2026-07-07T23:00:08.916802Z"}]}
{"channel":"book","type":"update","data":[{"symbol":"ETH/USD","bids":[],"asks":[{"price":1773.61,"qty":0.00000000},{"price":1773.84,"qty":15.57800000}],"checksum":2148276166,"timestamp":"2026-07-07T23:00:08.918046Z"}]}
{"channel":"book","type":"update","data":[{"symbol":"ETH/USD","bids":[],"asks":[{"price":1773.56,"qty":0.78660332}],"checksum":3204280140,"timestamp":"2026-07-07T23:00:08.918660Z"}]}
{"channel":"book","type":"update","data":[{"symbol":"ETH/USD","bids":[{"price":1773.27,"qty":0.48930000}],"asks":[],"checksum":3922865899,"timestamp":"2026-07-07T23:00:08.923611Z"}]}
{"channel":"book","type":"update","data":[{"symbol":"ETH/USD","bids":[{"price":1773.27,"qty":0.00000000},{"price":1773.09,"qty":0.45737557}],"asks":[],"checksum":1365133615,"timestamp":"2026-07-07T23:00:08.923948Z"}]}
{"channel":"book","type":"update","data":[{"symbol":"ETH/USD","bids":[{"price":1773.29,"qty":0.00000000},{"price":1773.07,"qty":8.65140978}],"asks":[],"checksum":2538727573,"timestamp":"2026-07-07T23:00:08.925401Z"}]}
{"channel":"book","type":"update","data":[{"symbol":"ETH/USD","bids":[{"price":1773.16,"qty":0.00000000},{"price":1773.06,"qty":28.19364735}],"asks":[],"checksum":2411558159,"timestamp":"2026-07-07T23:00:08.927536Z"}]}
{"channel":"book","type":"update","data":[{"symbol":"ETH/USD","bids":[],"asks":[{"price":1773.81,"qty":0.00000000},{"price":1773.85,"qty":0.50000000}],"checksum":1527535340,"timestamp":"2026-07-07T23:00:08.929933Z"}]}
{"channel":"book","type":"update","data":[{"symbol":"ETH/USD","bids":[{"price":1773.30,"qty":0.00000000},{"price":1773.05,"qty":0.30000000}],"asks":[],"checksum":490611867,"timestamp":"2026-07-07T23:00:08.929943Z"}]}
{"channel":"book","type":"update","data":[{"symbol":"ETH/USD","bids":[{"price":1773.17,"qty":0.00000000},{"price":1773.04,"qty":0.48930000}],"asks":[],"checksum":2993158803,"timestamp":"2026-07-07T23:00:08.932892Z"}]}
{"channel":"book","type":"update","data":[{"symbol":"ETH/USD","bids":[{"price":1773.23,"qty":0.00000000},{"price":1772.99,"qty":6.61182852}],"asks":[],"checksum":4033818719,"timestamp":"2026-07-07T23:00:08.933441Z"}]}
{"channel":"book","type":"update","data":[{"symbol":"ETH/USD","bids":[{"price":1773.06,"qty":0.00000000},{"price":1772.98,"qty":2.87402415},{"price":1773.00,"qty":28.19430765}],"asks":[],"checksum":1738798608,"timestamp":"2026-07-07T23:00:08.933586Z"}]}
{"channel":"book","type":"update","data":[{"symbol":"ETH/USD","bids":[{"price":1773.24,"qty":0.00000000},{"price":1772.98,"qty":2.87402415}],"asks":[],"checksum":3561267421,"timestamp":"2026-07-07T23:00:08.935702Z"}]}
{"channel":"book","type":"update","data":[{"symbol":"ETH/USD","bids":[],"asks":[{"price":1773.55,"qty":0.31674471}],"checksum":873121682,"timestamp":"2026-07-07T23:00:08.936486Z"}]}
{"channel":"book","type":"update","data":[{"symbol":"ETH/USD","bids":[],"asks":[{"price":1773.60,"qty":0.00000000},{"price":1773.85,"qty":0.50000000}],"checksum":1375671048,"timestamp":"2026-07-07T23:00:08.936500Z"}]}
{"channel":"book","type":"update","data":[{"symbol":"ETH/USD","bids":[],"asks":[{"price":1773.72,"qty":0.59738996}],"checksum":572122567,"timestamp":"2026-07-07T23:00:08.937164Z"}]}
{"channel":"book","type":"update","data":[{"symbol":"ETH/USD","bids":[{"price":1773.01,"qty":5.56003448}],"asks":[],"checksum":1007099193,"timestamp":"2026-07-07T23:00:08.937518Z"}]}
{"channel":"book","type":"update","data":[{"symbol":"ETH/USD","bids":[{"price":1773.21,"qty":0.00000000},{"price":1772.98,"qty":2.87402415}],"asks":[],"checksum":3405795466,"timestamp":"2026-07-07T23:00:08.940414Z"}]}
{"channel":"book","type":"update","data":[{"symbol":"ETH/USD","bids":[],"asks":[{"price":1773.55,"qty":0.80604471}],"checksum":2438232382,"timestamp":"2026-07-07T23:00:08.940657Z"}]}
{"channel":"book","type":"update","data":[{"symbol":"ETH/USD","bids":[],"asks":[{"price":1773.47,"qty":2.81934359}],"checksum":3626014639,"timestamp":"2026-07-07T23:00:08.941563Z"}]}
{"channel":"book","type":"update","data":[{"symbol":"ETH/USD","bids":[{"price":1773.14,"qty":2.81985399}],"asks":[],"checksum":2885174181,"timestamp":"2026-07-07T23:00:08.942021Z"}]}
{"channel":"book","type":"update","data":[{"symbol":"ETH/USD","bids":[],"asks":[{"price":1773.56,"qty":0.29730332}],"checksum":3075187849,"timestamp":"2026-07-07T23:00:08.942668Z"}]}
{"channel":"book","type":"update","data":[{"symbol":"ETH/USD","bids":[],"asks":[{"price":1773.54,"qty":0.62146149}],"checksum":349514932,"timestamp":"2026-07-07T23:00:08.944012Z"}]}
{"channel":"book","type":"update","data":[{"symbol":"ETH/USD","bids":[],"asks":[{"price":1773.46,"qty":0.84157406}],"checksum":858755163,"timestamp":"2026-07-07T23:00:08.945627Z"}]}
{"channel":"book","type":"update","data":[{"symbol":"ETH/USD","bids":[],"asks":[{"price":1773.47,"qty":3.30864359}],"checksum":2028319954,"timestamp":"2026-07-07T23:00:08.946331Z"}]}
{"channel":"book","type":"update","data":[{"symbol":"ETH/USD","bids":[{"price":1773.09,"qty":20.30353661}],"asks":[],"checksum":3351996240,"timestamp":"2026-07-07T23:00:08.946767Z"}]}
{"channel":"book","type":"update","data":[{"symbol":"ETH/USD","bids":[],"asks":[{"price":1773.55,"qty":0.31674471}],"checksum":2938516644,"timestamp":"2026-07-07T23:00:08.947002Z"}]}
{"channel":"book","type":"update","data":[{"symbol":"ETH/USD","bids":[],"asks":[{"price":1773.47,"qty":0.48930000}],"checksum":2827011884,"timestamp":"2026-07-07T23:00:08.947292Z"}]}
{"channel":"book","type":"update","data":[{"symbol":"ETH/USD","bids":[],"asks":[{"price":1773.54,"qty":0.00000000},{"price":1773.83,"qty":13.65108307}],"checksum":3259161345,"timestamp":"2026-07-07T23:00:08.949506Z"}]}
{"channel":"book","type":"update","data":[{"symbol":"ETH/USD","bids":[],"asks":[{"price":1773.46,"qty":0.00000000},{"price":1773.84,"qty":15.57800000}],"checksum":2525842772,"timestamp":"2026-07-07T23:00:08.949918Z"}]}
{"channel":"book","type":"update","data":[{"symbol":"ETH/USD","bids":[{"price":1773.10,"qty":6.06060568}],"asks":[],"checksum":1992606925,"timestamp":"2026-07-07T23:00:08.951821Z"}]}
{"channel":"book","type":"update","data":[{"symbol":"BTC/USD","bids":[{"price":63477.3,"qty":0.00000000},{"price":63477.1,"qty":0.00157500}],"asks":[],"checksum":921621860,"timestamp":"2026-07-07T23:00:08.958567Z"}]}
{"channel":"book","type":"update","data":[{"symbol":"ETH/USD","bids":[{"price":1773.15,"qty":0.47001888}],"asks":[],"checksum":902759965,"timestamp":"2026-07-07T23:00:08.961957Z"}]}
{"channel":"book","type":"update","data":[{"symbol":"ETH/USD","bids":[{"price":1773.01,"qty":0.00000000},{"price":1773.00,"qty":28.19430765},{"price":1773.11,"qty":5.56003448}],"asks":[],"checksum":4240873744,"timestamp":"2026-07-07T23:00:08.963460Z"}]}
{"channel":"book","type":"update","data":[{"symbol":"ETH/USD","bids":[{"price":1773.14,"qty":0.00000000},{"price":1773.00,"qty":28.19430765}],"asks":[],"checksum":2145046933,"timestamp":"2026-07-07T23:00:08.982168Z"}]}
{"channel":"book","type":"update","data":[{"symbol":"ETH/USD","bids":[],"asks":[{"price":1773.47,"qty":0.00000000},{"price":1773.85,"qty":0.50000000}],"checksum":3603807158,"timestamp":"2026-07-07T23:00:08.985503Z"}]}
{"channel":"book","type":"update","data":[{"symbol":"ETH/USD","bids":[],"asks":[{"price":1773.70,"qty":12.35426731}],"checksum":1732460300,"timestamp":"2026-07-07T23:00:09.006090Z"}]}
{"channel":"book","type":"update","data":[{"symbol":"ETH/USD","bids":[],"asks":[{"price":1773.83,"qty":4.77600128}],"checksum":1808684063,"timestamp":"2026-07-07T23:00:09.007639Z"}]}
{"channel":"book","type":"update","data":[{"symbol":"ETH/USD","bids":[],"asks":[{"price":1773.69,"qty":3.82804943}],"checksum":1243746782,"timestamp":"2026-07-07T23:00:09.007661Z"}]}
{"channel":"book","type":"update","data":[{"symbol":"ETH/USD","bids":[],"asks":[{"price":1773.82,"qty":6.69695895}],"checksum":1487104123,"timestamp":"2026-07-07T23:00:09.010789Z"}]}
{"channel":"book","type":"update","data":[{"symbol":"ETH/USD","bids":[{"price":1773.27,"qty":0.29909460}],"asks":[],"checksum":4212157920,"timestamp":"2026-07-07T23:00:09.024547Z"}]}
{"channel":"book","type":"update","data":[{"symbol":"ETH/USD","bids":[{"price":1773.16,"qty":1.30000000}],"asks":[],"checksum":2339656835,"timestamp":"2026-07-07T23:00:09.025585Z"}]}
{"channel":"book","type":"update","data":[{"symbol":"ETH/USD","bids":[{"price":1773.17,"qty":0.47001888}],"asks":[],"checksum":1349647506,"timestamp":"2026-07-07T23:00:09.027046Z"}]}
{"channel":"book","type":"update","data":[{"symbol":"ETH/USD","bids":[],"asks":[{"price":1773.54,"qty":2.81922404}],"checksum":2230221589,"timestamp":"2026-07-07T23:00:09.058380Z"}]}
{"channel":"book","type":"update","data":[{"symbol":"ETH/USD","bids":[{"price":1773.18,"qty":2.81978657}],"asks":[],"checksum":728337698,"timestamp":"2026-07-07T23:00:09.058653Z"}]}
{"channel":"book","type":"update","data":[{"symbol":"ETH/USD","bids":[],"asks":[{"price":1773.54,"qty":3.30852404}],"checksum":4213421845,"timestamp":"2026-07-07T23:00:09.059825Z"}]}
{"channel":"book","type":"update","data":[{"symbol":"ETH/USD","bids":[],"asks":[{"price":1773.54,"qty":0.48930000}],"checksum":1993567377,"timestamp":"2026-07-07T23:00:09.074444Z"}]}
{"channel":"book","type":"update","data":[{"symbol":"ETH/USD","bids":[{"price":1773.13,"qty":1.68966976}],"asks":[],"checksum":3718473974,"timestamp":"2026-07-07T23:00:09.079145Z"}]}
{"channel":"book","type":"update","data":[{"symbol":"ETH/USD","bids":[],"asks":[{"price":1773.55,"qty":0.00000000},{"price":1773.82,"qty":6.69695895}],"checksum":4239700180,"timestamp":"2026-07-07T23:00:09.079628Z"}]}
{"channel":"book","type":"update","data":[{"symbol":"ETH/USD","bids":[],"asks":[{"price":1773.53,"qty":0.31674471}],"checksum":157108387,"timestamp":"2026-07-07T23:00:09.079804Z"}]}
{"channel":"book","type":"update","data":[{"symbol":"ETH/USD","bids":[],"asks":[{"price":1773.53,"qty":0.80604471}],"checksum":569543826,"timestamp":"2026-07-07T23:00:09.081442Z"}]}
{"channel":"book","type":"update","data":[{"symbol":"ETH/USD","bids":[{"price":1773.15,"qty":0.00000000},{"price":1773.09,"qty":20.30353661}],"asks":[],"checksum":89941527,"timestamp":"2026-07-07T23:00:09.128207Z"}]}
{"channel":"book","type":"update","data":[{"symbol":"ETH/USD","bids":[],"asks":[{"price":1773.48,"qty":2.81932697}],"checksum":1519592322,"timestamp":"2026-07-07T23:00:09.175885Z"}]}
{"channel":"book","type":"update","data":[{"symbol":"ETH/USD","bids":[{"price":1773.19,"qty":0.47001888}],"asks":[],"checksum":1505110131,"timestamp":"2026-07-07T23:00:09.177398Z"}]}
{"channel":"book","type":"update","data":[{"symbol":"ETH/USD","bids":[],"asks":[{"price":1773.48,"qty":3.30862697}],"checksum":2419096612,"timestamp":"2026-07-07T23:00:09.209272Z"}]}
{"channel":"book","type":"update","data":[{"symbol":"ETH/USD","bids":[],"asks":[{"price":1773.57,"qty":0.00000000},{"price":1773.75,"qty":28.67822406}],"checksum":2176208106,"timestamp":"2026-07-07T23:00:09.211041Z"}]}
{"channel":"book","type":"update","data":[{"symbol":"ETH/USD","bids":[{"price":1773.18,"qty":0.00000000},{"price":1773.09,"qty":20.30353661}],"asks":[],"checksum":545174141,"timestamp":"2026-07-07T23:00:09.215038Z"}]}
{"channel":"book","type":"update","data":[{"symbol":"ETH/USD","bids":[],"asks":[{"price":1773.47,"qty":0.33970354}],"checksum":984698011,"timestamp":"2026-07-07T23:00:09.215248Z"}]}
{"channel":"book","type":"update","data":[{"symbol":"ETH/USD","bids":[{"price":1773.19,"qty":0.00000000},{"price":1773.07,"qty":8.65140978}],"asks":[],"checksum":3854299331,"timestamp":"2026-07-07T23:00:09.215280Z"}]}
{"channel":"book","type":"update","data":[{"symbol":"ETH/USD","bids":[{"price":1773.17,"qty":0.00000000},{"price":1773.04,"qty":0.48930000}],"asks":[],"checksum":3330689928,"timestamp":"2026-07-07T23:00:09.215504Z"}]}
{"channel":"book","type":"update","data":[{"symbol":"ETH/USD","bids":[{"price":1773.13,"qty":0.00000000},{"price":1773.00,"qty":28.19430765}],"asks":[],"checksum":405023993,"timestamp":"2026-07-07T23:00:09.217337Z"}]}
{"channel":"book","type":"update","data":[{"symbol":"ETH/USD","bids":[],"asks":[{"price":1773.56,"qty":0.00000000},{"price":1773.75,"qty":28.67822406}],"checksum":4117270922,"timestamp":"2026-07-07T23:00:09.217469Z"}]}
{"channel":"book","type":"update","data":[{"symbol":"ETH/USD","bids":[{"price":1773.14,"qty":2.81984887}],"asks":[],"checksum":3970653036,"timestamp":"2026-07-07T23:00:09.217488Z"}]}
{"channel":"book","type":"update","data":[{"symbol":"ETH/USD","bids":[],"asks":[{"price":1773.47,"qty":0.82900354}],"checksum":112986108,"timestamp":"2026-07-07T23:00:09.218863Z"}]}
{"channel":"book","type":"update","data":[{"symbol":"ETH/USD","bids":[],"asks":[{"price":1773.47,"qty":2.20328909}],"checksum":2734642258,"timestamp":"2026-07-07T23:00:09.219328Z"}]}
{"channel":"book","type":"update","data":[{"symbol":"ETH/USD","bids":[{"price":1773.14,"qty":0.00000000},{"price":1773.00,"qty":28.19430765}],"asks":[],"checksum":877123630,"timestamp":"2026-07-07T23:00:09.219814Z"}]}
{"channel":"book","type":"update","data":[{"symbol":"ETH/USD","bids":[],"asks":[{"price":1773.48,"qty":2.81932697}],"checksum":1514413929,"timestamp":"2026-07-07T23:00:09.220277Z"}]}
{"channel":"book","type":"update","data":[{"symbol":"ETH/USD","bids":[],"asks":[{"price":1773.47,"qty":2.67330797}],"checksum":2900751397,"timestamp":"2026-07-07T23:00:09.220893Z"}]}
{"channel":"book","type":"update","data":[{"symbol":"ETH/USD","bids":[],"asks":[{"price":1773.72,"qty":8.94116408}],"checksum":2448681507,"timestamp":"2026-07-07T23:00:09.225121Z"}]}
{"channel":"book","type":"update","data":[{"symbol":"ETH/USD","bids":[{"price":1773.00,"qty":0.00000000},{"price":1772.99,"qty":6.61182852}],"asks":[],"checksum":1713381737,"timestamp":"2026-07-07T23:00:09.225995Z"}]}
{"channel":"book","type":"update","data":[{"symbol":"ETH/USD","bids":[{"price":1773.11,"qty":0.00000000},{"price":1772.98,"qty":2.87402415}],"asks":[],"checksum":3083150640,"timestamp":"2026-07-07T23:00:09.227611Z"}]}
{"channel":"book","type":"update","data":[{"symbol":"ETH/USD","bids":[{"price":1773.07,"qty":0.00000000},{"price":1772.97,"qty":2.00000000}],"asks":[],"checksum":1363373037,"timestamp":"2026-07-07T23:00:09.228369Z"}]}
{"channel":"book","type":"update","data":[{"symbol":"ETH/USD","bids":[{"price":1772.99,"qty":5.15409517}],"asks":[],"checksum":3397160560,"timestamp":"2026-07-07T23:00:09.228413Z"}]}
{"channel":"book","type":"update","data":[{"symbol":"ETH/USD","bids":[{"price":1772.99,"qty":0.00000000},{"price":1772.94,"qty":28.19468585}],"asks":[],"checksum":627912981,"timestamp":"2026-07-07T23:00:09.228580Z"}]}
{"channel":"book","type":"update","data":[{"symbol":"ETH/USD","bids":[{"price":1772.95,"qty":13.75657723}],"asks":[],"checksum":3461216932,"timestamp":"2026-07-07T23:00:09.230934Z"}]}
{"channel":"book","type":"update","data":[{"symbol":"ETH/USD","bids":[],"asks":[{"price":1773.54,"qty":0.00000000},{"price":1773.82,"qty":6.69695895}],"checksum":2934198577,"timestamp":"2026-07-07T23:00:09.234602Z"}]}
{"channel":"book","type":"update","data":[{"symbol":"ETH/USD","bids":[{"price":1773.17,"qty":1.68966976}],"asks":[],"checksum":4286012732,"timestamp":"2026-07-07T23:00:09.250322Z"}]}
{"channel":"book","type":"update","data":[{"symbol":"ETH/USD","bids":[{"price":1773.10,"qty":0.00000000},{"price":1772.95,"qty":13.75657723}],"asks":[],"checksum":447206643,"timestamp":"2026-07-07T23:00:09.263296Z"}]}
{"channel":"book","type":"update","data":[{"symbol":"ETH/USD","bids":[{"price":1773.10,"qty":6.06060568}],"asks":[],"checksum":4286012732,"timestamp":"2026-07-07T23:00:09.318510Z"}]}
{"channel":"book","type":"update","data":[{"symbol":"ETH/USD","bids":[],"asks":[{"price":1773.71,"qty":0.00000000},{"price":1773.83,"qty":4.77600128}],"checksum":1112545422,"timestamp":"2026-07-07T23:00:09.322279Z"}]}
{"channel":"book","type":"update","data":[{"symbol":"ETH/USD","bids":[],"asks":[{"price":1773.48,"qty":0.00000000},{"price":1773.84,"qty":15.93800000}],"checksum":1962213627,"timestamp":"2026-07-07T23:00:09.328824Z"}]}
{"channel":"book","type":"update","data":[{"symbol":"ETH/USD","bids":[],"asks":[{"price":1773.75,"qty":0.48930000}],"checksum":1251369205,"timestamp":"2026-07-07T23:00:09.329066Z"}]}
{"channel":"book","type":"update","data":[{"symbol":"ETH/USD","bids":[],"asks":[{"price":1773.47,"qty":1.29902242}],"checksum":3205221193,"timestamp":"2026-07-07T23:00:09.330154Z"}]}
{"channel":"book","type":"update","data":[{"symbol":"ETH/USD","bids":[],"asks":[{"price":1773.46,"qty":0.62836254}],"checksum":339535345,"timestamp":"2026-07-07T23:00:09.330193Z"}]}
{"channel":"book","type":"update","data":[{"symbol":"ETH/USD","bids":[],"asks":[{"price":1773.72,"qty":0.59738996}],"checksum":680314597,"timestamp":"2026-07-07T23:00:09.330291Z"}]}
{"channel":"book","type":"update","data":[{"symbol":"ETH/USD","bids":[],"asks":[{"price":1773.46,"qty":3.44771003}],"checksum":2580301304,"timestamp":"2026-07-07T23:00:09.332077Z"}]}
{"channel":"book","type":"update","data":[{"symbol":"ETH/USD","bids":[{"price":1773.16,"qty":4.11982151}],"asks":[],"checksum":2986684088,"timestamp":"2026-07-07T23:00:09.332470Z"}]}
{"channel":"book","type":"update","data":[{"symbol":"ETH/USD","bids":[],"asks":[{"price":1773.45,"qty":0.47001888}],"checksum":3653162429,"timestamp":"2026-07-07T23:00:09.332489Z"}]}
{"channel":"book","type":"update","data":[{"symbol":"ETH/USD","bids":[],"asks":[{"price":1773.46,"qty":2.81934749}],"checksum":1145006725,"timestamp":"2026-07-07T23:00:09.333667Z"}]}
{"channel":"book","type":"update","data":[{"symbol":"ETH/USD","bids":[],"asks":[{"price":1773.45,"qty":1.93995664}],"checksum":762865908,"timestamp":"2026-07-07T23:00:09.333720Z"}]}
{"channel":"book","type":"update","data":[{"symbol":"ETH/USD","bids":[],"asks":[{"price":1773.53,"qty":0.31674471}],"checksum":3499631554,"timestamp":"2026-07-07T23:00:09.371060Z"}]}
{"channel":"book","type":"update","data":[{"symbol":"ETH/USD","bids":[],"asks":[{"price":1773.47,"qty":0.80972242}],"checksum":3087147230,"timestamp":"2026-07-07T23:00:09.407198Z"}]}
{"channel":"book","type":"update","data":[{"symbol":"ETH/USD","bids":[],"asks":[{"price":1773.47,"qty":0.33970354}],"checksum":1267400914,"timestamp":"2026-07-07T23:00:09.433521Z"}]}
{"channel":"book","type":"update","data":[{"symbol":"ETH/USD","bids":[],"asks":[{"price":1773.46,"qty":0.00000000},{"price":1773.83,"qty":4.77600128}],"checksum":48857194,"timestamp":"2026-07-07T23:00:09.434753Z"}]}
{"channel":"book","type":"update","data":[{"symbol":"ETH/USD","bids":[],"asks":[{"price":1773.45,"qty":0.47001888}],"checksum":1126764537,"timestamp":"2026-07-07T23:00:09.434900Z"}]}
{"channel":"book","type":"update","data":[{"symbol":"ETH/USD","bids":[],"asks":[{"price":1773.45,"qty":1.50754391}],"checksum":2945767799,"timestamp":"2026-07-07T23:00:09.435128Z"}]}
{"channel":"book","type":"update","data":[{"symbol":"ETH/USD","bids":[{"price":1773.16,"qty":1.30000000}],"asks":[],"checksum":2220732983,"timestamp":"2026-07-07T23:00:09.436202Z"}]}
{"channel":"book","type":"update","data":[{"symbol":"ETH/USD","bids":[],"asks":[{"price":1773.45,"qty":0.47001888}],"checksum":1759536313,"timestamp":"2026-07-07T23:00:09.436225Z"}]}
{"channel":"book","type":"update","data":[{"symbol":"ETH/USD","bids":[],"asks":[{"price":1773.51,"qty":2.81928140}],"checksum":1628269376,"timestamp":"2026-07-07T23:00:09.437685Z"}]}
{"channel":"book","type":"update","data":[{"symbol":"ETH/USD","bids":[{"price":1773.19,"qty":2.81976510}],"asks":[],"checksum":3907157255,"timestamp":"2026-07-07T23:00:09.437916Z"}]}
{"channel":"book","type":"update","data":[{"symbol":"ETH/USD","bids":[],"asks":[{"price":1773.50,"qty":0.93610379}],"checksum":544858803,"timestamp":"2026-07-07T23:00:09.439154Z"}]}
{"channel":"book","type":"update","data":[{"symbol":"ETH/USD","bids":[{"price":1773.17,"qty":0.00000000},{"price":1772.97,"qty":2.00000000},{"price":1773.20,"qty":1.68966976}],"asks":[],"checksum":4011205284,"timestamp":"2026-07-07T23:00:09.439229Z"}]}
{"channel":"book","type":"update","data":[{"symbol":"ETH/USD","bids":[{"price":1773.11,"qty":5.56003448}],"asks":[],"checksum":3811637663,"timestamp":"2026-07-07T23:00:09.440847Z"}]}
{"channel":"book","type":"update","data":[{"symbol":"BTC/USD","bids":[],"asks":[{"price":63502.2,"qty":0.03160644}],"checksum":1311807824,"timestamp":"2026-07-07T23:00:09.505634Z"}]}
{"channel":"book","type":"update","data":[{"symbol":"ETH/USD","bids":[{"price":1773.33,"qty":0.29711510}],"asks":[],"checksum":2289201373,"timestamp":"2026-07-07T23:00:09.516717Z"}]}
{"channel":"book","type":"update","data":[{"symbol":"ETH/USD","bids":[{"price":1773.27,"qty":0.00000000},{"price":1773.04,"qty":0.48930000}],"asks":[],"checksum":4008946284,"timestamp":"2026-07-07T23:00:09.518143Z"}]}
{"channel":"heartbeat"}
{"channel":"book","type":"update","data":[{"symbol":"ETH/USD","bids":[{"price":1773.19,"qty":0.00000000},{"price":1772.98,"qty":2.87402415}],"asks":[],"checksum":3821066644,"timestamp":"2026-07-07T23:00:09.600369Z"}]}
{"channel":"book","type":"update","data":[{"symbol":"ETH/USD","bids":[],"asks":[{"price":1773.75,"qty":28.67817146}],"checksum":438723266,"timestamp":"2026-07-07T23:00:09.601870Z"}]}
{"channel":"book","type":"update","data":[{"symbol":"ETH/USD","bids":[{"price":1773.20,"qty":0.00000000},{"price":1772.97,"qty":2.00000000},{"price":1773.17,"qty":1.68966976}],"asks":[],"checksum":177751164,"timestamp":"2026-07-07T23:00:09.601991Z"}]}
{"channel":"book","type":"update","data":[{"symbol":"ETH/USD","bids":[{"price":1773.22,"qty":2.81971591}],"asks":[],"checksum":1892643864,"timestamp":"2026-07-07T23:00:09.602253Z"}]}
{"channel":"book","type":"update","data":[{"symbol":"ETH/USD","bids":[],"asks":[{"price":1773.72,"qty":8.94114838}],"checksum":502732671,"timestamp":"2026-07-07T23:00:09.603313Z"}]}
{"channel":"book","type":"update","data":[{"symbol":"ETH/USD","bids":[],"asks":[{"price":1773.51,"qty":0.00000000},{"price":1773.82,"qty":6.69695895}],"checksum":2733499870,"timestamp":"2026-07-07T23:00:09.622548Z"}]}
{"channel":"book","type":"update","data":[{"symbol":"ETH/USD","bids":[],"asks":[{"price":1773.50,"qty":0.00000000},{"price":1773.83,"qty":4.77600128}],"checksum":1293398178,"timestamp":"2026-07-07T23:00:09.624049Z"}]}
{"channel":"book","type":"update","data":[{"symbol":"ETH/USD","bids":[],"asks":[{"price":1773.56,"qty":2.81918947}],"checksum":350785470,"timestamp":"2026-07-07T23:00:09.624340Z"}]}
{"channel":"book","type":"update","data":[{"symbol":"ETH/USD","bids":[],"asks":[{"price":1773.55,"qty":0.84152806}],"checksum":4063784720,"timestamp":"2026-07-07T23:00:09.626165Z"}]}
{"channel":"book","type":"update","data":[{"symbol":"ETH/USD","bids":[{"price":1773.04,"qty":8.90705796}],"asks":[],"checksum":3342465966,"timestamp":"2026-07-07T23:00:09.837853Z"}]}
{"channel":"book","type":"update","data":[{"symbol":"ETH/USD","bids":[],"asks":[{"price":1773.56,"qty":0.00000000},{"price":1773.82,"qty":6.69695895}],"checksum":403973932,"timestamp":"2026-07-07T23:00:09.878382Z"}]}
{"channel":"book","type":"update","data":[{"symbol":"ETH/USD","bids":[],"asks":[{"price":1773.45,"qty":0.00000000},{"price":1773.83,"qty":4.77600128}],"checksum":717478649,"timestamp":"2026-07-07T23:00:09.879595Z"}]}
{"channel":"book","type":"update","data":[{"symbol":"ETH/USD","bids":[],"asks":[{"price":1773.55,"qty":0.00000000},{"price":1773.84,"qty":15.93800000}],"checksum":2179223575,"timestamp":"2026-07-07T23:00:09.879720Z"}]}
{"channel":"book","type":"update","data":[{"symbol":"ETH/USD","bids":[],"asks":[{"price":1773.54,"qty":0.47001888}],"checksum":1581560125,"timestamp":"2026-07-07T23:00:09.879849Z"}]}
{"channel":"book","type":"update","data":[{"symbol":"ETH/USD","bids":[],"asks":[{"price":1773.53,"qty":3.13598766}],"checksum":1933119933,"timestamp":"2026-07-07T23:00:09.879982Z"}]}
{"channel":"book","type":"update","data":[{"symbol":"ETH/USD","bids":[],"asks":[{"price":1773.52,"qty":0.47001888}],"checksum":1546824361,"timestamp":"2026-07-07T23:00:09.881313Z"}]}
{"channel":"book","type":"update","data":[{"symbol":"ETH/USD","bids":[],"asks":[{"price":1773.47,"qty":0.82900354}],"checksum":888964396,"timestamp":"2026-07-07T23:00:09.881492Z"}]}
{"channel":"book","type":"update","data":[{"symbol":"ETH/USD","bids":[],"asks":[{"price":1773.52,"qty":1.54641183}],"checksum":1278724973,"timestamp":"2026-07-07T23:00:09.881632Z"}]}
{"channel":"book","type":"update","data":[{"symbol":"ETH/USD","bids":[],"asks":[{"price":1773.53,"qty":0.31674471}],"checksum":3078318215,"timestamp":"2026-07-07T23:00:09.886611Z"}]}
{"channel":"book","type":"update","data":[{"symbol":"ETH/USD","bids":[],"asks":[{"price":1773.52,"qty":0.47001888}],"checksum":2080148431,"timestamp":"2026-07-07T23:00:09.888073Z"}]}
{"channel":"book","type":"update","data":[{"symbol":"ETH/USD","bids":[],"asks":[{"price":1773.46,"qty":0.62260712}],"checksum":4197232016,"timestamp":"2026-07-07T23:00:09.889764Z"}]}
{"channel":"book","type":"update","data":[{"symbol":"ETH/USD","bids":[],"asks":[{"price":1773.46,"qty":1.11190712}],"checksum":1642451314,"timestamp":"2026-07-07T23:00:09.912579Z"}]}
{"channel":"book","type":"update","data":[{"symbol":"ETH/USD","bids":[{"price":1773.37,"qty":0.18213883}],"asks":[],"checksum":2529067216,"timestamp":"2026-07-07T23:00:09.927983Z"}]}
{"channel":"book","type":"update","data":[{"symbol":"ETH/USD","bids":[],"asks":[{"price":1773.54,"qty":0.00000000},{"price":1773.82,"qty":6.69695895}],"checksum":3559876922,"timestamp":"2026-07-07T23:00:09.982359Z"}]}
{"channel":"book","type":"update","data":[{"symbol":"ETH/USD","bids":[],"asks":[{"price":1773.45,"qty":0.47001888}],"checksum":2004017030,"timestamp":"2026-07-07T23:00:09.983684Z"}]}
{"channel":"book","type":"update","data":[{"symbol":"ETH/USD","bids":[],"asks":[{"price":1773.46,"qty":0.62260712}],"checksum":1678830529,"timestamp":"2026-07-07T23:00:10.005412Z"}]}
{"channel":"book","type":"update","data":[{"symbol":"ETH/USD","bids":[{"price":1773.18,"qty":0.05639585}],"asks":[],"checksum":21522559,"timestamp":"2026-07-07T23:00:10.010951Z"}]}
{"channel":"book","type":"update","data":[{"symbol":"ETH/USD","bids":[{"price":1773.17,"qty":0.00000000},{"price":1773.04,"qty":8.90705796},{"price":1773.19,"qty":1.68966976}],"asks":[],"checksum":458487674,"timestamp":"2026-07-07T23:00:10.012778Z"}]}
{"channel":"book","type":"update","data":[{"symbol":"ETH/USD","bids":[{"price":1773.18,"qty":0.00000000},{"price":1773.04,"qty":8.90705796},{"price":1773.20,"qty":0.05639521}],"asks":[],"checksum":3201200409,"timestamp":"2026-07-07T23:00:10.016786Z"}]}
{"channel":"book","type":"update","data":[{"symbol":"ETH/USD","bids":[],"asks":[{"price":1773.50,"qty":2.81929410}],"checksum":467054677,"timestamp":"2026-07-07T23:00:10.057936Z"}]}
{"channel":"book","type":"update","data":[{"symbol":"ETH/USD","bids":[],"asks":[{"price":1773.52,"qty":0.00000000},{"price":1773.75,"qty":28.67817146}],"checksum":1621308899,"timestamp":"2026-07-07T23:00:10.084457Z"}]}
{"channel":"book","type":"update","data":[{"symbol":"ETH/USD","bids":[{"price":1773.19,"qty":0.00000000},{"price":1773.04,"qty":8.90705796},{"price":1773.20,"qty":1.74606497}],"asks":[],"checksum":3555270817,"timestamp":"2026-07-07T23:00:10.186033Z"}]}
{"channel":"trade","type":"update","data":[{"symbol":"BTC/USD","side":"sell","price":63498.0,"qty":0.25005039,"ord_type":"limit","trade_id":103436772,"timestamp":"2026-07-07T23:00:10.240205Z"}]}
{"channel":"book","type":"update","data":[{"symbol":"BTC/USD","bids":[{"price":63498.0,"qty":1.05266166}],"asks":[],"checksum":419797136,"timestamp":"2026-07-07T23:00:10.240205Z"}]}
{"channel":"book","type":"update","data":[{"symbol":"ETH/USD","bids":[],"asks":[{"price":1773.47,"qty":0.33970354}],"checksum":2131879408,"timestamp":"2026-07-07T23:00:10.362520Z"}]}
{"channel":"book","type":"update","data":[{"symbol":"ETH/USD","bids":[],"asks":[{"price":1773.46,"qty":0.00000000},{"price":1773.82,"qty":6.69695895}],"checksum":3004649514,"timestamp":"2026-07-07T23:00:10.363937Z"}]}
{"channel":"book","type":"update","data":[{"symbol":"ETH/USD","bids":[],"asks":[{"price":1773.49,"qty":0.93610758}],"checksum":407278088,"timestamp":"2026-07-07T23:00:10.366083Z"}]}
{"channel":"book","type":"update","data":[{"symbol":"ETH/USD","bids":[],"asks":[{"price":1773.45,"qty":0.95931888}],"checksum":439642482,"timestamp":"2026-07-07T23:00:10.431969Z"}]}
{"channel":"book","type":"update","data":[{"symbol":"BTC/USD","bids":[],"asks":[{"price":63499.1,"qty":2.36305997}],"checksum":2264351774,"timestamp":"2026-07-07T23:00:10.434614Z"}]}
{"channel":"book","type":"update","data":[{"symbol":"ETH/USD","bids":[{"price":1773.22,"qty":0.00000000},{"price":1772.98,"qty":2.87402415}],"asks":[],"checksum":804252461,"timestamp":"2026-07-07T23:00:10.436037Z"}]}
{"channel":"book","type":"update","data":[{"symbol":"ETH/USD","bids":[],"asks":[{"price":1773.75,"qty":0.48930000}],"checksum":2142163341,"timestamp":"2026-07-07T23:00:10.436256Z"}]}
{"channel":"book","type":"update","data":[{"symbol":"ETH/USD","bids":[],"asks":[{"price":1773.50,"qty":0.00000000},{"price":1773.82,"qty":6.69695895}],"checksum":969499283,"timestamp":"2026-07-07T23:00:10.436653Z"}]}
{"channel":"book","type":"update","data":[{"symbol":"ETH/USD","bids":[{"price":1773.13,"qty":28.19445017}],"asks":[],"checksum":4270803953,"timestamp":"2026-07-07T23:00:10.437612Z"}]}
{"channel":"book","type":"update","data":[{"symbol":"ETH/USD","bids":[],"asks":[{"price":1773.70,"qty":0.00000000},{"price":1773.83,"qty":4.77600128},{"price":1773.81,"qty":12.35426731}],"checksum":3835367325,"timestamp":"2026-07-07T23:00:10.437726Z"}]}
{"channel":"book","type":"update","data":[{"symbol":"BTC/USD","bids":[],"asks":[{"price":63498.1,"qty":2.93998949}],"checksum":3165890182,"timestamp":"2026-07-07T23:00:10.438200Z"}]}
{"channel":"book","type":"update","data":[{"symbol":"ETH/USD","bids":[],"asks":[{"price":1773.47,"qty":3.15904553}],"checksum":2073512715,"timestamp":"2026-07-07T23:00:10.438938Z"}]}
{"channel":"book","type":"update","data":[{"symbol":"ETH/USD","bids":[],"asks":[{"price":1773.68,"qty":28.19010341}],"checksum":3309466853,"timestamp":"2026-07-07T23:00:10.439101Z"}]}
{"channel":"book","type":"update","data":[{"symbol":"ETH/USD","bids":[{"price":1773.15,"qty":2.81983139}],"asks":[],"checksum":1700175556,"timestamp":"2026-07-07T23:00:10.439421Z"}]}
{"channel":"book","type":"update","data":[{"symbol":"ETH/USD","bids":[],"asks":[{"price":1773.69,"qty":0.00000000},{"price":1773.82,"qty":6.69695895}],"checksum":1989167873,"timestamp":"2026-07-07T23:00:10.440651Z"}]}
{"channel":"book","type":"update","data":[{"symbol":"ETH/USD","bids":[],"asks":[{"price":1773.72,"qty":0.59738996}],"checksum":2215858909,"timestamp":"2026-07-07T23:00:10.440773Z"}]}
{"channel":"book","type":"update","data":[{"symbol":"BTC/USD","bids":[],"asks":[{"price":63498.5,"qty":1.01451635}],"checksum":757568184,"timestamp":"2026-07-07T23:00:10.440758Z"}]}
{"channel":"book","type":"update","data":[{"symbol":"BTC/USD","bids":[],"asks":[{"price":63499.1,"qty":0.00000000},{"price":63502.2,"qty":0.03160644},{"price":63501.2,"qty":2.36303368}],"checksum":2601132424,"timestamp":"2026-07-07T23:00:10.441194Z"}]}
{"channel":"book","type":"update","data":[{"symbol":"ETH/USD","bids":[],"asks":[{"price":1773.46,"qty":1.03752339}],"checksum":1861609662,"timestamp":"2026-07-07T23:00:10.442788Z"}]}
{"channel":"book","type":"update","data":[{"symbol":"ETH/USD","bids":[],"asks":[{"price":1773.49,"qty":0.00000000},{"price":1773.82,"qty":6.69695895}],"checksum":1878618594,"timestamp":"2026-07-07T23:00:10.443336Z"}]}
{"channel":"book","type":"update","data":[{"symbol":"ETH/USD","bids":[{"price":1773.13,"qty":0.00000000},{"price":1773.04,"qty":0.48930000},{"price":1773.05,"qty":28.19475004}],"asks":[],"checksum":151210161,"timestamp":"2026-07-07T23:00:10.443368Z"}]}
{"channel":"book","type":"update","data":[{"symbol":"ETH/USD","bids":[{"price":1773.11,"qty":0.00000000},{"price":1773.04,"qty":0.48930000},{"price":1773.14,"qty":5.56003448}],"asks":[],"checksum":3513291320,"timestamp":"2026-07-07T23:00:10.443400Z"}]}
{"channel":"book","type":"update","data":[{"symbol":"ETH/USD","bids":[],"asks":[{"price":1773.67,"qty":8.41474587}],"checksum":1940472268,"timestamp":"2026-07-07T23:00:10.443897Z"}]}
{"channel":"book","type":"update","data":[{"symbol":"ETH/USD","bids":[],"asks":[{"price":1773.72,"qty":4.21451904}],"checksum":127252876,"timestamp":"2026-07-07T23:00:10.444272Z"}]}
{"channel":"book","type":"update","data":[{"symbol":"BTC/USD","bids":[],"asks":[{"price":63498.5,"qty":0.35444250}],"checksum":178132406,"timestamp":"2026-07-07T23:00:10.444975Z"}]}
{"channel":"book","type":"update","data":[{"symbol":"BTC/USD","bids":[],"asks":[{"price":63501.3,"qty":0.78080773}],"checksum":2710145769,"timestamp":"2026-07-07T23:00:10.445020Z"}]}
{"channel":"book","type":"update","data":[{"symbol":"BTC/USD","bids":[],"asks":[{"price":63501.3,"qty":0.00000000},{"price":63502.2,"qty":0.03160644}],"checksum":1252503928,"timestamp":"2026-07-07T23:00:10.446742Z"}]}
{"channel":"book","type":"update","data":[{"symbol":"ETH/USD","bids":[{"price":1773.06,"qty":6.68414810}],"asks":[],"checksum":3067529642,"timestamp":"2026-07-07T23:00:10.447409Z"}]}
{"channel":"book","type":"update","data":[{"symbol":"BTC/USD","bids":[],"asks":[{"price":63501.1,"qty":1.94201371}],"checksum":4186590402,"timestamp":"2026-07-07T23:00:10.447575Z"}]}
{"channel":"book","type":"update","data":[{"symbol":"BTC/USD","bids":[],"asks":[{"price":63498.1,"qty":4.53998949}],"checksum":3893511747,"timestamp":"2026-07-07T23:00:10.459574Z"}]}
{"channel":"book","type":"update","data":[{"symbol":"ETH/USD","bids":[{"price":1773.37,"qty":0.06935921}],"asks":[],"checksum":182371169,"timestamp":"2026-07-07T23:00:10.469722Z"}]}
{"channel":"book","type":"update","data":[{"symbol":"ETH/USD","bids":[{"price":1773.14,"qty":0.00000000},{"price":1773.05,"qty":28.19475004},{"price":1773.11,"qty":5.56003448}],"asks":[],"checksum":1815056585,"timestamp":"2026-07-07T23:00:10.471095Z"}]}
{"channel":"book","type":"update","data":[{"symbol":"BTC/USD","bids":[],"asks":[{"price":63498.1,"qty":2.93998949}],"checksum":4186590402,"timestamp":"2026-07-07T23:00:10.493606Z"}]}
{"channel":"book","type":"update","data":[{"symbol":"ETH/USD","bids":[{"price":1773.15,"qty":0.00000000},{"price":1773.05,"qty":28.19475004}],"asks":[],"checksum":1266576630,"timestamp":"2026-07-07T23:00:10.510448Z"}]}
{"channel":"book","type":"update","data":[{"symbol":"ETH/USD","bids":[{"price":1773.20,"qty":4.56582244}],"asks":[],"checksum":999426942,"timestamp":"2026-07-07T23:00:10.512037Z"}]}
{"channel":"heartbeat"}
{"channel":"book","type":"update","data":[{"symbol":"BTC/USD","bids":[],"asks":[{"price":63501.6,"qty":0.00000000},{"price":63502.2,"qty":0.03160644},{"price":63498.1,"qty":4.50063044}],"checksum":199464457,"timestamp":"2026-07-07T23:00:10.588868Z"}]}
{"channel":"book","type":"update","data":[{"symbol":"BTC/USD","bids":[],"asks":[{"price":63498.1,"qty":4.50850042}],"checksum":661226913,"timestamp":"2026-07-07T23:00:10.604219Z"}]}
{"channel":"book","type":"update","data":[{"symbol":"ETH/USD","bids":[{"price":1773.20,"qty":1.74606497}],"asks":[],"checksum":1266576630,"timestamp":"2026-07-07T23:00:10.604395Z"}]}
{"channel":"book","type":"update","data":[{"symbol":"ETH/USD","bids":[],"asks":[{"price":1773.47,"qty":0.33970354}],"checksum":3897492567,"timestamp":"2026-07-07T23:00:10.604526Z"}]}
{"channel":"book","type":"update","data":[{"symbol":"ETH/USD","bids":[],"asks":[{"price":1773.46,"qty":0.00000000},{"price":1773.82,"qty":6.69695895}],"checksum":1817847557,"timestamp":"2026-07-07T23:00:10.606276Z"}]}
{"channel":"book","type":"update","data":[{"symbol":"ETH/USD","bids":[],"asks":[{"price":1773.51,"qty":2.81926889}],"checksum":2641344335,"timestamp":"2026-07-07T23:00:10.608187Z"}]}
{"channel":"book","type":"update","data":[{"symbol":"ETH/USD","bids":[{"price":1773.24,"qty":2.81968940}],"asks":[],"checksum":1440681247,"timestamp":"2026-07-07T23:00:10.608599Z"}]}
{"channel":"book","type":"update","data":[{"symbol":"ETH/USD","bids":[],"asks":[{"price":1773.50,"qty":0.93610006}],"checksum":335203793,"timestamp":"2026-07-07T23:00:10.609984Z"}]}
{"channel":"book","type":"update","data":[{"symbol":"ETH/USD","bids":[],"asks":[{"price":1773.45,"qty":0.47001888}],"checksum":1566324328,"timestamp":"2026-07-07T23:00:10.627224Z"}]}
{"channel":"book","type":"update","data":[{"symbol":"ETH/USD","bids":[],"asks":[{"price":1773.45,"qty":0.00000000},{"price":1773.81,"qty":12.35426731}],"checksum":2197123351,"timestamp":"2026-07-07T23:00:10.628501Z"}]}
{"channel":"book","type":"update","data":[{"symbol":"ETH/USD","bids":[],"asks":[{"price":1773.49,"qty":0.47001888}],"checksum":770215296,"timestamp":"2026-07-07T23:00:10.628689Z"}]}
{"channel":"book","type":"update","data":[{"symbol":"BTC/USD","bids":[],"asks":[{"price":63498.1,"qty":4.52150042}],"checksum":177586250,"timestamp":"2026-07-07T23:00:10.752202Z"}]}
{"channel":"book","type":"update","data":[{"symbol":"ETH/USD","bids":[],"asks":[{"price":1773.68,"qty":0.00000000},{"price":1773.81,"qty":12.35426731}],"checksum":961059300,"timestamp":"2026-07-07T23:00:10.843782Z"}]}
{"channel":"book","type":"update","data":[{"symbol":"ETH/USD","bids":[],"asks":[{"price":1773.51,"qty":0.00000000},{"price":1773.82,"qty":6.69695895}],"checksum":1146271130,"timestamp":"2026-07-07T23:00:10.844303Z"}]}
{"channel":"book","type":"update","data":[{"symbol":"ETH/USD","bids":[],"asks":[{"price":1773.67,"qty":0.00000000},{"price":1773.83,"qty":4.77600128}],"checksum":2660198557,"timestamp":"2026-07-07T23:00:10.845942Z"}]}
{"channel":"book","type":"update","data":[{"symbol":"ETH/USD","bids":[],"asks":[{"price":1773.50,"qty":0.00000000},{"price":1773.84,"qty":15.93800000}],"checksum":4112724138,"timestamp":"2026-07-07T23:00:10.846004Z"}]}
{"channel":"book","type":"update","data":[{"symbol":"ETH/USD","bids":[],"asks":[{"price":1773.55,"qty":2.81921140}],"checksum":3264631381,"timestamp":"2026-07-07T23:00:10.846423Z"}]}
{"channel":"book","type":"update","data":[{"symbol":"ETH/USD","bids":[],"asks":[{"price":1773.76,"qty":28.18879767}],"checksum":2416077621,"timestamp":"2026-07-07T23:00:10.846741Z"}]}
{"channel":"book","type":"update","data":[{"symbol":"ETH/USD","bids":[],"asks":[{"price":1773.72,"qty":3.61712908}],"checksum":877231584,"timestamp":"2026-07-07T23:00:10.848388Z"}]}
{"channel":"book","type":"update","data":[{"symbol":"ETH/USD","bids":[],"asks":[{"price":1773.72,"qty":0.00000000},{"price":1773.83,"qty":4.77600128}],"checksum":2322718077,"timestamp":"2026-07-07T23:00:10.848653Z"}]}
{"channel":"book","type":"update","data":[{"symbol":"ETH/USD","bids":[],"asks":[{"price":1773.54,"qty":0.84153460}],"checksum":2656476491,"timestamp":"2026-07-07T23:00:10.848773Z"}]}
{"channel":"book","type":"update","data":[{"symbol":"ETH/USD","bids":[],"asks":[{"price":1773.72,"qty":12.16643232}],"checksum":125301080,"timestamp":"2026-07-07T23:00:10.848959Z"}]}
{"channel":"book","type":"update","data":[{"symbol":"ETH/USD","bids":[{"price":1773.06,"qty":12.67243555}],"asks":[],"checksum":1371500149,"timestamp":"2026-07-07T23:00:10.852007Z"}]}
{"channel":"trade","type":"update","data":[{"symbol":"BTC/USD","side":"buy","price":63498.1,"qty":0.03355821,"ord_type":"limit","trade_id":103436773,"timestamp":"2026-07-07T23:00:10.859059Z"},{"symbol":"BTC/USD","side":"buy","price":63498.1,"qty":0.01004708,"ord_type":"limit","trade_id":103436774,"timestamp":"2026-07-07T23:00:10.859059Z"},{"symbol":"BTC/USD","side":"buy","price":63498.1,"qty":0.05990000,"ord_type":"limit","trade_id":103436775,"timestamp":"2026-07-07T23:00:10.859059Z"},{"symbol":"BTC/USD","side":"buy","price":63498.1,"qty":0.11000000,"ord_type":"limit","trade_id":103436776,"timestamp":"2026-07-07T23:00:10.859060Z"},{"symbol":"BTC/USD","side":"buy","price":63498.1,"qty":0.07297027,"ord_type":"limit","trade_id":103436777,"timestamp":"2026-07-07T23:00:10.859060Z"}]}
